File: data/XRD_RSM/YG059/YG059 phi0 STO 103 RSM slow 3 degree_1.xrdml
<?xml version="1.0" encoding="utf-8"?>
<xrdMeasurements xmlns="http://www.xrdml.com/XRDMeasurement/2.2" xmlns:xsi="http://www.w3.org/2001/XMLSchema-instance" xsi:schemaLocation="http://www.xrdml.com/XRDMeasurement/2.2 http://www.xrdml.com/XRDMeasurement/2.2/XRDMeasurement.xsd" status="Completed">
	<comment>
		<entry>Configuration=3-axes Cradle_Reflection, Owner=lw627, Creation date=9/2/2021 3:55:24 PM</entry>
		<entry>Goniometer=Theta/Theta; Minimum step size 2Theta:0.0001; Minimum step size Omega:0.0001</entry>
		<entry>Sample stage=Chi-Phi-z stage 240 mm (reflection); Minimum step size Phi:0.01; Minimum step size Chi:0.01; Minimum step size Z:0.001</entry>
		<entry>Diffractometer system=EMPYREAN</entry>
		<entry>Measurement program=C:\PANalytical\Data Collector\Programs\Liyan Wu\Film programs\RSM slow 3 degree.xrdmp, Identifier={0351664C-55A7-43E7-B72A-7307F4B26703}</entry>
	</comment>
	<sample type="To be analyzed">
		<id/>
		<name/>
		<preparedBy/>
	</sample>
	<xrdMeasurement status="Completed" measurementType="Area measurement" measurementStepAxis="Omega-2Theta" sampleMode="Reflection">
		<comment>
			<entry>PHD Lower Level = 4.02 (keV), PHD Upper Level = 11.27 (keV)</entry>
		</comment>
		<usedWavelength intended="K-Alpha 1">
			<kAlpha1 unit="Angstrom">1.5405980</kAlpha1>
			<kAlpha2 unit="Angstrom">1.5444260</kAlpha2>
			<kBeta unit="Angstrom">1.3922500</kBeta>
			<ratioKAlpha2KAlpha1>0</ratioKAlpha2KAlpha1>
		</usedWavelength>
		<incidentBeamPath>
			<radius unit="mm">240.00</radius>
			<xRayTube id="1010048" name="Empyrean Cu LFF HR (9430 033 7310x) DK432574">
				<tension unit="kV">45.0</tension>
				<current unit="mA">40.0</current>
				<anodeMaterial>Cu</anodeMaterial>
				<focus type="Line">
					<length unit="mm">12.0</length>
					<width unit="mm">0.4</width>
					<takeOffAngle unit="deg">4.4</takeOffAngle>
				</focus>
			</xRayTube>
			<xRayMirror xsi:type="xRayMirrorType" id="27080001" name="Inc. Beam Cu W/Si (hybrid MPD)" hybrid="true">
				<crystal type="Graded" shape="Parabolic">W/Si</crystal>
				<acceptanceAngle unit="deg">0.800</acceptanceAngle>
				<length unit="mm">55.3</length>
			</xRayMirror>
			<monochromator xsi:type="monochromatorType" id="23090002" name="Hybrid monochr. 2xGe220 Cu asym." hybrid="true">
				<crystal type="Asymmetric" shape="Flat">Ge</crystal>
				<numberOfReflections>2</numberOfReflections>
				<hkl>
					<h>2</h>
					<k>2</k>
					<l>0</l>
				</hkl>
			</monochromator>
			<divergenceSlit xsi:type="fixedDivergenceSlitType" id="22010005" name="Fixed slit 1/4°">
				<distanceToSample unit="mm">179.30</distanceToSample>
				<height unit="mm">0.38</height>
			</divergenceSlit>
		</incidentBeamPath>
		<diffractedBeamPath>
			<radius unit="mm">240.00</radius>
			<antiScatterSlit xsi:type="fixedAntiScatterSlitType" id="22060009" name="Programmable anti-scatter slit">
				<angle unit="deg">4</angle>
			</antiScatterSlit>
			<detector xsi:type="areaDetectorType" id="7010020" name="PIXcel3D-Medipix3 1x1 detector">
				<phd unit="%">
					<lowerLevel>25</lowerLevel>
					<upperLevel>70</upperLevel>
				</phd>
				<mode>Scanning snapshot equatorial</mode>
				<activeChannelsEquatorial>255</activeChannelsEquatorial>
				<activeChannelsAxial>255</activeChannelsAxial>
				<pitchEquatorial unit="mm">0.05500</pitchEquatorial>
				<pitchAxial unit="mm">0.05500</pitchAxial>
				<readOutPeriod unit="seconds">0.980</readOutPeriod>
			</detector>
		</diffractedBeamPath>
		<scan status="Completed" appendNumber="0" scanAxis="2Theta" mode="Continuous">
			<header>
				<startTimeStamp>2024-07-03T13:20:43-04:00</startTimeStamp>
				<endTimeStamp>2024-07-03T13:50:46-04:00</endTimeStamp>
				<author>
					<name>lw627</name>
				</author>
				<source>
					<applicationSoftware version="7.1">Data Collector</applicationSoftware>
					<instrumentControlSoftware version="8.2  20201204">EMPYREAN</instrumentControlSoftware>
					<instrumentID>0000000011260721</instrumentID>
				</source>
			</header>
			<dataPoints>
				<positions axis="2Theta" unit="deg">
					<startPosition>71.5574063943918</startPosition>
					<endPosition>74.9046761656082</endPosition>
				</positions>
				<positions axis="Omega" unit="deg">
					<commonPosition>17.96952064</commonPosition>
				</positions>
				<positions axis="Phi" unit="deg">
					<commonPosition>2.8</commonPosition>
				</positions>
				<positions axis="Chi" unit="deg">
					<commonPosition>0</commonPosition>
				</positions>
				<positions axis="Z" unit="mm">
					<commonPosition>8.386</commonPosition>
				</positions>
				<commonCountingTime unit="seconds">0.974</commonCountingTime>
				<counts unit="counts">0 1 0 1 1 0 0 0 0 0 0 0 0 0 0 1 0 0 0 3 0 0 0 1 0 0 0 0 1 0 0 2 1 0 1 0 0 0 0 1 0 0 0 1 0 0 0 0 0 0 1 0 0 0 1 1 0 0 0 0 0 2 1 0 0 0 0 0 0 1 0 0 0 0 0 0 0 1 1 1 0 1 1 0 0 0 0 1 0 1 0 0 0 1 0 1 0 0 0 0 0 1 0 0 0 0 0 1 0 0 0 0 0 0 0 0 0 0 0 0 0 1 0 0 0 0 0 0 0 0 1 0 0 0 0 0 0 1 0 0 1 0 0 1 1 0 0 0 1 0 1 2 0 0 0 0 0 0 0 0 0 0 0 1 1 0 0 0 0 0 0 0 0 1 0 1 0 0 2 1 1 0 1 0 1 0 0 0 0 0 1 0 0 0 0 1 0 0 0 0 1 0 1 0 0 0 1 0 2 1 1 0 0 0 0 1 0 0 0 1 0 2 0 0 1 1 0 1 0 1 2 0 0 0 1 0 0 1 0 1 0 0 0 0 0 2 0 0 0 1 0 0 1 1 0</counts>
			</dataPoints>
		</scan>
		<scan status="Completed" appendNumber="0" scanAxis="2Theta" mode="Continuous">
			<header>
				<startTimeStamp>2024-07-03T13:20:43-04:00</startTimeStamp>
				<endTimeStamp>2024-07-03T13:50:46-04:00</endTimeStamp>
				<author>
					<name>lw627</name>
				</author>
				<source>
					<applicationSoftware version="7.1">Data Collector</applicationSoftware>
					<instrumentControlSoftware version="8.2  20201204">EMPYREAN</instrumentControlSoftware>
					<instrumentID>0000000011260721</instrumentID>
				</source>
			</header>
			<dataPoints>
				<positions axis="2Theta" unit="deg">
					<startPosition>71.5606889650599</startPosition>
					<endPosition>74.9079587362764</endPosition>
				</positions>
				<positions axis="Omega" unit="deg">
					<commonPosition>17.9711619253341</commonPosition>
				</positions>
				<positions axis="Phi" unit="deg">
					<commonPosition>2.8</commonPosition>
				</positions>
				<positions axis="Chi" unit="deg">
					<commonPosition>0</commonPosition>
				</positions>
				<positions axis="Z" unit="mm">
					<commonPosition>8.386</commonPosition>
				</positions>
				<commonCountingTime unit="seconds">0.974</commonCountingTime>
				<counts unit="counts">0 0 0 0 0 1 0 1 0 0 0 0 1 1 1 0 0 0 0 0 0 1 0 0 0 0 0 1 0 3 0 0 0 0 0 0 1 1 1 0 1 0 1 1 1 0 0 0 1 0 0 0 1 0 0 0 1 0 0 0 0 0 0 1 1 0 0 0 0 0 0 0 0 0 0 0 0 0 0 0 0 0 0 0 1 1 0 0 0 0 1 0 0 1 0 0 0 0 0 0 0 0 2 0 0 1 0 0 0 1 1 0 0 0 0 0 0 0 2 1 1 1 0 1 0 1 0 0 0 0 0 0 0 0 0 0 0 2 0 0 0 0 0 0 0 0 1 0 0 0 1 0 0 0 0 0 0 1 1 0 0 0 0 1 0 0 1 0 0 0 0 0 0 1 0 1 1 0 0 1 0 0 0 0 1 0 0 0 0 1 1 0 0 0 0 0 0 2 2 1 0 1 0 0 0 0 0 0 0 0 1 0 0 0 0 0 0 1 0 2 0 0 1 0 0 0 0 0 1 1 0 0 0 1 1 0 0 0 0 1 0 1 0 0 1 1 0 0 0 2 0 0 2 0 0</counts>
			</dataPoints>
		</scan>
		<scan status="Completed" appendNumber="0" scanAxis="2Theta" mode="Continuous">
			<header>
				<startTimeStamp>2024-07-03T13:20:43-04:00</startTimeStamp>
				<endTimeStamp>2024-07-03T13:50:46-04:00</endTimeStamp>
				<author>
					<name>lw627</name>
				</author>
				<source>
					<applicationSoftware version="7.1">Data Collector</applicationSoftware>
					<instrumentControlSoftware version="8.2  20201204">EMPYREAN</instrumentControlSoftware>
					<instrumentID>0000000011260721</instrumentID>
				</source>
			</header>
			<dataPoints>
				<positions axis="2Theta" unit="deg">
					<startPosition>71.563971535728</startPosition>
					<endPosition>74.9112413069445</endPosition>
				</positions>
				<positions axis="Omega" unit="deg">
					<commonPosition>17.9728032106681</commonPosition>
				</positions>
				<positions axis="Phi" unit="deg">
					<commonPosition>2.8</commonPosition>
				</positions>
				<positions axis="Chi" unit="deg">
					<commonPosition>0</commonPosition>
				</positions>
				<positions axis="Z" unit="mm">
					<commonPosition>8.386</commonPosition>
				</positions>
				<commonCountingTime unit="seconds">0.974</commonCountingTime>
				<counts unit="counts">0 1 0 0 0 0 0 0 0 0 0 0 0 0 1 0 1 1 0 0 0 0 0 1 0 0 0 0 1 2 0 0 0 0 0 0 0 0 0 1 1 1 0 0 0 0 0 1 2 0 0 0 0 0 0 0 0 0 0 0 1 0 0 0 0 1 1 0 0 0 0 0 0 1 1 0 0 0 1 0 0 2 1 0 1 0 0 0 0 1 0 0 0 1 1 0 1 0 0 0 0 0 0 1 0 0 1 0 0 0 0 1 1 0 0 0 0 0 0 2 0 0 0 0 1 0 0 0 0 1 0 0 0 0 0 0 0 0 0 0 0 0 2 0 0 0 0 0 1 1 2 0 1 0 0 0 0 0 0 0 0 0 0 0 0 0 0 0 2 0 1 0 0 0 0 0 0 0 0 0 0 1 0 0 1 0 0 0 1 0 1 1 0 0 0 0 0 0 0 0 0 2 0 1 0 0 0 0 0 0 0 0 0 0 0 0 0 1 0 1 2 1 1 0 0 0 0 0 0 0 1 1 0 0 1 0 1 0 0 1 0 0 3 0 0 1 0 0 0 1 1 1 0 0 0</counts>
			</dataPoints>
		</scan>
		<scan status="Completed" appendNumber="0" scanAxis="2Theta" mode="Continuous">
			<header>
				<startTimeStamp>2024-07-03T13:20:43-04:00</startTimeStamp>
				<endTimeStamp>2024-07-03T13:50:46-04:00</endTimeStamp>
				<author>
					<name>lw627</name>
				</author>
				<source>
					<applicationSoftware version="7.1">Data Collector</applicationSoftware>
					<instrumentControlSoftware version="8.2  20201204">EMPYREAN</instrumentControlSoftware>
					<instrumentID>0000000011260721</instrumentID>
				</source>
			</header>
			<dataPoints>
				<positions axis="2Theta" unit="deg">
					<startPosition>71.5672541063961</startPosition>
					<endPosition>74.9145238776126</endPosition>
				</positions>
				<positions axis="Omega" unit="deg">
					<commonPosition>17.9744444960022</commonPosition>
				</positions>
				<positions axis="Phi" unit="deg">
					<commonPosition>2.8</commonPosition>
				</positions>
				<positions axis="Chi" unit="deg">
					<commonPosition>0</commonPosition>
				</positions>
				<positions axis="Z" unit="mm">
					<commonPosition>8.386</commonPosition>
				</positions>
				<commonCountingTime unit="seconds">0.974</commonCountingTime>
				<counts unit="counts">0 0 0 0 0 1 1 0 0 0 0 0 1 0 0 1 0 0 0 0 0 0 0 2 1 0 0 1 0 1 0 0 0 0 0 0 0 0 0 0 0 1 0 0 0 1 0 0 0 1 0 0 0 0 0 0 0 0 1 0 1 1 0 0 1 0 1 0 2 1 0 1 0 0 1 1 0 0 0 1 0 1 0 0 0 0 0 1 0 0 0 0 0 0 0 0 0 0 0 1 1 1 0 0 0 0 2 0 0 0 0 0 0 0 1 0 1 0 0 0 0 1 1 0 0 0 0 1 0 0 0 0 0 0 0 0 1 0 1 0 0 0 0 0 0 0 0 0 0 0 0 0 0 1 0 0 0 0 0 0 0 0 1 0 0 0 0 0 0 1 0 0 2 1 0 1 0 0 1 0 0 0 0 1 1 0 1 1 0 0 0 0 0 1 0 1 0 2 0 0 1 0 0 1 0 0 1 0 0 0 0 0 0 0 0 0 0 0 1 0 0 2 1 1 0 0 0 0 1 1 0 0 0 0 0 0 0 0 0 0 0 1 0 0 0 0 0 0 1 0 0 0 0 0 0</counts>
			</dataPoints>
		</scan>
		<scan status="Completed" appendNumber="0" scanAxis="2Theta" mode="Continuous">
			<header>
				<startTimeStamp>2024-07-03T13:20:43-04:00</startTimeStamp>
				<endTimeStamp>2024-07-03T13:50:46-04:00</endTimeStamp>
				<author>
					<name>lw627</name>
				</author>
				<source>
					<applicationSoftware version="7.1">Data Collector</applicationSoftware>
					<instrumentControlSoftware version="8.2  20201204">EMPYREAN</instrumentControlSoftware>
					<instrumentID>0000000011260721</instrumentID>
				</source>
			</header>
			<dataPoints>
				<positions axis="2Theta" unit="deg">
					<startPosition>71.5705366770643</startPosition>
					<endPosition>74.9178064482807</endPosition>
				</positions>
				<positions axis="Omega" unit="deg">
					<commonPosition>17.9760857813363</commonPosition>
				</positions>
				<positions axis="Phi" unit="deg">
					<commonPosition>2.8</commonPosition>
				</positions>
				<positions axis="Chi" unit="deg">
					<commonPosition>0</commonPosition>
				</positions>
				<positions axis="Z" unit="mm">
					<commonPosition>8.386</commonPosition>
				</positions>
				<commonCountingTime unit="seconds">0.974</commonCountingTime>
				<counts unit="counts">1 0 0 0 0 0 0 0 1 1 0 1 1 0 0 0 0 0 2 0 0 1 0 0 0 0 0 1 0 1 0 0 0 0 0 0 0 0 1 0 0 0 3 0 0 0 1 0 0 1 1 0 0 1 0 0 0 1 1 1 0 0 0 0 1 1 0 1 0 0 1 0 1 1 0 1 1 0 1 0 0 0 0 0 0 0 0 0 0 1 0 1 1 1 0 0 0 1 3 0 0 0 0 0 1 0 1 0 1 0 1 1 1 0 0 0 0 1 0 0 0 0 0 0 0 0 0 0 0 0 0 2 0 1 1 0 0 0 3 0 1 0 0 0 0 0 1 0 0 0 0 0 0 0 0 0 0 0 0 4 0 0 0 1 0 0 0 0 1 0 0 0 2 1 0 1 0 0 0 0 0 0 0 0 1 0 0 1 0 0 0 1 0 1 1 0 0 1 0 2 0 0 0 0 1 1 0 0 0 0 0 0 0 0 0 0 0 1 0 0 0 0 0 1 0 2 0 1 0 0 0 0 0 1 0 0 0 1 0 1 0 2 0 0 0 0 0 1 0 0 1 0 1 1 0</counts>
			</dataPoints>
		</scan>
		<scan status="Completed" appendNumber="0" scanAxis="2Theta" mode="Continuous">
			<header>
				<startTimeStamp>2024-07-03T13:20:43-04:00</startTimeStamp>
				<endTimeStamp>2024-07-03T13:50:46-04:00</endTimeStamp>
				<author>
					<name>lw627</name>
				</author>
				<source>
					<applicationSoftware version="7.1">Data Collector</applicationSoftware>
					<instrumentControlSoftware version="8.2  20201204">EMPYREAN</instrumentControlSoftware>
					<instrumentID>0000000011260721</instrumentID>
				</source>
			</header>
			<dataPoints>
				<positions axis="2Theta" unit="deg">
					<startPosition>71.5738192477324</startPosition>
					<endPosition>74.9210890189489</endPosition>
				</positions>
				<positions axis="Omega" unit="deg">
					<commonPosition>17.9777270666703</commonPosition>
				</positions>
				<positions axis="Phi" unit="deg">
					<commonPosition>2.8</commonPosition>
				</positions>
				<positions axis="Chi" unit="deg">
					<commonPosition>0</commonPosition>
				</positions>
				<positions axis="Z" unit="mm">
					<commonPosition>8.386</commonPosition>
				</positions>
				<commonCountingTime unit="seconds">0.974</commonCountingTime>
				<counts unit="counts">0 0 0 0 0 0 0 0 0 0 1 0 0 0 3 1 1 1 0 0 0 1 0 1 0 1 0 0 0 0 0 1 0 0 0 0 0 0 0 0 1 0 0 0 0 0 1 1 0 1 0 1 0 1 0 0 0 0 2 0 0 2 0 0 1 0 0 0 0 0 0 1 0 0 0 0 0 1 0 1 0 0 0 0 1 0 0 0 0 0 0 0 0 0 0 0 0 0 0 0 1 0 0 1 0 2 0 0 0 1 0 2 0 0 0 0 0 0 1 0 0 2 1 0 0 0 0 1 0 0 0 0 1 0 0 0 1 1 1 0 0 1 0 0 0 1 2 0 0 0 1 0 2 0 1 0 0 1 0 0 1 0 0 2 0 1 1 0 0 0 0 0 0 0 0 0 1 1 0 0 0 0 1 0 1 1 2 0 0 1 0 0 0 0 0 0 0 1 0 0 1 0 0 0 0 0 1 1 0 0 0 0 0 0 0 0 0 0 0 0 0 0 0 0 0 0 0 1 0 0 0 0 0 0 2 1 1 0 0 1 0 0 0 0 0 0 0 0 1 1 0 0 0 0 0</counts>
			</dataPoints>
		</scan>
		<scan status="Completed" appendNumber="0" scanAxis="2Theta" mode="Continuous">
			<header>
				<startTimeStamp>2024-07-03T13:20:43-04:00</startTimeStamp>
				<endTimeStamp>2024-07-03T13:50:46-04:00</endTimeStamp>
				<author>
					<name>lw627</name>
				</author>
				<source>
					<applicationSoftware version="7.1">Data Collector</applicationSoftware>
					<instrumentControlSoftware version="8.2  20201204">EMPYREAN</instrumentControlSoftware>
					<instrumentID>0000000011260721</instrumentID>
				</source>
			</header>
			<dataPoints>
				<positions axis="2Theta" unit="deg">
					<startPosition>71.5771018184005</startPosition>
					<endPosition>74.924371589617</endPosition>
				</positions>
				<positions axis="Omega" unit="deg">
					<commonPosition>17.9793683520044</commonPosition>
				</positions>
				<positions axis="Phi" unit="deg">
					<commonPosition>2.8</commonPosition>
				</positions>
				<positions axis="Chi" unit="deg">
					<commonPosition>0</commonPosition>
				</positions>
				<positions axis="Z" unit="mm">
					<commonPosition>8.386</commonPosition>
				</positions>
				<commonCountingTime unit="seconds">0.974</commonCountingTime>
				<counts unit="counts">0 0 0 1 0 0 1 0 1 1 0 1 0 0 0 0 0 0 1 1 0 0 1 1 0 2 1 0 0 0 0 0 0 0 1 0 0 0 0 0 0 0 0 0 0 1 0 1 1 0 0 1 0 0 1 0 0 0 0 0 1 0 0 2 2 0 0 1 0 0 0 1 0 0 1 1 0 3 0 0 1 0 0 0 0 0 0 0 0 2 0 0 1 2 0 0 0 0 0 2 0 0 1 0 3 0 0 1 0 1 0 2 0 0 1 2 1 0 0 0 0 0 0 1 0 0 1 0 0 0 1 1 0 0 0 0 1 1 0 0 0 0 1 0 1 0 0 0 0 0 0 0 0 0 1 0 1 0 1 1 1 0 0 0 0 0 0 0 0 0 0 0 0 0 0 1 0 0 0 0 0 0 0 0 0 0 0 1 0 0 0 1 1 0 0 1 0 0 0 0 0 0 0 0 0 0 1 0 0 2 0 0 0 0 0 1 0 0 1 0 0 0 1 0 0 0 0 0 0 0 0 0 0 0 0 0 0 0 0 0 0 1 1 0 0 1 0 2 0 0 0 3 0 2 0</counts>
			</dataPoints>
		</scan>
		<scan status="Completed" appendNumber="0" scanAxis="2Theta" mode="Continuous">
			<header>
				<startTimeStamp>2024-07-03T13:20:43-04:00</startTimeStamp>
				<endTimeStamp>2024-07-03T13:50:46-04:00</endTimeStamp>
				<author>
					<name>lw627</name>
				</author>
				<source>
					<applicationSoftware version="7.1">Data Collector</applicationSoftware>
					<instrumentControlSoftware version="8.2  20201204">EMPYREAN</instrumentControlSoftware>
					<instrumentID>0000000011260721</instrumentID>
				</source>
			</header>
			<dataPoints>
				<positions axis="2Theta" unit="deg">
					<startPosition>71.5803843890687</startPosition>
					<endPosition>74.9276541602851</endPosition>
				</positions>
				<positions axis="Omega" unit="deg">
					<commonPosition>17.9810096373384</commonPosition>
				</positions>
				<positions axis="Phi" unit="deg">
					<commonPosition>2.8</commonPosition>
				</positions>
				<positions axis="Chi" unit="deg">
					<commonPosition>0</commonPosition>
				</positions>
				<positions axis="Z" unit="mm">
					<commonPosition>8.386</commonPosition>
				</positions>
				<commonCountingTime unit="seconds">0.974</commonCountingTime>
				<counts unit="counts">2 0 0 0 0 0 1 0 0 0 0 0 1 0 0 0 0 1 1 0 0 0 0 0 1 0 1 2 0 0 2 0 0 1 0 0 0 1 0 1 0 1 0 0 0 0 0 0 0 0 1 0 0 0 0 0 0 0 1 2 0 0 0 2 1 0 0 1 0 0 0 1 1 0 0 0 0 0 0 0 0 0 0 1 0 0 1 0 0 0 0 1 0 1 0 0 0 0 1 0 0 0 1 0 0 0 0 0 1 0 0 4 1 1 1 0 0 0 1 0 0 0 0 1 1 0 0 2 2 0 1 0 0 0 0 0 0 0 0 0 0 1 0 1 1 0 1 0 0 0 0 0 1 1 0 1 1 0 0 0 0 0 0 0 0 1 0 0 0 0 2 0 0 2 0 0 1 0 1 0 1 0 0 0 1 0 0 0 0 0 0 0 0 0 0 0 1 0 0 1 0 0 0 2 0 1 0 1 1 0 0 1 2 0 0 0 0 0 1 0 0 0 0 0 1 0 0 0 1 0 0 3 1 0 0 0 0 0 0 1 0 0 0 0 0 0 1 1 0 0 0 1 0 1 0</counts>
			</dataPoints>
		</scan>
		<scan status="Completed" appendNumber="0" scanAxis="2Theta" mode="Continuous">
			<header>
				<startTimeStamp>2024-07-03T13:20:43-04:00</startTimeStamp>
				<endTimeStamp>2024-07-03T13:50:46-04:00</endTimeStamp>
				<author>
					<name>lw627</name>
				</author>
				<source>
					<applicationSoftware version="7.1">Data Collector</applicationSoftware>
					<instrumentControlSoftware version="8.2  20201204">EMPYREAN</instrumentControlSoftware>
					<instrumentID>0000000011260721</instrumentID>
				</source>
			</header>
			<dataPoints>
				<positions axis="2Theta" unit="deg">
					<startPosition>71.5836669597368</startPosition>
					<endPosition>74.9309367309532</endPosition>
				</positions>
				<positions axis="Omega" unit="deg">
					<commonPosition>17.9826509226725</commonPosition>
				</positions>
				<positions axis="Phi" unit="deg">
					<commonPosition>2.8</commonPosition>
				</positions>
				<positions axis="Chi" unit="deg">
					<commonPosition>0</commonPosition>
				</positions>
				<positions axis="Z" unit="mm">
					<commonPosition>8.386</commonPosition>
				</positions>
				<commonCountingTime unit="seconds">0.974</commonCountingTime>
				<counts unit="counts">0 0 0 1 0 0 0 3 0 0 0 1 0 0 0 0 0 0 0 0 0 1 1 2 0 0 0 1 0 0 1 0 1 1 0 0 0 0 0 0 1 1 0 0 0 0 0 0 0 1 0 0 0 0 0 0 0 0 2 1 0 0 0 1 0 0 0 1 0 0 0 0 0 0 0 1 0 0 1 0 0 0 0 0 0 1 0 1 0 0 0 0 0 0 0 1 0 0 0 0 1 2 0 0 0 0 0 0 0 0 1 0 0 1 0 0 1 0 0 2 0 0 0 0 0 0 1 0 0 0 0 0 0 0 0 0 0 0 0 0 1 0 1 0 0 0 1 1 0 1 1 0 0 0 0 1 0 0 1 1 1 0 0 0 3 0 0 0 1 0 0 0 0 0 1 0 0 0 0 0 2 0 0 1 0 0 0 0 1 1 0 2 0 0 0 0 0 0 1 0 2 0 0 1 0 0 0 0 0 0 0 0 0 1 0 0 0 0 0 0 0 0 0 0 0 1 1 0 0 0 0 0 0 0 0 0 0 0 0 0 1 1 0 0 1 0 0 0 0 0 0 1 0 0 1</counts>
			</dataPoints>
		</scan>
		<scan status="Completed" appendNumber="0" scanAxis="2Theta" mode="Continuous">
			<header>
				<startTimeStamp>2024-07-03T13:20:43-04:00</startTimeStamp>
				<endTimeStamp>2024-07-03T13:50:46-04:00</endTimeStamp>
				<author>
					<name>lw627</name>
				</author>
				<source>
					<applicationSoftware version="7.1">Data Collector</applicationSoftware>
					<instrumentControlSoftware version="8.2  20201204">EMPYREAN</instrumentControlSoftware>
					<instrumentID>0000000011260721</instrumentID>
				</source>
			</header>
			<dataPoints>
				<positions axis="2Theta" unit="deg">
					<startPosition>71.5869495304049</startPosition>
					<endPosition>74.9342193016214</endPosition>
				</positions>
				<positions axis="Omega" unit="deg">
					<commonPosition>17.9842922080066</commonPosition>
				</positions>
				<positions axis="Phi" unit="deg">
					<commonPosition>2.8</commonPosition>
				</positions>
				<positions axis="Chi" unit="deg">
					<commonPosition>0</commonPosition>
				</positions>
				<positions axis="Z" unit="mm">
					<commonPosition>8.386</commonPosition>
				</positions>
				<commonCountingTime unit="seconds">0.974</commonCountingTime>
				<counts unit="counts">0 1 0 0 0 0 1 0 0 0 0 0 0 1 3 0 0 0 0 0 0 1 0 0 0 1 0 1 0 1 0 0 0 0 0 0 0 0 0 0 0 0 0 0 1 0 1 0 0 0 0 0 0 0 0 0 0 0 0 0 0 0 0 0 0 1 0 0 0 2 0 0 0 0 0 0 0 0 1 0 1 0 0 1 0 0 0 0 0 1 0 0 0 0 0 0 0 0 0 2 0 0 1 0 0 1 0 0 0 0 0 0 1 0 0 0 0 0 0 0 0 0 0 0 1 0 0 0 0 0 0 0 0 1 0 2 0 1 0 0 0 0 1 0 0 0 0 1 0 0 0 0 0 1 1 1 1 0 1 2 0 0 0 1 0 0 0 0 0 0 2 0 0 1 1 0 0 1 0 0 0 0 0 0 0 0 0 0 0 0 0 1 0 1 0 1 1 1 1 1 3 1 0 0 0 2 0 0 0 1 1 2 1 1 0 0 0 0 0 0 0 0 0 0 0 2 0 0 0 0 0 0 0 1 0 0 1 0 0 0 0 0 1 0 0 1 0 0 0 1 0 0 0 1 0</counts>
			</dataPoints>
		</scan>
		<scan status="Completed" appendNumber="0" scanAxis="2Theta" mode="Continuous">
			<header>
				<startTimeStamp>2024-07-03T13:20:43-04:00</startTimeStamp>
				<endTimeStamp>2024-07-03T13:50:46-04:00</endTimeStamp>
				<author>
					<name>lw627</name>
				</author>
				<source>
					<applicationSoftware version="7.1">Data Collector</applicationSoftware>
					<instrumentControlSoftware version="8.2  20201204">EMPYREAN</instrumentControlSoftware>
					<instrumentID>0000000011260721</instrumentID>
				</source>
			</header>
			<dataPoints>
				<positions axis="2Theta" unit="deg">
					<startPosition>71.590232101073</startPosition>
					<endPosition>74.9375018722895</endPosition>
				</positions>
				<positions axis="Omega" unit="deg">
					<commonPosition>17.9859334933406</commonPosition>
				</positions>
				<positions axis="Phi" unit="deg">
					<commonPosition>2.8</commonPosition>
				</positions>
				<positions axis="Chi" unit="deg">
					<commonPosition>0</commonPosition>
				</positions>
				<positions axis="Z" unit="mm">
					<commonPosition>8.386</commonPosition>
				</positions>
				<commonCountingTime unit="seconds">0.974</commonCountingTime>
				<counts unit="counts">2 0 1 0 0 0 0 3 0 0 0 0 0 0 0 1 1 0 0 1 0 0 0 2 0 0 1 0 1 1 0 0 0 0 0 0 0 0 2 1 0 1 0 0 0 1 0 0 1 0 0 0 0 0 0 0 1 0 0 1 0 0 0 0 0 1 0 0 0 0 0 0 2 1 0 0 0 0 0 0 0 0 0 0 0 0 0 0 1 0 0 0 1 0 0 0 0 0 0 0 0 0 0 1 1 0 0 1 0 0 0 0 0 0 0 0 0 0 0 0 0 1 1 0 0 1 0 1 0 0 0 0 0 1 1 0 0 0 0 0 0 0 0 0 0 0 0 1 2 2 0 0 0 0 0 0 1 0 0 0 0 0 0 0 0 0 0 1 1 0 1 0 0 0 0 0 0 0 0 2 0 0 0 0 0 0 1 0 0 0 0 0 1 0 2 2 1 0 0 0 1 2 1 0 0 1 1 0 0 1 0 0 0 0 0 0 1 0 0 1 1 0 0 1 0 0 0 0 1 0 0 0 0 1 0 1 1 0 2 0 0 0 0 1 1 1 0 0 0 0 0 0 0 0 0</counts>
			</dataPoints>
		</scan>
		<scan status="Completed" appendNumber="0" scanAxis="2Theta" mode="Continuous">
			<header>
				<startTimeStamp>2024-07-03T13:20:43-04:00</startTimeStamp>
				<endTimeStamp>2024-07-03T13:50:46-04:00</endTimeStamp>
				<author>
					<name>lw627</name>
				</author>
				<source>
					<applicationSoftware version="7.1">Data Collector</applicationSoftware>
					<instrumentControlSoftware version="8.2  20201204">EMPYREAN</instrumentControlSoftware>
					<instrumentID>0000000011260721</instrumentID>
				</source>
			</header>
			<dataPoints>
				<positions axis="2Theta" unit="deg">
					<startPosition>71.5935146717412</startPosition>
					<endPosition>74.9407844429576</endPosition>
				</positions>
				<positions axis="Omega" unit="deg">
					<commonPosition>17.9875747786747</commonPosition>
				</positions>
				<positions axis="Phi" unit="deg">
					<commonPosition>2.8</commonPosition>
				</positions>
				<positions axis="Chi" unit="deg">
					<commonPosition>0</commonPosition>
				</positions>
				<positions axis="Z" unit="mm">
					<commonPosition>8.386</commonPosition>
				</positions>
				<commonCountingTime unit="seconds">0.974</commonCountingTime>
				<counts unit="counts">0 0 1 0 0 1 1 0 0 0 0 0 0 1 0 0 0 1 0 0 0 0 0 0 0 1 0 0 1 0 1 0 0 0 0 0 0 0 0 0 0 0 0 0 0 0 0 0 0 1 1 0 0 0 0 0 1 0 1 0 0 0 0 1 0 0 1 0 1 0 0 0 0 0 1 1 0 0 1 0 1 0 0 0 2 0 0 0 0 0 1 0 1 0 0 0 0 0 1 0 0 0 0 1 0 0 0 0 1 0 0 0 2 0 0 0 0 0 0 0 1 2 1 0 0 2 0 0 1 0 0 0 0 0 0 0 0 1 0 0 1 0 0 0 1 0 0 0 1 0 1 0 1 1 0 0 0 0 0 0 0 0 1 0 1 0 1 0 0 0 1 0 0 0 0 0 2 0 0 0 0 0 0 1 0 0 1 0 0 0 0 0 2 0 0 0 0 1 0 2 0 0 1 0 0 0 0 0 0 0 0 0 0 0 0 0 0 0 1 0 0 0 0 0 0 0 0 1 0 0 0 0 0 1 1 0 0 1 0 0 0 1 1 0 0 0 0 0 0 0 0 0 0 0 0</counts>
			</dataPoints>
		</scan>
		<scan status="Completed" appendNumber="0" scanAxis="2Theta" mode="Continuous">
			<header>
				<startTimeStamp>2024-07-03T13:20:43-04:00</startTimeStamp>
				<endTimeStamp>2024-07-03T13:50:46-04:00</endTimeStamp>
				<author>
					<name>lw627</name>
				</author>
				<source>
					<applicationSoftware version="7.1">Data Collector</applicationSoftware>
					<instrumentControlSoftware version="8.2  20201204">EMPYREAN</instrumentControlSoftware>
					<instrumentID>0000000011260721</instrumentID>
				</source>
			</header>
			<dataPoints>
				<positions axis="2Theta" unit="deg">
					<startPosition>71.5967972424093</startPosition>
					<endPosition>74.9440670136258</endPosition>
				</positions>
				<positions axis="Omega" unit="deg">
					<commonPosition>17.9892160640088</commonPosition>
				</positions>
				<positions axis="Phi" unit="deg">
					<commonPosition>2.8</commonPosition>
				</positions>
				<positions axis="Chi" unit="deg">
					<commonPosition>0</commonPosition>
				</positions>
				<positions axis="Z" unit="mm">
					<commonPosition>8.386</commonPosition>
				</positions>
				<commonCountingTime unit="seconds">0.974</commonCountingTime>
				<counts unit="counts">1 2 0 0 0 0 0 1 0 0 0 0 0 0 1 0 0 0 0 0 0 0 1 1 1 0 0 1 0 0 0 0 1 0 1 0 0 0 0 0 0 0 2 1 0 0 0 0 0 0 0 0 0 0 0 0 0 0 0 0 0 0 1 0 0 0 0 0 0 0 0 0 0 0 0 0 0 0 0 0 1 1 2 0 0 0 1 1 1 1 1 0 1 0 0 0 0 1 1 0 0 0 0 0 0 0 0 0 1 1 0 1 0 0 0 1 0 0 0 0 1 0 1 0 0 0 0 0 0 0 0 0 0 0 0 0 0 0 0 0 2 2 0 0 1 1 1 1 0 0 0 0 0 0 0 0 1 2 0 0 0 0 0 0 0 0 1 1 0 0 0 2 2 2 0 1 0 1 0 0 0 0 0 1 1 0 0 0 0 0 0 1 1 1 0 0 1 0 0 0 0 0 2 0 0 0 0 0 0 2 0 0 1 0 0 0 1 0 0 0 0 0 0 0 0 0 0 1 0 0 0 1 1 0 1 2 0 0 0 0 0 0 0 0 0 0 0 0 0 0 0 0 0 1 0</counts>
			</dataPoints>
		</scan>
		<scan status="Completed" appendNumber="0" scanAxis="2Theta" mode="Continuous">
			<header>
				<startTimeStamp>2024-07-03T13:20:43-04:00</startTimeStamp>
				<endTimeStamp>2024-07-03T13:50:46-04:00</endTimeStamp>
				<author>
					<name>lw627</name>
				</author>
				<source>
					<applicationSoftware version="7.1">Data Collector</applicationSoftware>
					<instrumentControlSoftware version="8.2  20201204">EMPYREAN</instrumentControlSoftware>
					<instrumentID>0000000011260721</instrumentID>
				</source>
			</header>
			<dataPoints>
				<positions axis="2Theta" unit="deg">
					<startPosition>71.6000798130774</startPosition>
					<endPosition>74.9473495842939</endPosition>
				</positions>
				<positions axis="Omega" unit="deg">
					<commonPosition>17.9908573493428</commonPosition>
				</positions>
				<positions axis="Phi" unit="deg">
					<commonPosition>2.8</commonPosition>
				</positions>
				<positions axis="Chi" unit="deg">
					<commonPosition>0</commonPosition>
				</positions>
				<positions axis="Z" unit="mm">
					<commonPosition>8.386</commonPosition>
				</positions>
				<commonCountingTime unit="seconds">0.974</commonCountingTime>
				<counts unit="counts">0 0 1 0 0 0 0 0 0 0 0 1 0 1 0 0 1 0 0 0 0 1 0 1 0 1 0 0 0 0 1 1 0 0 0 0 0 0 2 1 0 0 0 0 0 0 0 1 0 0 0 1 0 1 2 0 1 0 2 0 0 0 0 0 0 1 0 1 0 0 1 1 0 0 0 0 0 0 0 0 0 0 0 1 0 0 1 0 0 1 2 0 0 1 0 0 0 0 0 0 0 0 1 0 0 0 0 0 1 0 0 0 0 1 0 0 1 1 2 0 0 0 0 1 1 0 0 0 0 2 0 1 0 0 0 0 0 1 0 0 0 0 1 1 0 0 1 0 1 0 0 0 0 1 1 0 0 0 0 0 0 0 0 0 0 1 1 0 0 0 0 1 0 0 0 1 1 0 0 0 0 0 1 2 1 0 0 0 0 1 0 0 0 0 1 1 0 0 0 0 1 0 1 0 1 0 1 0 1 0 0 1 0 0 0 0 0 1 1 0 0 0 1 1 0 0 2 0 1 2 0 1 0 0 0 0 0 0 1 0 0 0 1 0 0 0 0 0 1 0 1 1 0 0 0</counts>
			</dataPoints>
		</scan>
		<scan status="Completed" appendNumber="0" scanAxis="2Theta" mode="Continuous">
			<header>
				<startTimeStamp>2024-07-03T13:20:43-04:00</startTimeStamp>
				<endTimeStamp>2024-07-03T13:50:46-04:00</endTimeStamp>
				<author>
					<name>lw627</name>
				</author>
				<source>
					<applicationSoftware version="7.1">Data Collector</applicationSoftware>
					<instrumentControlSoftware version="8.2  20201204">EMPYREAN</instrumentControlSoftware>
					<instrumentID>0000000011260721</instrumentID>
				</source>
			</header>
			<dataPoints>
				<positions axis="2Theta" unit="deg">
					<startPosition>71.6033623837455</startPosition>
					<endPosition>74.950632154962</endPosition>
				</positions>
				<positions axis="Omega" unit="deg">
					<commonPosition>17.9924986346769</commonPosition>
				</positions>
				<positions axis="Phi" unit="deg">
					<commonPosition>2.8</commonPosition>
				</positions>
				<positions axis="Chi" unit="deg">
					<commonPosition>0</commonPosition>
				</positions>
				<positions axis="Z" unit="mm">
					<commonPosition>8.386</commonPosition>
				</positions>
				<commonCountingTime unit="seconds">0.974</commonCountingTime>
				<counts unit="counts">1 0 0 0 0 2 0 0 0 0 1 1 0 0 0 1 0 1 0 2 2 1 0 0 0 1 0 0 0 0 0 0 1 0 2 0 2 0 0 0 0 0 0 1 0 1 0 0 0 0 0 0 0 0 0 0 2 0 0 0 1 0 1 0 2 0 0 0 3 0 0 1 0 1 1 0 0 0 0 0 0 1 1 0 0 0 0 0 1 2 0 0 0 0 0 0 1 1 1 0 0 0 0 0 1 0 1 2 1 0 0 0 0 1 0 1 0 1 1 0 0 0 0 0 0 0 1 0 1 0 0 0 2 0 0 1 0 0 0 0 1 0 0 0 1 0 0 0 0 1 0 0 0 0 0 0 0 1 0 0 0 0 0 0 1 0 0 0 0 1 0 1 1 0 0 0 0 0 0 0 0 0 1 1 0 0 0 0 0 1 2 0 0 0 1 1 1 1 0 1 1 0 1 0 1 0 0 0 0 0 0 1 1 1 0 0 2 0 0 1 0 2 0 0 0 0 0 0 0 0 0 0 1 0 0 1 1 0 1 0 0 1 0 1 0 1 0 1 0 0 0 0 0 1 0</counts>
			</dataPoints>
		</scan>
		<scan status="Completed" appendNumber="0" scanAxis="2Theta" mode="Continuous">
			<header>
				<startTimeStamp>2024-07-03T13:20:43-04:00</startTimeStamp>
				<endTimeStamp>2024-07-03T13:50:46-04:00</endTimeStamp>
				<author>
					<name>lw627</name>
				</author>
				<source>
					<applicationSoftware version="7.1">Data Collector</applicationSoftware>
					<instrumentControlSoftware version="8.2  20201204">EMPYREAN</instrumentControlSoftware>
					<instrumentID>0000000011260721</instrumentID>
				</source>
			</header>
			<dataPoints>
				<positions axis="2Theta" unit="deg">
					<startPosition>71.6066449544137</startPosition>
					<endPosition>74.9539147256301</endPosition>
				</positions>
				<positions axis="Omega" unit="deg">
					<commonPosition>17.994139920011</commonPosition>
				</positions>
				<positions axis="Phi" unit="deg">
					<commonPosition>2.8</commonPosition>
				</positions>
				<positions axis="Chi" unit="deg">
					<commonPosition>0</commonPosition>
				</positions>
				<positions axis="Z" unit="mm">
					<commonPosition>8.386</commonPosition>
				</positions>
				<commonCountingTime unit="seconds">0.974</commonCountingTime>
				<counts unit="counts">0 1 0 0 1 1 0 1 0 1 0 0 0 0 0 0 0 2 0 0 0 0 0 0 0 1 0 0 0 1 1 0 0 0 1 0 0 0 1 1 0 1 0 0 0 1 1 0 0 0 0 0 0 0 1 1 0 0 0 0 0 0 0 1 0 1 0 0 0 2 0 0 0 1 0 0 1 0 0 0 0 0 1 2 0 0 0 0 0 0 0 0 0 0 0 0 0 0 0 1 0 0 0 1 0 0 2 0 0 0 0 0 0 2 0 0 0 0 0 0 0 0 0 0 1 0 0 0 0 0 0 0 0 1 0 0 0 0 0 0 0 0 1 0 0 0 1 1 0 0 0 0 0 0 0 1 0 0 0 0 0 0 0 0 1 1 0 0 0 1 0 0 0 1 1 0 0 1 0 0 0 1 0 0 0 0 0 0 0 0 0 0 0 0 0 2 2 0 0 0 1 0 2 0 0 0 0 1 1 0 0 0 0 1 1 0 0 2 0 0 0 0 0 0 0 0 1 0 0 0 0 0 2 0 1 1 0 0 0 0 0 1 2 0 1 0 0 0 0 0 0 1 0 0 1</counts>
			</dataPoints>
		</scan>
		<scan status="Completed" appendNumber="0" scanAxis="2Theta" mode="Continuous">
			<header>
				<startTimeStamp>2024-07-03T13:20:43-04:00</startTimeStamp>
				<endTimeStamp>2024-07-03T13:50:46-04:00</endTimeStamp>
				<author>
					<name>lw627</name>
				</author>
				<source>
					<applicationSoftware version="7.1">Data Collector</applicationSoftware>
					<instrumentControlSoftware version="8.2  20201204">EMPYREAN</instrumentControlSoftware>
					<instrumentID>0000000011260721</instrumentID>
				</source>
			</header>
			<dataPoints>
				<positions axis="2Theta" unit="deg">
					<startPosition>71.6099275250818</startPosition>
					<endPosition>74.9571972962983</endPosition>
				</positions>
				<positions axis="Omega" unit="deg">
					<commonPosition>17.995781205345</commonPosition>
				</positions>
				<positions axis="Phi" unit="deg">
					<commonPosition>2.8</commonPosition>
				</positions>
				<positions axis="Chi" unit="deg">
					<commonPosition>0</commonPosition>
				</positions>
				<positions axis="Z" unit="mm">
					<commonPosition>8.386</commonPosition>
				</positions>
				<commonCountingTime unit="seconds">0.974</commonCountingTime>
				<counts unit="counts">0 0 0 0 1 1 0 0 0 0 0 1 0 0 2 0 0 0 0 0 0 0 0 1 0 0 1 2 1 0 0 0 1 0 0 2 0 2 0 1 0 1 1 0 0 0 0 1 0 2 1 0 1 0 0 0 1 0 1 0 0 0 0 0 1 1 0 0 0 0 1 1 0 0 0 0 0 0 1 0 0 0 0 0 0 0 1 0 0 1 1 0 0 0 0 0 0 1 1 0 0 1 1 0 0 0 0 0 0 0 0 0 0 0 0 0 0 0 0 0 1 0 0 1 1 0 0 0 0 0 0 1 0 0 0 0 1 0 0 0 0 0 0 1 0 1 0 1 0 0 0 1 0 0 0 0 1 1 1 1 0 0 3 1 0 0 0 0 1 0 0 0 0 1 1 1 0 0 0 0 1 0 0 0 0 1 1 0 2 0 2 0 0 1 0 1 1 3 0 0 0 0 0 1 0 0 0 1 0 0 1 0 1 1 0 0 0 1 0 1 0 0 0 0 0 1 2 0 0 0 0 0 1 0 0 0 1 1 0 1 1 0 0 0 0 0 0 0 0 0 0 0 1 0 1</counts>
			</dataPoints>
		</scan>
		<scan status="Completed" appendNumber="0" scanAxis="2Theta" mode="Continuous">
			<header>
				<startTimeStamp>2024-07-03T13:20:43-04:00</startTimeStamp>
				<endTimeStamp>2024-07-03T13:50:46-04:00</endTimeStamp>
				<author>
					<name>lw627</name>
				</author>
				<source>
					<applicationSoftware version="7.1">Data Collector</applicationSoftware>
					<instrumentControlSoftware version="8.2  20201204">EMPYREAN</instrumentControlSoftware>
					<instrumentID>0000000011260721</instrumentID>
				</source>
			</header>
			<dataPoints>
				<positions axis="2Theta" unit="deg">
					<startPosition>71.6132100957499</startPosition>
					<endPosition>74.9604798669664</endPosition>
				</positions>
				<positions axis="Omega" unit="deg">
					<commonPosition>17.9974224906791</commonPosition>
				</positions>
				<positions axis="Phi" unit="deg">
					<commonPosition>2.8</commonPosition>
				</positions>
				<positions axis="Chi" unit="deg">
					<commonPosition>0</commonPosition>
				</positions>
				<positions axis="Z" unit="mm">
					<commonPosition>8.386</commonPosition>
				</positions>
				<commonCountingTime unit="seconds">0.974</commonCountingTime>
				<counts unit="counts">0 0 1 0 0 1 1 1 0 0 0 2 0 0 0 0 1 0 1 0 0 0 0 0 0 0 1 0 0 0 0 0 0 0 0 0 0 0 1 0 0 0 0 0 0 1 0 0 1 0 0 0 0 0 2 0 1 0 2 1 0 1 1 0 0 0 0 0 0 0 0 0 0 1 0 0 0 0 0 0 1 0 1 0 1 0 0 0 0 0 1 1 1 0 0 0 1 0 0 0 0 0 0 0 0 0 1 0 0 0 0 1 0 0 0 0 0 0 0 0 1 0 0 0 1 0 0 1 0 1 0 0 0 2 0 0 0 0 1 2 0 0 0 0 0 0 0 1 0 0 0 0 1 0 1 0 0 0 0 1 0 0 0 2 0 1 0 0 0 0 0 0 0 0 0 1 0 0 0 1 0 1 0 1 0 1 0 1 0 1 0 0 0 0 0 0 0 0 1 1 0 0 0 0 0 0 0 1 0 1 0 0 0 0 0 0 1 1 0 1 0 0 0 1 0 1 0 0 0 0 0 0 0 0 0 0 0 0 0 0 0 0 2 0 0 0 0 2 1 1 0 1 0 0 0</counts>
			</dataPoints>
		</scan>
		<scan status="Completed" appendNumber="0" scanAxis="2Theta" mode="Continuous">
			<header>
				<startTimeStamp>2024-07-03T13:20:43-04:00</startTimeStamp>
				<endTimeStamp>2024-07-03T13:50:46-04:00</endTimeStamp>
				<author>
					<name>lw627</name>
				</author>
				<source>
					<applicationSoftware version="7.1">Data Collector</applicationSoftware>
					<instrumentControlSoftware version="8.2  20201204">EMPYREAN</instrumentControlSoftware>
					<instrumentID>0000000011260721</instrumentID>
				</source>
			</header>
			<dataPoints>
				<positions axis="2Theta" unit="deg">
					<startPosition>71.6164926664181</startPosition>
					<endPosition>74.9637624376345</endPosition>
				</positions>
				<positions axis="Omega" unit="deg">
					<commonPosition>17.9990637760131</commonPosition>
				</positions>
				<positions axis="Phi" unit="deg">
					<commonPosition>2.8</commonPosition>
				</positions>
				<positions axis="Chi" unit="deg">
					<commonPosition>0</commonPosition>
				</positions>
				<positions axis="Z" unit="mm">
					<commonPosition>8.386</commonPosition>
				</positions>
				<commonCountingTime unit="seconds">0.974</commonCountingTime>
				<counts unit="counts">0 0 0 0 1 0 1 1 0 1 0 0 1 0 0 0 0 0 0 0 1 0 1 0 1 1 0 1 0 0 0 0 1 2 0 0 0 0 0 0 0 1 0 0 2 0 0 0 2 0 1 1 0 0 0 0 0 0 0 0 0 0 0 0 0 0 1 0 1 0 0 1 0 0 0 1 0 2 0 0 0 0 0 1 0 0 0 0 1 0 0 0 0 0 0 1 0 0 0 0 2 0 1 0 0 0 0 2 1 0 0 0 0 0 0 0 0 2 1 0 0 1 0 0 0 0 0 1 1 0 0 0 0 0 1 0 0 0 0 1 1 0 0 0 0 0 0 0 0 0 0 0 2 0 1 0 0 1 0 0 0 0 0 0 1 0 0 0 2 0 0 0 1 0 0 0 0 0 0 0 0 0 1 0 0 1 0 0 0 0 0 0 0 0 0 0 1 0 0 0 0 0 0 0 0 2 0 0 0 0 1 2 0 1 0 0 0 1 0 0 0 0 0 0 1 0 0 1 1 0 1 0 1 1 1 0 0 1 1 0 0 0 0 0 2 2 1 0 0 0 0 0 0 0 0</counts>
			</dataPoints>
		</scan>
		<scan status="Completed" appendNumber="0" scanAxis="2Theta" mode="Continuous">
			<header>
				<startTimeStamp>2024-07-03T13:20:43-04:00</startTimeStamp>
				<endTimeStamp>2024-07-03T13:50:46-04:00</endTimeStamp>
				<author>
					<name>lw627</name>
				</author>
				<source>
					<applicationSoftware version="7.1">Data Collector</applicationSoftware>
					<instrumentControlSoftware version="8.2  20201204">EMPYREAN</instrumentControlSoftware>
					<instrumentID>0000000011260721</instrumentID>
				</source>
			</header>
			<dataPoints>
				<positions axis="2Theta" unit="deg">
					<startPosition>71.6197752370862</startPosition>
					<endPosition>74.9670450083026</endPosition>
				</positions>
				<positions axis="Omega" unit="deg">
					<commonPosition>18.0007050613472</commonPosition>
				</positions>
				<positions axis="Phi" unit="deg">
					<commonPosition>2.8</commonPosition>
				</positions>
				<positions axis="Chi" unit="deg">
					<commonPosition>0</commonPosition>
				</positions>
				<positions axis="Z" unit="mm">
					<commonPosition>8.386</commonPosition>
				</positions>
				<commonCountingTime unit="seconds">0.974</commonCountingTime>
				<counts unit="counts">0 0 0 0 0 0 0 2 1 0 0 0 0 1 0 0 0 1 0 0 1 0 0 0 0 0 0 0 0 1 0 2 1 0 0 0 0 0 0 0 0 0 1 0 0 0 0 0 0 0 1 0 0 1 0 0 0 0 0 0 1 1 0 1 0 0 1 0 1 0 0 0 0 1 1 1 0 0 0 0 1 0 0 1 1 0 1 0 0 0 0 0 0 1 1 0 1 0 0 0 0 0 0 0 1 0 1 0 0 1 0 0 0 0 2 0 0 0 0 0 0 0 0 0 0 0 1 0 0 0 0 0 0 0 1 1 0 0 0 3 0 0 0 0 0 1 1 0 0 0 0 1 0 0 0 1 0 1 0 0 1 0 0 0 0 0 1 0 0 0 0 1 0 0 0 0 0 0 0 0 1 0 0 1 0 2 0 0 0 0 0 0 1 1 1 0 0 0 3 0 0 0 0 0 1 2 0 0 1 0 0 0 0 0 0 1 3 1 0 0 0 0 0 1 0 0 0 1 0 0 1 1 0 0 0 0 1 0 0 0 1 0 0 0 0 0 0 0 0 1 0 1 0 0 0</counts>
			</dataPoints>
		</scan>
		<scan status="Completed" appendNumber="0" scanAxis="2Theta" mode="Continuous">
			<header>
				<startTimeStamp>2024-07-03T13:20:43-04:00</startTimeStamp>
				<endTimeStamp>2024-07-03T13:50:46-04:00</endTimeStamp>
				<author>
					<name>lw627</name>
				</author>
				<source>
					<applicationSoftware version="7.1">Data Collector</applicationSoftware>
					<instrumentControlSoftware version="8.2  20201204">EMPYREAN</instrumentControlSoftware>
					<instrumentID>0000000011260721</instrumentID>
				</source>
			</header>
			<dataPoints>
				<positions axis="2Theta" unit="deg">
					<startPosition>71.6230578077543</startPosition>
					<endPosition>74.9703275789708</endPosition>
				</positions>
				<positions axis="Omega" unit="deg">
					<commonPosition>18.0023463466813</commonPosition>
				</positions>
				<positions axis="Phi" unit="deg">
					<commonPosition>2.8</commonPosition>
				</positions>
				<positions axis="Chi" unit="deg">
					<commonPosition>0</commonPosition>
				</positions>
				<positions axis="Z" unit="mm">
					<commonPosition>8.386</commonPosition>
				</positions>
				<commonCountingTime unit="seconds">0.974</commonCountingTime>
				<counts unit="counts">0 2 1 0 1 0 0 0 1 0 0 0 0 0 1 0 0 1 0 0 0 1 0 0 0 0 0 0 0 0 0 1 0 0 0 0 0 2 1 0 0 1 1 0 1 0 1 1 0 0 0 0 1 0 0 0 0 0 0 0 0 0 0 1 0 1 1 0 0 0 0 0 0 1 1 0 1 1 1 0 0 0 0 0 1 0 0 0 0 0 1 1 0 0 1 0 1 0 0 1 0 0 0 0 2 0 0 1 1 1 1 0 0 1 0 0 2 0 2 0 2 0 1 0 0 1 0 1 1 0 0 0 0 0 1 0 1 1 0 0 0 1 0 1 0 0 0 0 0 1 0 0 0 0 0 0 0 0 0 1 0 0 0 0 0 0 1 0 0 0 0 0 0 0 0 0 0 0 0 0 0 3 0 1 1 0 0 0 1 0 0 0 0 0 0 0 0 0 0 0 0 0 0 3 0 0 0 0 0 0 0 0 0 1 0 0 1 0 1 0 0 0 0 0 0 1 0 0 0 0 1 0 2 1 0 0 1 0 0 1 2 0 0 0 1 2 0 0 0 0 0 2 0 0 0</counts>
[...]
					<commonPosition>0</commonPosition>
				</positions>
				<positions axis="Z" unit="mm">
					<commonPosition>8.386</commonPosition>
				</positions>
				<commonCountingTime unit="seconds">0.974</commonCountingTime>
				<counts unit="counts">1 1 0 1 0 0 1 1 0 0 0 0 0 0 0 0 0 0 0 0 0 1 0 0 1 0 1 0 1 0 0 1 0 0 0 0 0 0 0 0 0 0 0 1 1 0 0 0 0 1 0 0 0 0 0 0 0 0 1 1 0 1 0 1 0 0 0 0 0 0 0 0 0 0 0 0 0 0 0 0 0 0 0 0 0 0 0 0 0 1 0 0 0 0 0 0 0 0 0 1 0 0 0 0 0 0 0 0 0 0 0 1 0 0 0 0 0 0 0 0 0 1 0 0 1 1 0 0 0 0 0 0 2 0 0 1 1 0 2 1 1 1 1 0 0 0 0 0 1 0 0 0 0 0 0 0 0 0 1 0 0 0 0 0 0 0 0 1 0 0 0 0 0 0 0 0 0 0 0 1 1 1 0 0 1 0 0 0 0 0 1 0 0 0 1 1 0 0 0 1 0 0 0 0 0 0 1 0 0 0 0 0 0 0 0 0 0 0 0 0 0 0 0 0 0 0 1 0 0 0 0 0 0 0 0 0 0 0 0 1 0 1 0 0 0 1 1 1 0 0 0 3 0 0 0</counts>
			</dataPoints>
		</scan>
		<scan status="Completed" appendNumber="0" scanAxis="2Theta" mode="Continuous">
			<header>
				<startTimeStamp>2024-07-03T13:20:43-04:00</startTimeStamp>
				<endTimeStamp>2024-07-03T13:50:46-04:00</endTimeStamp>
				<author>
					<name>lw627</name>
				</author>
				<source>
					<applicationSoftware version="7.1">Data Collector</applicationSoftware>
					<instrumentControlSoftware version="8.2  20201204">EMPYREAN</instrumentControlSoftware>
					<instrumentID>0000000011260721</instrumentID>
				</source>
			</header>
			<dataPoints>
				<positions axis="2Theta" unit="deg">
					<startPosition>77.5185547277105</startPosition>
					<endPosition>80.865824498927</endPosition>
				</positions>
				<positions axis="Omega" unit="deg">
					<commonPosition>20.9500948066594</commonPosition>
				</positions>
				<positions axis="Phi" unit="deg">
					<commonPosition>2.8</commonPosition>
				</positions>
				<positions axis="Chi" unit="deg">
					<commonPosition>0</commonPosition>
				</positions>
				<positions axis="Z" unit="mm">
					<commonPosition>8.386</commonPosition>
				</positions>
				<commonCountingTime unit="seconds">0.974</commonCountingTime>
				<counts unit="counts">2 0 0 0 0 0 0 0 0 1 0 0 2 0 0 1 0 1 0 0 0 0 0 1 0 2 1 1 0 1 0 0 0 0 0 0 1 0 0 0 0 1 0 0 1 1 0 0 0 1 0 0 1 0 1 0 0 0 1 0 0 3 0 1 2 1 0 0 0 0 0 3 0 0 0 1 0 0 1 0 0 0 0 0 0 0 0 0 0 1 0 0 0 1 0 0 0 1 0 1 0 0 0 0 0 0 0 0 0 0 0 0 0 0 2 0 0 0 1 0 0 0 0 1 0 0 0 0 0 0 0 1 0 0 1 0 0 0 0 0 0 0 0 0 0 1 0 1 0 1 0 0 0 1 0 0 0 0 1 0 0 1 0 0 0 0 0 1 0 0 0 0 0 0 0 0 0 0 0 0 0 0 0 0 1 0 0 0 1 0 0 0 0 0 0 0 1 0 0 1 0 0 0 0 1 0 0 0 1 0 0 0 0 0 0 0 0 0 0 0 1 0 0 0 0 0 0 0 0 0 0 3 0 1 0 0 2 0 0 1 0 0 0 0 1 0 0 0 0 0 0 0 0 0 0</counts>
			</dataPoints>
		</scan>
		<scan status="Completed" appendNumber="0" scanAxis="2Theta" mode="Continuous">
			<header>
				<startTimeStamp>2024-07-03T13:20:43-04:00</startTimeStamp>
				<endTimeStamp>2024-07-03T13:50:46-04:00</endTimeStamp>
				<author>
					<name>lw627</name>
				</author>
				<source>
					<applicationSoftware version="7.1">Data Collector</applicationSoftware>
					<instrumentControlSoftware version="8.2  20201204">EMPYREAN</instrumentControlSoftware>
					<instrumentID>0000000011260721</instrumentID>
				</source>
			</header>
			<dataPoints>
				<positions axis="2Theta" unit="deg">
					<startPosition>77.5218372983786</startPosition>
					<endPosition>80.8691070695951</endPosition>
				</positions>
				<positions axis="Omega" unit="deg">
					<commonPosition>20.9517360919934</commonPosition>
				</positions>
				<positions axis="Phi" unit="deg">
					<commonPosition>2.8</commonPosition>
				</positions>
				<positions axis="Chi" unit="deg">
					<commonPosition>0</commonPosition>
				</positions>
				<positions axis="Z" unit="mm">
					<commonPosition>8.386</commonPosition>
				</positions>
				<commonCountingTime unit="seconds">0.974</commonCountingTime>
				<counts unit="counts">2 0 1 0 0 0 0 0 0 1 1 1 0 1 1 1 0 0 0 0 0 1 0 0 0 0 1 1 0 0 0 0 1 0 1 0 0 0 2 1 1 0 0 0 0 0 0 0 0 0 0 0 0 1 1 1 0 0 0 0 0 0 1 0 0 1 0 2 1 0 0 0 1 0 1 1 0 0 0 1 1 0 1 1 0 1 0 1 0 0 1 1 0 0 0 0 0 1 0 0 0 0 0 0 0 0 0 1 0 0 0 2 0 1 1 0 0 0 0 0 0 1 1 0 2 0 0 1 0 0 0 1 0 0 0 0 0 0 0 0 0 1 0 0 0 0 0 0 0 0 0 0 0 0 0 0 0 1 0 0 0 0 0 1 0 0 0 0 0 0 0 0 0 0 0 1 0 0 1 2 1 0 1 0 0 0 0 3 0 1 1 0 1 0 1 0 0 0 0 0 0 0 0 0 0 0 0 0 0 0 0 0 0 0 0 0 0 1 0 0 1 0 1 0 0 0 1 0 1 0 0 0 0 1 0 1 2 0 0 0 1 0 0 1 0 0 0 0 0 0 0 0 0 0 0</counts>
			</dataPoints>
		</scan>
		<scan status="Completed" appendNumber="0" scanAxis="2Theta" mode="Continuous">
			<header>
				<startTimeStamp>2024-07-03T13:20:43-04:00</startTimeStamp>
				<endTimeStamp>2024-07-03T13:50:46-04:00</endTimeStamp>
				<author>
					<name>lw627</name>
				</author>
				<source>
					<applicationSoftware version="7.1">Data Collector</applicationSoftware>
					<instrumentControlSoftware version="8.2  20201204">EMPYREAN</instrumentControlSoftware>
					<instrumentID>0000000011260721</instrumentID>
				</source>
			</header>
			<dataPoints>
				<positions axis="2Theta" unit="deg">
					<startPosition>77.5251198690467</startPosition>
					<endPosition>80.8723896402632</endPosition>
				</positions>
				<positions axis="Omega" unit="deg">
					<commonPosition>20.9533773773275</commonPosition>
				</positions>
				<positions axis="Phi" unit="deg">
					<commonPosition>2.8</commonPosition>
				</positions>
				<positions axis="Chi" unit="deg">
					<commonPosition>0</commonPosition>
				</positions>
				<positions axis="Z" unit="mm">
					<commonPosition>8.386</commonPosition>
				</positions>
				<commonCountingTime unit="seconds">0.974</commonCountingTime>
				<counts unit="counts">0 1 0 0 0 0 1 3 1 0 0 0 0 0 0 1 0 0 0 0 0 1 0 0 0 0 0 0 0 0 0 0 0 1 0 0 0 0 0 0 0 0 0 0 0 0 0 0 0 0 0 0 0 0 0 2 0 1 0 0 0 1 0 0 0 2 1 0 0 0 0 0 0 1 0 0 0 0 0 0 0 0 0 0 0 0 2 0 0 0 1 2 0 0 0 0 0 0 1 0 0 0 0 0 0 1 1 0 0 1 1 0 0 1 0 0 0 0 0 1 0 0 0 0 0 0 0 0 0 0 0 0 0 0 0 0 0 0 0 0 0 0 0 0 0 1 1 0 1 0 0 0 0 1 1 0 0 0 0 0 0 0 0 0 0 0 0 0 0 0 0 0 0 0 0 0 0 0 1 0 0 0 0 1 0 0 0 0 0 0 0 0 0 0 0 0 0 0 0 0 0 0 1 0 0 0 0 0 0 0 0 0 0 0 0 0 0 1 0 1 0 0 1 0 0 0 1 0 0 0 0 0 0 0 0 1 0 0 0 0 0 0 0 1 0 0 0 0 0 0 0 1 0 1 0</counts>
			</dataPoints>
		</scan>
		<scan status="Completed" appendNumber="0" scanAxis="2Theta" mode="Continuous">
			<header>
				<startTimeStamp>2024-07-03T13:20:43-04:00</startTimeStamp>
				<endTimeStamp>2024-07-03T13:50:46-04:00</endTimeStamp>
				<author>
					<name>lw627</name>
				</author>
				<source>
					<applicationSoftware version="7.1">Data Collector</applicationSoftware>
					<instrumentControlSoftware version="8.2  20201204">EMPYREAN</instrumentControlSoftware>
					<instrumentID>0000000011260721</instrumentID>
				</source>
			</header>
			<dataPoints>
				<positions axis="2Theta" unit="deg">
					<startPosition>77.5284024397149</startPosition>
					<endPosition>80.8756722109314</endPosition>
				</positions>
				<positions axis="Omega" unit="deg">
					<commonPosition>20.9550186626616</commonPosition>
				</positions>
				<positions axis="Phi" unit="deg">
					<commonPosition>2.8</commonPosition>
				</positions>
				<positions axis="Chi" unit="deg">
					<commonPosition>0</commonPosition>
				</positions>
				<positions axis="Z" unit="mm">
					<commonPosition>8.386</commonPosition>
				</positions>
				<commonCountingTime unit="seconds">0.974</commonCountingTime>
				<counts unit="counts">0 0 0 0 0 0 1 0 2 0 0 0 0 0 0 0 1 0 0 0 2 0 0 1 0 0 1 0 1 1 0 1 0 0 0 0 0 1 0 0 0 0 0 1 0 0 0 0 0 0 0 0 1 1 0 0 1 0 0 0 0 0 0 0 0 1 0 0 0 1 0 0 0 0 1 0 0 0 0 1 1 0 0 0 1 0 0 0 1 1 0 1 0 0 0 0 0 2 1 1 0 0 0 0 1 0 1 0 0 1 1 1 0 2 1 0 1 0 0 0 0 0 0 0 0 1 0 0 0 0 0 0 0 0 0 0 0 0 0 0 0 1 0 0 0 0 0 1 0 0 0 0 0 1 0 0 0 0 1 1 0 0 0 1 2 0 0 0 0 1 0 0 0 0 0 0 0 0 1 0 0 0 0 0 0 1 0 0 0 0 1 0 1 0 0 0 0 0 0 0 0 0 0 0 0 0 0 0 0 0 0 0 1 0 0 1 0 0 0 0 0 0 1 1 0 0 1 0 0 0 1 0 0 0 0 0 0 0 0 0 2 0 1 1 0 1 1 0 0 1 0 0 0 0 0</counts>
			</dataPoints>
		</scan>
		<scan status="Completed" appendNumber="0" scanAxis="2Theta" mode="Continuous">
			<header>
				<startTimeStamp>2024-07-03T13:20:43-04:00</startTimeStamp>
				<endTimeStamp>2024-07-03T13:50:46-04:00</endTimeStamp>
				<author>
					<name>lw627</name>
				</author>
				<source>
					<applicationSoftware version="7.1">Data Collector</applicationSoftware>
					<instrumentControlSoftware version="8.2  20201204">EMPYREAN</instrumentControlSoftware>
					<instrumentID>0000000011260721</instrumentID>
				</source>
			</header>
			<dataPoints>
				<positions axis="2Theta" unit="deg">
					<startPosition>77.531685010383</startPosition>
					<endPosition>80.8789547815995</endPosition>
				</positions>
				<positions axis="Omega" unit="deg">
					<commonPosition>20.9566599479956</commonPosition>
				</positions>
				<positions axis="Phi" unit="deg">
					<commonPosition>2.8</commonPosition>
				</positions>
				<positions axis="Chi" unit="deg">
					<commonPosition>0</commonPosition>
				</positions>
				<positions axis="Z" unit="mm">
					<commonPosition>8.386</commonPosition>
				</positions>
				<commonCountingTime unit="seconds">0.974</commonCountingTime>
				<counts unit="counts">0 0 1 1 1 0 0 0 1 0 1 0 0 0 0 1 1 0 0 1 0 1 0 1 0 0 0 0 0 1 0 0 0 0 0 2 0 1 1 1 0 1 0 0 0 1 1 0 0 0 1 1 1 0 1 0 0 1 0 0 1 0 1 1 0 0 0 0 0 0 1 0 0 0 2 0 2 0 0 0 0 0 0 2 0 0 0 0 0 0 0 0 0 0 0 0 0 0 0 0 0 1 0 0 0 0 0 0 0 0 1 0 0 0 0 0 2 0 0 0 2 0 0 0 0 0 0 0 0 0 0 0 0 0 1 0 0 0 2 0 0 0 2 0 0 1 1 0 0 1 0 0 0 0 1 0 0 1 0 0 1 0 0 0 0 2 0 0 0 0 0 0 0 1 0 0 1 0 0 0 1 0 0 0 0 0 0 0 0 1 0 0 0 0 0 0 0 0 0 0 1 0 2 0 0 1 1 1 0 0 0 0 0 1 2 1 0 0 0 0 1 1 0 0 0 0 0 0 0 0 0 1 0 0 1 2 1 0 0 0 0 0 1 1 0 1 0 1 1 0 0 0 0 1 0</counts>
			</dataPoints>
		</scan>
		<scan status="Completed" appendNumber="0" scanAxis="2Theta" mode="Continuous">
			<header>
				<startTimeStamp>2024-07-03T13:20:43-04:00</startTimeStamp>
				<endTimeStamp>2024-07-03T13:50:46-04:00</endTimeStamp>
				<author>
					<name>lw627</name>
				</author>
				<source>
					<applicationSoftware version="7.1">Data Collector</applicationSoftware>
					<instrumentControlSoftware version="8.2  20201204">EMPYREAN</instrumentControlSoftware>
					<instrumentID>0000000011260721</instrumentID>
				</source>
			</header>
			<dataPoints>
				<positions axis="2Theta" unit="deg">
					<startPosition>77.5349675810511</startPosition>
					<endPosition>80.8822373522676</endPosition>
				</positions>
				<positions axis="Omega" unit="deg">
					<commonPosition>20.9583012333297</commonPosition>
				</positions>
				<positions axis="Phi" unit="deg">
					<commonPosition>2.8</commonPosition>
				</positions>
				<positions axis="Chi" unit="deg">
					<commonPosition>0</commonPosition>
				</positions>
				<positions axis="Z" unit="mm">
					<commonPosition>8.386</commonPosition>
				</positions>
				<commonCountingTime unit="seconds">0.974</commonCountingTime>
				<counts unit="counts">0 0 0 0 2 0 0 0 0 0 0 0 1 0 0 1 1 0 1 1 0 1 0 0 0 0 0 0 0 1 0 0 1 1 0 0 0 1 0 1 1 0 1 0 0 0 0 0 0 1 0 0 0 3 0 0 0 0 0 0 1 2 0 0 0 0 1 0 0 0 0 0 0 0 0 1 1 1 2 1 0 0 0 0 1 0 0 1 0 1 1 0 0 1 0 0 0 0 0 0 1 1 2 0 0 1 1 0 1 0 1 1 0 0 0 0 0 0 0 0 0 0 1 1 0 0 0 0 1 0 1 1 0 1 0 0 0 0 1 0 0 0 0 0 0 0 0 0 0 0 0 0 0 0 0 0 0 0 1 0 0 0 0 0 0 0 1 0 0 1 0 0 0 0 0 1 0 0 0 0 0 1 0 2 0 0 0 0 0 0 0 0 0 0 1 0 0 0 0 0 0 0 0 0 2 0 0 1 0 0 0 1 0 0 0 0 0 1 0 0 0 0 0 0 0 0 0 0 0 0 0 0 0 0 1 0 0 0 1 0 0 1 0 0 0 0 1 0 1 0 0 0 1 0 1</counts>
			</dataPoints>
		</scan>
		<scan status="Completed" appendNumber="0" scanAxis="2Theta" mode="Continuous">
			<header>
				<startTimeStamp>2024-07-03T13:20:43-04:00</startTimeStamp>
				<endTimeStamp>2024-07-03T13:50:46-04:00</endTimeStamp>
				<author>
					<name>lw627</name>
				</author>
				<source>
					<applicationSoftware version="7.1">Data Collector</applicationSoftware>
					<instrumentControlSoftware version="8.2  20201204">EMPYREAN</instrumentControlSoftware>
					<instrumentID>0000000011260721</instrumentID>
				</source>
			</header>
			<dataPoints>
				<positions axis="2Theta" unit="deg">
					<startPosition>77.5382501517193</startPosition>
					<endPosition>80.8855199229357</endPosition>
				</positions>
				<positions axis="Omega" unit="deg">
					<commonPosition>20.9599425186637</commonPosition>
				</positions>
				<positions axis="Phi" unit="deg">
					<commonPosition>2.8</commonPosition>
				</positions>
				<positions axis="Chi" unit="deg">
					<commonPosition>0</commonPosition>
				</positions>
				<positions axis="Z" unit="mm">
					<commonPosition>8.386</commonPosition>
				</positions>
				<commonCountingTime unit="seconds">0.974</commonCountingTime>
				<counts unit="counts">0 0 0 0 2 2 1 0 0 0 1 0 0 0 0 0 0 1 0 0 0 1 1 0 0 1 0 0 2 1 1 0 3 1 0 0 0 0 1 2 0 0 0 0 1 2 0 0 0 0 0 0 0 0 0 0 1 0 0 0 1 0 0 0 0 1 2 2 0 0 1 0 0 0 0 0 1 1 0 0 1 0 0 0 0 0 0 0 0 0 0 1 0 0 1 0 0 1 0 0 0 1 0 0 1 0 0 0 1 1 1 0 0 0 1 1 0 0 0 0 0 0 0 1 0 0 0 0 0 0 0 0 0 0 0 0 0 0 0 0 0 0 0 0 1 1 0 0 0 0 0 0 2 1 0 0 0 0 0 0 1 0 0 1 0 0 0 0 0 0 0 0 0 1 1 0 1 1 0 0 2 0 0 0 0 0 0 0 1 0 0 0 0 0 0 0 0 0 0 0 0 0 0 0 0 0 0 0 1 1 0 0 0 0 0 0 1 0 0 1 0 1 0 0 0 1 0 0 0 0 0 1 0 0 0 0 1 0 1 0 1 0 0 0 0 0 1 0 0 0 0 0 1 0 0</counts>
			</dataPoints>
		</scan>
		<scan status="Completed" appendNumber="0" scanAxis="2Theta" mode="Continuous">
			<header>
				<startTimeStamp>2024-07-03T13:20:43-04:00</startTimeStamp>
				<endTimeStamp>2024-07-03T13:50:46-04:00</endTimeStamp>
				<author>
					<name>lw627</name>
				</author>
				<source>
					<applicationSoftware version="7.1">Data Collector</applicationSoftware>
					<instrumentControlSoftware version="8.2  20201204">EMPYREAN</instrumentControlSoftware>
					<instrumentID>0000000011260721</instrumentID>
				</source>
			</header>
			<dataPoints>
				<positions axis="2Theta" unit="deg">
					<startPosition>77.5415327223874</startPosition>
					<endPosition>80.8888024936039</endPosition>
				</positions>
				<positions axis="Omega" unit="deg">
					<commonPosition>20.9615838039978</commonPosition>
				</positions>
				<positions axis="Phi" unit="deg">
					<commonPosition>2.8</commonPosition>
				</positions>
				<positions axis="Chi" unit="deg">
					<commonPosition>0</commonPosition>
				</positions>
				<positions axis="Z" unit="mm">
					<commonPosition>8.386</commonPosition>
				</positions>
				<commonCountingTime unit="seconds">0.974</commonCountingTime>
				<counts unit="counts">0 0 1 0 0 0 1 0 0 0 0 1 0 0 0 0 0 0 1 0 0 0 0 0 0 0 0 0 0 0 0 0 0 1 1 0 0 0 0 0 0 1 2 0 0 1 0 0 0 0 0 0 0 0 0 4 1 0 0 0 2 0 1 0 0 0 0 1 0 1 1 1 0 0 0 0 0 0 1 1 1 0 1 0 0 0 0 0 1 0 0 0 0 2 0 0 0 0 0 0 1 0 0 1 0 0 0 0 1 0 0 0 0 0 0 0 0 1 1 0 0 1 0 0 0 0 1 0 0 0 0 1 0 1 0 0 0 0 0 0 0 1 0 0 0 0 0 0 0 0 0 0 0 1 0 0 1 0 1 0 0 0 0 1 0 0 1 0 1 0 1 0 1 0 0 1 0 0 0 0 0 1 1 0 2 0 0 0 1 0 1 1 0 0 0 0 0 2 0 1 0 0 0 0 0 1 0 0 0 0 1 0 0 0 1 1 0 0 0 1 0 0 0 0 0 0 1 0 0 0 0 0 0 0 0 2 0 0 0 0 0 1 0 0 0 1 0 0 1 1 0 0 0 1 0</counts>
			</dataPoints>
		</scan>
		<scan status="Completed" appendNumber="0" scanAxis="2Theta" mode="Continuous">
			<header>
				<startTimeStamp>2024-07-03T13:20:43-04:00</startTimeStamp>
				<endTimeStamp>2024-07-03T13:50:46-04:00</endTimeStamp>
				<author>
					<name>lw627</name>
				</author>
				<source>
					<applicationSoftware version="7.1">Data Collector</applicationSoftware>
					<instrumentControlSoftware version="8.2  20201204">EMPYREAN</instrumentControlSoftware>
					<instrumentID>0000000011260721</instrumentID>
				</source>
			</header>
			<dataPoints>
				<positions axis="2Theta" unit="deg">
					<startPosition>77.5448152930555</startPosition>
					<endPosition>80.892085064272</endPosition>
				</positions>
				<positions axis="Omega" unit="deg">
					<commonPosition>20.9632250893319</commonPosition>
				</positions>
				<positions axis="Phi" unit="deg">
					<commonPosition>2.8</commonPosition>
				</positions>
				<positions axis="Chi" unit="deg">
					<commonPosition>0</commonPosition>
				</positions>
				<positions axis="Z" unit="mm">
					<commonPosition>8.386</commonPosition>
				</positions>
				<commonCountingTime unit="seconds">0.974</commonCountingTime>
				<counts unit="counts">0 0 0 0 0 0 0 2 0 0 0 0 0 0 0 0 0 0 0 0 1 1 1 1 0 1 1 0 1 0 2 0 0 1 1 0 0 1 0 0 0 0 0 1 0 1 2 0 0 0 0 0 0 0 0 0 0 0 1 0 2 1 0 0 0 0 0 0 1 0 0 0 0 2 0 0 1 0 0 0 1 0 0 0 0 0 0 0 0 0 0 0 0 0 0 0 0 0 0 0 0 0 1 1 0 1 0 0 0 2 1 0 0 0 1 0 0 0 2 0 0 0 0 1 0 0 1 1 0 1 1 1 0 2 0 0 1 0 1 1 1 0 0 0 0 0 1 0 1 0 0 0 0 0 0 0 1 0 0 0 1 0 0 0 0 0 0 0 0 2 2 0 0 0 0 0 0 1 0 0 1 0 0 0 2 0 0 0 0 0 1 0 0 0 0 0 0 0 0 0 0 0 0 0 0 0 0 1 0 0 0 1 0 1 0 0 0 1 1 0 0 0 0 0 1 0 0 1 0 1 0 0 0 0 1 0 0 0 0 2 0 1 0 0 0 0 1 0 0 0 0 0 2 0 0</counts>
			</dataPoints>
		</scan>
		<scan status="Completed" appendNumber="0" scanAxis="2Theta" mode="Continuous">
			<header>
				<startTimeStamp>2024-07-03T13:20:43-04:00</startTimeStamp>
				<endTimeStamp>2024-07-03T13:50:46-04:00</endTimeStamp>
				<author>
					<name>lw627</name>
				</author>
				<source>
					<applicationSoftware version="7.1">Data Collector</applicationSoftware>
					<instrumentControlSoftware version="8.2  20201204">EMPYREAN</instrumentControlSoftware>
					<instrumentID>0000000011260721</instrumentID>
				</source>
			</header>
			<dataPoints>
				<positions axis="2Theta" unit="deg">
					<startPosition>77.5480978637236</startPosition>
					<endPosition>80.8953676349401</endPosition>
				</positions>
				<positions axis="Omega" unit="deg">
					<commonPosition>20.9648663746659</commonPosition>
				</positions>
				<positions axis="Phi" unit="deg">
					<commonPosition>2.8</commonPosition>
				</positions>
				<positions axis="Chi" unit="deg">
					<commonPosition>0</commonPosition>
				</positions>
				<positions axis="Z" unit="mm">
					<commonPosition>8.386</commonPosition>
				</positions>
				<commonCountingTime unit="seconds">0.974</commonCountingTime>
				<counts unit="counts">0 1 0 0 0 0 0 0 1 1 1 0 0 0 0 0 0 0 0 1 1 0 1 0 0 0 0 1 0 1 0 0 0 0 0 2 1 1 0 1 0 0 2 0 1 0 0 0 0 1 0 1 0 1 0 0 0 0 0 2 0 1 0 1 0 1 0 1 0 1 1 0 0 0 0 0 0 0 0 1 0 0 0 0 0 0 0 0 0 0 0 0 1 1 0 0 0 0 1 0 0 0 0 0 0 0 0 0 0 0 0 0 2 1 0 1 0 0 0 0 0 0 0 0 0 0 1 1 0 0 0 0 0 0 1 0 0 0 0 1 0 1 0 0 0 0 0 0 0 0 0 0 0 0 1 0 2 0 0 0 0 1 1 0 0 0 0 0 0 0 0 0 0 0 0 0 0 0 0 0 0 1 0 1 0 0 0 0 1 0 0 0 0 0 1 0 1 0 0 0 1 0 0 0 0 0 0 0 0 1 0 0 0 0 0 0 1 0 0 0 1 1 1 0 0 0 1 0 0 0 0 0 0 0 1 2 0 0 0 1 0 1 0 0 0 0 1 0 1 1 0 0 0 1 1</counts>
			</dataPoints>
		</scan>
		<scan status="Completed" appendNumber="0" scanAxis="2Theta" mode="Continuous">
			<header>
				<startTimeStamp>2024-07-03T13:20:43-04:00</startTimeStamp>
				<endTimeStamp>2024-07-03T13:50:46-04:00</endTimeStamp>
				<author>
					<name>lw627</name>
				</author>
				<source>
					<applicationSoftware version="7.1">Data Collector</applicationSoftware>
					<instrumentControlSoftware version="8.2  20201204">EMPYREAN</instrumentControlSoftware>
					<instrumentID>0000000011260721</instrumentID>
				</source>
			</header>
			<dataPoints>
				<positions axis="2Theta" unit="deg">
					<startPosition>77.5513804343918</startPosition>
					<endPosition>80.8986502056082</endPosition>
				</positions>
				<positions axis="Omega" unit="deg">
					<commonPosition>20.96650766</commonPosition>
				</positions>
				<positions axis="Phi" unit="deg">
					<commonPosition>2.8</commonPosition>
				</positions>
				<positions axis="Chi" unit="deg">
					<commonPosition>0</commonPosition>
				</positions>
				<positions axis="Z" unit="mm">
					<commonPosition>8.386</commonPosition>
				</positions>
				<commonCountingTime unit="seconds">0.974</commonCountingTime>
				<counts unit="counts">0 0 1 1 2 2 0 1 1 0 0 1 0 1 0 2 0 0 1 0 0 0 0 1 0 3 0 1 0 1 0 1 1 0 1 2 0 0 1 0 1 1 1 0 0 0 0 0 0 0 1 0 0 1 0 0 0 0 1 0 0 1 0 1 1 0 1 0 0 0 0 0 0 0 1 0 1 1 0 0 0 0 0 0 0 1 0 0 0 0 0 0 0 0 1 0 0 0 1 0 0 0 0 0 0 0 0 0 0 0 0 1 2 0 1 1 0 0 1 0 0 0 0 0 0 0 0 0 1 1 0 1 0 0 0 1 1 1 1 0 0 1 0 0 1 1 0 0 1 0 1 0 0 0 0 0 0 1 1 0 0 0 1 0 0 0 2 0 0 0 0 0 0 0 0 0 1 0 0 0 0 0 0 0 1 0 0 0 0 0 0 0 0 0 0 0 0 0 0 0 0 2 0 0 0 1 0 0 0 0 1 0 0 1 0 0 0 1 0 1 0 0 0 1 0 1 0 0 0 0 0 0 0 0 0 0 0 0 0 0 0 0 1 0 0 0 0 0 0 0 0 1 1 0 0</counts>
			</dataPoints>
		</scan>
	</xrdMeasurement>
</xrdMeasurements>