File: data/XRD_RSM/YG059/YG059 phi-180 STO 103 RSM slow 3 degree_1.xrdml
<?xml version="1.0" encoding="utf-8"?>
<xrdMeasurements xmlns="http://www.xrdml.com/XRDMeasurement/2.2" xmlns:xsi="http://www.w3.org/2001/XMLSchema-instance" xsi:schemaLocation="http://www.xrdml.com/XRDMeasurement/2.2 http://www.xrdml.com/XRDMeasurement/2.2/XRDMeasurement.xsd" status="Completed">
	<comment>
		<entry>Configuration=3-axes Cradle_Reflection, Owner=lw627, Creation date=9/2/2021 3:55:24 PM</entry>
		<entry>Goniometer=Theta/Theta; Minimum step size 2Theta:0.0001; Minimum step size Omega:0.0001</entry>
		<entry>Sample stage=Chi-Phi-z stage 240 mm (reflection); Minimum step size Phi:0.01; Minimum step size Chi:0.01; Minimum step size Z:0.001</entry>
		<entry>Diffractometer system=EMPYREAN</entry>
		<entry>Measurement program=C:\PANalytical\Data Collector\Programs\Liyan Wu\Film programs\RSM slow 3 degree.xrdmp, Identifier={0351664C-55A7-43E7-B72A-7307F4B26703}</entry>
	</comment>
	<sample type="To be analyzed">
		<id/>
		<name/>
		<preparedBy/>
	</sample>
	<xrdMeasurement status="Completed" measurementType="Area measurement" measurementStepAxis="Omega-2Theta" sampleMode="Reflection">
		<comment>
			<entry>PHD Lower Level = 4.02 (keV), PHD Upper Level = 11.27 (keV)</entry>
		</comment>
		<usedWavelength intended="K-Alpha 1">
			<kAlpha1 unit="Angstrom">1.5405980</kAlpha1>
			<kAlpha2 unit="Angstrom">1.5444260</kAlpha2>
			<kBeta unit="Angstrom">1.3922500</kBeta>
			<ratioKAlpha2KAlpha1>0</ratioKAlpha2KAlpha1>
		</usedWavelength>
		<incidentBeamPath>
			<radius unit="mm">240.00</radius>
			<xRayTube id="1010048" name="Empyrean Cu LFF HR (9430 033 7310x) DK432574">
				<tension unit="kV">45.0</tension>
				<current unit="mA">40.0</current>
				<anodeMaterial>Cu</anodeMaterial>
				<focus type="Line">
					<length unit="mm">12.0</length>
					<width unit="mm">0.4</width>
					<takeOffAngle unit="deg">4.4</takeOffAngle>
				</focus>
			</xRayTube>
			<xRayMirror xsi:type="xRayMirrorType" id="27080001" name="Inc. Beam Cu W/Si (hybrid MPD)" hybrid="true">
				<crystal type="Graded" shape="Parabolic">W/Si</crystal>
				<acceptanceAngle unit="deg">0.800</acceptanceAngle>
				<length unit="mm">55.3</length>
			</xRayMirror>
			<monochromator xsi:type="monochromatorType" id="23090002" name="Hybrid monochr. 2xGe220 Cu asym." hybrid="true">
				<crystal type="Asymmetric" shape="Flat">Ge</crystal>
				<numberOfReflections>2</numberOfReflections>
				<hkl>
					<h>2</h>
					<k>2</k>
					<l>0</l>
				</hkl>
			</monochromator>
			<divergenceSlit xsi:type="fixedDivergenceSlitType" id="22010005" name="Fixed slit 1/4°">
				<distanceToSample unit="mm">179.30</distanceToSample>
				<height unit="mm">0.38</height>
			</divergenceSlit>
		</incidentBeamPath>
		<diffractedBeamPath>
			<radius unit="mm">240.00</radius>
			<antiScatterSlit xsi:type="fixedAntiScatterSlitType" id="22060009" name="Programmable anti-scatter slit">
				<angle unit="deg">4</angle>
			</antiScatterSlit>
			<detector xsi:type="areaDetectorType" id="7010020" name="PIXcel3D-Medipix3 1x1 detector">
				<phd unit="%">
					<lowerLevel>25</lowerLevel>
					<upperLevel>70</upperLevel>
				</phd>
				<mode>Scanning snapshot equatorial</mode>
				<activeChannelsEquatorial>255</activeChannelsEquatorial>
				<activeChannelsAxial>255</activeChannelsAxial>
				<pitchEquatorial unit="mm">0.05500</pitchEquatorial>
				<pitchAxial unit="mm">0.05500</pitchAxial>
				<readOutPeriod unit="seconds">0.980</readOutPeriod>
			</detector>
		</diffractedBeamPath>
		<scan status="Completed" appendNumber="0" scanAxis="2Theta" mode="Continuous">
			<header>
				<startTimeStamp>2024-07-03T14:43:28-04:00</startTimeStamp>
				<endTimeStamp>2024-07-03T15:13:30-04:00</endTimeStamp>
				<author>
					<name>lw627</name>
				</author>
				<source>
					<applicationSoftware version="7.1">Data Collector</applicationSoftware>
					<instrumentControlSoftware version="8.2  20201204">EMPYREAN</instrumentControlSoftware>
					<instrumentID>0000000011260721</instrumentID>
				</source>
			</header>
			<dataPoints>
				<positions axis="2Theta" unit="deg">
					<startPosition>71.3954063943918</startPosition>
					<endPosition>74.7426761656082</endPosition>
				</positions>
				<positions axis="Omega" unit="deg">
					<commonPosition>17.90252064</commonPosition>
				</positions>
				<positions axis="Phi" unit="deg">
					<commonPosition>-176.8</commonPosition>
				</positions>
				<positions axis="Chi" unit="deg">
					<commonPosition>0</commonPosition>
				</positions>
				<positions axis="Z" unit="mm">
					<commonPosition>8.386</commonPosition>
				</positions>
				<commonCountingTime unit="seconds">0.974</commonCountingTime>
				<counts unit="counts">0 1 2 0 0 0 0 0 1 0 1 0 1 1 1 0 0 0 0 0 1 0 0 0 0 0 0 1 0 1 0 2 1 2 0 2 0 0 0 0 0 0 0 1 1 0 0 0 0 0 0 0 1 1 0 0 0 0 0 0 0 0 0 0 0 2 0 0 0 0 0 0 0 0 0 1 1 2 0 2 0 0 1 1 0 0 1 0 1 0 0 0 1 0 1 0 1 0 0 0 0 0 0 0 1 0 1 0 0 0 0 0 1 0 0 0 1 1 0 1 2 0 0 0 0 1 0 0 0 0 0 0 0 1 0 0 0 0 0 0 0 0 0 1 0 0 0 0 0 0 1 0 0 2 0 2 0 0 0 0 0 0 0 0 1 0 0 0 0 0 1 1 0 0 1 0 1 0 0 0 0 0 0 1 0 0 0 0 1 0 0 0 0 1 2 0 0 1 0 0 0 0 0 0 0 0 0 0 0 0 0 0 0 1 1 0 1 0 0 0 0 0 0 0 0 0 1 1 0 0 1 0 0 0 1 0 0 0 1 0 0 0 1 0 1 1 0 0 1 0 0 0 1 1 1</counts>
			</dataPoints>
		</scan>
		<scan status="Completed" appendNumber="0" scanAxis="2Theta" mode="Continuous">
			<header>
				<startTimeStamp>2024-07-03T14:43:28-04:00</startTimeStamp>
				<endTimeStamp>2024-07-03T15:13:30-04:00</endTimeStamp>
				<author>
					<name>lw627</name>
				</author>
				<source>
					<applicationSoftware version="7.1">Data Collector</applicationSoftware>
					<instrumentControlSoftware version="8.2  20201204">EMPYREAN</instrumentControlSoftware>
					<instrumentID>0000000011260721</instrumentID>
				</source>
			</header>
			<dataPoints>
				<positions axis="2Theta" unit="deg">
					<startPosition>71.3986889650599</startPosition>
					<endPosition>74.7459587362764</endPosition>
				</positions>
				<positions axis="Omega" unit="deg">
					<commonPosition>17.9041619253341</commonPosition>
				</positions>
				<positions axis="Phi" unit="deg">
					<commonPosition>-176.8</commonPosition>
				</positions>
				<positions axis="Chi" unit="deg">
					<commonPosition>0</commonPosition>
				</positions>
				<positions axis="Z" unit="mm">
					<commonPosition>8.386</commonPosition>
				</positions>
				<commonCountingTime unit="seconds">0.974</commonCountingTime>
				<counts unit="counts">1 0 0 0 0 0 0 1 1 1 1 0 0 0 0 0 1 0 0 0 0 0 1 0 0 0 2 1 0 0 0 0 0 0 0 1 0 2 0 0 0 0 0 0 0 0 0 0 0 0 0 0 1 1 3 0 0 1 0 0 1 0 0 0 0 0 0 0 0 0 0 0 1 1 0 0 0 0 0 0 0 1 3 0 0 0 0 0 0 0 0 0 0 2 2 0 1 1 0 0 0 1 0 0 0 2 0 0 0 0 1 0 0 0 0 0 0 0 0 2 0 0 0 0 0 0 2 0 0 0 0 0 0 1 1 0 0 2 0 1 1 1 0 0 0 0 0 1 0 0 0 0 1 0 0 1 0 0 0 1 2 0 0 0 0 0 0 1 2 1 0 1 0 0 0 0 0 0 0 1 0 1 1 0 1 1 0 0 0 1 0 0 0 1 0 1 0 0 1 0 0 0 0 0 2 2 0 1 0 0 0 0 0 0 0 0 0 0 0 0 1 0 0 0 1 1 0 0 1 0 0 1 0 0 0 0 0 0 0 0 0 0 0 1 0 0 1 0 0 0 0 0 0 0 0</counts>
			</dataPoints>
		</scan>
		<scan status="Completed" appendNumber="0" scanAxis="2Theta" mode="Continuous">
			<header>
				<startTimeStamp>2024-07-03T14:43:28-04:00</startTimeStamp>
				<endTimeStamp>2024-07-03T15:13:30-04:00</endTimeStamp>
				<author>
					<name>lw627</name>
				</author>
				<source>
					<applicationSoftware version="7.1">Data Collector</applicationSoftware>
					<instrumentControlSoftware version="8.2  20201204">EMPYREAN</instrumentControlSoftware>
					<instrumentID>0000000011260721</instrumentID>
				</source>
			</header>
			<dataPoints>
				<positions axis="2Theta" unit="deg">
					<startPosition>71.401971535728</startPosition>
					<endPosition>74.7492413069445</endPosition>
				</positions>
				<positions axis="Omega" unit="deg">
					<commonPosition>17.9058032106681</commonPosition>
				</positions>
				<positions axis="Phi" unit="deg">
					<commonPosition>-176.8</commonPosition>
				</positions>
				<positions axis="Chi" unit="deg">
					<commonPosition>0</commonPosition>
				</positions>
				<positions axis="Z" unit="mm">
					<commonPosition>8.386</commonPosition>
				</positions>
				<commonCountingTime unit="seconds">0.974</commonCountingTime>
				<counts unit="counts">0 0 0 1 1 0 1 0 1 0 0 0 0 0 0 0 0 0 0 1 1 0 0 0 1 1 2 1 1 0 0 0 1 0 2 0 1 0 0 0 0 0 0 0 0 0 0 0 0 0 0 0 0 0 0 0 0 0 0 0 0 1 0 0 0 1 1 0 0 0 0 0 0 0 0 0 1 0 0 1 1 0 0 0 0 0 0 0 1 0 0 0 0 0 0 0 0 0 1 0 0 0 1 0 0 0 0 0 0 0 0 1 1 0 1 1 0 0 1 1 0 0 0 0 0 0 0 1 0 1 0 1 1 0 1 1 1 0 0 0 0 0 1 0 0 0 0 1 0 0 1 0 0 0 0 0 0 0 0 0 0 0 0 0 0 0 0 0 0 1 0 2 1 0 1 0 0 2 1 1 0 0 0 0 1 0 0 1 0 0 0 0 0 0 0 0 1 0 0 0 0 0 0 1 0 0 1 1 0 0 0 0 0 0 0 0 1 1 0 0 0 0 0 0 0 0 0 0 1 0 0 0 0 0 0 1 2 1 0 0 1 0 0 0 1 1 1 1 0 0 0 0 1 1 0</counts>
			</dataPoints>
		</scan>
		<scan status="Completed" appendNumber="0" scanAxis="2Theta" mode="Continuous">
			<header>
				<startTimeStamp>2024-07-03T14:43:28-04:00</startTimeStamp>
				<endTimeStamp>2024-07-03T15:13:30-04:00</endTimeStamp>
				<author>
					<name>lw627</name>
				</author>
				<source>
					<applicationSoftware version="7.1">Data Collector</applicationSoftware>
					<instrumentControlSoftware version="8.2  20201204">EMPYREAN</instrumentControlSoftware>
					<instrumentID>0000000011260721</instrumentID>
				</source>
			</header>
			<dataPoints>
				<positions axis="2Theta" unit="deg">
					<startPosition>71.4052541063961</startPosition>
					<endPosition>74.7525238776126</endPosition>
				</positions>
				<positions axis="Omega" unit="deg">
					<commonPosition>17.9074444960022</commonPosition>
				</positions>
				<positions axis="Phi" unit="deg">
					<commonPosition>-176.8</commonPosition>
				</positions>
				<positions axis="Chi" unit="deg">
					<commonPosition>0</commonPosition>
				</positions>
				<positions axis="Z" unit="mm">
					<commonPosition>8.386</commonPosition>
				</positions>
				<commonCountingTime unit="seconds">0.974</commonCountingTime>
				<counts unit="counts">0 0 1 0 1 0 1 0 1 1 0 1 0 1 0 0 0 0 1 0 0 0 0 0 0 0 0 0 0 0 0 2 0 0 0 2 0 0 0 0 1 1 0 0 1 0 0 1 0 0 0 1 0 0 0 1 0 0 0 0 0 0 0 0 1 0 1 0 0 0 0 0 0 1 1 0 0 0 0 1 0 0 0 0 0 0 0 1 0 1 0 0 1 1 0 0 0 1 0 0 0 1 1 0 1 0 0 2 0 0 0 0 0 0 0 0 0 0 0 0 0 0 1 0 0 0 0 0 1 1 0 0 0 0 0 0 0 0 0 0 2 0 0 0 0 0 0 0 0 0 2 0 0 0 0 0 2 0 0 0 0 0 0 0 1 0 0 0 1 0 1 1 0 0 0 0 1 0 0 0 0 0 0 2 1 0 1 0 0 2 0 0 0 0 0 0 0 0 0 3 4 1 1 0 0 0 0 2 1 0 0 0 0 0 0 0 0 0 0 0 0 0 0 0 1 1 1 0 1 0 0 0 0 0 0 0 1 0 1 0 0 0 0 2 0 1 1 0 0 0 0 0 0 1 1</counts>
			</dataPoints>
		</scan>
		<scan status="Completed" appendNumber="0" scanAxis="2Theta" mode="Continuous">
			<header>
				<startTimeStamp>2024-07-03T14:43:28-04:00</startTimeStamp>
				<endTimeStamp>2024-07-03T15:13:30-04:00</endTimeStamp>
				<author>
					<name>lw627</name>
				</author>
				<source>
					<applicationSoftware version="7.1">Data Collector</applicationSoftware>
					<instrumentControlSoftware version="8.2  20201204">EMPYREAN</instrumentControlSoftware>
					<instrumentID>0000000011260721</instrumentID>
				</source>
			</header>
			<dataPoints>
				<positions axis="2Theta" unit="deg">
					<startPosition>71.4085366770643</startPosition>
					<endPosition>74.7558064482807</endPosition>
				</positions>
				<positions axis="Omega" unit="deg">
					<commonPosition>17.9090857813363</commonPosition>
				</positions>
				<positions axis="Phi" unit="deg">
					<commonPosition>-176.8</commonPosition>
				</positions>
				<positions axis="Chi" unit="deg">
					<commonPosition>0</commonPosition>
				</positions>
				<positions axis="Z" unit="mm">
					<commonPosition>8.386</commonPosition>
				</positions>
				<commonCountingTime unit="seconds">0.974</commonCountingTime>
				<counts unit="counts">0 0 0 0 0 0 0 2 0 1 0 0 0 0 0 0 2 0 0 0 0 0 1 1 0 1 1 0 0 0 0 2 0 1 1 1 0 0 0 0 0 0 0 0 1 1 0 0 0 0 0 0 0 0 1 0 0 0 0 0 0 0 0 0 0 0 0 2 0 0 0 1 1 1 1 0 0 1 0 0 1 0 0 1 0 1 0 0 0 0 0 0 0 0 0 0 0 0 1 0 0 0 0 0 3 0 0 0 0 1 0 0 0 0 0 0 2 0 0 0 0 0 0 0 0 2 0 0 0 0 1 0 2 2 1 0 0 0 0 1 0 0 0 0 0 2 0 0 0 2 1 0 0 0 1 0 0 0 0 1 0 0 1 1 0 0 1 0 0 0 0 0 1 0 0 0 0 1 0 0 0 0 0 2 0 0 0 1 0 0 0 0 0 0 0 0 1 0 0 0 0 0 0 0 0 2 0 0 0 0 0 1 0 1 0 1 1 1 0 0 1 0 2 0 1 0 1 0 1 0 1 0 0 0 0 0 1 0 1 0 1 0 1 0 0 0 2 1 2 1 0 0 0 0 0</counts>
			</dataPoints>
		</scan>
		<scan status="Completed" appendNumber="0" scanAxis="2Theta" mode="Continuous">
			<header>
				<startTimeStamp>2024-07-03T14:43:28-04:00</startTimeStamp>
				<endTimeStamp>2024-07-03T15:13:30-04:00</endTimeStamp>
				<author>
					<name>lw627</name>
				</author>
				<source>
					<applicationSoftware version="7.1">Data Collector</applicationSoftware>
					<instrumentControlSoftware version="8.2  20201204">EMPYREAN</instrumentControlSoftware>
					<instrumentID>0000000011260721</instrumentID>
				</source>
			</header>
			<dataPoints>
				<positions axis="2Theta" unit="deg">
					<startPosition>71.4118192477324</startPosition>
					<endPosition>74.7590890189489</endPosition>
				</positions>
				<positions axis="Omega" unit="deg">
					<commonPosition>17.9107270666703</commonPosition>
				</positions>
				<positions axis="Phi" unit="deg">
					<commonPosition>-176.8</commonPosition>
				</positions>
				<positions axis="Chi" unit="deg">
					<commonPosition>0</commonPosition>
				</positions>
				<positions axis="Z" unit="mm">
					<commonPosition>8.386</commonPosition>
				</positions>
				<commonCountingTime unit="seconds">0.974</commonCountingTime>
				<counts unit="counts">0 1 0 0 0 0 0 0 0 0 1 1 1 0 1 1 1 0 0 0 1 0 1 0 0 0 0 1 0 0 1 0 1 0 0 0 0 0 0 0 1 0 0 0 0 0 2 0 0 0 0 1 1 0 0 0 1 0 0 0 2 0 0 0 0 1 0 0 1 0 0 0 2 0 0 0 1 0 0 2 0 1 0 0 0 1 0 0 0 1 0 0 0 0 1 1 1 0 0 0 0 0 0 0 0 0 1 0 0 0 0 0 0 0 0 1 0 0 0 1 0 1 0 0 0 0 0 0 1 0 0 0 1 1 1 1 0 0 0 0 1 0 1 0 0 0 0 0 0 0 0 0 0 0 0 0 1 0 0 0 0 0 1 0 0 0 0 1 0 0 0 0 0 0 1 0 1 0 1 1 0 0 0 1 0 0 0 0 0 0 0 1 0 0 0 0 1 0 0 0 0 0 1 0 0 1 0 2 1 0 0 0 0 0 0 0 0 2 2 0 0 0 0 0 0 1 1 0 0 0 0 1 0 0 0 1 1 0 0 1 0 0 0 0 0 0 0 0 0 1 1 0 0 0 0</counts>
			</dataPoints>
		</scan>
		<scan status="Completed" appendNumber="0" scanAxis="2Theta" mode="Continuous">
			<header>
				<startTimeStamp>2024-07-03T14:43:28-04:00</startTimeStamp>
				<endTimeStamp>2024-07-03T15:13:30-04:00</endTimeStamp>
				<author>
					<name>lw627</name>
				</author>
				<source>
					<applicationSoftware version="7.1">Data Collector</applicationSoftware>
					<instrumentControlSoftware version="8.2  20201204">EMPYREAN</instrumentControlSoftware>
					<instrumentID>0000000011260721</instrumentID>
				</source>
			</header>
			<dataPoints>
				<positions axis="2Theta" unit="deg">
					<startPosition>71.4151018184005</startPosition>
					<endPosition>74.762371589617</endPosition>
				</positions>
				<positions axis="Omega" unit="deg">
					<commonPosition>17.9123683520044</commonPosition>
				</positions>
				<positions axis="Phi" unit="deg">
					<commonPosition>-176.8</commonPosition>
				</positions>
				<positions axis="Chi" unit="deg">
					<commonPosition>0</commonPosition>
				</positions>
				<positions axis="Z" unit="mm">
					<commonPosition>8.386</commonPosition>
				</positions>
				<commonCountingTime unit="seconds">0.974</commonCountingTime>
				<counts unit="counts">0 0 1 1 0 0 0 1 1 0 0 0 0 0 0 0 0 0 0 0 2 0 0 0 0 0 1 0 0 0 0 0 2 0 0 2 0 0 0 1 0 0 0 1 0 0 0 0 1 0 1 1 0 1 0 0 0 0 0 1 1 0 0 1 0 0 0 0 1 0 0 0 0 0 2 0 0 1 0 0 0 0 2 0 0 0 0 0 1 0 0 0 0 0 0 0 0 1 0 0 0 0 0 0 0 0 0 0 0 0 0 0 0 0 0 2 0 1 0 0 0 0 1 3 0 0 1 1 1 0 0 0 1 0 0 1 0 0 0 1 0 1 1 0 0 0 0 0 0 0 0 0 1 0 0 2 0 0 1 0 0 0 0 0 0 1 1 1 1 0 1 1 1 0 0 0 1 0 0 0 0 0 0 0 0 0 0 0 0 0 1 0 0 0 0 1 0 0 0 0 0 0 0 1 0 0 0 0 0 0 0 1 0 0 0 0 0 1 0 0 0 0 1 1 1 1 0 0 0 2 0 0 1 0 1 1 0 0 0 0 0 0 0 0 0 0 0 1 0 0 1 0 0 0 0</counts>
			</dataPoints>
		</scan>
		<scan status="Completed" appendNumber="0" scanAxis="2Theta" mode="Continuous">
			<header>
				<startTimeStamp>2024-07-03T14:43:28-04:00</startTimeStamp>
				<endTimeStamp>2024-07-03T15:13:30-04:00</endTimeStamp>
				<author>
					<name>lw627</name>
				</author>
				<source>
					<applicationSoftware version="7.1">Data Collector</applicationSoftware>
					<instrumentControlSoftware version="8.2  20201204">EMPYREAN</instrumentControlSoftware>
					<instrumentID>0000000011260721</instrumentID>
				</source>
			</header>
			<dataPoints>
				<positions axis="2Theta" unit="deg">
					<startPosition>71.4183843890686</startPosition>
					<endPosition>74.7656541602851</endPosition>
				</positions>
				<positions axis="Omega" unit="deg">
					<commonPosition>17.9140096373384</commonPosition>
				</positions>
				<positions axis="Phi" unit="deg">
					<commonPosition>-176.8</commonPosition>
				</positions>
				<positions axis="Chi" unit="deg">
					<commonPosition>0</commonPosition>
				</positions>
				<positions axis="Z" unit="mm">
					<commonPosition>8.386</commonPosition>
				</positions>
				<commonCountingTime unit="seconds">0.974</commonCountingTime>
				<counts unit="counts">0 3 1 1 0 0 0 0 0 2 0 1 0 3 0 0 0 1 0 0 1 0 0 0 1 2 0 0 2 0 0 0 0 1 1 0 0 0 1 0 0 0 1 2 0 0 0 0 1 0 1 0 0 0 0 0 0 0 0 1 1 2 0 1 0 0 1 0 0 1 0 1 0 0 0 2 0 1 0 0 0 0 1 0 1 0 1 0 3 0 1 0 0 1 0 1 1 0 0 0 0 2 0 1 0 0 0 0 0 0 0 1 0 0 0 0 2 0 0 1 0 0 0 0 0 1 1 1 0 0 1 0 1 1 0 0 1 2 0 0 0 1 0 0 0 0 0 1 0 0 0 0 0 0 0 1 0 1 0 1 0 0 0 0 1 0 0 0 1 1 1 1 0 1 0 0 0 0 0 0 0 0 0 0 0 1 0 1 1 2 0 0 2 0 0 0 0 0 0 0 0 0 0 0 0 1 0 0 0 0 0 0 0 0 0 0 1 0 0 1 0 0 1 0 0 0 0 0 0 1 0 0 1 0 0 0 0 0 0 0 0 0 0 1 1 1 0 1 0 0 0 1 0 0 0</counts>
			</dataPoints>
		</scan>
		<scan status="Completed" appendNumber="0" scanAxis="2Theta" mode="Continuous">
			<header>
				<startTimeStamp>2024-07-03T14:43:28-04:00</startTimeStamp>
				<endTimeStamp>2024-07-03T15:13:30-04:00</endTimeStamp>
				<author>
					<name>lw627</name>
				</author>
				<source>
					<applicationSoftware version="7.1">Data Collector</applicationSoftware>
					<instrumentControlSoftware version="8.2  20201204">EMPYREAN</instrumentControlSoftware>
					<instrumentID>0000000011260721</instrumentID>
				</source>
			</header>
			<dataPoints>
				<positions axis="2Theta" unit="deg">
					<startPosition>71.4216669597368</startPosition>
					<endPosition>74.7689367309532</endPosition>
				</positions>
				<positions axis="Omega" unit="deg">
					<commonPosition>17.9156509226725</commonPosition>
				</positions>
				<positions axis="Phi" unit="deg">
					<commonPosition>-176.8</commonPosition>
				</positions>
				<positions axis="Chi" unit="deg">
					<commonPosition>0</commonPosition>
				</positions>
				<positions axis="Z" unit="mm">
					<commonPosition>8.386</commonPosition>
				</positions>
				<commonCountingTime unit="seconds">0.974</commonCountingTime>
				<counts unit="counts">1 1 0 0 1 1 0 1 0 1 0 1 0 0 0 2 1 0 0 0 0 0 1 0 0 0 0 0 1 0 0 0 1 0 0 0 1 0 0 0 0 1 0 0 0 0 0 0 2 0 0 0 0 0 0 1 1 1 0 1 1 1 0 0 0 0 1 1 0 1 1 1 1 0 0 0 0 0 0 0 1 1 0 0 0 0 0 0 1 0 0 0 0 0 0 0 1 0 1 0 0 1 0 0 1 0 0 1 1 0 0 1 0 0 1 0 0 0 1 0 0 0 0 0 1 0 0 0 0 0 1 1 0 1 0 0 0 0 0 1 1 0 0 0 0 0 0 0 1 1 0 0 0 0 2 0 0 0 0 0 0 1 1 0 0 1 0 0 1 1 0 0 0 1 1 0 0 0 1 1 0 0 0 1 1 0 0 1 2 0 0 1 1 0 2 0 0 1 0 2 0 0 0 1 0 0 0 0 1 1 0 0 0 0 1 1 0 1 1 0 1 1 0 0 0 0 1 1 0 1 0 1 0 1 0 1 1 0 0 0 0 0 0 0 0 0 0 3 0 0 0 1 0 0 0</counts>
			</dataPoints>
		</scan>
		<scan status="Completed" appendNumber="0" scanAxis="2Theta" mode="Continuous">
			<header>
				<startTimeStamp>2024-07-03T14:43:28-04:00</startTimeStamp>
				<endTimeStamp>2024-07-03T15:13:30-04:00</endTimeStamp>
				<author>
					<name>lw627</name>
				</author>
				<source>
					<applicationSoftware version="7.1">Data Collector</applicationSoftware>
					<instrumentControlSoftware version="8.2  20201204">EMPYREAN</instrumentControlSoftware>
					<instrumentID>0000000011260721</instrumentID>
				</source>
			</header>
			<dataPoints>
				<positions axis="2Theta" unit="deg">
					<startPosition>71.4249495304049</startPosition>
					<endPosition>74.7722193016214</endPosition>
				</positions>
				<positions axis="Omega" unit="deg">
					<commonPosition>17.9172922080066</commonPosition>
				</positions>
				<positions axis="Phi" unit="deg">
					<commonPosition>-176.8</commonPosition>
				</positions>
				<positions axis="Chi" unit="deg">
					<commonPosition>0</commonPosition>
				</positions>
				<positions axis="Z" unit="mm">
					<commonPosition>8.386</commonPosition>
				</positions>
				<commonCountingTime unit="seconds">0.974</commonCountingTime>
				<counts unit="counts">0 0 0 1 0 0 0 0 0 1 0 0 0 0 0 0 0 0 0 0 0 0 0 0 0 2 0 0 2 0 0 0 0 0 1 0 1 0 0 0 0 1 2 3 0 1 0 0 0 0 1 0 1 1 0 1 1 0 0 0 0 2 0 0 0 0 0 0 1 0 0 1 1 0 0 0 0 0 0 1 0 0 0 0 1 1 0 0 1 1 1 0 0 0 0 0 0 1 0 0 1 1 0 0 0 1 1 0 0 0 1 0 0 1 0 1 0 0 0 0 0 0 0 0 0 0 0 0 1 0 1 1 1 0 0 0 0 0 0 0 0 0 0 0 0 1 1 0 0 0 0 0 0 1 0 0 0 0 1 0 0 0 0 1 0 0 0 0 1 1 0 0 1 0 0 0 1 0 0 1 1 0 0 0 0 0 1 0 1 0 0 1 0 1 0 1 0 4 1 0 0 0 0 0 1 0 0 0 0 0 1 0 1 1 0 0 0 0 2 0 0 0 0 1 0 0 0 0 1 0 1 0 0 0 0 1 0 2 0 0 2 0 0 0 0 1 0 0 1 1 2 1 1 0 0</counts>
			</dataPoints>
		</scan>
		<scan status="Completed" appendNumber="0" scanAxis="2Theta" mode="Continuous">
			<header>
				<startTimeStamp>2024-07-03T14:43:28-04:00</startTimeStamp>
				<endTimeStamp>2024-07-03T15:13:30-04:00</endTimeStamp>
				<author>
					<name>lw627</name>
				</author>
				<source>
					<applicationSoftware version="7.1">Data Collector</applicationSoftware>
					<instrumentControlSoftware version="8.2  20201204">EMPYREAN</instrumentControlSoftware>
					<instrumentID>0000000011260721</instrumentID>
				</source>
			</header>
			<dataPoints>
				<positions axis="2Theta" unit="deg">
					<startPosition>71.428232101073</startPosition>
					<endPosition>74.7755018722895</endPosition>
				</positions>
				<positions axis="Omega" unit="deg">
					<commonPosition>17.9189334933406</commonPosition>
				</positions>
				<positions axis="Phi" unit="deg">
					<commonPosition>-176.8</commonPosition>
				</positions>
				<positions axis="Chi" unit="deg">
					<commonPosition>0</commonPosition>
				</positions>
				<positions axis="Z" unit="mm">
					<commonPosition>8.386</commonPosition>
				</positions>
				<commonCountingTime unit="seconds">0.974</commonCountingTime>
				<counts unit="counts">0 0 0 0 0 1 1 0 0 0 0 0 0 0 0 0 0 1 1 0 0 0 0 0 0 1 0 0 1 0 0 1 0 0 0 1 0 0 1 0 1 1 0 2 0 0 0 0 0 0 0 0 1 0 0 2 1 0 0 0 0 1 0 0 0 2 0 2 0 1 1 4 0 0 1 0 0 0 0 0 2 0 0 1 0 0 0 0 0 0 0 0 0 1 0 0 0 0 0 0 0 0 1 1 0 1 0 0 0 0 0 0 1 0 1 1 0 0 1 0 1 0 0 0 0 0 1 1 0 0 0 0 1 0 0 0 0 0 0 0 0 0 1 0 0 0 0 1 0 0 0 1 1 1 0 3 0 0 0 0 1 0 1 1 0 0 0 0 0 2 0 0 1 1 0 0 1 0 0 0 0 0 0 0 2 0 0 0 0 0 0 0 1 1 0 0 0 0 1 0 0 0 0 2 3 0 0 0 0 0 0 0 0 0 0 0 0 0 0 0 0 0 0 0 1 0 1 0 0 0 0 0 1 0 0 0 2 0 0 0 1 0 0 3 0 1 1 0 0 0 0 0 0 0 1</counts>
			</dataPoints>
		</scan>
		<scan status="Completed" appendNumber="0" scanAxis="2Theta" mode="Continuous">
			<header>
				<startTimeStamp>2024-07-03T14:43:28-04:00</startTimeStamp>
				<endTimeStamp>2024-07-03T15:13:30-04:00</endTimeStamp>
				<author>
					<name>lw627</name>
				</author>
				<source>
					<applicationSoftware version="7.1">Data Collector</applicationSoftware>
					<instrumentControlSoftware version="8.2  20201204">EMPYREAN</instrumentControlSoftware>
					<instrumentID>0000000011260721</instrumentID>
				</source>
			</header>
			<dataPoints>
				<positions axis="2Theta" unit="deg">
					<startPosition>71.4315146717412</startPosition>
					<endPosition>74.7787844429576</endPosition>
				</positions>
				<positions axis="Omega" unit="deg">
					<commonPosition>17.9205747786747</commonPosition>
				</positions>
				<positions axis="Phi" unit="deg">
					<commonPosition>-176.8</commonPosition>
				</positions>
				<positions axis="Chi" unit="deg">
					<commonPosition>0</commonPosition>
				</positions>
				<positions axis="Z" unit="mm">
					<commonPosition>8.386</commonPosition>
				</positions>
				<commonCountingTime unit="seconds">0.974</commonCountingTime>
				<counts unit="counts">1 0 0 0 0 0 0 1 0 0 1 0 1 0 0 0 0 0 0 1 0 2 0 0 0 0 0 0 0 0 0 0 0 0 0 1 0 0 0 0 0 0 0 0 0 1 1 0 0 0 0 0 0 0 0 0 0 0 0 0 0 1 0 0 0 1 0 0 0 1 0 0 0 0 0 0 1 0 1 1 1 0 1 0 0 1 0 0 0 0 0 0 1 0 0 0 0 0 0 0 0 0 0 1 0 0 1 0 0 0 3 0 0 0 0 0 1 0 0 0 0 2 0 1 0 0 0 3 1 1 0 1 0 3 0 1 0 0 0 0 0 0 0 0 2 0 0 0 1 0 0 0 0 0 0 2 0 0 0 1 0 1 0 0 0 0 0 0 0 2 0 1 0 0 0 0 0 0 0 0 0 0 0 0 0 0 0 0 0 0 2 0 0 0 0 2 0 0 0 1 1 1 0 1 0 0 0 0 0 0 1 0 0 0 2 0 0 0 2 0 0 1 2 0 0 0 1 0 0 0 0 0 0 1 0 0 0 0 0 0 0 1 0 0 1 1 0 0 0 0 0 0 1 0 0</counts>
			</dataPoints>
		</scan>
		<scan status="Completed" appendNumber="0" scanAxis="2Theta" mode="Continuous">
			<header>
				<startTimeStamp>2024-07-03T14:43:28-04:00</startTimeStamp>
				<endTimeStamp>2024-07-03T15:13:30-04:00</endTimeStamp>
				<author>
					<name>lw627</name>
				</author>
				<source>
					<applicationSoftware version="7.1">Data Collector</applicationSoftware>
					<instrumentControlSoftware version="8.2  20201204">EMPYREAN</instrumentControlSoftware>
					<instrumentID>0000000011260721</instrumentID>
				</source>
			</header>
			<dataPoints>
				<positions axis="2Theta" unit="deg">
					<startPosition>71.4347972424093</startPosition>
					<endPosition>74.7820670136257</endPosition>
				</positions>
				<positions axis="Omega" unit="deg">
					<commonPosition>17.9222160640088</commonPosition>
				</positions>
				<positions axis="Phi" unit="deg">
					<commonPosition>-176.8</commonPosition>
				</positions>
				<positions axis="Chi" unit="deg">
					<commonPosition>0</commonPosition>
				</positions>
				<positions axis="Z" unit="mm">
					<commonPosition>8.386</commonPosition>
				</positions>
				<commonCountingTime unit="seconds">0.974</commonCountingTime>
				<counts unit="counts">1 0 0 1 0 0 0 0 1 1 1 1 2 0 0 0 0 1 0 0 0 0 0 0 0 1 0 2 2 0 0 0 0 2 0 0 0 0 0 0 0 0 0 1 2 1 1 0 0 1 0 1 0 2 1 1 1 0 0 0 0 0 0 0 0 0 1 0 0 1 0 0 1 0 0 2 1 0 0 0 0 1 1 0 1 0 0 0 1 0 1 0 1 0 0 1 0 0 0 1 0 0 0 1 0 0 0 0 0 0 0 0 0 0 1 0 0 0 1 1 0 0 0 0 0 0 1 0 0 0 0 0 0 0 0 0 0 0 1 0 0 0 0 0 1 0 1 0 0 0 1 0 0 0 0 0 0 0 0 1 0 0 0 0 1 0 0 0 2 0 1 0 0 3 0 0 1 0 0 0 1 0 0 0 0 0 0 2 0 0 0 1 1 0 2 0 0 0 0 0 1 0 0 0 0 3 2 1 0 0 0 0 0 0 1 1 0 0 0 0 1 1 0 1 0 0 0 1 0 1 0 0 1 0 1 0 0 1 0 2 0 2 0 1 0 0 2 0 0 0 0 0 0 0 0</counts>
			</dataPoints>
		</scan>
		<scan status="Completed" appendNumber="0" scanAxis="2Theta" mode="Continuous">
			<header>
				<startTimeStamp>2024-07-03T14:43:28-04:00</startTimeStamp>
				<endTimeStamp>2024-07-03T15:13:30-04:00</endTimeStamp>
				<author>
					<name>lw627</name>
				</author>
				<source>
					<applicationSoftware version="7.1">Data Collector</applicationSoftware>
					<instrumentControlSoftware version="8.2  20201204">EMPYREAN</instrumentControlSoftware>
					<instrumentID>0000000011260721</instrumentID>
				</source>
			</header>
			<dataPoints>
				<positions axis="2Theta" unit="deg">
					<startPosition>71.4380798130774</startPosition>
					<endPosition>74.7853495842939</endPosition>
				</positions>
				<positions axis="Omega" unit="deg">
					<commonPosition>17.9238573493428</commonPosition>
				</positions>
				<positions axis="Phi" unit="deg">
					<commonPosition>-176.8</commonPosition>
				</positions>
				<positions axis="Chi" unit="deg">
					<commonPosition>0</commonPosition>
				</positions>
				<positions axis="Z" unit="mm">
					<commonPosition>8.386</commonPosition>
				</positions>
				<commonCountingTime unit="seconds">0.974</commonCountingTime>
				<counts unit="counts">0 0 0 0 1 0 0 0 0 0 0 0 0 0 0 0 2 0 0 0 0 0 0 0 0 0 0 1 0 0 0 1 0 0 2 0 0 1 0 0 0 0 0 1 1 0 0 0 0 0 0 0 0 1 0 1 0 0 0 2 0 0 0 1 1 0 0 0 0 0 0 1 0 1 0 0 0 2 0 0 0 0 1 0 0 1 0 1 0 0 0 0 0 0 0 0 0 0 0 0 0 0 0 0 2 0 1 0 0 0 0 1 0 0 0 0 0 0 0 0 0 0 0 0 1 0 1 0 0 0 0 0 0 0 0 0 0 0 0 0 0 0 0 0 0 1 0 0 0 0 0 0 0 1 1 0 1 0 0 0 0 0 0 1 0 0 0 1 0 1 1 1 0 1 0 0 0 0 1 0 0 0 0 2 0 1 0 0 0 1 0 0 0 0 0 2 0 0 0 0 0 0 0 0 0 1 1 0 0 0 0 1 0 0 0 0 0 0 0 0 0 1 0 0 0 0 0 0 0 0 0 1 0 0 0 0 0 0 0 0 0 1 0 0 0 1 1 0 1 0 0 0 0 0 1</counts>
			</dataPoints>
		</scan>
		<scan status="Completed" appendNumber="0" scanAxis="2Theta" mode="Continuous">
			<header>
				<startTimeStamp>2024-07-03T14:43:28-04:00</startTimeStamp>
				<endTimeStamp>2024-07-03T15:13:30-04:00</endTimeStamp>
				<author>
					<name>lw627</name>
				</author>
				<source>
					<applicationSoftware version="7.1">Data Collector</applicationSoftware>
					<instrumentControlSoftware version="8.2  20201204">EMPYREAN</instrumentControlSoftware>
					<instrumentID>0000000011260721</instrumentID>
				</source>
			</header>
			<dataPoints>
				<positions axis="2Theta" unit="deg">
					<startPosition>71.4413623837455</startPosition>
					<endPosition>74.788632154962</endPosition>
				</positions>
				<positions axis="Omega" unit="deg">
					<commonPosition>17.9254986346769</commonPosition>
				</positions>
				<positions axis="Phi" unit="deg">
					<commonPosition>-176.8</commonPosition>
				</positions>
				<positions axis="Chi" unit="deg">
					<commonPosition>0</commonPosition>
				</positions>
				<positions axis="Z" unit="mm">
					<commonPosition>8.386</commonPosition>
				</positions>
				<commonCountingTime unit="seconds">0.974</commonCountingTime>
				<counts unit="counts">0 0 0 0 1 1 0 0 0 0 0 0 0 0 0 1 0 0 0 0 0 0 0 1 0 0 0 0 0 0 1 0 2 0 1 0 0 0 1 0 0 1 1 1 0 0 0 0 2 0 0 1 0 0 0 0 0 0 1 1 1 0 0 0 2 0 1 0 0 0 1 0 1 0 0 1 0 0 0 1 0 0 0 1 0 1 0 0 0 0 0 2 0 0 1 0 0 0 0 0 0 0 0 1 1 0 0 1 1 1 0 1 1 0 0 3 0 1 0 1 0 0 0 0 0 0 0 0 0 0 1 1 0 0 0 1 0 0 1 1 0 0 0 0 0 0 0 1 0 1 0 0 0 0 1 0 0 0 0 0 0 0 0 1 0 0 0 0 0 0 0 0 0 0 0 0 0 0 0 0 0 0 0 0 0 0 1 0 0 0 1 0 0 0 0 1 0 0 0 1 0 0 0 1 0 0 0 0 0 0 1 2 0 0 0 0 1 1 0 0 0 0 0 1 0 0 1 1 0 1 0 0 0 0 0 0 0 0 0 0 0 0 0 1 0 1 0 0 0 0 1 0 1 0 0</counts>
			</dataPoints>
		</scan>
		<scan status="Completed" appendNumber="0" scanAxis="2Theta" mode="Continuous">
			<header>
				<startTimeStamp>2024-07-03T14:43:28-04:00</startTimeStamp>
				<endTimeStamp>2024-07-03T15:13:30-04:00</endTimeStamp>
				<author>
					<name>lw627</name>
				</author>
				<source>
					<applicationSoftware version="7.1">Data Collector</applicationSoftware>
					<instrumentControlSoftware version="8.2  20201204">EMPYREAN</instrumentControlSoftware>
					<instrumentID>0000000011260721</instrumentID>
				</source>
			</header>
			<dataPoints>
				<positions axis="2Theta" unit="deg">
					<startPosition>71.4446449544137</startPosition>
					<endPosition>74.7919147256301</endPosition>
				</positions>
				<positions axis="Omega" unit="deg">
					<commonPosition>17.927139920011</commonPosition>
				</positions>
				<positions axis="Phi" unit="deg">
					<commonPosition>-176.8</commonPosition>
				</positions>
				<positions axis="Chi" unit="deg">
					<commonPosition>0</commonPosition>
				</positions>
				<positions axis="Z" unit="mm">
					<commonPosition>8.386</commonPosition>
				</positions>
				<commonCountingTime unit="seconds">0.974</commonCountingTime>
				<counts unit="counts">1 0 0 0 1 0 0 1 0 0 1 0 0 0 0 0 1 0 0 0 0 0 0 1 0 0 0 0 0 0 1 1 0 0 0 0 0 0 0 0 1 0 0 0 0 0 1 1 1 1 0 0 1 0 0 1 0 1 0 1 0 0 0 1 0 0 0 0 1 1 0 0 0 0 0 1 0 0 1 0 0 0 0 0 0 0 0 0 1 1 1 0 0 0 0 0 0 1 0 1 0 0 1 0 0 0 0 1 0 1 0 0 1 0 0 1 0 0 0 0 1 0 2 0 1 0 0 0 0 0 1 2 0 1 0 0 1 1 0 0 0 2 0 0 1 0 0 0 0 0 1 0 2 0 0 0 0 0 0 0 0 0 0 0 1 0 1 1 0 0 0 1 0 0 0 0 0 1 1 0 1 0 0 0 0 0 2 1 0 0 0 0 0 1 0 2 0 0 0 1 0 0 0 0 1 2 0 0 1 0 0 0 0 0 0 0 0 1 0 0 0 0 0 0 0 0 0 0 0 1 0 0 2 0 0 1 0 0 0 0 1 1 1 1 0 0 1 0 1 0 1 1 1 0 1</counts>
			</dataPoints>
		</scan>
		<scan status="Completed" appendNumber="0" scanAxis="2Theta" mode="Continuous">
			<header>
				<startTimeStamp>2024-07-03T14:43:28-04:00</startTimeStamp>
				<endTimeStamp>2024-07-03T15:13:30-04:00</endTimeStamp>
				<author>
					<name>lw627</name>
				</author>
				<source>
					<applicationSoftware version="7.1">Data Collector</applicationSoftware>
					<instrumentControlSoftware version="8.2  20201204">EMPYREAN</instrumentControlSoftware>
					<instrumentID>0000000011260721</instrumentID>
				</source>
			</header>
			<dataPoints>
				<positions axis="2Theta" unit="deg">
					<startPosition>71.4479275250818</startPosition>
					<endPosition>74.7951972962983</endPosition>
				</positions>
				<positions axis="Omega" unit="deg">
					<commonPosition>17.928781205345</commonPosition>
				</positions>
				<positions axis="Phi" unit="deg">
					<commonPosition>-176.8</commonPosition>
				</positions>
				<positions axis="Chi" unit="deg">
					<commonPosition>0</commonPosition>
				</positions>
				<positions axis="Z" unit="mm">
					<commonPosition>8.386</commonPosition>
				</positions>
				<commonCountingTime unit="seconds">0.974</commonCountingTime>
				<counts unit="counts">1 1 1 0 0 2 0 0 1 1 0 0 1 0 0 0 1 0 0 1 0 0 0 1 0 1 0 0 0 0 0 2 1 1 0 0 2 0 0 0 1 2 0 0 0 0 0 0 0 0 1 0 0 0 0 0 0 0 0 0 0 1 1 0 0 0 0 0 2 0 2 0 0 1 0 0 1 0 0 0 1 0 0 0 1 0 1 1 1 0 1 0 1 1 0 0 0 0 0 0 1 0 1 0 0 1 0 0 0 1 0 0 0 1 0 0 0 0 0 0 0 1 1 0 0 0 0 0 0 0 0 0 0 0 0 0 0 0 0 0 0 0 0 0 1 2 0 0 0 0 0 0 0 1 3 1 0 0 0 0 0 0 0 0 0 2 0 0 0 0 0 0 0 0 1 0 1 0 0 0 0 0 0 0 0 0 0 0 0 0 1 0 0 0 0 0 1 0 0 0 0 2 0 0 1 0 0 0 0 0 0 0 1 1 0 0 0 0 0 0 0 0 0 0 0 0 1 1 1 0 0 2 1 0 0 0 0 0 0 0 1 0 0 0 1 0 1 1 1 0 0 1 0 1 0</counts>
			</dataPoints>
		</scan>
		<scan status="Completed" appendNumber="0" scanAxis="2Theta" mode="Continuous">
			<header>
				<startTimeStamp>2024-07-03T14:43:28-04:00</startTimeStamp>
				<endTimeStamp>2024-07-03T15:13:30-04:00</endTimeStamp>
				<author>
					<name>lw627</name>
				</author>
				<source>
					<applicationSoftware version="7.1">Data Collector</applicationSoftware>
					<instrumentControlSoftware version="8.2  20201204">EMPYREAN</instrumentControlSoftware>
					<instrumentID>0000000011260721</instrumentID>
				</source>
			</header>
			<dataPoints>
				<positions axis="2Theta" unit="deg">
					<startPosition>71.4512100957499</startPosition>
					<endPosition>74.7984798669664</endPosition>
				</positions>
				<positions axis="Omega" unit="deg">
					<commonPosition>17.9304224906791</commonPosition>
				</positions>
				<positions axis="Phi" unit="deg">
					<commonPosition>-176.8</commonPosition>
				</positions>
				<positions axis="Chi" unit="deg">
					<commonPosition>0</commonPosition>
				</positions>
				<positions axis="Z" unit="mm">
					<commonPosition>8.386</commonPosition>
				</positions>
				<commonCountingTime unit="seconds">0.974</commonCountingTime>
				<counts unit="counts">0 0 0 0 1 1 0 0 1 0 0 0 0 0 0 0 1 0 0 0 0 0 0 1 1 1 0 0 0 0 0 0 0 0 0 1 1 0 0 1 0 0 2 1 1 0 0 0 1 0 0 0 0 1 0 0 0 1 0 1 0 0 1 0 0 0 0 1 0 0 2 1 0 1 0 0 0 0 0 1 0 0 0 0 0 0 0 1 0 1 0 0 0 1 0 0 0 0 0 1 0 0 0 0 0 0 0 0 0 0 1 0 1 2 0 0 2 0 0 0 0 0 0 0 0 0 0 1 0 0 1 0 0 0 0 1 0 0 0 0 0 0 0 0 0 0 0 0 0 0 0 0 0 1 0 0 1 1 0 0 0 1 0 0 0 0 0 0 1 0 0 0 0 0 0 0 2 0 1 0 0 1 0 1 1 0 0 0 1 0 3 1 0 0 1 0 0 0 0 0 0 0 0 0 0 0 0 0 1 0 0 1 0 0 0 0 0 0 0 0 0 2 0 2 0 0 1 0 0 0 0 0 0 0 0 1 0 0 0 0 0 0 0 2 0 0 0 1 0 1 1 0 0 0 0</counts>
			</dataPoints>
		</scan>
		<scan status="Completed" appendNumber="0" scanAxis="2Theta" mode="Continuous">
			<header>
				<startTimeStamp>2024-07-03T14:43:28-04:00</startTimeStamp>
				<endTimeStamp>2024-07-03T15:13:30-04:00</endTimeStamp>
				<author>
					<name>lw627</name>
				</author>
				<source>
					<applicationSoftware version="7.1">Data Collector</applicationSoftware>
					<instrumentControlSoftware version="8.2  20201204">EMPYREAN</instrumentControlSoftware>
					<instrumentID>0000000011260721</instrumentID>
				</source>
			</header>
			<dataPoints>
				<positions axis="2Theta" unit="deg">
					<startPosition>71.454492666418</startPosition>
					<endPosition>74.8017624376345</endPosition>
				</positions>
				<positions axis="Omega" unit="deg">
					<commonPosition>17.9320637760131</commonPosition>
				</positions>
				<positions axis="Phi" unit="deg">
					<commonPosition>-176.8</commonPosition>
				</positions>
				<positions axis="Chi" unit="deg">
					<commonPosition>0</commonPosition>
				</positions>
				<positions axis="Z" unit="mm">
					<commonPosition>8.386</commonPosition>
				</positions>
				<commonCountingTime unit="seconds">0.974</commonCountingTime>
				<counts unit="counts">1 1 0 0 0 3 1 0 0 0 0 0 1 0 0 0 0 0 0 0 0 0 1 0 0 0 2 0 2 1 0 0 0 0 0 0 0 1 0 0 0 1 1 0 0 0 0 1 0 0 0 0 1 0 0 1 0 1 0 0 0 2 0 0 1 0 0 0 0 1 0 0 2 0 1 0 0 0 0 2 0 1 0 0 0 0 0 0 0 0 0 1 0 0 0 0 0 0 1 0 1 0 0 0 0 0 0 0 0 0 1 0 0 1 0 0 0 0 1 0 0 1 0 0 0 0 0 0 0 0 2 0 1 2 1 0 1 1 0 0 0 0 0 0 1 1 0 0 0 0 0 0 0 0 0 1 0 0 1 0 0 0 1 2 0 0 1 1 0 1 0 0 1 1 0 0 0 0 0 0 0 0 2 0 1 1 0 0 0 0 2 0 0 0 1 0 2 1 0 1 0 0 1 0 0 0 1 0 1 0 0 0 1 0 0 1 0 0 0 1 0 0 0 1 1 0 0 0 0 0 0 2 0 1 0 1 0 0 0 1 0 1 0 1 2 1 0 0 1 0 1 0 0 0 0</counts>
			</dataPoints>
		</scan>
		<scan status="Completed" appendNumber="0" scanAxis="2Theta" mode="Continuous">
			<header>
				<startTimeStamp>2024-07-03T14:43:28-04:00</startTimeStamp>
				<endTimeStamp>2024-07-03T15:13:30-04:00</endTimeStamp>
				<author>
					<name>lw627</name>
				</author>
				<source>
					<applicationSoftware version="7.1">Data Collector</applicationSoftware>
					<instrumentControlSoftware version="8.2  20201204">EMPYREAN</instrumentControlSoftware>
					<instrumentID>0000000011260721</instrumentID>
				</source>
			</header>
			<dataPoints>
				<positions axis="2Theta" unit="deg">
					<startPosition>71.4577752370862</startPosition>
					<endPosition>74.8050450083026</endPosition>
				</positions>
				<positions axis="Omega" unit="deg">
					<commonPosition>17.9337050613472</commonPosition>
				</positions>
				<positions axis="Phi" unit="deg">
					<commonPosition>-176.8</commonPosition>
				</positions>
				<positions axis="Chi" unit="deg">
					<commonPosition>0</commonPosition>
				</positions>
				<positions axis="Z" unit="mm">
					<commonPosition>8.386</commonPosition>
				</positions>
				<commonCountingTime unit="seconds">0.974</commonCountingTime>
				<counts unit="counts">0 1 1 0 0 0 0 1 0 0 0 0 0 0 0 0 0 0 1 1 0 3 0 2 0 0 0 0 1 0 0 0 0 0 0 0 0 0 0 0 0 0 0 0 1 0 0 0 0 1 1 1 0 1 0 0 0 0 0 1 1 0 0 0 0 0 0 0 0 0 0 0 2 0 1 0 0 0 0 0 1 0 0 0 0 0 0 0 0 0 0 0 0 0 1 1 0 0 0 0 0 1 0 0 0 0 0 2 1 0 0 1 0 0 0 1 3 0 0 0 0 0 0 1 0 0 0 0 0 0 0 0 0 0 0 0 0 0 0 1 0 1 1 2 0 0 2 0 0 0 0 1 0 0 1 0 0 0 1 1 0 0 0 1 1 1 0 0 0 0 0 0 0 0 0 1 0 0 0 0 0 1 0 0 0 1 1 1 1 0 1 0 0 1 0 0 0 0 0 0 0 0 1 1 1 0 0 1 0 0 0 0 2 2 0 0 0 0 0 0 0 2 0 0 0 0 0 0 0 0 1 0 0 0 1 0 0 0 3 1 1 0 0 0 1 0 1 1 0 1 2 0 0 0 1</counts>
			</dataPoints>
		</scan>
		<scan status="Completed" appendNumber="0" scanAxis="2Theta" mode="Continuous">
			<header>
				<startTimeStamp>2024-07-03T14:43:28-04:00</startTimeStamp>
				<endTimeStamp>2024-07-03T15:13:30-04:00</endTimeStamp>
				<author>
					<name>lw627</name>
				</author>
				<source>
					<applicationSoftware version="7.1">Data Collector</applicationSoftware>
					<instrumentControlSoftware version="8.2  20201204">EMPYREAN</instrumentControlSoftware>
					<instrumentID>0000000011260721</instrumentID>
				</source>
			</header>
			<dataPoints>
				<positions axis="2Theta" unit="deg">
					<startPosition>71.4610578077543</startPosition>
					<endPosition>74.8083275789708</endPosition>
				</positions>
				<positions axis="Omega" unit="deg">
					<commonPosition>17.9353463466813</commonPosition>
				</positions>
				<positions axis="Phi" unit="deg">
					<commonPosition>-176.8</commonPosition>
				</positions>
				<positions axis="Chi" unit="deg">
					<commonPosition>0</commonPosition>
				</positions>
				<positions axis="Z" unit="mm">
					<commonPosition>8.386</commonPosition>
				</positions>
				<commonCountingTime unit="seconds">0.974</commonCountingTime>
[...]
				</positions>
				<positions axis="Z" unit="mm">
					<commonPosition>8.386</commonPosition>
				</positions>
				<commonCountingTime unit="seconds">0.974</commonCountingTime>
				<counts unit="counts">0 0 0 0 1 0 0 0 0 0 0 1 0 0 0 0 0 0 0 0 0 0 1 1 1 0 0 0 1 1 0 1 0 0 1 1 1 1 0 0 0 0 0 0 0 0 0 0 0 1 1 0 0 1 0 1 0 0 0 0 1 2 0 0 0 0 0 1 0 0 0 0 1 0 0 0 1 0 0 0 0 0 0 0 0 0 0 3 0 0 1 1 0 0 0 0 0 0 0 0 0 1 0 1 0 0 0 3 1 0 0 0 0 0 0 0 1 0 0 1 0 0 1 0 0 0 0 1 0 0 0 0 1 1 0 0 0 1 0 0 1 0 0 0 0 0 1 0 0 0 0 0 0 0 0 0 0 0 0 0 0 0 0 0 0 0 0 0 1 1 0 0 0 0 1 1 0 0 0 0 0 1 0 0 0 1 0 0 0 1 0 1 0 2 0 0 0 0 0 0 0 0 0 0 0 0 0 1 0 0 0 1 0 0 0 0 0 0 1 0 0 0 0 1 0 0 0 0 0 0 1 0 1 1 0 0 0 0 0 0 1 0 0 0 1 0 0 0 3 1 0 0 0 0 0</counts>
			</dataPoints>
		</scan>
		<scan status="Completed" appendNumber="0" scanAxis="2Theta" mode="Continuous">
			<header>
				<startTimeStamp>2024-07-03T14:43:28-04:00</startTimeStamp>
				<endTimeStamp>2024-07-03T15:13:30-04:00</endTimeStamp>
				<author>
					<name>lw627</name>
				</author>
				<source>
					<applicationSoftware version="7.1">Data Collector</applicationSoftware>
					<instrumentControlSoftware version="8.2  20201204">EMPYREAN</instrumentControlSoftware>
					<instrumentID>0000000011260721</instrumentID>
				</source>
			</header>
			<dataPoints>
				<positions axis="2Theta" unit="deg">
					<startPosition>77.3565547277105</startPosition>
					<endPosition>80.703824498927</endPosition>
				</positions>
				<positions axis="Omega" unit="deg">
					<commonPosition>20.8830948066594</commonPosition>
				</positions>
				<positions axis="Phi" unit="deg">
					<commonPosition>-176.8</commonPosition>
				</positions>
				<positions axis="Chi" unit="deg">
					<commonPosition>0</commonPosition>
				</positions>
				<positions axis="Z" unit="mm">
					<commonPosition>8.386</commonPosition>
				</positions>
				<commonCountingTime unit="seconds">0.974</commonCountingTime>
				<counts unit="counts">2 0 1 0 0 0 1 0 0 1 0 0 0 0 0 0 0 0 0 0 1 0 0 0 0 0 1 3 0 0 1 0 0 0 0 0 0 0 0 0 1 0 0 1 0 0 1 0 0 0 1 0 1 0 1 0 0 1 1 0 0 0 0 1 1 0 1 0 0 0 0 0 0 0 0 0 0 0 0 2 1 1 0 1 0 0 0 1 0 0 0 0 0 0 2 0 0 1 0 0 0 1 1 0 0 0 1 0 0 0 0 1 0 0 0 0 0 0 0 0 0 0 0 0 0 0 0 0 0 1 0 0 1 0 0 1 0 0 0 1 0 0 0 0 0 0 0 0 0 0 1 0 0 0 1 0 1 0 0 0 0 0 0 0 0 0 0 0 0 2 0 0 0 0 0 0 0 1 0 0 1 0 1 2 1 1 0 0 0 0 0 0 1 0 0 1 0 0 0 0 0 0 0 1 0 1 1 0 0 0 1 0 0 1 0 0 0 1 0 0 0 0 0 0 0 1 0 0 0 1 1 0 0 0 0 1 0 0 0 0 0 0 1 0 1 0 0 0 0 2 0 0 0 2 0</counts>
			</dataPoints>
		</scan>
		<scan status="Completed" appendNumber="0" scanAxis="2Theta" mode="Continuous">
			<header>
				<startTimeStamp>2024-07-03T14:43:28-04:00</startTimeStamp>
				<endTimeStamp>2024-07-03T15:13:30-04:00</endTimeStamp>
				<author>
					<name>lw627</name>
				</author>
				<source>
					<applicationSoftware version="7.1">Data Collector</applicationSoftware>
					<instrumentControlSoftware version="8.2  20201204">EMPYREAN</instrumentControlSoftware>
					<instrumentID>0000000011260721</instrumentID>
				</source>
			</header>
			<dataPoints>
				<positions axis="2Theta" unit="deg">
					<startPosition>77.3598372983786</startPosition>
					<endPosition>80.7071070695951</endPosition>
				</positions>
				<positions axis="Omega" unit="deg">
					<commonPosition>20.8847360919934</commonPosition>
				</positions>
				<positions axis="Phi" unit="deg">
					<commonPosition>-176.8</commonPosition>
				</positions>
				<positions axis="Chi" unit="deg">
					<commonPosition>0</commonPosition>
				</positions>
				<positions axis="Z" unit="mm">
					<commonPosition>8.386</commonPosition>
				</positions>
				<commonCountingTime unit="seconds">0.974</commonCountingTime>
				<counts unit="counts">0 1 1 0 0 0 0 0 0 2 0 1 1 0 1 0 0 1 0 1 0 0 0 0 0 0 1 0 0 0 0 0 1 1 0 0 0 2 0 0 0 0 1 0 1 0 0 0 0 0 0 0 0 0 0 0 1 1 0 1 1 0 0 0 0 1 0 1 0 0 0 0 0 0 0 0 1 1 0 0 0 1 0 0 0 0 0 0 0 0 1 0 1 0 0 0 1 0 0 1 2 0 0 0 0 0 0 0 0 0 0 0 0 0 0 0 1 0 0 0 0 0 1 0 1 0 0 0 0 0 0 1 0 1 0 1 2 0 0 0 0 0 0 0 0 0 0 0 0 0 0 0 0 0 0 0 0 1 1 0 0 0 0 1 0 0 0 0 0 0 0 0 1 0 1 0 1 1 0 0 1 0 0 1 0 1 0 0 0 1 0 0 1 0 0 1 0 0 0 0 2 2 0 0 0 0 1 0 1 0 0 0 1 0 0 1 0 0 0 0 0 0 0 1 0 0 0 0 0 0 1 0 0 1 1 0 0 0 0 2 0 1 0 0 1 0 2 1 1 1 0 0 1 0 1</counts>
			</dataPoints>
		</scan>
		<scan status="Completed" appendNumber="0" scanAxis="2Theta" mode="Continuous">
			<header>
				<startTimeStamp>2024-07-03T14:43:28-04:00</startTimeStamp>
				<endTimeStamp>2024-07-03T15:13:30-04:00</endTimeStamp>
				<author>
					<name>lw627</name>
				</author>
				<source>
					<applicationSoftware version="7.1">Data Collector</applicationSoftware>
					<instrumentControlSoftware version="8.2  20201204">EMPYREAN</instrumentControlSoftware>
					<instrumentID>0000000011260721</instrumentID>
				</source>
			</header>
			<dataPoints>
				<positions axis="2Theta" unit="deg">
					<startPosition>77.3631198690467</startPosition>
					<endPosition>80.7103896402632</endPosition>
				</positions>
				<positions axis="Omega" unit="deg">
					<commonPosition>20.8863773773275</commonPosition>
				</positions>
				<positions axis="Phi" unit="deg">
					<commonPosition>-176.8</commonPosition>
				</positions>
				<positions axis="Chi" unit="deg">
					<commonPosition>0</commonPosition>
				</positions>
				<positions axis="Z" unit="mm">
					<commonPosition>8.386</commonPosition>
				</positions>
				<commonCountingTime unit="seconds">0.974</commonCountingTime>
				<counts unit="counts">1 1 0 0 0 0 0 0 0 0 0 2 1 1 0 1 0 0 0 0 1 0 1 2 0 1 0 0 1 0 1 0 0 0 0 0 0 0 0 0 0 0 0 0 0 0 2 0 2 0 0 0 0 1 0 0 0 0 1 0 1 0 0 0 1 0 2 1 0 0 0 1 0 0 0 1 0 0 0 0 0 0 0 0 1 0 0 0 0 0 0 0 0 1 1 0 0 0 1 0 0 0 0 0 0 0 0 1 0 2 0 0 1 1 0 0 0 0 0 0 0 0 0 0 0 0 0 0 0 1 0 0 0 0 0 0 0 0 1 3 0 1 0 0 0 0 1 2 0 0 1 0 0 0 0 0 0 1 0 1 0 0 1 0 0 0 0 0 0 1 0 0 1 0 0 1 0 0 0 0 0 1 0 1 1 0 0 0 0 0 0 0 0 0 0 0 0 0 0 2 0 1 1 0 1 0 1 0 0 0 0 0 1 1 1 0 0 0 0 1 0 1 0 1 0 1 1 0 1 0 0 0 0 1 0 1 0 1 0 0 0 1 0 0 0 0 0 1 0 0 0 0 0 1 0</counts>
			</dataPoints>
		</scan>
		<scan status="Completed" appendNumber="0" scanAxis="2Theta" mode="Continuous">
			<header>
				<startTimeStamp>2024-07-03T14:43:28-04:00</startTimeStamp>
				<endTimeStamp>2024-07-03T15:13:30-04:00</endTimeStamp>
				<author>
					<name>lw627</name>
				</author>
				<source>
					<applicationSoftware version="7.1">Data Collector</applicationSoftware>
					<instrumentControlSoftware version="8.2  20201204">EMPYREAN</instrumentControlSoftware>
					<instrumentID>0000000011260721</instrumentID>
				</source>
			</header>
			<dataPoints>
				<positions axis="2Theta" unit="deg">
					<startPosition>77.3664024397149</startPosition>
					<endPosition>80.7136722109314</endPosition>
				</positions>
				<positions axis="Omega" unit="deg">
					<commonPosition>20.8880186626616</commonPosition>
				</positions>
				<positions axis="Phi" unit="deg">
					<commonPosition>-176.8</commonPosition>
				</positions>
				<positions axis="Chi" unit="deg">
					<commonPosition>0</commonPosition>
				</positions>
				<positions axis="Z" unit="mm">
					<commonPosition>8.386</commonPosition>
				</positions>
				<commonCountingTime unit="seconds">0.974</commonCountingTime>
				<counts unit="counts">0 0 1 1 0 0 0 1 0 0 0 1 0 2 0 0 1 1 1 1 0 1 0 0 1 0 0 0 0 0 0 0 0 0 1 1 0 0 0 0 0 1 0 0 0 0 0 1 1 0 0 0 0 0 0 0 0 0 0 1 0 0 1 0 0 0 0 0 0 1 0 1 1 0 1 0 0 1 0 0 0 0 2 1 2 0 0 0 0 0 0 0 0 0 0 0 0 0 0 0 1 0 0 0 0 2 0 0 0 0 1 1 0 0 0 0 0 0 1 0 0 0 1 0 1 0 0 0 0 0 0 0 1 1 0 0 2 0 0 0 0 0 0 0 1 0 0 0 0 0 0 0 0 0 0 1 1 0 0 0 1 0 0 0 0 0 2 0 2 1 0 0 0 0 0 0 2 1 0 0 0 0 0 0 0 0 1 0 0 1 0 1 1 0 1 0 0 0 0 0 0 0 1 0 1 0 0 0 0 1 0 0 0 0 0 0 0 0 0 1 0 0 0 0 0 0 0 1 2 0 0 1 0 0 0 0 1 0 0 0 0 0 1 0 1 0 0 0 0 1 2 0 0 0 1</counts>
			</dataPoints>
		</scan>
		<scan status="Completed" appendNumber="0" scanAxis="2Theta" mode="Continuous">
			<header>
				<startTimeStamp>2024-07-03T14:43:28-04:00</startTimeStamp>
				<endTimeStamp>2024-07-03T15:13:30-04:00</endTimeStamp>
				<author>
					<name>lw627</name>
				</author>
				<source>
					<applicationSoftware version="7.1">Data Collector</applicationSoftware>
					<instrumentControlSoftware version="8.2  20201204">EMPYREAN</instrumentControlSoftware>
					<instrumentID>0000000011260721</instrumentID>
				</source>
			</header>
			<dataPoints>
				<positions axis="2Theta" unit="deg">
					<startPosition>77.369685010383</startPosition>
					<endPosition>80.7169547815995</endPosition>
				</positions>
				<positions axis="Omega" unit="deg">
					<commonPosition>20.8896599479956</commonPosition>
				</positions>
				<positions axis="Phi" unit="deg">
					<commonPosition>-176.8</commonPosition>
				</positions>
				<positions axis="Chi" unit="deg">
					<commonPosition>0</commonPosition>
				</positions>
				<positions axis="Z" unit="mm">
					<commonPosition>8.386</commonPosition>
				</positions>
				<commonCountingTime unit="seconds">0.974</commonCountingTime>
				<counts unit="counts">0 0 0 0 1 1 0 0 0 0 1 1 1 1 2 1 0 0 1 0 0 0 1 1 1 0 0 0 0 1 0 1 0 0 1 1 0 1 1 0 1 1 0 0 0 1 0 0 1 0 0 0 0 1 1 1 0 0 1 0 0 1 0 0 0 1 0 0 0 0 0 1 0 0 0 1 0 0 0 1 0 1 0 0 0 0 0 0 0 1 1 0 0 0 1 0 0 0 0 1 0 0 0 1 0 0 1 0 0 1 0 0 0 0 0 1 0 0 1 0 0 1 0 2 0 0 1 0 1 0 1 0 0 0 0 0 0 1 1 0 0 0 0 0 0 0 0 0 0 0 0 0 0 0 0 0 0 1 0 0 1 0 0 0 1 0 0 0 0 0 0 1 0 0 0 0 0 0 0 0 1 0 0 0 0 0 0 0 0 0 0 0 0 0 0 1 1 0 0 0 2 0 1 0 0 1 0 2 1 1 0 0 0 0 0 0 0 0 0 0 0 0 0 0 0 0 0 0 0 1 0 1 0 0 0 0 0 0 0 0 1 0 0 1 1 0 0 0 0 0 0 0 0 0 0</counts>
			</dataPoints>
		</scan>
		<scan status="Completed" appendNumber="0" scanAxis="2Theta" mode="Continuous">
			<header>
				<startTimeStamp>2024-07-03T14:43:28-04:00</startTimeStamp>
				<endTimeStamp>2024-07-03T15:13:30-04:00</endTimeStamp>
				<author>
					<name>lw627</name>
				</author>
				<source>
					<applicationSoftware version="7.1">Data Collector</applicationSoftware>
					<instrumentControlSoftware version="8.2  20201204">EMPYREAN</instrumentControlSoftware>
					<instrumentID>0000000011260721</instrumentID>
				</source>
			</header>
			<dataPoints>
				<positions axis="2Theta" unit="deg">
					<startPosition>77.3729675810511</startPosition>
					<endPosition>80.7202373522676</endPosition>
				</positions>
				<positions axis="Omega" unit="deg">
					<commonPosition>20.8913012333297</commonPosition>
				</positions>
				<positions axis="Phi" unit="deg">
					<commonPosition>-176.8</commonPosition>
				</positions>
				<positions axis="Chi" unit="deg">
					<commonPosition>0</commonPosition>
				</positions>
				<positions axis="Z" unit="mm">
					<commonPosition>8.386</commonPosition>
				</positions>
				<commonCountingTime unit="seconds">0.974</commonCountingTime>
				<counts unit="counts">1 0 0 0 1 1 1 0 2 0 1 1 0 0 0 0 1 1 0 0 2 0 0 0 0 0 0 1 0 0 0 0 0 0 0 0 0 1 0 2 0 1 1 0 0 2 0 1 0 0 0 0 1 1 0 0 0 0 0 0 0 0 0 0 0 0 1 0 0 0 1 1 0 1 1 1 0 0 1 0 1 0 1 0 0 0 0 0 0 0 0 0 1 0 2 0 0 0 0 0 0 0 0 0 0 0 1 0 0 0 0 2 0 0 0 1 0 0 0 1 0 0 0 0 0 0 1 0 0 0 0 1 0 0 1 0 0 1 0 0 0 0 0 0 0 1 0 0 1 0 0 1 0 0 2 1 0 0 0 0 0 0 0 0 0 0 0 1 0 0 0 0 0 1 0 0 0 0 0 0 0 0 0 0 0 0 0 0 2 0 0 0 0 0 2 0 0 1 0 0 1 0 0 0 0 0 0 0 0 0 0 0 0 1 0 0 1 0 1 0 0 0 1 0 2 0 1 1 0 0 1 0 0 0 0 0 0 0 0 1 0 0 0 0 0 0 0 0 1 0 0 0 0 1 0</counts>
			</dataPoints>
		</scan>
		<scan status="Completed" appendNumber="0" scanAxis="2Theta" mode="Continuous">
			<header>
				<startTimeStamp>2024-07-03T14:43:28-04:00</startTimeStamp>
				<endTimeStamp>2024-07-03T15:13:30-04:00</endTimeStamp>
				<author>
					<name>lw627</name>
				</author>
				<source>
					<applicationSoftware version="7.1">Data Collector</applicationSoftware>
					<instrumentControlSoftware version="8.2  20201204">EMPYREAN</instrumentControlSoftware>
					<instrumentID>0000000011260721</instrumentID>
				</source>
			</header>
			<dataPoints>
				<positions axis="2Theta" unit="deg">
					<startPosition>77.3762501517193</startPosition>
					<endPosition>80.7235199229357</endPosition>
				</positions>
				<positions axis="Omega" unit="deg">
					<commonPosition>20.8929425186637</commonPosition>
				</positions>
				<positions axis="Phi" unit="deg">
					<commonPosition>-176.8</commonPosition>
				</positions>
				<positions axis="Chi" unit="deg">
					<commonPosition>0</commonPosition>
				</positions>
				<positions axis="Z" unit="mm">
					<commonPosition>8.386</commonPosition>
				</positions>
				<commonCountingTime unit="seconds">0.974</commonCountingTime>
				<counts unit="counts">0 0 0 2 0 0 0 1 0 0 0 0 1 0 1 0 1 0 0 0 1 0 0 2 1 0 2 0 1 0 0 0 0 1 0 0 2 1 0 0 0 0 0 1 1 1 0 2 1 0 0 0 0 0 0 1 0 0 1 0 1 1 1 0 0 0 0 0 0 0 0 0 1 0 1 0 3 0 0 0 0 0 0 0 0 0 0 0 0 0 0 0 2 0 1 0 0 0 0 0 0 0 0 0 0 0 0 0 2 0 2 0 0 0 0 0 0 0 1 1 0 0 0 0 1 0 0 1 1 0 0 0 0 0 0 0 0 0 0 0 0 0 0 1 0 0 0 1 2 0 2 0 1 1 1 0 1 0 0 0 1 0 0 0 0 0 0 0 0 0 0 0 0 0 0 0 0 0 2 0 0 0 0 0 1 1 0 0 0 0 0 1 0 0 0 0 1 0 1 0 0 0 0 0 0 0 1 0 0 1 1 0 0 1 0 0 1 0 0 0 0 0 1 0 0 0 0 0 0 0 1 0 0 0 0 0 0 0 0 0 0 0 0 0 0 0 0 0 0 0 0 1 0 0 0</counts>
			</dataPoints>
		</scan>
		<scan status="Completed" appendNumber="0" scanAxis="2Theta" mode="Continuous">
			<header>
				<startTimeStamp>2024-07-03T14:43:28-04:00</startTimeStamp>
				<endTimeStamp>2024-07-03T15:13:30-04:00</endTimeStamp>
				<author>
					<name>lw627</name>
				</author>
				<source>
					<applicationSoftware version="7.1">Data Collector</applicationSoftware>
					<instrumentControlSoftware version="8.2  20201204">EMPYREAN</instrumentControlSoftware>
					<instrumentID>0000000011260721</instrumentID>
				</source>
			</header>
			<dataPoints>
				<positions axis="2Theta" unit="deg">
					<startPosition>77.3795327223874</startPosition>
					<endPosition>80.7268024936039</endPosition>
				</positions>
				<positions axis="Omega" unit="deg">
					<commonPosition>20.8945838039978</commonPosition>
				</positions>
				<positions axis="Phi" unit="deg">
					<commonPosition>-176.8</commonPosition>
				</positions>
				<positions axis="Chi" unit="deg">
					<commonPosition>0</commonPosition>
				</positions>
				<positions axis="Z" unit="mm">
					<commonPosition>8.386</commonPosition>
				</positions>
				<commonCountingTime unit="seconds">0.974</commonCountingTime>
				<counts unit="counts">0 1 0 1 0 0 0 0 1 2 3 0 0 0 1 2 0 1 0 1 0 0 0 0 0 0 0 0 0 0 0 0 1 0 1 0 0 0 1 0 0 0 1 0 1 0 0 1 0 1 1 1 2 0 1 0 0 1 0 0 0 1 1 3 2 0 1 0 0 1 0 1 0 1 0 1 0 1 1 3 0 1 0 0 0 1 0 2 1 0 1 0 1 0 1 0 0 1 2 1 0 0 0 0 1 1 0 0 1 0 0 0 0 0 1 1 0 0 0 0 0 1 0 1 0 0 1 0 0 0 1 2 2 1 0 2 0 0 0 0 1 0 0 1 0 2 0 1 0 1 0 0 2 0 0 0 0 1 1 0 0 0 0 2 0 0 0 0 1 0 1 0 0 0 1 0 0 0 1 1 1 0 2 0 0 0 0 0 1 0 0 0 0 0 0 0 0 1 0 1 0 0 0 0 1 0 0 1 2 1 0 2 0 0 1 0 1 0 0 0 0 0 1 0 0 0 0 0 0 0 0 0 0 2 0 0 0 0 0 0 0 0 0 0 0 0 0 1 0 0 0 0 0 0 0</counts>
			</dataPoints>
		</scan>
		<scan status="Completed" appendNumber="0" scanAxis="2Theta" mode="Continuous">
			<header>
				<startTimeStamp>2024-07-03T14:43:28-04:00</startTimeStamp>
				<endTimeStamp>2024-07-03T15:13:30-04:00</endTimeStamp>
				<author>
					<name>lw627</name>
				</author>
				<source>
					<applicationSoftware version="7.1">Data Collector</applicationSoftware>
					<instrumentControlSoftware version="8.2  20201204">EMPYREAN</instrumentControlSoftware>
					<instrumentID>0000000011260721</instrumentID>
				</source>
			</header>
			<dataPoints>
				<positions axis="2Theta" unit="deg">
					<startPosition>77.3828152930555</startPosition>
					<endPosition>80.730085064272</endPosition>
				</positions>
				<positions axis="Omega" unit="deg">
					<commonPosition>20.8962250893319</commonPosition>
				</positions>
				<positions axis="Phi" unit="deg">
					<commonPosition>-176.8</commonPosition>
				</positions>
				<positions axis="Chi" unit="deg">
					<commonPosition>0</commonPosition>
				</positions>
				<positions axis="Z" unit="mm">
					<commonPosition>8.386</commonPosition>
				</positions>
				<commonCountingTime unit="seconds">0.974</commonCountingTime>
				<counts unit="counts">1 1 0 0 0 0 1 0 0 0 2 0 1 0 1 0 0 0 0 0 0 0 0 0 1 0 1 1 0 0 0 1 0 0 1 1 0 0 0 0 0 2 0 0 0 1 1 1 0 0 0 1 1 0 0 0 1 0 1 0 0 0 0 1 0 0 0 1 1 0 1 0 1 0 0 1 1 0 0 1 0 0 0 0 0 0 0 0 0 0 0 0 1 1 1 0 0 2 0 0 1 1 2 0 0 0 0 1 0 1 1 0 0 0 0 1 0 1 0 0 0 0 0 0 0 0 1 0 0 1 0 1 0 0 0 0 1 0 1 1 0 0 0 0 0 0 0 0 0 0 0 0 0 0 1 1 0 1 0 0 0 0 0 0 0 0 1 0 0 0 1 0 0 0 1 0 2 0 0 0 0 0 0 0 2 0 0 0 0 0 0 0 0 0 0 0 0 0 2 0 0 0 0 1 1 0 0 0 1 0 0 0 0 0 0 0 0 0 0 0 0 0 0 1 0 0 0 0 2 0 0 1 0 0 0 0 0 0 0 1 0 0 1 0 0 0 0 0 0 0 1 0 0 0 0</counts>
			</dataPoints>
		</scan>
		<scan status="Completed" appendNumber="0" scanAxis="2Theta" mode="Continuous">
			<header>
				<startTimeStamp>2024-07-03T14:43:28-04:00</startTimeStamp>
				<endTimeStamp>2024-07-03T15:13:30-04:00</endTimeStamp>
				<author>
					<name>lw627</name>
				</author>
				<source>
					<applicationSoftware version="7.1">Data Collector</applicationSoftware>
					<instrumentControlSoftware version="8.2  20201204">EMPYREAN</instrumentControlSoftware>
					<instrumentID>0000000011260721</instrumentID>
				</source>
			</header>
			<dataPoints>
				<positions axis="2Theta" unit="deg">
					<startPosition>77.3860978637236</startPosition>
					<endPosition>80.7333676349401</endPosition>
				</positions>
				<positions axis="Omega" unit="deg">
					<commonPosition>20.8978663746659</commonPosition>
				</positions>
				<positions axis="Phi" unit="deg">
					<commonPosition>-176.8</commonPosition>
				</positions>
				<positions axis="Chi" unit="deg">
					<commonPosition>0</commonPosition>
				</positions>
				<positions axis="Z" unit="mm">
					<commonPosition>8.386</commonPosition>
				</positions>
				<commonCountingTime unit="seconds">0.974</commonCountingTime>
				<counts unit="counts">1 0 2 0 1 0 0 1 2 0 1 1 0 0 0 0 1 0 0 2 0 0 1 0 0 0 1 1 0 0 0 0 0 0 0 2 0 0 0 0 0 1 0 0 1 0 0 0 1 0 1 0 0 0 0 1 2 0 1 0 0 1 0 1 0 0 0 0 1 1 0 0 0 1 0 0 1 0 1 0 0 0 0 0 0 0 0 0 0 0 1 1 1 1 0 0 2 1 1 0 0 1 0 0 0 0 0 1 0 1 0 0 0 1 0 1 0 0 0 0 0 0 1 0 0 0 0 1 0 0 0 0 0 0 0 0 0 1 0 0 0 1 0 0 0 0 0 0 0 0 0 0 0 0 0 0 0 0 0 0 0 0 1 0 0 0 0 0 1 0 0 0 1 0 0 0 0 0 1 1 0 0 1 0 1 0 0 0 0 0 0 0 0 0 0 0 0 1 0 0 1 0 1 0 0 0 2 0 1 0 1 0 1 0 0 0 0 1 1 0 0 0 0 0 0 1 0 0 0 0 1 1 0 0 0 0 0 0 0 0 0 0 2 0 1 1 0 0 0 0 1 0 1 0 0</counts>
			</dataPoints>
		</scan>
		<scan status="Completed" appendNumber="0" scanAxis="2Theta" mode="Continuous">
			<header>
				<startTimeStamp>2024-07-03T14:43:28-04:00</startTimeStamp>
				<endTimeStamp>2024-07-03T15:13:30-04:00</endTimeStamp>
				<author>
					<name>lw627</name>
				</author>
				<source>
					<applicationSoftware version="7.1">Data Collector</applicationSoftware>
					<instrumentControlSoftware version="8.2  20201204">EMPYREAN</instrumentControlSoftware>
					<instrumentID>0000000011260721</instrumentID>
				</source>
			</header>
			<dataPoints>
				<positions axis="2Theta" unit="deg">
					<startPosition>77.3893804343918</startPosition>
					<endPosition>80.7366502056082</endPosition>
				</positions>
				<positions axis="Omega" unit="deg">
					<commonPosition>20.89950766</commonPosition>
				</positions>
				<positions axis="Phi" unit="deg">
					<commonPosition>-176.8</commonPosition>
				</positions>
				<positions axis="Chi" unit="deg">
					<commonPosition>0</commonPosition>
				</positions>
				<positions axis="Z" unit="mm">
					<commonPosition>8.386</commonPosition>
				</positions>
				<commonCountingTime unit="seconds">0.974</commonCountingTime>
				<counts unit="counts">0 0 1 1 1 0 1 0 0 0 0 0 0 1 0 1 0 0 0 0 0 0 2 0 0 0 0 0 1 0 1 0 0 0 1 0 1 0 0 0 0 0 0 0 0 0 1 0 2 0 0 0 0 0 0 0 0 0 0 0 0 0 1 0 0 0 0 1 1 0 1 0 0 0 0 0 0 0 0 0 0 0 2 1 0 0 1 1 1 0 0 1 1 1 0 0 0 1 0 1 0 0 0 0 0 0 0 0 0 0 0 0 0 0 0 0 0 0 0 2 0 0 0 0 0 0 0 0 0 0 1 0 1 0 1 0 0 1 1 0 0 1 1 0 0 0 0 0 1 0 1 0 0 0 0 0 0 0 0 0 0 0 2 1 0 0 0 0 0 0 0 1 0 2 0 0 0 0 1 1 0 0 0 1 0 0 0 0 0 1 2 0 0 0 0 0 0 0 1 0 0 1 0 1 0 0 0 0 0 0 0 0 1 0 0 0 0 0 0 0 0 0 0 0 0 0 1 0 1 0 0 0 0 0 0 0 0 1 0 0 1 0 1 0 1 0 0 0 0 0 0 0 0 1 4</counts>
			</dataPoints>
		</scan>
	</xrdMeasurement>
</xrdMeasurements>