File: data/YY189_RSM_240 332 420/YY189_RSM 332 slow.xrdml
<?xml version="1.0" encoding="utf-8"?>
<xrdMeasurements xmlns="http://www.xrdml.com/XRDMeasurement/2.2" xmlns:xsi="http://www.w3.org/2001/XMLSchema-instance" xsi:schemaLocation="http://www.xrdml.com/XRDMeasurement/2.2 http://www.xrdml.com/XRDMeasurement/2.2/XRDMeasurement.xsd" status="Completed">
	<comment>
		<entry>Configuration=3-axes Cradle_Reflection, Owner=User, Creation date=9/2/2021 3:55:24 PM</entry>
		<entry>Goniometer=Theta/Theta; Minimum step size 2Theta:0.0001; Minimum step size Omega:0.0001</entry>
		<entry>Sample stage=Chi-Phi-z stage 240 mm (reflection); Minimum step size Phi:0.01; Minimum step size Chi:0.01; Minimum step size Z:0.001</entry>
		<entry>Diffractometer system=EMPYREAN</entry>
		<entry>Measurement program=C:\PANalytical\Data Collector\Programs\Yu Yun\RSM\RSM 2degree_high resolution_ultra slow.xrdmp, Identifier={E7FADADD-DC24-46CD-AE09-8DCC8F7825B3}</entry>
	</comment>
	<sample type="To be analyzed">
		<id/>
		<name/>
		<preparedBy/>
	</sample>
	<xrdMeasurement status="Completed" measurementType="Area measurement" measurementStepAxis="Omega-2Theta" sampleMode="Reflection">
		<comment>
			<entry>PHD Lower Level = 4.02 (keV), PHD Upper Level = 11.26 (keV)</entry>
		</comment>
		<usedWavelength intended="K-Alpha">
			<kAlpha1 unit="Angstrom">1.5405980</kAlpha1>
			<kAlpha2 unit="Angstrom">1.5444260</kAlpha2>
			<kBeta unit="Angstrom">1.3922500</kBeta>
			<ratioKAlpha2KAlpha1>0</ratioKAlpha2KAlpha1>
		</usedWavelength>
		<incidentBeamPath>
			<radius unit="mm">240.00</radius>
			<xRayTube id="1010048" name="Empyrean Cu LFF HR (9430 033 7310x) DK432574">
				<tension unit="kV">45.0</tension>
				<current unit="mA">40.0</current>
				<anodeMaterial>Cu</anodeMaterial>
				<focus type="Line">
					<length unit="mm">12.0</length>
					<width unit="mm">0.4</width>
					<takeOffAngle unit="deg">4.4</takeOffAngle>
				</focus>
			</xRayTube>
			<xRayMirror xsi:type="xRayMirrorType" id="27080001" name="Inc. Beam Cu W/Si (hybrid MPD)" hybrid="true">
				<crystal type="Graded" shape="Parabolic">W/Si</crystal>
				<acceptanceAngle unit="deg">0.800</acceptanceAngle>
				<length unit="mm">55.3</length>
			</xRayMirror>
			<monochromator xsi:type="monochromatorType" id="23090002" name="Hybrid monochr. 2xGe220 Cu asym." hybrid="true">
				<crystal type="Asymmetric" shape="Flat">Ge</crystal>
				<numberOfReflections>2</numberOfReflections>
				<hkl>
					<h>2</h>
					<k>2</k>
					<l>0</l>
				</hkl>
			</monochromator>
			<mask xsi:type="maskType" id="22030008" name="Fixed mask 4 mm">
				<distanceToSample unit="mm">171.00</distanceToSample>
				<width unit="mm">4.00</width>
			</mask>
			<divergenceSlit xsi:type="fixedDivergenceSlitType" id="22010007" name="Fixed slit 1/8°">
				<distanceToSample unit="mm">179.30</distanceToSample>
				<height unit="mm">0.19</height>
			</divergenceSlit>
		</incidentBeamPath>
		<diffractedBeamPath>
			<radius unit="mm">240.00</radius>
			<antiScatterSlit xsi:type="fixedAntiScatterSlitType" id="22060009" name="Programmable anti-scatter slit">
				<angle unit="deg">4</angle>
			</antiScatterSlit>
			<detector xsi:type="areaDetectorType" id="7010020" name="PIXcel3D-Medipix3 1x1 detector">
				<phd unit="%">
					<lowerLevel>25</lowerLevel>
					<upperLevel>70</upperLevel>
				</phd>
				<mode>Scanning snapshot equatorial</mode>
				<activeChannelsEquatorial>255</activeChannelsEquatorial>
				<activeChannelsAxial>255</activeChannelsAxial>
				<pitchEquatorial unit="mm">0.05500</pitchEquatorial>
				<pitchAxial unit="mm">0.05500</pitchAxial>
				<readOutPeriod unit="seconds">0.790</readOutPeriod>
			</detector>
		</diffractedBeamPath>
		<scan status="Completed" appendNumber="0" scanAxis="2Theta" mode="Continuous">
			<header>
				<startTimeStamp>2023-01-13T16:56:26-05:00</startTimeStamp>
				<endTimeStamp>2023-01-13T17:12:39-05:00</endTimeStamp>
				<author>
					<name>User</name>
				</author>
				<source>
					<applicationSoftware version="7.1">Data Collector</applicationSoftware>
					<instrumentControlSoftware version="8.2  20201204">EMPYREAN</instrumentControlSoftware>
					<instrumentID>0000000011260721</instrumentID>
				</source>
			</header>
			<dataPoints>
				<positions axis="2Theta" unit="deg">
					<startPosition>71.2226063943918</startPosition>
					<endPosition>74.5698761656082</endPosition>
				</positions>
				<positions axis="Omega" unit="deg">
					<commonPosition>17.96472064</commonPosition>
				</positions>
				<positions axis="Phi" unit="deg">
					<commonPosition>-86.42</commonPosition>
				</positions>
				<positions axis="Chi" unit="deg">
					<commonPosition>0</commonPosition>
				</positions>
				<positions axis="Z" unit="mm">
					<commonPosition>8.428</commonPosition>
				</positions>
				<commonCountingTime unit="seconds">0.784</commonCountingTime>
				<counts unit="counts">0 0 0 0 0 0 0 1 1 0 1 0 0 0 0 0 0 2 0 0 0 0 1 0 0 0 2 2 0 0 1 1 0 0 0 0 2 1 2 2 0 0 0 0 0 0 1 0 1 0 2 0 0 0 0 1 0 0 1 1 1 0 1 0 0 1 1 0 0 0 1 0 0 0 1 1 0 0 0 0 0 0 0 0 0 0 0 0 0 1 0 0 0 0 0 0 0 1 0 0 2 1 0 0 0 0 1 0 1 0 1 0 0 0 0 1 0 0 1 0 1 0 0 1 0 0 1 0 0 1 0 0 1 0 1 1 0 0 1 0 0 2 0 0 0 0 0 0 0 1 0 1 0 0 0 1 1 0 0 0 0 1 0 0 0 0 7 6 3 1 0 0 0 1 2 0 1 1 1 0 1 1 0 1 2 0 0 0 0 0 1 0 1 0 0 1 1 1 1 0 0 0 0 0 0 1 0 1 0 0 1 0 1 1 0 1 0 0 1 1 0 0 1 1 0 0 0 1 2 2 0 0 0 1 0 0 0 0 0 0 0 1 0 0 0 1 0 0 1 0 2 0 0 2 1</counts>
			</dataPoints>
		</scan>
		<scan status="Completed" appendNumber="0" scanAxis="2Theta" mode="Continuous">
			<header>
				<startTimeStamp>2023-01-13T16:56:26-05:00</startTimeStamp>
				<endTimeStamp>2023-01-13T17:12:39-05:00</endTimeStamp>
				<author>
					<name>User</name>
				</author>
				<source>
					<applicationSoftware version="7.1">Data Collector</applicationSoftware>
					<instrumentControlSoftware version="8.2  20201204">EMPYREAN</instrumentControlSoftware>
					<instrumentID>0000000011260721</instrumentID>
				</source>
			</header>
			<dataPoints>
				<positions axis="2Theta" unit="deg">
					<startPosition>71.2258889650661</startPosition>
					<endPosition>74.5731587362826</endPosition>
				</positions>
				<positions axis="Omega" unit="deg">
					<commonPosition>17.9663619253372</commonPosition>
				</positions>
				<positions axis="Phi" unit="deg">
					<commonPosition>-86.42</commonPosition>
				</positions>
				<positions axis="Chi" unit="deg">
					<commonPosition>0</commonPosition>
				</positions>
				<positions axis="Z" unit="mm">
					<commonPosition>8.428</commonPosition>
				</positions>
				<commonCountingTime unit="seconds">0.784</commonCountingTime>
				<counts unit="counts">0 0 0 0 0 0 0 0 1 2 0 1 0 0 0 0 0 0 0 0 0 3 0 0 0 1 0 1 1 1 0 0 0 0 0 1 0 1 0 0 0 1 1 1 2 0 1 0 2 1 0 0 0 0 0 0 0 0 0 0 1 0 0 0 0 1 0 0 0 1 0 0 1 0 0 0 2 2 0 1 0 1 1 0 0 0 0 1 0 0 0 1 1 1 0 0 0 0 1 0 0 1 0 1 0 1 0 1 2 0 2 0 0 1 1 0 0 0 0 0 0 0 0 0 0 1 0 0 0 0 1 0 0 0 0 0 1 1 0 0 0 0 0 0 0 0 0 0 0 0 0 0 1 0 0 2 0 0 0 0 0 0 0 2 1 3 4 3 3 2 1 0 0 0 0 0 0 0 0 0 0 0 0 0 0 0 1 1 0 0 1 0 0 0 2 0 0 1 0 0 0 1 1 1 0 1 0 0 0 0 1 0 0 0 0 0 0 0 1 0 0 0 0 0 1 0 1 0 0 1 0 0 0 0 0 0 0 1 0 3 0 0 0 0 1 0 0 0 0 1 1 2 0 0 1</counts>
			</dataPoints>
		</scan>
		<scan status="Completed" appendNumber="0" scanAxis="2Theta" mode="Continuous">
			<header>
				<startTimeStamp>2023-01-13T16:56:26-05:00</startTimeStamp>
				<endTimeStamp>2023-01-13T17:12:39-05:00</endTimeStamp>
				<author>
					<name>User</name>
				</author>
				<source>
					<applicationSoftware version="7.1">Data Collector</applicationSoftware>
					<instrumentControlSoftware version="8.2  20201204">EMPYREAN</instrumentControlSoftware>
					<instrumentID>0000000011260721</instrumentID>
				</source>
			</header>
			<dataPoints>
				<positions axis="2Theta" unit="deg">
					<startPosition>71.2291715357404</startPosition>
					<endPosition>74.5764413069569</endPosition>
				</positions>
				<positions axis="Omega" unit="deg">
					<commonPosition>17.9680032106743</commonPosition>
				</positions>
				<positions axis="Phi" unit="deg">
					<commonPosition>-86.42</commonPosition>
				</positions>
				<positions axis="Chi" unit="deg">
					<commonPosition>0</commonPosition>
				</positions>
				<positions axis="Z" unit="mm">
					<commonPosition>8.428</commonPosition>
				</positions>
				<commonCountingTime unit="seconds">0.784</commonCountingTime>
				<counts unit="counts">0 0 0 1 0 0 1 1 0 2 0 0 0 0 1 0 0 1 1 1 0 0 0 1 0 0 0 0 0 0 0 1 0 0 1 1 0 1 0 1 0 1 0 0 0 0 0 0 1 0 0 1 1 0 0 0 0 0 0 0 0 0 0 0 1 0 0 0 0 0 1 1 0 0 0 1 0 0 0 1 0 0 0 0 0 0 2 1 0 1 0 0 0 2 0 0 1 1 1 0 0 0 0 0 0 1 0 1 3 1 1 1 0 0 2 0 0 0 1 0 0 0 1 0 0 0 0 1 0 1 0 1 0 0 0 0 0 1 0 0 2 0 0 0 0 2 0 0 0 1 0 1 0 1 1 0 1 0 1 0 1 1 2 2 2 4 1 2 6 3 2 0 1 1 1 1 0 1 0 1 0 0 2 1 0 0 0 0 0 0 0 0 2 0 0 0 0 0 0 0 1 2 1 0 1 0 0 1 2 0 0 0 0 1 0 0 0 0 1 0 1 0 0 0 0 0 1 0 0 1 0 1 0 0 1 1 1 0 0 0 0 0 0 0 2 0 0 1 1 0 1 1 1 0 0</counts>
			</dataPoints>
		</scan>
		<scan status="Completed" appendNumber="0" scanAxis="2Theta" mode="Continuous">
			<header>
				<startTimeStamp>2023-01-13T16:56:26-05:00</startTimeStamp>
				<endTimeStamp>2023-01-13T17:12:39-05:00</endTimeStamp>
				<author>
					<name>User</name>
				</author>
				<source>
					<applicationSoftware version="7.1">Data Collector</applicationSoftware>
					<instrumentControlSoftware version="8.2  20201204">EMPYREAN</instrumentControlSoftware>
					<instrumentID>0000000011260721</instrumentID>
				</source>
			</header>
			<dataPoints>
				<positions axis="2Theta" unit="deg">
					<startPosition>71.2324541064148</startPosition>
					<endPosition>74.5797238776313</endPosition>
				</positions>
				<positions axis="Omega" unit="deg">
					<commonPosition>17.9696444960115</commonPosition>
				</positions>
				<positions axis="Phi" unit="deg">
					<commonPosition>-86.42</commonPosition>
				</positions>
				<positions axis="Chi" unit="deg">
					<commonPosition>0</commonPosition>
				</positions>
				<positions axis="Z" unit="mm">
					<commonPosition>8.428</commonPosition>
				</positions>
				<commonCountingTime unit="seconds">0.784</commonCountingTime>
				<counts unit="counts">0 0 0 0 0 1 2 0 0 0 1 0 0 0 1 0 0 1 1 0 0 0 0 1 0 1 1 2 0 1 0 0 0 0 0 0 0 0 0 0 0 0 0 0 1 0 0 2 0 1 0 0 2 0 0 0 0 0 0 0 1 1 1 0 0 1 0 0 0 0 0 0 0 0 2 0 1 0 1 1 1 1 1 2 1 1 0 1 0 1 0 0 1 0 0 0 1 0 0 0 0 0 0 0 0 0 0 0 0 0 0 1 0 0 2 3 2 1 1 2 0 0 0 0 0 0 0 0 0 0 0 1 1 1 1 0 0 0 0 0 2 0 1 1 0 1 0 0 0 0 0 0 0 0 1 1 0 0 0 0 0 0 0 1 1 3 2 4 2 2 0 3 1 0 0 1 0 2 0 0 1 1 0 1 0 1 1 1 0 0 0 1 0 0 1 1 0 0 1 0 1 2 3 1 1 1 0 1 0 0 3 0 1 1 1 0 0 0 0 0 0 1 2 0 0 1 1 0 0 0 1 2 0 0 0 1 1 0 0 0 0 1 0 0 0 0 1 0 1 0 0 0 1 0 0</counts>
			</dataPoints>
		</scan>
		<scan status="Completed" appendNumber="0" scanAxis="2Theta" mode="Continuous">
			<header>
				<startTimeStamp>2023-01-13T16:56:26-05:00</startTimeStamp>
				<endTimeStamp>2023-01-13T17:12:39-05:00</endTimeStamp>
				<author>
					<name>User</name>
				</author>
				<source>
					<applicationSoftware version="7.1">Data Collector</applicationSoftware>
					<instrumentControlSoftware version="8.2  20201204">EMPYREAN</instrumentControlSoftware>
					<instrumentID>0000000011260721</instrumentID>
				</source>
			</header>
			<dataPoints>
				<positions axis="2Theta" unit="deg">
					<startPosition>71.2357366770891</startPosition>
					<endPosition>74.5830064483056</endPosition>
				</positions>
				<positions axis="Omega" unit="deg">
					<commonPosition>17.9712857813487</commonPosition>
				</positions>
				<positions axis="Phi" unit="deg">
					<commonPosition>-86.42</commonPosition>
				</positions>
				<positions axis="Chi" unit="deg">
					<commonPosition>0</commonPosition>
				</positions>
				<positions axis="Z" unit="mm">
					<commonPosition>8.428</commonPosition>
				</positions>
				<commonCountingTime unit="seconds">0.784</commonCountingTime>
				<counts unit="counts">1 1 0 0 0 1 1 1 0 1 0 1 1 0 0 0 0 0 1 0 1 2 0 0 0 0 1 0 0 1 0 0 0 1 0 0 0 0 0 2 0 0 0 0 0 0 0 1 0 0 0 0 0 0 0 0 3 0 0 1 1 0 1 0 0 1 0 1 0 0 0 0 0 0 2 0 1 2 1 1 0 0 0 0 0 0 1 1 0 0 1 0 1 1 1 0 0 1 0 0 2 1 0 2 1 0 0 1 0 0 0 1 0 1 0 0 0 0 1 1 2 0 0 0 1 0 0 0 0 0 0 0 0 1 2 0 1 1 0 0 0 1 0 0 0 1 1 0 0 1 0 0 1 0 0 0 0 0 0 0 0 0 1 0 3 5 4 1 3 1 2 0 0 0 0 0 0 0 1 1 0 2 0 0 0 2 0 0 0 0 1 0 0 0 1 0 0 1 0 0 0 0 0 0 0 1 0 0 1 1 0 0 0 0 1 0 1 2 1 0 0 0 0 0 0 0 0 0 1 1 1 0 0 1 0 1 0 0 0 0 0 0 0 0 0 0 2 0 1 0 0 2 0 0 0</counts>
			</dataPoints>
		</scan>
		<scan status="Completed" appendNumber="0" scanAxis="2Theta" mode="Continuous">
			<header>
				<startTimeStamp>2023-01-13T16:56:26-05:00</startTimeStamp>
				<endTimeStamp>2023-01-13T17:12:39-05:00</endTimeStamp>
				<author>
					<name>User</name>
				</author>
				<source>
					<applicationSoftware version="7.1">Data Collector</applicationSoftware>
					<instrumentControlSoftware version="8.2  20201204">EMPYREAN</instrumentControlSoftware>
					<instrumentID>0000000011260721</instrumentID>
				</source>
			</header>
			<dataPoints>
				<positions axis="2Theta" unit="deg">
					<startPosition>71.2390192477635</startPosition>
					<endPosition>74.58628901898</endPosition>
				</positions>
				<positions axis="Omega" unit="deg">
					<commonPosition>17.9729270666859</commonPosition>
				</positions>
				<positions axis="Phi" unit="deg">
					<commonPosition>-86.42</commonPosition>
				</positions>
				<positions axis="Chi" unit="deg">
					<commonPosition>0</commonPosition>
				</positions>
				<positions axis="Z" unit="mm">
					<commonPosition>8.428</commonPosition>
				</positions>
				<commonCountingTime unit="seconds">0.784</commonCountingTime>
				<counts unit="counts">1 0 1 2 0 0 0 0 0 1 1 0 0 0 0 0 1 0 0 0 0 0 0 1 1 0 0 0 0 2 0 1 2 0 0 0 0 0 0 1 0 1 0 0 0 0 1 0 0 1 0 0 0 0 0 1 1 0 1 0 0 0 0 1 0 0 0 0 0 0 1 0 0 0 0 1 0 1 0 1 0 0 0 0 0 0 0 2 0 0 1 0 1 1 0 0 0 0 0 0 0 0 0 1 0 0 1 0 0 0 1 0 1 0 0 0 0 0 1 0 0 1 1 0 0 0 0 1 0 0 1 0 0 0 1 0 1 0 1 0 0 2 1 0 0 0 1 1 3 1 0 0 1 1 1 1 0 0 0 1 0 1 0 0 4 3 1 4 1 1 3 0 1 0 0 0 0 0 0 0 0 0 1 0 0 0 0 0 0 0 0 0 0 0 0 0 0 0 0 1 0 1 1 1 1 0 0 0 0 0 0 1 0 0 1 0 2 0 0 1 0 0 0 1 0 1 0 1 0 0 2 0 0 0 0 0 0 0 0 0 0 4 0 2 0 0 0 0 1 0 1 0 0 1 0</counts>
			</dataPoints>
		</scan>
		<scan status="Completed" appendNumber="0" scanAxis="2Theta" mode="Continuous">
			<header>
				<startTimeStamp>2023-01-13T16:56:26-05:00</startTimeStamp>
				<endTimeStamp>2023-01-13T17:12:39-05:00</endTimeStamp>
				<author>
					<name>User</name>
				</author>
				<source>
					<applicationSoftware version="7.1">Data Collector</applicationSoftware>
					<instrumentControlSoftware version="8.2  20201204">EMPYREAN</instrumentControlSoftware>
					<instrumentID>0000000011260721</instrumentID>
				</source>
			</header>
			<dataPoints>
				<positions axis="2Theta" unit="deg">
					<startPosition>71.2423018184378</startPosition>
					<endPosition>74.5895715896543</endPosition>
				</positions>
				<positions axis="Omega" unit="deg">
					<commonPosition>17.974568352023</commonPosition>
				</positions>
				<positions axis="Phi" unit="deg">
					<commonPosition>-86.42</commonPosition>
				</positions>
				<positions axis="Chi" unit="deg">
					<commonPosition>0</commonPosition>
				</positions>
				<positions axis="Z" unit="mm">
					<commonPosition>8.428</commonPosition>
				</positions>
				<commonCountingTime unit="seconds">0.784</commonCountingTime>
				<counts unit="counts">0 1 0 0 0 1 1 1 0 0 0 0 1 0 0 1 1 1 1 1 0 2 0 0 0 0 0 0 1 2 0 0 0 1 1 1 1 0 0 3 0 0 0 1 1 1 0 0 0 0 1 0 0 0 0 0 0 2 0 1 0 2 0 1 0 1 0 0 1 0 1 0 0 0 0 0 0 0 0 0 2 0 0 2 0 0 0 0 0 0 0 0 0 0 0 0 0 0 0 1 0 0 0 0 0 1 0 0 0 0 0 1 0 1 1 0 0 0 0 0 0 1 1 0 0 0 0 1 0 0 1 0 0 0 1 0 1 2 1 0 1 0 1 1 0 0 1 1 1 0 1 0 1 0 0 1 1 0 1 1 0 0 1 2 4 2 7 7 4 1 0 0 0 0 0 1 1 0 0 0 0 0 0 0 0 0 0 0 1 0 0 0 1 0 0 0 0 0 2 0 0 0 1 2 2 1 0 0 0 0 0 2 0 0 0 0 0 0 0 1 0 0 1 0 1 1 0 1 0 0 0 0 0 2 0 0 0 0 1 0 0 0 3 1 0 0 0 0 0 0 0 0 0 0 1</counts>
			</dataPoints>
		</scan>
		<scan status="Completed" appendNumber="0" scanAxis="2Theta" mode="Continuous">
			<header>
				<startTimeStamp>2023-01-13T16:56:26-05:00</startTimeStamp>
				<endTimeStamp>2023-01-13T17:12:39-05:00</endTimeStamp>
				<author>
					<name>User</name>
				</author>
				<source>
					<applicationSoftware version="7.1">Data Collector</applicationSoftware>
					<instrumentControlSoftware version="8.2  20201204">EMPYREAN</instrumentControlSoftware>
					<instrumentID>0000000011260721</instrumentID>
				</source>
			</header>
			<dataPoints>
				<positions axis="2Theta" unit="deg">
					<startPosition>71.2455843891122</startPosition>
					<endPosition>74.5928541603286</endPosition>
				</positions>
				<positions axis="Omega" unit="deg">
					<commonPosition>17.9762096373602</commonPosition>
				</positions>
				<positions axis="Phi" unit="deg">
					<commonPosition>-86.42</commonPosition>
				</positions>
				<positions axis="Chi" unit="deg">
					<commonPosition>0</commonPosition>
				</positions>
				<positions axis="Z" unit="mm">
					<commonPosition>8.428</commonPosition>
				</positions>
				<commonCountingTime unit="seconds">0.784</commonCountingTime>
				<counts unit="counts">0 0 0 0 0 0 1 0 1 0 0 0 0 0 0 0 0 0 0 0 0 0 0 0 0 1 0 0 0 1 0 0 0 0 0 0 0 0 0 0 1 0 0 0 0 0 0 1 1 1 0 2 0 1 1 0 0 0 2 0 0 0 0 0 1 0 1 0 0 0 0 0 0 0 0 0 0 1 0 0 0 1 0 0 0 0 0 0 0 1 0 1 1 0 0 0 0 0 0 0 1 0 1 0 0 0 0 1 0 0 0 0 0 0 0 1 1 0 0 1 0 0 0 0 0 0 0 1 0 0 0 0 0 0 0 0 0 0 1 0 0 0 0 0 0 0 0 0 1 0 0 0 0 1 0 0 0 2 0 0 1 2 1 1 0 4 3 2 0 4 1 1 1 0 0 0 1 0 0 1 0 2 0 0 1 0 0 0 0 0 0 0 2 0 0 0 0 0 0 0 1 0 0 0 1 1 1 1 0 0 0 0 0 1 1 0 0 0 0 1 1 0 3 0 1 0 0 0 0 1 0 0 0 0 0 0 1 1 0 0 0 0 0 0 0 1 0 0 1 1 0 0 1 1 0</counts>
			</dataPoints>
		</scan>
		<scan status="Completed" appendNumber="0" scanAxis="2Theta" mode="Continuous">
			<header>
				<startTimeStamp>2023-01-13T16:56:26-05:00</startTimeStamp>
				<endTimeStamp>2023-01-13T17:12:39-05:00</endTimeStamp>
				<author>
					<name>User</name>
				</author>
				<source>
					<applicationSoftware version="7.1">Data Collector</applicationSoftware>
					<instrumentControlSoftware version="8.2  20201204">EMPYREAN</instrumentControlSoftware>
					<instrumentID>0000000011260721</instrumentID>
				</source>
			</header>
			<dataPoints>
				<positions axis="2Theta" unit="deg">
					<startPosition>71.2488669597865</startPosition>
					<endPosition>74.596136731003</endPosition>
				</positions>
				<positions axis="Omega" unit="deg">
					<commonPosition>17.9778509226974</commonPosition>
				</positions>
				<positions axis="Phi" unit="deg">
					<commonPosition>-86.42</commonPosition>
				</positions>
				<positions axis="Chi" unit="deg">
					<commonPosition>0</commonPosition>
				</positions>
				<positions axis="Z" unit="mm">
					<commonPosition>8.428</commonPosition>
				</positions>
				<commonCountingTime unit="seconds">0.784</commonCountingTime>
				<counts unit="counts">2 1 0 1 0 1 1 1 0 0 0 0 0 1 0 0 0 0 0 0 0 0 0 0 0 1 1 0 0 1 1 0 3 0 0 0 2 1 1 2 0 0 0 1 0 1 2 0 0 0 0 0 0 1 1 1 0 0 0 0 0 0 1 2 0 0 0 1 0 0 1 2 1 1 0 0 0 0 0 0 0 1 1 0 0 0 0 0 1 1 0 1 0 0 0 0 0 0 1 0 0 1 0 0 1 0 0 0 0 0 1 1 0 0 1 1 1 0 0 1 0 1 0 0 0 0 0 0 2 1 0 0 1 0 0 0 0 0 1 0 0 0 0 0 1 1 0 0 0 0 1 0 1 1 0 0 2 0 0 0 1 1 1 0 4 6 1 3 0 1 0 1 1 0 0 0 0 0 0 1 3 0 0 1 1 0 1 0 0 0 1 0 1 1 0 0 0 0 0 1 1 0 0 0 0 0 0 0 0 0 0 0 0 1 1 0 0 0 1 0 0 0 1 1 0 1 1 0 0 1 1 0 0 0 0 0 0 0 1 1 2 0 0 0 0 1 1 0 1 2 0 0 0 0 0</counts>
			</dataPoints>
		</scan>
		<scan status="Completed" appendNumber="0" scanAxis="2Theta" mode="Continuous">
			<header>
				<startTimeStamp>2023-01-13T16:56:26-05:00</startTimeStamp>
				<endTimeStamp>2023-01-13T17:12:39-05:00</endTimeStamp>
				<author>
					<name>User</name>
				</author>
				<source>
					<applicationSoftware version="7.1">Data Collector</applicationSoftware>
					<instrumentControlSoftware version="8.2  20201204">EMPYREAN</instrumentControlSoftware>
					<instrumentID>0000000011260721</instrumentID>
				</source>
			</header>
			<dataPoints>
				<positions axis="2Theta" unit="deg">
					<startPosition>71.2521495304608</startPosition>
					<endPosition>74.5994193016773</endPosition>
				</positions>
				<positions axis="Omega" unit="deg">
					<commonPosition>17.9794922080345</commonPosition>
				</positions>
				<positions axis="Phi" unit="deg">
					<commonPosition>-86.42</commonPosition>
				</positions>
				<positions axis="Chi" unit="deg">
					<commonPosition>0</commonPosition>
				</positions>
				<positions axis="Z" unit="mm">
					<commonPosition>8.428</commonPosition>
				</positions>
				<commonCountingTime unit="seconds">0.784</commonCountingTime>
				<counts unit="counts">0 0 0 0 0 0 0 0 0 2 0 0 1 0 1 0 0 1 1 0 0 0 0 1 1 3 1 0 1 0 1 1 0 0 2 0 0 0 0 1 0 1 0 0 0 1 0 0 1 0 2 0 0 0 0 0 0 0 0 0 0 1 1 0 1 0 0 0 1 0 0 0 0 0 0 1 0 0 0 1 0 0 0 1 2 0 0 2 1 0 1 0 0 0 1 0 0 0 1 0 0 1 0 0 1 0 0 1 1 0 0 0 1 0 0 0 0 2 2 0 1 0 1 0 0 0 0 0 0 0 0 0 0 0 0 0 1 0 0 1 0 0 0 3 0 0 0 0 0 0 0 0 0 0 0 0 1 1 1 0 0 1 0 0 1 3 7 5 0 1 3 0 1 1 1 0 0 0 0 0 1 0 1 0 1 1 0 0 0 0 0 2 0 1 1 0 0 0 1 0 0 1 1 0 1 2 0 0 1 0 0 2 0 0 2 0 0 0 1 0 1 1 0 0 0 0 0 0 1 0 2 0 0 1 0 0 1 0 0 1 0 0 0 0 0 0 1 0 0 0 0 0 0 0 0</counts>
			</dataPoints>
		</scan>
		<scan status="Completed" appendNumber="0" scanAxis="2Theta" mode="Continuous">
			<header>
				<startTimeStamp>2023-01-13T16:56:26-05:00</startTimeStamp>
				<endTimeStamp>2023-01-13T17:12:39-05:00</endTimeStamp>
				<author>
					<name>User</name>
				</author>
				<source>
					<applicationSoftware version="7.1">Data Collector</applicationSoftware>
					<instrumentControlSoftware version="8.2  20201204">EMPYREAN</instrumentControlSoftware>
					<instrumentID>0000000011260721</instrumentID>
				</source>
			</header>
			<dataPoints>
				<positions axis="2Theta" unit="deg">
					<startPosition>71.2554321011352</startPosition>
					<endPosition>74.6027018723517</endPosition>
				</positions>
				<positions axis="Omega" unit="deg">
					<commonPosition>17.9811334933717</commonPosition>
				</positions>
				<positions axis="Phi" unit="deg">
					<commonPosition>-86.42</commonPosition>
				</positions>
				<positions axis="Chi" unit="deg">
					<commonPosition>0</commonPosition>
				</positions>
				<positions axis="Z" unit="mm">
					<commonPosition>8.428</commonPosition>
				</positions>
				<commonCountingTime unit="seconds">0.784</commonCountingTime>
				<counts unit="counts">0 0 1 0 0 1 0 1 1 0 0 1 2 1 0 0 1 0 0 0 0 0 0 0 0 0 2 1 0 0 1 0 1 0 0 0 1 0 0 0 0 1 1 0 3 1 1 0 1 1 1 0 0 0 1 2 1 0 1 0 1 1 0 1 2 1 0 0 0 0 0 0 0 1 0 0 0 0 1 1 0 0 0 0 1 1 1 0 0 0 0 0 0 0 0 0 0 0 1 0 0 0 0 0 2 1 0 1 0 2 1 0 0 1 0 0 1 0 0 0 0 0 1 0 0 1 0 0 1 0 0 0 0 0 1 0 1 0 0 0 0 2 1 0 1 0 0 0 0 1 1 0 0 0 0 0 0 0 0 1 1 0 1 1 1 2 1 1 3 0 0 0 0 0 0 1 0 0 0 0 0 1 1 0 0 0 0 0 0 0 0 1 2 0 0 1 0 0 0 1 0 1 0 0 0 1 0 0 0 0 0 1 1 0 0 0 0 0 1 0 0 0 0 0 0 1 0 2 0 0 0 0 0 0 0 0 0 1 1 0 1 2 0 0 1 0 0 0 2 0 3 0 0 0 1</counts>
			</dataPoints>
		</scan>
		<scan status="Completed" appendNumber="0" scanAxis="2Theta" mode="Continuous">
			<header>
				<startTimeStamp>2023-01-13T16:56:26-05:00</startTimeStamp>
				<endTimeStamp>2023-01-13T17:12:39-05:00</endTimeStamp>
				<author>
					<name>User</name>
				</author>
				<source>
					<applicationSoftware version="7.1">Data Collector</applicationSoftware>
					<instrumentControlSoftware version="8.2  20201204">EMPYREAN</instrumentControlSoftware>
					<instrumentID>0000000011260721</instrumentID>
				</source>
			</header>
			<dataPoints>
				<positions axis="2Theta" unit="deg">
					<startPosition>71.2587146718095</startPosition>
					<endPosition>74.605984443026</endPosition>
				</positions>
				<positions axis="Omega" unit="deg">
					<commonPosition>17.9827747787089</commonPosition>
				</positions>
				<positions axis="Phi" unit="deg">
					<commonPosition>-86.42</commonPosition>
				</positions>
				<positions axis="Chi" unit="deg">
					<commonPosition>0</commonPosition>
				</positions>
				<positions axis="Z" unit="mm">
					<commonPosition>8.428</commonPosition>
				</positions>
				<commonCountingTime unit="seconds">0.784</commonCountingTime>
				<counts unit="counts">1 0 1 0 1 1 1 1 1 1 0 1 0 0 0 3 0 0 0 0 0 0 0 0 0 0 0 0 1 0 1 1 1 0 0 1 0 0 0 1 0 1 1 0 0 0 0 0 0 1 1 0 1 0 0 0 0 1 0 0 0 0 1 0 0 0 0 0 1 0 1 0 0 0 0 1 1 0 1 2 0 0 1 1 0 0 0 1 0 0 1 0 1 0 0 1 0 1 0 0 0 1 0 0 0 1 1 0 0 0 1 0 1 2 0 0 1 0 0 1 0 0 1 0 0 1 0 0 0 0 0 1 1 1 0 1 1 1 0 0 0 0 0 0 0 1 1 1 0 0 0 2 1 2 0 1 1 1 0 0 1 0 0 1 3 2 3 2 0 3 2 0 0 0 0 1 0 0 0 0 1 1 1 0 0 0 1 0 0 1 0 0 0 1 0 0 0 0 1 0 0 0 0 0 0 0 0 1 0 0 0 0 1 0 2 0 0 1 3 0 1 2 0 1 1 0 0 1 1 1 1 0 0 0 0 0 0 0 0 0 1 0 0 0 1 1 0 0 0 1 0 0 0 0 0</counts>
			</dataPoints>
		</scan>
		<scan status="Completed" appendNumber="0" scanAxis="2Theta" mode="Continuous">
			<header>
				<startTimeStamp>2023-01-13T16:56:26-05:00</startTimeStamp>
				<endTimeStamp>2023-01-13T17:12:39-05:00</endTimeStamp>
				<author>
					<name>User</name>
				</author>
				<source>
					<applicationSoftware version="7.1">Data Collector</applicationSoftware>
					<instrumentControlSoftware version="8.2  20201204">EMPYREAN</instrumentControlSoftware>
					<instrumentID>0000000011260721</instrumentID>
				</source>
			</header>
			<dataPoints>
				<positions axis="2Theta" unit="deg">
					<startPosition>71.2619972424839</startPosition>
					<endPosition>74.6092670137003</endPosition>
				</positions>
				<positions axis="Omega" unit="deg">
					<commonPosition>17.9844160640461</commonPosition>
				</positions>
				<positions axis="Phi" unit="deg">
					<commonPosition>-86.42</commonPosition>
				</positions>
				<positions axis="Chi" unit="deg">
					<commonPosition>0</commonPosition>
				</positions>
				<positions axis="Z" unit="mm">
					<commonPosition>8.428</commonPosition>
				</positions>
				<commonCountingTime unit="seconds">0.784</commonCountingTime>
				<counts unit="counts">0 1 1 1 0 1 0 0 2 1 0 1 1 0 1 1 1 0 0 1 0 0 1 0 0 0 0 0 2 1 0 1 0 1 0 0 0 1 0 0 0 0 1 2 0 0 0 0 0 1 0 0 0 0 1 1 0 1 0 1 0 1 0 0 0 0 1 0 1 0 0 0 0 0 0 0 0 0 2 0 0 1 0 0 0 0 0 0 0 2 1 0 0 0 0 2 1 0 0 0 0 1 0 0 1 0 0 0 1 0 0 1 2 1 0 0 0 1 0 1 1 0 0 0 1 0 0 1 1 0 0 1 1 0 0 1 1 1 1 0 1 0 1 0 1 1 0 1 0 1 1 0 1 0 1 1 1 0 0 0 1 0 2 0 1 1 3 1 0 1 0 2 1 0 0 0 0 0 0 0 1 1 1 0 0 0 0 0 0 1 0 0 0 0 0 1 0 0 0 0 0 1 0 0 0 0 0 1 0 0 0 0 0 1 0 1 2 1 0 1 0 0 0 0 0 1 1 0 0 0 0 1 0 0 1 0 0 1 0 0 1 1 0 0 0 0 0 1 1 0 1 1 0 0 0</counts>
			</dataPoints>
		</scan>
		<scan status="Completed" appendNumber="0" scanAxis="2Theta" mode="Continuous">
			<header>
				<startTimeStamp>2023-01-13T16:56:26-05:00</startTimeStamp>
				<endTimeStamp>2023-01-13T17:12:39-05:00</endTimeStamp>
				<author>
					<name>User</name>
				</author>
				<source>
					<applicationSoftware version="7.1">Data Collector</applicationSoftware>
					<instrumentControlSoftware version="8.2  20201204">EMPYREAN</instrumentControlSoftware>
					<instrumentID>0000000011260721</instrumentID>
				</source>
			</header>
			<dataPoints>
				<positions axis="2Theta" unit="deg">
					<startPosition>71.2652798131582</startPosition>
					<endPosition>74.6125495843747</endPosition>
				</positions>
				<positions axis="Omega" unit="deg">
					<commonPosition>17.9860573493832</commonPosition>
				</positions>
				<positions axis="Phi" unit="deg">
					<commonPosition>-86.42</commonPosition>
				</positions>
				<positions axis="Chi" unit="deg">
					<commonPosition>0</commonPosition>
				</positions>
				<positions axis="Z" unit="mm">
					<commonPosition>8.428</commonPosition>
				</positions>
				<commonCountingTime unit="seconds">0.784</commonCountingTime>
				<counts unit="counts">0 2 0 0 0 3 0 0 0 1 2 1 1 0 0 0 0 0 2 0 0 0 0 1 1 0 1 1 1 0 0 0 0 2 0 0 0 2 0 1 0 1 0 0 0 1 0 1 0 0 1 0 0 0 0 1 0 1 0 0 0 0 1 0 0 1 0 2 0 0 0 1 0 0 1 1 1 0 0 1 0 0 0 0 0 0 0 1 0 2 0 0 0 1 1 0 1 1 1 0 0 0 0 1 0 0 0 1 0 0 0 0 0 1 0 0 1 1 0 1 0 0 1 1 0 0 2 1 0 0 0 0 1 1 0 0 1 2 0 1 0 1 0 1 0 1 0 1 0 0 0 0 1 0 0 0 0 0 0 1 0 0 1 0 1 3 3 0 1 0 1 0 0 1 0 0 1 0 0 0 0 0 3 0 1 0 0 0 3 0 0 2 1 1 1 1 0 0 1 0 0 0 0 1 0 0 0 0 0 0 0 1 0 2 0 1 0 0 0 1 1 0 0 0 2 1 0 0 2 0 0 0 0 1 1 1 0 1 0 0 0 0 0 0 0 1 1 0 0 0 2 0 1 0 1</counts>
			</dataPoints>
		</scan>
		<scan status="Completed" appendNumber="0" scanAxis="2Theta" mode="Continuous">
			<header>
				<startTimeStamp>2023-01-13T16:56:26-05:00</startTimeStamp>
				<endTimeStamp>2023-01-13T17:12:39-05:00</endTimeStamp>
				<author>
					<name>User</name>
				</author>
				<source>
					<applicationSoftware version="7.1">Data Collector</applicationSoftware>
					<instrumentControlSoftware version="8.2  20201204">EMPYREAN</instrumentControlSoftware>
					<instrumentID>0000000011260721</instrumentID>
				</source>
			</header>
			<dataPoints>
				<positions axis="2Theta" unit="deg">
					<startPosition>71.2685623838325</startPosition>
					<endPosition>74.615832155049</endPosition>
				</positions>
				<positions axis="Omega" unit="deg">
					<commonPosition>17.9876986347204</commonPosition>
				</positions>
				<positions axis="Phi" unit="deg">
					<commonPosition>-86.42</commonPosition>
				</positions>
				<positions axis="Chi" unit="deg">
					<commonPosition>0</commonPosition>
				</positions>
				<positions axis="Z" unit="mm">
					<commonPosition>8.428</commonPosition>
				</positions>
				<commonCountingTime unit="seconds">0.784</commonCountingTime>
				<counts unit="counts">1 1 0 0 2 1 0 0 0 0 0 0 0 0 0 0 0 0 0 0 0 1 0 0 1 0 0 0 0 0 0 0 0 0 0 1 0 0 0 0 0 1 0 0 0 1 0 0 0 1 0 0 0 0 1 0 1 0 0 0 0 0 0 1 0 0 0 0 0 0 0 0 0 1 0 0 0 0 1 1 0 0 0 0 0 1 0 0 0 1 0 0 0 0 0 1 0 0 0 1 0 1 0 1 0 0 0 0 0 1 1 1 1 1 0 1 1 1 1 0 1 1 1 0 1 0 0 0 0 0 0 1 0 0 0 0 0 0 0 0 0 0 0 0 1 1 0 0 0 0 0 1 0 0 0 1 0 0 0 1 1 1 0 0 3 2 1 2 2 0 0 0 0 0 0 0 0 2 1 0 0 0 0 0 1 0 1 0 0 0 0 0 0 0 0 0 1 0 0 0 0 0 1 0 0 0 0 1 1 2 0 0 0 0 1 0 3 0 1 0 0 0 0 1 1 0 0 1 2 0 0 0 0 1 1 0 2 0 0 0 0 1 0 2 2 0 1 0 1 0 0 0 0 0 0</counts>
			</dataPoints>
		</scan>
		<scan status="Completed" appendNumber="0" scanAxis="2Theta" mode="Continuous">
			<header>
				<startTimeStamp>2023-01-13T16:56:26-05:00</startTimeStamp>
				<endTimeStamp>2023-01-13T17:12:39-05:00</endTimeStamp>
				<author>
					<name>User</name>
				</author>
				<source>
					<applicationSoftware version="7.1">Data Collector</applicationSoftware>
					<instrumentControlSoftware version="8.2  20201204">EMPYREAN</instrumentControlSoftware>
					<instrumentID>0000000011260721</instrumentID>
				</source>
			</header>
			<dataPoints>
				<positions axis="2Theta" unit="deg">
					<startPosition>71.2718449545069</startPosition>
					<endPosition>74.6191147257234</endPosition>
				</positions>
				<positions axis="Omega" unit="deg">
					<commonPosition>17.9893399200576</commonPosition>
				</positions>
				<positions axis="Phi" unit="deg">
					<commonPosition>-86.42</commonPosition>
				</positions>
				<positions axis="Chi" unit="deg">
					<commonPosition>0</commonPosition>
				</positions>
				<positions axis="Z" unit="mm">
					<commonPosition>8.428</commonPosition>
				</positions>
				<commonCountingTime unit="seconds">0.784</commonCountingTime>
				<counts unit="counts">0 0 1 1 0 0 0 0 0 0 1 2 0 0 0 0 0 0 0 0 1 0 1 0 0 0 1 0 1 0 3 0 0 1 0 1 0 2 1 0 0 1 0 2 1 2 0 0 0 0 1 0 0 1 1 0 1 0 1 0 1 0 0 0 0 1 0 1 0 1 0 1 0 0 0 0 0 0 1 0 0 1 0 0 1 1 0 1 2 0 0 0 0 0 0 1 0 0 0 0 1 0 0 2 0 0 0 0 0 0 0 0 0 0 0 1 5 0 1 0 0 0 0 0 1 0 2 1 0 0 0 2 0 0 0 1 1 0 2 1 0 1 0 1 4 0 2 1 0 0 0 0 0 1 2 0 1 1 1 1 1 0 0 0 2 6 4 4 3 0 0 0 1 2 0 0 0 0 1 0 0 4 1 0 0 1 0 1 0 0 0 0 0 0 0 0 0 0 0 1 0 0 0 1 0 0 0 0 1 2 0 1 1 1 0 0 0 0 0 0 0 0 0 0 1 0 0 1 1 1 0 0 2 2 2 1 2 1 0 0 1 0 0 0 0 0 0 1 0 0 0 2 0 0 1</counts>
			</dataPoints>
		</scan>
		<scan status="Completed" appendNumber="0" scanAxis="2Theta" mode="Continuous">
			<header>
				<startTimeStamp>2023-01-13T16:56:26-05:00</startTimeStamp>
				<endTimeStamp>2023-01-13T17:12:39-05:00</endTimeStamp>
				<author>
					<name>User</name>
				</author>
				<source>
					<applicationSoftware version="7.1">Data Collector</applicationSoftware>
					<instrumentControlSoftware version="8.2  20201204">EMPYREAN</instrumentControlSoftware>
					<instrumentID>0000000011260721</instrumentID>
				</source>
			</header>
			<dataPoints>
				<positions axis="2Theta" unit="deg">
					<startPosition>71.2751275251812</startPosition>
					<endPosition>74.6223972963977</endPosition>
				</positions>
				<positions axis="Omega" unit="deg">
					<commonPosition>17.9909812053947</commonPosition>
				</positions>
				<positions axis="Phi" unit="deg">
					<commonPosition>-86.42</commonPosition>
				</positions>
				<positions axis="Chi" unit="deg">
					<commonPosition>0</commonPosition>
				</positions>
				<positions axis="Z" unit="mm">
					<commonPosition>8.428</commonPosition>
				</positions>
				<commonCountingTime unit="seconds">0.784</commonCountingTime>
				<counts unit="counts">0 0 0 0 2 0 0 1 0 0 0 1 0 0 1 0 0 1 0 0 1 0 0 1 0 1 1 0 0 0 1 0 1 0 1 1 0 0 0 0 0 1 0 0 0 0 0 0 0 0 0 0 0 0 0 1 0 0 1 0 0 0 0 0 0 1 1 1 1 0 0 0 1 1 0 1 0 1 0 0 0 0 0 1 0 0 0 0 1 0 2 1 1 0 1 1 0 1 0 0 0 0 1 1 0 0 0 1 0 0 0 0 0 0 0 0 0 0 0 2 0 0 0 0 3 1 1 0 0 0 0 1 0 1 0 0 0 0 1 0 0 1 2 0 0 1 0 0 0 0 0 0 0 0 0 0 0 1 1 0 0 0 0 0 0 2 2 5 0 0 1 1 2 0 0 1 0 1 0 2 0 0 0 1 0 0 1 1 0 0 1 1 0 0 0 2 1 0 1 0 0 0 0 0 0 0 1 0 1 1 0 0 2 1 0 0 0 0 0 0 2 0 1 2 0 0 2 0 0 0 0 0 0 0 0 0 1 1 0 1 0 0 0 0 0 1 1 0 0 1 0 0 0 1 0</counts>
			</dataPoints>
		</scan>
		<scan status="Completed" appendNumber="0" scanAxis="2Theta" mode="Continuous">
			<header>
				<startTimeStamp>2023-01-13T16:56:26-05:00</startTimeStamp>
				<endTimeStamp>2023-01-13T17:12:39-05:00</endTimeStamp>
				<author>
					<name>User</name>
				</author>
				<source>
					<applicationSoftware version="7.1">Data Collector</applicationSoftware>
					<instrumentControlSoftware version="8.2  20201204">EMPYREAN</instrumentControlSoftware>
					<instrumentID>0000000011260721</instrumentID>
				</source>
			</header>
			<dataPoints>
				<positions axis="2Theta" unit="deg">
					<startPosition>71.2784100958556</startPosition>
					<endPosition>74.6256798670721</endPosition>
				</positions>
				<positions axis="Omega" unit="deg">
					<commonPosition>17.9926224907319</commonPosition>
				</positions>
				<positions axis="Phi" unit="deg">
					<commonPosition>-86.42</commonPosition>
				</positions>
				<positions axis="Chi" unit="deg">
					<commonPosition>0</commonPosition>
				</positions>
				<positions axis="Z" unit="mm">
					<commonPosition>8.428</commonPosition>
				</positions>
				<commonCountingTime unit="seconds">0.784</commonCountingTime>
				<counts unit="counts">0 0 0 0 1 0 0 0 0 1 0 0 1 0 0 0 0 0 1 0 0 0 0 1 0 1 1 0 0 2 0 0 0 0 0 1 2 0 1 0 0 0 0 0 0 0 2 0 1 0 1 0 1 0 0 0 2 0 0 1 2 0 1 0 0 0 1 0 0 0 0 0 0 0 0 1 1 2 0 0 0 0 2 0 0 1 1 2 1 0 1 0 0 0 0 0 0 0 1 0 0 1 0 1 0 1 1 0 0 0 1 0 0 0 0 0 0 0 0 0 0 0 0 1 0 0 2 1 0 1 1 1 0 0 0 0 0 2 0 3 1 1 1 1 0 0 0 0 1 0 1 1 0 0 1 1 0 0 0 0 0 0 1 0 1 3 5 1 0 0 1 1 1 2 1 1 0 1 0 1 0 0 1 0 0 3 0 0 0 0 0 1 0 1 1 0 1 1 0 0 1 1 1 1 0 1 0 1 0 1 0 1 0 0 0 1 0 0 0 1 1 0 0 0 2 1 0 0 0 0 0 0 0 0 0 0 0 0 0 0 1 0 0 1 0 1 0 0 0 0 1 2 1 0 2</counts>
			</dataPoints>
		</scan>
		<scan status="Completed" appendNumber="0" scanAxis="2Theta" mode="Continuous">
			<header>
				<startTimeStamp>2023-01-13T16:56:26-05:00</startTimeStamp>
				<endTimeStamp>2023-01-13T17:12:39-05:00</endTimeStamp>
				<author>
					<name>User</name>
				</author>
				<source>
					<applicationSoftware version="7.1">Data Collector</applicationSoftware>
					<instrumentControlSoftware version="8.2  20201204">EMPYREAN</instrumentControlSoftware>
					<instrumentID>0000000011260721</instrumentID>
				</source>
			</header>
			<dataPoints>
				<positions axis="2Theta" unit="deg">
					<startPosition>71.2816926665299</startPosition>
					<endPosition>74.6289624377464</endPosition>
				</positions>
				<positions axis="Omega" unit="deg">
					<commonPosition>17.9942637760691</commonPosition>
				</positions>
				<positions axis="Phi" unit="deg">
					<commonPosition>-86.42</commonPosition>
				</positions>
				<positions axis="Chi" unit="deg">
					<commonPosition>0</commonPosition>
				</positions>
				<positions axis="Z" unit="mm">
					<commonPosition>8.428</commonPosition>
				</positions>
				<commonCountingTime unit="seconds">0.784</commonCountingTime>
				<counts unit="counts">1 0 0 1 0 0 0 0 0 0 0 0 1 0 1 2 1 2 0 1 2 0 0 0 1 0 0 0 0 0 0 0 0 0 0 0 0 0 0 2 0 0 0 1 0 0 0 1 0 0 0 0 0 0 0 1 0 1 1 0 2 1 0 0 0 1 0 0 1 0 0 1 0 1 0 0 0 0 1 1 0 0 0 0 1 1 1 0 0 1 0 0 1 0 0 0 0 0 0 0 0 0 0 0 0 1 0 0 0 0 0 0 0 1 0 0 0 1 1 0 1 0 1 2 0 2 0 0 1 1 0 0 0 0 0 1 1 1 0 2 0 1 0 0 0 1 0 0 0 0 1 0 1 0 0 0 1 2 0 1 0 0 0 0 2 2 3 2 0 1 0 1 0 1 1 0 1 0 1 0 0 0 0 0 0 0 0 0 1 1 0 0 1 0 0 0 0 0 0 0 0 1 1 0 1 0 0 0 0 0 0 1 0 1 1 0 0 0 0 2 0 0 0 1 1 1 1 0 0 0 2 0 0 0 1 1 0 0 2 0 2 0 0 0 0 0 1 0 2 0 0 1 0 0 1</counts>
			</dataPoints>
		</scan>
		<scan status="Completed" appendNumber="0" scanAxis="2Theta" mode="Continuous">
			<header>
				<startTimeStamp>2023-01-13T16:56:26-05:00</startTimeStamp>
				<endTimeStamp>2023-01-13T17:12:39-05:00</endTimeStamp>
				<author>
					<name>User</name>
				</author>
				<source>
					<applicationSoftware version="7.1">Data Collector</applicationSoftware>
					<instrumentControlSoftware version="8.2  20201204">EMPYREAN</instrumentControlSoftware>
					<instrumentID>0000000011260721</instrumentID>
				</source>
			</header>
			<dataPoints>
				<positions axis="2Theta" unit="deg">
					<startPosition>71.2849752372043</startPosition>
					<endPosition>74.6322450084207</endPosition>
				</positions>
				<positions axis="Omega" unit="deg">
					<commonPosition>17.9959050614063</commonPosition>
				</positions>
				<positions axis="Phi" unit="deg">
					<commonPosition>-86.42</commonPosition>
				</positions>
				<positions axis="Chi" unit="deg">
					<commonPosition>0</commonPosition>
				</positions>
				<positions axis="Z" unit="mm">
					<commonPosition>8.428</commonPosition>
				</positions>
				<commonCountingTime unit="seconds">0.784</commonCountingTime>
				<counts unit="counts">0 0 1 4 0 1 0 0 0 1 0 0 0 1 0 1 3 1 1 0 0 1 1 0 1 0 0 1 1 1 0 0 0 1 1 0 0 0 0 0 1 2 0 1 0 0 1 0 1 1 0 0 1 1 2 0 0 0 0 0 0 0 0 1 1 0 0 1 1 0 1 1 3 0 1 1 0 1 1 0 0 0 0 0 1 0 2 1 0 1 0 0 0 0 0 0 2 0 0 1 1 0 0 0 0 0 0 0 0 0 0 0 0 0 1 1 2 0 0 0 1 1 0 1 1 1 0 0 0 0 0 2 1 0 1 0 0 0 0 0 0 0 0 0 1 1 0 1 0 2 0 1 0 1 1 0 0 0 0 0 1 1 0 0 0 1 1 2 0 2 0 0 0 1 0 0 1 0 0 0 0 0 0 0 0 0 1 0 0 0 0 0 0 0 2 1 0 0 0 0 0 0 0 0 1 1 0 1 1 1 2 0 1 0 0 0 0 0 2 1 0 1 0 0 0 0 1 0 1 0 1 0 1 0 0 0 0 1 0 0 0 1 0 0 0 0 1 0 0 0 0 0 0 0 0</counts>
			</dataPoints>
		</scan>
		<scan status="Completed" appendNumber="0" scanAxis="2Theta" mode="Continuous">
			<header>
				<startTimeStamp>2023-01-13T16:56:26-05:00</startTimeStamp>
				<endTimeStamp>2023-01-13T17:12:39-05:00</endTimeStamp>
				<author>
					<name>User</name>
				</author>
				<source>
					<applicationSoftware version="7.1">Data Collector</applicationSoftware>
					<instrumentControlSoftware version="8.2  20201204">EMPYREAN</instrumentControlSoftware>
					<instrumentID>0000000011260721</instrumentID>
				</source>
			</header>
			<dataPoints>
				<positions axis="2Theta" unit="deg">
					<startPosition>71.2882578078786</startPosition>
					<endPosition>74.6355275790951</endPosition>
				</positions>
				<positions axis="Omega" unit="deg">
					<commonPosition>17.9975463467434</commonPosition>
				</positions>
				<positions axis="Phi" unit="deg">
					<commonPosition>-86.42</commonPosition>
				</positions>
				<positions axis="Chi" unit="deg">
					<commonPosition>0</commonPosition>
				</positions>
				<positions axis="Z" unit="mm">
					<commonPosition>8.428</commonPosition>
				</positions>
				<commonCountingTime unit="seconds">0.784</commonCountingTime>
[...]
					<commonPosition>0</commonPosition>
				</positions>
				<positions axis="Z" unit="mm">
					<commonPosition>8.428</commonPosition>
				</positions>
				<commonCountingTime unit="seconds">0.784</commonCountingTime>
				<counts unit="counts">1 0 0 1 1 0 0 0 0 0 1 1 0 0 0 2 1 1 0 1 1 1 2 1 0 1 1 0 0 0 0 1 0 0 0 0 1 0 1 0 0 0 0 1 0 0 0 1 0 1 1 0 0 0 0 0 1 0 0 0 0 0 0 0 0 0 0 0 1 0 0 0 0 1 3 1 1 1 0 1 0 0 1 0 1 0 1 1 1 0 0 4 1 0 0 0 0 0 1 0 0 2 1 0 0 0 1 0 0 1 0 0 0 0 0 0 0 0 1 0 0 0 0 0 0 0 0 1 0 0 0 1 2 0 0 0 0 0 0 2 0 0 0 0 0 0 0 0 0 0 0 0 0 1 0 0 0 0 0 1 1 1 0 0 0 0 0 1 0 0 1 0 0 1 0 0 0 0 1 0 0 0 1 3 1 1 0 1 0 0 0 1 1 0 0 2 0 2 0 0 1 1 0 0 0 0 0 0 0 0 1 0 1 0 0 0 0 0 0 0 1 0 1 1 0 1 1 0 1 0 1 0 1 0 1 0 0 0 0 1 1 0 1 0 0 1 0 0 0 0 0 0 0 1 1</counts>
			</dataPoints>
		</scan>
		<scan status="Completed" appendNumber="0" scanAxis="2Theta" mode="Continuous">
			<header>
				<startTimeStamp>2023-01-13T16:56:26-05:00</startTimeStamp>
				<endTimeStamp>2023-01-13T17:12:39-05:00</endTimeStamp>
				<author>
					<name>User</name>
				</author>
				<source>
					<applicationSoftware version="7.1">Data Collector</applicationSoftware>
					<instrumentControlSoftware version="8.2  20201204">EMPYREAN</instrumentControlSoftware>
					<instrumentID>0000000011260721</instrumentID>
				</source>
			</header>
			<dataPoints>
				<positions axis="2Theta" unit="deg">
					<startPosition>75.1813866276483</startPosition>
					<endPosition>78.5286563988648</endPosition>
				</positions>
				<positions axis="Omega" unit="deg">
					<commonPosition>19.9441107566283</commonPosition>
				</positions>
				<positions axis="Phi" unit="deg">
					<commonPosition>-86.42</commonPosition>
				</positions>
				<positions axis="Chi" unit="deg">
					<commonPosition>0</commonPosition>
				</positions>
				<positions axis="Z" unit="mm">
					<commonPosition>8.428</commonPosition>
				</positions>
				<commonCountingTime unit="seconds">0.784</commonCountingTime>
				<counts unit="counts">0 1 0 0 0 2 0 1 1 1 0 0 0 1 1 0 0 1 0 1 0 0 0 0 0 0 0 0 0 1 0 0 1 1 1 0 0 0 1 0 1 2 1 0 0 0 0 2 1 0 2 1 0 0 0 0 0 1 0 0 0 0 2 0 0 0 0 0 0 0 0 0 0 0 0 0 0 1 0 0 0 0 0 0 0 0 0 0 2 0 0 1 0 0 0 1 0 1 1 0 0 0 0 0 0 0 0 0 1 0 0 0 0 0 1 1 0 0 1 1 0 0 0 1 0 0 0 0 0 0 0 0 0 0 1 0 0 1 0 0 1 0 1 0 0 0 0 0 0 1 1 0 0 0 0 1 1 0 0 1 0 0 0 0 0 0 0 0 0 0 0 0 1 0 0 0 2 0 1 0 0 0 0 1 1 1 0 0 0 1 0 0 0 0 0 0 0 0 0 0 0 0 0 2 1 0 0 0 0 2 1 1 0 2 0 0 1 0 0 0 0 0 0 0 0 0 1 0 1 0 0 0 0 1 0 0 0 4 2 0 0 1 1 2 0 1 0 0 0 0 0 0 0 0 0</counts>
			</dataPoints>
		</scan>
		<scan status="Completed" appendNumber="0" scanAxis="2Theta" mode="Continuous">
			<header>
				<startTimeStamp>2023-01-13T16:56:26-05:00</startTimeStamp>
				<endTimeStamp>2023-01-13T17:12:39-05:00</endTimeStamp>
				<author>
					<name>User</name>
				</author>
				<source>
					<applicationSoftware version="7.1">Data Collector</applicationSoftware>
					<instrumentControlSoftware version="8.2  20201204">EMPYREAN</instrumentControlSoftware>
					<instrumentID>0000000011260721</instrumentID>
				</source>
			</header>
			<dataPoints>
				<positions axis="2Theta" unit="deg">
					<startPosition>75.1846691983227</startPosition>
					<endPosition>78.5319389695392</endPosition>
				</positions>
				<positions axis="Omega" unit="deg">
					<commonPosition>19.9457520419655</commonPosition>
				</positions>
				<positions axis="Phi" unit="deg">
					<commonPosition>-86.42</commonPosition>
				</positions>
				<positions axis="Chi" unit="deg">
					<commonPosition>0</commonPosition>
				</positions>
				<positions axis="Z" unit="mm">
					<commonPosition>8.428</commonPosition>
				</positions>
				<commonCountingTime unit="seconds">0.784</commonCountingTime>
				<counts unit="counts">1 0 1 0 0 0 1 0 1 1 1 0 0 1 0 0 2 0 0 1 0 3 1 0 0 1 1 0 1 0 0 0 1 0 0 0 0 0 1 0 0 1 1 0 0 1 0 0 1 0 0 1 0 0 2 1 0 0 2 1 1 0 0 0 0 1 1 1 0 0 0 1 0 2 0 0 0 0 0 0 0 2 1 0 0 0 0 0 0 0 0 0 0 0 0 0 0 0 0 0 1 0 0 0 0 2 0 0 0 0 0 0 2 1 0 0 0 0 1 0 0 1 0 0 0 0 1 0 1 1 0 0 0 1 0 0 0 1 0 0 0 0 0 0 0 0 0 0 1 0 0 0 0 0 0 0 0 0 1 0 0 1 0 0 1 0 0 0 0 0 0 0 0 1 2 0 0 0 0 0 2 1 0 1 0 0 0 0 0 0 0 0 0 1 1 1 0 0 1 1 0 1 0 0 0 0 0 0 1 1 0 1 1 0 1 0 0 1 0 1 0 2 0 0 0 0 0 1 0 1 0 0 0 0 1 0 2 0 0 2 1 0 0 1 0 0 0 1 1 0 0 0 0 1 1</counts>
			</dataPoints>
		</scan>
		<scan status="Completed" appendNumber="0" scanAxis="2Theta" mode="Continuous">
			<header>
				<startTimeStamp>2023-01-13T16:56:26-05:00</startTimeStamp>
				<endTimeStamp>2023-01-13T17:12:39-05:00</endTimeStamp>
				<author>
					<name>User</name>
				</author>
				<source>
					<applicationSoftware version="7.1">Data Collector</applicationSoftware>
					<instrumentControlSoftware version="8.2  20201204">EMPYREAN</instrumentControlSoftware>
					<instrumentID>0000000011260721</instrumentID>
				</source>
			</header>
			<dataPoints>
				<positions axis="2Theta" unit="deg">
					<startPosition>75.187951768997</startPosition>
					<endPosition>78.5352215402135</endPosition>
				</positions>
				<positions axis="Omega" unit="deg">
					<commonPosition>19.9473933273026</commonPosition>
				</positions>
				<positions axis="Phi" unit="deg">
					<commonPosition>-86.42</commonPosition>
				</positions>
				<positions axis="Chi" unit="deg">
					<commonPosition>0</commonPosition>
				</positions>
				<positions axis="Z" unit="mm">
					<commonPosition>8.428</commonPosition>
				</positions>
				<commonCountingTime unit="seconds">0.784</commonCountingTime>
				<counts unit="counts">0 1 2 0 2 1 0 1 0 0 0 1 2 1 0 0 0 1 0 0 0 1 0 0 1 3 0 1 0 0 0 0 1 0 0 0 2 0 0 0 0 1 0 0 0 0 0 1 0 0 0 0 0 0 1 0 0 0 0 1 0 0 0 0 1 1 0 0 1 0 1 0 0 0 1 2 0 0 0 1 0 0 1 1 0 0 0 0 0 0 2 0 0 0 0 0 0 0 0 0 0 0 0 0 1 1 0 0 0 0 0 0 1 0 0 0 0 0 1 2 0 0 2 0 1 1 1 0 0 0 0 0 0 1 0 0 0 0 0 0 0 0 0 0 0 1 0 0 1 1 0 1 0 0 0 0 1 0 0 0 0 1 1 1 1 0 0 0 0 0 0 0 2 2 0 2 0 0 0 0 0 0 0 0 1 0 0 0 0 0 0 1 0 1 0 0 0 0 0 1 0 0 1 0 2 0 0 0 0 0 1 2 0 0 0 1 0 0 0 0 0 1 0 0 1 0 0 2 0 0 0 0 0 0 0 0 0 0 1 1 1 0 0 0 1 1 0 0 0 0 1 0 0 1 0</counts>
			</dataPoints>
		</scan>
		<scan status="Completed" appendNumber="0" scanAxis="2Theta" mode="Continuous">
			<header>
				<startTimeStamp>2023-01-13T16:56:26-05:00</startTimeStamp>
				<endTimeStamp>2023-01-13T17:12:39-05:00</endTimeStamp>
				<author>
					<name>User</name>
				</author>
				<source>
					<applicationSoftware version="7.1">Data Collector</applicationSoftware>
					<instrumentControlSoftware version="8.2  20201204">EMPYREAN</instrumentControlSoftware>
					<instrumentID>0000000011260721</instrumentID>
				</source>
			</header>
			<dataPoints>
				<positions axis="2Theta" unit="deg">
					<startPosition>75.1912343396714</startPosition>
					<endPosition>78.5385041108878</endPosition>
				</positions>
				<positions axis="Omega" unit="deg">
					<commonPosition>19.9490346126398</commonPosition>
				</positions>
				<positions axis="Phi" unit="deg">
					<commonPosition>-86.42</commonPosition>
				</positions>
				<positions axis="Chi" unit="deg">
					<commonPosition>0</commonPosition>
				</positions>
				<positions axis="Z" unit="mm">
					<commonPosition>8.428</commonPosition>
				</positions>
				<commonCountingTime unit="seconds">0.784</commonCountingTime>
				<counts unit="counts">0 0 0 0 0 0 1 1 0 1 0 1 3 0 0 0 0 1 1 0 2 0 0 1 0 0 0 0 1 0 1 0 1 0 0 0 0 0 0 0 0 1 0 0 0 0 0 0 0 0 0 0 0 2 0 0 0 3 0 0 3 0 0 0 0 0 0 2 0 0 3 0 1 1 0 0 2 1 2 0 0 0 1 1 1 1 1 0 0 0 0 0 1 0 0 0 0 1 0 0 1 0 0 0 0 0 0 0 0 0 1 0 0 1 0 0 0 1 0 3 0 0 1 1 0 0 0 0 3 0 0 2 1 0 0 0 0 1 2 0 0 0 0 0 0 0 0 0 0 0 0 0 0 0 0 1 0 0 1 0 0 0 0 1 0 1 0 0 0 0 0 0 0 1 1 0 1 0 0 0 0 0 0 0 0 0 2 0 0 0 0 1 0 0 0 0 1 0 0 1 1 1 1 1 0 1 0 0 1 1 0 0 0 0 0 0 0 0 0 2 0 0 1 0 0 0 0 0 0 0 0 0 0 0 0 1 0 0 0 0 0 0 2 0 0 1 0 0 0 0 0 0 0 0 0</counts>
			</dataPoints>
		</scan>
		<scan status="Completed" appendNumber="0" scanAxis="2Theta" mode="Continuous">
			<header>
				<startTimeStamp>2023-01-13T16:56:26-05:00</startTimeStamp>
				<endTimeStamp>2023-01-13T17:12:39-05:00</endTimeStamp>
				<author>
					<name>User</name>
				</author>
				<source>
					<applicationSoftware version="7.1">Data Collector</applicationSoftware>
					<instrumentControlSoftware version="8.2  20201204">EMPYREAN</instrumentControlSoftware>
					<instrumentID>0000000011260721</instrumentID>
				</source>
			</header>
			<dataPoints>
				<positions axis="2Theta" unit="deg">
					<startPosition>75.1945169103457</startPosition>
					<endPosition>78.5417866815622</endPosition>
				</positions>
				<positions axis="Omega" unit="deg">
					<commonPosition>19.950675897977</commonPosition>
				</positions>
				<positions axis="Phi" unit="deg">
					<commonPosition>-86.42</commonPosition>
				</positions>
				<positions axis="Chi" unit="deg">
					<commonPosition>0</commonPosition>
				</positions>
				<positions axis="Z" unit="mm">
					<commonPosition>8.428</commonPosition>
				</positions>
				<commonCountingTime unit="seconds">0.784</commonCountingTime>
				<counts unit="counts">1 1 1 0 0 1 0 0 0 0 0 0 0 0 0 0 0 1 1 0 1 0 0 0 1 1 0 0 0 1 0 1 1 0 0 0 0 0 1 1 1 0 0 0 0 0 0 1 0 1 0 0 0 0 0 1 1 0 0 1 1 1 3 0 0 0 0 0 0 0 1 0 1 0 2 0 1 2 0 0 0 1 2 0 0 1 0 2 0 1 1 0 0 0 0 0 1 0 0 0 0 1 0 0 1 0 1 1 0 1 0 1 0 0 0 0 0 0 1 1 0 0 0 0 0 0 0 0 1 0 0 0 0 0 0 0 1 0 0 0 0 0 0 0 1 0 0 0 4 1 0 0 0 0 0 0 1 0 0 0 0 0 1 0 1 0 0 0 0 0 0 0 0 0 1 0 0 0 1 0 0 0 0 0 1 1 1 1 0 0 1 0 0 0 0 0 0 0 1 1 0 0 1 0 0 0 0 0 0 0 0 0 0 0 0 0 0 1 0 0 1 0 0 0 1 1 1 0 0 0 1 0 1 0 1 0 0 0 0 0 0 0 0 0 0 0 0 1 0 0 0 0 0 1 0</counts>
			</dataPoints>
		</scan>
		<scan status="Completed" appendNumber="0" scanAxis="2Theta" mode="Continuous">
			<header>
				<startTimeStamp>2023-01-13T16:56:26-05:00</startTimeStamp>
				<endTimeStamp>2023-01-13T17:12:39-05:00</endTimeStamp>
				<author>
					<name>User</name>
				</author>
				<source>
					<applicationSoftware version="7.1">Data Collector</applicationSoftware>
					<instrumentControlSoftware version="8.2  20201204">EMPYREAN</instrumentControlSoftware>
					<instrumentID>0000000011260721</instrumentID>
				</source>
			</header>
			<dataPoints>
				<positions axis="2Theta" unit="deg">
					<startPosition>75.19779948102</startPosition>
					<endPosition>78.5450692522365</endPosition>
				</positions>
				<positions axis="Omega" unit="deg">
					<commonPosition>19.9523171833141</commonPosition>
				</positions>
				<positions axis="Phi" unit="deg">
					<commonPosition>-86.42</commonPosition>
				</positions>
				<positions axis="Chi" unit="deg">
					<commonPosition>0</commonPosition>
				</positions>
				<positions axis="Z" unit="mm">
					<commonPosition>8.428</commonPosition>
				</positions>
				<commonCountingTime unit="seconds">0.784</commonCountingTime>
				<counts unit="counts">1 0 0 0 1 0 0 0 0 1 0 1 2 0 1 0 0 1 0 1 0 0 0 1 0 1 1 0 0 0 0 1 0 1 0 1 0 0 1 0 0 2 0 0 0 0 2 0 1 1 0 0 0 0 1 1 0 0 2 0 0 0 1 0 1 1 0 0 0 0 0 2 0 2 0 2 0 2 0 0 0 0 0 0 0 0 0 1 0 1 0 0 0 2 0 0 0 0 0 0 0 0 0 0 1 1 0 1 0 0 0 0 0 1 0 0 0 0 1 0 0 0 0 1 0 0 0 0 0 2 0 0 0 2 0 2 1 0 1 0 1 0 1 1 0 1 0 1 0 0 0 0 2 0 0 0 0 1 1 1 1 0 0 0 0 2 1 0 0 0 0 0 1 0 0 1 1 0 0 2 1 1 0 2 0 0 2 0 0 1 0 0 1 0 1 1 0 0 0 1 0 0 1 1 0 0 1 0 1 0 0 0 1 0 0 1 0 0 0 0 0 1 0 0 1 0 0 0 0 0 2 1 0 0 0 0 0 0 0 0 0 0 0 1 0 1 0 0 0 0 0 0 0 1 1</counts>
			</dataPoints>
		</scan>
		<scan status="Completed" appendNumber="0" scanAxis="2Theta" mode="Continuous">
			<header>
				<startTimeStamp>2023-01-13T16:56:26-05:00</startTimeStamp>
				<endTimeStamp>2023-01-13T17:12:39-05:00</endTimeStamp>
				<author>
					<name>User</name>
				</author>
				<source>
					<applicationSoftware version="7.1">Data Collector</applicationSoftware>
					<instrumentControlSoftware version="8.2  20201204">EMPYREAN</instrumentControlSoftware>
					<instrumentID>0000000011260721</instrumentID>
				</source>
			</header>
			<dataPoints>
				<positions axis="2Theta" unit="deg">
					<startPosition>75.2010820516944</startPosition>
					<endPosition>78.5483518229109</endPosition>
				</positions>
				<positions axis="Omega" unit="deg">
					<commonPosition>19.9539584686513</commonPosition>
				</positions>
				<positions axis="Phi" unit="deg">
					<commonPosition>-86.42</commonPosition>
				</positions>
				<positions axis="Chi" unit="deg">
					<commonPosition>0</commonPosition>
				</positions>
				<positions axis="Z" unit="mm">
					<commonPosition>8.428</commonPosition>
				</positions>
				<commonCountingTime unit="seconds">0.784</commonCountingTime>
				<counts unit="counts">1 1 1 0 0 0 1 0 2 1 0 0 0 0 0 0 3 0 1 0 1 1 0 0 0 1 0 0 0 1 0 1 1 0 0 0 0 1 1 0 0 0 0 0 0 0 0 0 1 0 1 2 2 1 0 0 0 0 0 0 0 0 0 1 2 0 1 0 0 2 0 2 1 0 0 3 1 0 0 1 0 1 2 0 0 1 0 1 1 0 0 2 0 1 0 0 1 0 0 0 0 0 0 1 0 0 0 0 1 0 0 1 0 2 0 1 1 0 2 0 1 0 0 0 1 0 0 0 1 0 1 0 0 0 0 0 0 0 1 0 0 0 0 0 0 1 0 1 0 0 0 0 0 0 0 1 0 1 0 0 0 0 0 0 1 0 1 1 0 0 0 1 0 0 1 0 0 0 0 0 0 0 0 0 0 0 0 1 0 1 0 0 0 0 0 0 0 0 0 0 0 0 0 0 0 0 0 0 3 0 1 0 1 0 0 0 0 0 0 0 1 1 0 1 0 0 1 0 0 0 0 1 0 1 1 0 0 0 1 1 0 0 0 0 0 0 0 1 0 1 0 0 0 0 0</counts>
			</dataPoints>
		</scan>
		<scan status="Completed" appendNumber="0" scanAxis="2Theta" mode="Continuous">
			<header>
				<startTimeStamp>2023-01-13T16:56:26-05:00</startTimeStamp>
				<endTimeStamp>2023-01-13T17:12:39-05:00</endTimeStamp>
				<author>
					<name>User</name>
				</author>
				<source>
					<applicationSoftware version="7.1">Data Collector</applicationSoftware>
					<instrumentControlSoftware version="8.2  20201204">EMPYREAN</instrumentControlSoftware>
					<instrumentID>0000000011260721</instrumentID>
				</source>
			</header>
			<dataPoints>
				<positions axis="2Theta" unit="deg">
					<startPosition>75.2043646223687</startPosition>
					<endPosition>78.5516343935852</endPosition>
				</positions>
				<positions axis="Omega" unit="deg">
					<commonPosition>19.9555997539885</commonPosition>
				</positions>
				<positions axis="Phi" unit="deg">
					<commonPosition>-86.42</commonPosition>
				</positions>
				<positions axis="Chi" unit="deg">
					<commonPosition>0</commonPosition>
				</positions>
				<positions axis="Z" unit="mm">
					<commonPosition>8.428</commonPosition>
				</positions>
				<commonCountingTime unit="seconds">0.784</commonCountingTime>
				<counts unit="counts">0 0 0 1 0 0 0 0 0 2 0 0 1 0 0 1 1 1 1 0 0 0 1 0 0 0 1 0 2 0 0 1 0 0 2 0 0 0 0 0 0 0 1 0 1 1 0 0 0 1 0 2 0 0 0 1 1 1 0 0 1 0 0 1 1 3 0 1 2 2 1 1 0 2 1 1 2 0 2 1 1 0 1 0 2 0 1 0 1 0 1 0 0 1 0 0 0 0 0 0 0 0 0 1 0 0 0 1 0 0 0 1 0 0 0 0 0 0 0 0 1 0 0 0 0 2 0 0 0 1 0 0 0 1 0 0 0 0 0 1 0 0 1 0 0 1 0 0 0 1 0 1 0 0 0 0 0 0 0 0 1 0 0 0 1 0 0 0 0 0 1 0 0 0 0 0 1 1 0 1 0 0 0 0 2 0 0 0 0 0 0 0 0 0 0 0 0 0 0 0 0 0 1 0 0 0 0 0 0 0 1 0 0 0 1 1 0 0 1 1 0 1 1 1 0 1 0 1 1 0 0 0 1 0 0 0 0 0 2 0 1 0 1 0 0 1 2 1 1 0 2 0 1 1 2</counts>
			</dataPoints>
		</scan>
		<scan status="Completed" appendNumber="0" scanAxis="2Theta" mode="Continuous">
			<header>
				<startTimeStamp>2023-01-13T16:56:26-05:00</startTimeStamp>
				<endTimeStamp>2023-01-13T17:12:39-05:00</endTimeStamp>
				<author>
					<name>User</name>
				</author>
				<source>
					<applicationSoftware version="7.1">Data Collector</applicationSoftware>
					<instrumentControlSoftware version="8.2  20201204">EMPYREAN</instrumentControlSoftware>
					<instrumentID>0000000011260721</instrumentID>
				</source>
			</header>
			<dataPoints>
				<positions axis="2Theta" unit="deg">
					<startPosition>75.2076471930431</startPosition>
					<endPosition>78.5549169642595</endPosition>
				</positions>
				<positions axis="Omega" unit="deg">
					<commonPosition>19.9572410393257</commonPosition>
				</positions>
				<positions axis="Phi" unit="deg">
					<commonPosition>-86.42</commonPosition>
				</positions>
				<positions axis="Chi" unit="deg">
					<commonPosition>0</commonPosition>
				</positions>
				<positions axis="Z" unit="mm">
					<commonPosition>8.428</commonPosition>
				</positions>
				<commonCountingTime unit="seconds">0.784</commonCountingTime>
				<counts unit="counts">0 0 0 1 0 0 0 0 1 0 0 0 2 0 1 0 0 0 1 1 2 2 1 1 0 1 0 0 0 0 0 0 0 0 0 1 1 1 0 0 0 0 0 0 0 0 1 1 0 0 1 0 0 0 0 1 0 0 1 0 0 0 1 0 0 1 0 0 0 1 0 0 1 1 1 0 1 0 1 0 1 0 0 0 1 0 0 0 2 0 0 0 0 0 0 1 0 0 0 1 0 0 2 0 1 0 0 1 0 2 1 1 0 1 0 0 0 0 0 0 0 0 0 0 4 3 1 1 1 0 1 0 1 0 1 0 0 0 2 0 0 2 3 0 0 1 0 0 0 0 0 0 0 1 0 0 0 1 0 1 0 0 1 1 0 0 0 0 0 0 0 0 0 0 0 0 0 0 0 3 0 0 0 1 0 1 0 0 0 0 0 0 0 1 1 0 0 0 0 0 0 2 0 0 0 0 0 1 0 0 2 0 0 0 2 0 1 1 0 1 0 0 0 1 1 1 1 0 1 0 1 0 0 0 0 2 0 0 0 1 0 1 0 0 0 0 0 1 0 2 0 0 0 1 0</counts>
			</dataPoints>
		</scan>
		<scan status="Completed" appendNumber="0" scanAxis="2Theta" mode="Continuous">
			<header>
				<startTimeStamp>2023-01-13T16:56:26-05:00</startTimeStamp>
				<endTimeStamp>2023-01-13T17:12:39-05:00</endTimeStamp>
				<author>
					<name>User</name>
				</author>
				<source>
					<applicationSoftware version="7.1">Data Collector</applicationSoftware>
					<instrumentControlSoftware version="8.2  20201204">EMPYREAN</instrumentControlSoftware>
					<instrumentID>0000000011260721</instrumentID>
				</source>
			</header>
			<dataPoints>
				<positions axis="2Theta" unit="deg">
					<startPosition>75.2109297637174</startPosition>
					<endPosition>78.5581995349339</endPosition>
				</positions>
				<positions axis="Omega" unit="deg">
					<commonPosition>19.9588823246628</commonPosition>
				</positions>
				<positions axis="Phi" unit="deg">
					<commonPosition>-86.42</commonPosition>
				</positions>
				<positions axis="Chi" unit="deg">
					<commonPosition>0</commonPosition>
				</positions>
				<positions axis="Z" unit="mm">
					<commonPosition>8.428</commonPosition>
				</positions>
				<commonCountingTime unit="seconds">0.784</commonCountingTime>
				<counts unit="counts">0 2 0 0 0 0 2 0 0 2 0 0 0 1 0 0 0 0 0 1 0 0 1 0 0 1 0 1 0 1 0 0 0 0 0 0 1 0 0 0 0 0 0 0 0 2 0 1 0 0 0 1 0 0 0 0 1 0 1 0 0 2 0 0 0 0 0 0 0 0 0 0 0 0 0 1 0 0 0 1 0 1 0 2 0 0 0 1 1 0 0 0 0 0 0 0 0 1 0 0 0 0 1 0 0 0 1 1 0 0 0 0 0 0 0 0 0 0 0 0 0 0 0 1 0 0 0 0 0 0 1 0 0 0 0 0 1 2 0 2 0 1 0 1 0 0 0 1 1 0 0 2 1 0 0 1 1 1 0 1 0 0 1 1 0 2 0 0 0 1 0 0 0 1 1 0 1 1 0 0 0 0 0 0 1 0 2 0 1 0 0 1 0 1 0 0 0 0 0 1 0 2 0 0 0 0 1 0 0 0 0 0 0 0 1 0 0 0 0 0 0 0 0 1 0 0 0 1 0 0 1 0 0 1 2 0 0 0 0 0 2 0 0 0 0 0 0 0 1 0 1 0 0 0 0</counts>
			</dataPoints>
		</scan>
		<scan status="Completed" appendNumber="0" scanAxis="2Theta" mode="Continuous">
			<header>
				<startTimeStamp>2023-01-13T16:56:26-05:00</startTimeStamp>
				<endTimeStamp>2023-01-13T17:12:39-05:00</endTimeStamp>
				<author>
					<name>User</name>
				</author>
				<source>
					<applicationSoftware version="7.1">Data Collector</applicationSoftware>
					<instrumentControlSoftware version="8.2  20201204">EMPYREAN</instrumentControlSoftware>
					<instrumentID>0000000011260721</instrumentID>
				</source>
			</header>
			<dataPoints>
				<positions axis="2Theta" unit="deg">
					<startPosition>75.2142123343918</startPosition>
					<endPosition>78.5614821056082</endPosition>
				</positions>
				<positions axis="Omega" unit="deg">
					<commonPosition>19.96052361</commonPosition>
				</positions>
				<positions axis="Phi" unit="deg">
					<commonPosition>-86.42</commonPosition>
				</positions>
				<positions axis="Chi" unit="deg">
					<commonPosition>0</commonPosition>
				</positions>
				<positions axis="Z" unit="mm">
					<commonPosition>8.428</commonPosition>
				</positions>
				<commonCountingTime unit="seconds">0.784</commonCountingTime>
				<counts unit="counts">0 0 1 0 0 0 1 1 0 1 0 1 0 0 0 0 0 0 0 0 1 0 0 1 1 0 0 0 0 0 1 3 0 0 0 0 0 0 1 1 3 0 0 0 0 0 0 0 2 0 0 0 2 1 0 0 2 1 0 1 0 0 0 1 1 0 1 0 0 0 0 0 1 2 1 2 1 0 0 0 0 0 0 0 0 0 0 0 1 0 0 0 1 1 0 0 1 0 0 0 0 0 0 0 0 0 0 1 3 0 1 0 0 0 1 1 0 0 0 1 1 0 0 0 0 0 0 0 0 2 1 0 0 0 0 0 1 3 0 1 1 1 0 0 0 0 0 0 0 1 0 0 0 1 0 0 1 1 1 2 0 0 0 0 1 0 0 0 0 0 1 1 0 0 2 0 2 0 1 0 0 0 0 0 0 1 0 0 0 1 2 0 0 1 0 0 0 0 0 0 0 2 0 1 0 0 0 1 0 1 0 0 0 0 0 0 0 0 1 1 1 1 2 0 0 0 0 0 0 0 0 1 0 0 0 0 0 0 2 1 1 0 0 0 0 1 0 0 0 1 0 0 0 2 0</counts>
			</dataPoints>
		</scan>
	</xrdMeasurement>
</xrdMeasurements>