File: data/YY189_RSM_240 332 420/YY189_RSM 240 slow.xrdml
<?xml version="1.0" encoding="utf-8"?>
<xrdMeasurements xmlns="http://www.xrdml.com/XRDMeasurement/2.2" xmlns:xsi="http://www.w3.org/2001/XMLSchema-instance" xsi:schemaLocation="http://www.xrdml.com/XRDMeasurement/2.2 http://www.xrdml.com/XRDMeasurement/2.2/XRDMeasurement.xsd" status="Completed">
	<comment>
		<entry>Configuration=3-axes Cradle_Reflection, Owner=User, Creation date=9/2/2021 3:55:24 PM</entry>
		<entry>Goniometer=Theta/Theta; Minimum step size 2Theta:0.0001; Minimum step size Omega:0.0001</entry>
		<entry>Sample stage=Chi-Phi-z stage 240 mm (reflection); Minimum step size Phi:0.01; Minimum step size Chi:0.01; Minimum step size Z:0.001</entry>
		<entry>Diffractometer system=EMPYREAN</entry>
		<entry>Measurement program=C:\PANalytical\Data Collector\Programs\Yu Yun\RSM\RSM 2degree_high resolution_ultra slow.xrdmp, Identifier={E7FADADD-DC24-46CD-AE09-8DCC8F7825B3}</entry>
	</comment>
	<sample type="To be analyzed">
		<id/>
		<name/>
		<preparedBy/>
	</sample>
	<xrdMeasurement status="Completed" measurementType="Area measurement" measurementStepAxis="Omega-2Theta" sampleMode="Reflection">
		<comment>
			<entry>PHD Lower Level = 4.02 (keV), PHD Upper Level = 11.26 (keV)</entry>
		</comment>
		<usedWavelength intended="K-Alpha">
			<kAlpha1 unit="Angstrom">1.5405980</kAlpha1>
			<kAlpha2 unit="Angstrom">1.5444260</kAlpha2>
			<kBeta unit="Angstrom">1.3922500</kBeta>
			<ratioKAlpha2KAlpha1>0</ratioKAlpha2KAlpha1>
		</usedWavelength>
		<incidentBeamPath>
			<radius unit="mm">240.00</radius>
			<xRayTube id="1010048" name="Empyrean Cu LFF HR (9430 033 7310x) DK432574">
				<tension unit="kV">45.0</tension>
				<current unit="mA">40.0</current>
				<anodeMaterial>Cu</anodeMaterial>
				<focus type="Line">
					<length unit="mm">12.0</length>
					<width unit="mm">0.4</width>
					<takeOffAngle unit="deg">4.4</takeOffAngle>
				</focus>
			</xRayTube>
			<xRayMirror xsi:type="xRayMirrorType" id="27080001" name="Inc. Beam Cu W/Si (hybrid MPD)" hybrid="true">
				<crystal type="Graded" shape="Parabolic">W/Si</crystal>
				<acceptanceAngle unit="deg">0.800</acceptanceAngle>
				<length unit="mm">55.3</length>
			</xRayMirror>
			<monochromator xsi:type="monochromatorType" id="23090002" name="Hybrid monochr. 2xGe220 Cu asym." hybrid="true">
				<crystal type="Asymmetric" shape="Flat">Ge</crystal>
				<numberOfReflections>2</numberOfReflections>
				<hkl>
					<h>2</h>
					<k>2</k>
					<l>0</l>
				</hkl>
			</monochromator>
			<mask xsi:type="maskType" id="22030008" name="Fixed mask 4 mm">
				<distanceToSample unit="mm">171.00</distanceToSample>
				<width unit="mm">4.00</width>
			</mask>
			<divergenceSlit xsi:type="fixedDivergenceSlitType" id="22010007" name="Fixed slit 1/8°">
				<distanceToSample unit="mm">179.30</distanceToSample>
				<height unit="mm">0.19</height>
			</divergenceSlit>
		</incidentBeamPath>
		<diffractedBeamPath>
			<radius unit="mm">240.00</radius>
			<antiScatterSlit xsi:type="fixedAntiScatterSlitType" id="22060009" name="Programmable anti-scatter slit">
				<angle unit="deg">4</angle>
			</antiScatterSlit>
			<detector xsi:type="areaDetectorType" id="7010020" name="PIXcel3D-Medipix3 1x1 detector">
				<phd unit="%">
					<lowerLevel>25</lowerLevel>
					<upperLevel>70</upperLevel>
				</phd>
				<mode>Scanning snapshot equatorial</mode>
				<activeChannelsEquatorial>255</activeChannelsEquatorial>
				<activeChannelsAxial>255</activeChannelsAxial>
				<pitchEquatorial unit="mm">0.05500</pitchEquatorial>
				<pitchAxial unit="mm">0.05500</pitchAxial>
				<readOutPeriod unit="seconds">0.790</readOutPeriod>
			</detector>
		</diffractedBeamPath>
		<scan status="Completed" appendNumber="0" scanAxis="2Theta" mode="Continuous">
			<header>
				<startTimeStamp>2023-01-13T16:09:10-05:00</startTimeStamp>
				<endTimeStamp>2023-01-13T16:25:22-05:00</endTimeStamp>
				<author>
					<name>User</name>
				</author>
				<source>
					<applicationSoftware version="7.1">Data Collector</applicationSoftware>
					<instrumentControlSoftware version="8.2  20201204">EMPYREAN</instrumentControlSoftware>
					<instrumentID>0000000011260721</instrumentID>
				</source>
			</header>
			<dataPoints>
				<positions axis="2Theta" unit="deg">
					<startPosition>71.4316063943918</startPosition>
					<endPosition>74.7788761656082</endPosition>
				</positions>
				<positions axis="Omega" unit="deg">
					<commonPosition>18.20412064</commonPosition>
				</positions>
				<positions axis="Phi" unit="deg">
					<commonPosition>-176.42</commonPosition>
				</positions>
				<positions axis="Chi" unit="deg">
					<commonPosition>0</commonPosition>
				</positions>
				<positions axis="Z" unit="mm">
					<commonPosition>8.428</commonPosition>
				</positions>
				<commonCountingTime unit="seconds">0.784</commonCountingTime>
				<counts unit="counts">0 0 0 1 0 0 1 1 1 0 0 0 2 0 0 1 1 0 0 0 1 0 1 0 0 0 0 0 0 0 1 0 0 1 1 0 0 0 1 1 0 0 1 0 0 0 0 0 0 0 0 0 0 0 0 0 1 0 0 0 1 0 0 1 2 0 0 1 0 1 2 0 0 1 0 0 0 0 0 0 0 0 0 1 0 0 0 0 0 0 0 0 1 0 2 0 1 0 1 0 1 0 0 1 0 1 0 0 0 0 1 0 0 0 0 0 0 0 0 0 0 0 0 0 0 2 1 1 0 0 2 0 0 0 1 1 1 0 0 2 0 0 0 2 0 0 0 0 1 0 0 0 0 0 0 1 0 1 0 1 1 1 0 1 1 0 0 1 1 0 0 1 1 3 5 2 2 1 0 0 1 0 0 0 0 0 1 0 0 0 1 0 0 1 0 0 0 2 0 0 0 0 0 0 1 0 0 1 1 1 0 0 0 0 0 0 1 1 0 1 1 3 1 0 0 0 1 0 1 0 1 0 1 0 0 0 3 1 0 1 0 1 1 2 1 0 1 0 0 0 1 0 0 1 0</counts>
			</dataPoints>
		</scan>
		<scan status="Completed" appendNumber="0" scanAxis="2Theta" mode="Continuous">
			<header>
				<startTimeStamp>2023-01-13T16:09:10-05:00</startTimeStamp>
				<endTimeStamp>2023-01-13T16:25:22-05:00</endTimeStamp>
				<author>
					<name>User</name>
				</author>
				<source>
					<applicationSoftware version="7.1">Data Collector</applicationSoftware>
					<instrumentControlSoftware version="8.2  20201204">EMPYREAN</instrumentControlSoftware>
					<instrumentID>0000000011260721</instrumentID>
				</source>
			</header>
			<dataPoints>
				<positions axis="2Theta" unit="deg">
					<startPosition>71.4348889650661</startPosition>
					<endPosition>74.7821587362826</endPosition>
				</positions>
				<positions axis="Omega" unit="deg">
					<commonPosition>18.2057619253372</commonPosition>
				</positions>
				<positions axis="Phi" unit="deg">
					<commonPosition>-176.42</commonPosition>
				</positions>
				<positions axis="Chi" unit="deg">
					<commonPosition>0</commonPosition>
				</positions>
				<positions axis="Z" unit="mm">
					<commonPosition>8.428</commonPosition>
				</positions>
				<commonCountingTime unit="seconds">0.784</commonCountingTime>
				<counts unit="counts">1 0 0 0 0 0 0 0 1 0 1 0 0 1 0 2 0 0 0 1 1 0 0 0 1 0 0 0 0 1 2 1 0 1 1 1 0 0 0 0 0 0 0 1 0 0 0 0 1 1 0 0 0 0 0 1 0 1 0 0 0 0 1 1 0 0 1 0 1 0 2 0 0 0 0 2 0 0 0 0 0 1 0 0 0 0 0 1 1 0 1 0 0 1 0 0 0 0 0 1 0 0 0 1 0 1 1 0 0 0 0 0 0 0 0 0 1 0 0 0 1 0 0 1 0 0 1 1 0 1 0 0 1 0 1 1 1 0 0 0 1 1 0 1 0 0 0 3 0 0 0 0 0 0 0 0 1 0 0 0 0 1 1 1 0 0 1 0 0 1 0 1 2 2 4 2 1 1 0 0 1 1 0 0 0 0 0 0 0 0 0 0 1 0 0 2 0 2 0 1 0 2 2 0 0 0 0 1 0 0 0 1 0 2 1 0 2 1 1 0 3 0 1 0 0 0 0 0 0 0 0 1 0 0 0 0 0 0 1 0 0 0 0 0 0 0 0 0 0 1 0 0 1 0 0</counts>
			</dataPoints>
		</scan>
		<scan status="Completed" appendNumber="0" scanAxis="2Theta" mode="Continuous">
			<header>
				<startTimeStamp>2023-01-13T16:09:10-05:00</startTimeStamp>
				<endTimeStamp>2023-01-13T16:25:22-05:00</endTimeStamp>
				<author>
					<name>User</name>
				</author>
				<source>
					<applicationSoftware version="7.1">Data Collector</applicationSoftware>
					<instrumentControlSoftware version="8.2  20201204">EMPYREAN</instrumentControlSoftware>
					<instrumentID>0000000011260721</instrumentID>
				</source>
			</header>
			<dataPoints>
				<positions axis="2Theta" unit="deg">
					<startPosition>71.4381715357405</startPosition>
					<endPosition>74.7854413069569</endPosition>
				</positions>
				<positions axis="Omega" unit="deg">
					<commonPosition>18.2074032106743</commonPosition>
				</positions>
				<positions axis="Phi" unit="deg">
					<commonPosition>-176.42</commonPosition>
				</positions>
				<positions axis="Chi" unit="deg">
					<commonPosition>0</commonPosition>
				</positions>
				<positions axis="Z" unit="mm">
					<commonPosition>8.428</commonPosition>
				</positions>
				<commonCountingTime unit="seconds">0.784</commonCountingTime>
				<counts unit="counts">1 0 0 1 0 0 1 0 0 0 1 2 0 0 0 0 1 0 0 0 0 1 1 1 1 1 0 0 1 1 1 0 1 1 0 0 0 0 0 0 1 0 1 0 0 0 0 0 1 0 0 0 0 0 0 0 0 0 0 0 0 0 0 1 0 0 0 0 0 0 0 0 1 0 0 0 0 1 0 0 1 1 0 1 0 0 0 0 0 0 2 0 1 0 0 1 1 1 0 0 1 0 0 0 0 0 0 0 1 0 0 0 0 0 1 1 1 0 0 0 0 1 0 0 0 2 0 0 0 0 1 0 0 1 0 1 1 0 1 1 1 0 0 2 1 0 1 1 0 0 0 0 0 0 0 0 0 0 0 0 0 1 0 0 0 0 0 1 1 0 0 1 2 2 2 0 0 0 1 2 1 0 1 1 0 0 1 1 2 0 2 1 0 0 0 1 0 0 0 0 0 1 2 0 1 0 0 0 0 0 0 2 0 0 2 0 0 1 0 2 1 1 1 1 1 1 0 0 1 0 2 0 0 0 0 1 0 0 0 1 0 0 0 1 1 0 0 1 1 0 0 0 0 0 1</counts>
			</dataPoints>
		</scan>
		<scan status="Completed" appendNumber="0" scanAxis="2Theta" mode="Continuous">
			<header>
				<startTimeStamp>2023-01-13T16:09:10-05:00</startTimeStamp>
				<endTimeStamp>2023-01-13T16:25:22-05:00</endTimeStamp>
				<author>
					<name>User</name>
				</author>
				<source>
					<applicationSoftware version="7.1">Data Collector</applicationSoftware>
					<instrumentControlSoftware version="8.2  20201204">EMPYREAN</instrumentControlSoftware>
					<instrumentID>0000000011260721</instrumentID>
				</source>
			</header>
			<dataPoints>
				<positions axis="2Theta" unit="deg">
					<startPosition>71.4414541064148</startPosition>
					<endPosition>74.7887238776313</endPosition>
				</positions>
				<positions axis="Omega" unit="deg">
					<commonPosition>18.2090444960115</commonPosition>
				</positions>
				<positions axis="Phi" unit="deg">
					<commonPosition>-176.42</commonPosition>
				</positions>
				<positions axis="Chi" unit="deg">
					<commonPosition>0</commonPosition>
				</positions>
				<positions axis="Z" unit="mm">
					<commonPosition>8.428</commonPosition>
				</positions>
				<commonCountingTime unit="seconds">0.784</commonCountingTime>
				<counts unit="counts">0 0 0 1 0 1 0 0 1 0 1 0 1 0 2 0 0 0 1 0 0 0 1 1 1 0 0 0 0 0 0 3 0 0 0 1 0 0 1 0 1 0 0 2 0 0 0 0 0 1 0 0 0 0 0 0 0 1 0 0 0 0 0 0 0 0 0 0 0 0 0 1 2 0 0 1 0 0 1 0 2 0 0 1 1 0 1 0 1 0 0 0 0 0 0 1 0 0 2 0 3 0 1 0 0 0 1 1 0 0 0 0 0 1 0 0 2 1 0 0 0 0 1 0 0 1 0 0 1 1 0 0 3 0 0 0 0 0 0 0 0 1 1 0 0 1 1 2 0 0 0 1 0 0 1 2 0 0 1 0 0 1 1 1 0 0 0 1 0 3 1 1 2 1 3 1 0 0 0 0 0 0 1 0 1 0 2 2 2 1 0 0 1 3 0 0 0 1 0 3 0 0 0 1 0 1 1 0 0 0 0 0 0 1 1 0 1 0 1 2 0 0 0 1 0 0 0 0 0 0 0 0 2 1 0 0 0 0 0 0 0 0 0 0 0 0 0 2 0 0 0 0 0 0 0</counts>
			</dataPoints>
		</scan>
		<scan status="Completed" appendNumber="0" scanAxis="2Theta" mode="Continuous">
			<header>
				<startTimeStamp>2023-01-13T16:09:10-05:00</startTimeStamp>
				<endTimeStamp>2023-01-13T16:25:22-05:00</endTimeStamp>
				<author>
					<name>User</name>
				</author>
				<source>
					<applicationSoftware version="7.1">Data Collector</applicationSoftware>
					<instrumentControlSoftware version="8.2  20201204">EMPYREAN</instrumentControlSoftware>
					<instrumentID>0000000011260721</instrumentID>
				</source>
			</header>
			<dataPoints>
				<positions axis="2Theta" unit="deg">
					<startPosition>71.4447366770891</startPosition>
					<endPosition>74.7920064483056</endPosition>
				</positions>
				<positions axis="Omega" unit="deg">
					<commonPosition>18.2106857813487</commonPosition>
				</positions>
				<positions axis="Phi" unit="deg">
					<commonPosition>-176.42</commonPosition>
				</positions>
				<positions axis="Chi" unit="deg">
					<commonPosition>0</commonPosition>
				</positions>
				<positions axis="Z" unit="mm">
					<commonPosition>8.428</commonPosition>
				</positions>
				<commonCountingTime unit="seconds">0.784</commonCountingTime>
				<counts unit="counts">0 0 0 2 1 0 0 0 1 1 0 3 0 0 1 0 0 0 0 0 1 0 0 0 1 0 0 0 0 0 0 0 1 0 1 0 0 0 0 0 0 0 0 0 0 0 0 0 2 0 0 0 0 1 1 1 0 0 0 0 0 0 0 0 0 1 0 2 0 0 1 0 0 0 0 0 0 0 0 0 1 1 0 0 0 0 2 0 0 0 1 0 0 0 0 0 1 0 0 0 0 0 0 0 1 0 1 1 1 0 0 1 0 1 0 0 0 0 0 0 0 1 0 0 0 0 2 1 1 0 0 0 1 0 0 0 0 0 1 0 0 0 0 0 1 0 0 0 0 0 1 0 0 0 0 1 1 0 1 0 0 0 0 2 1 2 0 1 1 0 1 3 1 3 4 2 0 0 1 0 1 0 0 0 1 0 0 1 2 0 1 0 0 4 0 0 0 1 2 0 1 0 0 0 1 0 1 0 1 0 0 0 0 0 0 0 0 0 2 0 2 0 0 1 1 0 1 0 0 1 0 0 0 0 0 0 0 0 1 0 0 0 1 2 0 1 0 1 2 1 0 0 1 0 0</counts>
			</dataPoints>
		</scan>
		<scan status="Completed" appendNumber="0" scanAxis="2Theta" mode="Continuous">
			<header>
				<startTimeStamp>2023-01-13T16:09:10-05:00</startTimeStamp>
				<endTimeStamp>2023-01-13T16:25:22-05:00</endTimeStamp>
				<author>
					<name>User</name>
				</author>
				<source>
					<applicationSoftware version="7.1">Data Collector</applicationSoftware>
					<instrumentControlSoftware version="8.2  20201204">EMPYREAN</instrumentControlSoftware>
					<instrumentID>0000000011260721</instrumentID>
				</source>
			</header>
			<dataPoints>
				<positions axis="2Theta" unit="deg">
					<startPosition>71.4480192477635</startPosition>
					<endPosition>74.79528901898</endPosition>
				</positions>
				<positions axis="Omega" unit="deg">
					<commonPosition>18.2123270666859</commonPosition>
				</positions>
				<positions axis="Phi" unit="deg">
					<commonPosition>-176.42</commonPosition>
				</positions>
				<positions axis="Chi" unit="deg">
					<commonPosition>0</commonPosition>
				</positions>
				<positions axis="Z" unit="mm">
					<commonPosition>8.428</commonPosition>
				</positions>
				<commonCountingTime unit="seconds">0.784</commonCountingTime>
				<counts unit="counts">0 0 0 1 1 0 0 0 1 0 2 1 0 1 0 0 2 0 0 0 1 0 0 0 1 0 0 0 1 0 1 0 0 0 0 0 0 0 0 0 0 0 0 0 0 0 0 1 0 1 1 0 0 1 1 0 0 1 0 0 1 0 2 0 0 0 1 1 0 0 0 0 1 0 0 0 0 2 1 0 0 0 1 0 1 0 0 0 1 0 0 1 0 1 0 1 0 0 2 0 1 0 1 1 0 1 0 2 0 0 0 0 2 0 0 0 0 1 1 3 3 0 0 1 1 0 1 0 0 0 0 0 0 2 1 1 1 0 1 0 2 0 0 1 0 0 0 0 0 0 1 2 1 0 0 1 0 3 0 1 1 0 0 0 1 1 0 0 0 2 1 0 1 4 0 0 0 0 0 0 1 0 0 1 0 1 0 1 2 0 0 0 0 0 1 0 1 1 0 0 0 0 1 0 0 0 0 0 1 1 0 2 0 0 1 0 0 0 2 0 1 0 0 0 1 0 0 0 1 1 1 0 0 1 0 0 1 1 0 0 0 0 0 0 0 0 1 0 0 0 0 1 0 0 1</counts>
			</dataPoints>
		</scan>
		<scan status="Completed" appendNumber="0" scanAxis="2Theta" mode="Continuous">
			<header>
				<startTimeStamp>2023-01-13T16:09:10-05:00</startTimeStamp>
				<endTimeStamp>2023-01-13T16:25:22-05:00</endTimeStamp>
				<author>
					<name>User</name>
				</author>
				<source>
					<applicationSoftware version="7.1">Data Collector</applicationSoftware>
					<instrumentControlSoftware version="8.2  20201204">EMPYREAN</instrumentControlSoftware>
					<instrumentID>0000000011260721</instrumentID>
				</source>
			</header>
			<dataPoints>
				<positions axis="2Theta" unit="deg">
					<startPosition>71.4513018184378</startPosition>
					<endPosition>74.7985715896543</endPosition>
				</positions>
				<positions axis="Omega" unit="deg">
					<commonPosition>18.213968352023</commonPosition>
				</positions>
				<positions axis="Phi" unit="deg">
					<commonPosition>-176.42</commonPosition>
				</positions>
				<positions axis="Chi" unit="deg">
					<commonPosition>0</commonPosition>
				</positions>
				<positions axis="Z" unit="mm">
					<commonPosition>8.428</commonPosition>
				</positions>
				<commonCountingTime unit="seconds">0.784</commonCountingTime>
				<counts unit="counts">0 1 1 0 1 0 0 1 0 0 0 1 0 0 0 0 0 1 0 1 0 2 2 0 1 0 0 0 0 1 0 0 0 0 0 0 0 0 1 0 0 0 0 0 2 0 1 0 0 0 1 0 0 1 0 1 0 0 2 0 1 1 0 0 1 0 0 1 0 0 0 1 0 1 0 0 0 0 0 0 1 0 0 1 0 0 0 0 0 1 0 0 0 1 0 0 1 0 1 0 1 0 0 1 0 0 0 1 0 0 0 1 0 0 0 3 0 0 1 0 1 1 3 1 0 0 0 0 1 0 0 0 0 1 0 0 0 0 1 0 0 0 0 1 0 0 0 1 1 0 0 0 1 0 2 0 0 0 0 1 0 0 0 0 0 0 0 0 0 0 0 0 1 0 3 2 0 2 2 0 0 0 0 1 1 0 0 1 1 0 0 0 0 1 0 0 1 0 1 0 0 0 0 1 1 1 2 1 0 2 0 1 2 0 0 1 0 1 0 1 1 2 0 0 1 0 1 0 0 0 1 0 0 2 0 1 0 0 1 0 0 0 0 0 0 0 0 0 0 1 1 1 2 0 0</counts>
			</dataPoints>
		</scan>
		<scan status="Completed" appendNumber="0" scanAxis="2Theta" mode="Continuous">
			<header>
				<startTimeStamp>2023-01-13T16:09:10-05:00</startTimeStamp>
				<endTimeStamp>2023-01-13T16:25:22-05:00</endTimeStamp>
				<author>
					<name>User</name>
				</author>
				<source>
					<applicationSoftware version="7.1">Data Collector</applicationSoftware>
					<instrumentControlSoftware version="8.2  20201204">EMPYREAN</instrumentControlSoftware>
					<instrumentID>0000000011260721</instrumentID>
				</source>
			</header>
			<dataPoints>
				<positions axis="2Theta" unit="deg">
					<startPosition>71.4545843891122</startPosition>
					<endPosition>74.8018541603286</endPosition>
				</positions>
				<positions axis="Omega" unit="deg">
					<commonPosition>18.2156096373602</commonPosition>
				</positions>
				<positions axis="Phi" unit="deg">
					<commonPosition>-176.42</commonPosition>
				</positions>
				<positions axis="Chi" unit="deg">
					<commonPosition>0</commonPosition>
				</positions>
				<positions axis="Z" unit="mm">
					<commonPosition>8.428</commonPosition>
				</positions>
				<commonCountingTime unit="seconds">0.784</commonCountingTime>
				<counts unit="counts">0 0 0 1 0 0 0 0 1 0 2 2 1 0 3 0 0 0 0 0 1 0 1 1 0 0 0 0 1 0 0 0 0 1 1 1 0 0 0 0 2 1 0 0 0 0 0 0 0 0 2 0 0 0 0 2 1 0 1 0 0 1 0 0 0 0 1 0 0 0 1 0 1 1 0 0 1 0 0 1 1 0 2 2 0 0 0 1 0 0 1 1 0 1 0 0 0 0 1 1 0 0 0 0 0 1 0 1 1 0 0 0 0 0 1 0 0 0 2 0 0 0 1 0 0 0 0 1 3 0 1 0 0 0 0 1 2 0 0 0 0 0 0 0 0 1 0 0 1 1 0 0 1 2 0 0 0 0 0 1 0 1 1 3 0 1 0 0 1 0 0 4 3 2 2 1 0 0 0 0 2 1 1 0 0 0 1 0 1 0 1 2 0 0 0 2 0 1 0 0 1 0 0 0 0 0 0 1 2 1 0 0 0 0 0 0 0 2 1 0 0 0 2 0 0 1 0 0 0 0 1 1 0 1 0 1 0 1 0 0 2 1 0 0 0 0 0 1 0 1 1 0 0 0 0</counts>
			</dataPoints>
		</scan>
		<scan status="Completed" appendNumber="0" scanAxis="2Theta" mode="Continuous">
			<header>
				<startTimeStamp>2023-01-13T16:09:10-05:00</startTimeStamp>
				<endTimeStamp>2023-01-13T16:25:22-05:00</endTimeStamp>
				<author>
					<name>User</name>
				</author>
				<source>
					<applicationSoftware version="7.1">Data Collector</applicationSoftware>
					<instrumentControlSoftware version="8.2  20201204">EMPYREAN</instrumentControlSoftware>
					<instrumentID>0000000011260721</instrumentID>
				</source>
			</header>
			<dataPoints>
				<positions axis="2Theta" unit="deg">
					<startPosition>71.4578669597865</startPosition>
					<endPosition>74.805136731003</endPosition>
				</positions>
				<positions axis="Omega" unit="deg">
					<commonPosition>18.2172509226974</commonPosition>
				</positions>
				<positions axis="Phi" unit="deg">
					<commonPosition>-176.42</commonPosition>
				</positions>
				<positions axis="Chi" unit="deg">
					<commonPosition>0</commonPosition>
				</positions>
				<positions axis="Z" unit="mm">
					<commonPosition>8.428</commonPosition>
				</positions>
				<commonCountingTime unit="seconds">0.784</commonCountingTime>
				<counts unit="counts">0 0 0 0 2 0 0 1 0 1 0 1 0 0 0 0 1 0 1 0 0 2 0 0 0 0 0 1 0 0 0 1 0 1 1 0 0 0 0 0 0 0 0 5 2 0 1 2 1 0 0 1 1 0 0 0 0 0 0 1 0 0 0 1 0 0 2 0 0 0 1 0 0 1 1 1 0 2 2 0 0 1 0 1 0 0 1 0 2 1 0 0 0 0 1 1 0 0 0 0 0 0 0 0 1 1 0 1 0 1 0 0 1 0 0 0 0 0 0 0 0 0 0 0 0 0 0 0 0 0 0 0 1 1 0 0 0 1 0 2 0 0 0 0 0 0 0 0 0 0 0 0 0 1 0 1 0 1 0 1 1 0 0 0 1 0 0 1 1 0 1 0 3 6 2 2 0 1 0 1 1 0 0 3 0 1 1 1 0 1 0 1 1 0 0 1 0 0 0 0 0 1 0 0 0 0 2 0 1 1 1 0 0 0 0 0 0 0 1 0 0 0 0 0 0 0 0 0 0 1 1 0 0 0 0 0 0 0 1 0 0 0 2 0 0 0 1 1 0 0 0 0 0 0 0</counts>
			</dataPoints>
		</scan>
		<scan status="Completed" appendNumber="0" scanAxis="2Theta" mode="Continuous">
			<header>
				<startTimeStamp>2023-01-13T16:09:10-05:00</startTimeStamp>
				<endTimeStamp>2023-01-13T16:25:22-05:00</endTimeStamp>
				<author>
					<name>User</name>
				</author>
				<source>
					<applicationSoftware version="7.1">Data Collector</applicationSoftware>
					<instrumentControlSoftware version="8.2  20201204">EMPYREAN</instrumentControlSoftware>
					<instrumentID>0000000011260721</instrumentID>
				</source>
			</header>
			<dataPoints>
				<positions axis="2Theta" unit="deg">
					<startPosition>71.4611495304608</startPosition>
					<endPosition>74.8084193016773</endPosition>
				</positions>
				<positions axis="Omega" unit="deg">
					<commonPosition>18.2188922080345</commonPosition>
				</positions>
				<positions axis="Phi" unit="deg">
					<commonPosition>-176.42</commonPosition>
				</positions>
				<positions axis="Chi" unit="deg">
					<commonPosition>0</commonPosition>
				</positions>
				<positions axis="Z" unit="mm">
					<commonPosition>8.428</commonPosition>
				</positions>
				<commonCountingTime unit="seconds">0.784</commonCountingTime>
				<counts unit="counts">0 0 0 0 0 0 0 0 0 0 1 0 0 0 0 0 0 2 1 0 0 1 0 0 0 1 0 0 1 0 0 1 0 2 1 0 0 1 2 0 0 0 1 0 0 0 0 1 0 0 0 0 0 0 0 0 1 0 2 0 0 0 1 0 0 0 0 0 0 0 0 0 0 0 0 0 0 1 0 0 0 0 0 0 1 0 1 0 0 2 0 1 0 0 0 0 1 0 1 0 0 0 0 1 0 1 0 0 1 0 1 0 0 1 0 0 1 0 0 0 0 0 0 0 1 0 0 0 0 1 2 0 0 0 0 0 0 1 1 0 0 0 0 0 1 0 1 0 0 1 0 1 0 1 0 0 0 0 0 0 2 0 0 0 0 0 0 3 1 0 0 0 0 3 2 0 2 0 0 0 0 0 0 0 0 0 1 0 1 0 0 0 1 0 0 0 0 0 4 0 2 0 0 0 1 0 1 0 1 0 1 0 0 0 1 0 1 0 0 0 0 0 0 0 0 0 0 0 0 0 1 0 0 1 0 0 0 1 0 0 0 0 1 1 1 0 0 0 0 0 0 0 1 0 1</counts>
			</dataPoints>
		</scan>
		<scan status="Completed" appendNumber="0" scanAxis="2Theta" mode="Continuous">
			<header>
				<startTimeStamp>2023-01-13T16:09:10-05:00</startTimeStamp>
				<endTimeStamp>2023-01-13T16:25:22-05:00</endTimeStamp>
				<author>
					<name>User</name>
				</author>
				<source>
					<applicationSoftware version="7.1">Data Collector</applicationSoftware>
					<instrumentControlSoftware version="8.2  20201204">EMPYREAN</instrumentControlSoftware>
					<instrumentID>0000000011260721</instrumentID>
				</source>
			</header>
			<dataPoints>
				<positions axis="2Theta" unit="deg">
					<startPosition>71.4644321011352</startPosition>
					<endPosition>74.8117018723517</endPosition>
				</positions>
				<positions axis="Omega" unit="deg">
					<commonPosition>18.2205334933717</commonPosition>
				</positions>
				<positions axis="Phi" unit="deg">
					<commonPosition>-176.42</commonPosition>
				</positions>
				<positions axis="Chi" unit="deg">
					<commonPosition>0</commonPosition>
				</positions>
				<positions axis="Z" unit="mm">
					<commonPosition>8.428</commonPosition>
				</positions>
				<commonCountingTime unit="seconds">0.784</commonCountingTime>
				<counts unit="counts">0 0 1 0 0 0 0 0 0 0 0 1 1 1 0 0 0 1 4 1 0 1 0 0 0 0 0 0 0 0 0 1 1 0 0 3 2 0 0 1 0 0 1 1 0 0 0 0 0 1 0 0 0 0 0 0 1 0 0 0 1 1 0 1 0 0 0 0 1 2 0 0 0 2 0 1 0 0 0 0 0 1 0 1 0 0 0 0 0 0 1 0 0 0 0 1 0 0 1 1 1 0 0 1 0 1 0 0 0 2 0 0 1 0 0 0 0 0 1 0 1 0 0 0 1 0 0 0 1 0 0 0 0 0 1 0 0 0 1 1 1 0 0 0 2 0 1 0 0 1 0 0 0 0 0 0 2 0 0 0 1 0 0 0 0 0 1 2 1 0 0 5 4 1 7 1 0 0 0 1 0 2 1 0 0 1 0 0 0 1 1 2 0 0 0 0 1 0 0 1 1 0 1 0 1 0 0 1 0 0 1 0 0 0 0 0 0 1 0 1 0 0 0 0 0 0 1 1 0 0 0 0 1 0 0 1 0 0 1 0 0 0 0 0 2 0 0 0 0 0 0 0 1 0 1</counts>
			</dataPoints>
		</scan>
		<scan status="Completed" appendNumber="0" scanAxis="2Theta" mode="Continuous">
			<header>
				<startTimeStamp>2023-01-13T16:09:10-05:00</startTimeStamp>
				<endTimeStamp>2023-01-13T16:25:22-05:00</endTimeStamp>
				<author>
					<name>User</name>
				</author>
				<source>
					<applicationSoftware version="7.1">Data Collector</applicationSoftware>
					<instrumentControlSoftware version="8.2  20201204">EMPYREAN</instrumentControlSoftware>
					<instrumentID>0000000011260721</instrumentID>
				</source>
			</header>
			<dataPoints>
				<positions axis="2Theta" unit="deg">
					<startPosition>71.4677146718095</startPosition>
					<endPosition>74.814984443026</endPosition>
				</positions>
				<positions axis="Omega" unit="deg">
					<commonPosition>18.2221747787089</commonPosition>
				</positions>
				<positions axis="Phi" unit="deg">
					<commonPosition>-176.42</commonPosition>
				</positions>
				<positions axis="Chi" unit="deg">
					<commonPosition>0</commonPosition>
				</positions>
				<positions axis="Z" unit="mm">
					<commonPosition>8.428</commonPosition>
				</positions>
				<commonCountingTime unit="seconds">0.784</commonCountingTime>
				<counts unit="counts">1 0 1 1 0 1 0 0 0 1 0 0 1 0 0 0 0 0 0 0 0 0 1 0 0 1 1 0 0 0 0 0 0 1 1 0 0 0 1 1 1 0 3 0 0 0 0 1 0 0 2 1 0 0 0 0 0 1 0 1 0 1 0 1 0 0 0 0 0 0 0 0 0 0 0 0 0 1 0 1 1 0 0 1 0 1 1 0 1 0 0 0 1 0 0 0 1 0 1 0 0 0 0 0 0 0 1 0 0 1 0 0 0 0 0 0 2 0 1 0 2 0 0 0 0 0 0 0 1 0 2 3 1 0 0 0 0 2 1 2 1 0 0 1 1 1 0 0 0 0 0 1 0 1 0 0 2 0 0 1 2 0 0 0 1 0 0 0 1 1 1 1 1 1 0 1 0 0 1 0 1 0 0 0 1 0 1 0 0 1 1 1 0 0 0 0 0 0 1 0 0 0 0 1 0 0 0 1 0 0 0 0 0 1 1 0 1 0 0 0 0 0 0 0 1 0 0 0 1 0 1 0 0 0 1 0 0 0 1 0 0 1 0 1 0 1 0 1 0 0 0 0 0 0 1</counts>
			</dataPoints>
		</scan>
		<scan status="Completed" appendNumber="0" scanAxis="2Theta" mode="Continuous">
			<header>
				<startTimeStamp>2023-01-13T16:09:10-05:00</startTimeStamp>
				<endTimeStamp>2023-01-13T16:25:22-05:00</endTimeStamp>
				<author>
					<name>User</name>
				</author>
				<source>
					<applicationSoftware version="7.1">Data Collector</applicationSoftware>
					<instrumentControlSoftware version="8.2  20201204">EMPYREAN</instrumentControlSoftware>
					<instrumentID>0000000011260721</instrumentID>
				</source>
			</header>
			<dataPoints>
				<positions axis="2Theta" unit="deg">
					<startPosition>71.4709972424839</startPosition>
					<endPosition>74.8182670137003</endPosition>
				</positions>
				<positions axis="Omega" unit="deg">
					<commonPosition>18.2238160640461</commonPosition>
				</positions>
				<positions axis="Phi" unit="deg">
					<commonPosition>-176.42</commonPosition>
				</positions>
				<positions axis="Chi" unit="deg">
					<commonPosition>0</commonPosition>
				</positions>
				<positions axis="Z" unit="mm">
					<commonPosition>8.428</commonPosition>
				</positions>
				<commonCountingTime unit="seconds">0.784</commonCountingTime>
				<counts unit="counts">0 0 0 0 0 1 0 1 0 0 0 0 0 1 0 0 0 0 0 0 0 0 2 1 0 0 0 1 0 2 0 1 0 1 0 0 0 0 0 1 2 0 0 0 0 1 0 0 1 1 0 0 1 1 0 0 0 0 0 0 0 0 0 1 0 0 0 0 0 1 0 0 0 0 0 0 4 0 0 0 0 1 0 0 0 0 0 1 1 0 0 0 2 0 0 0 1 0 2 0 1 1 0 0 0 0 0 0 0 0 0 1 0 0 0 0 0 0 0 1 0 0 0 2 0 1 0 0 0 0 0 1 0 0 0 0 0 0 0 0 1 0 0 0 0 0 0 0 1 0 1 1 2 0 1 0 0 2 0 1 0 0 0 1 0 0 1 1 0 1 1 0 0 2 1 0 0 0 1 0 1 0 0 0 0 0 0 0 0 0 0 0 1 0 0 0 1 0 0 0 0 0 0 1 0 1 0 0 0 1 0 2 0 0 1 0 1 0 1 1 0 0 0 0 1 0 0 1 0 0 2 0 0 1 0 1 0 0 2 0 0 0 0 0 0 0 0 0 0 1 1 1 0 1 0</counts>
			</dataPoints>
		</scan>
		<scan status="Completed" appendNumber="0" scanAxis="2Theta" mode="Continuous">
			<header>
				<startTimeStamp>2023-01-13T16:09:10-05:00</startTimeStamp>
				<endTimeStamp>2023-01-13T16:25:22-05:00</endTimeStamp>
				<author>
					<name>User</name>
				</author>
				<source>
					<applicationSoftware version="7.1">Data Collector</applicationSoftware>
					<instrumentControlSoftware version="8.2  20201204">EMPYREAN</instrumentControlSoftware>
					<instrumentID>0000000011260721</instrumentID>
				</source>
			</header>
			<dataPoints>
				<positions axis="2Theta" unit="deg">
					<startPosition>71.4742798131582</startPosition>
					<endPosition>74.8215495843747</endPosition>
				</positions>
				<positions axis="Omega" unit="deg">
					<commonPosition>18.2254573493832</commonPosition>
				</positions>
				<positions axis="Phi" unit="deg">
					<commonPosition>-176.42</commonPosition>
				</positions>
				<positions axis="Chi" unit="deg">
					<commonPosition>0</commonPosition>
				</positions>
				<positions axis="Z" unit="mm">
					<commonPosition>8.428</commonPosition>
				</positions>
				<commonCountingTime unit="seconds">0.784</commonCountingTime>
				<counts unit="counts">1 0 1 2 0 0 1 0 0 0 1 0 1 0 0 0 0 0 0 0 0 0 0 1 0 1 0 2 0 1 0 0 1 0 0 0 0 1 0 0 4 0 1 1 0 0 0 0 0 1 1 2 0 0 0 0 0 0 0 0 0 0 0 0 0 0 0 0 0 0 0 0 0 0 1 1 2 0 1 0 0 1 0 0 0 0 1 0 1 1 1 1 0 0 0 1 0 0 0 1 0 0 2 1 0 0 1 1 1 0 0 2 1 1 0 0 1 1 0 0 1 0 0 0 1 0 1 2 0 0 1 0 0 0 0 0 0 0 2 0 0 0 0 0 0 0 0 1 1 0 0 0 0 0 0 1 0 0 1 0 0 1 0 1 0 0 0 0 0 0 1 4 3 2 3 0 1 0 1 1 0 1 0 1 1 0 0 2 0 0 0 0 0 1 1 1 0 0 1 0 0 1 0 0 0 0 1 1 1 0 0 0 1 0 0 1 1 0 0 1 1 1 0 0 0 1 0 0 1 0 1 0 1 0 2 0 3 1 0 2 0 1 1 0 0 0 1 1 0 0 1 0 0 0 0</counts>
			</dataPoints>
		</scan>
		<scan status="Completed" appendNumber="0" scanAxis="2Theta" mode="Continuous">
			<header>
				<startTimeStamp>2023-01-13T16:09:10-05:00</startTimeStamp>
				<endTimeStamp>2023-01-13T16:25:22-05:00</endTimeStamp>
				<author>
					<name>User</name>
				</author>
				<source>
					<applicationSoftware version="7.1">Data Collector</applicationSoftware>
					<instrumentControlSoftware version="8.2  20201204">EMPYREAN</instrumentControlSoftware>
					<instrumentID>0000000011260721</instrumentID>
				</source>
			</header>
			<dataPoints>
				<positions axis="2Theta" unit="deg">
					<startPosition>71.4775623838325</startPosition>
					<endPosition>74.824832155049</endPosition>
				</positions>
				<positions axis="Omega" unit="deg">
					<commonPosition>18.2270986347204</commonPosition>
				</positions>
				<positions axis="Phi" unit="deg">
					<commonPosition>-176.42</commonPosition>
				</positions>
				<positions axis="Chi" unit="deg">
					<commonPosition>0</commonPosition>
				</positions>
				<positions axis="Z" unit="mm">
					<commonPosition>8.428</commonPosition>
				</positions>
				<commonCountingTime unit="seconds">0.784</commonCountingTime>
				<counts unit="counts">0 0 0 3 0 0 1 0 1 0 0 0 1 1 1 0 0 1 0 0 0 0 0 0 0 0 0 0 0 0 1 1 0 0 0 0 1 1 0 0 1 2 0 0 2 0 1 1 0 0 0 0 0 0 0 0 0 1 1 1 1 0 2 1 1 0 0 0 0 0 1 0 0 1 0 1 0 0 0 0 1 0 0 0 0 0 0 0 1 0 0 0 1 0 0 0 0 0 1 0 0 1 0 1 1 1 0 1 0 0 0 0 0 0 0 1 1 0 0 0 0 1 0 1 1 0 0 0 0 1 0 0 0 0 2 0 0 0 1 1 1 1 2 0 1 0 0 0 0 0 0 0 1 0 0 0 0 1 0 0 0 0 0 0 0 1 1 0 1 0 2 0 2 2 3 0 0 0 1 0 1 0 0 0 0 1 0 0 0 1 1 0 0 0 0 0 0 0 0 0 1 1 1 1 0 0 0 0 0 0 0 0 1 0 1 0 0 0 0 0 0 0 0 1 1 0 0 0 1 0 0 0 0 0 0 0 0 0 0 2 1 0 1 0 0 0 0 0 0 0 0 0 0 1 0</counts>
			</dataPoints>
		</scan>
		<scan status="Completed" appendNumber="0" scanAxis="2Theta" mode="Continuous">
			<header>
				<startTimeStamp>2023-01-13T16:09:10-05:00</startTimeStamp>
				<endTimeStamp>2023-01-13T16:25:22-05:00</endTimeStamp>
				<author>
					<name>User</name>
				</author>
				<source>
					<applicationSoftware version="7.1">Data Collector</applicationSoftware>
					<instrumentControlSoftware version="8.2  20201204">EMPYREAN</instrumentControlSoftware>
					<instrumentID>0000000011260721</instrumentID>
				</source>
			</header>
			<dataPoints>
				<positions axis="2Theta" unit="deg">
					<startPosition>71.4808449545069</startPosition>
					<endPosition>74.8281147257234</endPosition>
				</positions>
				<positions axis="Omega" unit="deg">
					<commonPosition>18.2287399200576</commonPosition>
				</positions>
				<positions axis="Phi" unit="deg">
					<commonPosition>-176.42</commonPosition>
				</positions>
				<positions axis="Chi" unit="deg">
					<commonPosition>0</commonPosition>
				</positions>
				<positions axis="Z" unit="mm">
					<commonPosition>8.428</commonPosition>
				</positions>
				<commonCountingTime unit="seconds">0.784</commonCountingTime>
				<counts unit="counts">0 0 1 0 0 0 0 1 1 0 0 1 0 0 1 0 0 1 0 0 0 0 1 2 2 1 1 3 0 1 0 0 0 0 0 0 0 1 0 0 1 0 0 0 0 0 0 0 0 0 0 0 0 0 0 0 0 0 1 1 0 0 0 0 0 0 1 0 1 0 0 0 1 0 0 0 0 0 0 0 1 0 0 0 0 0 0 1 1 1 0 0 0 0 1 0 0 0 0 0 1 0 0 0 1 0 2 1 2 0 1 1 0 0 1 0 0 0 0 1 0 0 0 0 0 1 1 0 1 0 3 0 0 1 0 2 0 2 2 1 0 0 0 0 0 0 0 0 0 0 0 1 0 1 2 0 0 0 0 1 0 1 0 0 0 0 0 0 0 0 0 0 1 0 2 2 1 0 1 0 0 1 1 1 1 0 0 0 1 0 0 0 0 1 0 0 0 0 0 0 0 1 1 0 2 0 0 0 1 0 0 1 0 0 0 1 0 0 0 0 0 0 0 1 0 1 0 0 0 0 0 1 1 0 0 1 0 0 0 0 0 0 1 0 0 1 0 1 0 1 0 1 1 0 0</counts>
			</dataPoints>
		</scan>
		<scan status="Completed" appendNumber="0" scanAxis="2Theta" mode="Continuous">
			<header>
				<startTimeStamp>2023-01-13T16:09:10-05:00</startTimeStamp>
				<endTimeStamp>2023-01-13T16:25:22-05:00</endTimeStamp>
				<author>
					<name>User</name>
				</author>
				<source>
					<applicationSoftware version="7.1">Data Collector</applicationSoftware>
					<instrumentControlSoftware version="8.2  20201204">EMPYREAN</instrumentControlSoftware>
					<instrumentID>0000000011260721</instrumentID>
				</source>
			</header>
			<dataPoints>
				<positions axis="2Theta" unit="deg">
					<startPosition>71.4841275251812</startPosition>
					<endPosition>74.8313972963977</endPosition>
				</positions>
				<positions axis="Omega" unit="deg">
					<commonPosition>18.2303812053947</commonPosition>
				</positions>
				<positions axis="Phi" unit="deg">
					<commonPosition>-176.42</commonPosition>
				</positions>
				<positions axis="Chi" unit="deg">
					<commonPosition>0</commonPosition>
				</positions>
				<positions axis="Z" unit="mm">
					<commonPosition>8.428</commonPosition>
				</positions>
				<commonCountingTime unit="seconds">0.784</commonCountingTime>
				<counts unit="counts">0 0 0 0 0 0 0 0 0 0 0 0 1 1 0 0 1 0 1 0 0 1 0 0 0 1 2 1 1 0 1 2 1 1 0 0 1 0 0 0 0 0 0 0 0 0 1 0 0 0 1 2 2 1 0 0 1 0 1 2 3 0 0 0 1 0 0 1 1 1 1 2 1 1 0 1 0 0 0 0 0 0 0 1 1 0 1 1 0 1 0 0 1 0 0 0 1 1 0 0 3 0 0 0 0 0 0 0 0 2 0 0 0 0 0 0 0 0 0 0 0 1 0 0 0 1 0 1 2 0 0 0 0 0 0 1 0 0 0 0 1 0 0 1 1 0 1 0 0 0 1 0 0 0 1 0 1 1 0 0 0 1 1 1 0 0 0 1 1 0 0 2 0 2 1 0 1 1 0 0 0 0 0 2 1 2 0 0 1 0 0 1 0 0 0 0 0 0 0 0 1 0 1 1 0 0 0 0 0 0 1 0 1 0 0 1 0 0 0 0 0 1 0 0 0 0 0 1 0 0 0 0 0 1 1 1 0 0 0 2 2 1 1 0 0 0 0 1 0 2 2 0 1 0 0</counts>
			</dataPoints>
		</scan>
		<scan status="Completed" appendNumber="0" scanAxis="2Theta" mode="Continuous">
			<header>
				<startTimeStamp>2023-01-13T16:09:10-05:00</startTimeStamp>
				<endTimeStamp>2023-01-13T16:25:22-05:00</endTimeStamp>
				<author>
					<name>User</name>
				</author>
				<source>
					<applicationSoftware version="7.1">Data Collector</applicationSoftware>
					<instrumentControlSoftware version="8.2  20201204">EMPYREAN</instrumentControlSoftware>
					<instrumentID>0000000011260721</instrumentID>
				</source>
			</header>
			<dataPoints>
				<positions axis="2Theta" unit="deg">
					<startPosition>71.4874100958556</startPosition>
					<endPosition>74.8346798670721</endPosition>
				</positions>
				<positions axis="Omega" unit="deg">
					<commonPosition>18.2320224907319</commonPosition>
				</positions>
				<positions axis="Phi" unit="deg">
					<commonPosition>-176.42</commonPosition>
				</positions>
				<positions axis="Chi" unit="deg">
					<commonPosition>0</commonPosition>
				</positions>
				<positions axis="Z" unit="mm">
					<commonPosition>8.428</commonPosition>
				</positions>
				<commonCountingTime unit="seconds">0.784</commonCountingTime>
				<counts unit="counts">0 0 0 0 0 0 0 1 0 0 0 0 0 0 0 2 0 0 1 1 1 0 0 0 0 0 1 1 0 0 0 0 0 0 0 0 1 0 0 2 1 0 0 0 1 0 0 0 0 0 0 0 1 1 0 0 0 0 2 0 0 0 1 0 1 0 0 0 1 0 1 0 1 0 0 0 0 1 0 0 0 1 1 1 0 0 0 0 0 2 0 0 0 0 0 1 0 1 0 0 0 0 2 0 0 0 0 0 0 0 0 0 0 1 1 0 1 1 0 0 0 1 0 0 1 1 0 1 0 0 0 0 2 0 1 0 0 0 0 0 0 0 0 0 0 1 0 2 0 0 1 0 0 0 0 1 0 1 0 0 1 1 1 0 2 1 0 2 0 1 2 3 1 2 1 2 0 0 0 0 1 1 1 0 0 0 0 1 0 0 0 0 0 0 0 0 0 1 0 0 0 0 0 0 0 0 0 0 0 0 0 0 1 0 1 0 1 0 1 1 0 0 1 0 0 0 0 1 2 0 0 0 0 1 0 0 0 0 1 0 0 0 0 0 0 0 0 1 2 1 0 1 1 0 0</counts>
			</dataPoints>
		</scan>
		<scan status="Completed" appendNumber="0" scanAxis="2Theta" mode="Continuous">
			<header>
				<startTimeStamp>2023-01-13T16:09:10-05:00</startTimeStamp>
				<endTimeStamp>2023-01-13T16:25:22-05:00</endTimeStamp>
				<author>
					<name>User</name>
				</author>
				<source>
					<applicationSoftware version="7.1">Data Collector</applicationSoftware>
					<instrumentControlSoftware version="8.2  20201204">EMPYREAN</instrumentControlSoftware>
					<instrumentID>0000000011260721</instrumentID>
				</source>
			</header>
			<dataPoints>
				<positions axis="2Theta" unit="deg">
					<startPosition>71.4906926665299</startPosition>
					<endPosition>74.8379624377464</endPosition>
				</positions>
				<positions axis="Omega" unit="deg">
					<commonPosition>18.2336637760691</commonPosition>
				</positions>
				<positions axis="Phi" unit="deg">
					<commonPosition>-176.42</commonPosition>
				</positions>
				<positions axis="Chi" unit="deg">
					<commonPosition>0</commonPosition>
				</positions>
				<positions axis="Z" unit="mm">
					<commonPosition>8.428</commonPosition>
				</positions>
				<commonCountingTime unit="seconds">0.784</commonCountingTime>
				<counts unit="counts">0 0 3 1 0 1 0 1 0 1 1 0 0 0 0 0 0 0 1 0 2 0 0 2 0 0 0 0 0 0 0 0 0 0 0 0 0 0 0 0 0 0 1 0 0 0 0 0 0 0 0 0 1 0 1 2 0 0 0 0 0 1 0 0 0 0 1 0 0 1 0 0 1 1 1 0 1 0 1 0 0 0 0 0 1 1 2 0 0 0 0 0 0 1 1 1 0 0 1 0 0 0 0 0 0 1 0 0 0 1 0 0 0 0 0 2 0 0 0 0 0 0 0 0 0 1 0 1 0 2 0 0 0 0 0 0 0 0 0 0 0 1 1 1 0 0 1 1 0 0 0 1 0 0 0 0 1 0 0 1 2 0 0 1 2 0 0 2 1 1 0 2 0 1 0 0 4 1 0 1 0 0 1 0 0 1 0 0 0 0 1 0 0 0 0 0 0 0 0 0 2 0 1 2 0 0 0 0 2 1 0 0 1 0 0 0 0 0 0 0 0 0 1 1 0 0 0 0 0 1 0 1 1 0 0 1 1 0 0 0 1 0 1 1 0 0 0 0 1 0 1 0 0 0 1</counts>
			</dataPoints>
		</scan>
		<scan status="Completed" appendNumber="0" scanAxis="2Theta" mode="Continuous">
			<header>
				<startTimeStamp>2023-01-13T16:09:10-05:00</startTimeStamp>
				<endTimeStamp>2023-01-13T16:25:22-05:00</endTimeStamp>
				<author>
					<name>User</name>
				</author>
				<source>
					<applicationSoftware version="7.1">Data Collector</applicationSoftware>
					<instrumentControlSoftware version="8.2  20201204">EMPYREAN</instrumentControlSoftware>
					<instrumentID>0000000011260721</instrumentID>
				</source>
			</header>
			<dataPoints>
				<positions axis="2Theta" unit="deg">
					<startPosition>71.4939752372043</startPosition>
					<endPosition>74.8412450084207</endPosition>
				</positions>
				<positions axis="Omega" unit="deg">
					<commonPosition>18.2353050614063</commonPosition>
				</positions>
				<positions axis="Phi" unit="deg">
					<commonPosition>-176.42</commonPosition>
				</positions>
				<positions axis="Chi" unit="deg">
					<commonPosition>0</commonPosition>
				</positions>
				<positions axis="Z" unit="mm">
					<commonPosition>8.428</commonPosition>
				</positions>
				<commonCountingTime unit="seconds">0.784</commonCountingTime>
				<counts unit="counts">1 0 0 1 1 0 1 0 0 0 0 0 0 0 0 0 0 1 0 0 0 1 0 0 0 0 0 0 1 0 0 0 0 0 0 0 0 0 1 0 1 0 0 1 0 1 1 0 1 0 0 1 0 0 0 0 1 0 1 1 0 0 0 0 0 0 1 0 1 2 0 0 0 0 0 0 1 0 0 0 0 0 0 0 0 1 0 0 0 0 0 0 1 1 1 0 0 2 0 1 0 0 0 2 0 0 4 0 0 0 0 1 0 0 0 0 0 0 0 0 0 1 0 0 1 1 1 0 0 1 0 0 1 0 0 0 0 0 0 0 0 0 1 1 0 0 1 0 0 0 0 0 1 1 2 0 0 0 1 1 0 0 0 0 1 1 0 0 1 0 2 1 3 1 0 1 0 0 1 0 0 1 0 0 1 1 1 0 3 1 0 0 0 0 0 1 0 1 0 0 0 0 2 2 0 0 1 0 0 0 0 0 1 0 0 0 0 0 1 2 1 1 0 0 2 0 0 2 0 1 0 0 0 0 0 0 0 0 0 0 0 0 0 1 1 1 0 0 0 1 0 1 1 1 0</counts>
			</dataPoints>
		</scan>
		<scan status="Completed" appendNumber="0" scanAxis="2Theta" mode="Continuous">
			<header>
				<startTimeStamp>2023-01-13T16:09:10-05:00</startTimeStamp>
				<endTimeStamp>2023-01-13T16:25:22-05:00</endTimeStamp>
				<author>
					<name>User</name>
				</author>
				<source>
					<applicationSoftware version="7.1">Data Collector</applicationSoftware>
					<instrumentControlSoftware version="8.2  20201204">EMPYREAN</instrumentControlSoftware>
					<instrumentID>0000000011260721</instrumentID>
				</source>
			</header>
			<dataPoints>
				<positions axis="2Theta" unit="deg">
					<startPosition>71.4972578078786</startPosition>
					<endPosition>74.8445275790951</endPosition>
				</positions>
				<positions axis="Omega" unit="deg">
					<commonPosition>18.2369463467434</commonPosition>
				</positions>
				<positions axis="Phi" unit="deg">
					<commonPosition>-176.42</commonPosition>
				</positions>
				<positions axis="Chi" unit="deg">
					<commonPosition>0</commonPosition>
				</positions>
				<positions axis="Z" unit="mm">
					<commonPosition>8.428</commonPosition>
				</positions>
				<commonCountingTime unit="seconds">0.784</commonCountingTime>
[...]
				</positions>
				<positions axis="Z" unit="mm">
					<commonPosition>8.428</commonPosition>
				</positions>
				<commonCountingTime unit="seconds">0.784</commonCountingTime>
				<counts unit="counts">0 2 0 0 0 0 1 0 1 0 0 0 0 0 1 1 1 0 0 0 1 0 0 0 2 1 0 0 0 0 0 0 2 0 2 0 1 0 0 0 1 0 0 0 0 1 1 0 0 0 1 1 0 0 0 1 0 1 0 0 0 1 1 0 0 1 2 0 0 0 1 0 0 1 1 0 1 2 0 0 2 1 2 1 0 1 0 0 0 0 1 0 0 0 0 0 1 0 0 0 1 0 1 0 0 0 0 1 0 1 0 1 0 1 1 0 1 0 0 1 0 2 0 0 0 0 0 0 0 0 0 1 1 0 0 0 1 0 1 1 0 0 0 0 0 2 0 0 0 0 0 0 0 0 0 0 0 0 0 0 0 0 2 0 0 1 0 0 0 1 1 1 0 0 0 0 1 0 0 0 0 0 1 1 0 0 0 0 0 1 0 0 0 1 0 1 2 0 0 0 0 0 0 0 0 3 0 0 0 0 0 0 1 0 2 0 0 0 0 0 3 1 0 0 0 0 0 1 1 1 0 0 0 1 0 0 0 0 0 0 0 1 1 0 0 0 1 0 1 0 0 0 0 0 1</counts>
			</dataPoints>
		</scan>
		<scan status="Completed" appendNumber="0" scanAxis="2Theta" mode="Continuous">
			<header>
				<startTimeStamp>2023-01-13T16:09:10-05:00</startTimeStamp>
				<endTimeStamp>2023-01-13T16:25:22-05:00</endTimeStamp>
				<author>
					<name>User</name>
				</author>
				<source>
					<applicationSoftware version="7.1">Data Collector</applicationSoftware>
					<instrumentControlSoftware version="8.2  20201204">EMPYREAN</instrumentControlSoftware>
					<instrumentID>0000000011260721</instrumentID>
				</source>
			</header>
			<dataPoints>
				<positions axis="2Theta" unit="deg">
					<startPosition>75.3903866276483</startPosition>
					<endPosition>78.7376563988648</endPosition>
				</positions>
				<positions axis="Omega" unit="deg">
					<commonPosition>20.1835107566283</commonPosition>
				</positions>
				<positions axis="Phi" unit="deg">
					<commonPosition>-176.42</commonPosition>
				</positions>
				<positions axis="Chi" unit="deg">
					<commonPosition>0</commonPosition>
				</positions>
				<positions axis="Z" unit="mm">
					<commonPosition>8.428</commonPosition>
				</positions>
				<commonCountingTime unit="seconds">0.784</commonCountingTime>
				<counts unit="counts">0 1 0 0 0 1 0 2 0 0 0 2 0 1 0 0 0 1 1 0 0 0 2 0 0 1 0 2 1 0 0 0 1 1 1 0 0 1 1 1 0 0 0 0 0 1 0 0 1 0 0 0 0 0 2 0 0 2 1 0 0 0 0 0 2 0 0 0 1 0 0 0 1 1 1 1 0 0 3 0 0 0 0 0 0 0 2 0 1 0 0 2 1 1 1 0 0 1 2 0 0 0 2 0 0 0 1 1 0 0 0 0 1 0 0 0 0 1 1 0 0 1 0 1 2 0 1 0 2 2 0 1 0 1 0 0 0 0 0 0 0 1 2 0 1 1 0 0 1 3 0 0 0 0 0 0 0 1 0 0 0 2 1 0 0 0 1 0 1 0 0 0 0 0 1 0 0 0 1 0 1 1 0 0 0 1 1 0 1 0 1 0 0 0 0 0 2 1 0 2 0 1 1 0 0 0 0 1 0 0 1 0 0 0 0 0 0 0 0 0 0 0 1 0 0 0 0 0 1 0 0 1 0 0 1 0 0 1 1 0 0 2 0 0 0 0 0 0 1 0 1 0 0 0 0</counts>
			</dataPoints>
		</scan>
		<scan status="Completed" appendNumber="0" scanAxis="2Theta" mode="Continuous">
			<header>
				<startTimeStamp>2023-01-13T16:09:10-05:00</startTimeStamp>
				<endTimeStamp>2023-01-13T16:25:22-05:00</endTimeStamp>
				<author>
					<name>User</name>
				</author>
				<source>
					<applicationSoftware version="7.1">Data Collector</applicationSoftware>
					<instrumentControlSoftware version="8.2  20201204">EMPYREAN</instrumentControlSoftware>
					<instrumentID>0000000011260721</instrumentID>
				</source>
			</header>
			<dataPoints>
				<positions axis="2Theta" unit="deg">
					<startPosition>75.3936691983227</startPosition>
					<endPosition>78.7409389695392</endPosition>
				</positions>
				<positions axis="Omega" unit="deg">
					<commonPosition>20.1851520419655</commonPosition>
				</positions>
				<positions axis="Phi" unit="deg">
					<commonPosition>-176.42</commonPosition>
				</positions>
				<positions axis="Chi" unit="deg">
					<commonPosition>0</commonPosition>
				</positions>
				<positions axis="Z" unit="mm">
					<commonPosition>8.428</commonPosition>
				</positions>
				<commonCountingTime unit="seconds">0.784</commonCountingTime>
				<counts unit="counts">0 0 0 0 0 0 0 0 1 1 1 0 2 0 2 0 0 0 0 0 1 1 0 0 0 0 1 1 0 0 1 1 0 1 0 0 0 0 0 0 0 0 1 0 0 0 0 0 0 1 1 0 1 0 0 1 0 0 0 1 0 1 0 1 0 0 1 0 0 1 1 0 0 0 0 0 0 0 2 1 1 0 0 1 1 0 1 0 0 0 0 0 0 2 0 0 1 0 0 0 2 0 0 1 0 1 0 0 0 1 1 1 0 1 2 1 0 0 0 0 0 0 1 1 0 0 1 0 1 0 0 0 1 0 0 0 2 0 0 0 0 1 0 0 0 0 0 0 0 0 0 0 0 0 0 0 0 1 0 0 1 1 0 0 2 0 3 0 0 0 0 0 1 2 0 0 0 0 0 0 0 1 0 0 0 0 0 1 0 0 0 2 0 0 0 1 0 0 1 0 0 0 1 2 0 0 0 0 0 0 1 1 0 1 0 1 0 0 0 1 0 0 0 0 1 0 0 0 0 0 1 1 0 0 0 1 0 0 0 0 0 0 0 0 0 0 0 0 1 0 0 0 0 0 0</counts>
			</dataPoints>
		</scan>
		<scan status="Completed" appendNumber="0" scanAxis="2Theta" mode="Continuous">
			<header>
				<startTimeStamp>2023-01-13T16:09:10-05:00</startTimeStamp>
				<endTimeStamp>2023-01-13T16:25:22-05:00</endTimeStamp>
				<author>
					<name>User</name>
				</author>
				<source>
					<applicationSoftware version="7.1">Data Collector</applicationSoftware>
					<instrumentControlSoftware version="8.2  20201204">EMPYREAN</instrumentControlSoftware>
					<instrumentID>0000000011260721</instrumentID>
				</source>
			</header>
			<dataPoints>
				<positions axis="2Theta" unit="deg">
					<startPosition>75.396951768997</startPosition>
					<endPosition>78.7442215402135</endPosition>
				</positions>
				<positions axis="Omega" unit="deg">
					<commonPosition>20.1867933273026</commonPosition>
				</positions>
				<positions axis="Phi" unit="deg">
					<commonPosition>-176.42</commonPosition>
				</positions>
				<positions axis="Chi" unit="deg">
					<commonPosition>0</commonPosition>
				</positions>
				<positions axis="Z" unit="mm">
					<commonPosition>8.428</commonPosition>
				</positions>
				<commonCountingTime unit="seconds">0.784</commonCountingTime>
				<counts unit="counts">0 0 1 0 0 0 1 0 0 0 0 1 0 0 0 0 1 0 0 0 1 0 0 1 0 0 1 1 0 0 0 2 0 0 0 0 0 0 0 1 0 0 1 0 0 1 0 1 0 0 0 1 0 1 1 1 2 0 1 0 0 1 0 0 0 1 0 1 2 0 0 0 0 0 0 0 0 0 0 0 3 0 0 1 0 1 0 0 0 0 0 0 1 1 1 1 0 0 0 2 1 0 0 1 1 0 2 1 0 0 0 1 0 0 0 0 0 0 0 1 0 1 0 0 0 1 1 1 1 0 0 0 0 4 0 0 0 0 0 0 0 0 0 0 0 2 1 0 0 0 0 0 0 0 1 0 0 0 0 0 0 0 0 1 0 0 0 0 0 0 0 0 0 0 0 1 1 2 0 0 0 0 1 0 0 0 0 0 2 0 0 2 0 0 0 0 0 0 2 0 1 0 1 0 0 0 0 0 0 0 1 1 1 0 0 1 0 0 0 0 0 0 0 0 0 0 1 0 0 0 0 2 0 0 0 0 0 1 0 1 1 0 1 1 0 1 0 2 0 0 0 0 0 0 0</counts>
			</dataPoints>
		</scan>
		<scan status="Completed" appendNumber="0" scanAxis="2Theta" mode="Continuous">
			<header>
				<startTimeStamp>2023-01-13T16:09:10-05:00</startTimeStamp>
				<endTimeStamp>2023-01-13T16:25:22-05:00</endTimeStamp>
				<author>
					<name>User</name>
				</author>
				<source>
					<applicationSoftware version="7.1">Data Collector</applicationSoftware>
					<instrumentControlSoftware version="8.2  20201204">EMPYREAN</instrumentControlSoftware>
					<instrumentID>0000000011260721</instrumentID>
				</source>
			</header>
			<dataPoints>
				<positions axis="2Theta" unit="deg">
					<startPosition>75.4002343396714</startPosition>
					<endPosition>78.7475041108878</endPosition>
				</positions>
				<positions axis="Omega" unit="deg">
					<commonPosition>20.1884346126398</commonPosition>
				</positions>
				<positions axis="Phi" unit="deg">
					<commonPosition>-176.42</commonPosition>
				</positions>
				<positions axis="Chi" unit="deg">
					<commonPosition>0</commonPosition>
				</positions>
				<positions axis="Z" unit="mm">
					<commonPosition>8.428</commonPosition>
				</positions>
				<commonCountingTime unit="seconds">0.784</commonCountingTime>
				<counts unit="counts">1 0 1 0 0 0 0 0 0 1 0 0 1 0 0 0 1 0 0 0 1 2 0 0 0 1 1 0 0 0 3 0 1 0 0 0 0 0 1 0 0 0 0 1 0 0 0 0 1 0 0 0 0 0 1 0 0 0 0 1 1 0 0 0 0 0 0 0 1 3 0 0 1 0 0 0 0 0 0 0 1 0 1 0 0 1 0 0 0 1 1 0 1 1 0 1 1 0 0 1 0 0 0 0 1 1 0 0 0 0 0 1 0 1 1 0 0 1 0 0 1 0 3 2 2 0 0 0 1 0 0 0 1 1 0 0 0 1 0 0 0 1 0 1 1 0 0 0 1 0 1 0 0 1 0 0 1 0 0 0 0 0 0 0 0 0 1 0 0 0 1 1 0 0 0 3 0 0 0 0 1 0 1 1 0 0 0 1 0 0 1 0 0 0 0 0 0 0 0 0 1 0 2 0 0 0 1 0 1 0 1 0 1 1 0 0 0 0 0 0 0 0 0 0 0 0 1 1 0 0 0 0 0 0 0 0 0 1 0 1 1 1 0 1 0 0 0 0 0 0 0 0 0 0 0</counts>
			</dataPoints>
		</scan>
		<scan status="Completed" appendNumber="0" scanAxis="2Theta" mode="Continuous">
			<header>
				<startTimeStamp>2023-01-13T16:09:10-05:00</startTimeStamp>
				<endTimeStamp>2023-01-13T16:25:22-05:00</endTimeStamp>
				<author>
					<name>User</name>
				</author>
				<source>
					<applicationSoftware version="7.1">Data Collector</applicationSoftware>
					<instrumentControlSoftware version="8.2  20201204">EMPYREAN</instrumentControlSoftware>
					<instrumentID>0000000011260721</instrumentID>
				</source>
			</header>
			<dataPoints>
				<positions axis="2Theta" unit="deg">
					<startPosition>75.4035169103457</startPosition>
					<endPosition>78.7507866815622</endPosition>
				</positions>
				<positions axis="Omega" unit="deg">
					<commonPosition>20.190075897977</commonPosition>
				</positions>
				<positions axis="Phi" unit="deg">
					<commonPosition>-176.42</commonPosition>
				</positions>
				<positions axis="Chi" unit="deg">
					<commonPosition>0</commonPosition>
				</positions>
				<positions axis="Z" unit="mm">
					<commonPosition>8.428</commonPosition>
				</positions>
				<commonCountingTime unit="seconds">0.784</commonCountingTime>
				<counts unit="counts">1 1 0 0 1 0 0 0 0 1 0 1 0 0 0 0 1 2 0 0 0 0 1 0 0 0 2 0 0 0 0 0 0 1 1 0 1 0 0 0 0 0 0 0 0 1 0 0 0 2 1 0 2 1 0 0 0 0 0 0 0 0 0 0 1 0 1 0 1 0 2 2 0 0 0 0 1 0 0 0 0 1 1 1 2 1 0 0 0 0 0 0 0 1 0 0 1 0 0 0 0 0 0 0 0 0 0 1 0 0 0 0 0 0 1 0 1 0 0 0 0 2 0 0 0 1 0 0 1 1 0 0 0 0 1 1 0 0 0 0 2 1 0 0 0 0 0 0 0 0 0 0 0 0 0 0 1 0 1 2 0 0 0 0 0 0 0 0 2 0 0 0 0 0 0 1 2 0 0 0 0 0 0 0 1 0 0 0 0 0 0 0 1 2 0 0 0 0 1 1 0 0 0 0 0 0 0 1 0 0 1 0 0 0 0 0 0 0 0 0 0 0 0 0 2 0 0 0 1 0 0 1 1 0 0 0 0 0 0 0 0 0 0 0 1 0 0 0 0 1 0 3 1 0 0</counts>
			</dataPoints>
		</scan>
		<scan status="Completed" appendNumber="0" scanAxis="2Theta" mode="Continuous">
			<header>
				<startTimeStamp>2023-01-13T16:09:10-05:00</startTimeStamp>
				<endTimeStamp>2023-01-13T16:25:22-05:00</endTimeStamp>
				<author>
					<name>User</name>
				</author>
				<source>
					<applicationSoftware version="7.1">Data Collector</applicationSoftware>
					<instrumentControlSoftware version="8.2  20201204">EMPYREAN</instrumentControlSoftware>
					<instrumentID>0000000011260721</instrumentID>
				</source>
			</header>
			<dataPoints>
				<positions axis="2Theta" unit="deg">
					<startPosition>75.40679948102</startPosition>
					<endPosition>78.7540692522365</endPosition>
				</positions>
				<positions axis="Omega" unit="deg">
					<commonPosition>20.1917171833141</commonPosition>
				</positions>
				<positions axis="Phi" unit="deg">
					<commonPosition>-176.42</commonPosition>
				</positions>
				<positions axis="Chi" unit="deg">
					<commonPosition>0</commonPosition>
				</positions>
				<positions axis="Z" unit="mm">
					<commonPosition>8.428</commonPosition>
				</positions>
				<commonCountingTime unit="seconds">0.784</commonCountingTime>
				<counts unit="counts">2 1 0 0 0 0 0 1 2 0 0 0 0 1 2 0 1 0 0 0 0 1 0 1 0 0 1 0 1 0 1 1 0 2 0 0 1 0 0 0 0 0 0 0 0 1 1 0 0 0 0 1 1 0 0 0 0 1 0 0 0 0 0 0 0 0 0 1 0 0 0 0 0 0 0 0 0 0 0 0 1 0 2 4 2 1 0 2 0 1 0 1 0 0 0 1 2 0 0 0 1 1 1 0 0 0 0 0 0 0 2 1 0 0 0 1 0 0 0 0 1 0 0 0 0 0 1 0 2 0 0 0 0 0 0 0 0 0 0 0 0 0 0 0 1 0 0 0 1 1 0 2 1 0 0 1 0 0 0 0 0 1 0 0 0 0 0 0 0 3 1 0 0 0 0 1 0 0 0 0 0 0 0 0 0 0 1 0 0 0 0 0 0 1 0 0 0 1 0 0 0 0 0 0 1 1 0 1 0 1 0 0 0 0 0 1 1 0 0 1 1 0 0 0 0 0 1 0 1 0 0 0 0 0 0 1 1 0 1 0 0 0 0 0 0 0 1 0 0 2 0 0 0 0 1</counts>
			</dataPoints>
		</scan>
		<scan status="Completed" appendNumber="0" scanAxis="2Theta" mode="Continuous">
			<header>
				<startTimeStamp>2023-01-13T16:09:10-05:00</startTimeStamp>
				<endTimeStamp>2023-01-13T16:25:22-05:00</endTimeStamp>
				<author>
					<name>User</name>
				</author>
				<source>
					<applicationSoftware version="7.1">Data Collector</applicationSoftware>
					<instrumentControlSoftware version="8.2  20201204">EMPYREAN</instrumentControlSoftware>
					<instrumentID>0000000011260721</instrumentID>
				</source>
			</header>
			<dataPoints>
				<positions axis="2Theta" unit="deg">
					<startPosition>75.4100820516944</startPosition>
					<endPosition>78.7573518229109</endPosition>
				</positions>
				<positions axis="Omega" unit="deg">
					<commonPosition>20.1933584686513</commonPosition>
				</positions>
				<positions axis="Phi" unit="deg">
					<commonPosition>-176.42</commonPosition>
				</positions>
				<positions axis="Chi" unit="deg">
					<commonPosition>0</commonPosition>
				</positions>
				<positions axis="Z" unit="mm">
					<commonPosition>8.428</commonPosition>
				</positions>
				<commonCountingTime unit="seconds">0.784</commonCountingTime>
				<counts unit="counts">0 0 0 1 5 1 0 1 0 0 0 0 0 0 1 1 0 0 1 0 0 2 0 0 0 1 0 1 0 1 0 0 0 0 3 0 0 1 0 0 0 0 0 1 1 1 0 2 2 0 0 0 1 0 0 0 0 2 2 0 0 0 0 0 0 0 0 1 1 0 0 0 1 0 1 0 1 1 0 0 1 0 2 2 1 0 0 0 0 0 1 0 1 0 0 0 2 0 0 0 0 0 1 0 0 0 1 0 0 0 0 0 0 0 0 1 2 0 0 2 1 0 0 0 0 0 0 0 1 0 1 0 0 1 1 0 1 0 1 0 0 0 0 1 0 1 0 0 0 0 0 0 1 1 0 2 0 0 0 2 0 0 0 0 0 0 1 1 1 0 0 0 0 1 0 0 1 0 0 3 0 1 0 0 0 0 1 0 0 0 0 0 0 0 0 0 1 0 0 0 0 1 0 0 0 0 0 0 1 0 1 0 1 1 0 0 1 0 1 0 0 0 0 0 0 0 0 0 1 0 0 1 0 0 1 2 0 1 0 0 1 1 0 2 0 0 0 0 0 1 2 1 0 0 1</counts>
			</dataPoints>
		</scan>
		<scan status="Completed" appendNumber="0" scanAxis="2Theta" mode="Continuous">
			<header>
				<startTimeStamp>2023-01-13T16:09:10-05:00</startTimeStamp>
				<endTimeStamp>2023-01-13T16:25:22-05:00</endTimeStamp>
				<author>
					<name>User</name>
				</author>
				<source>
					<applicationSoftware version="7.1">Data Collector</applicationSoftware>
					<instrumentControlSoftware version="8.2  20201204">EMPYREAN</instrumentControlSoftware>
					<instrumentID>0000000011260721</instrumentID>
				</source>
			</header>
			<dataPoints>
				<positions axis="2Theta" unit="deg">
					<startPosition>75.4133646223687</startPosition>
					<endPosition>78.7606343935852</endPosition>
				</positions>
				<positions axis="Omega" unit="deg">
					<commonPosition>20.1949997539885</commonPosition>
				</positions>
				<positions axis="Phi" unit="deg">
					<commonPosition>-176.42</commonPosition>
				</positions>
				<positions axis="Chi" unit="deg">
					<commonPosition>0</commonPosition>
				</positions>
				<positions axis="Z" unit="mm">
					<commonPosition>8.428</commonPosition>
				</positions>
				<commonCountingTime unit="seconds">0.784</commonCountingTime>
				<counts unit="counts">1 0 0 1 0 1 0 1 0 0 0 0 1 0 0 0 0 1 0 0 0 0 0 1 1 1 0 0 0 0 1 0 0 0 2 0 1 0 0 0 0 0 0 0 0 2 0 0 0 0 0 0 2 2 0 0 0 0 0 0 1 0 0 1 0 0 0 4 0 0 0 1 0 1 1 1 1 0 0 0 1 0 0 0 1 0 0 0 0 0 1 0 0 0 2 0 0 0 0 0 0 0 0 0 0 0 0 0 1 1 0 1 2 0 0 0 0 0 0 0 0 0 0 0 0 0 0 0 0 1 0 0 0 0 0 0 1 0 1 0 0 0 0 0 0 1 0 0 2 0 2 0 0 0 0 0 0 0 1 0 0 0 0 0 0 1 0 0 0 1 0 0 0 1 0 0 0 0 0 0 1 0 0 0 0 0 0 0 0 0 0 0 0 0 1 0 2 1 1 2 1 0 0 0 0 0 1 0 0 0 1 0 1 1 0 0 0 0 0 0 1 1 0 1 0 0 0 0 0 0 0 0 0 0 0 0 0 4 0 1 0 0 0 1 0 0 0 1 0 0 0 1 0 0 0</counts>
			</dataPoints>
		</scan>
		<scan status="Completed" appendNumber="0" scanAxis="2Theta" mode="Continuous">
			<header>
				<startTimeStamp>2023-01-13T16:09:10-05:00</startTimeStamp>
				<endTimeStamp>2023-01-13T16:25:22-05:00</endTimeStamp>
				<author>
					<name>User</name>
				</author>
				<source>
					<applicationSoftware version="7.1">Data Collector</applicationSoftware>
					<instrumentControlSoftware version="8.2  20201204">EMPYREAN</instrumentControlSoftware>
					<instrumentID>0000000011260721</instrumentID>
				</source>
			</header>
			<dataPoints>
				<positions axis="2Theta" unit="deg">
					<startPosition>75.4166471930431</startPosition>
					<endPosition>78.7639169642596</endPosition>
				</positions>
				<positions axis="Omega" unit="deg">
					<commonPosition>20.1966410393257</commonPosition>
				</positions>
				<positions axis="Phi" unit="deg">
					<commonPosition>-176.42</commonPosition>
				</positions>
				<positions axis="Chi" unit="deg">
					<commonPosition>0</commonPosition>
				</positions>
				<positions axis="Z" unit="mm">
					<commonPosition>8.428</commonPosition>
				</positions>
				<commonCountingTime unit="seconds">0.784</commonCountingTime>
				<counts unit="counts">2 1 0 0 0 0 0 0 0 1 1 0 0 1 0 2 0 0 0 0 0 1 0 0 1 0 1 0 0 0 1 0 0 0 0 0 0 1 0 0 0 0 1 0 0 0 0 0 0 0 1 0 0 1 1 1 0 0 0 0 1 0 0 0 1 0 0 0 0 0 0 0 0 0 0 0 0 1 0 0 1 1 0 1 0 0 1 1 2 1 0 0 0 3 0 0 1 0 1 1 0 0 1 0 1 1 0 1 0 0 0 1 0 0 1 0 0 0 0 0 0 0 0 0 1 1 0 2 0 1 0 0 0 0 3 0 1 0 0 0 0 0 0 1 0 0 0 1 0 0 0 1 0 0 0 0 0 1 0 1 2 1 0 0 1 0 0 1 1 0 0 0 0 2 0 0 0 0 0 0 0 0 0 1 0 0 0 0 0 0 1 1 0 0 1 0 2 0 1 0 1 0 0 0 0 0 1 0 0 0 0 0 0 0 0 1 0 0 0 0 0 0 1 0 0 2 0 0 0 1 0 0 0 1 0 0 0 0 0 0 2 0 0 0 0 1 1 0 2 0 0 0 2 0 1</counts>
			</dataPoints>
		</scan>
		<scan status="Completed" appendNumber="0" scanAxis="2Theta" mode="Continuous">
			<header>
				<startTimeStamp>2023-01-13T16:09:10-05:00</startTimeStamp>
				<endTimeStamp>2023-01-13T16:25:22-05:00</endTimeStamp>
				<author>
					<name>User</name>
				</author>
				<source>
					<applicationSoftware version="7.1">Data Collector</applicationSoftware>
					<instrumentControlSoftware version="8.2  20201204">EMPYREAN</instrumentControlSoftware>
					<instrumentID>0000000011260721</instrumentID>
				</source>
			</header>
			<dataPoints>
				<positions axis="2Theta" unit="deg">
					<startPosition>75.4199297637174</startPosition>
					<endPosition>78.7671995349339</endPosition>
				</positions>
				<positions axis="Omega" unit="deg">
					<commonPosition>20.1982823246628</commonPosition>
				</positions>
				<positions axis="Phi" unit="deg">
					<commonPosition>-176.42</commonPosition>
				</positions>
				<positions axis="Chi" unit="deg">
					<commonPosition>0</commonPosition>
				</positions>
				<positions axis="Z" unit="mm">
					<commonPosition>8.428</commonPosition>
				</positions>
				<commonCountingTime unit="seconds">0.784</commonCountingTime>
				<counts unit="counts">0 0 0 0 0 0 0 0 1 0 0 1 0 0 1 0 0 2 0 0 1 0 0 0 0 0 2 0 0 0 0 0 0 0 0 0 1 0 0 0 0 0 1 1 0 1 0 0 0 0 1 0 0 0 0 0 1 0 0 0 0 0 1 0 0 1 0 0 0 1 0 0 0 0 0 0 2 0 0 0 1 0 2 0 1 0 0 0 0 0 0 0 0 0 0 0 0 0 1 0 0 1 0 0 0 1 0 0 0 1 0 0 3 0 1 0 1 0 0 0 0 0 2 0 0 0 0 0 1 1 0 0 1 0 0 0 1 0 0 0 0 1 0 1 1 0 1 0 0 0 0 1 0 0 0 1 0 1 0 1 0 1 0 0 0 0 0 0 0 1 0 0 1 0 0 0 0 0 0 1 1 0 1 0 0 1 1 1 0 1 0 0 0 1 0 0 0 0 0 0 0 0 0 1 0 1 0 0 0 0 0 0 0 1 0 0 0 0 0 0 1 0 1 0 0 1 1 0 0 0 1 0 0 0 1 0 0 0 0 0 0 2 0 0 0 1 0 0 0 0 0 0 0 0 0</counts>
			</dataPoints>
		</scan>
		<scan status="Completed" appendNumber="0" scanAxis="2Theta" mode="Continuous">
			<header>
				<startTimeStamp>2023-01-13T16:09:10-05:00</startTimeStamp>
				<endTimeStamp>2023-01-13T16:25:22-05:00</endTimeStamp>
				<author>
					<name>User</name>
				</author>
				<source>
					<applicationSoftware version="7.1">Data Collector</applicationSoftware>
					<instrumentControlSoftware version="8.2  20201204">EMPYREAN</instrumentControlSoftware>
					<instrumentID>0000000011260721</instrumentID>
				</source>
			</header>
			<dataPoints>
				<positions axis="2Theta" unit="deg">
					<startPosition>75.4232123343918</startPosition>
					<endPosition>78.7704821056082</endPosition>
				</positions>
				<positions axis="Omega" unit="deg">
					<commonPosition>20.19992361</commonPosition>
				</positions>
				<positions axis="Phi" unit="deg">
					<commonPosition>-176.42</commonPosition>
				</positions>
				<positions axis="Chi" unit="deg">
					<commonPosition>0</commonPosition>
				</positions>
				<positions axis="Z" unit="mm">
					<commonPosition>8.428</commonPosition>
				</positions>
				<commonCountingTime unit="seconds">0.784</commonCountingTime>
				<counts unit="counts">0 0 0 0 1 1 0 0 0 0 0 1 1 0 0 0 0 1 0 0 0 0 1 0 1 0 0 1 0 0 1 1 1 0 1 1 0 0 0 1 0 0 1 0 1 0 0 0 1 0 0 0 1 0 0 1 1 2 0 0 0 1 0 0 0 1 1 2 2 0 0 0 0 0 1 0 0 0 0 0 0 1 2 1 3 0 0 1 0 0 0 1 0 0 0 0 0 1 0 0 0 0 0 0 0 0 0 1 0 0 0 3 0 0 0 0 0 0 0 1 1 0 0 1 0 1 0 0 0 0 0 1 0 0 1 0 0 1 0 0 1 0 0 0 0 1 0 1 0 0 0 1 1 0 0 1 0 0 0 0 1 0 1 0 0 1 0 1 0 0 1 0 0 0 1 0 0 0 0 0 0 0 3 0 0 0 0 0 0 0 0 0 1 0 3 1 0 1 0 0 0 0 0 0 1 0 1 0 1 0 0 0 1 1 0 0 0 0 0 0 1 0 0 1 0 0 0 0 0 0 0 1 0 0 0 0 1 0 0 1 1 1 1 1 1 0 0 0 0 0 0 1 0 0 0</counts>
			</dataPoints>
		</scan>
	</xrdMeasurement>
</xrdMeasurements>