File: data/XRD_RSM/YG061/YCG061 phi-270 RSM slow 3 degree_1.xrdml
<?xml version="1.0" encoding="utf-8"?>
<xrdMeasurements xmlns="http://www.xrdml.com/XRDMeasurement/2.2" xmlns:xsi="http://www.w3.org/2001/XMLSchema-instance" xsi:schemaLocation="http://www.xrdml.com/XRDMeasurement/2.2 http://www.xrdml.com/XRDMeasurement/2.2/XRDMeasurement.xsd" status="Completed">
	<comment>
		<entry>Configuration=3-axes Cradle_Reflection, Owner=lw627, Creation date=9/2/2021 3:55:24 PM</entry>
		<entry>Goniometer=Theta/Theta; Minimum step size 2Theta:0.0001; Minimum step size Omega:0.0001</entry>
		<entry>Sample stage=Chi-Phi-z stage 240 mm (reflection); Minimum step size Phi:0.01; Minimum step size Chi:0.01; Minimum step size Z:0.001</entry>
		<entry>Diffractometer system=EMPYREAN</entry>
		<entry>Measurement program=C:\PANalytical\Data Collector\Programs\Liyan Wu\Film programs\RSM slow 3 degree.xrdmp, Identifier={0351664C-55A7-43E7-B72A-7307F4B26703}</entry>
	</comment>
	<sample type="To be analyzed">
		<id/>
		<name/>
		<preparedBy/>
	</sample>
	<xrdMeasurement status="Completed" measurementType="Area measurement" measurementStepAxis="Omega-2Theta" sampleMode="Reflection">
		<comment>
			<entry>PHD Lower Level = 4.02 (keV), PHD Upper Level = 11.27 (keV)</entry>
		</comment>
		<usedWavelength intended="K-Alpha 1">
			<kAlpha1 unit="Angstrom">1.5405980</kAlpha1>
			<kAlpha2 unit="Angstrom">1.5444260</kAlpha2>
			<kBeta unit="Angstrom">1.3922500</kBeta>
			<ratioKAlpha2KAlpha1>0</ratioKAlpha2KAlpha1>
		</usedWavelength>
		<incidentBeamPath>
			<radius unit="mm">240.00</radius>
			<xRayTube id="1010048" name="Empyrean Cu LFF HR (9430 033 7310x) DK432574">
				<tension unit="kV">45.0</tension>
				<current unit="mA">40.0</current>
				<anodeMaterial>Cu</anodeMaterial>
				<focus type="Line">
					<length unit="mm">12.0</length>
					<width unit="mm">0.4</width>
					<takeOffAngle unit="deg">4.4</takeOffAngle>
				</focus>
			</xRayTube>
			<xRayMirror xsi:type="xRayMirrorType" id="27080001" name="Inc. Beam Cu W/Si (hybrid MPD)" hybrid="true">
				<crystal type="Graded" shape="Parabolic">W/Si</crystal>
				<acceptanceAngle unit="deg">0.800</acceptanceAngle>
				<length unit="mm">55.3</length>
			</xRayMirror>
			<monochromator xsi:type="monochromatorType" id="23090002" name="Hybrid monochr. 2xGe220 Cu asym." hybrid="true">
				<crystal type="Asymmetric" shape="Flat">Ge</crystal>
				<numberOfReflections>2</numberOfReflections>
				<hkl>
					<h>2</h>
					<k>2</k>
					<l>0</l>
				</hkl>
			</monochromator>
			<divergenceSlit xsi:type="fixedDivergenceSlitType" id="22010005" name="Fixed slit 1/4°">
				<distanceToSample unit="mm">179.30</distanceToSample>
				<height unit="mm">0.38</height>
			</divergenceSlit>
		</incidentBeamPath>
		<diffractedBeamPath>
			<radius unit="mm">240.00</radius>
			<antiScatterSlit xsi:type="fixedAntiScatterSlitType" id="22060009" name="Programmable anti-scatter slit">
				<angle unit="deg">4</angle>
			</antiScatterSlit>
			<detector xsi:type="areaDetectorType" id="7010020" name="PIXcel3D-Medipix3 1x1 detector">
				<phd unit="%">
					<lowerLevel>25</lowerLevel>
					<upperLevel>70</upperLevel>
				</phd>
				<mode>Scanning snapshot equatorial</mode>
				<activeChannelsEquatorial>255</activeChannelsEquatorial>
				<activeChannelsAxial>255</activeChannelsAxial>
				<pitchEquatorial unit="mm">0.05500</pitchEquatorial>
				<pitchAxial unit="mm">0.05500</pitchAxial>
				<readOutPeriod unit="seconds">0.980</readOutPeriod>
			</detector>
		</diffractedBeamPath>
		<scan status="Completed" appendNumber="0" scanAxis="2Theta" mode="Continuous">
			<header>
				<startTimeStamp>2024-07-05T13:46:22-04:00</startTimeStamp>
				<endTimeStamp>2024-07-05T14:16:20-04:00</endTimeStamp>
				<author>
					<name>lw627</name>
				</author>
				<source>
					<applicationSoftware version="7.1">Data Collector</applicationSoftware>
					<instrumentControlSoftware version="8.2  20201204">EMPYREAN</instrumentControlSoftware>
					<instrumentID>0000000011260721</instrumentID>
				</source>
			</header>
			<dataPoints>
				<positions axis="2Theta" unit="deg">
					<startPosition>71.5524063943918</startPosition>
					<endPosition>74.8996761656082</endPosition>
				</positions>
				<positions axis="Omega" unit="deg">
					<commonPosition>17.97052064</commonPosition>
				</positions>
				<positions axis="Phi" unit="deg">
					<commonPosition>-267.92</commonPosition>
				</positions>
				<positions axis="Chi" unit="deg">
					<commonPosition>0</commonPosition>
				</positions>
				<positions axis="Z" unit="mm">
					<commonPosition>8.391</commonPosition>
				</positions>
				<commonCountingTime unit="seconds">0.974</commonCountingTime>
				<counts unit="counts">0 0 0 1 0 0 0 0 1 0 0 0 0 0 0 0 1 0 0 0 0 1 0 1 2 0 1 0 0 0 0 1 0 1 0 0 0 0 1 0 1 0 1 1 0 0 0 0 1 1 0 1 1 1 0 0 0 0 1 0 2 0 0 0 0 0 0 1 1 0 1 0 0 0 1 0 0 1 0 1 0 0 0 0 1 0 0 0 1 0 0 0 0 0 0 0 0 1 0 0 0 1 1 0 0 0 0 0 0 0 1 0 0 1 0 0 0 1 0 0 0 0 0 0 0 0 1 0 1 0 0 0 0 0 0 0 0 1 0 1 0 0 0 0 1 1 2 0 0 0 0 0 0 1 0 0 1 0 1 0 0 1 0 0 0 1 0 1 2 0 0 0 0 0 0 0 1 2 1 0 0 0 0 1 1 0 1 0 0 0 1 0 0 0 0 0 0 1 0 0 0 0 0 0 1 1 1 0 0 0 0 0 0 0 0 0 0 1 1 1 1 0 0 0 1 0 0 0 0 2 0 2 0 0 0 0 1 0 0 0 0 0 0 0 0 0 1 0 0 0 0 0 0 0 1</counts>
			</dataPoints>
		</scan>
		<scan status="Completed" appendNumber="0" scanAxis="2Theta" mode="Continuous">
			<header>
				<startTimeStamp>2024-07-05T13:46:22-04:00</startTimeStamp>
				<endTimeStamp>2024-07-05T14:16:20-04:00</endTimeStamp>
				<author>
					<name>lw627</name>
				</author>
				<source>
					<applicationSoftware version="7.1">Data Collector</applicationSoftware>
					<instrumentControlSoftware version="8.2  20201204">EMPYREAN</instrumentControlSoftware>
					<instrumentID>0000000011260721</instrumentID>
				</source>
			</header>
			<dataPoints>
				<positions axis="2Theta" unit="deg">
					<startPosition>71.5556889650599</startPosition>
					<endPosition>74.9029587362764</endPosition>
				</positions>
				<positions axis="Omega" unit="deg">
					<commonPosition>17.9721619253341</commonPosition>
				</positions>
				<positions axis="Phi" unit="deg">
					<commonPosition>-267.92</commonPosition>
				</positions>
				<positions axis="Chi" unit="deg">
					<commonPosition>0</commonPosition>
				</positions>
				<positions axis="Z" unit="mm">
					<commonPosition>8.391</commonPosition>
				</positions>
				<commonCountingTime unit="seconds">0.974</commonCountingTime>
				<counts unit="counts">0 0 0 1 1 1 0 0 1 0 2 0 0 2 1 1 0 0 0 0 0 0 0 0 2 0 0 2 1 2 1 2 0 1 0 0 0 1 1 1 0 0 2 1 1 0 0 0 0 0 0 0 2 0 0 0 0 0 1 0 0 0 1 1 1 0 0 0 1 0 0 2 2 0 0 2 1 0 0 0 1 0 1 2 1 0 0 0 1 0 0 0 2 0 1 1 0 0 0 0 0 0 2 0 1 0 0 2 1 0 0 0 0 0 0 1 0 0 0 0 0 0 1 0 0 0 0 0 1 0 0 0 0 0 3 1 1 0 0 0 0 2 0 0 0 0 1 1 0 0 0 0 0 0 0 0 0 0 0 0 0 0 0 0 0 0 0 1 0 0 1 2 0 0 0 0 0 0 0 0 0 0 0 0 0 1 0 0 1 0 0 0 0 0 1 0 1 1 0 1 1 0 0 0 0 0 0 0 1 0 1 0 0 0 0 0 0 0 1 1 1 0 0 0 0 0 0 0 1 0 0 1 0 1 0 0 1 1 0 0 0 1 2 0 0 0 0 0 1 0 1 0 0 1 0</counts>
			</dataPoints>
		</scan>
		<scan status="Completed" appendNumber="0" scanAxis="2Theta" mode="Continuous">
			<header>
				<startTimeStamp>2024-07-05T13:46:22-04:00</startTimeStamp>
				<endTimeStamp>2024-07-05T14:16:20-04:00</endTimeStamp>
				<author>
					<name>lw627</name>
				</author>
				<source>
					<applicationSoftware version="7.1">Data Collector</applicationSoftware>
					<instrumentControlSoftware version="8.2  20201204">EMPYREAN</instrumentControlSoftware>
					<instrumentID>0000000011260721</instrumentID>
				</source>
			</header>
			<dataPoints>
				<positions axis="2Theta" unit="deg">
					<startPosition>71.558971535728</startPosition>
					<endPosition>74.9062413069445</endPosition>
				</positions>
				<positions axis="Omega" unit="deg">
					<commonPosition>17.9738032106681</commonPosition>
				</positions>
				<positions axis="Phi" unit="deg">
					<commonPosition>-267.92</commonPosition>
				</positions>
				<positions axis="Chi" unit="deg">
					<commonPosition>0</commonPosition>
				</positions>
				<positions axis="Z" unit="mm">
					<commonPosition>8.391</commonPosition>
				</positions>
				<commonCountingTime unit="seconds">0.974</commonCountingTime>
				<counts unit="counts">1 0 0 1 0 0 1 0 0 1 0 0 0 0 0 1 0 0 0 0 1 0 2 0 0 0 0 0 1 1 0 0 0 0 0 1 0 1 0 1 0 1 0 0 1 0 0 1 1 0 0 0 0 1 0 1 0 0 0 0 0 0 0 0 0 0 0 0 1 0 0 0 1 0 0 0 0 1 0 0 0 0 1 1 1 0 2 1 0 1 0 0 0 0 0 0 0 0 0 0 1 0 0 0 0 1 0 3 1 0 0 0 0 0 0 0 0 0 1 1 0 0 0 0 1 1 0 0 0 0 0 1 1 0 0 1 0 0 1 1 0 1 0 1 0 1 0 0 0 0 1 0 0 0 0 1 1 0 0 0 1 0 1 0 1 1 1 0 0 0 0 0 1 0 0 0 1 0 0 0 2 0 0 0 0 0 1 0 0 0 2 0 0 0 0 0 0 0 2 0 0 1 0 0 0 1 0 1 0 1 0 1 0 0 0 0 0 0 0 2 0 0 0 0 0 0 0 0 1 0 0 0 0 1 0 0 0 1 0 0 0 0 0 0 0 0 1 0 0 0 0 0 1 1 0</counts>
			</dataPoints>
		</scan>
		<scan status="Completed" appendNumber="0" scanAxis="2Theta" mode="Continuous">
			<header>
				<startTimeStamp>2024-07-05T13:46:22-04:00</startTimeStamp>
				<endTimeStamp>2024-07-05T14:16:20-04:00</endTimeStamp>
				<author>
					<name>lw627</name>
				</author>
				<source>
					<applicationSoftware version="7.1">Data Collector</applicationSoftware>
					<instrumentControlSoftware version="8.2  20201204">EMPYREAN</instrumentControlSoftware>
					<instrumentID>0000000011260721</instrumentID>
				</source>
			</header>
			<dataPoints>
				<positions axis="2Theta" unit="deg">
					<startPosition>71.5622541063962</startPosition>
					<endPosition>74.9095238776126</endPosition>
				</positions>
				<positions axis="Omega" unit="deg">
					<commonPosition>17.9754444960022</commonPosition>
				</positions>
				<positions axis="Phi" unit="deg">
					<commonPosition>-267.92</commonPosition>
				</positions>
				<positions axis="Chi" unit="deg">
					<commonPosition>0</commonPosition>
				</positions>
				<positions axis="Z" unit="mm">
					<commonPosition>8.391</commonPosition>
				</positions>
				<commonCountingTime unit="seconds">0.974</commonCountingTime>
				<counts unit="counts">0 0 0 0 0 0 0 0 0 0 1 0 2 0 2 0 1 1 0 0 0 1 1 0 0 2 1 1 1 0 0 0 1 1 0 0 0 0 1 1 0 0 0 1 0 0 0 0 0 0 2 0 1 0 2 0 0 0 0 0 0 0 0 0 0 1 1 0 0 0 3 0 0 0 0 1 1 0 1 0 0 2 0 1 0 1 0 0 0 0 1 0 0 0 1 0 0 0 1 0 0 1 0 0 1 0 0 0 0 0 0 0 1 0 1 0 0 0 0 0 1 0 0 0 0 0 0 0 2 0 0 0 0 1 0 0 0 0 0 0 0 0 1 1 0 0 0 0 0 0 0 0 1 0 0 0 0 0 1 0 0 0 0 0 1 0 0 0 0 0 0 0 0 0 1 1 1 1 0 0 0 0 0 0 1 0 3 1 0 0 0 2 1 0 0 0 0 0 0 1 1 0 0 0 0 0 0 0 0 0 0 1 0 2 0 0 0 0 1 0 0 0 0 0 1 0 1 0 1 1 0 0 0 0 0 0 0 1 0 0 0 1 0 0 2 0 0 0 0 0 0 0 1 1 0</counts>
			</dataPoints>
		</scan>
		<scan status="Completed" appendNumber="0" scanAxis="2Theta" mode="Continuous">
			<header>
				<startTimeStamp>2024-07-05T13:46:22-04:00</startTimeStamp>
				<endTimeStamp>2024-07-05T14:16:20-04:00</endTimeStamp>
				<author>
					<name>lw627</name>
				</author>
				<source>
					<applicationSoftware version="7.1">Data Collector</applicationSoftware>
					<instrumentControlSoftware version="8.2  20201204">EMPYREAN</instrumentControlSoftware>
					<instrumentID>0000000011260721</instrumentID>
				</source>
			</header>
			<dataPoints>
				<positions axis="2Theta" unit="deg">
					<startPosition>71.5655366770643</startPosition>
					<endPosition>74.9128064482807</endPosition>
				</positions>
				<positions axis="Omega" unit="deg">
					<commonPosition>17.9770857813363</commonPosition>
				</positions>
				<positions axis="Phi" unit="deg">
					<commonPosition>-267.92</commonPosition>
				</positions>
				<positions axis="Chi" unit="deg">
					<commonPosition>0</commonPosition>
				</positions>
				<positions axis="Z" unit="mm">
					<commonPosition>8.391</commonPosition>
				</positions>
				<commonCountingTime unit="seconds">0.974</commonCountingTime>
				<counts unit="counts">0 0 0 0 0 1 0 0 0 1 0 0 0 0 1 0 0 1 0 0 0 0 0 0 0 0 0 0 1 1 1 1 0 0 1 1 2 0 0 0 0 1 0 0 0 1 1 0 0 0 1 1 0 0 1 1 0 0 0 0 0 0 2 1 0 0 1 0 0 0 0 0 1 0 0 1 0 0 0 0 0 0 0 1 0 1 0 0 2 0 0 1 0 0 1 0 0 2 2 0 0 1 1 0 0 0 0 0 0 0 0 0 0 0 0 0 0 0 0 1 0 0 1 0 0 0 0 3 1 0 0 0 0 0 0 0 0 0 0 0 0 0 0 0 0 0 0 2 0 1 0 0 0 1 0 0 1 1 0 0 1 1 0 0 0 0 0 0 0 0 0 1 0 0 0 3 1 0 0 0 0 0 2 0 0 0 0 0 0 1 0 0 0 2 0 0 0 0 1 0 0 1 0 1 0 0 0 0 0 1 0 0 0 0 0 0 0 0 0 0 1 0 0 0 1 0 1 0 0 0 0 0 0 1 0 0 0 0 0 1 1 1 1 0 1 0 3 0 0 0 1 1 0 1 0</counts>
			</dataPoints>
		</scan>
		<scan status="Completed" appendNumber="0" scanAxis="2Theta" mode="Continuous">
			<header>
				<startTimeStamp>2024-07-05T13:46:22-04:00</startTimeStamp>
				<endTimeStamp>2024-07-05T14:16:20-04:00</endTimeStamp>
				<author>
					<name>lw627</name>
				</author>
				<source>
					<applicationSoftware version="7.1">Data Collector</applicationSoftware>
					<instrumentControlSoftware version="8.2  20201204">EMPYREAN</instrumentControlSoftware>
					<instrumentID>0000000011260721</instrumentID>
				</source>
			</header>
			<dataPoints>
				<positions axis="2Theta" unit="deg">
					<startPosition>71.5688192477324</startPosition>
					<endPosition>74.9160890189489</endPosition>
				</positions>
				<positions axis="Omega" unit="deg">
					<commonPosition>17.9787270666703</commonPosition>
				</positions>
				<positions axis="Phi" unit="deg">
					<commonPosition>-267.92</commonPosition>
				</positions>
				<positions axis="Chi" unit="deg">
					<commonPosition>0</commonPosition>
				</positions>
				<positions axis="Z" unit="mm">
					<commonPosition>8.391</commonPosition>
				</positions>
				<commonCountingTime unit="seconds">0.974</commonCountingTime>
				<counts unit="counts">0 1 0 0 0 0 0 0 1 0 0 1 1 0 0 0 1 1 0 0 0 0 0 0 1 0 0 0 0 0 0 0 0 0 0 0 1 2 0 2 0 0 1 1 1 0 0 1 0 0 2 0 0 2 0 2 0 0 0 0 1 0 0 0 1 0 0 1 2 0 0 0 0 0 1 0 0 2 0 0 1 0 0 0 0 0 1 0 0 0 2 1 1 0 0 0 0 0 0 0 0 1 1 0 0 0 0 0 0 0 0 0 0 1 0 0 0 0 0 0 0 1 0 0 0 0 2 0 0 0 0 0 0 0 0 0 0 1 0 0 1 3 0 0 1 1 2 0 0 1 1 0 0 0 1 1 0 0 0 0 0 0 0 0 0 0 0 0 1 0 1 1 0 0 0 0 1 1 1 0 0 0 0 0 0 0 1 0 1 0 0 0 0 0 2 0 0 2 0 0 0 2 0 0 0 0 0 0 1 0 0 0 1 0 0 0 1 1 2 0 1 1 0 0 0 1 0 0 0 0 0 0 0 1 1 0 0 0 1 0 0 0 0 1 0 0 0 0 0 0 0 0 0 0 1</counts>
			</dataPoints>
		</scan>
		<scan status="Completed" appendNumber="0" scanAxis="2Theta" mode="Continuous">
			<header>
				<startTimeStamp>2024-07-05T13:46:22-04:00</startTimeStamp>
				<endTimeStamp>2024-07-05T14:16:20-04:00</endTimeStamp>
				<author>
					<name>lw627</name>
				</author>
				<source>
					<applicationSoftware version="7.1">Data Collector</applicationSoftware>
					<instrumentControlSoftware version="8.2  20201204">EMPYREAN</instrumentControlSoftware>
					<instrumentID>0000000011260721</instrumentID>
				</source>
			</header>
			<dataPoints>
				<positions axis="2Theta" unit="deg">
					<startPosition>71.5721018184005</startPosition>
					<endPosition>74.919371589617</endPosition>
				</positions>
				<positions axis="Omega" unit="deg">
					<commonPosition>17.9803683520044</commonPosition>
				</positions>
				<positions axis="Phi" unit="deg">
					<commonPosition>-267.92</commonPosition>
				</positions>
				<positions axis="Chi" unit="deg">
					<commonPosition>0</commonPosition>
				</positions>
				<positions axis="Z" unit="mm">
					<commonPosition>8.391</commonPosition>
				</positions>
				<commonCountingTime unit="seconds">0.974</commonCountingTime>
				<counts unit="counts">0 0 1 0 1 0 0 0 0 0 1 2 0 0 3 0 0 0 0 1 0 0 0 1 1 0 0 0 1 0 0 0 1 0 0 0 0 0 2 0 0 2 0 2 0 0 0 0 0 0 0 0 0 0 1 0 0 1 0 1 0 1 0 0 0 0 0 0 1 0 0 0 1 0 0 0 1 1 1 0 0 2 0 0 1 1 1 0 0 0 0 1 0 0 0 0 0 0 0 0 0 1 0 0 2 0 1 1 1 0 0 1 0 1 0 1 0 0 0 0 0 0 0 0 0 0 0 0 1 2 0 1 0 0 1 0 0 0 0 0 1 1 0 0 0 0 2 0 1 0 2 1 0 0 0 0 1 0 0 0 0 2 0 0 0 0 1 0 0 1 1 0 0 1 0 0 0 0 0 1 0 0 1 1 0 2 0 0 0 0 0 0 0 0 0 0 1 0 1 0 0 1 1 0 0 0 0 0 0 0 1 1 0 1 0 0 1 0 1 0 0 0 0 1 0 0 0 0 0 0 1 1 0 0 0 0 0 0 0 1 2 0 1 0 0 1 0 0 3 2 0 0 0 0 0</counts>
			</dataPoints>
		</scan>
		<scan status="Completed" appendNumber="0" scanAxis="2Theta" mode="Continuous">
			<header>
				<startTimeStamp>2024-07-05T13:46:22-04:00</startTimeStamp>
				<endTimeStamp>2024-07-05T14:16:20-04:00</endTimeStamp>
				<author>
					<name>lw627</name>
				</author>
				<source>
					<applicationSoftware version="7.1">Data Collector</applicationSoftware>
					<instrumentControlSoftware version="8.2  20201204">EMPYREAN</instrumentControlSoftware>
					<instrumentID>0000000011260721</instrumentID>
				</source>
			</header>
			<dataPoints>
				<positions axis="2Theta" unit="deg">
					<startPosition>71.5753843890687</startPosition>
					<endPosition>74.9226541602851</endPosition>
				</positions>
				<positions axis="Omega" unit="deg">
					<commonPosition>17.9820096373384</commonPosition>
				</positions>
				<positions axis="Phi" unit="deg">
					<commonPosition>-267.92</commonPosition>
				</positions>
				<positions axis="Chi" unit="deg">
					<commonPosition>0</commonPosition>
				</positions>
				<positions axis="Z" unit="mm">
					<commonPosition>8.391</commonPosition>
				</positions>
				<commonCountingTime unit="seconds">0.974</commonCountingTime>
				<counts unit="counts">0 0 0 0 0 0 0 0 1 0 0 0 0 0 0 0 2 1 0 0 0 0 0 0 0 1 0 0 0 0 0 1 0 0 0 0 1 0 0 0 0 0 0 0 1 0 0 1 1 0 0 1 0 0 0 1 1 1 0 1 0 1 0 1 1 0 0 0 1 0 1 0 0 0 1 1 0 1 0 0 2 1 0 1 0 0 0 0 1 0 0 0 0 0 0 1 2 0 0 0 1 0 0 0 0 0 1 1 0 1 0 0 0 0 0 1 0 0 0 0 0 0 1 1 0 0 0 1 0 0 0 0 0 0 0 0 0 1 1 0 0 1 0 0 1 0 0 1 0 1 0 0 1 1 0 0 1 0 0 1 0 1 0 0 1 0 0 0 0 0 1 0 0 0 1 0 0 0 1 0 0 0 1 0 0 0 0 1 1 0 0 0 0 0 0 0 0 1 0 1 0 1 0 0 2 0 1 3 0 1 0 1 0 1 0 0 1 0 0 0 2 1 1 1 0 0 0 0 0 1 0 0 0 1 0 1 0 0 1 2 0 0 0 0 0 0 0 0 1 1 1 0 0 0 0</counts>
			</dataPoints>
		</scan>
		<scan status="Completed" appendNumber="0" scanAxis="2Theta" mode="Continuous">
			<header>
				<startTimeStamp>2024-07-05T13:46:22-04:00</startTimeStamp>
				<endTimeStamp>2024-07-05T14:16:20-04:00</endTimeStamp>
				<author>
					<name>lw627</name>
				</author>
				<source>
					<applicationSoftware version="7.1">Data Collector</applicationSoftware>
					<instrumentControlSoftware version="8.2  20201204">EMPYREAN</instrumentControlSoftware>
					<instrumentID>0000000011260721</instrumentID>
				</source>
			</header>
			<dataPoints>
				<positions axis="2Theta" unit="deg">
					<startPosition>71.5786669597368</startPosition>
					<endPosition>74.9259367309533</endPosition>
				</positions>
				<positions axis="Omega" unit="deg">
					<commonPosition>17.9836509226725</commonPosition>
				</positions>
				<positions axis="Phi" unit="deg">
					<commonPosition>-267.92</commonPosition>
				</positions>
				<positions axis="Chi" unit="deg">
					<commonPosition>0</commonPosition>
				</positions>
				<positions axis="Z" unit="mm">
					<commonPosition>8.391</commonPosition>
				</positions>
				<commonCountingTime unit="seconds">0.974</commonCountingTime>
				<counts unit="counts">0 2 0 1 0 0 0 0 0 0 0 1 0 0 0 1 0 0 0 1 0 0 0 0 0 0 0 0 0 1 0 0 0 0 0 0 0 0 0 0 4 0 1 0 0 0 0 1 0 1 0 1 0 0 0 0 0 0 0 1 0 0 1 2 0 0 0 0 0 0 0 0 2 0 1 0 0 0 0 0 0 0 0 0 0 0 0 1 2 2 0 1 0 0 0 0 0 0 0 0 1 1 0 0 0 0 0 0 0 2 0 0 0 0 0 0 0 0 1 0 0 0 1 1 0 1 0 0 1 0 0 1 1 1 0 0 1 1 1 1 1 1 0 0 0 0 0 0 0 0 1 0 0 0 1 0 0 0 1 0 0 0 0 1 0 0 0 0 0 1 0 1 1 0 0 0 0 0 0 0 0 0 1 1 0 0 0 0 0 0 3 0 0 0 1 0 0 0 0 0 0 0 0 0 0 0 0 0 0 0 0 0 0 0 0 0 0 0 0 1 2 0 0 0 0 3 0 0 0 0 1 0 0 0 0 0 0 0 1 0 0 1 0 2 1 0 0 1 1 0 0 0 0 0 0</counts>
			</dataPoints>
		</scan>
		<scan status="Completed" appendNumber="0" scanAxis="2Theta" mode="Continuous">
			<header>
				<startTimeStamp>2024-07-05T13:46:22-04:00</startTimeStamp>
				<endTimeStamp>2024-07-05T14:16:20-04:00</endTimeStamp>
				<author>
					<name>lw627</name>
				</author>
				<source>
					<applicationSoftware version="7.1">Data Collector</applicationSoftware>
					<instrumentControlSoftware version="8.2  20201204">EMPYREAN</instrumentControlSoftware>
					<instrumentID>0000000011260721</instrumentID>
				</source>
			</header>
			<dataPoints>
				<positions axis="2Theta" unit="deg">
					<startPosition>71.5819495304049</startPosition>
					<endPosition>74.9292193016214</endPosition>
				</positions>
				<positions axis="Omega" unit="deg">
					<commonPosition>17.9852922080066</commonPosition>
				</positions>
				<positions axis="Phi" unit="deg">
					<commonPosition>-267.92</commonPosition>
				</positions>
				<positions axis="Chi" unit="deg">
					<commonPosition>0</commonPosition>
				</positions>
				<positions axis="Z" unit="mm">
					<commonPosition>8.391</commonPosition>
				</positions>
				<commonCountingTime unit="seconds">0.974</commonCountingTime>
				<counts unit="counts">0 0 0 0 0 2 0 1 0 1 0 1 2 0 0 0 0 0 0 1 0 0 0 0 0 0 1 0 1 2 0 0 0 1 1 0 0 0 0 0 0 0 1 0 0 0 0 0 1 0 0 0 1 0 0 0 1 0 0 0 1 0 0 0 1 1 0 0 0 0 1 0 0 0 0 1 0 1 0 0 0 1 0 0 0 0 0 1 1 2 1 0 0 1 2 0 0 0 0 0 0 0 0 1 0 0 0 1 0 0 1 1 0 0 0 1 1 0 0 0 2 0 0 1 0 1 0 0 1 0 1 0 0 0 0 0 0 0 1 0 0 2 0 1 0 1 0 1 1 0 1 0 0 0 0 0 0 0 0 0 0 0 0 0 0 0 1 0 0 1 0 1 0 0 0 1 0 0 0 0 0 0 2 0 0 0 0 0 1 0 1 0 0 0 0 1 0 1 1 1 0 0 1 0 1 0 0 0 1 0 0 0 0 0 1 1 1 0 0 1 0 0 1 0 2 0 0 0 1 0 0 0 0 0 0 0 0 0 0 0 0 1 0 0 0 0 0 1 0 0 0 0 1 0 0</counts>
			</dataPoints>
		</scan>
		<scan status="Completed" appendNumber="0" scanAxis="2Theta" mode="Continuous">
			<header>
				<startTimeStamp>2024-07-05T13:46:22-04:00</startTimeStamp>
				<endTimeStamp>2024-07-05T14:16:20-04:00</endTimeStamp>
				<author>
					<name>lw627</name>
				</author>
				<source>
					<applicationSoftware version="7.1">Data Collector</applicationSoftware>
					<instrumentControlSoftware version="8.2  20201204">EMPYREAN</instrumentControlSoftware>
					<instrumentID>0000000011260721</instrumentID>
				</source>
			</header>
			<dataPoints>
				<positions axis="2Theta" unit="deg">
					<startPosition>71.585232101073</startPosition>
					<endPosition>74.9325018722895</endPosition>
				</positions>
				<positions axis="Omega" unit="deg">
					<commonPosition>17.9869334933406</commonPosition>
				</positions>
				<positions axis="Phi" unit="deg">
					<commonPosition>-267.92</commonPosition>
				</positions>
				<positions axis="Chi" unit="deg">
					<commonPosition>0</commonPosition>
				</positions>
				<positions axis="Z" unit="mm">
					<commonPosition>8.391</commonPosition>
				</positions>
				<commonCountingTime unit="seconds">0.974</commonCountingTime>
				<counts unit="counts">1 0 0 0 0 0 0 0 0 0 0 0 1 0 0 0 2 0 1 0 0 0 0 0 0 0 0 0 0 0 0 0 1 0 0 1 1 0 1 0 0 0 2 1 0 0 0 1 0 0 0 0 0 0 1 0 0 1 0 1 0 0 0 0 0 0 0 0 0 0 1 0 0 0 1 1 0 0 0 0 0 0 2 1 1 1 0 0 1 0 1 0 0 0 0 0 0 0 0 0 1 1 0 1 0 1 0 3 0 0 0 1 0 0 0 1 1 0 1 0 0 0 0 0 0 1 0 0 0 0 1 0 0 0 1 0 0 1 0 0 0 1 0 0 1 0 0 0 0 0 0 0 0 0 1 0 0 0 1 0 0 0 0 0 0 1 0 1 0 0 0 0 1 0 0 1 2 0 0 0 0 0 1 0 0 0 0 0 1 0 1 1 0 1 0 0 0 0 1 0 0 0 0 0 0 0 0 0 1 0 0 1 0 0 0 0 0 0 0 0 0 0 1 0 0 0 0 0 0 1 0 0 0 0 0 0 0 0 1 1 0 0 0 1 1 1 0 0 0 1 1 1 1 0 0</counts>
			</dataPoints>
		</scan>
		<scan status="Completed" appendNumber="0" scanAxis="2Theta" mode="Continuous">
			<header>
				<startTimeStamp>2024-07-05T13:46:22-04:00</startTimeStamp>
				<endTimeStamp>2024-07-05T14:16:20-04:00</endTimeStamp>
				<author>
					<name>lw627</name>
				</author>
				<source>
					<applicationSoftware version="7.1">Data Collector</applicationSoftware>
					<instrumentControlSoftware version="8.2  20201204">EMPYREAN</instrumentControlSoftware>
					<instrumentID>0000000011260721</instrumentID>
				</source>
			</header>
			<dataPoints>
				<positions axis="2Theta" unit="deg">
					<startPosition>71.5885146717412</startPosition>
					<endPosition>74.9357844429576</endPosition>
				</positions>
				<positions axis="Omega" unit="deg">
					<commonPosition>17.9885747786747</commonPosition>
				</positions>
				<positions axis="Phi" unit="deg">
					<commonPosition>-267.92</commonPosition>
				</positions>
				<positions axis="Chi" unit="deg">
					<commonPosition>0</commonPosition>
				</positions>
				<positions axis="Z" unit="mm">
					<commonPosition>8.391</commonPosition>
				</positions>
				<commonCountingTime unit="seconds">0.974</commonCountingTime>
				<counts unit="counts">0 0 0 0 0 1 1 1 0 1 0 0 0 0 1 0 0 1 1 0 1 0 0 0 1 1 2 0 0 0 1 1 1 0 0 0 1 0 0 1 0 0 0 0 0 0 0 1 1 1 0 0 0 1 1 0 0 0 0 1 0 0 0 0 0 0 0 1 1 1 0 0 0 0 0 0 0 0 0 0 0 0 0 2 0 0 1 0 0 0 0 0 0 0 1 0 1 0 0 0 0 1 1 0 0 0 0 2 0 1 0 1 0 0 0 1 0 0 0 0 0 0 0 0 0 0 0 0 0 0 0 0 0 0 0 0 0 0 0 0 0 0 0 1 0 0 1 1 0 0 1 0 0 0 0 0 0 0 0 0 0 0 1 0 0 1 0 0 1 0 0 0 0 1 0 0 0 1 0 0 1 0 0 0 0 0 0 0 0 0 0 0 0 0 1 0 3 0 0 0 0 0 0 0 0 0 1 2 0 0 0 0 0 0 0 0 0 0 1 1 0 0 0 0 1 0 0 2 0 0 1 0 0 1 0 1 1 0 0 0 0 0 0 0 0 1 1 1 0 0 0 1 1 0 1</counts>
			</dataPoints>
		</scan>
		<scan status="Completed" appendNumber="0" scanAxis="2Theta" mode="Continuous">
			<header>
				<startTimeStamp>2024-07-05T13:46:22-04:00</startTimeStamp>
				<endTimeStamp>2024-07-05T14:16:20-04:00</endTimeStamp>
				<author>
					<name>lw627</name>
				</author>
				<source>
					<applicationSoftware version="7.1">Data Collector</applicationSoftware>
					<instrumentControlSoftware version="8.2  20201204">EMPYREAN</instrumentControlSoftware>
					<instrumentID>0000000011260721</instrumentID>
				</source>
			</header>
			<dataPoints>
				<positions axis="2Theta" unit="deg">
					<startPosition>71.5917972424093</startPosition>
					<endPosition>74.9390670136258</endPosition>
				</positions>
				<positions axis="Omega" unit="deg">
					<commonPosition>17.9902160640088</commonPosition>
				</positions>
				<positions axis="Phi" unit="deg">
					<commonPosition>-267.92</commonPosition>
				</positions>
				<positions axis="Chi" unit="deg">
					<commonPosition>0</commonPosition>
				</positions>
				<positions axis="Z" unit="mm">
					<commonPosition>8.391</commonPosition>
				</positions>
				<commonCountingTime unit="seconds">0.974</commonCountingTime>
				<counts unit="counts">0 1 0 0 0 2 0 0 1 2 0 1 0 1 0 0 0 0 0 0 0 0 0 0 2 0 0 0 0 1 0 0 1 0 0 0 0 1 0 0 0 0 1 0 0 0 1 0 1 0 0 0 0 1 1 0 1 0 0 0 0 0 0 0 0 0 0 0 0 1 0 0 0 0 0 2 2 1 0 0 0 0 1 0 0 0 0 1 0 0 0 0 0 0 0 0 0 0 0 1 0 1 0 0 0 1 0 0 1 0 0 0 0 0 0 0 1 0 1 1 0 0 0 0 1 0 0 0 1 0 1 0 1 1 0 0 0 1 0 0 0 0 0 1 0 0 0 0 0 0 0 0 1 1 0 1 0 0 0 0 1 0 0 0 0 0 2 0 1 2 0 0 0 0 0 0 0 1 0 0 0 0 1 0 1 2 1 0 0 1 1 1 0 0 0 0 0 0 0 0 0 0 1 1 0 0 0 0 0 0 0 0 0 1 0 0 0 0 0 0 0 0 0 0 0 0 0 0 0 0 0 0 1 0 0 1 0 1 0 0 1 0 0 0 0 2 0 0 0 0 0 0 0 0 0</counts>
			</dataPoints>
		</scan>
		<scan status="Completed" appendNumber="0" scanAxis="2Theta" mode="Continuous">
			<header>
				<startTimeStamp>2024-07-05T13:46:22-04:00</startTimeStamp>
				<endTimeStamp>2024-07-05T14:16:20-04:00</endTimeStamp>
				<author>
					<name>lw627</name>
				</author>
				<source>
					<applicationSoftware version="7.1">Data Collector</applicationSoftware>
					<instrumentControlSoftware version="8.2  20201204">EMPYREAN</instrumentControlSoftware>
					<instrumentID>0000000011260721</instrumentID>
				</source>
			</header>
			<dataPoints>
				<positions axis="2Theta" unit="deg">
					<startPosition>71.5950798130774</startPosition>
					<endPosition>74.9423495842939</endPosition>
				</positions>
				<positions axis="Omega" unit="deg">
					<commonPosition>17.9918573493428</commonPosition>
				</positions>
				<positions axis="Phi" unit="deg">
					<commonPosition>-267.92</commonPosition>
				</positions>
				<positions axis="Chi" unit="deg">
					<commonPosition>0</commonPosition>
				</positions>
				<positions axis="Z" unit="mm">
					<commonPosition>8.391</commonPosition>
				</positions>
				<commonCountingTime unit="seconds">0.974</commonCountingTime>
				<counts unit="counts">1 1 0 0 0 1 0 0 1 0 1 0 0 0 0 0 0 1 0 0 0 0 0 0 0 0 0 0 1 1 0 1 0 0 0 0 0 0 0 0 1 0 0 0 0 0 0 0 0 1 0 1 1 0 0 0 0 0 0 0 0 0 0 0 1 0 0 2 0 1 0 0 0 3 1 0 1 0 0 0 1 0 0 0 0 0 0 0 1 0 0 0 0 0 0 0 0 0 1 0 0 0 0 1 0 1 0 0 1 0 0 0 0 0 1 0 2 1 1 1 0 0 0 0 1 0 1 0 0 0 0 1 0 0 0 1 1 0 0 0 0 0 0 0 0 0 0 0 0 0 2 0 0 0 0 0 0 0 0 0 0 0 0 1 2 1 1 0 0 0 0 0 0 0 1 0 0 1 1 0 0 1 0 0 1 0 0 0 0 1 1 0 0 0 0 1 0 0 0 0 0 0 0 0 0 0 0 1 0 0 0 0 0 0 1 0 0 0 1 0 0 1 0 1 0 1 1 0 0 1 1 0 0 0 1 0 1 0 1 0 0 0 0 0 1 0 0 0 0 0 0 0 0 0 0</counts>
			</dataPoints>
		</scan>
		<scan status="Completed" appendNumber="0" scanAxis="2Theta" mode="Continuous">
			<header>
				<startTimeStamp>2024-07-05T13:46:22-04:00</startTimeStamp>
				<endTimeStamp>2024-07-05T14:16:20-04:00</endTimeStamp>
				<author>
					<name>lw627</name>
				</author>
				<source>
					<applicationSoftware version="7.1">Data Collector</applicationSoftware>
					<instrumentControlSoftware version="8.2  20201204">EMPYREAN</instrumentControlSoftware>
					<instrumentID>0000000011260721</instrumentID>
				</source>
			</header>
			<dataPoints>
				<positions axis="2Theta" unit="deg">
					<startPosition>71.5983623837456</startPosition>
					<endPosition>74.945632154962</endPosition>
				</positions>
				<positions axis="Omega" unit="deg">
					<commonPosition>17.9934986346769</commonPosition>
				</positions>
				<positions axis="Phi" unit="deg">
					<commonPosition>-267.92</commonPosition>
				</positions>
				<positions axis="Chi" unit="deg">
					<commonPosition>0</commonPosition>
				</positions>
				<positions axis="Z" unit="mm">
					<commonPosition>8.391</commonPosition>
				</positions>
				<commonCountingTime unit="seconds">0.974</commonCountingTime>
				<counts unit="counts">0 0 1 0 0 0 0 0 0 1 0 0 0 0 0 0 1 0 0 1 2 0 0 0 0 0 0 0 1 1 0 0 0 0 0 0 0 0 0 0 1 0 0 0 1 0 0 1 0 0 0 0 1 0 0 0 0 0 0 0 0 1 0 0 0 0 0 2 0 0 2 0 0 0 1 0 1 1 0 0 0 0 0 2 0 0 0 0 0 0 0 0 0 1 0 0 1 0 0 1 0 0 0 0 0 0 0 0 0 1 0 0 1 0 2 1 0 2 0 0 0 0 1 0 0 0 0 0 0 0 1 0 0 1 0 0 0 0 0 0 1 0 1 0 0 0 0 0 1 0 0 0 1 0 0 0 1 0 0 1 0 0 0 0 0 1 2 0 0 0 1 0 0 0 0 0 0 2 1 0 0 0 0 1 0 0 0 0 1 0 0 0 0 0 1 1 0 1 1 0 0 0 0 0 0 0 0 0 1 1 3 0 0 0 0 1 0 1 1 0 0 1 1 0 0 0 0 0 0 0 0 0 0 0 0 0 0 1 0 0 0 0 1 0 0 0 1 0 0 0 0 0 0 0 0</counts>
			</dataPoints>
		</scan>
		<scan status="Completed" appendNumber="0" scanAxis="2Theta" mode="Continuous">
			<header>
				<startTimeStamp>2024-07-05T13:46:22-04:00</startTimeStamp>
				<endTimeStamp>2024-07-05T14:16:20-04:00</endTimeStamp>
				<author>
					<name>lw627</name>
				</author>
				<source>
					<applicationSoftware version="7.1">Data Collector</applicationSoftware>
					<instrumentControlSoftware version="8.2  20201204">EMPYREAN</instrumentControlSoftware>
					<instrumentID>0000000011260721</instrumentID>
				</source>
			</header>
			<dataPoints>
				<positions axis="2Theta" unit="deg">
					<startPosition>71.6016449544137</startPosition>
					<endPosition>74.9489147256301</endPosition>
				</positions>
				<positions axis="Omega" unit="deg">
					<commonPosition>17.995139920011</commonPosition>
				</positions>
				<positions axis="Phi" unit="deg">
					<commonPosition>-267.92</commonPosition>
				</positions>
				<positions axis="Chi" unit="deg">
					<commonPosition>0</commonPosition>
				</positions>
				<positions axis="Z" unit="mm">
					<commonPosition>8.391</commonPosition>
				</positions>
				<commonCountingTime unit="seconds">0.974</commonCountingTime>
				<counts unit="counts">1 0 0 0 1 0 0 0 0 0 0 0 0 0 1 1 2 1 1 0 1 0 0 1 0 0 0 0 0 1 0 0 1 0 1 1 0 0 0 0 0 1 0 0 1 1 1 0 2 0 0 0 1 0 0 0 0 0 0 0 0 0 0 0 1 0 0 0 0 1 0 1 1 0 0 0 0 0 2 0 0 1 0 0 1 0 1 0 0 0 0 0 0 0 1 0 0 0 0 0 0 0 1 0 1 0 0 0 1 0 1 0 1 0 0 1 0 0 1 0 0 0 0 0 0 0 0 1 0 0 0 0 1 0 0 0 0 0 1 0 0 0 0 0 0 0 0 0 0 1 1 0 0 0 0 0 1 1 1 0 1 0 0 0 1 1 0 0 1 0 0 1 2 0 0 0 1 0 0 0 0 0 2 0 0 2 0 1 0 0 1 0 0 1 0 1 0 1 0 0 0 0 0 0 0 0 1 1 0 0 1 0 0 0 0 0 0 0 1 1 0 0 1 1 0 0 0 2 0 0 2 0 0 0 0 0 0 0 2 0 0 0 0 0 0 2 0 1 0 0 0 0 2 1 2</counts>
			</dataPoints>
		</scan>
		<scan status="Completed" appendNumber="0" scanAxis="2Theta" mode="Continuous">
			<header>
				<startTimeStamp>2024-07-05T13:46:22-04:00</startTimeStamp>
				<endTimeStamp>2024-07-05T14:16:20-04:00</endTimeStamp>
				<author>
					<name>lw627</name>
				</author>
				<source>
					<applicationSoftware version="7.1">Data Collector</applicationSoftware>
					<instrumentControlSoftware version="8.2  20201204">EMPYREAN</instrumentControlSoftware>
					<instrumentID>0000000011260721</instrumentID>
				</source>
			</header>
			<dataPoints>
				<positions axis="2Theta" unit="deg">
					<startPosition>71.6049275250818</startPosition>
					<endPosition>74.9521972962983</endPosition>
				</positions>
				<positions axis="Omega" unit="deg">
					<commonPosition>17.996781205345</commonPosition>
				</positions>
				<positions axis="Phi" unit="deg">
					<commonPosition>-267.92</commonPosition>
				</positions>
				<positions axis="Chi" unit="deg">
					<commonPosition>0</commonPosition>
				</positions>
				<positions axis="Z" unit="mm">
					<commonPosition>8.391</commonPosition>
				</positions>
				<commonCountingTime unit="seconds">0.974</commonCountingTime>
				<counts unit="counts">0 0 0 1 0 0 0 0 0 0 0 0 1 0 0 0 0 0 0 0 0 0 0 1 1 0 0 0 0 0 0 0 0 0 0 1 0 0 0 0 0 1 0 0 1 0 0 0 1 1 0 0 1 0 0 0 1 0 1 0 0 0 2 0 1 0 0 0 0 0 0 0 2 1 0 0 1 0 0 0 0 1 0 0 0 0 0 0 0 0 0 0 0 1 0 0 0 1 0 0 0 0 0 0 0 0 0 1 0 1 0 0 1 0 0 0 0 0 0 2 0 1 0 0 0 0 1 0 0 2 0 0 1 0 0 0 0 0 0 0 1 2 0 0 0 0 0 0 0 2 0 0 0 1 0 0 1 0 0 0 0 0 0 0 0 0 0 2 2 1 2 0 0 0 3 0 0 0 1 1 0 1 1 0 0 1 0 0 1 1 0 0 0 0 2 1 0 0 0 0 0 0 0 0 1 0 0 1 0 0 0 0 0 0 1 0 0 0 0 0 0 1 1 2 0 0 0 0 0 1 0 0 1 0 0 0 0 0 2 0 0 2 0 0 0 1 0 0 1 1 1 0 1 0 0</counts>
			</dataPoints>
		</scan>
		<scan status="Completed" appendNumber="0" scanAxis="2Theta" mode="Continuous">
			<header>
				<startTimeStamp>2024-07-05T13:46:22-04:00</startTimeStamp>
				<endTimeStamp>2024-07-05T14:16:20-04:00</endTimeStamp>
				<author>
					<name>lw627</name>
				</author>
				<source>
					<applicationSoftware version="7.1">Data Collector</applicationSoftware>
					<instrumentControlSoftware version="8.2  20201204">EMPYREAN</instrumentControlSoftware>
					<instrumentID>0000000011260721</instrumentID>
				</source>
			</header>
			<dataPoints>
				<positions axis="2Theta" unit="deg">
					<startPosition>71.6082100957499</startPosition>
					<endPosition>74.9554798669664</endPosition>
				</positions>
				<positions axis="Omega" unit="deg">
					<commonPosition>17.9984224906791</commonPosition>
				</positions>
				<positions axis="Phi" unit="deg">
					<commonPosition>-267.92</commonPosition>
				</positions>
				<positions axis="Chi" unit="deg">
					<commonPosition>0</commonPosition>
				</positions>
				<positions axis="Z" unit="mm">
					<commonPosition>8.391</commonPosition>
				</positions>
				<commonCountingTime unit="seconds">0.974</commonCountingTime>
				<counts unit="counts">2 1 0 0 1 1 1 0 0 0 1 0 1 1 1 0 0 1 0 1 0 2 2 1 0 0 0 0 0 0 0 1 1 1 0 0 1 0 0 0 0 1 0 1 0 0 1 0 0 0 0 2 0 0 0 0 0 0 0 0 0 2 0 1 0 0 0 0 0 1 1 0 0 0 0 1 0 0 0 0 0 0 0 0 1 0 0 0 0 1 0 1 0 0 1 0 0 2 1 1 0 3 1 1 1 0 0 0 0 0 1 0 1 2 0 0 1 0 0 1 0 0 0 0 0 2 1 1 0 0 0 0 1 0 1 0 0 0 0 0 0 1 0 0 1 0 0 0 1 0 0 0 0 1 0 1 0 0 0 0 1 0 0 1 0 2 0 0 0 0 1 0 0 1 0 0 0 0 0 0 0 0 0 0 0 0 0 0 0 1 0 2 0 0 2 0 1 1 1 2 0 0 1 1 1 0 1 0 0 0 0 1 0 0 1 0 0 0 1 0 0 0 0 1 0 0 0 0 0 1 0 0 0 0 2 1 1 1 0 0 0 0 0 0 0 1 1 1 0 0 0 0 0 0 0</counts>
			</dataPoints>
		</scan>
		<scan status="Completed" appendNumber="0" scanAxis="2Theta" mode="Continuous">
			<header>
				<startTimeStamp>2024-07-05T13:46:22-04:00</startTimeStamp>
				<endTimeStamp>2024-07-05T14:16:20-04:00</endTimeStamp>
				<author>
					<name>lw627</name>
				</author>
				<source>
					<applicationSoftware version="7.1">Data Collector</applicationSoftware>
					<instrumentControlSoftware version="8.2  20201204">EMPYREAN</instrumentControlSoftware>
					<instrumentID>0000000011260721</instrumentID>
				</source>
			</header>
			<dataPoints>
				<positions axis="2Theta" unit="deg">
					<startPosition>71.6114926664181</startPosition>
					<endPosition>74.9587624376345</endPosition>
				</positions>
				<positions axis="Omega" unit="deg">
					<commonPosition>18.0000637760131</commonPosition>
				</positions>
				<positions axis="Phi" unit="deg">
					<commonPosition>-267.92</commonPosition>
				</positions>
				<positions axis="Chi" unit="deg">
					<commonPosition>0</commonPosition>
				</positions>
				<positions axis="Z" unit="mm">
					<commonPosition>8.391</commonPosition>
				</positions>
				<commonCountingTime unit="seconds">0.974</commonCountingTime>
				<counts unit="counts">2 0 0 0 1 1 1 0 0 0 1 0 1 0 0 0 2 0 0 1 0 2 0 1 0 1 0 2 1 0 0 0 1 0 0 0 1 1 0 0 1 0 0 0 0 0 0 0 1 0 1 0 0 1 0 0 0 0 1 0 1 0 0 0 0 0 0 0 0 0 0 0 0 0 0 0 0 0 1 0 1 0 0 0 0 0 0 2 0 1 0 0 0 0 0 0 1 0 0 1 0 0 0 0 1 0 0 0 0 0 1 0 0 1 0 0 0 0 0 0 0 0 1 0 1 0 0 1 0 0 0 0 0 0 0 0 1 0 1 1 0 0 0 0 2 0 0 0 0 0 1 0 1 0 0 0 0 0 0 0 0 0 0 0 0 1 0 0 0 0 0 0 0 0 0 0 0 0 1 0 0 0 0 1 0 0 0 0 0 0 0 0 0 0 0 2 0 1 0 1 0 0 0 0 0 0 0 0 0 0 0 0 0 0 0 1 0 0 0 0 0 0 0 0 0 0 0 0 0 0 0 0 0 0 0 1 0 1 1 0 0 0 0 0 1 0 0 0 2 0 0 0 0 2 1</counts>
			</dataPoints>
		</scan>
		<scan status="Completed" appendNumber="0" scanAxis="2Theta" mode="Continuous">
			<header>
				<startTimeStamp>2024-07-05T13:46:22-04:00</startTimeStamp>
				<endTimeStamp>2024-07-05T14:16:20-04:00</endTimeStamp>
				<author>
					<name>lw627</name>
				</author>
				<source>
					<applicationSoftware version="7.1">Data Collector</applicationSoftware>
					<instrumentControlSoftware version="8.2  20201204">EMPYREAN</instrumentControlSoftware>
					<instrumentID>0000000011260721</instrumentID>
				</source>
			</header>
			<dataPoints>
				<positions axis="2Theta" unit="deg">
					<startPosition>71.6147752370862</startPosition>
					<endPosition>74.9620450083027</endPosition>
				</positions>
				<positions axis="Omega" unit="deg">
					<commonPosition>18.0017050613472</commonPosition>
				</positions>
				<positions axis="Phi" unit="deg">
					<commonPosition>-267.92</commonPosition>
				</positions>
				<positions axis="Chi" unit="deg">
					<commonPosition>0</commonPosition>
				</positions>
				<positions axis="Z" unit="mm">
					<commonPosition>8.391</commonPosition>
				</positions>
				<commonCountingTime unit="seconds">0.974</commonCountingTime>
				<counts unit="counts">0 0 1 0 1 0 0 0 0 1 0 1 0 0 0 0 0 1 0 1 1 1 0 1 1 0 0 0 0 0 1 0 0 1 0 0 2 1 0 1 0 0 0 0 0 2 1 2 0 1 0 1 0 1 1 0 0 1 0 0 0 0 2 0 0 0 0 0 1 0 0 0 2 0 0 2 1 0 0 0 1 3 0 0 0 1 0 0 0 0 0 1 0 0 0 0 1 0 0 0 0 0 1 0 0 0 0 0 1 0 0 0 0 0 1 0 0 1 0 2 0 0 1 0 1 0 0 0 0 0 0 0 0 1 0 0 1 0 0 0 0 0 0 0 0 0 1 1 1 0 0 0 0 0 0 0 0 0 1 0 1 0 0 0 0 1 0 0 0 0 0 1 0 2 0 0 0 0 0 0 0 0 0 0 1 0 0 0 0 0 0 0 0 0 0 1 0 1 0 0 0 2 3 0 0 0 0 1 1 0 0 0 1 0 0 1 0 0 0 0 0 0 0 1 1 0 0 1 1 0 0 0 0 1 0 0 2 0 0 0 0 0 0 0 0 1 1 0 0 0 0 0 0 0 1</counts>
			</dataPoints>
		</scan>
		<scan status="Completed" appendNumber="0" scanAxis="2Theta" mode="Continuous">
			<header>
				<startTimeStamp>2024-07-05T13:46:22-04:00</startTimeStamp>
				<endTimeStamp>2024-07-05T14:16:20-04:00</endTimeStamp>
				<author>
					<name>lw627</name>
				</author>
				<source>
					<applicationSoftware version="7.1">Data Collector</applicationSoftware>
					<instrumentControlSoftware version="8.2  20201204">EMPYREAN</instrumentControlSoftware>
					<instrumentID>0000000011260721</instrumentID>
				</source>
			</header>
			<dataPoints>
				<positions axis="2Theta" unit="deg">
					<startPosition>71.6180578077543</startPosition>
					<endPosition>74.9653275789708</endPosition>
				</positions>
				<positions axis="Omega" unit="deg">
					<commonPosition>18.0033463466813</commonPosition>
				</positions>
				<positions axis="Phi" unit="deg">
					<commonPosition>-267.92</commonPosition>
				</positions>
				<positions axis="Chi" unit="deg">
					<commonPosition>0</commonPosition>
				</positions>
				<positions axis="Z" unit="mm">
					<commonPosition>8.391</commonPosition>
				</positions>
				<commonCountingTime unit="seconds">0.974</commonCountingTime>
[...]
				</positions>
				<positions axis="Z" unit="mm">
					<commonPosition>8.391</commonPosition>
				</positions>
				<commonCountingTime unit="seconds">0.974</commonCountingTime>
				<counts unit="counts">0 0 2 0 0 0 0 1 0 1 0 1 0 1 2 0 0 0 2 0 1 1 0 0 0 0 1 0 0 0 0 0 0 1 0 1 0 0 1 0 0 0 0 1 0 1 0 0 0 1 1 0 0 0 0 1 0 0 0 2 1 1 1 0 0 0 1 0 0 0 0 1 0 0 0 1 1 0 0 0 1 0 1 0 0 0 0 0 0 1 0 0 0 0 0 1 1 0 1 0 0 0 0 0 0 0 0 0 1 0 2 1 1 2 1 0 1 0 0 0 0 0 0 1 0 1 1 0 0 1 1 0 0 0 1 0 0 0 0 0 1 0 0 1 0 0 0 0 1 1 0 0 0 1 1 0 1 0 0 1 0 0 0 0 0 0 0 0 0 1 0 0 0 0 1 0 0 0 0 1 0 0 0 0 0 0 0 0 0 0 1 0 1 0 0 0 0 0 1 0 0 1 0 0 0 0 0 0 0 0 1 0 0 0 0 1 0 0 0 0 0 0 0 2 1 0 0 0 2 0 0 0 0 0 0 2 0 1 1 2 0 0 0 0 1 0 0 1 0 1 0 0 0 0 0</counts>
			</dataPoints>
		</scan>
		<scan status="Completed" appendNumber="0" scanAxis="2Theta" mode="Continuous">
			<header>
				<startTimeStamp>2024-07-05T13:46:22-04:00</startTimeStamp>
				<endTimeStamp>2024-07-05T14:16:20-04:00</endTimeStamp>
				<author>
					<name>lw627</name>
				</author>
				<source>
					<applicationSoftware version="7.1">Data Collector</applicationSoftware>
					<instrumentControlSoftware version="8.2  20201204">EMPYREAN</instrumentControlSoftware>
					<instrumentID>0000000011260721</instrumentID>
				</source>
			</header>
			<dataPoints>
				<positions axis="2Theta" unit="deg">
					<startPosition>77.5135547277105</startPosition>
					<endPosition>80.860824498927</endPosition>
				</positions>
				<positions axis="Omega" unit="deg">
					<commonPosition>20.9510948066594</commonPosition>
				</positions>
				<positions axis="Phi" unit="deg">
					<commonPosition>-267.92</commonPosition>
				</positions>
				<positions axis="Chi" unit="deg">
					<commonPosition>0</commonPosition>
				</positions>
				<positions axis="Z" unit="mm">
					<commonPosition>8.391</commonPosition>
				</positions>
				<commonCountingTime unit="seconds">0.974</commonCountingTime>
				<counts unit="counts">1 0 0 1 0 0 0 0 0 2 0 0 0 1 1 0 0 0 1 0 0 3 1 1 1 0 1 0 2 0 0 0 0 1 0 0 0 0 0 0 0 1 1 0 0 0 0 0 0 0 0 1 2 2 0 0 1 0 0 1 1 1 0 0 2 0 1 1 0 0 1 3 0 1 0 0 0 1 0 0 0 0 0 0 1 0 0 0 0 2 0 1 2 1 0 0 0 0 0 1 0 0 2 0 0 0 0 1 0 0 1 1 0 0 0 0 0 0 0 1 0 1 2 0 0 0 0 1 0 1 0 0 0 0 0 0 0 1 0 0 1 0 0 0 1 1 0 1 0 1 1 1 1 0 0 0 0 0 0 0 0 0 0 1 0 1 0 1 0 0 0 1 0 0 0 0 4 0 0 0 0 0 0 0 0 0 0 0 0 1 0 1 1 1 0 0 1 0 0 0 0 0 0 2 0 0 0 0 2 0 0 0 0 0 0 1 0 0 0 0 0 1 1 0 0 1 0 0 1 0 1 2 0 0 2 0 1 1 0 0 0 0 1 0 0 0 0 0 0 0 0 0 1 0 0</counts>
			</dataPoints>
		</scan>
		<scan status="Completed" appendNumber="0" scanAxis="2Theta" mode="Continuous">
			<header>
				<startTimeStamp>2024-07-05T13:46:22-04:00</startTimeStamp>
				<endTimeStamp>2024-07-05T14:16:20-04:00</endTimeStamp>
				<author>
					<name>lw627</name>
				</author>
				<source>
					<applicationSoftware version="7.1">Data Collector</applicationSoftware>
					<instrumentControlSoftware version="8.2  20201204">EMPYREAN</instrumentControlSoftware>
					<instrumentID>0000000011260721</instrumentID>
				</source>
			</header>
			<dataPoints>
				<positions axis="2Theta" unit="deg">
					<startPosition>77.5168372983786</startPosition>
					<endPosition>80.8641070695951</endPosition>
				</positions>
				<positions axis="Omega" unit="deg">
					<commonPosition>20.9527360919934</commonPosition>
				</positions>
				<positions axis="Phi" unit="deg">
					<commonPosition>-267.92</commonPosition>
				</positions>
				<positions axis="Chi" unit="deg">
					<commonPosition>0</commonPosition>
				</positions>
				<positions axis="Z" unit="mm">
					<commonPosition>8.391</commonPosition>
				</positions>
				<commonCountingTime unit="seconds">0.974</commonCountingTime>
				<counts unit="counts">0 0 1 0 1 0 0 0 1 1 1 0 0 1 0 0 1 1 0 0 0 1 0 2 0 0 0 0 0 0 0 0 0 0 0 1 0 0 0 0 0 1 3 0 1 2 2 0 0 0 0 0 1 0 0 1 0 1 0 1 0 2 1 0 0 0 0 0 1 1 0 0 0 0 1 0 0 0 0 0 0 0 0 0 0 0 0 0 0 0 0 0 0 0 0 1 0 0 0 1 1 0 1 0 0 0 0 1 0 0 0 0 0 0 0 0 0 0 0 0 0 0 0 0 0 0 0 0 0 0 1 0 1 1 0 0 2 0 0 0 0 0 0 0 0 1 0 0 1 0 0 1 0 0 0 1 0 1 0 1 0 0 0 1 1 0 0 0 0 0 0 0 0 0 0 0 0 0 0 1 1 0 1 0 1 0 0 2 0 0 0 0 1 0 0 1 0 0 0 0 0 0 1 0 0 0 1 0 1 0 0 0 0 0 0 0 0 0 0 0 0 0 0 0 0 0 0 0 0 0 0 0 0 0 0 0 1 0 0 0 0 0 0 0 0 0 0 0 0 0 0 1 0 0 0</counts>
			</dataPoints>
		</scan>
		<scan status="Completed" appendNumber="0" scanAxis="2Theta" mode="Continuous">
			<header>
				<startTimeStamp>2024-07-05T13:46:22-04:00</startTimeStamp>
				<endTimeStamp>2024-07-05T14:16:20-04:00</endTimeStamp>
				<author>
					<name>lw627</name>
				</author>
				<source>
					<applicationSoftware version="7.1">Data Collector</applicationSoftware>
					<instrumentControlSoftware version="8.2  20201204">EMPYREAN</instrumentControlSoftware>
					<instrumentID>0000000011260721</instrumentID>
				</source>
			</header>
			<dataPoints>
				<positions axis="2Theta" unit="deg">
					<startPosition>77.5201198690467</startPosition>
					<endPosition>80.8673896402632</endPosition>
				</positions>
				<positions axis="Omega" unit="deg">
					<commonPosition>20.9543773773275</commonPosition>
				</positions>
				<positions axis="Phi" unit="deg">
					<commonPosition>-267.92</commonPosition>
				</positions>
				<positions axis="Chi" unit="deg">
					<commonPosition>0</commonPosition>
				</positions>
				<positions axis="Z" unit="mm">
					<commonPosition>8.391</commonPosition>
				</positions>
				<commonCountingTime unit="seconds">0.974</commonCountingTime>
				<counts unit="counts">0 0 2 0 0 0 0 1 0 1 0 3 1 0 0 1 0 0 0 1 1 1 0 1 0 0 0 1 0 0 1 0 0 0 1 0 0 1 0 1 0 0 0 0 0 1 0 0 1 0 0 0 0 0 0 0 0 1 1 0 0 0 1 1 0 0 0 0 0 0 0 0 0 0 3 0 2 0 1 0 0 0 0 1 1 0 0 0 0 0 1 0 0 1 0 0 0 0 0 0 0 0 0 0 0 0 0 0 2 0 0 0 0 0 0 1 0 0 0 0 1 0 2 0 0 0 0 0 0 1 0 0 1 0 0 0 0 2 0 0 0 0 1 0 0 0 0 0 0 0 1 0 0 0 0 0 0 0 0 1 1 1 1 0 0 0 1 1 0 0 0 1 0 3 0 0 0 0 1 0 1 0 0 1 1 1 1 0 1 0 2 0 1 2 0 1 0 0 0 0 0 1 1 0 0 0 0 0 0 0 0 0 0 0 0 0 0 0 1 0 0 0 0 0 0 0 0 1 0 2 0 1 1 0 0 0 1 0 0 1 0 0 0 0 0 1 1 0 1 0 0 0 0 0 0</counts>
			</dataPoints>
		</scan>
		<scan status="Completed" appendNumber="0" scanAxis="2Theta" mode="Continuous">
			<header>
				<startTimeStamp>2024-07-05T13:46:22-04:00</startTimeStamp>
				<endTimeStamp>2024-07-05T14:16:20-04:00</endTimeStamp>
				<author>
					<name>lw627</name>
				</author>
				<source>
					<applicationSoftware version="7.1">Data Collector</applicationSoftware>
					<instrumentControlSoftware version="8.2  20201204">EMPYREAN</instrumentControlSoftware>
					<instrumentID>0000000011260721</instrumentID>
				</source>
			</header>
			<dataPoints>
				<positions axis="2Theta" unit="deg">
					<startPosition>77.5234024397149</startPosition>
					<endPosition>80.8706722109313</endPosition>
				</positions>
				<positions axis="Omega" unit="deg">
					<commonPosition>20.9560186626616</commonPosition>
				</positions>
				<positions axis="Phi" unit="deg">
					<commonPosition>-267.92</commonPosition>
				</positions>
				<positions axis="Chi" unit="deg">
					<commonPosition>0</commonPosition>
				</positions>
				<positions axis="Z" unit="mm">
					<commonPosition>8.391</commonPosition>
				</positions>
				<commonCountingTime unit="seconds">0.974</commonCountingTime>
				<counts unit="counts">0 0 0 0 1 0 2 2 0 0 1 0 0 0 0 0 0 0 0 1 1 0 0 2 1 2 1 0 1 1 0 0 1 2 1 1 0 0 0 0 0 0 0 0 0 1 0 1 0 0 0 2 0 0 0 2 1 0 0 0 2 2 3 0 0 0 0 0 1 0 0 0 1 0 0 0 1 1 1 1 0 0 0 1 0 1 1 1 1 0 0 1 1 0 0 0 0 0 0 0 0 0 0 0 0 1 0 0 0 0 1 0 1 0 0 0 0 0 1 0 0 2 2 0 0 1 0 0 0 2 0 0 1 0 0 0 0 0 0 0 1 0 0 2 0 1 0 0 0 0 0 0 1 0 0 0 0 0 0 0 1 0 1 0 0 0 0 0 0 0 0 0 0 0 1 2 0 1 0 1 1 1 1 0 1 0 0 0 0 0 0 0 0 0 0 1 0 0 0 1 1 0 0 0 0 1 1 0 0 0 0 0 1 0 1 0 0 0 0 0 0 2 0 0 0 0 0 0 0 0 1 0 1 0 1 1 0 1 0 0 0 0 0 2 0 0 0 0 1 0 1 0 0 0 0</counts>
			</dataPoints>
		</scan>
		<scan status="Completed" appendNumber="0" scanAxis="2Theta" mode="Continuous">
			<header>
				<startTimeStamp>2024-07-05T13:46:22-04:00</startTimeStamp>
				<endTimeStamp>2024-07-05T14:16:20-04:00</endTimeStamp>
				<author>
					<name>lw627</name>
				</author>
				<source>
					<applicationSoftware version="7.1">Data Collector</applicationSoftware>
					<instrumentControlSoftware version="8.2  20201204">EMPYREAN</instrumentControlSoftware>
					<instrumentID>0000000011260721</instrumentID>
				</source>
			</header>
			<dataPoints>
				<positions axis="2Theta" unit="deg">
					<startPosition>77.526685010383</startPosition>
					<endPosition>80.8739547815995</endPosition>
				</positions>
				<positions axis="Omega" unit="deg">
					<commonPosition>20.9576599479956</commonPosition>
				</positions>
				<positions axis="Phi" unit="deg">
					<commonPosition>-267.92</commonPosition>
				</positions>
				<positions axis="Chi" unit="deg">
					<commonPosition>0</commonPosition>
				</positions>
				<positions axis="Z" unit="mm">
					<commonPosition>8.391</commonPosition>
				</positions>
				<commonCountingTime unit="seconds">0.974</commonCountingTime>
				<counts unit="counts">0 0 1 0 0 1 0 0 0 1 0 1 0 0 0 0 0 0 0 0 0 0 0 0 0 0 0 0 0 0 0 0 0 0 1 0 1 0 0 0 0 0 0 1 2 1 0 1 0 1 1 0 0 0 0 0 1 1 0 0 0 1 0 0 0 1 0 0 0 0 0 0 0 0 0 0 1 0 1 0 0 0 0 0 1 0 0 1 0 0 1 1 1 0 1 0 0 0 0 0 1 0 0 0 0 0 0 0 0 0 1 1 0 0 0 0 0 0 0 1 0 0 0 0 0 0 0 0 0 0 2 1 0 0 0 0 0 0 0 1 0 0 0 1 0 0 1 1 1 0 0 0 0 0 0 0 0 0 1 1 0 2 0 0 1 1 0 0 0 0 0 0 0 0 0 1 0 0 1 0 0 1 0 0 0 0 0 1 0 0 0 1 0 0 0 0 0 0 0 0 0 0 0 0 0 0 0 0 0 0 0 0 0 1 0 0 0 0 0 0 0 0 1 0 0 1 0 1 0 0 0 0 0 0 0 0 0 0 0 1 0 1 0 0 0 0 0 0 0 0 0 0 0 0 0</counts>
			</dataPoints>
		</scan>
		<scan status="Completed" appendNumber="0" scanAxis="2Theta" mode="Continuous">
			<header>
				<startTimeStamp>2024-07-05T13:46:22-04:00</startTimeStamp>
				<endTimeStamp>2024-07-05T14:16:20-04:00</endTimeStamp>
				<author>
					<name>lw627</name>
				</author>
				<source>
					<applicationSoftware version="7.1">Data Collector</applicationSoftware>
					<instrumentControlSoftware version="8.2  20201204">EMPYREAN</instrumentControlSoftware>
					<instrumentID>0000000011260721</instrumentID>
				</source>
			</header>
			<dataPoints>
				<positions axis="2Theta" unit="deg">
					<startPosition>77.5299675810511</startPosition>
					<endPosition>80.8772373522676</endPosition>
				</positions>
				<positions axis="Omega" unit="deg">
					<commonPosition>20.9593012333297</commonPosition>
				</positions>
				<positions axis="Phi" unit="deg">
					<commonPosition>-267.92</commonPosition>
				</positions>
				<positions axis="Chi" unit="deg">
					<commonPosition>0</commonPosition>
				</positions>
				<positions axis="Z" unit="mm">
					<commonPosition>8.391</commonPosition>
				</positions>
				<commonCountingTime unit="seconds">0.974</commonCountingTime>
				<counts unit="counts">0 1 0 1 1 0 1 0 0 0 1 1 0 2 0 1 0 0 0 0 0 1 0 1 0 0 0 1 0 1 0 0 1 1 0 0 0 0 1 0 0 0 0 1 0 1 2 1 0 1 0 0 0 0 1 0 0 0 1 0 1 0 0 0 1 0 0 0 0 0 0 0 1 0 0 0 0 0 0 0 0 0 0 1 1 1 0 0 0 0 1 0 1 0 0 0 0 0 0 1 0 3 0 0 0 0 0 0 0 0 0 1 0 0 0 0 0 0 0 0 0 0 0 0 0 0 0 0 1 1 0 0 0 0 1 1 1 0 2 0 0 0 0 0 0 0 0 0 0 0 1 0 0 0 0 0 0 0 3 0 1 0 0 0 0 0 0 1 1 0 0 1 0 0 0 0 0 0 0 0 0 0 0 0 1 0 0 0 1 0 0 1 0 1 0 0 0 1 0 1 1 1 0 0 0 1 0 0 1 0 0 1 0 0 1 0 1 0 1 0 0 0 0 0 0 0 0 0 0 0 0 1 0 0 0 0 0 1 0 0 0 0 0 1 1 0 0 0 0 0 0 0 0 0 1</counts>
			</dataPoints>
		</scan>
		<scan status="Completed" appendNumber="0" scanAxis="2Theta" mode="Continuous">
			<header>
				<startTimeStamp>2024-07-05T13:46:22-04:00</startTimeStamp>
				<endTimeStamp>2024-07-05T14:16:20-04:00</endTimeStamp>
				<author>
					<name>lw627</name>
				</author>
				<source>
					<applicationSoftware version="7.1">Data Collector</applicationSoftware>
					<instrumentControlSoftware version="8.2  20201204">EMPYREAN</instrumentControlSoftware>
					<instrumentID>0000000011260721</instrumentID>
				</source>
			</header>
			<dataPoints>
				<positions axis="2Theta" unit="deg">
					<startPosition>77.5332501517193</startPosition>
					<endPosition>80.8805199229357</endPosition>
				</positions>
				<positions axis="Omega" unit="deg">
					<commonPosition>20.9609425186637</commonPosition>
				</positions>
				<positions axis="Phi" unit="deg">
					<commonPosition>-267.92</commonPosition>
				</positions>
				<positions axis="Chi" unit="deg">
					<commonPosition>0</commonPosition>
				</positions>
				<positions axis="Z" unit="mm">
					<commonPosition>8.391</commonPosition>
				</positions>
				<commonCountingTime unit="seconds">0.974</commonCountingTime>
				<counts unit="counts">0 1 0 1 0 1 1 0 0 0 0 0 0 1 0 0 0 0 2 1 0 0 0 0 0 1 0 0 0 0 1 0 0 0 1 0 1 0 0 1 1 2 0 0 0 1 0 0 0 0 0 0 2 0 1 1 0 0 0 1 0 0 0 1 0 0 2 0 0 1 0 1 0 0 0 0 2 0 0 0 0 0 1 0 0 0 0 0 0 0 0 0 0 1 0 1 0 0 0 0 0 1 0 1 0 0 0 0 1 1 0 0 0 0 1 2 0 0 0 0 0 1 0 0 0 0 0 2 0 0 0 1 1 1 0 1 0 0 0 0 0 0 0 0 0 0 2 2 0 1 0 0 0 0 1 1 1 0 1 0 0 0 0 0 0 1 0 0 0 0 0 0 0 0 1 1 1 0 0 0 0 1 1 1 0 0 0 0 0 1 1 1 0 0 0 0 0 0 0 0 0 0 0 1 0 0 0 1 0 1 0 0 1 0 1 0 0 2 0 0 0 0 0 0 2 0 1 1 0 0 0 0 0 1 0 0 0 0 0 0 1 0 0 0 0 1 2 1 1 0 0 0 0 0 0</counts>
			</dataPoints>
		</scan>
		<scan status="Completed" appendNumber="0" scanAxis="2Theta" mode="Continuous">
			<header>
				<startTimeStamp>2024-07-05T13:46:22-04:00</startTimeStamp>
				<endTimeStamp>2024-07-05T14:16:20-04:00</endTimeStamp>
				<author>
					<name>lw627</name>
				</author>
				<source>
					<applicationSoftware version="7.1">Data Collector</applicationSoftware>
					<instrumentControlSoftware version="8.2  20201204">EMPYREAN</instrumentControlSoftware>
					<instrumentID>0000000011260721</instrumentID>
				</source>
			</header>
			<dataPoints>
				<positions axis="2Theta" unit="deg">
					<startPosition>77.5365327223874</startPosition>
					<endPosition>80.8838024936039</endPosition>
				</positions>
				<positions axis="Omega" unit="deg">
					<commonPosition>20.9625838039978</commonPosition>
				</positions>
				<positions axis="Phi" unit="deg">
					<commonPosition>-267.92</commonPosition>
				</positions>
				<positions axis="Chi" unit="deg">
					<commonPosition>0</commonPosition>
				</positions>
				<positions axis="Z" unit="mm">
					<commonPosition>8.391</commonPosition>
				</positions>
				<commonCountingTime unit="seconds">0.974</commonCountingTime>
				<counts unit="counts">0 0 1 0 2 0 0 1 1 0 0 1 1 1 0 0 1 0 1 0 0 0 0 0 0 0 2 1 1 0 1 0 0 1 1 0 0 0 0 1 0 0 1 0 0 0 1 0 0 1 1 0 0 2 0 0 1 0 1 0 1 0 0 1 0 0 0 0 3 0 0 1 0 0 2 0 1 0 0 0 1 0 0 0 0 0 0 0 0 0 0 0 0 2 0 1 0 0 1 0 1 1 0 0 0 0 0 0 1 0 0 0 0 1 0 1 0 0 0 1 0 0 1 0 0 0 0 0 1 2 0 0 1 0 0 1 0 0 0 0 0 0 0 0 0 0 1 1 0 0 1 1 0 0 2 0 1 0 0 2 0 0 0 0 0 0 0 0 0 0 1 0 0 0 0 0 0 0 0 0 0 0 1 0 0 0 0 0 0 0 0 0 0 0 1 0 0 0 0 1 0 0 2 0 0 0 0 0 0 0 0 0 0 0 1 0 0 0 0 1 0 0 0 0 0 0 0 1 0 0 0 0 0 0 0 0 0 0 0 0 0 1 0 0 0 0 0 0 0 0 1 0 0 0 0</counts>
			</dataPoints>
		</scan>
		<scan status="Completed" appendNumber="0" scanAxis="2Theta" mode="Continuous">
			<header>
				<startTimeStamp>2024-07-05T13:46:22-04:00</startTimeStamp>
				<endTimeStamp>2024-07-05T14:16:20-04:00</endTimeStamp>
				<author>
					<name>lw627</name>
				</author>
				<source>
					<applicationSoftware version="7.1">Data Collector</applicationSoftware>
					<instrumentControlSoftware version="8.2  20201204">EMPYREAN</instrumentControlSoftware>
					<instrumentID>0000000011260721</instrumentID>
				</source>
			</header>
			<dataPoints>
				<positions axis="2Theta" unit="deg">
					<startPosition>77.5398152930555</startPosition>
					<endPosition>80.887085064272</endPosition>
				</positions>
				<positions axis="Omega" unit="deg">
					<commonPosition>20.9642250893319</commonPosition>
				</positions>
				<positions axis="Phi" unit="deg">
					<commonPosition>-267.92</commonPosition>
				</positions>
				<positions axis="Chi" unit="deg">
					<commonPosition>0</commonPosition>
				</positions>
				<positions axis="Z" unit="mm">
					<commonPosition>8.391</commonPosition>
				</positions>
				<commonCountingTime unit="seconds">0.974</commonCountingTime>
				<counts unit="counts">0 0 0 0 0 0 0 2 1 0 0 1 0 1 1 0 0 0 1 0 1 1 0 1 1 0 0 0 0 0 0 0 2 0 1 0 0 2 0 0 0 3 0 1 2 0 0 0 1 0 0 0 1 0 0 1 0 0 1 1 1 0 0 0 0 1 0 0 1 1 1 1 0 0 0 0 0 0 0 0 0 0 1 0 1 1 1 0 0 0 1 0 0 0 0 0 1 2 0 0 0 0 0 1 0 0 0 1 1 0 0 0 0 1 0 1 0 0 0 0 0 0 0 0 0 0 0 1 0 0 1 0 1 2 0 0 0 1 1 1 1 0 0 0 0 0 0 0 0 0 1 0 0 0 1 0 1 0 0 0 0 0 0 1 1 1 0 0 1 0 2 1 0 0 0 0 0 0 0 0 0 0 1 1 0 0 0 1 0 1 0 0 0 0 0 0 0 0 0 0 0 0 1 0 1 0 0 0 1 1 0 0 1 1 0 0 0 1 0 1 0 1 0 2 1 0 0 0 0 0 1 0 1 0 0 0 0 0 0 0 2 1 0 0 1 1 2 1 0 0 1 0 0 0 1</counts>
			</dataPoints>
		</scan>
		<scan status="Completed" appendNumber="0" scanAxis="2Theta" mode="Continuous">
			<header>
				<startTimeStamp>2024-07-05T13:46:22-04:00</startTimeStamp>
				<endTimeStamp>2024-07-05T14:16:20-04:00</endTimeStamp>
				<author>
					<name>lw627</name>
				</author>
				<source>
					<applicationSoftware version="7.1">Data Collector</applicationSoftware>
					<instrumentControlSoftware version="8.2  20201204">EMPYREAN</instrumentControlSoftware>
					<instrumentID>0000000011260721</instrumentID>
				</source>
			</header>
			<dataPoints>
				<positions axis="2Theta" unit="deg">
					<startPosition>77.5430978637236</startPosition>
					<endPosition>80.8903676349401</endPosition>
				</positions>
				<positions axis="Omega" unit="deg">
					<commonPosition>20.9658663746659</commonPosition>
				</positions>
				<positions axis="Phi" unit="deg">
					<commonPosition>-267.92</commonPosition>
				</positions>
				<positions axis="Chi" unit="deg">
					<commonPosition>0</commonPosition>
				</positions>
				<positions axis="Z" unit="mm">
					<commonPosition>8.391</commonPosition>
				</positions>
				<commonCountingTime unit="seconds">0.974</commonCountingTime>
				<counts unit="counts">0 1 0 0 1 0 0 0 0 2 0 0 1 0 1 0 0 0 0 0 0 1 2 0 1 1 0 0 2 2 1 1 0 1 0 1 0 0 0 0 0 1 0 0 1 0 1 0 0 2 0 0 2 1 0 0 1 0 1 0 0 0 1 0 0 0 1 0 4 0 0 0 0 0 0 1 0 0 0 0 1 0 0 0 1 0 0 1 0 0 0 0 0 0 0 0 0 0 0 0 0 0 0 0 1 0 0 2 0 0 0 0 0 0 0 1 0 0 1 0 0 0 0 0 1 0 0 0 0 0 1 0 0 0 0 0 0 0 0 0 1 0 0 1 0 0 0 0 2 0 0 0 0 0 0 0 0 1 0 0 0 0 0 0 0 1 1 0 0 0 0 0 0 0 0 0 0 0 0 0 0 0 0 0 0 0 0 0 0 0 0 0 0 1 0 1 1 0 0 1 1 0 2 0 0 0 0 0 0 0 0 1 0 0 0 0 1 0 0 0 0 0 0 0 0 0 0 0 0 0 0 0 0 0 0 0 0 0 0 0 0 0 0 1 0 0 0 1 1 0 0 1 0 0 1</counts>
			</dataPoints>
		</scan>
		<scan status="Completed" appendNumber="0" scanAxis="2Theta" mode="Continuous">
			<header>
				<startTimeStamp>2024-07-05T13:46:22-04:00</startTimeStamp>
				<endTimeStamp>2024-07-05T14:16:20-04:00</endTimeStamp>
				<author>
					<name>lw627</name>
				</author>
				<source>
					<applicationSoftware version="7.1">Data Collector</applicationSoftware>
					<instrumentControlSoftware version="8.2  20201204">EMPYREAN</instrumentControlSoftware>
					<instrumentID>0000000011260721</instrumentID>
				</source>
			</header>
			<dataPoints>
				<positions axis="2Theta" unit="deg">
					<startPosition>77.5463804343918</startPosition>
					<endPosition>80.8936502056082</endPosition>
				</positions>
				<positions axis="Omega" unit="deg">
					<commonPosition>20.96750766</commonPosition>
				</positions>
				<positions axis="Phi" unit="deg">
					<commonPosition>-267.92</commonPosition>
				</positions>
				<positions axis="Chi" unit="deg">
					<commonPosition>0</commonPosition>
				</positions>
				<positions axis="Z" unit="mm">
					<commonPosition>8.391</commonPosition>
				</positions>
				<commonCountingTime unit="seconds">0.974</commonCountingTime>
				<counts unit="counts">0 0 0 0 0 1 0 2 0 0 0 1 0 0 0 0 1 1 0 1 1 1 0 0 1 0 0 0 1 0 0 1 0 1 0 1 1 0 2 0 0 1 0 1 0 1 0 0 1 1 0 2 1 0 2 0 0 2 2 0 1 0 0 0 0 0 0 0 0 0 0 0 0 0 0 0 0 0 0 1 0 0 0 0 0 0 0 1 0 0 0 0 0 0 0 0 0 0 0 0 1 1 0 1 0 0 0 1 0 0 0 0 1 1 0 0 0 1 0 0 0 0 1 0 0 1 1 0 0 1 0 0 0 0 0 0 0 0 0 1 0 0 0 1 1 0 0 0 0 0 0 0 0 1 0 0 1 0 0 1 0 0 0 0 0 1 0 0 0 0 0 1 0 0 0 0 0 0 2 1 1 0 0 0 0 0 0 0 0 0 0 1 0 0 0 0 0 0 0 0 0 0 1 0 0 0 0 0 0 0 0 0 0 1 0 0 0 0 0 0 0 1 2 0 0 0 0 0 0 0 0 0 1 0 0 0 0 0 0 0 0 0 0 0 0 0 0 0 0 0 0 0 0 1 0</counts>
			</dataPoints>
		</scan>
	</xrdMeasurement>
</xrdMeasurements>