File: data/XRD_RSM/YY189_RSM_240 332 420/YY189_RSM 420 slow.xrdml
<?xml version="1.0" encoding="utf-8"?>
<xrdMeasurements xmlns="http://www.xrdml.com/XRDMeasurement/2.2" xmlns:xsi="http://www.w3.org/2001/XMLSchema-instance" xsi:schemaLocation="http://www.xrdml.com/XRDMeasurement/2.2 http://www.xrdml.com/XRDMeasurement/2.2/XRDMeasurement.xsd" status="Completed">
	<comment>
		<entry>Configuration=3-axes Cradle_Reflection, Owner=User, Creation date=9/2/2021 3:55:24 PM</entry>
		<entry>Goniometer=Theta/Theta; Minimum step size 2Theta:0.0001; Minimum step size Omega:0.0001</entry>
		<entry>Sample stage=Chi-Phi-z stage 240 mm (reflection); Minimum step size Phi:0.01; Minimum step size Chi:0.01; Minimum step size Z:0.001</entry>
		<entry>Diffractometer system=EMPYREAN</entry>
		<entry>Measurement program=C:\PANalytical\Data Collector\Programs\Yu Yun\RSM\RSM 2degree_high resolution_ultra slow.xrdmp, Identifier={E7FADADD-DC24-46CD-AE09-8DCC8F7825B3}</entry>
	</comment>
	<sample type="To be analyzed">
		<id/>
		<name/>
		<preparedBy/>
	</sample>
	<xrdMeasurement status="Completed" measurementType="Area measurement" measurementStepAxis="Omega-2Theta" sampleMode="Reflection">
		<comment>
			<entry>PHD Lower Level = 4.02 (keV), PHD Upper Level = 11.26 (keV)</entry>
		</comment>
		<usedWavelength intended="K-Alpha">
			<kAlpha1 unit="Angstrom">1.5405980</kAlpha1>
			<kAlpha2 unit="Angstrom">1.5444260</kAlpha2>
			<kBeta unit="Angstrom">1.3922500</kBeta>
			<ratioKAlpha2KAlpha1>0</ratioKAlpha2KAlpha1>
		</usedWavelength>
		<incidentBeamPath>
			<radius unit="mm">240.00</radius>
			<xRayTube id="1010048" name="Empyrean Cu LFF HR (9430 033 7310x) DK432574">
				<tension unit="kV">45.0</tension>
				<current unit="mA">40.0</current>
				<anodeMaterial>Cu</anodeMaterial>
				<focus type="Line">
					<length unit="mm">12.0</length>
					<width unit="mm">0.4</width>
					<takeOffAngle unit="deg">4.4</takeOffAngle>
				</focus>
			</xRayTube>
			<xRayMirror xsi:type="xRayMirrorType" id="27080001" name="Inc. Beam Cu W/Si (hybrid MPD)" hybrid="true">
				<crystal type="Graded" shape="Parabolic">W/Si</crystal>
				<acceptanceAngle unit="deg">0.800</acceptanceAngle>
				<length unit="mm">55.3</length>
			</xRayMirror>
			<monochromator xsi:type="monochromatorType" id="23090002" name="Hybrid monochr. 2xGe220 Cu asym." hybrid="true">
				<crystal type="Asymmetric" shape="Flat">Ge</crystal>
				<numberOfReflections>2</numberOfReflections>
				<hkl>
					<h>2</h>
					<k>2</k>
					<l>0</l>
				</hkl>
			</monochromator>
			<mask xsi:type="maskType" id="22030008" name="Fixed mask 4 mm">
				<distanceToSample unit="mm">171.00</distanceToSample>
				<width unit="mm">4.00</width>
			</mask>
			<divergenceSlit xsi:type="fixedDivergenceSlitType" id="22010007" name="Fixed slit 1/8°">
				<distanceToSample unit="mm">179.30</distanceToSample>
				<height unit="mm">0.19</height>
			</divergenceSlit>
		</incidentBeamPath>
		<diffractedBeamPath>
			<radius unit="mm">240.00</radius>
			<antiScatterSlit xsi:type="fixedAntiScatterSlitType" id="22060009" name="Programmable anti-scatter slit">
				<angle unit="deg">4</angle>
			</antiScatterSlit>
			<detector xsi:type="areaDetectorType" id="7010020" name="PIXcel3D-Medipix3 1x1 detector">
				<phd unit="%">
					<lowerLevel>25</lowerLevel>
					<upperLevel>70</upperLevel>
				</phd>
				<mode>Scanning snapshot equatorial</mode>
				<activeChannelsEquatorial>255</activeChannelsEquatorial>
				<activeChannelsAxial>255</activeChannelsAxial>
				<pitchEquatorial unit="mm">0.05500</pitchEquatorial>
				<pitchAxial unit="mm">0.05500</pitchAxial>
				<readOutPeriod unit="seconds">0.790</readOutPeriod>
			</detector>
		</diffractedBeamPath>
		<scan status="Completed" appendNumber="0" scanAxis="2Theta" mode="Continuous">
			<header>
				<startTimeStamp>2023-01-13T17:58:27-05:00</startTimeStamp>
				<endTimeStamp>2023-01-13T18:14:40-05:00</endTimeStamp>
				<author>
					<name>User</name>
				</author>
				<source>
					<applicationSoftware version="7.1">Data Collector</applicationSoftware>
					<instrumentControlSoftware version="8.2  20201204">EMPYREAN</instrumentControlSoftware>
					<instrumentID>0000000011260721</instrumentID>
				</source>
			</header>
			<dataPoints>
				<positions axis="2Theta" unit="deg">
					<startPosition>70.8716063943918</startPosition>
					<endPosition>74.2188761656082</endPosition>
				</positions>
				<positions axis="Omega" unit="deg">
					<commonPosition>17.84612064</commonPosition>
				</positions>
				<positions axis="Phi" unit="deg">
					<commonPosition>3.6</commonPosition>
				</positions>
				<positions axis="Chi" unit="deg">
					<commonPosition>0</commonPosition>
				</positions>
				<positions axis="Z" unit="mm">
					<commonPosition>8.428</commonPosition>
				</positions>
				<commonCountingTime unit="seconds">0.784</commonCountingTime>
				<counts unit="counts">0 0 0 0 0 0 1 0 0 0 0 1 1 0 1 0 0 0 0 0 1 0 1 0 0 0 0 0 0 0 0 0 0 0 0 0 1 1 0 0 0 0 1 0 0 1 0 1 0 1 2 0 0 0 1 0 0 0 1 0 0 1 0 0 1 0 0 0 1 0 0 1 0 0 0 0 0 1 1 0 0 0 1 1 0 0 0 2 1 0 0 0 0 2 0 0 0 0 0 0 0 0 0 0 0 0 0 1 1 0 0 0 0 0 2 0 2 0 0 0 0 1 2 1 0 0 0 0 0 1 0 1 0 0 1 0 0 1 0 0 0 1 1 2 0 1 0 0 1 0 0 1 2 0 0 0 0 0 0 2 0 0 0 0 0 1 0 0 1 0 0 0 1 2 3 2 2 1 1 1 0 0 0 0 0 0 0 0 0 0 0 1 0 0 1 0 2 1 2 0 0 0 0 0 0 0 1 0 1 0 0 1 0 0 1 0 1 0 0 0 1 0 0 0 1 0 0 0 0 0 0 0 1 0 0 0 0 0 4 2 0 0 0 1 0 0 0 0 0 0 0 1 2 1 1</counts>
			</dataPoints>
		</scan>
		<scan status="Completed" appendNumber="0" scanAxis="2Theta" mode="Continuous">
			<header>
				<startTimeStamp>2023-01-13T17:58:27-05:00</startTimeStamp>
				<endTimeStamp>2023-01-13T18:14:40-05:00</endTimeStamp>
				<author>
					<name>User</name>
				</author>
				<source>
					<applicationSoftware version="7.1">Data Collector</applicationSoftware>
					<instrumentControlSoftware version="8.2  20201204">EMPYREAN</instrumentControlSoftware>
					<instrumentID>0000000011260721</instrumentID>
				</source>
			</header>
			<dataPoints>
				<positions axis="2Theta" unit="deg">
					<startPosition>70.8748889650661</startPosition>
					<endPosition>74.2221587362826</endPosition>
				</positions>
				<positions axis="Omega" unit="deg">
					<commonPosition>17.8477619253372</commonPosition>
				</positions>
				<positions axis="Phi" unit="deg">
					<commonPosition>3.6</commonPosition>
				</positions>
				<positions axis="Chi" unit="deg">
					<commonPosition>0</commonPosition>
				</positions>
				<positions axis="Z" unit="mm">
					<commonPosition>8.428</commonPosition>
				</positions>
				<commonCountingTime unit="seconds">0.784</commonCountingTime>
				<counts unit="counts">0 1 0 0 0 1 0 0 0 0 0 1 1 0 0 1 0 1 0 1 0 0 0 0 0 0 0 2 0 0 1 1 1 1 0 1 0 0 1 0 0 0 0 0 0 0 0 2 0 0 0 0 1 0 0 1 0 0 1 0 0 0 0 0 0 0 0 0 0 0 0 0 0 0 0 0 0 1 0 1 0 0 0 0 0 0 0 0 0 0 1 0 0 0 0 0 0 2 0 0 0 1 0 0 0 0 0 0 0 0 1 0 0 1 1 2 0 0 1 2 0 0 0 1 0 0 0 0 2 0 0 0 0 3 0 1 1 0 0 0 0 0 0 0 0 0 0 0 1 0 0 0 0 0 0 0 0 0 0 0 0 1 0 0 1 1 0 1 2 1 0 2 0 4 3 1 1 1 0 0 0 0 0 0 0 1 0 0 2 1 0 2 0 1 1 1 0 0 0 1 0 0 1 2 0 0 1 0 1 0 0 1 2 0 1 1 0 0 0 0 0 1 0 0 1 1 0 0 0 0 0 0 0 0 0 0 0 1 1 1 0 0 0 0 0 0 0 0 0 2 0 1 0 0 0</counts>
			</dataPoints>
		</scan>
		<scan status="Completed" appendNumber="0" scanAxis="2Theta" mode="Continuous">
			<header>
				<startTimeStamp>2023-01-13T17:58:27-05:00</startTimeStamp>
				<endTimeStamp>2023-01-13T18:14:40-05:00</endTimeStamp>
				<author>
					<name>User</name>
				</author>
				<source>
					<applicationSoftware version="7.1">Data Collector</applicationSoftware>
					<instrumentControlSoftware version="8.2  20201204">EMPYREAN</instrumentControlSoftware>
					<instrumentID>0000000011260721</instrumentID>
				</source>
			</header>
			<dataPoints>
				<positions axis="2Theta" unit="deg">
					<startPosition>70.8781715357404</startPosition>
					<endPosition>74.2254413069569</endPosition>
				</positions>
				<positions axis="Omega" unit="deg">
					<commonPosition>17.8494032106743</commonPosition>
				</positions>
				<positions axis="Phi" unit="deg">
					<commonPosition>3.6</commonPosition>
				</positions>
				<positions axis="Chi" unit="deg">
					<commonPosition>0</commonPosition>
				</positions>
				<positions axis="Z" unit="mm">
					<commonPosition>8.428</commonPosition>
				</positions>
				<commonCountingTime unit="seconds">0.784</commonCountingTime>
				<counts unit="counts">0 0 2 1 0 0 1 0 0 1 0 1 1 0 0 0 0 0 1 0 0 0 0 0 0 0 0 0 0 0 1 1 0 1 0 0 0 0 0 0 1 0 1 0 2 0 1 0 0 0 0 0 0 0 1 1 0 0 0 2 0 0 0 0 0 0 0 0 0 0 0 0 0 1 0 0 0 1 0 0 0 0 0 2 0 0 0 0 0 0 0 0 1 1 0 0 0 0 0 1 0 0 0 1 1 0 0 0 0 0 1 0 0 0 2 0 0 0 0 1 0 0 0 0 0 0 1 2 0 0 0 1 4 0 0 0 0 0 0 0 1 0 0 0 0 0 0 0 0 0 0 0 0 0 0 1 1 0 0 0 0 0 2 0 1 0 1 0 0 2 0 0 1 4 1 1 0 0 0 1 0 0 0 1 0 1 0 0 0 0 1 0 0 1 0 0 0 0 1 0 0 0 0 0 0 0 0 0 0 1 1 2 0 0 1 0 1 1 1 1 0 0 0 0 0 1 0 0 0 0 0 2 0 0 0 0 1 1 0 1 0 0 0 0 0 1 0 0 1 0 1 0 0 1 0</counts>
			</dataPoints>
		</scan>
		<scan status="Completed" appendNumber="0" scanAxis="2Theta" mode="Continuous">
			<header>
				<startTimeStamp>2023-01-13T17:58:27-05:00</startTimeStamp>
				<endTimeStamp>2023-01-13T18:14:40-05:00</endTimeStamp>
				<author>
					<name>User</name>
				</author>
				<source>
					<applicationSoftware version="7.1">Data Collector</applicationSoftware>
					<instrumentControlSoftware version="8.2  20201204">EMPYREAN</instrumentControlSoftware>
					<instrumentID>0000000011260721</instrumentID>
				</source>
			</header>
			<dataPoints>
				<positions axis="2Theta" unit="deg">
					<startPosition>70.8814541064148</startPosition>
					<endPosition>74.2287238776313</endPosition>
				</positions>
				<positions axis="Omega" unit="deg">
					<commonPosition>17.8510444960115</commonPosition>
				</positions>
				<positions axis="Phi" unit="deg">
					<commonPosition>3.6</commonPosition>
				</positions>
				<positions axis="Chi" unit="deg">
					<commonPosition>0</commonPosition>
				</positions>
				<positions axis="Z" unit="mm">
					<commonPosition>8.428</commonPosition>
				</positions>
				<commonCountingTime unit="seconds">0.784</commonCountingTime>
				<counts unit="counts">2 0 0 0 0 0 0 1 0 0 0 1 0 0 0 0 0 0 0 1 0 0 0 0 0 0 0 0 0 1 0 0 1 1 0 0 0 1 0 0 0 0 0 0 1 0 0 0 0 0 0 1 1 0 1 2 0 0 0 0 1 1 1 0 2 0 1 0 1 0 0 0 0 0 0 0 2 0 2 0 1 0 0 0 0 0 1 0 0 0 1 0 0 0 0 0 0 0 0 0 0 0 0 0 1 0 0 0 0 0 0 0 1 0 1 1 0 1 0 0 0 1 0 0 1 1 1 0 0 0 0 1 0 0 0 0 0 1 0 0 0 0 0 0 0 0 0 1 1 0 1 0 1 0 1 0 0 0 1 0 0 1 0 0 0 0 0 0 0 0 2 0 0 4 1 0 2 0 0 2 0 0 0 0 0 0 0 0 0 1 0 0 1 1 1 0 0 0 0 2 1 0 0 1 0 0 0 2 0 0 1 0 0 1 0 1 0 0 0 0 0 2 0 0 0 0 0 0 1 0 1 2 1 0 0 0 0 1 1 0 0 0 0 2 2 0 0 0 0 1 0 0 0 0 3</counts>
			</dataPoints>
		</scan>
		<scan status="Completed" appendNumber="0" scanAxis="2Theta" mode="Continuous">
			<header>
				<startTimeStamp>2023-01-13T17:58:27-05:00</startTimeStamp>
				<endTimeStamp>2023-01-13T18:14:40-05:00</endTimeStamp>
				<author>
					<name>User</name>
				</author>
				<source>
					<applicationSoftware version="7.1">Data Collector</applicationSoftware>
					<instrumentControlSoftware version="8.2  20201204">EMPYREAN</instrumentControlSoftware>
					<instrumentID>0000000011260721</instrumentID>
				</source>
			</header>
			<dataPoints>
				<positions axis="2Theta" unit="deg">
					<startPosition>70.8847366770891</startPosition>
					<endPosition>74.2320064483056</endPosition>
				</positions>
				<positions axis="Omega" unit="deg">
					<commonPosition>17.8526857813487</commonPosition>
				</positions>
				<positions axis="Phi" unit="deg">
					<commonPosition>3.6</commonPosition>
				</positions>
				<positions axis="Chi" unit="deg">
					<commonPosition>0</commonPosition>
				</positions>
				<positions axis="Z" unit="mm">
					<commonPosition>8.428</commonPosition>
				</positions>
				<commonCountingTime unit="seconds">0.784</commonCountingTime>
				<counts unit="counts">0 0 0 0 0 0 1 0 0 1 1 0 0 2 0 1 0 0 1 0 0 0 1 1 0 0 0 0 0 0 0 0 0 0 0 0 0 1 1 1 0 0 1 0 0 1 0 0 1 1 1 0 0 0 1 0 1 0 1 0 0 1 0 0 0 0 3 1 0 0 0 0 0 1 0 0 1 0 0 0 1 0 0 0 0 0 0 0 0 0 1 1 0 1 0 0 0 2 1 0 1 0 1 0 0 0 0 1 0 0 0 0 0 0 1 0 0 0 0 1 0 0 0 0 0 0 0 2 0 0 0 0 1 0 0 0 0 0 0 0 0 0 0 0 0 0 1 1 0 1 0 1 0 0 0 1 0 0 0 0 1 0 0 0 2 1 1 0 1 1 2 2 0 4 3 1 0 0 1 1 1 0 1 0 0 3 1 2 0 1 0 0 0 0 2 0 0 0 0 0 0 1 0 0 1 0 1 0 1 0 2 0 1 1 0 0 0 1 0 0 0 0 2 0 1 0 1 0 0 0 0 1 0 0 0 0 0 0 0 0 1 0 1 0 0 1 1 0 0 2 1 0 1 0 0</counts>
			</dataPoints>
		</scan>
		<scan status="Completed" appendNumber="0" scanAxis="2Theta" mode="Continuous">
			<header>
				<startTimeStamp>2023-01-13T17:58:27-05:00</startTimeStamp>
				<endTimeStamp>2023-01-13T18:14:40-05:00</endTimeStamp>
				<author>
					<name>User</name>
				</author>
				<source>
					<applicationSoftware version="7.1">Data Collector</applicationSoftware>
					<instrumentControlSoftware version="8.2  20201204">EMPYREAN</instrumentControlSoftware>
					<instrumentID>0000000011260721</instrumentID>
				</source>
			</header>
			<dataPoints>
				<positions axis="2Theta" unit="deg">
					<startPosition>70.8880192477635</startPosition>
					<endPosition>74.23528901898</endPosition>
				</positions>
				<positions axis="Omega" unit="deg">
					<commonPosition>17.8543270666859</commonPosition>
				</positions>
				<positions axis="Phi" unit="deg">
					<commonPosition>3.6</commonPosition>
				</positions>
				<positions axis="Chi" unit="deg">
					<commonPosition>0</commonPosition>
				</positions>
				<positions axis="Z" unit="mm">
					<commonPosition>8.428</commonPosition>
				</positions>
				<commonCountingTime unit="seconds">0.784</commonCountingTime>
				<counts unit="counts">0 0 0 0 0 0 0 0 0 1 0 1 0 0 1 0 0 0 0 2 0 0 0 0 0 1 0 0 0 0 2 0 0 0 0 0 1 0 2 1 0 0 1 1 0 0 0 0 0 1 0 0 1 0 0 0 0 1 0 0 0 0 0 1 0 0 0 1 0 0 0 2 0 0 0 0 0 1 0 0 0 1 1 0 0 0 0 1 1 0 1 0 1 0 0 0 0 0 0 0 0 0 1 0 0 0 0 0 0 0 1 1 0 1 0 0 0 1 0 0 0 0 0 0 1 0 0 0 0 0 0 0 1 1 0 0 1 0 1 0 0 0 0 0 0 0 0 0 1 0 1 1 0 0 0 0 0 2 0 1 0 3 0 1 1 0 0 0 3 2 1 1 2 3 4 1 0 0 0 0 0 0 0 0 1 0 1 0 0 1 1 0 0 0 0 0 0 0 0 0 0 1 0 1 1 0 2 1 0 1 1 0 1 1 1 0 0 0 0 0 0 1 1 0 0 0 0 0 1 0 0 0 0 0 0 1 0 0 0 1 3 0 0 0 0 0 0 0 0 0 0 0 1 1 1</counts>
			</dataPoints>
		</scan>
		<scan status="Completed" appendNumber="0" scanAxis="2Theta" mode="Continuous">
			<header>
				<startTimeStamp>2023-01-13T17:58:27-05:00</startTimeStamp>
				<endTimeStamp>2023-01-13T18:14:40-05:00</endTimeStamp>
				<author>
					<name>User</name>
				</author>
				<source>
					<applicationSoftware version="7.1">Data Collector</applicationSoftware>
					<instrumentControlSoftware version="8.2  20201204">EMPYREAN</instrumentControlSoftware>
					<instrumentID>0000000011260721</instrumentID>
				</source>
			</header>
			<dataPoints>
				<positions axis="2Theta" unit="deg">
					<startPosition>70.8913018184378</startPosition>
					<endPosition>74.2385715896543</endPosition>
				</positions>
				<positions axis="Omega" unit="deg">
					<commonPosition>17.855968352023</commonPosition>
				</positions>
				<positions axis="Phi" unit="deg">
					<commonPosition>3.6</commonPosition>
				</positions>
				<positions axis="Chi" unit="deg">
					<commonPosition>0</commonPosition>
				</positions>
				<positions axis="Z" unit="mm">
					<commonPosition>8.428</commonPosition>
				</positions>
				<commonCountingTime unit="seconds">0.784</commonCountingTime>
				<counts unit="counts">0 1 1 1 0 1 0 1 0 1 0 3 0 1 1 0 0 1 0 1 0 0 0 0 1 0 0 0 0 0 0 1 0 0 0 0 0 1 3 0 0 1 0 1 0 0 0 0 0 0 0 0 0 0 0 1 0 1 0 1 1 0 0 1 0 0 0 0 1 1 0 0 0 0 0 0 1 0 0 0 1 0 0 1 0 2 1 0 0 1 1 0 1 2 1 1 0 0 1 1 1 1 0 0 0 0 0 0 1 1 0 0 0 0 0 0 0 0 0 1 1 0 0 1 2 0 0 1 1 0 0 0 0 0 0 0 2 0 1 1 0 0 1 1 0 0 1 0 0 0 0 0 1 0 0 0 0 1 0 0 0 0 0 0 0 0 0 0 0 0 2 3 1 4 1 1 0 0 0 0 1 2 1 1 1 0 0 0 1 0 0 0 0 0 0 0 1 0 0 0 0 0 0 1 0 0 0 0 0 0 0 0 0 1 0 0 0 0 0 0 0 2 1 0 0 0 0 0 0 0 0 2 1 0 1 0 1 0 0 0 0 0 1 0 2 0 0 0 0 0 1 0 0 0 0</counts>
			</dataPoints>
		</scan>
		<scan status="Completed" appendNumber="0" scanAxis="2Theta" mode="Continuous">
			<header>
				<startTimeStamp>2023-01-13T17:58:27-05:00</startTimeStamp>
				<endTimeStamp>2023-01-13T18:14:40-05:00</endTimeStamp>
				<author>
					<name>User</name>
				</author>
				<source>
					<applicationSoftware version="7.1">Data Collector</applicationSoftware>
					<instrumentControlSoftware version="8.2  20201204">EMPYREAN</instrumentControlSoftware>
					<instrumentID>0000000011260721</instrumentID>
				</source>
			</header>
			<dataPoints>
				<positions axis="2Theta" unit="deg">
					<startPosition>70.8945843891122</startPosition>
					<endPosition>74.2418541603286</endPosition>
				</positions>
				<positions axis="Omega" unit="deg">
					<commonPosition>17.8576096373602</commonPosition>
				</positions>
				<positions axis="Phi" unit="deg">
					<commonPosition>3.6</commonPosition>
				</positions>
				<positions axis="Chi" unit="deg">
					<commonPosition>0</commonPosition>
				</positions>
				<positions axis="Z" unit="mm">
					<commonPosition>8.428</commonPosition>
				</positions>
				<commonCountingTime unit="seconds">0.784</commonCountingTime>
				<counts unit="counts">0 0 0 0 0 0 0 1 0 0 2 0 1 1 0 0 0 0 0 2 1 0 0 0 1 0 0 1 0 0 0 0 0 0 1 0 0 1 2 0 0 0 1 1 0 1 0 0 0 0 1 0 0 0 1 0 0 1 0 0 0 0 0 1 0 0 1 0 0 0 0 0 2 3 0 0 0 1 0 0 1 0 0 0 1 0 0 1 0 0 0 0 0 0 1 0 0 1 0 0 0 0 0 1 2 0 1 0 0 0 0 0 1 0 1 2 0 0 0 0 1 0 0 0 0 0 0 0 0 1 1 0 0 0 0 1 1 0 0 0 0 1 0 0 1 0 0 0 0 0 0 2 1 0 0 0 0 1 0 1 2 2 0 2 0 0 0 0 0 0 1 2 4 2 5 2 0 0 0 1 0 1 2 1 1 1 1 0 0 0 0 0 0 0 0 0 0 0 0 1 0 0 0 0 1 0 0 0 0 0 0 0 1 0 1 2 0 0 0 0 0 0 4 1 0 0 0 0 1 0 0 1 1 0 2 1 2 0 0 0 0 2 0 0 0 1 0 0 0 1 0 0 1 0 0</counts>
			</dataPoints>
		</scan>
		<scan status="Completed" appendNumber="0" scanAxis="2Theta" mode="Continuous">
			<header>
				<startTimeStamp>2023-01-13T17:58:27-05:00</startTimeStamp>
				<endTimeStamp>2023-01-13T18:14:40-05:00</endTimeStamp>
				<author>
					<name>User</name>
				</author>
				<source>
					<applicationSoftware version="7.1">Data Collector</applicationSoftware>
					<instrumentControlSoftware version="8.2  20201204">EMPYREAN</instrumentControlSoftware>
					<instrumentID>0000000011260721</instrumentID>
				</source>
			</header>
			<dataPoints>
				<positions axis="2Theta" unit="deg">
					<startPosition>70.8978669597865</startPosition>
					<endPosition>74.245136731003</endPosition>
				</positions>
				<positions axis="Omega" unit="deg">
					<commonPosition>17.8592509226974</commonPosition>
				</positions>
				<positions axis="Phi" unit="deg">
					<commonPosition>3.6</commonPosition>
				</positions>
				<positions axis="Chi" unit="deg">
					<commonPosition>0</commonPosition>
				</positions>
				<positions axis="Z" unit="mm">
					<commonPosition>8.428</commonPosition>
				</positions>
				<commonCountingTime unit="seconds">0.784</commonCountingTime>
				<counts unit="counts">0 0 0 2 1 0 2 0 0 0 1 0 0 0 0 0 2 0 0 0 1 0 0 0 0 0 0 0 0 1 0 0 0 0 0 0 0 0 1 1 1 1 1 0 0 0 0 0 0 0 2 0 1 0 0 0 2 2 0 0 2 1 0 0 1 0 0 0 0 3 1 0 1 0 1 0 0 1 0 0 0 0 0 1 0 0 0 0 1 0 0 1 1 0 0 0 0 0 0 0 0 0 0 0 0 3 0 0 1 2 0 1 1 1 0 0 0 0 0 0 0 0 0 0 1 1 2 1 0 1 0 0 0 0 0 0 0 1 0 0 0 0 0 0 1 0 0 0 1 0 0 0 0 0 0 0 0 0 0 0 0 1 0 0 0 0 0 1 0 0 1 1 6 2 0 1 0 0 0 0 0 0 0 0 1 2 0 1 0 1 1 0 0 0 0 1 0 0 0 1 0 0 2 1 0 0 0 0 2 0 0 0 0 1 0 0 2 0 1 0 0 2 0 0 0 0 0 1 0 0 1 1 1 0 0 0 0 0 0 0 0 0 0 1 0 0 0 0 0 0 1 0 1 0 0</counts>
			</dataPoints>
		</scan>
		<scan status="Completed" appendNumber="0" scanAxis="2Theta" mode="Continuous">
			<header>
				<startTimeStamp>2023-01-13T17:58:27-05:00</startTimeStamp>
				<endTimeStamp>2023-01-13T18:14:40-05:00</endTimeStamp>
				<author>
					<name>User</name>
				</author>
				<source>
					<applicationSoftware version="7.1">Data Collector</applicationSoftware>
					<instrumentControlSoftware version="8.2  20201204">EMPYREAN</instrumentControlSoftware>
					<instrumentID>0000000011260721</instrumentID>
				</source>
			</header>
			<dataPoints>
				<positions axis="2Theta" unit="deg">
					<startPosition>70.9011495304608</startPosition>
					<endPosition>74.2484193016773</endPosition>
				</positions>
				<positions axis="Omega" unit="deg">
					<commonPosition>17.8608922080345</commonPosition>
				</positions>
				<positions axis="Phi" unit="deg">
					<commonPosition>3.6</commonPosition>
				</positions>
				<positions axis="Chi" unit="deg">
					<commonPosition>0</commonPosition>
				</positions>
				<positions axis="Z" unit="mm">
					<commonPosition>8.428</commonPosition>
				</positions>
				<commonCountingTime unit="seconds">0.784</commonCountingTime>
				<counts unit="counts">0 0 1 0 0 0 1 0 1 0 0 0 0 0 0 0 0 1 0 0 0 0 0 0 0 0 0 1 0 0 0 0 0 1 1 1 0 1 1 0 1 1 0 0 0 0 0 1 0 0 0 1 0 0 0 0 0 1 0 1 0 2 1 0 0 0 0 0 1 0 1 2 0 0 0 1 2 0 1 0 1 1 2 0 0 1 0 0 0 0 1 0 0 0 0 2 0 0 0 0 1 1 0 0 1 1 1 0 0 0 0 0 1 0 0 0 0 2 0 0 0 0 0 0 0 0 0 0 0 0 1 0 0 0 0 1 0 0 1 0 2 1 0 0 0 0 0 0 0 0 0 0 1 0 1 0 1 0 0 1 0 0 0 0 1 0 0 0 0 1 2 3 3 5 2 1 1 1 0 0 0 1 1 1 1 0 1 1 0 0 2 0 1 1 1 0 0 0 0 0 0 0 1 2 1 0 0 0 0 0 1 0 0 0 0 0 0 0 0 1 0 2 0 1 0 0 0 1 0 1 0 0 0 1 0 0 2 1 0 1 1 1 1 0 0 0 1 0 1 0 1 0 1 0 0</counts>
			</dataPoints>
		</scan>
		<scan status="Completed" appendNumber="0" scanAxis="2Theta" mode="Continuous">
			<header>
				<startTimeStamp>2023-01-13T17:58:27-05:00</startTimeStamp>
				<endTimeStamp>2023-01-13T18:14:40-05:00</endTimeStamp>
				<author>
					<name>User</name>
				</author>
				<source>
					<applicationSoftware version="7.1">Data Collector</applicationSoftware>
					<instrumentControlSoftware version="8.2  20201204">EMPYREAN</instrumentControlSoftware>
					<instrumentID>0000000011260721</instrumentID>
				</source>
			</header>
			<dataPoints>
				<positions axis="2Theta" unit="deg">
					<startPosition>70.9044321011352</startPosition>
					<endPosition>74.2517018723517</endPosition>
				</positions>
				<positions axis="Omega" unit="deg">
					<commonPosition>17.8625334933717</commonPosition>
				</positions>
				<positions axis="Phi" unit="deg">
					<commonPosition>3.6</commonPosition>
				</positions>
				<positions axis="Chi" unit="deg">
					<commonPosition>0</commonPosition>
				</positions>
				<positions axis="Z" unit="mm">
					<commonPosition>8.428</commonPosition>
				</positions>
				<commonCountingTime unit="seconds">0.784</commonCountingTime>
				<counts unit="counts">0 0 0 0 0 0 2 1 0 0 0 0 0 0 0 0 0 0 2 0 0 0 0 0 0 0 0 0 0 1 0 0 0 0 0 0 1 0 0 0 0 0 0 0 1 0 0 1 0 0 0 0 0 0 1 0 0 1 0 0 1 1 0 0 0 0 0 0 0 1 0 0 0 2 0 0 3 0 1 0 0 0 0 0 0 0 0 0 2 0 1 0 0 2 0 0 2 0 0 0 0 0 1 1 0 1 0 0 2 0 0 0 0 0 0 0 0 0 0 1 0 0 0 1 0 1 0 0 0 0 2 0 0 0 1 1 0 0 0 1 2 1 0 0 0 0 0 0 0 1 0 0 0 0 0 0 0 0 0 1 1 0 0 1 0 1 0 1 3 1 2 2 4 0 1 0 0 2 1 1 0 1 1 1 2 0 0 1 0 0 0 0 0 0 2 0 0 0 0 0 0 2 0 0 0 0 2 0 0 0 0 0 0 0 0 0 1 1 1 1 0 0 0 1 2 0 0 1 0 0 0 1 2 0 0 0 1 0 0 0 0 0 0 1 0 2 0 2 0 0 0 1 2 0 0</counts>
			</dataPoints>
		</scan>
		<scan status="Completed" appendNumber="0" scanAxis="2Theta" mode="Continuous">
			<header>
				<startTimeStamp>2023-01-13T17:58:27-05:00</startTimeStamp>
				<endTimeStamp>2023-01-13T18:14:40-05:00</endTimeStamp>
				<author>
					<name>User</name>
				</author>
				<source>
					<applicationSoftware version="7.1">Data Collector</applicationSoftware>
					<instrumentControlSoftware version="8.2  20201204">EMPYREAN</instrumentControlSoftware>
					<instrumentID>0000000011260721</instrumentID>
				</source>
			</header>
			<dataPoints>
				<positions axis="2Theta" unit="deg">
					<startPosition>70.9077146718095</startPosition>
					<endPosition>74.254984443026</endPosition>
				</positions>
				<positions axis="Omega" unit="deg">
					<commonPosition>17.8641747787089</commonPosition>
				</positions>
				<positions axis="Phi" unit="deg">
					<commonPosition>3.6</commonPosition>
				</positions>
				<positions axis="Chi" unit="deg">
					<commonPosition>0</commonPosition>
				</positions>
				<positions axis="Z" unit="mm">
					<commonPosition>8.428</commonPosition>
				</positions>
				<commonCountingTime unit="seconds">0.784</commonCountingTime>
				<counts unit="counts">2 0 1 4 0 0 1 0 0 0 1 0 0 0 0 0 0 0 0 1 1 0 0 0 2 0 0 0 0 0 0 0 0 1 0 0 1 0 0 0 0 0 0 0 1 3 0 0 0 1 0 1 0 0 0 1 0 0 1 0 0 0 0 0 0 0 1 0 3 0 0 0 0 1 0 0 0 1 1 0 1 0 0 1 0 0 0 0 1 0 0 1 1 0 1 0 0 1 0 0 2 0 0 0 0 0 0 0 1 0 1 0 0 0 0 0 0 1 2 0 0 0 0 1 0 1 0 0 0 0 0 1 1 2 0 0 1 0 0 0 0 3 0 0 0 0 0 0 1 0 0 0 0 0 0 1 0 0 0 0 0 0 0 0 2 1 0 0 0 0 0 3 1 3 1 0 0 0 0 1 1 2 0 0 0 1 0 0 1 0 0 0 2 0 0 0 1 0 0 0 0 1 0 0 0 1 1 0 0 0 0 0 0 0 0 0 0 1 0 0 0 0 0 1 0 0 1 0 1 0 0 1 0 0 0 0 1 1 0 1 0 0 1 0 0 0 0 1 0 1 0 1 0 1 2</counts>
			</dataPoints>
		</scan>
		<scan status="Completed" appendNumber="0" scanAxis="2Theta" mode="Continuous">
			<header>
				<startTimeStamp>2023-01-13T17:58:27-05:00</startTimeStamp>
				<endTimeStamp>2023-01-13T18:14:40-05:00</endTimeStamp>
				<author>
					<name>User</name>
				</author>
				<source>
					<applicationSoftware version="7.1">Data Collector</applicationSoftware>
					<instrumentControlSoftware version="8.2  20201204">EMPYREAN</instrumentControlSoftware>
					<instrumentID>0000000011260721</instrumentID>
				</source>
			</header>
			<dataPoints>
				<positions axis="2Theta" unit="deg">
					<startPosition>70.9109972424839</startPosition>
					<endPosition>74.2582670137003</endPosition>
				</positions>
				<positions axis="Omega" unit="deg">
					<commonPosition>17.8658160640461</commonPosition>
				</positions>
				<positions axis="Phi" unit="deg">
					<commonPosition>3.6</commonPosition>
				</positions>
				<positions axis="Chi" unit="deg">
					<commonPosition>0</commonPosition>
				</positions>
				<positions axis="Z" unit="mm">
					<commonPosition>8.428</commonPosition>
				</positions>
				<commonCountingTime unit="seconds">0.784</commonCountingTime>
				<counts unit="counts">0 1 0 1 0 0 0 0 1 0 0 0 0 1 0 1 0 0 1 0 0 0 1 0 0 0 0 0 0 0 2 1 0 0 1 0 1 0 0 0 0 0 0 1 1 0 0 0 1 1 0 1 1 0 0 0 1 0 1 0 1 0 1 0 0 0 0 0 1 0 0 0 1 0 0 0 0 1 0 0 0 0 0 0 0 1 0 0 1 1 0 0 0 0 0 0 5 0 1 0 0 0 0 0 0 0 0 0 0 0 0 0 0 0 0 0 0 0 0 3 0 0 1 0 0 0 0 0 0 1 0 0 0 0 0 3 0 0 1 0 0 0 0 0 0 0 0 0 2 0 1 0 0 0 0 0 0 0 0 0 1 0 0 0 0 0 2 1 0 1 1 4 6 2 3 0 3 0 0 0 0 0 1 1 0 0 0 0 1 2 0 0 1 0 0 0 0 0 1 1 2 0 0 0 1 0 1 1 0 0 2 2 0 1 1 0 1 1 0 1 0 0 1 1 1 1 0 0 0 0 0 0 0 0 0 0 1 0 0 0 1 3 0 1 0 0 0 1 0 0 0 1 0 1 0</counts>
			</dataPoints>
		</scan>
		<scan status="Completed" appendNumber="0" scanAxis="2Theta" mode="Continuous">
			<header>
				<startTimeStamp>2023-01-13T17:58:27-05:00</startTimeStamp>
				<endTimeStamp>2023-01-13T18:14:40-05:00</endTimeStamp>
				<author>
					<name>User</name>
				</author>
				<source>
					<applicationSoftware version="7.1">Data Collector</applicationSoftware>
					<instrumentControlSoftware version="8.2  20201204">EMPYREAN</instrumentControlSoftware>
					<instrumentID>0000000011260721</instrumentID>
				</source>
			</header>
			<dataPoints>
				<positions axis="2Theta" unit="deg">
					<startPosition>70.9142798131582</startPosition>
					<endPosition>74.2615495843747</endPosition>
				</positions>
				<positions axis="Omega" unit="deg">
					<commonPosition>17.8674573493832</commonPosition>
				</positions>
				<positions axis="Phi" unit="deg">
					<commonPosition>3.6</commonPosition>
				</positions>
				<positions axis="Chi" unit="deg">
					<commonPosition>0</commonPosition>
				</positions>
				<positions axis="Z" unit="mm">
					<commonPosition>8.428</commonPosition>
				</positions>
				<commonCountingTime unit="seconds">0.784</commonCountingTime>
				<counts unit="counts">0 0 0 2 0 0 0 1 0 0 0 0 1 0 0 1 1 0 0 0 0 1 1 1 0 1 0 0 1 0 0 0 0 1 0 0 0 0 1 0 1 1 0 0 0 0 1 0 0 0 1 1 0 0 0 2 1 0 0 0 0 1 0 1 0 0 1 1 0 1 0 0 0 0 0 0 0 2 0 3 0 0 0 0 1 0 1 0 0 1 0 1 1 0 0 2 0 1 1 1 0 0 0 0 1 0 0 0 0 0 0 1 0 1 0 1 0 1 0 1 0 0 0 1 0 0 0 1 0 0 0 0 0 1 1 0 1 4 0 1 1 0 2 1 0 2 1 0 0 0 1 0 0 0 0 1 0 1 2 0 0 1 0 2 0 0 1 1 2 2 1 2 1 2 3 0 0 0 1 0 0 0 0 0 1 0 0 0 1 0 1 0 0 1 0 1 0 0 0 0 0 0 0 0 1 0 0 0 0 0 1 0 1 0 1 0 1 0 2 0 0 0 0 1 0 0 1 0 0 0 0 0 0 0 0 0 1 0 0 0 0 1 0 0 0 1 0 1 0 0 1 1 1 1 0</counts>
			</dataPoints>
		</scan>
		<scan status="Completed" appendNumber="0" scanAxis="2Theta" mode="Continuous">
			<header>
				<startTimeStamp>2023-01-13T17:58:27-05:00</startTimeStamp>
				<endTimeStamp>2023-01-13T18:14:40-05:00</endTimeStamp>
				<author>
					<name>User</name>
				</author>
				<source>
					<applicationSoftware version="7.1">Data Collector</applicationSoftware>
					<instrumentControlSoftware version="8.2  20201204">EMPYREAN</instrumentControlSoftware>
					<instrumentID>0000000011260721</instrumentID>
				</source>
			</header>
			<dataPoints>
				<positions axis="2Theta" unit="deg">
					<startPosition>70.9175623838325</startPosition>
					<endPosition>74.264832155049</endPosition>
				</positions>
				<positions axis="Omega" unit="deg">
					<commonPosition>17.8690986347204</commonPosition>
				</positions>
				<positions axis="Phi" unit="deg">
					<commonPosition>3.6</commonPosition>
				</positions>
				<positions axis="Chi" unit="deg">
					<commonPosition>0</commonPosition>
				</positions>
				<positions axis="Z" unit="mm">
					<commonPosition>8.428</commonPosition>
				</positions>
				<commonCountingTime unit="seconds">0.784</commonCountingTime>
				<counts unit="counts">0 1 1 0 0 0 1 0 0 1 1 2 0 0 0 0 0 0 0 1 0 0 0 0 0 0 0 0 0 0 0 0 1 0 0 1 0 0 1 1 0 0 0 0 0 1 0 0 1 0 1 0 0 0 0 1 1 0 0 1 1 0 1 0 0 0 0 0 0 1 0 0 0 0 1 2 0 0 1 0 0 0 1 0 2 1 1 0 3 2 0 1 0 0 0 0 1 1 1 0 0 0 0 0 0 1 1 0 0 0 1 2 0 2 0 0 0 2 0 1 1 0 0 0 0 0 0 0 0 0 0 0 1 0 0 0 0 1 0 0 0 0 0 2 1 0 2 0 0 0 0 1 0 0 0 0 0 2 0 0 0 0 0 1 2 0 0 1 0 1 2 0 1 1 6 0 0 1 0 0 1 0 0 0 0 0 1 2 0 0 0 0 0 0 0 0 0 1 0 0 0 0 0 1 0 0 0 2 0 0 3 0 1 1 2 0 0 0 1 0 1 0 0 0 0 0 0 1 0 0 0 0 1 0 1 0 0 0 0 0 1 1 0 0 0 0 0 1 0 0 1 0 0 0 1</counts>
			</dataPoints>
		</scan>
		<scan status="Completed" appendNumber="0" scanAxis="2Theta" mode="Continuous">
			<header>
				<startTimeStamp>2023-01-13T17:58:27-05:00</startTimeStamp>
				<endTimeStamp>2023-01-13T18:14:40-05:00</endTimeStamp>
				<author>
					<name>User</name>
				</author>
				<source>
					<applicationSoftware version="7.1">Data Collector</applicationSoftware>
					<instrumentControlSoftware version="8.2  20201204">EMPYREAN</instrumentControlSoftware>
					<instrumentID>0000000011260721</instrumentID>
				</source>
			</header>
			<dataPoints>
				<positions axis="2Theta" unit="deg">
					<startPosition>70.9208449545069</startPosition>
					<endPosition>74.2681147257234</endPosition>
				</positions>
				<positions axis="Omega" unit="deg">
					<commonPosition>17.8707399200576</commonPosition>
				</positions>
				<positions axis="Phi" unit="deg">
					<commonPosition>3.6</commonPosition>
				</positions>
				<positions axis="Chi" unit="deg">
					<commonPosition>0</commonPosition>
				</positions>
				<positions axis="Z" unit="mm">
					<commonPosition>8.428</commonPosition>
				</positions>
				<commonCountingTime unit="seconds">0.784</commonCountingTime>
				<counts unit="counts">0 1 1 1 1 0 0 0 0 0 0 0 0 0 1 0 0 0 0 1 0 0 0 0 0 0 1 1 1 0 1 1 1 1 0 0 0 0 0 0 0 0 0 0 0 0 0 0 1 0 0 0 0 0 0 0 0 1 0 0 0 2 0 0 1 0 0 0 2 0 2 0 0 1 0 0 1 0 0 0 0 1 1 0 0 0 0 0 0 1 1 1 0 0 0 0 0 0 1 0 2 1 0 0 0 0 0 0 0 0 1 1 1 2 0 1 0 0 1 0 0 1 0 0 0 0 0 1 1 1 0 0 0 0 0 0 0 0 0 0 0 0 0 0 0 0 1 1 1 1 0 0 0 0 0 0 0 0 0 0 0 0 1 1 0 0 0 1 1 1 2 1 9 0 1 0 0 1 0 1 0 0 0 1 0 0 0 0 0 0 1 1 0 1 0 0 1 0 0 0 0 0 2 1 1 0 0 1 0 0 1 0 0 1 0 0 0 0 0 0 0 0 0 0 0 0 0 0 0 3 1 0 0 2 0 0 1 0 0 0 0 1 1 1 0 0 1 1 0 0 0 0 0 1 1</counts>
			</dataPoints>
		</scan>
		<scan status="Completed" appendNumber="0" scanAxis="2Theta" mode="Continuous">
			<header>
				<startTimeStamp>2023-01-13T17:58:27-05:00</startTimeStamp>
				<endTimeStamp>2023-01-13T18:14:40-05:00</endTimeStamp>
				<author>
					<name>User</name>
				</author>
				<source>
					<applicationSoftware version="7.1">Data Collector</applicationSoftware>
					<instrumentControlSoftware version="8.2  20201204">EMPYREAN</instrumentControlSoftware>
					<instrumentID>0000000011260721</instrumentID>
				</source>
			</header>
			<dataPoints>
				<positions axis="2Theta" unit="deg">
					<startPosition>70.9241275251812</startPosition>
					<endPosition>74.2713972963977</endPosition>
				</positions>
				<positions axis="Omega" unit="deg">
					<commonPosition>17.8723812053947</commonPosition>
				</positions>
				<positions axis="Phi" unit="deg">
					<commonPosition>3.6</commonPosition>
				</positions>
				<positions axis="Chi" unit="deg">
					<commonPosition>0</commonPosition>
				</positions>
				<positions axis="Z" unit="mm">
					<commonPosition>8.428</commonPosition>
				</positions>
				<commonCountingTime unit="seconds">0.784</commonCountingTime>
				<counts unit="counts">0 2 0 0 0 0 0 0 0 0 0 0 0 0 0 0 0 0 0 0 0 0 0 1 0 0 0 0 0 1 0 0 0 0 0 0 0 0 0 0 0 0 1 0 2 0 0 1 0 0 0 0 0 0 1 0 1 0 1 0 0 0 0 0 0 0 1 0 0 0 0 2 0 0 0 0 0 2 1 1 2 1 1 0 0 0 2 0 0 0 0 3 0 1 0 0 0 0 1 0 1 0 1 0 0 0 0 0 0 1 1 0 1 1 0 0 0 0 0 1 2 1 1 1 0 0 0 0 3 0 0 1 0 0 1 0 0 1 0 0 0 0 0 0 0 0 1 0 0 0 0 0 0 1 1 2 0 1 0 1 0 0 0 0 0 0 2 0 0 1 1 1 3 3 1 0 0 0 0 0 0 0 0 0 0 1 1 1 1 0 0 1 0 1 1 0 0 0 0 1 0 0 1 2 1 0 0 0 2 0 0 0 0 0 1 1 0 0 2 0 1 0 0 0 0 0 1 0 0 0 0 0 0 1 2 1 0 0 0 0 0 1 0 0 0 0 0 0 0 2 0 0 0 0 0</counts>
			</dataPoints>
		</scan>
		<scan status="Completed" appendNumber="0" scanAxis="2Theta" mode="Continuous">
			<header>
				<startTimeStamp>2023-01-13T17:58:27-05:00</startTimeStamp>
				<endTimeStamp>2023-01-13T18:14:40-05:00</endTimeStamp>
				<author>
					<name>User</name>
				</author>
				<source>
					<applicationSoftware version="7.1">Data Collector</applicationSoftware>
					<instrumentControlSoftware version="8.2  20201204">EMPYREAN</instrumentControlSoftware>
					<instrumentID>0000000011260721</instrumentID>
				</source>
			</header>
			<dataPoints>
				<positions axis="2Theta" unit="deg">
					<startPosition>70.9274100958556</startPosition>
					<endPosition>74.2746798670721</endPosition>
				</positions>
				<positions axis="Omega" unit="deg">
					<commonPosition>17.8740224907319</commonPosition>
				</positions>
				<positions axis="Phi" unit="deg">
					<commonPosition>3.6</commonPosition>
				</positions>
				<positions axis="Chi" unit="deg">
					<commonPosition>0</commonPosition>
				</positions>
				<positions axis="Z" unit="mm">
					<commonPosition>8.428</commonPosition>
				</positions>
				<commonCountingTime unit="seconds">0.784</commonCountingTime>
				<counts unit="counts">0 2 0 0 0 2 0 0 1 1 0 1 1 0 0 2 0 0 0 1 1 0 1 0 0 0 0 0 0 0 0 0 2 0 0 0 0 0 1 0 0 0 0 0 0 1 0 0 1 1 2 0 0 0 0 0 1 1 1 1 0 0 0 0 0 0 0 0 0 0 0 0 0 0 1 1 0 0 0 2 1 0 0 0 2 0 1 0 0 2 0 0 0 1 0 0 0 1 0 0 0 1 0 0 0 0 0 1 1 1 0 0 0 0 0 0 0 0 0 0 0 0 0 0 0 0 0 0 0 0 0 1 0 1 0 1 0 0 2 2 0 0 0 2 0 0 0 0 0 0 0 0 1 0 2 0 1 1 1 1 1 0 1 0 1 0 0 0 0 1 3 4 4 1 1 0 1 0 1 0 1 2 0 0 0 0 0 0 1 0 1 0 1 0 0 0 0 0 0 1 1 0 0 0 1 1 2 0 1 0 0 0 1 0 0 0 0 1 1 0 0 1 0 0 2 0 1 0 1 0 0 0 0 0 1 0 0 0 0 1 0 1 0 1 0 0 1 0 0 1 1 0 0 1 0</counts>
			</dataPoints>
		</scan>
		<scan status="Completed" appendNumber="0" scanAxis="2Theta" mode="Continuous">
			<header>
				<startTimeStamp>2023-01-13T17:58:27-05:00</startTimeStamp>
				<endTimeStamp>2023-01-13T18:14:40-05:00</endTimeStamp>
				<author>
					<name>User</name>
				</author>
				<source>
					<applicationSoftware version="7.1">Data Collector</applicationSoftware>
					<instrumentControlSoftware version="8.2  20201204">EMPYREAN</instrumentControlSoftware>
					<instrumentID>0000000011260721</instrumentID>
				</source>
			</header>
			<dataPoints>
				<positions axis="2Theta" unit="deg">
					<startPosition>70.9306926665299</startPosition>
					<endPosition>74.2779624377464</endPosition>
				</positions>
				<positions axis="Omega" unit="deg">
					<commonPosition>17.8756637760691</commonPosition>
				</positions>
				<positions axis="Phi" unit="deg">
					<commonPosition>3.6</commonPosition>
				</positions>
				<positions axis="Chi" unit="deg">
					<commonPosition>0</commonPosition>
				</positions>
				<positions axis="Z" unit="mm">
					<commonPosition>8.428</commonPosition>
				</positions>
				<commonCountingTime unit="seconds">0.784</commonCountingTime>
				<counts unit="counts">0 0 0 0 0 0 0 0 1 0 2 0 0 0 0 0 1 0 0 1 0 1 1 0 0 1 0 0 0 0 0 1 0 0 0 0 0 0 0 0 0 0 0 0 0 2 0 0 0 1 0 1 0 1 0 0 1 0 0 0 0 1 0 0 0 0 0 0 1 0 0 0 1 0 0 1 0 0 0 0 0 1 0 1 1 0 2 0 1 0 0 0 0 0 0 1 0 0 0 0 0 0 0 0 1 1 0 0 0 1 0 0 1 0 0 1 2 0 0 1 0 0 0 0 0 0 1 0 0 0 0 0 0 0 0 0 0 0 0 0 0 1 0 0 0 0 0 0 0 1 0 0 0 1 0 0 0 0 0 0 0 0 1 0 0 0 0 0 0 1 1 2 4 2 4 3 2 0 0 1 1 1 1 0 0 0 1 0 0 0 1 1 0 0 1 2 0 0 0 0 0 0 0 0 0 1 1 0 0 0 0 0 0 0 0 0 2 0 1 0 0 0 2 0 0 0 0 0 0 0 0 0 0 1 0 0 0 1 1 1 0 1 1 0 0 0 0 0 0 1 0 0 0 0 0</counts>
			</dataPoints>
		</scan>
		<scan status="Completed" appendNumber="0" scanAxis="2Theta" mode="Continuous">
			<header>
				<startTimeStamp>2023-01-13T17:58:27-05:00</startTimeStamp>
				<endTimeStamp>2023-01-13T18:14:40-05:00</endTimeStamp>
				<author>
					<name>User</name>
				</author>
				<source>
					<applicationSoftware version="7.1">Data Collector</applicationSoftware>
					<instrumentControlSoftware version="8.2  20201204">EMPYREAN</instrumentControlSoftware>
					<instrumentID>0000000011260721</instrumentID>
				</source>
			</header>
			<dataPoints>
				<positions axis="2Theta" unit="deg">
					<startPosition>70.9339752372043</startPosition>
					<endPosition>74.2812450084207</endPosition>
				</positions>
				<positions axis="Omega" unit="deg">
					<commonPosition>17.8773050614063</commonPosition>
				</positions>
				<positions axis="Phi" unit="deg">
					<commonPosition>3.6</commonPosition>
				</positions>
				<positions axis="Chi" unit="deg">
					<commonPosition>0</commonPosition>
				</positions>
				<positions axis="Z" unit="mm">
					<commonPosition>8.428</commonPosition>
				</positions>
				<commonCountingTime unit="seconds">0.784</commonCountingTime>
				<counts unit="counts">0 0 0 0 0 0 1 0 0 0 0 0 1 1 1 0 0 0 0 1 1 1 0 1 1 0 0 0 0 0 0 0 0 1 1 0 0 0 0 0 0 1 0 0 0 2 0 1 1 0 0 2 1 0 0 1 0 0 0 0 0 1 0 1 0 0 0 3 0 0 0 0 0 0 1 0 0 0 0 0 0 0 0 0 0 2 0 0 0 0 1 1 0 2 0 0 1 0 0 0 0 0 0 0 0 0 0 1 1 1 0 1 0 1 0 1 0 1 0 4 1 0 0 1 0 0 0 0 1 0 0 0 0 1 0 0 0 0 0 0 0 0 0 0 0 0 1 1 1 1 0 0 1 0 0 0 0 1 1 1 1 1 0 0 0 0 1 1 1 2 1 5 5 1 0 0 0 0 0 1 0 0 1 2 1 0 0 0 0 1 1 1 0 0 1 0 0 0 0 0 0 0 0 0 0 0 1 0 0 1 0 0 0 1 1 1 0 0 0 0 0 1 1 0 0 0 0 0 0 0 0 0 0 0 0 0 0 0 0 2 0 1 1 0 0 0 1 0 2 0 0 2 1 1 1</counts>
			</dataPoints>
		</scan>
		<scan status="Completed" appendNumber="0" scanAxis="2Theta" mode="Continuous">
			<header>
				<startTimeStamp>2023-01-13T17:58:27-05:00</startTimeStamp>
				<endTimeStamp>2023-01-13T18:14:40-05:00</endTimeStamp>
				<author>
					<name>User</name>
				</author>
				<source>
					<applicationSoftware version="7.1">Data Collector</applicationSoftware>
					<instrumentControlSoftware version="8.2  20201204">EMPYREAN</instrumentControlSoftware>
					<instrumentID>0000000011260721</instrumentID>
				</source>
			</header>
			<dataPoints>
				<positions axis="2Theta" unit="deg">
					<startPosition>70.9372578078786</startPosition>
					<endPosition>74.2845275790951</endPosition>
				</positions>
				<positions axis="Omega" unit="deg">
					<commonPosition>17.8789463467434</commonPosition>
				</positions>
				<positions axis="Phi" unit="deg">
					<commonPosition>3.6</commonPosition>
				</positions>
				<positions axis="Chi" unit="deg">
					<commonPosition>0</commonPosition>
				</positions>
				<positions axis="Z" unit="mm">
					<commonPosition>8.428</commonPosition>
				</positions>
				<commonCountingTime unit="seconds">0.784</commonCountingTime>
[...]
				<positions axis="Chi" unit="deg">
					<commonPosition>0</commonPosition>
				</positions>
				<positions axis="Z" unit="mm">
					<commonPosition>8.428</commonPosition>
				</positions>
				<commonCountingTime unit="seconds">0.784</commonCountingTime>
				<counts unit="counts">0 0 2 0 1 0 0 1 0 0 0 1 0 1 0 1 0 0 0 0 0 2 0 0 2 0 0 0 1 0 1 1 0 0 1 0 0 1 0 0 1 0 0 0 1 0 0 1 0 0 1 1 0 0 1 0 0 0 1 0 0 1 0 0 1 0 0 0 1 0 0 0 0 0 1 1 0 0 0 1 0 0 0 0 0 1 0 0 0 0 0 0 0 1 0 1 1 0 0 1 0 1 0 0 0 0 0 0 1 0 0 1 0 0 1 0 0 0 1 0 0 0 0 1 0 2 2 0 0 1 0 0 1 0 0 0 1 0 0 1 0 0 0 1 0 0 0 1 0 2 0 0 0 0 0 1 0 0 0 1 1 1 0 0 0 0 0 0 0 0 3 1 0 0 1 2 0 1 0 0 0 0 0 0 0 0 1 0 2 0 0 0 0 0 0 1 0 0 0 0 0 0 1 1 0 0 0 1 0 0 1 1 0 1 0 0 0 1 0 0 1 0 1 0 0 0 0 0 0 1 0 0 0 0 1 1 0 0 1 1 0 1 1 0 0 0 0 0 0 1 1 0 0 0 0</counts>
			</dataPoints>
		</scan>
		<scan status="Completed" appendNumber="0" scanAxis="2Theta" mode="Continuous">
			<header>
				<startTimeStamp>2023-01-13T17:58:27-05:00</startTimeStamp>
				<endTimeStamp>2023-01-13T18:14:40-05:00</endTimeStamp>
				<author>
					<name>User</name>
				</author>
				<source>
					<applicationSoftware version="7.1">Data Collector</applicationSoftware>
					<instrumentControlSoftware version="8.2  20201204">EMPYREAN</instrumentControlSoftware>
					<instrumentID>0000000011260721</instrumentID>
				</source>
			</header>
			<dataPoints>
				<positions axis="2Theta" unit="deg">
					<startPosition>74.8303866276483</startPosition>
					<endPosition>78.1776563988648</endPosition>
				</positions>
				<positions axis="Omega" unit="deg">
					<commonPosition>19.8255107566283</commonPosition>
				</positions>
				<positions axis="Phi" unit="deg">
					<commonPosition>3.6</commonPosition>
				</positions>
				<positions axis="Chi" unit="deg">
					<commonPosition>0</commonPosition>
				</positions>
				<positions axis="Z" unit="mm">
					<commonPosition>8.428</commonPosition>
				</positions>
				<commonCountingTime unit="seconds">0.784</commonCountingTime>
				<counts unit="counts">1 2 0 0 0 0 0 0 0 1 0 1 2 0 0 1 0 1 0 1 0 0 0 1 1 0 1 0 0 1 0 0 0 0 1 0 0 0 2 0 0 1 1 0 0 0 0 0 0 0 0 0 0 0 0 0 1 1 1 0 0 0 0 1 1 0 0 0 0 0 0 2 0 0 1 0 1 0 0 0 3 0 0 5 1 1 1 0 1 2 0 2 1 0 2 0 0 0 0 0 1 0 0 1 0 0 2 0 1 0 0 0 1 0 1 0 0 0 0 0 0 0 2 0 0 2 1 0 1 1 0 0 0 0 0 0 1 0 0 1 0 1 0 1 1 1 0 0 0 0 0 0 0 1 0 1 1 2 0 1 0 1 0 1 0 0 0 1 0 0 0 0 0 0 1 0 1 1 0 0 1 0 0 0 0 0 0 0 0 0 1 0 0 0 0 0 0 0 0 0 1 0 0 0 0 1 0 1 0 0 0 0 0 0 0 0 0 0 0 1 1 1 0 1 0 1 1 1 0 0 0 1 1 1 0 0 0 0 0 0 0 0 0 0 0 1 0 0 0 0 1 0 1 1 1</counts>
			</dataPoints>
		</scan>
		<scan status="Completed" appendNumber="0" scanAxis="2Theta" mode="Continuous">
			<header>
				<startTimeStamp>2023-01-13T17:58:27-05:00</startTimeStamp>
				<endTimeStamp>2023-01-13T18:14:40-05:00</endTimeStamp>
				<author>
					<name>User</name>
				</author>
				<source>
					<applicationSoftware version="7.1">Data Collector</applicationSoftware>
					<instrumentControlSoftware version="8.2  20201204">EMPYREAN</instrumentControlSoftware>
					<instrumentID>0000000011260721</instrumentID>
				</source>
			</header>
			<dataPoints>
				<positions axis="2Theta" unit="deg">
					<startPosition>74.8336691983227</startPosition>
					<endPosition>78.1809389695392</endPosition>
				</positions>
				<positions axis="Omega" unit="deg">
					<commonPosition>19.8271520419655</commonPosition>
				</positions>
				<positions axis="Phi" unit="deg">
					<commonPosition>3.6</commonPosition>
				</positions>
				<positions axis="Chi" unit="deg">
					<commonPosition>0</commonPosition>
				</positions>
				<positions axis="Z" unit="mm">
					<commonPosition>8.428</commonPosition>
				</positions>
				<commonCountingTime unit="seconds">0.784</commonCountingTime>
				<counts unit="counts">1 0 0 0 1 1 0 0 1 2 0 1 0 0 3 0 2 0 0 0 0 1 1 2 0 0 0 0 1 0 2 1 0 0 1 0 1 2 0 1 0 1 0 0 1 0 0 1 1 1 1 1 1 0 0 1 1 1 2 1 0 0 0 0 0 1 3 1 0 0 1 0 1 0 0 0 1 0 1 3 1 1 1 0 0 1 0 0 1 2 0 0 0 2 1 0 1 2 0 1 0 1 0 0 1 1 4 1 1 0 0 1 1 0 1 0 0 0 1 1 0 1 0 1 0 0 0 0 0 0 0 0 0 0 1 0 0 0 0 0 0 2 0 0 0 0 0 0 0 1 0 0 0 0 0 0 0 1 0 0 0 0 0 0 0 0 1 1 1 0 0 0 0 1 0 0 0 0 0 0 0 0 0 0 2 0 0 0 0 0 1 0 0 0 0 0 0 0 0 0 0 0 0 0 0 2 0 0 1 0 0 0 2 1 0 1 0 0 1 0 0 0 0 1 0 0 0 0 0 0 0 0 0 0 0 0 1 0 0 1 0 0 0 0 0 0 0 0 0 0 0 0 0 0 0</counts>
			</dataPoints>
		</scan>
		<scan status="Completed" appendNumber="0" scanAxis="2Theta" mode="Continuous">
			<header>
				<startTimeStamp>2023-01-13T17:58:27-05:00</startTimeStamp>
				<endTimeStamp>2023-01-13T18:14:40-05:00</endTimeStamp>
				<author>
					<name>User</name>
				</author>
				<source>
					<applicationSoftware version="7.1">Data Collector</applicationSoftware>
					<instrumentControlSoftware version="8.2  20201204">EMPYREAN</instrumentControlSoftware>
					<instrumentID>0000000011260721</instrumentID>
				</source>
			</header>
			<dataPoints>
				<positions axis="2Theta" unit="deg">
					<startPosition>74.836951768997</startPosition>
					<endPosition>78.1842215402135</endPosition>
				</positions>
				<positions axis="Omega" unit="deg">
					<commonPosition>19.8287933273026</commonPosition>
				</positions>
				<positions axis="Phi" unit="deg">
					<commonPosition>3.6</commonPosition>
				</positions>
				<positions axis="Chi" unit="deg">
					<commonPosition>0</commonPosition>
				</positions>
				<positions axis="Z" unit="mm">
					<commonPosition>8.428</commonPosition>
				</positions>
				<commonCountingTime unit="seconds">0.784</commonCountingTime>
				<counts unit="counts">0 0 0 0 0 0 0 0 0 0 0 1 0 0 0 0 1 1 0 0 1 0 0 1 1 1 0 1 0 0 4 0 1 0 0 0 0 0 0 0 0 0 2 1 1 2 2 0 0 0 1 0 3 0 0 0 0 1 1 1 0 0 1 0 0 0 1 0 0 2 1 0 1 0 0 1 0 0 0 1 0 1 1 1 0 0 0 0 1 1 1 0 3 0 0 0 0 0 0 0 0 0 0 1 0 0 0 0 0 1 1 0 0 0 0 1 1 0 1 1 0 0 0 0 0 0 0 0 0 0 1 1 0 0 0 0 0 0 0 0 1 2 2 0 0 0 1 1 0 1 1 0 0 0 1 0 1 0 0 0 0 0 0 1 0 1 0 2 1 0 1 1 0 0 0 0 0 1 1 0 1 2 0 0 0 0 1 0 0 0 1 0 1 1 0 0 0 1 0 0 0 2 1 1 0 0 0 0 1 0 0 0 0 0 0 0 0 0 0 0 0 1 0 0 1 0 1 0 0 0 1 0 0 0 0 1 1 0 0 0 0 0 0 0 0 0 0 0 1 2 0 0 2 0 1</counts>
			</dataPoints>
		</scan>
		<scan status="Completed" appendNumber="0" scanAxis="2Theta" mode="Continuous">
			<header>
				<startTimeStamp>2023-01-13T17:58:27-05:00</startTimeStamp>
				<endTimeStamp>2023-01-13T18:14:40-05:00</endTimeStamp>
				<author>
					<name>User</name>
				</author>
				<source>
					<applicationSoftware version="7.1">Data Collector</applicationSoftware>
					<instrumentControlSoftware version="8.2  20201204">EMPYREAN</instrumentControlSoftware>
					<instrumentID>0000000011260721</instrumentID>
				</source>
			</header>
			<dataPoints>
				<positions axis="2Theta" unit="deg">
					<startPosition>74.8402343396714</startPosition>
					<endPosition>78.1875041108878</endPosition>
				</positions>
				<positions axis="Omega" unit="deg">
					<commonPosition>19.8304346126398</commonPosition>
				</positions>
				<positions axis="Phi" unit="deg">
					<commonPosition>3.6</commonPosition>
				</positions>
				<positions axis="Chi" unit="deg">
					<commonPosition>0</commonPosition>
				</positions>
				<positions axis="Z" unit="mm">
					<commonPosition>8.428</commonPosition>
				</positions>
				<commonCountingTime unit="seconds">0.784</commonCountingTime>
				<counts unit="counts">0 1 0 1 1 0 0 0 0 0 1 0 0 0 1 0 0 0 0 0 0 0 0 3 0 0 0 0 2 0 0 1 0 1 0 1 0 1 1 0 1 1 0 0 0 0 1 0 1 0 0 2 0 0 1 0 0 1 2 1 0 1 1 0 0 0 1 0 1 0 0 0 1 1 0 0 0 0 1 0 0 4 1 1 1 0 0 0 0 1 3 0 0 0 1 1 0 1 0 0 0 0 0 1 0 0 1 0 0 1 0 0 0 2 1 0 1 1 0 0 0 0 0 0 0 0 0 2 1 1 1 0 1 0 1 1 0 0 0 0 0 1 0 0 0 0 1 0 0 0 0 0 0 0 0 0 0 0 0 0 0 1 2 1 0 0 2 0 0 0 0 0 0 0 0 0 1 0 0 0 1 0 0 0 0 1 0 0 0 2 0 1 1 0 0 0 0 0 0 1 1 0 0 0 0 0 0 0 0 1 0 0 1 0 0 0 0 0 0 0 0 0 0 0 0 0 0 0 1 0 0 0 0 0 0 1 0 0 0 0 0 0 0 0 0 0 0 1 0 0 0 0 1 1 0</counts>
			</dataPoints>
		</scan>
		<scan status="Completed" appendNumber="0" scanAxis="2Theta" mode="Continuous">
			<header>
				<startTimeStamp>2023-01-13T17:58:27-05:00</startTimeStamp>
				<endTimeStamp>2023-01-13T18:14:40-05:00</endTimeStamp>
				<author>
					<name>User</name>
				</author>
				<source>
					<applicationSoftware version="7.1">Data Collector</applicationSoftware>
					<instrumentControlSoftware version="8.2  20201204">EMPYREAN</instrumentControlSoftware>
					<instrumentID>0000000011260721</instrumentID>
				</source>
			</header>
			<dataPoints>
				<positions axis="2Theta" unit="deg">
					<startPosition>74.8435169103457</startPosition>
					<endPosition>78.1907866815622</endPosition>
				</positions>
				<positions axis="Omega" unit="deg">
					<commonPosition>19.832075897977</commonPosition>
				</positions>
				<positions axis="Phi" unit="deg">
					<commonPosition>3.6</commonPosition>
				</positions>
				<positions axis="Chi" unit="deg">
					<commonPosition>0</commonPosition>
				</positions>
				<positions axis="Z" unit="mm">
					<commonPosition>8.428</commonPosition>
				</positions>
				<commonCountingTime unit="seconds">0.784</commonCountingTime>
				<counts unit="counts">0 0 0 0 0 0 1 1 1 0 1 2 1 0 2 1 1 0 0 1 0 0 0 0 0 0 1 0 1 0 0 0 0 0 0 1 1 1 0 1 1 0 0 0 0 0 0 0 0 0 0 2 0 0 0 0 1 0 1 1 0 0 0 0 1 1 0 0 0 1 0 1 1 0 0 0 1 1 1 0 0 2 0 1 0 0 1 1 0 0 0 1 0 0 1 0 2 0 0 0 0 0 0 1 0 0 0 0 0 0 1 1 1 0 0 0 0 0 0 0 1 0 0 0 0 0 0 0 0 1 2 1 0 0 0 0 0 0 0 1 0 0 1 0 1 0 1 2 1 0 0 2 0 0 0 1 0 0 1 0 0 1 1 0 0 0 0 0 1 0 0 1 0 0 1 0 0 1 1 0 0 0 2 0 0 0 0 0 0 0 0 0 2 1 1 0 0 2 0 0 0 1 0 0 0 0 1 0 0 0 0 1 1 0 0 0 0 0 0 0 0 0 0 0 0 0 0 0 0 0 0 0 0 0 1 0 0 0 0 0 0 0 0 0 0 0 0 0 0 1 0 0 0 0 0</counts>
			</dataPoints>
		</scan>
		<scan status="Completed" appendNumber="0" scanAxis="2Theta" mode="Continuous">
			<header>
				<startTimeStamp>2023-01-13T17:58:27-05:00</startTimeStamp>
				<endTimeStamp>2023-01-13T18:14:40-05:00</endTimeStamp>
				<author>
					<name>User</name>
				</author>
				<source>
					<applicationSoftware version="7.1">Data Collector</applicationSoftware>
					<instrumentControlSoftware version="8.2  20201204">EMPYREAN</instrumentControlSoftware>
					<instrumentID>0000000011260721</instrumentID>
				</source>
			</header>
			<dataPoints>
				<positions axis="2Theta" unit="deg">
					<startPosition>74.84679948102</startPosition>
					<endPosition>78.1940692522365</endPosition>
				</positions>
				<positions axis="Omega" unit="deg">
					<commonPosition>19.8337171833141</commonPosition>
				</positions>
				<positions axis="Phi" unit="deg">
					<commonPosition>3.6</commonPosition>
				</positions>
				<positions axis="Chi" unit="deg">
					<commonPosition>0</commonPosition>
				</positions>
				<positions axis="Z" unit="mm">
					<commonPosition>8.428</commonPosition>
				</positions>
				<commonCountingTime unit="seconds">0.784</commonCountingTime>
				<counts unit="counts">0 0 0 0 1 1 0 2 0 2 0 0 1 0 0 0 1 0 1 0 0 1 0 0 0 1 0 0 1 0 0 0 0 0 0 0 0 2 0 0 0 0 1 0 0 0 0 0 1 0 1 1 1 1 1 1 0 0 1 0 0 0 0 0 0 0 0 0 1 0 0 0 2 1 0 0 1 0 0 1 2 0 0 2 1 1 0 0 0 0 0 1 0 0 0 0 0 2 0 1 1 0 1 0 0 0 0 1 0 0 0 0 0 1 0 1 0 0 0 0 0 1 1 3 0 1 0 0 0 0 0 0 0 0 0 0 0 2 0 0 1 0 0 3 0 0 0 2 0 1 0 0 1 1 1 0 0 0 1 0 0 0 2 0 0 0 2 1 0 0 0 0 0 0 0 0 0 0 1 0 0 1 0 0 1 0 1 0 1 0 1 0 1 1 1 0 1 1 0 0 0 1 0 1 1 0 0 1 1 1 1 1 0 0 0 0 1 0 0 1 0 1 0 0 0 0 0 1 0 0 0 0 2 1 0 0 0 1 1 2 1 0 0 2 0 1 0 0 0 0 0 1 0 0 0</counts>
			</dataPoints>
		</scan>
		<scan status="Completed" appendNumber="0" scanAxis="2Theta" mode="Continuous">
			<header>
				<startTimeStamp>2023-01-13T17:58:27-05:00</startTimeStamp>
				<endTimeStamp>2023-01-13T18:14:40-05:00</endTimeStamp>
				<author>
					<name>User</name>
				</author>
				<source>
					<applicationSoftware version="7.1">Data Collector</applicationSoftware>
					<instrumentControlSoftware version="8.2  20201204">EMPYREAN</instrumentControlSoftware>
					<instrumentID>0000000011260721</instrumentID>
				</source>
			</header>
			<dataPoints>
				<positions axis="2Theta" unit="deg">
					<startPosition>74.8500820516944</startPosition>
					<endPosition>78.1973518229109</endPosition>
				</positions>
				<positions axis="Omega" unit="deg">
					<commonPosition>19.8353584686513</commonPosition>
				</positions>
				<positions axis="Phi" unit="deg">
					<commonPosition>3.6</commonPosition>
				</positions>
				<positions axis="Chi" unit="deg">
					<commonPosition>0</commonPosition>
				</positions>
				<positions axis="Z" unit="mm">
					<commonPosition>8.428</commonPosition>
				</positions>
				<commonCountingTime unit="seconds">0.784</commonCountingTime>
				<counts unit="counts">2 0 0 0 0 0 0 0 1 2 1 0 1 1 0 1 0 1 2 0 1 0 0 0 0 0 0 0 0 1 1 1 1 2 1 2 2 0 0 0 0 0 0 1 2 0 0 1 0 0 0 1 0 1 0 0 0 0 0 1 1 0 0 0 0 0 1 0 0 0 0 1 0 0 0 0 0 0 0 0 1 1 0 0 0 0 0 0 0 0 1 0 2 1 0 2 0 0 0 0 0 0 0 0 0 0 0 0 0 0 1 0 1 0 0 0 0 0 0 0 0 0 0 0 0 0 0 0 0 3 1 0 2 1 0 1 0 0 0 0 0 0 1 0 0 0 0 0 2 0 0 0 0 2 0 0 0 0 1 0 0 0 0 0 0 0 0 0 0 1 1 0 0 0 1 0 0 0 0 0 1 0 0 1 1 1 0 0 0 0 0 1 1 0 0 0 1 0 0 1 0 0 0 0 0 0 0 1 0 0 1 2 0 0 0 0 0 1 0 0 0 1 0 0 0 1 1 0 2 1 1 0 0 0 1 0 2 0 1 0 2 0 1 0 1 0 0 1 0 0 1 0 1 1 0</counts>
			</dataPoints>
		</scan>
		<scan status="Completed" appendNumber="0" scanAxis="2Theta" mode="Continuous">
			<header>
				<startTimeStamp>2023-01-13T17:58:27-05:00</startTimeStamp>
				<endTimeStamp>2023-01-13T18:14:40-05:00</endTimeStamp>
				<author>
					<name>User</name>
				</author>
				<source>
					<applicationSoftware version="7.1">Data Collector</applicationSoftware>
					<instrumentControlSoftware version="8.2  20201204">EMPYREAN</instrumentControlSoftware>
					<instrumentID>0000000011260721</instrumentID>
				</source>
			</header>
			<dataPoints>
				<positions axis="2Theta" unit="deg">
					<startPosition>74.8533646223687</startPosition>
					<endPosition>78.2006343935852</endPosition>
				</positions>
				<positions axis="Omega" unit="deg">
					<commonPosition>19.8369997539885</commonPosition>
				</positions>
				<positions axis="Phi" unit="deg">
					<commonPosition>3.6</commonPosition>
				</positions>
				<positions axis="Chi" unit="deg">
					<commonPosition>0</commonPosition>
				</positions>
				<positions axis="Z" unit="mm">
					<commonPosition>8.428</commonPosition>
				</positions>
				<commonCountingTime unit="seconds">0.784</commonCountingTime>
				<counts unit="counts">0 0 0 0 0 0 0 0 1 0 0 1 1 0 1 1 0 1 0 1 0 0 0 0 0 0 0 0 0 4 0 0 0 0 0 0 1 0 0 0 1 0 0 0 0 0 0 0 1 0 2 1 1 0 0 0 0 0 0 1 0 0 1 0 0 0 0 0 0 0 0 0 0 2 1 0 0 0 0 0 2 0 0 0 2 1 0 0 0 0 2 0 0 1 0 0 0 0 2 0 0 0 1 1 3 0 1 0 0 0 0 0 0 0 0 2 0 0 0 0 0 1 1 0 0 0 0 0 1 1 0 0 0 0 0 0 0 0 0 1 0 1 0 0 0 1 0 0 0 0 0 0 1 0 0 1 1 0 1 0 0 0 0 0 0 0 0 0 0 2 0 0 0 0 2 0 0 2 2 0 0 0 0 0 0 1 0 0 0 1 0 0 0 1 0 0 0 0 0 0 0 0 0 0 0 0 0 1 0 0 1 0 0 0 1 0 0 0 0 0 1 2 1 1 0 1 1 0 1 0 1 0 0 0 0 0 0 0 0 0 0 0 1 1 1 0 0 1 1 0 1 0 0 0 1</counts>
			</dataPoints>
		</scan>
		<scan status="Completed" appendNumber="0" scanAxis="2Theta" mode="Continuous">
			<header>
				<startTimeStamp>2023-01-13T17:58:27-05:00</startTimeStamp>
				<endTimeStamp>2023-01-13T18:14:40-05:00</endTimeStamp>
				<author>
					<name>User</name>
				</author>
				<source>
					<applicationSoftware version="7.1">Data Collector</applicationSoftware>
					<instrumentControlSoftware version="8.2  20201204">EMPYREAN</instrumentControlSoftware>
					<instrumentID>0000000011260721</instrumentID>
				</source>
			</header>
			<dataPoints>
				<positions axis="2Theta" unit="deg">
					<startPosition>74.8566471930431</startPosition>
					<endPosition>78.2039169642595</endPosition>
				</positions>
				<positions axis="Omega" unit="deg">
					<commonPosition>19.8386410393257</commonPosition>
				</positions>
				<positions axis="Phi" unit="deg">
					<commonPosition>3.6</commonPosition>
				</positions>
				<positions axis="Chi" unit="deg">
					<commonPosition>0</commonPosition>
				</positions>
				<positions axis="Z" unit="mm">
					<commonPosition>8.428</commonPosition>
				</positions>
				<commonCountingTime unit="seconds">0.784</commonCountingTime>
				<counts unit="counts">0 0 0 0 0 0 0 1 2 0 1 0 1 0 0 0 1 0 1 0 0 0 0 0 0 0 0 0 0 0 1 1 0 0 0 0 0 1 1 0 1 0 2 1 0 0 0 0 0 0 1 0 1 0 0 0 0 2 1 1 0 1 0 0 0 0 0 0 0 0 1 0 0 0 0 1 0 1 0 2 0 0 1 0 0 1 0 1 0 0 0 0 0 0 0 1 0 0 0 0 0 0 0 0 1 0 0 1 1 0 0 0 0 0 2 0 2 2 0 1 0 0 0 0 0 0 0 0 0 0 1 0 0 0 0 0 1 0 0 0 1 1 0 0 0 0 0 0 0 0 0 0 0 0 1 0 0 2 1 0 0 1 0 0 0 0 0 0 1 1 0 0 0 0 0 0 0 0 0 0 0 0 1 0 1 3 1 0 0 0 1 0 0 0 0 0 1 0 0 0 0 0 0 1 0 1 0 0 0 0 2 0 0 1 0 0 0 0 0 1 0 0 0 0 0 0 0 0 0 0 1 1 0 0 2 1 0 0 0 0 0 0 1 0 1 0 0 0 0 1 0 0 1 0 0</counts>
			</dataPoints>
		</scan>
		<scan status="Completed" appendNumber="0" scanAxis="2Theta" mode="Continuous">
			<header>
				<startTimeStamp>2023-01-13T17:58:27-05:00</startTimeStamp>
				<endTimeStamp>2023-01-13T18:14:40-05:00</endTimeStamp>
				<author>
					<name>User</name>
				</author>
				<source>
					<applicationSoftware version="7.1">Data Collector</applicationSoftware>
					<instrumentControlSoftware version="8.2  20201204">EMPYREAN</instrumentControlSoftware>
					<instrumentID>0000000011260721</instrumentID>
				</source>
			</header>
			<dataPoints>
				<positions axis="2Theta" unit="deg">
					<startPosition>74.8599297637174</startPosition>
					<endPosition>78.2071995349339</endPosition>
				</positions>
				<positions axis="Omega" unit="deg">
					<commonPosition>19.8402823246628</commonPosition>
				</positions>
				<positions axis="Phi" unit="deg">
					<commonPosition>3.6</commonPosition>
				</positions>
				<positions axis="Chi" unit="deg">
					<commonPosition>0</commonPosition>
				</positions>
				<positions axis="Z" unit="mm">
					<commonPosition>8.428</commonPosition>
				</positions>
				<commonCountingTime unit="seconds">0.784</commonCountingTime>
				<counts unit="counts">0 0 0 1 0 0 1 0 0 1 0 0 1 1 1 1 1 0 0 1 0 0 0 0 1 0 0 0 0 0 0 1 0 0 1 0 0 0 0 1 0 0 0 0 0 1 0 1 0 1 0 0 0 0 2 0 0 0 0 0 1 0 0 0 0 2 0 1 0 2 1 0 0 0 0 0 0 0 0 2 3 0 0 2 1 1 1 1 1 0 0 1 1 1 0 0 0 0 0 1 0 1 0 0 0 0 2 0 0 1 0 0 0 1 3 0 1 0 0 0 0 1 0 0 0 0 1 0 0 0 0 1 0 0 0 0 1 0 0 2 0 0 0 0 0 0 0 0 0 1 0 0 0 0 0 0 0 0 0 0 0 0 1 0 1 0 0 1 0 0 0 0 0 0 0 0 1 0 0 0 0 1 0 0 0 0 0 2 0 0 0 0 0 0 1 0 0 1 2 2 1 1 0 0 1 0 0 0 0 0 0 0 0 0 0 0 0 0 0 1 0 0 0 0 1 1 2 0 0 0 0 0 0 0 0 1 2 0 2 0 0 0 0 0 0 1 0 0 0 0 0 0 1 0 1</counts>
			</dataPoints>
		</scan>
		<scan status="Completed" appendNumber="0" scanAxis="2Theta" mode="Continuous">
			<header>
				<startTimeStamp>2023-01-13T17:58:27-05:00</startTimeStamp>
				<endTimeStamp>2023-01-13T18:14:40-05:00</endTimeStamp>
				<author>
					<name>User</name>
				</author>
				<source>
					<applicationSoftware version="7.1">Data Collector</applicationSoftware>
					<instrumentControlSoftware version="8.2  20201204">EMPYREAN</instrumentControlSoftware>
					<instrumentID>0000000011260721</instrumentID>
				</source>
			</header>
			<dataPoints>
				<positions axis="2Theta" unit="deg">
					<startPosition>74.8632123343918</startPosition>
					<endPosition>78.2104821056082</endPosition>
				</positions>
				<positions axis="Omega" unit="deg">
					<commonPosition>19.84192361</commonPosition>
				</positions>
				<positions axis="Phi" unit="deg">
					<commonPosition>3.6</commonPosition>
				</positions>
				<positions axis="Chi" unit="deg">
					<commonPosition>0</commonPosition>
				</positions>
				<positions axis="Z" unit="mm">
					<commonPosition>8.428</commonPosition>
				</positions>
				<commonCountingTime unit="seconds">0.784</commonCountingTime>
				<counts unit="counts">1 0 0 0 0 0 1 0 1 1 0 0 1 2 0 0 2 0 1 0 0 2 0 0 0 0 0 0 0 0 1 0 0 0 1 1 2 1 1 2 0 0 0 2 0 0 0 0 0 1 0 2 0 0 0 0 1 2 0 0 1 0 1 0 0 1 0 0 0 0 0 0 1 0 0 2 0 0 0 0 0 3 0 0 0 0 0 0 2 0 0 0 0 1 0 0 0 0 2 2 1 0 0 0 0 0 0 0 0 0 0 1 0 0 0 0 0 0 0 0 0 0 0 0 0 0 0 0 1 0 0 0 0 0 1 0 0 0 0 1 0 1 0 0 0 1 0 0 2 2 0 0 0 0 0 1 1 0 0 0 0 0 0 1 0 0 1 0 0 0 0 0 1 0 0 0 0 1 0 0 0 0 1 0 0 0 0 0 0 0 0 0 1 1 0 0 0 0 0 0 1 0 0 0 0 1 0 1 0 1 0 0 0 1 0 0 1 0 0 0 2 0 0 0 2 0 1 0 1 0 0 0 0 0 0 1 1 0 0 1 2 1 1 0 0 0 0 0 1 0 0 1 0 0 0</counts>
			</dataPoints>
		</scan>
	</xrdMeasurement>
</xrdMeasurements>