File: data/XRD_RSM/YG063/YG063_RSM-103_phi-angle2.xrdml
<?xml version="1.0" encoding="utf-8"?>
<xrdMeasurements xmlns="http://www.xrdml.com/XRDMeasurement/2.2" xmlns:xsi="http://www.w3.org/2001/XMLSchema-instance" xsi:schemaLocation="http://www.xrdml.com/XRDMeasurement/2.2 http://www.xrdml.com/XRDMeasurement/2.2/XRDMeasurement.xsd" status="Completed">
	<comment>
		<entry>Configuration=3-axes Cradle_Reflection, Owner=ib355, Creation date=9/2/2021 3:55:24 PM</entry>
		<entry>Goniometer=Theta/Theta; Minimum step size 2Theta:0.0001; Minimum step size Omega:0.0001</entry>
		<entry>Sample stage=Chi-Phi-z stage 240 mm (reflection); Minimum step size Phi:0.01; Minimum step size Chi:0.01; Minimum step size Z:0.001</entry>
		<entry>Diffractometer system=EMPYREAN</entry>
		<entry>Measurement program=C:\PANalytical\Data Collector\Programs\Liyan Wu\Film programs\RSM slow 3 degree.xrdmp, Identifier={0351664C-55A7-43E7-B72A-7307F4B26703}</entry>
	</comment>
	<sample type="To be analyzed">
		<id/>
		<name/>
		<preparedBy/>
	</sample>
	<xrdMeasurement status="Completed" measurementType="Area measurement" measurementStepAxis="Omega-2Theta" sampleMode="Reflection">
		<comment>
			<entry>PHD Lower Level = 4.02 (keV), PHD Upper Level = 11.27 (keV)</entry>
		</comment>
		<usedWavelength intended="K-Alpha 1">
			<kAlpha1 unit="Angstrom">1.5405980</kAlpha1>
			<kAlpha2 unit="Angstrom">1.5444260</kAlpha2>
			<kBeta unit="Angstrom">1.3922500</kBeta>
			<ratioKAlpha2KAlpha1>0</ratioKAlpha2KAlpha1>
		</usedWavelength>
		<incidentBeamPath>
			<radius unit="mm">240.00</radius>
			<xRayTube id="1010048" name="Empyrean Cu LFF HR (9430 033 7310x) DK432574">
				<tension unit="kV">45.0</tension>
				<current unit="mA">40.0</current>
				<anodeMaterial>Cu</anodeMaterial>
				<focus type="Line">
					<length unit="mm">12.0</length>
					<width unit="mm">0.4</width>
					<takeOffAngle unit="deg">4.4</takeOffAngle>
				</focus>
			</xRayTube>
			<xRayMirror xsi:type="xRayMirrorType" id="27080001" name="Inc. Beam Cu W/Si (hybrid MPD)" hybrid="true">
				<crystal type="Graded" shape="Parabolic">W/Si</crystal>
				<acceptanceAngle unit="deg">0.800</acceptanceAngle>
				<length unit="mm">55.3</length>
			</xRayMirror>
			<monochromator xsi:type="monochromatorType" id="23090002" name="Hybrid monochr. 2xGe220 Cu asym." hybrid="true">
				<crystal type="Asymmetric" shape="Flat">Ge</crystal>
				<numberOfReflections>2</numberOfReflections>
				<hkl>
					<h>2</h>
					<k>2</k>
					<l>0</l>
				</hkl>
			</monochromator>
			<divergenceSlit xsi:type="fixedDivergenceSlitType" id="22010005" name="Fixed slit 1/4°">
				<distanceToSample unit="mm">179.30</distanceToSample>
				<height unit="mm">0.38</height>
			</divergenceSlit>
		</incidentBeamPath>
		<diffractedBeamPath>
			<radius unit="mm">240.00</radius>
			<antiScatterSlit xsi:type="fixedAntiScatterSlitType" id="22060009" name="Programmable anti-scatter slit">
				<angle unit="deg">4</angle>
			</antiScatterSlit>
			<detector xsi:type="areaDetectorType" id="7010020" name="PIXcel3D-Medipix3 1x1 detector">
				<phd unit="%">
					<lowerLevel>25</lowerLevel>
					<upperLevel>70</upperLevel>
				</phd>
				<mode>Scanning snapshot equatorial</mode>
				<activeChannelsEquatorial>255</activeChannelsEquatorial>
				<activeChannelsAxial>255</activeChannelsAxial>
				<pitchEquatorial unit="mm">0.05500</pitchEquatorial>
				<pitchAxial unit="mm">0.05500</pitchAxial>
				<readOutPeriod unit="seconds">0.980</readOutPeriod>
			</detector>
		</diffractedBeamPath>
		<scan status="Completed" appendNumber="0" scanAxis="2Theta" mode="Continuous">
			<header>
				<startTimeStamp>2024-10-29T15:44:48-04:00</startTimeStamp>
				<endTimeStamp>2024-10-29T16:14:46-04:00</endTimeStamp>
				<author>
					<name>ib355</name>
				</author>
				<source>
					<applicationSoftware version="7.1">Data Collector</applicationSoftware>
					<instrumentControlSoftware version="8.2  20201204">EMPYREAN</instrumentControlSoftware>
					<instrumentID>0000000011260721</instrumentID>
				</source>
			</header>
			<dataPoints>
				<positions axis="2Theta" unit="deg">
					<startPosition>72.0584063943918</startPosition>
					<endPosition>75.4056761656082</endPosition>
				</positions>
				<positions axis="Omega" unit="deg">
					<commonPosition>18.32752064</commonPosition>
				</positions>
				<positions axis="Phi" unit="deg">
					<commonPosition>-91.57</commonPosition>
				</positions>
				<positions axis="Chi" unit="deg">
					<commonPosition>0</commonPosition>
				</positions>
				<positions axis="Z" unit="mm">
					<commonPosition>8.368</commonPosition>
				</positions>
				<commonCountingTime unit="seconds">0.974</commonCountingTime>
				<counts unit="counts">0 0 1 0 0 0 0 0 0 0 0 0 0 1 0 1 1 0 0 0 1 0 0 1 0 0 1 0 0 0 0 0 0 0 2 0 1 0 0 0 0 0 0 0 0 2 0 0 0 0 0 0 0 0 0 0 0 0 0 0 0 0 1 1 0 0 0 1 0 0 1 1 0 0 0 0 0 0 0 1 0 0 0 1 0 0 0 0 0 0 0 0 1 1 0 0 0 0 0 0 0 0 0 0 0 0 1 0 0 1 0 0 1 0 0 0 0 0 1 1 0 1 0 0 0 0 0 0 1 1 0 0 1 0 0 0 0 0 0 0 0 0 0 0 0 0 0 0 0 0 1 0 0 0 0 0 0 0 0 0 0 0 1 0 0 0 2 1 0 0 1 0 2 0 0 0 1 2 0 0 0 0 0 0 0 0 1 0 1 0 1 0 0 1 1 0 0 1 1 0 0 0 0 0 0 0 0 0 0 0 0 0 0 0 0 0 0 1 0 0 0 1 0 0 0 0 0 0 0 1 1 0 1 0 0 0 0 0 1 0 0 2 0 0 0 0 0 0 0 0 0 0 0 1 2</counts>
			</dataPoints>
		</scan>
		<scan status="Completed" appendNumber="0" scanAxis="2Theta" mode="Continuous">
			<header>
				<startTimeStamp>2024-10-29T15:44:48-04:00</startTimeStamp>
				<endTimeStamp>2024-10-29T16:14:46-04:00</endTimeStamp>
				<author>
					<name>ib355</name>
				</author>
				<source>
					<applicationSoftware version="7.1">Data Collector</applicationSoftware>
					<instrumentControlSoftware version="8.2  20201204">EMPYREAN</instrumentControlSoftware>
					<instrumentID>0000000011260721</instrumentID>
				</source>
			</header>
			<dataPoints>
				<positions axis="2Theta" unit="deg">
					<startPosition>72.0616889650599</startPosition>
					<endPosition>75.4089587362764</endPosition>
				</positions>
				<positions axis="Omega" unit="deg">
					<commonPosition>18.3291619253341</commonPosition>
				</positions>
				<positions axis="Phi" unit="deg">
					<commonPosition>-91.57</commonPosition>
				</positions>
				<positions axis="Chi" unit="deg">
					<commonPosition>0</commonPosition>
				</positions>
				<positions axis="Z" unit="mm">
					<commonPosition>8.368</commonPosition>
				</positions>
				<commonCountingTime unit="seconds">0.974</commonCountingTime>
				<counts unit="counts">0 0 0 0 0 2 0 1 0 1 0 1 2 0 1 0 0 1 2 0 0 0 0 1 0 0 0 0 0 0 1 0 0 0 0 0 0 0 0 0 0 1 1 0 1 0 0 0 0 1 0 0 0 0 0 1 0 1 0 0 0 1 0 0 0 0 0 0 0 0 1 1 1 0 4 0 0 1 0 0 1 0 0 0 0 1 1 1 0 0 1 0 0 0 0 0 0 1 0 0 0 0 0 0 0 0 0 1 0 1 0 0 1 0 1 0 0 0 0 1 0 0 0 0 0 0 0 0 0 0 0 0 1 0 1 2 1 0 0 0 0 0 0 0 0 0 1 0 0 0 0 0 0 2 2 0 0 0 0 2 0 0 0 0 1 0 0 1 0 0 1 0 0 0 0 0 0 0 0 0 0 0 0 1 1 0 0 0 1 0 0 1 0 0 0 1 0 0 0 1 0 0 0 1 1 0 1 0 0 1 0 0 0 0 0 0 0 0 1 1 0 0 0 0 0 1 0 1 1 1 0 0 1 0 0 0 0 0 0 0 0 0 1 0 0 1 0 1 0 0 1 0 0 0 0</counts>
			</dataPoints>
		</scan>
		<scan status="Completed" appendNumber="0" scanAxis="2Theta" mode="Continuous">
			<header>
				<startTimeStamp>2024-10-29T15:44:48-04:00</startTimeStamp>
				<endTimeStamp>2024-10-29T16:14:46-04:00</endTimeStamp>
				<author>
					<name>ib355</name>
				</author>
				<source>
					<applicationSoftware version="7.1">Data Collector</applicationSoftware>
					<instrumentControlSoftware version="8.2  20201204">EMPYREAN</instrumentControlSoftware>
					<instrumentID>0000000011260721</instrumentID>
				</source>
			</header>
			<dataPoints>
				<positions axis="2Theta" unit="deg">
					<startPosition>72.064971535728</startPosition>
					<endPosition>75.4122413069445</endPosition>
				</positions>
				<positions axis="Omega" unit="deg">
					<commonPosition>18.3308032106681</commonPosition>
				</positions>
				<positions axis="Phi" unit="deg">
					<commonPosition>-91.57</commonPosition>
				</positions>
				<positions axis="Chi" unit="deg">
					<commonPosition>0</commonPosition>
				</positions>
				<positions axis="Z" unit="mm">
					<commonPosition>8.368</commonPosition>
				</positions>
				<commonCountingTime unit="seconds">0.974</commonCountingTime>
				<counts unit="counts">0 0 1 0 0 0 0 2 0 1 0 0 0 0 1 0 0 0 0 0 0 1 0 1 0 0 0 0 0 0 0 0 0 0 0 0 1 0 1 0 0 1 0 0 0 1 0 1 0 1 0 1 1 0 1 2 1 1 1 2 0 1 0 0 1 1 0 0 0 0 0 1 0 1 0 0 0 0 0 3 1 1 0 0 3 2 0 0 0 1 1 1 1 1 1 0 0 0 0 0 1 0 2 0 0 0 0 1 1 0 0 0 0 1 0 0 0 0 0 0 0 0 1 0 1 0 0 0 0 0 0 0 1 2 1 0 0 1 1 0 0 0 0 0 0 1 1 1 1 0 0 0 0 0 1 0 0 0 0 0 0 0 0 0 0 0 0 0 1 1 0 2 0 0 1 1 1 0 1 0 0 0 0 0 0 1 0 0 1 0 0 1 0 0 0 0 1 0 3 1 1 1 0 0 0 0 0 0 0 0 0 1 0 0 0 0 0 0 1 0 0 0 0 1 0 0 0 1 0 1 0 1 0 0 0 0 0 1 2 1 0 1 1 0 1 0 0 0 0 0 0 0 0 1 1</counts>
			</dataPoints>
		</scan>
		<scan status="Completed" appendNumber="0" scanAxis="2Theta" mode="Continuous">
			<header>
				<startTimeStamp>2024-10-29T15:44:48-04:00</startTimeStamp>
				<endTimeStamp>2024-10-29T16:14:46-04:00</endTimeStamp>
				<author>
					<name>ib355</name>
				</author>
				<source>
					<applicationSoftware version="7.1">Data Collector</applicationSoftware>
					<instrumentControlSoftware version="8.2  20201204">EMPYREAN</instrumentControlSoftware>
					<instrumentID>0000000011260721</instrumentID>
				</source>
			</header>
			<dataPoints>
				<positions axis="2Theta" unit="deg">
					<startPosition>72.0682541063962</startPosition>
					<endPosition>75.4155238776126</endPosition>
				</positions>
				<positions axis="Omega" unit="deg">
					<commonPosition>18.3324444960022</commonPosition>
				</positions>
				<positions axis="Phi" unit="deg">
					<commonPosition>-91.57</commonPosition>
				</positions>
				<positions axis="Chi" unit="deg">
					<commonPosition>0</commonPosition>
				</positions>
				<positions axis="Z" unit="mm">
					<commonPosition>8.368</commonPosition>
				</positions>
				<commonCountingTime unit="seconds">0.974</commonCountingTime>
				<counts unit="counts">0 0 1 0 0 0 0 0 0 0 0 1 1 0 0 0 0 0 1 0 0 0 0 0 0 1 0 0 2 1 0 3 0 0 0 0 0 0 0 1 0 0 0 1 0 0 1 0 0 0 1 0 1 0 0 1 0 0 0 1 0 0 1 1 0 0 0 0 1 0 0 2 0 0 1 0 0 0 1 0 0 1 2 0 1 1 0 0 0 0 0 1 0 0 2 0 0 1 0 0 0 1 0 0 0 0 0 0 0 0 0 0 0 0 0 0 0 0 1 1 0 1 1 0 0 0 0 1 0 2 0 0 0 0 0 1 0 1 0 0 0 0 0 0 0 0 0 0 2 0 0 1 0 0 0 0 0 0 0 0 1 0 1 0 0 0 0 0 1 1 2 0 2 0 0 0 0 0 0 0 0 0 1 0 1 0 0 0 0 0 0 0 1 0 1 0 1 2 1 1 0 1 0 0 0 1 0 1 0 1 1 0 0 0 0 1 0 0 0 1 0 0 0 1 0 0 0 0 0 0 0 1 0 0 0 0 1 0 0 1 0 0 1 0 0 0 0 0 1 0 0 0 0 0 0</counts>
			</dataPoints>
		</scan>
		<scan status="Completed" appendNumber="0" scanAxis="2Theta" mode="Continuous">
			<header>
				<startTimeStamp>2024-10-29T15:44:48-04:00</startTimeStamp>
				<endTimeStamp>2024-10-29T16:14:46-04:00</endTimeStamp>
				<author>
					<name>ib355</name>
				</author>
				<source>
					<applicationSoftware version="7.1">Data Collector</applicationSoftware>
					<instrumentControlSoftware version="8.2  20201204">EMPYREAN</instrumentControlSoftware>
					<instrumentID>0000000011260721</instrumentID>
				</source>
			</header>
			<dataPoints>
				<positions axis="2Theta" unit="deg">
					<startPosition>72.0715366770643</startPosition>
					<endPosition>75.4188064482807</endPosition>
				</positions>
				<positions axis="Omega" unit="deg">
					<commonPosition>18.3340857813363</commonPosition>
				</positions>
				<positions axis="Phi" unit="deg">
					<commonPosition>-91.57</commonPosition>
				</positions>
				<positions axis="Chi" unit="deg">
					<commonPosition>0</commonPosition>
				</positions>
				<positions axis="Z" unit="mm">
					<commonPosition>8.368</commonPosition>
				</positions>
				<commonCountingTime unit="seconds">0.974</commonCountingTime>
				<counts unit="counts">0 1 0 0 0 0 0 0 2 0 0 0 1 0 0 0 0 1 1 0 0 0 1 0 0 0 2 1 0 0 0 0 0 0 0 0 1 0 0 2 0 1 0 0 1 2 0 0 0 0 0 0 0 1 0 0 1 0 0 0 1 1 0 0 0 0 0 1 0 0 0 0 1 0 0 0 2 0 0 0 0 1 0 1 0 0 0 0 1 2 0 0 0 0 0 0 1 0 0 0 1 0 0 0 0 1 0 0 0 0 0 0 0 0 0 0 0 0 0 0 0 0 0 1 0 1 0 0 0 0 0 0 1 0 0 0 0 0 0 0 0 0 0 1 0 1 0 0 0 2 0 0 1 1 0 0 0 1 1 0 0 0 0 0 0 1 2 0 0 0 0 0 0 0 0 0 0 0 0 0 1 0 0 0 2 0 0 1 1 0 0 0 0 0 0 0 1 0 2 0 0 0 0 1 1 1 0 0 1 0 1 1 0 0 1 0 0 0 1 0 0 1 0 0 1 0 0 0 0 1 0 2 1 0 0 1 0 0 0 0 0 2 0 0 0 0 0 0 0 0 0 0 0 0 0</counts>
			</dataPoints>
		</scan>
		<scan status="Completed" appendNumber="0" scanAxis="2Theta" mode="Continuous">
			<header>
				<startTimeStamp>2024-10-29T15:44:48-04:00</startTimeStamp>
				<endTimeStamp>2024-10-29T16:14:46-04:00</endTimeStamp>
				<author>
					<name>ib355</name>
				</author>
				<source>
					<applicationSoftware version="7.1">Data Collector</applicationSoftware>
					<instrumentControlSoftware version="8.2  20201204">EMPYREAN</instrumentControlSoftware>
					<instrumentID>0000000011260721</instrumentID>
				</source>
			</header>
			<dataPoints>
				<positions axis="2Theta" unit="deg">
					<startPosition>72.0748192477324</startPosition>
					<endPosition>75.4220890189489</endPosition>
				</positions>
				<positions axis="Omega" unit="deg">
					<commonPosition>18.3357270666703</commonPosition>
				</positions>
				<positions axis="Phi" unit="deg">
					<commonPosition>-91.57</commonPosition>
				</positions>
				<positions axis="Chi" unit="deg">
					<commonPosition>0</commonPosition>
				</positions>
				<positions axis="Z" unit="mm">
					<commonPosition>8.368</commonPosition>
				</positions>
				<commonCountingTime unit="seconds">0.974</commonCountingTime>
				<counts unit="counts">0 1 0 0 0 1 2 1 0 0 0 0 0 1 0 0 0 0 0 0 1 0 0 1 0 0 1 1 0 1 0 1 0 1 1 0 0 0 1 1 0 0 0 0 0 0 0 0 0 0 0 0 1 1 0 1 0 0 0 1 0 1 0 0 0 0 0 0 0 0 0 1 0 0 1 0 0 0 0 0 0 1 0 0 0 0 0 1 1 0 0 0 0 0 0 0 0 0 0 1 0 0 0 0 0 0 0 0 0 0 0 1 0 1 0 1 0 0 0 1 1 0 0 0 0 0 1 0 0 1 0 0 0 0 0 0 1 0 0 0 0 1 0 1 0 0 0 1 0 0 1 0 0 0 0 0 0 0 0 0 1 0 0 0 0 0 1 0 1 0 0 0 0 1 0 0 0 1 1 0 0 0 0 2 0 0 0 0 0 0 0 0 1 0 0 2 0 0 0 0 1 1 1 0 0 0 0 0 0 2 0 1 0 1 0 0 0 2 1 0 0 0 0 0 0 0 0 0 0 0 1 0 0 0 1 1 0 1 0 1 0 1 0 0 0 0 0 0 1 0 0 0 0 0 0</counts>
			</dataPoints>
		</scan>
		<scan status="Completed" appendNumber="0" scanAxis="2Theta" mode="Continuous">
			<header>
				<startTimeStamp>2024-10-29T15:44:48-04:00</startTimeStamp>
				<endTimeStamp>2024-10-29T16:14:46-04:00</endTimeStamp>
				<author>
					<name>ib355</name>
				</author>
				<source>
					<applicationSoftware version="7.1">Data Collector</applicationSoftware>
					<instrumentControlSoftware version="8.2  20201204">EMPYREAN</instrumentControlSoftware>
					<instrumentID>0000000011260721</instrumentID>
				</source>
			</header>
			<dataPoints>
				<positions axis="2Theta" unit="deg">
					<startPosition>72.0781018184005</startPosition>
					<endPosition>75.425371589617</endPosition>
				</positions>
				<positions axis="Omega" unit="deg">
					<commonPosition>18.3373683520044</commonPosition>
				</positions>
				<positions axis="Phi" unit="deg">
					<commonPosition>-91.57</commonPosition>
				</positions>
				<positions axis="Chi" unit="deg">
					<commonPosition>0</commonPosition>
				</positions>
				<positions axis="Z" unit="mm">
					<commonPosition>8.368</commonPosition>
				</positions>
				<commonCountingTime unit="seconds">0.974</commonCountingTime>
				<counts unit="counts">0 0 0 0 1 0 0 0 0 0 0 0 0 0 2 0 0 1 0 0 0 1 1 0 1 0 0 1 1 0 0 0 0 0 0 0 0 0 0 0 1 0 0 1 0 0 0 0 0 0 0 0 1 1 1 0 0 0 1 0 1 1 0 0 1 1 2 0 0 0 0 1 0 0 0 0 2 0 0 0 0 0 0 0 0 0 0 0 0 0 0 1 0 0 0 0 1 0 0 2 0 0 0 1 0 0 0 1 0 0 0 0 1 0 0 0 0 0 0 0 0 1 0 0 1 0 0 0 0 1 0 0 0 0 0 0 1 0 0 2 0 1 0 0 1 0 1 0 0 1 0 0 0 0 0 1 0 0 0 1 0 0 1 0 0 0 1 0 0 1 0 0 1 0 0 0 0 0 0 0 0 0 0 0 0 0 0 2 0 1 0 0 1 0 2 1 0 0 0 0 1 0 0 0 1 0 1 0 1 0 0 0 1 0 0 1 0 0 0 0 2 0 1 2 0 2 1 1 1 0 0 0 1 1 1 0 2 0 0 0 0 2 1 0 1 0 0 0 0 0 0 0 0 0 0</counts>
			</dataPoints>
		</scan>
		<scan status="Completed" appendNumber="0" scanAxis="2Theta" mode="Continuous">
			<header>
				<startTimeStamp>2024-10-29T15:44:48-04:00</startTimeStamp>
				<endTimeStamp>2024-10-29T16:14:46-04:00</endTimeStamp>
				<author>
					<name>ib355</name>
				</author>
				<source>
					<applicationSoftware version="7.1">Data Collector</applicationSoftware>
					<instrumentControlSoftware version="8.2  20201204">EMPYREAN</instrumentControlSoftware>
					<instrumentID>0000000011260721</instrumentID>
				</source>
			</header>
			<dataPoints>
				<positions axis="2Theta" unit="deg">
					<startPosition>72.0813843890687</startPosition>
					<endPosition>75.4286541602851</endPosition>
				</positions>
				<positions axis="Omega" unit="deg">
					<commonPosition>18.3390096373384</commonPosition>
				</positions>
				<positions axis="Phi" unit="deg">
					<commonPosition>-91.57</commonPosition>
				</positions>
				<positions axis="Chi" unit="deg">
					<commonPosition>0</commonPosition>
				</positions>
				<positions axis="Z" unit="mm">
					<commonPosition>8.368</commonPosition>
				</positions>
				<commonCountingTime unit="seconds">0.974</commonCountingTime>
				<counts unit="counts">0 1 0 1 0 0 0 0 0 0 0 0 1 0 0 1 0 1 0 0 0 0 1 0 0 0 0 0 0 0 0 0 1 0 0 1 0 0 1 0 1 2 0 3 0 0 0 0 0 0 0 0 1 0 0 0 1 0 0 0 1 1 0 0 1 0 0 0 0 1 0 1 0 0 0 1 1 0 1 0 1 0 0 0 0 0 2 0 0 0 1 0 0 0 1 0 0 0 0 0 0 1 0 1 0 0 0 0 0 0 2 1 0 0 0 0 0 0 0 0 0 0 1 0 1 0 0 0 0 2 0 0 0 0 1 0 0 2 0 0 0 1 1 1 0 1 0 0 0 1 0 0 0 1 0 0 1 0 1 1 0 0 1 0 0 1 0 0 0 0 0 0 0 0 0 1 0 0 1 1 0 0 0 0 1 0 1 0 2 0 0 0 0 1 0 0 1 0 0 2 0 1 0 1 1 0 1 0 0 0 0 0 0 1 0 0 0 1 0 0 0 0 0 0 0 1 0 1 0 0 1 0 1 0 1 0 0 1 0 0 1 0 0 1 0 0 0 0 0 0 0 0 0 0 0</counts>
			</dataPoints>
		</scan>
		<scan status="Completed" appendNumber="0" scanAxis="2Theta" mode="Continuous">
			<header>
				<startTimeStamp>2024-10-29T15:44:48-04:00</startTimeStamp>
				<endTimeStamp>2024-10-29T16:14:46-04:00</endTimeStamp>
				<author>
					<name>ib355</name>
				</author>
				<source>
					<applicationSoftware version="7.1">Data Collector</applicationSoftware>
					<instrumentControlSoftware version="8.2  20201204">EMPYREAN</instrumentControlSoftware>
					<instrumentID>0000000011260721</instrumentID>
				</source>
			</header>
			<dataPoints>
				<positions axis="2Theta" unit="deg">
					<startPosition>72.0846669597368</startPosition>
					<endPosition>75.4319367309533</endPosition>
				</positions>
				<positions axis="Omega" unit="deg">
					<commonPosition>18.3406509226725</commonPosition>
				</positions>
				<positions axis="Phi" unit="deg">
					<commonPosition>-91.57</commonPosition>
				</positions>
				<positions axis="Chi" unit="deg">
					<commonPosition>0</commonPosition>
				</positions>
				<positions axis="Z" unit="mm">
					<commonPosition>8.368</commonPosition>
				</positions>
				<commonCountingTime unit="seconds">0.974</commonCountingTime>
				<counts unit="counts">0 0 1 1 0 1 0 0 1 0 0 1 1 1 0 0 1 0 0 0 1 0 0 1 1 0 1 0 1 0 0 1 1 1 0 0 0 1 1 1 0 0 0 0 0 0 0 0 1 1 1 0 0 0 0 1 1 1 1 0 0 0 0 0 0 0 0 0 0 0 0 0 1 1 0 0 2 0 0 0 1 0 1 0 1 0 0 0 2 0 1 0 0 0 1 1 0 0 1 0 0 0 0 0 1 0 1 0 1 1 0 1 0 0 2 1 0 0 0 1 1 1 1 1 0 0 0 0 0 0 0 0 1 0 1 0 0 0 1 0 0 0 0 0 0 0 0 0 0 1 1 0 2 1 1 0 0 0 0 0 0 0 0 0 0 0 0 0 0 0 0 1 0 0 1 0 2 0 0 0 1 0 0 1 0 0 0 0 0 1 0 0 0 0 2 1 2 0 0 0 0 1 1 0 0 0 0 0 0 0 0 0 2 0 1 0 0 1 0 0 0 0 0 0 0 0 1 0 0 0 1 0 0 1 2 0 0 0 0 0 2 0 1 0 2 0 1 1 1 0 0 0 1 0 0</counts>
			</dataPoints>
		</scan>
		<scan status="Completed" appendNumber="0" scanAxis="2Theta" mode="Continuous">
			<header>
				<startTimeStamp>2024-10-29T15:44:48-04:00</startTimeStamp>
				<endTimeStamp>2024-10-29T16:14:46-04:00</endTimeStamp>
				<author>
					<name>ib355</name>
				</author>
				<source>
					<applicationSoftware version="7.1">Data Collector</applicationSoftware>
					<instrumentControlSoftware version="8.2  20201204">EMPYREAN</instrumentControlSoftware>
					<instrumentID>0000000011260721</instrumentID>
				</source>
			</header>
			<dataPoints>
				<positions axis="2Theta" unit="deg">
					<startPosition>72.0879495304049</startPosition>
					<endPosition>75.4352193016214</endPosition>
				</positions>
				<positions axis="Omega" unit="deg">
					<commonPosition>18.3422922080066</commonPosition>
				</positions>
				<positions axis="Phi" unit="deg">
					<commonPosition>-91.57</commonPosition>
				</positions>
				<positions axis="Chi" unit="deg">
					<commonPosition>0</commonPosition>
				</positions>
				<positions axis="Z" unit="mm">
					<commonPosition>8.368</commonPosition>
				</positions>
				<commonCountingTime unit="seconds">0.974</commonCountingTime>
				<counts unit="counts">0 0 0 0 0 0 0 0 0 1 2 1 0 0 1 0 0 1 1 0 0 0 0 0 1 0 0 0 0 1 0 0 0 2 1 0 0 0 0 0 1 0 0 0 0 0 0 0 0 0 0 0 0 0 0 0 1 0 2 0 0 1 0 0 1 2 0 1 0 0 1 0 0 1 0 0 1 0 1 0 0 0 2 0 1 0 0 0 0 0 1 1 0 0 0 1 0 1 0 1 0 0 0 0 1 0 0 0 1 0 0 0 0 0 0 0 0 0 0 0 0 0 0 0 0 0 0 0 0 0 0 0 1 0 1 0 1 1 0 0 0 0 0 0 0 0 0 0 0 0 0 0 0 0 0 0 0 0 0 0 0 0 0 0 0 0 0 0 0 0 0 0 0 0 0 1 0 0 0 0 0 0 0 2 0 1 0 0 0 0 1 0 0 2 0 0 2 0 0 0 0 0 0 0 2 0 0 0 0 0 1 0 2 0 1 0 0 0 0 0 0 0 1 0 1 1 0 0 0 1 0 0 0 0 0 0 0 0 0 0 1 1 0 0 0 5 0 0 0 0 0 0 0 1 1</counts>
			</dataPoints>
		</scan>
		<scan status="Completed" appendNumber="0" scanAxis="2Theta" mode="Continuous">
			<header>
				<startTimeStamp>2024-10-29T15:44:48-04:00</startTimeStamp>
				<endTimeStamp>2024-10-29T16:14:46-04:00</endTimeStamp>
				<author>
					<name>ib355</name>
				</author>
				<source>
					<applicationSoftware version="7.1">Data Collector</applicationSoftware>
					<instrumentControlSoftware version="8.2  20201204">EMPYREAN</instrumentControlSoftware>
					<instrumentID>0000000011260721</instrumentID>
				</source>
			</header>
			<dataPoints>
				<positions axis="2Theta" unit="deg">
					<startPosition>72.091232101073</startPosition>
					<endPosition>75.4385018722895</endPosition>
				</positions>
				<positions axis="Omega" unit="deg">
					<commonPosition>18.3439334933406</commonPosition>
				</positions>
				<positions axis="Phi" unit="deg">
					<commonPosition>-91.57</commonPosition>
				</positions>
				<positions axis="Chi" unit="deg">
					<commonPosition>0</commonPosition>
				</positions>
				<positions axis="Z" unit="mm">
					<commonPosition>8.368</commonPosition>
				</positions>
				<commonCountingTime unit="seconds">0.974</commonCountingTime>
				<counts unit="counts">0 0 0 0 0 0 0 0 0 1 0 0 0 0 0 0 0 1 0 2 0 2 0 0 0 0 1 1 1 0 1 0 0 1 0 0 0 0 0 0 1 0 0 0 2 2 0 0 0 0 1 0 1 0 0 0 0 0 1 2 0 0 0 0 0 0 0 0 0 0 0 0 1 1 0 1 0 2 0 0 0 0 0 1 0 0 1 0 0 1 1 2 0 0 0 1 0 0 0 1 1 0 0 0 0 1 0 0 0 0 0 0 1 0 0 0 1 0 0 0 0 0 1 0 0 0 0 0 0 1 0 1 0 0 0 0 0 0 0 0 0 0 0 1 1 0 0 0 0 1 1 0 0 0 0 0 0 0 1 0 2 1 1 1 0 0 0 2 0 0 1 0 0 0 0 0 0 0 0 1 0 0 0 0 1 0 1 1 0 0 0 0 0 1 1 0 0 0 0 0 0 0 0 0 1 0 0 0 0 0 0 1 0 2 0 0 1 1 0 1 0 0 0 0 0 0 0 0 0 0 1 0 0 0 0 0 0 0 0 1 1 0 0 1 1 0 1 1 0 0 0 1 1 0 0</counts>
			</dataPoints>
		</scan>
		<scan status="Completed" appendNumber="0" scanAxis="2Theta" mode="Continuous">
			<header>
				<startTimeStamp>2024-10-29T15:44:48-04:00</startTimeStamp>
				<endTimeStamp>2024-10-29T16:14:46-04:00</endTimeStamp>
				<author>
					<name>ib355</name>
				</author>
				<source>
					<applicationSoftware version="7.1">Data Collector</applicationSoftware>
					<instrumentControlSoftware version="8.2  20201204">EMPYREAN</instrumentControlSoftware>
					<instrumentID>0000000011260721</instrumentID>
				</source>
			</header>
			<dataPoints>
				<positions axis="2Theta" unit="deg">
					<startPosition>72.0945146717412</startPosition>
					<endPosition>75.4417844429576</endPosition>
				</positions>
				<positions axis="Omega" unit="deg">
					<commonPosition>18.3455747786747</commonPosition>
				</positions>
				<positions axis="Phi" unit="deg">
					<commonPosition>-91.57</commonPosition>
				</positions>
				<positions axis="Chi" unit="deg">
					<commonPosition>0</commonPosition>
				</positions>
				<positions axis="Z" unit="mm">
					<commonPosition>8.368</commonPosition>
				</positions>
				<commonCountingTime unit="seconds">0.974</commonCountingTime>
				<counts unit="counts">1 0 0 0 1 0 0 0 1 0 0 0 0 2 1 0 0 1 0 1 0 1 1 0 0 1 1 2 0 0 0 0 2 2 0 0 2 0 0 0 0 0 0 1 0 1 0 0 0 0 0 1 0 1 2 1 0 1 0 0 1 0 0 0 0 0 0 0 0 0 0 1 0 0 0 1 0 0 1 0 0 0 0 1 0 0 1 0 0 2 0 1 0 0 0 0 0 0 0 1 0 2 0 0 1 0 0 0 0 0 1 0 1 1 0 0 0 1 0 0 0 2 0 0 0 1 0 1 0 0 0 0 1 0 1 0 1 0 0 0 0 0 0 0 0 0 0 0 0 0 1 0 0 0 0 1 0 0 1 0 0 1 0 0 0 0 0 0 0 1 1 0 0 0 0 0 0 0 0 0 0 0 0 0 2 1 0 0 0 0 0 1 1 0 1 0 0 1 0 1 0 1 1 0 0 2 0 0 0 0 0 0 0 0 0 2 2 0 1 0 0 1 0 0 0 1 0 1 0 0 0 1 1 0 0 0 0 0 0 1 0 0 1 0 0 0 0 0 0 1 1 0 0 0 1</counts>
			</dataPoints>
		</scan>
		<scan status="Completed" appendNumber="0" scanAxis="2Theta" mode="Continuous">
			<header>
				<startTimeStamp>2024-10-29T15:44:48-04:00</startTimeStamp>
				<endTimeStamp>2024-10-29T16:14:46-04:00</endTimeStamp>
				<author>
					<name>ib355</name>
				</author>
				<source>
					<applicationSoftware version="7.1">Data Collector</applicationSoftware>
					<instrumentControlSoftware version="8.2  20201204">EMPYREAN</instrumentControlSoftware>
					<instrumentID>0000000011260721</instrumentID>
				</source>
			</header>
			<dataPoints>
				<positions axis="2Theta" unit="deg">
					<startPosition>72.0977972424093</startPosition>
					<endPosition>75.4450670136258</endPosition>
				</positions>
				<positions axis="Omega" unit="deg">
					<commonPosition>18.3472160640088</commonPosition>
				</positions>
				<positions axis="Phi" unit="deg">
					<commonPosition>-91.57</commonPosition>
				</positions>
				<positions axis="Chi" unit="deg">
					<commonPosition>0</commonPosition>
				</positions>
				<positions axis="Z" unit="mm">
					<commonPosition>8.368</commonPosition>
				</positions>
				<commonCountingTime unit="seconds">0.974</commonCountingTime>
				<counts unit="counts">0 0 0 0 0 0 0 0 0 0 0 1 0 1 0 0 0 0 0 0 1 0 0 0 0 1 1 0 1 1 0 0 0 1 1 1 1 0 0 0 0 1 0 0 1 0 1 0 0 0 0 0 0 0 1 0 0 0 0 0 0 0 0 0 0 0 1 1 0 0 0 0 0 1 0 0 0 0 1 0 1 0 2 0 0 0 0 0 0 1 0 0 0 0 0 0 0 0 0 0 0 0 0 0 1 1 1 0 0 1 0 1 0 1 0 0 0 0 0 0 0 0 0 0 0 0 2 0 0 0 0 0 0 0 0 0 1 0 1 0 0 0 0 0 0 0 0 0 0 0 0 0 0 0 1 1 0 0 0 0 0 0 0 1 1 0 0 0 0 1 0 0 0 0 0 0 0 0 0 1 0 0 0 0 0 0 0 0 2 0 1 0 1 2 1 0 2 0 2 1 0 0 0 0 0 0 0 0 0 0 0 1 0 0 1 0 0 0 0 0 0 1 0 1 1 0 0 0 1 0 0 0 1 0 0 0 0 0 0 0 0 1 0 1 0 1 1 0 0 1 1 0 3 0 0</counts>
			</dataPoints>
		</scan>
		<scan status="Completed" appendNumber="0" scanAxis="2Theta" mode="Continuous">
			<header>
				<startTimeStamp>2024-10-29T15:44:48-04:00</startTimeStamp>
				<endTimeStamp>2024-10-29T16:14:46-04:00</endTimeStamp>
				<author>
					<name>ib355</name>
				</author>
				<source>
					<applicationSoftware version="7.1">Data Collector</applicationSoftware>
					<instrumentControlSoftware version="8.2  20201204">EMPYREAN</instrumentControlSoftware>
					<instrumentID>0000000011260721</instrumentID>
				</source>
			</header>
			<dataPoints>
				<positions axis="2Theta" unit="deg">
					<startPosition>72.1010798130774</startPosition>
					<endPosition>75.4483495842939</endPosition>
				</positions>
				<positions axis="Omega" unit="deg">
					<commonPosition>18.3488573493428</commonPosition>
				</positions>
				<positions axis="Phi" unit="deg">
					<commonPosition>-91.57</commonPosition>
				</positions>
				<positions axis="Chi" unit="deg">
					<commonPosition>0</commonPosition>
				</positions>
				<positions axis="Z" unit="mm">
					<commonPosition>8.368</commonPosition>
				</positions>
				<commonCountingTime unit="seconds">0.974</commonCountingTime>
				<counts unit="counts">0 0 0 0 1 0 0 1 0 0 0 1 0 0 0 0 0 1 0 0 0 0 0 1 1 1 0 0 0 1 0 1 0 0 1 1 0 0 0 0 0 0 0 0 1 0 0 0 2 0 0 0 0 3 0 0 0 1 0 0 0 1 0 0 1 0 0 0 0 0 0 0 0 0 0 1 0 0 0 1 0 0 0 0 0 0 0 0 1 0 0 0 1 1 0 0 0 1 0 0 0 0 0 0 1 0 1 0 1 0 0 0 0 0 1 0 0 0 0 0 0 0 1 1 0 1 1 0 1 0 0 0 0 0 1 1 1 0 0 0 0 0 0 1 1 1 0 0 0 1 0 0 0 1 0 0 0 1 1 0 2 0 1 0 1 0 1 0 0 1 0 0 0 0 0 1 0 2 0 1 0 0 0 0 0 0 0 1 1 0 0 2 0 0 0 0 1 0 0 0 0 1 0 0 0 0 1 0 1 0 0 0 0 0 0 0 0 0 0 1 0 0 0 0 0 0 0 0 1 0 0 0 0 1 0 1 1 0 0 0 0 0 0 1 1 0 0 1 1 0 0 0 1 0 0</counts>
			</dataPoints>
		</scan>
		<scan status="Completed" appendNumber="0" scanAxis="2Theta" mode="Continuous">
			<header>
				<startTimeStamp>2024-10-29T15:44:48-04:00</startTimeStamp>
				<endTimeStamp>2024-10-29T16:14:46-04:00</endTimeStamp>
				<author>
					<name>ib355</name>
				</author>
				<source>
					<applicationSoftware version="7.1">Data Collector</applicationSoftware>
					<instrumentControlSoftware version="8.2  20201204">EMPYREAN</instrumentControlSoftware>
					<instrumentID>0000000011260721</instrumentID>
				</source>
			</header>
			<dataPoints>
				<positions axis="2Theta" unit="deg">
					<startPosition>72.1043623837456</startPosition>
					<endPosition>75.451632154962</endPosition>
				</positions>
				<positions axis="Omega" unit="deg">
					<commonPosition>18.3504986346769</commonPosition>
				</positions>
				<positions axis="Phi" unit="deg">
					<commonPosition>-91.57</commonPosition>
				</positions>
				<positions axis="Chi" unit="deg">
					<commonPosition>0</commonPosition>
				</positions>
				<positions axis="Z" unit="mm">
					<commonPosition>8.368</commonPosition>
				</positions>
				<commonCountingTime unit="seconds">0.974</commonCountingTime>
				<counts unit="counts">2 0 0 0 0 0 0 0 1 0 0 0 2 0 0 0 1 2 0 0 0 0 0 0 0 0 0 2 0 0 1 0 1 1 0 0 0 0 0 1 2 0 0 0 1 2 1 0 0 0 0 0 0 0 0 0 0 0 0 0 1 0 1 0 0 1 0 0 0 0 2 2 1 0 0 0 0 1 0 0 0 0 0 0 0 1 0 0 0 1 1 0 1 0 0 1 0 1 0 0 0 0 1 2 1 0 1 0 1 0 0 0 0 0 0 0 0 0 0 0 0 0 0 1 0 0 0 0 0 0 1 0 0 0 0 0 0 2 0 0 0 0 0 1 0 1 0 0 0 0 0 0 0 0 0 1 0 0 1 0 1 0 0 0 1 0 0 0 0 1 0 0 0 1 0 1 0 0 0 0 0 0 0 0 0 0 0 0 1 0 1 1 0 1 1 1 0 0 0 0 0 0 1 0 0 0 0 1 0 1 0 0 0 0 1 2 0 1 0 0 0 0 0 0 1 0 1 0 0 0 0 0 1 1 1 0 0 0 0 0 0 0 0 0 1 0 0 0 0 0 0 0 0 1 2</counts>
			</dataPoints>
		</scan>
		<scan status="Completed" appendNumber="0" scanAxis="2Theta" mode="Continuous">
			<header>
				<startTimeStamp>2024-10-29T15:44:48-04:00</startTimeStamp>
				<endTimeStamp>2024-10-29T16:14:46-04:00</endTimeStamp>
				<author>
					<name>ib355</name>
				</author>
				<source>
					<applicationSoftware version="7.1">Data Collector</applicationSoftware>
					<instrumentControlSoftware version="8.2  20201204">EMPYREAN</instrumentControlSoftware>
					<instrumentID>0000000011260721</instrumentID>
				</source>
			</header>
			<dataPoints>
				<positions axis="2Theta" unit="deg">
					<startPosition>72.1076449544137</startPosition>
					<endPosition>75.4549147256301</endPosition>
				</positions>
				<positions axis="Omega" unit="deg">
					<commonPosition>18.352139920011</commonPosition>
				</positions>
				<positions axis="Phi" unit="deg">
					<commonPosition>-91.57</commonPosition>
				</positions>
				<positions axis="Chi" unit="deg">
					<commonPosition>0</commonPosition>
				</positions>
				<positions axis="Z" unit="mm">
					<commonPosition>8.368</commonPosition>
				</positions>
				<commonCountingTime unit="seconds">0.974</commonCountingTime>
				<counts unit="counts">1 1 2 1 1 0 0 1 0 0 1 0 1 1 0 0 0 1 1 1 0 2 0 1 0 0 0 0 1 0 0 0 0 0 0 1 0 0 0 1 0 0 0 0 0 0 0 0 0 0 0 0 1 0 0 0 0 0 0 0 0 0 0 1 0 0 0 0 0 0 0 0 1 1 0 0 0 0 0 2 0 0 1 0 0 0 1 0 0 1 1 0 1 0 1 0 0 0 0 0 0 1 0 0 1 0 0 0 0 0 0 0 0 1 0 0 0 1 0 0 0 0 1 0 0 1 0 0 0 0 0 0 0 0 1 0 1 1 1 0 1 0 0 0 1 1 1 0 0 0 0 1 1 0 0 0 0 0 0 1 0 0 0 0 0 0 1 0 0 0 1 0 0 0 1 0 1 1 0 0 0 0 0 0 0 0 1 0 0 0 0 0 0 1 0 0 0 1 0 1 0 0 0 0 0 1 0 0 0 0 0 0 0 0 0 1 0 1 0 0 0 0 1 0 0 0 1 1 0 0 1 0 0 0 1 1 0 1 0 1 1 0 0 1 2 0 0 1 0 2 0 0 1 1 1</counts>
			</dataPoints>
		</scan>
		<scan status="Completed" appendNumber="0" scanAxis="2Theta" mode="Continuous">
			<header>
				<startTimeStamp>2024-10-29T15:44:48-04:00</startTimeStamp>
				<endTimeStamp>2024-10-29T16:14:46-04:00</endTimeStamp>
				<author>
					<name>ib355</name>
				</author>
				<source>
					<applicationSoftware version="7.1">Data Collector</applicationSoftware>
					<instrumentControlSoftware version="8.2  20201204">EMPYREAN</instrumentControlSoftware>
					<instrumentID>0000000011260721</instrumentID>
				</source>
			</header>
			<dataPoints>
				<positions axis="2Theta" unit="deg">
					<startPosition>72.1109275250818</startPosition>
					<endPosition>75.4581972962983</endPosition>
				</positions>
				<positions axis="Omega" unit="deg">
					<commonPosition>18.353781205345</commonPosition>
				</positions>
				<positions axis="Phi" unit="deg">
					<commonPosition>-91.57</commonPosition>
				</positions>
				<positions axis="Chi" unit="deg">
					<commonPosition>0</commonPosition>
				</positions>
				<positions axis="Z" unit="mm">
					<commonPosition>8.368</commonPosition>
				</positions>
				<commonCountingTime unit="seconds">0.974</commonCountingTime>
				<counts unit="counts">0 2 0 1 0 1 0 0 1 1 0 0 0 1 0 0 0 0 0 0 0 0 0 0 1 0 0 0 0 1 1 0 2 1 0 0 0 1 0 1 0 1 1 0 1 0 0 1 0 1 0 1 0 0 1 0 0 0 0 0 0 0 0 1 0 0 0 0 1 0 0 1 0 0 1 0 0 0 0 0 0 2 0 0 0 0 0 0 0 0 0 1 0 0 0 0 0 0 0 0 0 1 0 0 1 0 0 0 0 1 0 1 1 1 0 0 1 0 0 0 0 0 0 0 0 0 0 0 0 0 0 0 0 0 0 1 1 0 1 0 0 1 0 0 0 0 0 0 0 0 0 1 0 1 1 0 1 0 0 1 0 0 0 0 0 0 1 0 0 0 0 0 0 0 0 1 2 1 1 0 0 0 1 0 0 1 0 0 0 0 1 1 0 0 0 1 0 0 0 1 0 0 0 1 0 0 0 0 0 0 1 1 0 0 0 0 0 0 0 0 0 0 0 1 0 0 1 3 0 1 0 1 1 1 2 1 0 0 1 0 0 1 0 0 0 0 1 0 0 0 0 0 0 1 0</counts>
			</dataPoints>
		</scan>
		<scan status="Completed" appendNumber="0" scanAxis="2Theta" mode="Continuous">
			<header>
				<startTimeStamp>2024-10-29T15:44:48-04:00</startTimeStamp>
				<endTimeStamp>2024-10-29T16:14:46-04:00</endTimeStamp>
				<author>
					<name>ib355</name>
				</author>
				<source>
					<applicationSoftware version="7.1">Data Collector</applicationSoftware>
					<instrumentControlSoftware version="8.2  20201204">EMPYREAN</instrumentControlSoftware>
					<instrumentID>0000000011260721</instrumentID>
				</source>
			</header>
			<dataPoints>
				<positions axis="2Theta" unit="deg">
					<startPosition>72.1142100957499</startPosition>
					<endPosition>75.4614798669664</endPosition>
				</positions>
				<positions axis="Omega" unit="deg">
					<commonPosition>18.3554224906791</commonPosition>
				</positions>
				<positions axis="Phi" unit="deg">
					<commonPosition>-91.57</commonPosition>
				</positions>
				<positions axis="Chi" unit="deg">
					<commonPosition>0</commonPosition>
				</positions>
				<positions axis="Z" unit="mm">
					<commonPosition>8.368</commonPosition>
				</positions>
				<commonCountingTime unit="seconds">0.974</commonCountingTime>
				<counts unit="counts">2 0 1 0 1 0 1 0 0 0 1 0 0 0 0 0 2 0 0 0 0 2 0 0 0 0 0 0 0 0 1 0 0 0 1 0 0 0 0 0 1 1 1 0 0 0 1 2 1 0 0 0 2 0 0 0 0 0 0 0 0 1 0 0 1 0 0 0 1 0 0 0 0 1 1 0 0 0 0 0 0 0 1 0 0 0 0 0 0 0 1 0 0 0 0 0 0 0 0 0 0 0 0 1 0 0 0 0 0 0 1 0 1 0 1 1 1 1 0 0 0 0 0 0 0 0 0 0 0 0 0 1 0 0 0 1 0 0 1 0 0 0 0 0 0 0 1 0 0 2 0 0 0 0 0 1 0 0 0 1 0 0 0 0 0 0 0 0 1 0 0 0 0 0 0 0 0 0 0 1 1 0 0 0 1 0 0 0 1 0 1 2 1 0 0 0 0 0 0 0 0 0 0 1 0 0 0 1 0 2 0 0 0 0 0 1 1 0 0 0 0 1 0 0 1 0 0 0 0 1 0 0 1 0 0 1 0 0 1 0 0 1 1 0 1 1 2 0 1 1 0 0 0 0 0</counts>
			</dataPoints>
		</scan>
		<scan status="Completed" appendNumber="0" scanAxis="2Theta" mode="Continuous">
			<header>
				<startTimeStamp>2024-10-29T15:44:48-04:00</startTimeStamp>
				<endTimeStamp>2024-10-29T16:14:46-04:00</endTimeStamp>
				<author>
					<name>ib355</name>
				</author>
				<source>
					<applicationSoftware version="7.1">Data Collector</applicationSoftware>
					<instrumentControlSoftware version="8.2  20201204">EMPYREAN</instrumentControlSoftware>
					<instrumentID>0000000011260721</instrumentID>
				</source>
			</header>
			<dataPoints>
				<positions axis="2Theta" unit="deg">
					<startPosition>72.1174926664181</startPosition>
					<endPosition>75.4647624376345</endPosition>
				</positions>
				<positions axis="Omega" unit="deg">
					<commonPosition>18.3570637760131</commonPosition>
				</positions>
				<positions axis="Phi" unit="deg">
					<commonPosition>-91.57</commonPosition>
				</positions>
				<positions axis="Chi" unit="deg">
					<commonPosition>0</commonPosition>
				</positions>
				<positions axis="Z" unit="mm">
					<commonPosition>8.368</commonPosition>
				</positions>
				<commonCountingTime unit="seconds">0.974</commonCountingTime>
				<counts unit="counts">0 0 0 0 0 0 0 0 1 0 0 0 0 0 0 1 0 1 0 0 1 1 1 0 0 0 0 0 1 0 0 0 0 0 0 0 0 1 0 0 0 0 0 0 0 1 0 1 0 0 0 0 0 1 0 0 0 0 1 0 0 0 1 1 0 0 1 0 1 2 0 0 0 0 0 1 1 0 0 0 0 1 0 0 1 1 0 1 1 0 0 0 0 0 0 1 1 0 0 0 0 0 1 0 1 0 0 0 1 0 0 0 0 0 0 0 0 0 0 0 1 0 0 1 0 1 0 0 0 0 0 0 0 0 0 1 0 0 0 0 0 1 1 0 0 0 1 0 1 0 0 1 0 0 1 0 1 0 2 0 0 0 0 0 0 0 0 1 0 0 0 0 1 0 0 0 0 1 0 0 1 1 1 0 0 1 0 0 0 0 1 0 1 1 1 1 0 2 2 0 0 0 0 0 0 1 0 0 0 1 1 0 0 0 0 0 2 2 0 0 0 1 0 0 0 0 0 0 0 0 0 0 0 0 0 0 0 0 0 0 0 1 1 0 0 1 0 1 0 1 0 1 1 0 0</counts>
			</dataPoints>
		</scan>
		<scan status="Completed" appendNumber="0" scanAxis="2Theta" mode="Continuous">
			<header>
				<startTimeStamp>2024-10-29T15:44:48-04:00</startTimeStamp>
				<endTimeStamp>2024-10-29T16:14:46-04:00</endTimeStamp>
				<author>
					<name>ib355</name>
				</author>
				<source>
					<applicationSoftware version="7.1">Data Collector</applicationSoftware>
					<instrumentControlSoftware version="8.2  20201204">EMPYREAN</instrumentControlSoftware>
					<instrumentID>0000000011260721</instrumentID>
				</source>
			</header>
			<dataPoints>
				<positions axis="2Theta" unit="deg">
					<startPosition>72.1207752370862</startPosition>
					<endPosition>75.4680450083027</endPosition>
				</positions>
				<positions axis="Omega" unit="deg">
					<commonPosition>18.3587050613472</commonPosition>
				</positions>
				<positions axis="Phi" unit="deg">
					<commonPosition>-91.57</commonPosition>
				</positions>
				<positions axis="Chi" unit="deg">
					<commonPosition>0</commonPosition>
				</positions>
				<positions axis="Z" unit="mm">
					<commonPosition>8.368</commonPosition>
				</positions>
				<commonCountingTime unit="seconds">0.974</commonCountingTime>
				<counts unit="counts">0 1 0 0 1 1 2 0 0 0 0 0 1 1 1 0 0 0 0 0 0 1 1 1 0 0 0 0 0 0 0 0 0 1 0 0 1 0 0 0 0 1 0 0 0 0 0 0 0 0 0 0 0 0 0 2 1 0 0 0 0 1 0 0 0 0 0 0 1 0 0 0 0 0 2 1 0 0 0 0 1 0 0 1 0 0 1 0 0 1 1 0 0 0 0 0 0 1 3 0 0 0 0 1 0 0 0 0 0 1 2 0 0 0 1 1 0 0 0 0 0 0 2 0 0 0 0 1 0 0 0 1 0 0 2 0 0 0 0 0 0 1 0 0 1 0 0 2 1 1 0 0 1 1 1 1 0 0 1 0 0 1 0 1 0 1 0 0 1 0 0 1 0 0 0 0 2 0 0 0 0 0 0 0 1 0 1 0 1 0 0 0 0 0 1 0 1 0 0 0 0 0 0 0 1 0 0 0 0 0 0 0 0 1 0 0 1 0 0 0 0 1 0 0 1 0 0 0 0 0 0 0 0 1 0 0 0 0 0 0 1 0 0 0 0 0 0 2 0 0 0 0 0 0 0</counts>
			</dataPoints>
		</scan>
		<scan status="Completed" appendNumber="0" scanAxis="2Theta" mode="Continuous">
			<header>
				<startTimeStamp>2024-10-29T15:44:48-04:00</startTimeStamp>
				<endTimeStamp>2024-10-29T16:14:46-04:00</endTimeStamp>
				<author>
					<name>ib355</name>
				</author>
				<source>
					<applicationSoftware version="7.1">Data Collector</applicationSoftware>
					<instrumentControlSoftware version="8.2  20201204">EMPYREAN</instrumentControlSoftware>
					<instrumentID>0000000011260721</instrumentID>
				</source>
			</header>
			<dataPoints>
				<positions axis="2Theta" unit="deg">
					<startPosition>72.1240578077543</startPosition>
					<endPosition>75.4713275789708</endPosition>
				</positions>
				<positions axis="Omega" unit="deg">
					<commonPosition>18.3603463466813</commonPosition>
				</positions>
				<positions axis="Phi" unit="deg">
					<commonPosition>-91.57</commonPosition>
				</positions>
				<positions axis="Chi" unit="deg">
					<commonPosition>0</commonPosition>
				</positions>
				<positions axis="Z" unit="mm">
					<commonPosition>8.368</commonPosition>
				</positions>
				<commonCountingTime unit="seconds">0.974</commonCountingTime>
[...]
				</positions>
				<positions axis="Z" unit="mm">
					<commonPosition>8.368</commonPosition>
				</positions>
				<commonCountingTime unit="seconds">0.974</commonCountingTime>
				<counts unit="counts">0 0 0 0 1 1 3 0 0 0 0 0 1 0 0 0 0 1 2 0 1 0 0 0 1 0 1 1 0 0 0 0 0 1 0 0 0 0 0 0 0 0 0 1 0 0 0 1 2 1 0 1 0 0 1 0 0 1 0 0 0 0 0 0 0 0 0 1 0 1 0 0 0 0 0 0 0 0 1 1 0 0 0 0 0 0 0 0 0 0 0 0 0 0 0 0 0 0 1 0 1 0 0 0 0 0 0 0 0 0 0 0 0 1 0 0 0 0 0 0 0 1 0 0 1 0 0 1 3 0 0 0 0 1 0 2 0 0 1 0 0 1 1 0 0 1 0 0 0 0 0 0 1 0 0 0 0 0 0 0 0 0 0 1 0 1 0 0 1 0 0 1 1 0 0 1 0 1 1 0 2 0 0 0 0 2 1 1 1 0 0 0 2 0 0 0 0 0 0 0 0 0 0 0 1 0 1 0 1 0 0 0 0 1 1 0 0 0 0 0 1 0 2 2 0 0 1 0 0 0 0 1 0 0 0 0 1 0 1 0 1 0 0 0 1 0 1 0 0 0 0 0 0 1 0</counts>
			</dataPoints>
		</scan>
		<scan status="Completed" appendNumber="0" scanAxis="2Theta" mode="Continuous">
			<header>
				<startTimeStamp>2024-10-29T15:44:48-04:00</startTimeStamp>
				<endTimeStamp>2024-10-29T16:14:46-04:00</endTimeStamp>
				<author>
					<name>ib355</name>
				</author>
				<source>
					<applicationSoftware version="7.1">Data Collector</applicationSoftware>
					<instrumentControlSoftware version="8.2  20201204">EMPYREAN</instrumentControlSoftware>
					<instrumentID>0000000011260721</instrumentID>
				</source>
			</header>
			<dataPoints>
				<positions axis="2Theta" unit="deg">
					<startPosition>78.0195547277105</startPosition>
					<endPosition>81.366824498927</endPosition>
				</positions>
				<positions axis="Omega" unit="deg">
					<commonPosition>21.3080948066594</commonPosition>
				</positions>
				<positions axis="Phi" unit="deg">
					<commonPosition>-91.57</commonPosition>
				</positions>
				<positions axis="Chi" unit="deg">
					<commonPosition>0</commonPosition>
				</positions>
				<positions axis="Z" unit="mm">
					<commonPosition>8.368</commonPosition>
				</positions>
				<commonCountingTime unit="seconds">0.974</commonCountingTime>
				<counts unit="counts">0 0 1 0 0 0 1 1 0 0 1 1 0 0 0 0 0 0 0 0 0 1 0 1 0 0 0 0 0 0 1 0 0 0 1 0 1 0 0 0 0 0 0 1 1 0 0 0 1 1 0 1 0 0 0 0 0 0 0 0 0 0 1 0 0 0 0 0 0 0 0 0 0 0 1 0 0 0 1 0 0 0 0 1 0 1 0 0 1 1 1 0 0 0 0 0 0 1 0 1 0 0 1 0 1 1 0 0 0 0 0 0 0 1 0 1 0 0 0 0 0 0 1 0 0 0 0 0 0 0 0 0 0 0 1 0 1 1 0 0 1 0 0 0 0 0 0 0 0 0 1 2 0 1 0 0 0 1 2 0 0 0 1 0 0 0 0 0 0 0 0 0 0 0 0 0 0 1 1 1 0 0 1 0 1 0 1 0 0 0 0 0 0 1 0 0 1 0 0 0 0 0 0 0 0 0 0 0 0 0 0 0 1 1 0 0 0 0 1 0 0 0 1 2 1 0 0 1 1 0 0 0 0 0 1 1 0 0 1 0 0 0 0 0 0 1 0 0 1 1 0 0 0 0 0</counts>
			</dataPoints>
		</scan>
		<scan status="Completed" appendNumber="0" scanAxis="2Theta" mode="Continuous">
			<header>
				<startTimeStamp>2024-10-29T15:44:48-04:00</startTimeStamp>
				<endTimeStamp>2024-10-29T16:14:46-04:00</endTimeStamp>
				<author>
					<name>ib355</name>
				</author>
				<source>
					<applicationSoftware version="7.1">Data Collector</applicationSoftware>
					<instrumentControlSoftware version="8.2  20201204">EMPYREAN</instrumentControlSoftware>
					<instrumentID>0000000011260721</instrumentID>
				</source>
			</header>
			<dataPoints>
				<positions axis="2Theta" unit="deg">
					<startPosition>78.0228372983786</startPosition>
					<endPosition>81.3701070695951</endPosition>
				</positions>
				<positions axis="Omega" unit="deg">
					<commonPosition>21.3097360919934</commonPosition>
				</positions>
				<positions axis="Phi" unit="deg">
					<commonPosition>-91.57</commonPosition>
				</positions>
				<positions axis="Chi" unit="deg">
					<commonPosition>0</commonPosition>
				</positions>
				<positions axis="Z" unit="mm">
					<commonPosition>8.368</commonPosition>
				</positions>
				<commonCountingTime unit="seconds">0.974</commonCountingTime>
				<counts unit="counts">0 0 1 1 0 0 1 1 1 1 0 0 0 0 0 0 0 0 0 0 0 0 0 0 0 0 0 0 2 0 0 0 0 0 0 0 0 0 0 1 1 1 0 0 0 0 0 0 2 0 0 0 0 0 0 1 1 0 0 0 0 0 1 0 1 0 0 0 0 0 0 0 0 0 0 0 0 0 1 1 0 0 0 0 0 1 0 0 0 0 0 2 0 1 1 0 0 1 1 0 1 0 0 1 1 1 0 0 0 0 1 0 0 0 0 0 0 0 1 0 0 0 0 1 0 0 0 0 0 0 0 0 0 1 0 0 0 0 0 0 0 1 0 0 0 0 1 0 1 0 0 1 0 2 1 0 0 0 0 1 0 0 0 0 0 0 1 0 0 0 0 0 0 0 0 0 0 0 0 0 1 0 0 0 0 1 0 0 0 0 0 1 0 0 0 1 0 0 0 0 0 0 0 0 0 0 0 0 1 0 0 0 0 0 0 1 0 0 0 1 0 0 0 0 0 0 1 0 0 0 1 0 0 0 0 0 1 0 0 0 0 0 0 0 0 1 0 0 0 0 0 2 0 1 1</counts>
			</dataPoints>
		</scan>
		<scan status="Completed" appendNumber="0" scanAxis="2Theta" mode="Continuous">
			<header>
				<startTimeStamp>2024-10-29T15:44:48-04:00</startTimeStamp>
				<endTimeStamp>2024-10-29T16:14:46-04:00</endTimeStamp>
				<author>
					<name>ib355</name>
				</author>
				<source>
					<applicationSoftware version="7.1">Data Collector</applicationSoftware>
					<instrumentControlSoftware version="8.2  20201204">EMPYREAN</instrumentControlSoftware>
					<instrumentID>0000000011260721</instrumentID>
				</source>
			</header>
			<dataPoints>
				<positions axis="2Theta" unit="deg">
					<startPosition>78.0261198690467</startPosition>
					<endPosition>81.3733896402632</endPosition>
				</positions>
				<positions axis="Omega" unit="deg">
					<commonPosition>21.3113773773275</commonPosition>
				</positions>
				<positions axis="Phi" unit="deg">
					<commonPosition>-91.57</commonPosition>
				</positions>
				<positions axis="Chi" unit="deg">
					<commonPosition>0</commonPosition>
				</positions>
				<positions axis="Z" unit="mm">
					<commonPosition>8.368</commonPosition>
				</positions>
				<commonCountingTime unit="seconds">0.974</commonCountingTime>
				<counts unit="counts">0 0 0 0 0 0 0 1 1 0 0 1 1 0 0 1 1 2 1 0 1 0 0 0 0 0 0 1 0 0 0 0 0 0 0 0 0 1 0 0 0 0 0 0 1 2 1 1 0 0 1 1 0 0 0 0 1 1 0 0 1 0 0 0 1 0 0 0 1 0 0 0 0 0 0 0 1 0 0 0 0 1 1 0 0 0 0 1 0 0 0 0 0 0 1 0 0 0 0 1 2 0 0 0 0 1 1 0 0 1 0 0 3 0 0 0 0 1 1 1 0 0 0 0 0 0 0 0 2 0 0 0 0 0 2 0 0 0 0 0 0 1 0 1 0 0 1 0 1 0 0 1 0 0 1 0 0 0 0 0 1 0 0 0 1 0 0 0 0 1 0 0 0 0 0 1 0 1 0 0 0 0 0 0 1 0 0 0 0 0 0 0 0 0 0 0 0 1 0 0 0 0 0 1 0 1 0 0 0 0 1 0 1 1 0 0 0 0 0 0 0 0 0 0 1 0 0 0 0 0 0 0 0 0 0 0 0 0 0 0 0 0 0 0 1 1 0 0 1 0 0 0 0 1 0</counts>
			</dataPoints>
		</scan>
		<scan status="Completed" appendNumber="0" scanAxis="2Theta" mode="Continuous">
			<header>
				<startTimeStamp>2024-10-29T15:44:48-04:00</startTimeStamp>
				<endTimeStamp>2024-10-29T16:14:46-04:00</endTimeStamp>
				<author>
					<name>ib355</name>
				</author>
				<source>
					<applicationSoftware version="7.1">Data Collector</applicationSoftware>
					<instrumentControlSoftware version="8.2  20201204">EMPYREAN</instrumentControlSoftware>
					<instrumentID>0000000011260721</instrumentID>
				</source>
			</header>
			<dataPoints>
				<positions axis="2Theta" unit="deg">
					<startPosition>78.0294024397149</startPosition>
					<endPosition>81.3766722109313</endPosition>
				</positions>
				<positions axis="Omega" unit="deg">
					<commonPosition>21.3130186626616</commonPosition>
				</positions>
				<positions axis="Phi" unit="deg">
					<commonPosition>-91.57</commonPosition>
				</positions>
				<positions axis="Chi" unit="deg">
					<commonPosition>0</commonPosition>
				</positions>
				<positions axis="Z" unit="mm">
					<commonPosition>8.368</commonPosition>
				</positions>
				<commonCountingTime unit="seconds">0.974</commonCountingTime>
				<counts unit="counts">1 0 3 1 0 0 0 2 0 0 1 1 0 1 0 0 0 0 0 0 0 0 0 0 0 0 0 0 0 0 0 0 1 0 1 0 0 2 0 1 1 0 0 1 1 0 0 1 0 1 0 0 0 0 3 1 1 0 0 3 0 1 0 1 0 0 0 1 0 0 0 0 0 0 0 0 0 0 1 1 0 0 1 0 0 0 0 1 1 1 0 1 0 0 0 0 1 1 1 0 0 1 0 0 1 0 0 1 0 1 0 0 0 0 0 0 0 0 0 2 0 0 0 0 0 0 0 0 0 0 1 0 0 1 0 1 2 0 0 0 0 0 0 0 0 1 1 0 0 0 1 0 0 0 1 0 0 1 0 0 0 0 1 1 1 0 1 0 0 0 0 0 0 0 1 1 0 0 0 0 0 0 0 0 0 0 0 0 0 0 0 0 0 0 0 0 0 2 0 0 1 0 0 0 1 1 1 0 0 2 0 0 0 0 1 0 0 0 0 1 0 1 0 0 0 0 0 0 0 1 0 0 0 0 0 0 0 0 0 0 0 0 0 0 1 0 0 0 0 0 0 0 0 0 2</counts>
			</dataPoints>
		</scan>
		<scan status="Completed" appendNumber="0" scanAxis="2Theta" mode="Continuous">
			<header>
				<startTimeStamp>2024-10-29T15:44:48-04:00</startTimeStamp>
				<endTimeStamp>2024-10-29T16:14:46-04:00</endTimeStamp>
				<author>
					<name>ib355</name>
				</author>
				<source>
					<applicationSoftware version="7.1">Data Collector</applicationSoftware>
					<instrumentControlSoftware version="8.2  20201204">EMPYREAN</instrumentControlSoftware>
					<instrumentID>0000000011260721</instrumentID>
				</source>
			</header>
			<dataPoints>
				<positions axis="2Theta" unit="deg">
					<startPosition>78.032685010383</startPosition>
					<endPosition>81.3799547815995</endPosition>
				</positions>
				<positions axis="Omega" unit="deg">
					<commonPosition>21.3146599479956</commonPosition>
				</positions>
				<positions axis="Phi" unit="deg">
					<commonPosition>-91.57</commonPosition>
				</positions>
				<positions axis="Chi" unit="deg">
					<commonPosition>0</commonPosition>
				</positions>
				<positions axis="Z" unit="mm">
					<commonPosition>8.368</commonPosition>
				</positions>
				<commonCountingTime unit="seconds">0.974</commonCountingTime>
				<counts unit="counts">0 0 0 0 1 0 0 0 0 0 1 0 1 0 0 1 0 0 0 0 1 1 0 0 0 0 0 0 0 1 0 0 0 0 1 0 1 0 0 0 0 0 1 1 2 1 0 0 0 0 0 0 0 0 2 0 0 0 1 2 5 2 0 0 0 0 2 0 0 0 0 2 0 0 1 0 0 0 0 1 0 0 0 0 0 0 0 0 0 1 0 1 3 0 0 0 0 0 1 0 3 0 1 0 1 0 0 0 0 0 0 0 0 0 0 1 1 1 0 1 0 0 0 0 0 0 0 0 0 0 0 1 0 0 1 0 0 0 0 0 0 0 0 0 0 0 0 0 0 0 0 0 1 2 0 0 0 0 0 1 0 0 0 1 0 0 0 0 1 1 1 0 1 0 0 0 0 1 0 0 0 0 0 0 0 0 0 0 0 0 2 0 0 0 1 1 0 1 0 0 0 1 0 0 1 1 0 0 1 0 1 0 0 0 0 1 0 0 1 0 0 0 0 0 0 1 0 0 2 0 0 0 1 0 0 0 0 0 0 0 1 1 0 0 0 0 0 0 0 0 0 0 0 0 0</counts>
			</dataPoints>
		</scan>
		<scan status="Completed" appendNumber="0" scanAxis="2Theta" mode="Continuous">
			<header>
				<startTimeStamp>2024-10-29T15:44:48-04:00</startTimeStamp>
				<endTimeStamp>2024-10-29T16:14:46-04:00</endTimeStamp>
				<author>
					<name>ib355</name>
				</author>
				<source>
					<applicationSoftware version="7.1">Data Collector</applicationSoftware>
					<instrumentControlSoftware version="8.2  20201204">EMPYREAN</instrumentControlSoftware>
					<instrumentID>0000000011260721</instrumentID>
				</source>
			</header>
			<dataPoints>
				<positions axis="2Theta" unit="deg">
					<startPosition>78.0359675810511</startPosition>
					<endPosition>81.3832373522676</endPosition>
				</positions>
				<positions axis="Omega" unit="deg">
					<commonPosition>21.3163012333297</commonPosition>
				</positions>
				<positions axis="Phi" unit="deg">
					<commonPosition>-91.57</commonPosition>
				</positions>
				<positions axis="Chi" unit="deg">
					<commonPosition>0</commonPosition>
				</positions>
				<positions axis="Z" unit="mm">
					<commonPosition>8.368</commonPosition>
				</positions>
				<commonCountingTime unit="seconds">0.974</commonCountingTime>
				<counts unit="counts">0 0 0 0 0 0 0 1 1 0 1 1 2 0 1 0 0 0 1 1 0 0 0 0 0 0 1 0 0 1 1 0 0 1 0 0 0 0 0 0 0 1 1 0 0 0 0 0 0 0 0 0 0 0 1 0 0 0 1 0 0 0 0 0 2 0 1 0 0 0 0 0 0 0 1 2 0 0 1 0 0 0 0 0 0 0 0 0 1 0 0 0 1 0 0 0 0 0 0 0 0 0 0 0 1 0 1 0 1 0 0 0 1 0 0 0 0 0 0 0 0 0 0 0 0 0 0 0 0 0 0 0 0 0 0 0 1 0 0 0 0 0 0 0 0 1 0 0 0 0 1 0 0 0 1 0 2 0 0 0 0 0 1 0 0 0 0 0 0 1 0 0 2 0 0 0 0 1 0 0 0 0 0 0 0 0 0 1 0 0 0 1 0 1 1 1 1 1 1 0 0 0 0 0 1 0 0 0 0 0 0 0 0 0 0 0 1 0 0 0 0 0 0 0 0 0 0 1 0 0 1 0 0 0 0 0 0 0 0 0 0 0 0 2 1 0 0 0 0 0 0 0 0 0 1</counts>
			</dataPoints>
		</scan>
		<scan status="Completed" appendNumber="0" scanAxis="2Theta" mode="Continuous">
			<header>
				<startTimeStamp>2024-10-29T15:44:48-04:00</startTimeStamp>
				<endTimeStamp>2024-10-29T16:14:46-04:00</endTimeStamp>
				<author>
					<name>ib355</name>
				</author>
				<source>
					<applicationSoftware version="7.1">Data Collector</applicationSoftware>
					<instrumentControlSoftware version="8.2  20201204">EMPYREAN</instrumentControlSoftware>
					<instrumentID>0000000011260721</instrumentID>
				</source>
			</header>
			<dataPoints>
				<positions axis="2Theta" unit="deg">
					<startPosition>78.0392501517193</startPosition>
					<endPosition>81.3865199229357</endPosition>
				</positions>
				<positions axis="Omega" unit="deg">
					<commonPosition>21.3179425186637</commonPosition>
				</positions>
				<positions axis="Phi" unit="deg">
					<commonPosition>-91.57</commonPosition>
				</positions>
				<positions axis="Chi" unit="deg">
					<commonPosition>0</commonPosition>
				</positions>
				<positions axis="Z" unit="mm">
					<commonPosition>8.368</commonPosition>
				</positions>
				<commonCountingTime unit="seconds">0.974</commonCountingTime>
				<counts unit="counts">0 0 0 0 0 0 0 0 0 0 1 0 0 1 0 1 0 0 0 1 1 0 0 0 1 0 0 1 0 0 0 1 1 0 0 0 0 0 1 0 0 1 0 0 0 0 0 0 0 1 0 0 1 0 0 0 0 0 1 0 0 2 0 0 0 0 1 0 0 1 0 1 0 0 0 0 0 0 1 1 0 1 1 0 0 0 0 0 0 1 0 0 0 0 0 1 0 1 0 0 1 0 0 0 0 1 0 0 0 0 1 0 0 0 0 0 0 0 0 0 0 0 0 0 0 1 0 0 0 0 0 0 0 0 0 0 1 1 2 0 0 0 0 0 0 0 0 0 0 0 1 1 0 0 0 0 0 0 1 0 0 0 0 0 0 0 0 0 0 0 0 0 0 1 0 2 1 0 0 1 0 0 0 1 0 0 0 0 0 0 0 2 0 0 0 0 2 0 1 0 0 0 0 0 0 1 0 0 1 0 0 0 0 0 0 1 0 1 1 0 1 0 0 0 0 0 0 1 0 0 0 0 0 0 0 0 1 0 1 0 1 0 1 0 0 0 0 2 0 0 0 0 0 0 0</counts>
			</dataPoints>
		</scan>
		<scan status="Completed" appendNumber="0" scanAxis="2Theta" mode="Continuous">
			<header>
				<startTimeStamp>2024-10-29T15:44:48-04:00</startTimeStamp>
				<endTimeStamp>2024-10-29T16:14:46-04:00</endTimeStamp>
				<author>
					<name>ib355</name>
				</author>
				<source>
					<applicationSoftware version="7.1">Data Collector</applicationSoftware>
					<instrumentControlSoftware version="8.2  20201204">EMPYREAN</instrumentControlSoftware>
					<instrumentID>0000000011260721</instrumentID>
				</source>
			</header>
			<dataPoints>
				<positions axis="2Theta" unit="deg">
					<startPosition>78.0425327223874</startPosition>
					<endPosition>81.3898024936039</endPosition>
				</positions>
				<positions axis="Omega" unit="deg">
					<commonPosition>21.3195838039978</commonPosition>
				</positions>
				<positions axis="Phi" unit="deg">
					<commonPosition>-91.57</commonPosition>
				</positions>
				<positions axis="Chi" unit="deg">
					<commonPosition>0</commonPosition>
				</positions>
				<positions axis="Z" unit="mm">
					<commonPosition>8.368</commonPosition>
				</positions>
				<commonCountingTime unit="seconds">0.974</commonCountingTime>
				<counts unit="counts">0 0 0 0 0 1 0 0 1 1 1 1 0 0 1 0 1 0 0 1 1 1 0 0 0 0 0 3 0 0 0 0 1 0 0 0 0 1 0 0 0 0 0 1 1 0 0 0 2 0 0 1 0 1 0 0 0 1 0 0 0 1 0 1 1 0 2 0 0 0 0 0 0 0 0 1 0 0 1 0 1 0 0 0 0 1 0 0 0 0 0 1 0 0 0 0 0 2 0 1 0 1 1 0 0 0 1 0 0 0 0 0 0 0 0 0 0 0 0 0 0 0 1 0 0 0 0 2 0 0 0 0 0 0 0 1 0 0 1 0 1 2 0 1 0 0 0 0 1 0 0 0 0 0 1 1 0 0 0 1 0 0 1 1 2 0 0 0 0 0 0 0 0 0 0 0 0 0 0 0 0 0 0 0 0 0 0 0 0 0 0 0 0 0 0 1 0 0 0 0 0 1 0 0 0 0 0 0 0 0 0 0 1 1 0 0 0 0 0 0 0 0 0 0 0 0 0 0 0 1 0 1 0 1 0 0 1 1 0 0 0 0 0 0 1 0 0 0 0 1 0 0 0 0 1</counts>
			</dataPoints>
		</scan>
		<scan status="Completed" appendNumber="0" scanAxis="2Theta" mode="Continuous">
			<header>
				<startTimeStamp>2024-10-29T15:44:48-04:00</startTimeStamp>
				<endTimeStamp>2024-10-29T16:14:46-04:00</endTimeStamp>
				<author>
					<name>ib355</name>
				</author>
				<source>
					<applicationSoftware version="7.1">Data Collector</applicationSoftware>
					<instrumentControlSoftware version="8.2  20201204">EMPYREAN</instrumentControlSoftware>
					<instrumentID>0000000011260721</instrumentID>
				</source>
			</header>
			<dataPoints>
				<positions axis="2Theta" unit="deg">
					<startPosition>78.0458152930555</startPosition>
					<endPosition>81.393085064272</endPosition>
				</positions>
				<positions axis="Omega" unit="deg">
					<commonPosition>21.3212250893319</commonPosition>
				</positions>
				<positions axis="Phi" unit="deg">
					<commonPosition>-91.57</commonPosition>
				</positions>
				<positions axis="Chi" unit="deg">
					<commonPosition>0</commonPosition>
				</positions>
				<positions axis="Z" unit="mm">
					<commonPosition>8.368</commonPosition>
				</positions>
				<commonCountingTime unit="seconds">0.974</commonCountingTime>
				<counts unit="counts">0 1 0 0 0 0 0 0 0 0 1 0 1 0 0 2 0 2 1 0 0 0 1 0 0 0 1 1 0 2 1 0 0 0 0 0 0 1 0 0 0 0 1 0 0 0 1 0 0 0 0 0 0 0 0 0 0 0 0 0 0 0 0 1 1 0 1 0 2 0 0 0 0 0 1 1 0 1 0 1 0 0 0 0 0 1 0 0 0 0 1 0 0 0 1 0 0 0 1 0 0 1 0 1 1 0 1 0 1 0 1 0 2 0 0 0 1 0 0 0 0 0 0 2 0 0 0 2 0 0 2 1 0 0 0 1 0 0 2 0 1 0 0 0 1 0 0 0 0 0 0 0 0 0 0 0 0 0 0 1 1 0 0 0 0 0 1 0 0 0 0 0 0 0 0 0 0 1 0 0 0 0 0 1 1 0 0 1 0 0 0 0 0 0 0 1 0 0 0 0 0 0 0 0 0 1 0 0 0 1 0 0 0 0 0 0 1 1 0 0 1 0 0 0 0 0 0 0 0 1 0 0 0 0 0 1 0 0 0 0 0 0 0 0 0 0 0 0 0 0 0 0 0 0 0</counts>
			</dataPoints>
		</scan>
		<scan status="Completed" appendNumber="0" scanAxis="2Theta" mode="Continuous">
			<header>
				<startTimeStamp>2024-10-29T15:44:48-04:00</startTimeStamp>
				<endTimeStamp>2024-10-29T16:14:46-04:00</endTimeStamp>
				<author>
					<name>ib355</name>
				</author>
				<source>
					<applicationSoftware version="7.1">Data Collector</applicationSoftware>
					<instrumentControlSoftware version="8.2  20201204">EMPYREAN</instrumentControlSoftware>
					<instrumentID>0000000011260721</instrumentID>
				</source>
			</header>
			<dataPoints>
				<positions axis="2Theta" unit="deg">
					<startPosition>78.0490978637236</startPosition>
					<endPosition>81.3963676349401</endPosition>
				</positions>
				<positions axis="Omega" unit="deg">
					<commonPosition>21.3228663746659</commonPosition>
				</positions>
				<positions axis="Phi" unit="deg">
					<commonPosition>-91.57</commonPosition>
				</positions>
				<positions axis="Chi" unit="deg">
					<commonPosition>0</commonPosition>
				</positions>
				<positions axis="Z" unit="mm">
					<commonPosition>8.368</commonPosition>
				</positions>
				<commonCountingTime unit="seconds">0.974</commonCountingTime>
				<counts unit="counts">0 0 0 0 0 0 0 0 0 0 0 0 0 1 0 0 0 0 1 0 0 0 1 1 0 0 0 0 1 1 0 0 0 0 0 1 1 2 1 0 0 0 0 0 0 0 0 0 0 0 0 0 0 0 0 0 1 1 1 0 1 0 1 1 0 1 1 0 1 0 0 0 1 0 0 1 0 1 0 0 1 0 0 0 0 0 1 0 0 0 0 0 0 1 0 1 0 1 0 0 0 0 1 0 2 0 0 0 0 0 0 0 0 1 0 1 0 0 0 0 0 1 0 0 0 0 0 0 0 0 0 1 2 0 2 0 0 0 0 0 0 0 0 0 0 0 0 0 0 0 0 1 1 0 0 0 0 0 0 0 1 0 0 0 0 0 0 0 1 0 0 1 0 0 0 0 0 0 0 0 1 1 0 1 1 0 0 1 0 0 0 1 1 0 0 0 0 0 1 0 0 0 0 0 1 0 0 0 0 0 0 0 0 1 0 0 0 0 0 0 0 1 0 0 0 0 0 0 0 0 0 1 0 0 1 0 1 1 0 0 0 0 0 1 1 0 1 0 0 1 0 0 0 0 0</counts>
			</dataPoints>
		</scan>
		<scan status="Completed" appendNumber="0" scanAxis="2Theta" mode="Continuous">
			<header>
				<startTimeStamp>2024-10-29T15:44:48-04:00</startTimeStamp>
				<endTimeStamp>2024-10-29T16:14:46-04:00</endTimeStamp>
				<author>
					<name>ib355</name>
				</author>
				<source>
					<applicationSoftware version="7.1">Data Collector</applicationSoftware>
					<instrumentControlSoftware version="8.2  20201204">EMPYREAN</instrumentControlSoftware>
					<instrumentID>0000000011260721</instrumentID>
				</source>
			</header>
			<dataPoints>
				<positions axis="2Theta" unit="deg">
					<startPosition>78.0523804343918</startPosition>
					<endPosition>81.3996502056082</endPosition>
				</positions>
				<positions axis="Omega" unit="deg">
					<commonPosition>21.32450766</commonPosition>
				</positions>
				<positions axis="Phi" unit="deg">
					<commonPosition>-91.57</commonPosition>
				</positions>
				<positions axis="Chi" unit="deg">
					<commonPosition>0</commonPosition>
				</positions>
				<positions axis="Z" unit="mm">
					<commonPosition>8.368</commonPosition>
				</positions>
				<commonCountingTime unit="seconds">0.974</commonCountingTime>
				<counts unit="counts">1 0 0 1 0 0 0 1 0 0 0 0 0 0 0 0 0 0 0 0 3 0 0 0 0 0 1 0 1 0 0 1 1 0 1 0 0 0 0 0 0 1 2 0 0 1 0 1 0 0 0 0 0 0 0 1 0 0 0 0 0 0 1 0 0 0 0 0 1 0 0 0 2 1 0 0 0 0 0 0 0 0 1 0 1 0 0 0 1 0 1 0 1 0 0 0 0 0 0 0 0 0 0 0 1 0 0 0 0 0 0 0 0 0 0 1 1 0 0 0 0 0 0 1 0 1 0 0 0 0 0 0 0 0 0 0 0 0 0 0 0 1 0 1 0 1 0 0 0 0 1 0 0 1 1 1 1 1 0 0 1 0 0 0 0 0 1 0 0 0 0 0 0 0 0 0 0 0 0 1 0 0 0 0 0 0 0 0 1 0 0 0 0 0 0 0 0 0 0 0 0 0 0 1 1 0 0 0 0 0 0 0 0 0 0 0 0 0 1 0 1 2 1 0 0 0 0 0 0 0 1 0 1 0 0 1 0 0 0 0 1 0 0 0 1 2 0 0 0 0 1 0 0 0 0</counts>
			</dataPoints>
		</scan>
	</xrdMeasurement>
</xrdMeasurements>