File: data/XRD_RSM/RSM YY128/YY128_NSO_332_RSM 1.xrdml
<?xml version="1.0" encoding="utf-8"?>
<xrdMeasurements xmlns="http://www.xrdml.com/XRDMeasurement/2.2" xmlns:xsi="http://www.w3.org/2001/XMLSchema-instance" xsi:schemaLocation="http://www.xrdml.com/XRDMeasurement/2.2 http://www.xrdml.com/XRDMeasurement/2.2/XRDMeasurement.xsd" status="Completed">
	<comment>
		<entry>Configuration=3-axes Cradle_Reflection, Owner=User, Creation date=9/2/2021 3:55:24 PM</entry>
		<entry>Goniometer=Theta/Theta; Minimum step size 2Theta:0.0001; Minimum step size Omega:0.0001</entry>
		<entry>Sample stage=Chi-Phi-z stage 240 mm (reflection); Minimum step size Phi:0.01; Minimum step size Chi:0.01; Minimum step size Z:0.001</entry>
		<entry>Diffractometer system=EMPYREAN</entry>
		<entry>Measurement program=C:\PANalytical\Data Collector\Programs\Yu Yun\RSM\RSM 3degree_high resolution_10 min.xrdmp, Identifier={AFDDD7BF-A0A1-4F43-BECC-00159C8DE462}</entry>
	</comment>
	<sample type="To be analyzed">
		<id/>
		<name/>
		<preparedBy/>
	</sample>
	<xrdMeasurement status="Completed" measurementType="Area measurement" measurementStepAxis="Omega-2Theta" sampleMode="Reflection">
		<comment>
			<entry>PHD Lower Level = 4.02 (keV), PHD Upper Level = 11.26 (keV)</entry>
		</comment>
		<usedWavelength intended="K-Alpha">
			<kAlpha1 unit="Angstrom">1.5405980</kAlpha1>
			<kAlpha2 unit="Angstrom">1.5444260</kAlpha2>
			<kBeta unit="Angstrom">1.3922500</kBeta>
			<ratioKAlpha2KAlpha1>0</ratioKAlpha2KAlpha1>
		</usedWavelength>
		<incidentBeamPath>
			<radius unit="mm">240.00</radius>
			<xRayTube id="1010048" name="Empyrean Cu LFF HR (9430 033 7310x) DK432574">
				<tension unit="kV">45.0</tension>
				<current unit="mA">40.0</current>
				<anodeMaterial>Cu</anodeMaterial>
				<focus type="Line">
					<length unit="mm">12.0</length>
					<width unit="mm">0.4</width>
					<takeOffAngle unit="deg">4.4</takeOffAngle>
				</focus>
			</xRayTube>
			<xRayMirror xsi:type="xRayMirrorType" id="27080001" name="Inc. Beam Cu W/Si (hybrid MPD)" hybrid="true">
				<crystal type="Graded" shape="Parabolic">W/Si</crystal>
				<acceptanceAngle unit="deg">0.800</acceptanceAngle>
				<length unit="mm">55.3</length>
			</xRayMirror>
			<monochromator xsi:type="monochromatorType" id="23090002" name="Hybrid monochr. 2xGe220 Cu asym." hybrid="true">
				<crystal type="Asymmetric" shape="Flat">Ge</crystal>
				<numberOfReflections>2</numberOfReflections>
				<hkl>
					<h>2</h>
					<k>2</k>
					<l>0</l>
				</hkl>
			</monochromator>
			<mask xsi:type="maskType" id="22030008" name="Fixed mask 4 mm">
				<distanceToSample unit="mm">171.00</distanceToSample>
				<width unit="mm">4.00</width>
			</mask>
			<divergenceSlit xsi:type="fixedDivergenceSlitType" id="22010007" name="Fixed slit 1/8°">
				<distanceToSample unit="mm">179.30</distanceToSample>
				<height unit="mm">0.19</height>
			</divergenceSlit>
		</incidentBeamPath>
		<diffractedBeamPath>
			<radius unit="mm">240.00</radius>
			<antiScatterSlit xsi:type="fixedAntiScatterSlitType" id="22060009" name="Programmable anti-scatter slit">
				<angle unit="deg">4</angle>
			</antiScatterSlit>
			<detector xsi:type="areaDetectorType" id="7010020" name="PIXcel3D-Medipix3 1x1 detector">
				<phd unit="%">
					<lowerLevel>25</lowerLevel>
					<upperLevel>70</upperLevel>
				</phd>
				<mode>Scanning snapshot equatorial</mode>
				<activeChannelsEquatorial>255</activeChannelsEquatorial>
				<activeChannelsAxial>255</activeChannelsAxial>
				<pitchEquatorial unit="mm">0.05500</pitchEquatorial>
				<pitchAxial unit="mm">0.05500</pitchAxial>
				<readOutPeriod unit="seconds">0.315</readOutPeriod>
			</detector>
		</diffractedBeamPath>
		<scan status="Completed" appendNumber="0" scanAxis="2Theta" mode="Continuous">
			<header>
				<startTimeStamp>2022-11-11T16:28:16-05:00</startTimeStamp>
				<endTimeStamp>2022-11-11T16:33:14-05:00</endTimeStamp>
				<author>
					<name>User</name>
				</author>
				<source>
					<applicationSoftware version="7.1">Data Collector</applicationSoftware>
					<instrumentControlSoftware version="8.2  20201204">EMPYREAN</instrumentControlSoftware>
					<instrumentID>0000000011260721</instrumentID>
				</source>
			</header>
			<dataPoints>
				<positions axis="2Theta" unit="deg">
					<startPosition>70.2246476943918</startPosition>
					<endPosition>73.5719174656082</endPosition>
				</positions>
				<positions axis="Omega" unit="deg">
					<commonPosition>17.46574129</commonPosition>
				</positions>
				<positions axis="Phi" unit="deg">
					<commonPosition>93.93</commonPosition>
				</positions>
				<positions axis="Chi" unit="deg">
					<commonPosition>0</commonPosition>
				</positions>
				<positions axis="Z" unit="mm">
					<commonPosition>8.387</commonPosition>
				</positions>
				<commonCountingTime unit="seconds">0.309</commonCountingTime>
				<counts unit="counts">0 0 0 1 1 0 0 0 0 0 1 0 0 0 0 0 0 0 0 0 0 0 0 0 0 0 0 0 0 0 0 0 0 0 1 0 0 1 0 0 0 0 0 0 0 0 0 0 0 1 0 1 0 0 1 0 0 0 0 1 0 0 0 2 1 0 0 0 1 0 0 1 1 0 0 0 1 0 0 0 0 0 0 0 0 0 0 0 0 0 0 0 0 0 1 0 1 0 0 0 0 0 0 0 0 0 0 0 1 1 0 0 0 0 0 0 0 0 0 0 0 0 1 1 0 0 0 0 0 0 0 0 1 0 0 0 0 0 0 0 0 0 0 1 0 1 0 0 1 0 0 0 0 1 0 0 0 0 0 0 1 2 1 0 0 0 0 0 1 0 0 0 0 0 1 0 0 0 0 0 0 0 0 1 0 0 1 0 0 0 0 0 1 1 1 1 0 0 0 0 0 1 1 0 0 0 0 0 0 0 1 0 0 0 0 0 0 0 1 0 0 0 0 0 0 0 0 1 0 0 1 1 0 0 0 0 0 0 1 0 1 1 0 0 1 1 0 0 0 0 0 0 0 0 0</counts>
			</dataPoints>
		</scan>
		<scan status="Completed" appendNumber="0" scanAxis="2Theta" mode="Continuous">
			<header>
				<startTimeStamp>2022-11-11T16:28:16-05:00</startTimeStamp>
				<endTimeStamp>2022-11-11T16:33:14-05:00</endTimeStamp>
				<author>
					<name>User</name>
				</author>
				<source>
					<applicationSoftware version="7.1">Data Collector</applicationSoftware>
					<instrumentControlSoftware version="8.2  20201204">EMPYREAN</instrumentControlSoftware>
					<instrumentID>0000000011260721</instrumentID>
				</source>
			</header>
			<dataPoints>
				<positions axis="2Theta" unit="deg">
					<startPosition>70.2312128357295</startPosition>
					<endPosition>73.578482606946</endPosition>
				</positions>
				<positions axis="Omega" unit="deg">
					<commonPosition>17.4690238606689</commonPosition>
				</positions>
				<positions axis="Phi" unit="deg">
					<commonPosition>93.93</commonPosition>
				</positions>
				<positions axis="Chi" unit="deg">
					<commonPosition>0</commonPosition>
				</positions>
				<positions axis="Z" unit="mm">
					<commonPosition>8.387</commonPosition>
				</positions>
				<commonCountingTime unit="seconds">0.309</commonCountingTime>
				<counts unit="counts">0 0 0 0 0 2 1 0 0 0 0 1 0 0 0 0 0 0 0 0 0 0 0 0 0 1 0 0 1 1 0 0 0 0 1 1 0 0 0 0 0 0 1 0 0 0 0 0 0 0 0 1 0 0 0 0 0 0 0 0 0 0 1 0 0 0 0 0 0 0 0 0 0 0 1 1 0 0 1 0 0 0 0 0 0 1 0 0 0 0 0 0 0 0 1 0 0 0 0 1 0 0 1 0 0 1 0 0 0 0 0 0 1 0 0 0 0 0 0 0 1 0 0 0 0 1 0 1 0 0 0 0 0 0 1 0 0 0 2 0 0 1 0 0 0 0 1 0 0 0 0 0 0 0 1 0 0 0 0 0 2 0 0 0 0 0 0 1 0 0 2 0 0 1 0 0 1 0 0 0 0 0 0 1 0 0 0 0 0 0 0 0 0 0 0 0 0 1 3 0 0 1 0 1 0 0 0 1 0 0 1 0 0 0 0 1 0 0 0 0 1 0 0 0 0 0 0 0 0 0 1 0 0 0 0 0 0 0 0 0 0 0 1 0 0 0 0 0 0 0 0 1 1 0 0</counts>
			</dataPoints>
		</scan>
		<scan status="Completed" appendNumber="0" scanAxis="2Theta" mode="Continuous">
			<header>
				<startTimeStamp>2022-11-11T16:28:16-05:00</startTimeStamp>
				<endTimeStamp>2022-11-11T16:33:14-05:00</endTimeStamp>
				<author>
					<name>User</name>
				</author>
				<source>
					<applicationSoftware version="7.1">Data Collector</applicationSoftware>
					<instrumentControlSoftware version="8.2  20201204">EMPYREAN</instrumentControlSoftware>
					<instrumentID>0000000011260721</instrumentID>
				</source>
			</header>
			<dataPoints>
				<positions axis="2Theta" unit="deg">
					<startPosition>70.2377779770672</startPosition>
					<endPosition>73.5850477482837</endPosition>
				</positions>
				<positions axis="Omega" unit="deg">
					<commonPosition>17.4723064313377</commonPosition>
				</positions>
				<positions axis="Phi" unit="deg">
					<commonPosition>93.93</commonPosition>
				</positions>
				<positions axis="Chi" unit="deg">
					<commonPosition>0</commonPosition>
				</positions>
				<positions axis="Z" unit="mm">
					<commonPosition>8.387</commonPosition>
				</positions>
				<commonCountingTime unit="seconds">0.309</commonCountingTime>
				<counts unit="counts">0 0 0 0 0 0 1 0 0 0 0 0 0 1 0 0 0 0 0 1 1 0 0 1 1 0 0 0 0 0 1 0 0 0 0 0 0 2 1 0 0 0 0 0 0 0 0 0 0 0 0 0 0 0 0 0 0 0 0 1 0 0 0 0 0 0 0 0 0 0 0 0 1 0 1 1 0 0 0 0 1 0 0 0 0 0 0 0 0 0 0 1 0 0 1 0 0 0 0 0 0 0 0 1 1 0 0 0 0 1 0 0 0 0 0 0 0 0 0 0 0 0 0 0 0 0 0 0 0 0 1 0 0 1 0 0 0 0 0 0 0 0 0 1 0 0 0 1 0 0 0 0 0 0 0 0 0 0 0 0 0 0 0 0 0 0 0 0 0 0 0 0 1 0 0 0 0 0 1 2 0 0 0 0 0 0 0 0 0 0 0 1 1 0 0 0 0 1 0 1 0 0 0 0 0 1 0 1 0 0 0 0 0 0 0 1 1 1 0 0 0 1 0 1 0 0 0 1 0 0 0 1 0 2 1 0 0 0 1 0 0 0 0 0 0 0 0 0 1 1 0 1 0 0 1</counts>
			</dataPoints>
		</scan>
		<scan status="Completed" appendNumber="0" scanAxis="2Theta" mode="Continuous">
			<header>
				<startTimeStamp>2022-11-11T16:28:16-05:00</startTimeStamp>
				<endTimeStamp>2022-11-11T16:33:14-05:00</endTimeStamp>
				<author>
					<name>User</name>
				</author>
				<source>
					<applicationSoftware version="7.1">Data Collector</applicationSoftware>
					<instrumentControlSoftware version="8.2  20201204">EMPYREAN</instrumentControlSoftware>
					<instrumentID>0000000011260721</instrumentID>
				</source>
			</header>
			<dataPoints>
				<positions axis="2Theta" unit="deg">
					<startPosition>70.2443431184049</startPosition>
					<endPosition>73.5916128896214</endPosition>
				</positions>
				<positions axis="Omega" unit="deg">
					<commonPosition>17.4755890020066</commonPosition>
				</positions>
				<positions axis="Phi" unit="deg">
					<commonPosition>93.93</commonPosition>
				</positions>
				<positions axis="Chi" unit="deg">
					<commonPosition>0</commonPosition>
				</positions>
				<positions axis="Z" unit="mm">
					<commonPosition>8.387</commonPosition>
				</positions>
				<commonCountingTime unit="seconds">0.309</commonCountingTime>
				<counts unit="counts">1 0 1 0 2 0 0 0 0 0 0 0 1 0 0 0 1 0 0 0 0 0 1 1 0 0 0 0 0 0 0 1 0 0 0 0 0 0 0 0 0 0 1 0 0 0 0 2 1 0 0 0 0 0 0 0 0 0 0 0 1 0 0 1 0 0 1 0 3 0 0 0 0 0 0 0 0 0 0 0 0 1 0 0 0 0 0 0 0 0 0 0 0 0 0 0 0 1 0 0 0 0 0 0 0 1 1 1 0 0 0 0 0 0 0 0 0 1 0 0 0 0 0 0 0 0 0 0 0 0 1 0 0 0 0 0 0 0 1 0 0 0 0 0 0 0 1 0 0 0 0 0 1 1 0 0 0 0 0 0 0 1 0 0 0 0 0 0 0 1 0 0 0 1 0 0 0 0 0 0 1 0 1 0 0 0 0 0 0 0 0 0 2 0 0 1 0 1 1 0 0 1 0 0 0 0 0 0 0 1 0 0 0 0 0 0 0 0 0 1 0 0 0 0 0 0 0 0 0 0 0 0 0 0 0 0 0 0 0 0 0 0 0 0 0 1 0 0 0 0 1 0 0 0 0</counts>
			</dataPoints>
		</scan>
		<scan status="Completed" appendNumber="0" scanAxis="2Theta" mode="Continuous">
			<header>
				<startTimeStamp>2022-11-11T16:28:16-05:00</startTimeStamp>
				<endTimeStamp>2022-11-11T16:33:14-05:00</endTimeStamp>
				<author>
					<name>User</name>
				</author>
				<source>
					<applicationSoftware version="7.1">Data Collector</applicationSoftware>
					<instrumentControlSoftware version="8.2  20201204">EMPYREAN</instrumentControlSoftware>
					<instrumentID>0000000011260721</instrumentID>
				</source>
			</header>
			<dataPoints>
				<positions axis="2Theta" unit="deg">
					<startPosition>70.2509082597426</startPosition>
					<endPosition>73.5981780309591</endPosition>
				</positions>
				<positions axis="Omega" unit="deg">
					<commonPosition>17.4788715726754</commonPosition>
				</positions>
				<positions axis="Phi" unit="deg">
					<commonPosition>93.93</commonPosition>
				</positions>
				<positions axis="Chi" unit="deg">
					<commonPosition>0</commonPosition>
				</positions>
				<positions axis="Z" unit="mm">
					<commonPosition>8.387</commonPosition>
				</positions>
				<commonCountingTime unit="seconds">0.309</commonCountingTime>
				<counts unit="counts">1 0 0 0 0 0 0 0 0 1 0 0 0 0 1 0 0 1 0 0 0 0 0 1 0 1 0 0 1 0 0 0 0 0 2 0 0 1 2 0 0 0 0 0 0 0 0 0 0 0 0 0 1 2 0 0 0 0 1 0 0 1 0 1 0 1 0 1 0 0 0 0 0 0 1 0 0 0 0 0 0 0 0 0 0 0 0 0 0 0 0 0 0 0 0 0 0 0 0 1 0 0 0 0 0 0 0 0 1 0 0 0 0 1 1 0 0 0 0 0 0 0 0 0 0 1 0 0 0 0 0 0 0 0 0 0 0 0 0 0 0 0 0 0 0 0 0 0 0 0 0 0 0 0 0 0 0 0 0 0 0 0 0 1 0 0 0 0 0 0 0 0 1 0 0 0 0 0 0 1 0 0 1 0 0 0 0 1 0 0 0 0 0 0 0 0 0 1 0 1 0 0 0 0 0 0 0 0 0 0 0 0 0 0 0 0 0 0 0 0 0 0 0 0 1 0 0 0 0 0 0 1 0 0 0 0 1 0 0 0 0 1 0 0 0 0 0 0 0 1 1 2 0 1 0</counts>
			</dataPoints>
		</scan>
		<scan status="Completed" appendNumber="0" scanAxis="2Theta" mode="Continuous">
			<header>
				<startTimeStamp>2022-11-11T16:28:16-05:00</startTimeStamp>
				<endTimeStamp>2022-11-11T16:33:14-05:00</endTimeStamp>
				<author>
					<name>User</name>
				</author>
				<source>
					<applicationSoftware version="7.1">Data Collector</applicationSoftware>
					<instrumentControlSoftware version="8.2  20201204">EMPYREAN</instrumentControlSoftware>
					<instrumentID>0000000011260721</instrumentID>
				</source>
			</header>
			<dataPoints>
				<positions axis="2Theta" unit="deg">
					<startPosition>70.2574734010804</startPosition>
					<endPosition>73.6047431722968</endPosition>
				</positions>
				<positions axis="Omega" unit="deg">
					<commonPosition>17.4821541433443</commonPosition>
				</positions>
				<positions axis="Phi" unit="deg">
					<commonPosition>93.93</commonPosition>
				</positions>
				<positions axis="Chi" unit="deg">
					<commonPosition>0</commonPosition>
				</positions>
				<positions axis="Z" unit="mm">
					<commonPosition>8.387</commonPosition>
				</positions>
				<commonCountingTime unit="seconds">0.309</commonCountingTime>
				<counts unit="counts">1 0 0 0 0 0 0 0 0 1 0 0 0 0 0 0 0 0 0 0 0 0 0 0 0 1 0 0 2 0 0 0 0 1 0 0 0 1 0 0 0 0 0 0 0 0 1 0 0 0 0 0 0 0 0 0 0 0 0 0 1 0 0 0 0 0 1 0 0 1 0 0 0 0 0 1 0 0 0 0 0 0 0 0 0 0 0 0 0 0 0 0 0 0 0 1 0 0 0 0 0 0 0 0 0 0 0 0 0 0 0 0 0 1 0 0 0 0 0 1 0 0 0 0 0 0 0 0 0 0 0 0 0 0 0 0 0 0 0 1 0 0 2 0 0 0 0 0 1 0 0 0 0 0 0 0 0 0 0 1 0 0 0 0 0 0 0 0 0 0 0 0 0 1 0 0 0 0 0 0 0 0 1 0 1 0 0 0 0 1 0 0 0 0 1 2 0 0 2 1 0 0 0 0 0 0 0 0 0 0 0 0 1 0 0 0 0 0 0 0 0 0 0 0 0 0 3 0 0 1 0 0 0 0 0 1 0 1 0 1 0 0 0 0 0 0 0 0 0 0 0 0 0 0 1</counts>
			</dataPoints>
		</scan>
		<scan status="Completed" appendNumber="0" scanAxis="2Theta" mode="Continuous">
			<header>
				<startTimeStamp>2022-11-11T16:28:16-05:00</startTimeStamp>
				<endTimeStamp>2022-11-11T16:33:14-05:00</endTimeStamp>
				<author>
					<name>User</name>
				</author>
				<source>
					<applicationSoftware version="7.1">Data Collector</applicationSoftware>
					<instrumentControlSoftware version="8.2  20201204">EMPYREAN</instrumentControlSoftware>
					<instrumentID>0000000011260721</instrumentID>
				</source>
			</header>
			<dataPoints>
				<positions axis="2Theta" unit="deg">
					<startPosition>70.2640385424181</startPosition>
					<endPosition>73.6113083136346</endPosition>
				</positions>
				<positions axis="Omega" unit="deg">
					<commonPosition>17.4854367140132</commonPosition>
				</positions>
				<positions axis="Phi" unit="deg">
					<commonPosition>93.93</commonPosition>
				</positions>
				<positions axis="Chi" unit="deg">
					<commonPosition>0</commonPosition>
				</positions>
				<positions axis="Z" unit="mm">
					<commonPosition>8.387</commonPosition>
				</positions>
				<commonCountingTime unit="seconds">0.309</commonCountingTime>
				<counts unit="counts">0 0 0 0 0 2 0 0 0 0 1 0 0 0 0 0 0 0 0 0 2 1 0 0 0 0 0 0 0 0 0 0 0 0 0 0 0 0 0 2 0 0 0 0 0 0 0 0 0 0 0 0 0 1 0 0 0 0 0 0 0 0 0 0 0 1 0 0 0 0 0 0 0 1 1 0 0 0 0 1 0 0 0 0 0 0 0 0 0 0 1 0 0 0 0 0 0 0 0 0 0 0 0 1 0 0 0 0 0 0 0 0 0 0 0 0 0 0 1 0 0 0 0 0 1 0 0 0 0 0 0 0 0 0 0 0 0 0 0 0 0 0 0 0 0 0 0 0 1 0 0 1 0 0 0 0 0 1 0 1 0 0 0 0 0 0 0 0 0 0 0 0 0 0 0 0 0 0 0 0 0 0 0 0 0 0 1 0 0 0 1 0 0 1 0 0 0 0 0 1 1 1 0 0 0 1 0 0 1 0 0 0 0 0 0 0 0 0 0 1 0 1 0 0 0 1 1 1 0 1 0 0 0 0 0 0 0 0 0 0 0 0 0 0 0 0 0 0 0 1 0 0 0 0 1</counts>
			</dataPoints>
		</scan>
		<scan status="Completed" appendNumber="0" scanAxis="2Theta" mode="Continuous">
			<header>
				<startTimeStamp>2022-11-11T16:28:16-05:00</startTimeStamp>
				<endTimeStamp>2022-11-11T16:33:14-05:00</endTimeStamp>
				<author>
					<name>User</name>
				</author>
				<source>
					<applicationSoftware version="7.1">Data Collector</applicationSoftware>
					<instrumentControlSoftware version="8.2  20201204">EMPYREAN</instrumentControlSoftware>
					<instrumentID>0000000011260721</instrumentID>
				</source>
			</header>
			<dataPoints>
				<positions axis="2Theta" unit="deg">
					<startPosition>70.2706036837558</startPosition>
					<endPosition>73.6178734549723</endPosition>
				</positions>
				<positions axis="Omega" unit="deg">
					<commonPosition>17.488719284682</commonPosition>
				</positions>
				<positions axis="Phi" unit="deg">
					<commonPosition>93.93</commonPosition>
				</positions>
				<positions axis="Chi" unit="deg">
					<commonPosition>0</commonPosition>
				</positions>
				<positions axis="Z" unit="mm">
					<commonPosition>8.387</commonPosition>
				</positions>
				<commonCountingTime unit="seconds">0.309</commonCountingTime>
				<counts unit="counts">1 0 0 0 0 0 1 0 1 0 0 1 0 0 0 0 0 0 0 0 0 1 0 0 0 1 0 1 0 0 0 0 1 0 0 0 1 0 0 0 0 0 0 0 1 0 1 0 0 0 0 0 0 1 0 0 0 0 0 0 1 0 2 0 0 0 1 0 1 0 0 0 0 0 0 0 0 0 0 0 1 0 0 0 0 0 1 0 0 0 0 0 0 0 0 0 0 2 0 0 1 0 1 0 0 1 0 0 0 1 0 0 0 0 0 0 0 0 1 1 0 1 0 0 1 1 0 0 0 0 0 0 0 1 1 0 1 0 2 0 0 0 0 0 0 1 0 0 0 0 0 0 0 1 0 0 0 1 0 0 0 0 0 2 0 1 0 0 0 0 1 0 0 0 0 0 0 0 0 0 0 0 1 0 0 0 0 0 0 1 0 0 0 1 0 0 0 1 0 2 0 0 0 0 0 0 0 0 0 0 0 0 0 0 0 0 0 0 0 0 0 0 0 0 1 0 0 0 0 0 0 0 0 0 0 0 0 0 0 0 0 0 1 0 0 1 0 1 1 0 0 0 0 0 0</counts>
			</dataPoints>
		</scan>
		<scan status="Completed" appendNumber="0" scanAxis="2Theta" mode="Continuous">
			<header>
				<startTimeStamp>2022-11-11T16:28:16-05:00</startTimeStamp>
				<endTimeStamp>2022-11-11T16:33:14-05:00</endTimeStamp>
				<author>
					<name>User</name>
				</author>
				<source>
					<applicationSoftware version="7.1">Data Collector</applicationSoftware>
					<instrumentControlSoftware version="8.2  20201204">EMPYREAN</instrumentControlSoftware>
					<instrumentID>0000000011260721</instrumentID>
				</source>
			</header>
			<dataPoints>
				<positions axis="2Theta" unit="deg">
					<startPosition>70.2771688250935</startPosition>
					<endPosition>73.62443859631</endPosition>
				</positions>
				<positions axis="Omega" unit="deg">
					<commonPosition>17.4920018553509</commonPosition>
				</positions>
				<positions axis="Phi" unit="deg">
					<commonPosition>93.93</commonPosition>
				</positions>
				<positions axis="Chi" unit="deg">
					<commonPosition>0</commonPosition>
				</positions>
				<positions axis="Z" unit="mm">
					<commonPosition>8.387</commonPosition>
				</positions>
				<commonCountingTime unit="seconds">0.309</commonCountingTime>
				<counts unit="counts">0 0 0 0 0 0 1 0 0 1 0 1 0 0 0 0 1 0 0 0 0 0 1 0 1 0 0 0 0 0 0 0 0 0 0 0 0 0 1 2 0 0 0 0 0 0 0 0 0 1 0 0 0 1 0 0 0 0 0 0 0 0 0 0 0 0 0 0 0 0 0 2 0 0 0 0 0 0 1 0 1 0 0 0 0 1 1 0 0 0 0 1 0 0 0 0 0 0 1 0 0 0 1 0 0 0 1 1 0 1 0 0 0 0 0 0 0 0 0 0 0 0 0 0 0 2 0 0 0 1 0 0 0 0 0 0 0 0 0 1 0 1 0 1 0 0 1 0 0 0 0 0 0 0 0 0 0 0 0 0 0 0 0 0 0 0 0 0 0 0 0 0 0 0 0 0 0 0 0 0 0 0 0 1 0 1 0 0 0 0 0 0 0 0 1 3 0 0 1 0 0 0 1 0 0 0 0 0 0 0 0 0 2 0 0 0 0 0 0 0 0 0 0 0 0 0 0 0 0 1 0 0 0 0 0 0 0 1 0 0 0 0 1 1 0 0 0 1 0 0 0 0 0 0 0</counts>
			</dataPoints>
		</scan>
		<scan status="Completed" appendNumber="0" scanAxis="2Theta" mode="Continuous">
			<header>
				<startTimeStamp>2022-11-11T16:28:16-05:00</startTimeStamp>
				<endTimeStamp>2022-11-11T16:33:14-05:00</endTimeStamp>
				<author>
					<name>User</name>
				</author>
				<source>
					<applicationSoftware version="7.1">Data Collector</applicationSoftware>
					<instrumentControlSoftware version="8.2  20201204">EMPYREAN</instrumentControlSoftware>
					<instrumentID>0000000011260721</instrumentID>
				</source>
			</header>
			<dataPoints>
				<positions axis="2Theta" unit="deg">
					<startPosition>70.2837339664312</startPosition>
					<endPosition>73.6310037376477</endPosition>
				</positions>
				<positions axis="Omega" unit="deg">
					<commonPosition>17.4952844260197</commonPosition>
				</positions>
				<positions axis="Phi" unit="deg">
					<commonPosition>93.93</commonPosition>
				</positions>
				<positions axis="Chi" unit="deg">
					<commonPosition>0</commonPosition>
				</positions>
				<positions axis="Z" unit="mm">
					<commonPosition>8.387</commonPosition>
				</positions>
				<commonCountingTime unit="seconds">0.309</commonCountingTime>
				<counts unit="counts">0 0 0 0 0 0 1 0 1 1 0 1 0 0 0 0 0 0 0 1 1 0 0 0 0 0 0 0 0 0 0 0 1 0 0 0 0 0 0 0 0 0 0 0 0 0 0 0 0 0 0 0 1 0 0 0 1 0 0 1 0 0 0 1 0 0 0 0 0 0 0 0 1 0 0 0 0 0 0 0 0 0 0 0 0 0 0 0 0 0 0 0 0 1 1 0 0 0 0 0 0 0 0 0 1 0 1 0 0 1 0 0 0 0 0 1 0 0 0 0 0 0 0 0 0 0 0 0 0 0 1 0 0 0 0 0 0 1 0 0 0 0 0 1 0 0 0 0 0 1 0 0 1 1 0 1 0 0 0 0 1 0 1 0 0 0 0 1 1 1 0 1 0 0 0 0 0 0 0 0 0 0 0 0 0 0 1 0 1 0 0 1 0 0 0 1 0 0 0 0 0 0 1 0 0 0 0 0 0 0 0 1 0 1 0 0 0 0 0 0 0 0 0 0 0 0 1 0 0 0 0 0 0 0 0 0 0 1 0 0 0 0 0 0 0 0 0 0 0 0 0 0 0 0 0</counts>
			</dataPoints>
		</scan>
		<scan status="Completed" appendNumber="0" scanAxis="2Theta" mode="Continuous">
			<header>
				<startTimeStamp>2022-11-11T16:28:16-05:00</startTimeStamp>
				<endTimeStamp>2022-11-11T16:33:14-05:00</endTimeStamp>
				<author>
					<name>User</name>
				</author>
				<source>
					<applicationSoftware version="7.1">Data Collector</applicationSoftware>
					<instrumentControlSoftware version="8.2  20201204">EMPYREAN</instrumentControlSoftware>
					<instrumentID>0000000011260721</instrumentID>
				</source>
			</header>
			<dataPoints>
				<positions axis="2Theta" unit="deg">
					<startPosition>70.290299107769</startPosition>
					<endPosition>73.6375688789854</endPosition>
				</positions>
				<positions axis="Omega" unit="deg">
					<commonPosition>17.4985669966886</commonPosition>
				</positions>
				<positions axis="Phi" unit="deg">
					<commonPosition>93.93</commonPosition>
				</positions>
				<positions axis="Chi" unit="deg">
					<commonPosition>0</commonPosition>
				</positions>
				<positions axis="Z" unit="mm">
					<commonPosition>8.387</commonPosition>
				</positions>
				<commonCountingTime unit="seconds">0.309</commonCountingTime>
				<counts unit="counts">1 0 0 0 0 0 0 2 0 0 1 0 0 0 0 0 0 0 0 0 0 0 0 0 0 0 1 0 0 0 1 0 0 0 0 0 0 0 0 0 1 0 0 0 0 1 0 1 0 0 0 0 0 0 0 0 1 0 0 1 0 1 0 0 0 0 0 0 0 0 0 0 0 0 0 0 0 0 0 0 0 0 0 0 0 0 0 0 1 0 1 0 0 0 0 0 1 0 0 0 2 1 1 0 0 0 1 0 0 1 0 0 0 0 0 0 0 0 1 0 0 1 0 0 0 0 0 0 0 0 0 1 0 0 0 0 0 1 2 0 0 0 0 0 1 0 0 0 0 1 0 0 0 0 2 0 0 0 1 1 0 1 0 0 2 0 1 0 0 0 0 1 0 0 0 0 1 0 0 0 0 0 0 0 0 1 1 0 1 0 0 1 0 0 0 0 0 1 0 1 1 0 0 1 0 0 1 0 0 0 1 0 0 0 0 0 0 0 0 0 0 0 0 0 0 0 0 0 0 0 0 0 0 0 1 0 0 0 0 0 0 0 0 0 1 0 1 0 0 0 0 1 0 0 0</counts>
			</dataPoints>
		</scan>
		<scan status="Completed" appendNumber="0" scanAxis="2Theta" mode="Continuous">
			<header>
				<startTimeStamp>2022-11-11T16:28:16-05:00</startTimeStamp>
				<endTimeStamp>2022-11-11T16:33:14-05:00</endTimeStamp>
				<author>
					<name>User</name>
				</author>
				<source>
					<applicationSoftware version="7.1">Data Collector</applicationSoftware>
					<instrumentControlSoftware version="8.2  20201204">EMPYREAN</instrumentControlSoftware>
					<instrumentID>0000000011260721</instrumentID>
				</source>
			</header>
			<dataPoints>
				<positions axis="2Theta" unit="deg">
					<startPosition>70.2968642491067</startPosition>
					<endPosition>73.6441340203232</endPosition>
				</positions>
				<positions axis="Omega" unit="deg">
					<commonPosition>17.5018495673575</commonPosition>
				</positions>
				<positions axis="Phi" unit="deg">
					<commonPosition>93.93</commonPosition>
				</positions>
				<positions axis="Chi" unit="deg">
					<commonPosition>0</commonPosition>
				</positions>
				<positions axis="Z" unit="mm">
					<commonPosition>8.387</commonPosition>
				</positions>
				<commonCountingTime unit="seconds">0.309</commonCountingTime>
				<counts unit="counts">2 0 0 1 0 0 0 0 0 0 0 0 0 0 0 0 0 1 0 0 0 0 0 0 0 0 1 0 0 0 0 0 0 0 1 1 0 0 0 1 0 0 0 0 0 1 0 0 0 0 0 0 0 0 0 0 0 0 0 0 0 0 0 0 0 0 0 0 0 0 0 0 0 0 0 0 0 0 0 0 0 0 0 0 0 1 0 0 0 0 0 0 1 0 1 0 0 0 0 0 0 0 0 0 0 0 0 1 0 0 0 0 0 0 0 0 0 0 0 0 0 0 0 0 0 0 0 0 0 0 0 0 0 0 0 0 0 0 1 0 0 1 1 2 0 0 0 0 0 1 0 1 0 0 0 0 0 0 0 0 1 0 0 0 1 1 0 0 1 0 0 0 0 1 0 0 1 0 0 0 0 0 0 0 0 0 0 0 0 0 1 0 0 1 0 0 0 0 1 0 0 0 1 0 0 0 0 0 0 0 0 0 0 0 0 0 0 0 0 1 0 0 0 0 0 0 0 0 0 0 0 1 1 1 0 1 0 0 0 0 0 0 0 0 0 0 0 1 0 0 0 0 0 0 1</counts>
			</dataPoints>
		</scan>
		<scan status="Completed" appendNumber="0" scanAxis="2Theta" mode="Continuous">
			<header>
				<startTimeStamp>2022-11-11T16:28:16-05:00</startTimeStamp>
				<endTimeStamp>2022-11-11T16:33:14-05:00</endTimeStamp>
				<author>
					<name>User</name>
				</author>
				<source>
					<applicationSoftware version="7.1">Data Collector</applicationSoftware>
					<instrumentControlSoftware version="8.2  20201204">EMPYREAN</instrumentControlSoftware>
					<instrumentID>0000000011260721</instrumentID>
				</source>
			</header>
			<dataPoints>
				<positions axis="2Theta" unit="deg">
					<startPosition>70.3034293904444</startPosition>
					<endPosition>73.6506991616609</endPosition>
				</positions>
				<positions axis="Omega" unit="deg">
					<commonPosition>17.5051321380263</commonPosition>
				</positions>
				<positions axis="Phi" unit="deg">
					<commonPosition>93.93</commonPosition>
				</positions>
				<positions axis="Chi" unit="deg">
					<commonPosition>0</commonPosition>
				</positions>
				<positions axis="Z" unit="mm">
					<commonPosition>8.387</commonPosition>
				</positions>
				<commonCountingTime unit="seconds">0.309</commonCountingTime>
				<counts unit="counts">0 1 0 0 0 0 0 0 0 0 0 0 1 0 0 0 0 1 0 0 0 0 0 0 1 0 1 0 0 0 0 0 0 0 0 0 0 0 0 0 1 0 1 0 0 0 1 0 0 0 0 0 0 0 1 0 0 1 1 0 0 0 2 0 0 0 0 0 0 0 0 0 1 0 0 1 0 0 0 0 0 0 0 0 2 1 1 0 0 0 0 0 0 0 0 1 0 1 0 1 0 0 0 0 0 0 1 0 0 0 0 1 0 0 0 1 0 0 0 0 0 1 1 0 0 0 0 0 0 0 0 0 0 0 0 0 0 0 0 0 0 1 0 0 0 0 0 0 2 0 0 0 0 0 2 0 0 0 0 1 2 0 0 0 0 0 1 0 1 0 0 0 0 0 1 0 0 0 0 0 0 0 0 0 0 0 0 0 0 0 0 1 1 0 0 0 0 0 1 1 0 0 0 0 0 0 0 0 0 0 1 0 0 0 0 0 1 1 0 0 0 0 1 0 0 0 0 0 0 0 0 0 0 0 0 0 0 0 0 1 0 1 0 0 0 0 0 0 0 0 1 0 0 0 0</counts>
			</dataPoints>
		</scan>
		<scan status="Completed" appendNumber="0" scanAxis="2Theta" mode="Continuous">
			<header>
				<startTimeStamp>2022-11-11T16:28:16-05:00</startTimeStamp>
				<endTimeStamp>2022-11-11T16:33:14-05:00</endTimeStamp>
				<author>
					<name>User</name>
				</author>
				<source>
					<applicationSoftware version="7.1">Data Collector</applicationSoftware>
					<instrumentControlSoftware version="8.2  20201204">EMPYREAN</instrumentControlSoftware>
					<instrumentID>0000000011260721</instrumentID>
				</source>
			</header>
			<dataPoints>
				<positions axis="2Theta" unit="deg">
					<startPosition>70.3099945317821</startPosition>
					<endPosition>73.6572643029986</endPosition>
				</positions>
				<positions axis="Omega" unit="deg">
					<commonPosition>17.5084147086952</commonPosition>
				</positions>
				<positions axis="Phi" unit="deg">
					<commonPosition>93.93</commonPosition>
				</positions>
				<positions axis="Chi" unit="deg">
					<commonPosition>0</commonPosition>
				</positions>
				<positions axis="Z" unit="mm">
					<commonPosition>8.387</commonPosition>
				</positions>
				<commonCountingTime unit="seconds">0.309</commonCountingTime>
				<counts unit="counts">0 0 0 0 2 1 1 0 0 0 0 0 0 0 0 0 0 0 0 0 1 0 0 1 0 0 0 0 0 3 0 0 0 0 0 1 0 0 0 0 0 0 0 0 0 0 0 0 0 0 1 0 1 0 0 1 0 0 0 0 0 0 0 0 0 0 0 1 0 0 0 0 0 0 0 0 0 0 1 1 0 1 0 0 0 0 0 0 0 1 0 0 0 1 0 0 0 0 0 0 0 0 0 0 1 0 0 0 0 0 0 0 0 0 0 0 0 0 0 0 0 0 0 1 0 1 1 1 0 0 0 0 1 0 1 0 0 0 1 1 0 0 0 0 1 1 1 0 0 0 0 0 1 0 0 0 0 0 0 0 0 0 0 0 0 0 0 0 1 0 0 0 0 0 0 0 0 0 1 0 0 0 0 0 0 1 0 0 0 0 0 0 0 1 1 0 0 0 0 0 0 1 1 0 0 0 1 0 0 0 1 0 0 0 0 0 0 2 0 0 0 0 1 0 0 0 0 0 0 0 0 0 0 0 0 0 0 0 0 0 0 1 0 0 0 0 0 0 0 0 0 0 0 0 1</counts>
			</dataPoints>
		</scan>
		<scan status="Completed" appendNumber="0" scanAxis="2Theta" mode="Continuous">
			<header>
				<startTimeStamp>2022-11-11T16:28:16-05:00</startTimeStamp>
				<endTimeStamp>2022-11-11T16:33:14-05:00</endTimeStamp>
				<author>
					<name>User</name>
				</author>
				<source>
					<applicationSoftware version="7.1">Data Collector</applicationSoftware>
					<instrumentControlSoftware version="8.2  20201204">EMPYREAN</instrumentControlSoftware>
					<instrumentID>0000000011260721</instrumentID>
				</source>
			</header>
			<dataPoints>
				<positions axis="2Theta" unit="deg">
					<startPosition>70.3165596731198</startPosition>
					<endPosition>73.6638294443363</endPosition>
				</positions>
				<positions axis="Omega" unit="deg">
					<commonPosition>17.511697279364</commonPosition>
				</positions>
				<positions axis="Phi" unit="deg">
					<commonPosition>93.93</commonPosition>
				</positions>
				<positions axis="Chi" unit="deg">
					<commonPosition>0</commonPosition>
				</positions>
				<positions axis="Z" unit="mm">
					<commonPosition>8.387</commonPosition>
				</positions>
				<commonCountingTime unit="seconds">0.309</commonCountingTime>
				<counts unit="counts">0 1 0 0 0 0 0 0 0 0 0 0 0 0 0 0 0 0 0 0 0 0 0 0 0 0 0 0 0 0 0 0 0 0 0 1 0 1 0 0 0 0 0 0 0 0 0 0 0 0 1 0 0 0 0 0 0 0 0 0 0 0 0 0 0 0 0 0 0 0 0 0 1 0 0 1 0 0 0 0 0 0 0 0 1 0 0 0 0 0 0 0 0 0 0 0 0 0 0 1 1 0 0 0 1 0 0 0 0 0 0 0 0 0 0 0 0 0 0 0 0 0 0 0 0 0 0 1 0 0 0 0 0 0 0 0 0 0 0 0 1 0 0 1 0 0 0 0 0 0 0 0 1 0 0 0 0 0 0 2 0 0 2 1 0 0 0 0 0 0 0 0 0 0 0 0 0 0 0 0 0 0 0 0 0 0 0 0 0 0 0 0 0 0 0 0 0 1 1 1 1 0 0 0 0 0 0 1 0 0 0 0 0 1 0 0 1 0 1 0 0 0 0 0 0 0 0 0 0 0 0 0 0 0 1 0 0 0 0 1 0 0 0 0 0 0 0 0 0 0 0 0 1 0 0</counts>
			</dataPoints>
		</scan>
		<scan status="Completed" appendNumber="0" scanAxis="2Theta" mode="Continuous">
			<header>
				<startTimeStamp>2022-11-11T16:28:16-05:00</startTimeStamp>
				<endTimeStamp>2022-11-11T16:33:14-05:00</endTimeStamp>
				<author>
					<name>User</name>
				</author>
				<source>
					<applicationSoftware version="7.1">Data Collector</applicationSoftware>
					<instrumentControlSoftware version="8.2  20201204">EMPYREAN</instrumentControlSoftware>
					<instrumentID>0000000011260721</instrumentID>
				</source>
			</header>
			<dataPoints>
				<positions axis="2Theta" unit="deg">
					<startPosition>70.3231248144575</startPosition>
					<endPosition>73.670394585674</endPosition>
				</positions>
				<positions axis="Omega" unit="deg">
					<commonPosition>17.5149798500329</commonPosition>
				</positions>
				<positions axis="Phi" unit="deg">
					<commonPosition>93.93</commonPosition>
				</positions>
				<positions axis="Chi" unit="deg">
					<commonPosition>0</commonPosition>
				</positions>
				<positions axis="Z" unit="mm">
					<commonPosition>8.387</commonPosition>
				</positions>
				<commonCountingTime unit="seconds">0.309</commonCountingTime>
				<counts unit="counts">0 0 0 0 0 0 0 0 1 0 0 1 0 0 0 0 0 0 0 0 0 0 1 0 1 1 1 0 0 0 0 0 0 0 0 0 0 0 0 0 0 0 0 0 0 0 0 0 0 0 0 0 1 1 1 0 1 1 0 0 0 0 1 0 0 0 0 0 0 0 0 0 0 1 0 0 0 0 0 0 0 0 2 0 0 0 0 0 0 1 0 0 0 0 0 0 1 0 1 0 2 0 0 0 1 1 0 0 0 2 0 0 0 1 0 0 0 0 0 0 0 0 1 0 0 0 0 0 0 0 0 0 0 1 0 0 0 1 0 0 0 0 0 0 0 1 0 0 1 0 0 0 0 0 0 0 0 1 1 0 0 0 0 0 0 0 0 0 1 0 0 0 0 0 0 0 0 0 1 0 0 0 0 0 0 0 0 1 1 0 0 0 0 0 0 0 0 0 0 0 0 0 0 0 1 0 1 0 0 1 1 1 0 0 0 0 0 0 1 0 0 0 0 0 0 0 0 1 0 0 0 1 2 0 0 0 0 0 0 0 1 1 1 0 1 1 0 0 1 0 0 0 1 0 0</counts>
			</dataPoints>
		</scan>
		<scan status="Completed" appendNumber="0" scanAxis="2Theta" mode="Continuous">
			<header>
				<startTimeStamp>2022-11-11T16:28:16-05:00</startTimeStamp>
				<endTimeStamp>2022-11-11T16:33:14-05:00</endTimeStamp>
				<author>
					<name>User</name>
				</author>
				<source>
					<applicationSoftware version="7.1">Data Collector</applicationSoftware>
					<instrumentControlSoftware version="8.2  20201204">EMPYREAN</instrumentControlSoftware>
					<instrumentID>0000000011260721</instrumentID>
				</source>
			</header>
			<dataPoints>
				<positions axis="2Theta" unit="deg">
					<startPosition>70.3296899557953</startPosition>
					<endPosition>73.6769597270117</endPosition>
				</positions>
				<positions axis="Omega" unit="deg">
					<commonPosition>17.5182624207018</commonPosition>
				</positions>
				<positions axis="Phi" unit="deg">
					<commonPosition>93.93</commonPosition>
				</positions>
				<positions axis="Chi" unit="deg">
					<commonPosition>0</commonPosition>
				</positions>
				<positions axis="Z" unit="mm">
					<commonPosition>8.387</commonPosition>
				</positions>
				<commonCountingTime unit="seconds">0.309</commonCountingTime>
				<counts unit="counts">0 0 0 1 1 0 0 0 1 0 0 0 0 0 0 0 0 0 0 0 0 0 1 0 0 1 0 1 0 0 0 0 0 0 1 0 0 0 1 0 0 0 0 0 0 0 0 0 0 0 0 0 0 0 0 1 0 0 0 0 0 2 0 0 1 0 0 0 0 0 0 0 0 1 0 0 0 0 0 0 0 0 0 0 2 0 0 0 1 0 0 0 0 0 0 0 0 0 0 0 0 0 0 0 0 1 0 0 0 0 0 0 1 1 0 0 0 0 1 0 0 0 1 0 0 0 0 0 1 0 0 0 0 1 0 1 0 0 0 0 0 0 0 0 0 0 0 0 0 1 0 0 0 0 1 1 0 0 0 0 0 0 0 0 0 0 0 0 0 0 0 0 0 0 0 0 1 0 0 0 1 0 0 0 0 0 0 0 0 0 1 0 0 0 1 1 1 0 0 0 0 0 0 3 0 0 0 1 0 0 0 0 0 0 0 0 0 0 0 0 0 0 0 0 0 0 0 0 0 0 0 0 0 0 0 0 0 0 0 0 0 0 0 0 0 0 0 0 0 0 0 0 0 0 0</counts>
			</dataPoints>
		</scan>
		<scan status="Completed" appendNumber="0" scanAxis="2Theta" mode="Continuous">
			<header>
				<startTimeStamp>2022-11-11T16:28:16-05:00</startTimeStamp>
				<endTimeStamp>2022-11-11T16:33:14-05:00</endTimeStamp>
				<author>
					<name>User</name>
				</author>
				<source>
					<applicationSoftware version="7.1">Data Collector</applicationSoftware>
					<instrumentControlSoftware version="8.2  20201204">EMPYREAN</instrumentControlSoftware>
					<instrumentID>0000000011260721</instrumentID>
				</source>
			</header>
			<dataPoints>
				<positions axis="2Theta" unit="deg">
					<startPosition>70.336255097133</startPosition>
					<endPosition>73.6835248683495</endPosition>
				</positions>
				<positions axis="Omega" unit="deg">
					<commonPosition>17.5215449913706</commonPosition>
				</positions>
				<positions axis="Phi" unit="deg">
					<commonPosition>93.93</commonPosition>
				</positions>
				<positions axis="Chi" unit="deg">
					<commonPosition>0</commonPosition>
				</positions>
				<positions axis="Z" unit="mm">
					<commonPosition>8.387</commonPosition>
				</positions>
				<commonCountingTime unit="seconds">0.309</commonCountingTime>
				<counts unit="counts">0 0 0 0 1 0 0 0 0 1 0 0 1 1 0 0 0 2 0 0 1 0 0 2 0 0 0 1 0 0 0 0 0 0 0 0 0 0 0 0 0 0 0 0 0 0 0 0 0 0 0 0 1 0 0 0 0 0 0 0 0 1 1 0 0 0 0 0 1 1 1 0 0 0 0 0 0 0 0 0 0 0 0 0 0 1 0 0 0 0 0 1 0 0 0 0 0 0 1 0 1 1 0 0 0 0 1 0 1 0 0 1 0 1 0 0 0 0 0 0 0 0 0 0 0 0 0 0 0 0 0 0 0 0 0 0 0 0 0 0 0 0 0 0 0 0 0 0 0 0 0 0 0 0 0 0 0 0 0 0 0 0 1 0 0 0 1 0 0 0 0 0 0 0 0 0 0 0 0 0 1 0 0 0 0 0 0 0 0 0 0 0 0 0 0 2 0 0 0 0 0 0 0 0 0 2 1 1 1 0 0 0 0 0 0 1 0 0 0 0 0 0 0 0 0 0 1 0 1 0 0 0 0 0 1 0 0 2 0 0 0 0 0 0 0 0 0 0 0 0 2 0 0 0 0</counts>
			</dataPoints>
		</scan>
		<scan status="Completed" appendNumber="0" scanAxis="2Theta" mode="Continuous">
			<header>
				<startTimeStamp>2022-11-11T16:28:16-05:00</startTimeStamp>
				<endTimeStamp>2022-11-11T16:33:14-05:00</endTimeStamp>
				<author>
					<name>User</name>
				</author>
				<source>
					<applicationSoftware version="7.1">Data Collector</applicationSoftware>
					<instrumentControlSoftware version="8.2  20201204">EMPYREAN</instrumentControlSoftware>
					<instrumentID>0000000011260721</instrumentID>
				</source>
			</header>
			<dataPoints>
				<positions axis="2Theta" unit="deg">
					<startPosition>70.3428202384707</startPosition>
					<endPosition>73.6900900096872</endPosition>
				</positions>
				<positions axis="Omega" unit="deg">
					<commonPosition>17.5248275620395</commonPosition>
				</positions>
				<positions axis="Phi" unit="deg">
					<commonPosition>93.93</commonPosition>
				</positions>
				<positions axis="Chi" unit="deg">
					<commonPosition>0</commonPosition>
				</positions>
				<positions axis="Z" unit="mm">
					<commonPosition>8.387</commonPosition>
				</positions>
				<commonCountingTime unit="seconds">0.309</commonCountingTime>
				<counts unit="counts">0 1 1 0 0 0 1 0 0 0 0 0 0 0 1 0 0 0 0 0 0 0 0 0 0 0 1 0 0 0 1 1 0 1 0 0 1 0 1 0 0 0 0 0 1 0 0 0 0 0 0 0 0 1 0 1 0 0 0 0 0 1 0 0 1 1 0 0 0 1 0 0 0 0 1 3 0 0 0 0 2 0 0 0 1 1 0 0 0 0 0 0 0 0 0 1 0 0 0 0 0 0 1 0 1 1 0 0 0 0 0 0 0 1 0 0 0 0 0 0 0 0 0 0 0 0 0 0 0 0 0 0 0 0 0 0 0 0 0 0 0 0 0 0 1 0 0 0 0 1 0 0 0 0 0 0 0 0 0 1 0 0 0 0 0 0 0 0 1 0 1 0 0 0 1 0 0 1 0 0 0 0 1 0 0 0 0 0 0 0 0 1 0 0 1 0 0 0 0 0 1 1 1 0 0 1 0 0 0 0 0 0 0 0 0 1 0 0 0 2 0 0 0 1 1 0 0 0 0 0 0 0 0 0 0 0 0 1 0 1 0 0 0 0 0 0 0 0 0 0 0 0 0 0 0</counts>
			</dataPoints>
		</scan>
		<scan status="Completed" appendNumber="0" scanAxis="2Theta" mode="Continuous">
			<header>
				<startTimeStamp>2022-11-11T16:28:16-05:00</startTimeStamp>
				<endTimeStamp>2022-11-11T16:33:14-05:00</endTimeStamp>
				<author>
					<name>User</name>
				</author>
				<source>
					<applicationSoftware version="7.1">Data Collector</applicationSoftware>
					<instrumentControlSoftware version="8.2  20201204">EMPYREAN</instrumentControlSoftware>
					<instrumentID>0000000011260721</instrumentID>
				</source>
			</header>
			<dataPoints>
				<positions axis="2Theta" unit="deg">
					<startPosition>70.3493853798084</startPosition>
					<endPosition>73.6966551510249</endPosition>
				</positions>
				<positions axis="Omega" unit="deg">
					<commonPosition>17.5281101327083</commonPosition>
				</positions>
				<positions axis="Phi" unit="deg">
					<commonPosition>93.93</commonPosition>
				</positions>
				<positions axis="Chi" unit="deg">
					<commonPosition>0</commonPosition>
				</positions>
				<positions axis="Z" unit="mm">
					<commonPosition>8.387</commonPosition>
				</positions>
				<commonCountingTime unit="seconds">0.309</commonCountingTime>
				<counts unit="counts">0 0 0 0 0 0 0 0 0 0 0 0 0 0 0 1 0 0 0 0 0 0 0 0 0 0 0 0 0 0 0 0 1 0 0 0 0 0 0 0 0 0 0 0 0 0 0 0 0 0 0 0 0 0 0 0 0 1 0 0 0 0 0 1 0 0 1 0 0 0 0 0 0 0 0 0 0 0 0 0 0 0 0 0 0 1 0 0 0 0 0 1 0 0 0 0 0 0 0 0 0 2 2 0 0 0 0 0 0 0 0 0 0 0 0 0 1 0 0 0 0 0 0 0 0 0 0 0 0 0 0 1 0 0 0 0 1 2 0 0 0 0 0 0 0 0 0 1 0 1 0 1 0 0 0 0 0 0 0 0 0 0 0 0 0 0 1 0 0 0 1 0 0 0 0 0 0 0 1 0 0 0 0 1 0 0 0 1 0 0 0 0 1 0 1 0 1 0 0 0 0 0 0 0 0 0 2 1 0 0 0 0 0 0 0 1 1 0 0 0 0 0 0 1 1 0 0 0 0 0 0 0 0 0 0 0 1 0 0 0 0 0 0 0 0 0 1 2 1 0 1 0 0 0 0</counts>
			</dataPoints>
		</scan>
		<scan status="Completed" appendNumber="0" scanAxis="2Theta" mode="Continuous">
			<header>
				<startTimeStamp>2022-11-11T16:28:16-05:00</startTimeStamp>
				<endTimeStamp>2022-11-11T16:33:14-05:00</endTimeStamp>
				<author>
					<name>User</name>
				</author>
				<source>
					<applicationSoftware version="7.1">Data Collector</applicationSoftware>
					<instrumentControlSoftware version="8.2  20201204">EMPYREAN</instrumentControlSoftware>
					<instrumentID>0000000011260721</instrumentID>
				</source>
			</header>
			<dataPoints>
				<positions axis="2Theta" unit="deg">
					<startPosition>70.3559505211462</startPosition>
					<endPosition>73.7032202923626</endPosition>
				</positions>
				<positions axis="Omega" unit="deg">
					<commonPosition>17.5313927033772</commonPosition>
				</positions>
				<positions axis="Phi" unit="deg">
					<commonPosition>93.93</commonPosition>
				</positions>
				<positions axis="Chi" unit="deg">
					<commonPosition>0</commonPosition>
				</positions>
				<positions axis="Z" unit="mm">
					<commonPosition>8.387</commonPosition>
				</positions>
				<commonCountingTime unit="seconds">0.309</commonCountingTime>
[...]
					<commonPosition>0</commonPosition>
				</positions>
				<positions axis="Z" unit="mm">
					<commonPosition>8.387</commonPosition>
				</positions>
				<commonCountingTime unit="seconds">0.309</commonCountingTime>
				<counts unit="counts">0 0 0 0 0 0 1 1 0 0 0 0 0 0 0 0 0 0 0 0 0 0 1 0 0 0 1 0 0 0 0 0 0 0 0 0 0 0 0 0 0 0 1 0 0 0 0 0 0 0 0 0 0 2 0 0 0 0 0 1 0 0 0 0 0 0 0 0 0 0 1 0 0 2 0 0 0 0 1 0 0 0 0 0 0 0 0 0 0 0 2 0 0 0 0 0 0 0 0 0 0 0 0 0 1 0 0 0 0 0 0 0 0 0 0 0 0 0 0 0 0 0 0 0 0 0 0 0 1 0 1 0 0 0 0 1 0 0 0 0 0 1 0 1 0 1 0 0 0 0 1 0 0 0 0 0 0 0 0 0 0 0 0 0 0 0 0 0 0 0 0 0 0 0 0 0 0 1 1 1 0 0 1 2 0 0 0 0 0 0 0 0 0 0 0 0 0 0 0 0 0 0 0 0 0 0 0 0 0 0 1 2 0 0 0 0 0 0 0 0 0 0 0 1 1 0 1 0 0 0 0 0 0 0 0 0 0 0 0 0 0 0 0 0 0 0 0 0 0 0 0 0 0 0 0</counts>
			</dataPoints>
		</scan>
		<scan status="Completed" appendNumber="0" scanAxis="2Theta" mode="Continuous">
			<header>
				<startTimeStamp>2022-11-11T16:28:16-05:00</startTimeStamp>
				<endTimeStamp>2022-11-11T16:33:14-05:00</endTimeStamp>
				<author>
					<name>User</name>
				</author>
				<source>
					<applicationSoftware version="7.1">Data Collector</applicationSoftware>
					<instrumentControlSoftware version="8.2  20201204">EMPYREAN</instrumentControlSoftware>
					<instrumentID>0000000011260721</instrumentID>
				</source>
			</header>
			<dataPoints>
				<positions axis="2Theta" unit="deg">
					<startPosition>76.1464051810146</startPosition>
					<endPosition>79.493674952231</endPosition>
				</positions>
				<positions axis="Omega" unit="deg">
					<commonPosition>20.4266200333114</commonPosition>
				</positions>
				<positions axis="Phi" unit="deg">
					<commonPosition>93.93</commonPosition>
				</positions>
				<positions axis="Chi" unit="deg">
					<commonPosition>0</commonPosition>
				</positions>
				<positions axis="Z" unit="mm">
					<commonPosition>8.387</commonPosition>
				</positions>
				<commonCountingTime unit="seconds">0.309</commonCountingTime>
				<counts unit="counts">0 0 0 1 0 0 0 0 0 1 0 0 0 0 0 0 0 0 0 0 0 0 0 0 0 0 1 0 0 0 0 0 0 0 0 0 0 0 0 0 0 1 0 1 0 0 0 0 0 0 1 0 0 0 0 0 0 0 1 0 0 0 0 0 0 0 0 2 0 2 0 0 0 0 0 0 0 0 0 0 0 0 0 0 0 0 0 0 0 0 0 0 0 0 0 1 0 0 0 0 0 0 1 0 1 0 0 0 0 1 0 0 1 0 0 0 1 1 0 0 0 0 0 0 0 0 0 0 0 0 1 0 0 1 0 0 0 1 0 0 2 0 1 0 0 0 0 2 0 0 2 0 0 0 0 1 1 1 0 0 1 0 0 0 0 0 0 0 0 0 1 0 0 1 0 0 0 0 0 0 0 1 0 0 0 0 0 0 0 0 0 0 0 0 0 0 0 0 1 0 0 0 0 0 1 0 0 0 0 0 0 1 0 0 1 0 1 0 0 0 0 0 0 0 1 0 0 0 0 1 0 0 0 0 0 0 0 0 0 2 0 0 0 0 0 1 0 0 0 1 0 0 0 1 0</counts>
			</dataPoints>
		</scan>
		<scan status="Completed" appendNumber="0" scanAxis="2Theta" mode="Continuous">
			<header>
				<startTimeStamp>2022-11-11T16:28:16-05:00</startTimeStamp>
				<endTimeStamp>2022-11-11T16:33:14-05:00</endTimeStamp>
				<author>
					<name>User</name>
				</author>
				<source>
					<applicationSoftware version="7.1">Data Collector</applicationSoftware>
					<instrumentControlSoftware version="8.2  20201204">EMPYREAN</instrumentControlSoftware>
					<instrumentID>0000000011260721</instrumentID>
				</source>
			</header>
			<dataPoints>
				<positions axis="2Theta" unit="deg">
					<startPosition>76.1529703223523</startPosition>
					<endPosition>79.5002400935688</endPosition>
				</positions>
				<positions axis="Omega" unit="deg">
					<commonPosition>20.4299026039803</commonPosition>
				</positions>
				<positions axis="Phi" unit="deg">
					<commonPosition>93.93</commonPosition>
				</positions>
				<positions axis="Chi" unit="deg">
					<commonPosition>0</commonPosition>
				</positions>
				<positions axis="Z" unit="mm">
					<commonPosition>8.387</commonPosition>
				</positions>
				<commonCountingTime unit="seconds">0.309</commonCountingTime>
				<counts unit="counts">0 0 0 0 1 0 0 0 0 0 0 0 0 0 0 0 0 0 0 0 0 0 0 0 0 0 1 0 0 0 0 0 0 0 0 0 1 0 0 0 0 0 0 0 0 0 0 0 0 0 0 0 0 0 0 0 0 0 0 0 0 0 0 0 0 0 0 0 0 1 0 0 1 0 0 0 0 1 0 0 0 0 0 0 0 0 1 0 0 0 0 0 0 0 0 0 0 0 0 1 0 0 0 0 0 0 0 0 2 0 0 0 0 0 0 0 0 0 0 0 0 0 0 0 0 0 0 0 0 1 0 1 1 0 0 0 0 0 1 0 0 0 0 0 0 0 0 0 0 1 0 0 0 0 0 1 0 0 0 0 0 0 0 0 0 0 0 0 0 0 0 0 0 1 0 0 0 0 0 0 1 0 0 1 2 0 0 1 0 0 0 0 0 0 0 0 0 0 0 0 0 0 0 1 0 0 0 0 0 0 0 0 0 1 0 0 0 0 0 0 0 0 0 0 0 0 0 0 0 0 0 0 0 0 0 0 0 0 0 0 0 0 0 0 0 0 0 0 0 0 0 0 0 1 0</counts>
			</dataPoints>
		</scan>
		<scan status="Completed" appendNumber="0" scanAxis="2Theta" mode="Continuous">
			<header>
				<startTimeStamp>2022-11-11T16:28:16-05:00</startTimeStamp>
				<endTimeStamp>2022-11-11T16:33:14-05:00</endTimeStamp>
				<author>
					<name>User</name>
				</author>
				<source>
					<applicationSoftware version="7.1">Data Collector</applicationSoftware>
					<instrumentControlSoftware version="8.2  20201204">EMPYREAN</instrumentControlSoftware>
					<instrumentID>0000000011260721</instrumentID>
				</source>
			</header>
			<dataPoints>
				<positions axis="2Theta" unit="deg">
					<startPosition>76.15953546369</startPosition>
					<endPosition>79.5068052349065</endPosition>
				</positions>
				<positions axis="Omega" unit="deg">
					<commonPosition>20.4331851746491</commonPosition>
				</positions>
				<positions axis="Phi" unit="deg">
					<commonPosition>93.93</commonPosition>
				</positions>
				<positions axis="Chi" unit="deg">
					<commonPosition>0</commonPosition>
				</positions>
				<positions axis="Z" unit="mm">
					<commonPosition>8.387</commonPosition>
				</positions>
				<commonCountingTime unit="seconds">0.309</commonCountingTime>
				<counts unit="counts">1 0 0 0 0 0 0 0 0 1 0 0 0 0 0 0 0 1 0 0 0 0 0 0 0 0 1 1 0 0 0 0 0 0 0 0 1 0 0 0 0 0 0 0 0 2 0 0 0 0 0 0 0 0 0 0 0 0 0 0 1 0 0 1 0 1 0 0 0 0 0 0 0 0 0 0 0 1 0 0 0 0 1 0 0 0 0 0 1 0 0 0 0 0 0 0 0 0 0 0 0 0 0 0 0 0 4 0 0 0 0 0 0 0 0 0 1 0 0 0 1 2 0 0 0 1 0 1 0 0 0 0 1 0 0 0 0 0 0 0 0 0 0 0 1 0 0 0 0 0 0 0 0 0 0 0 0 0 0 0 0 0 0 0 0 0 0 0 0 0 0 0 0 0 0 0 0 2 0 0 0 0 0 0 0 0 1 1 0 0 0 0 0 0 0 0 0 1 0 1 0 0 0 0 0 0 0 0 1 0 0 0 0 0 0 1 0 0 0 0 0 0 1 1 0 0 0 0 0 1 0 0 0 0 1 0 0 0 1 0 0 0 0 0 0 0 0 0 0 0 0 1 0 0 0</counts>
			</dataPoints>
		</scan>
		<scan status="Completed" appendNumber="0" scanAxis="2Theta" mode="Continuous">
			<header>
				<startTimeStamp>2022-11-11T16:28:16-05:00</startTimeStamp>
				<endTimeStamp>2022-11-11T16:33:14-05:00</endTimeStamp>
				<author>
					<name>User</name>
				</author>
				<source>
					<applicationSoftware version="7.1">Data Collector</applicationSoftware>
					<instrumentControlSoftware version="8.2  20201204">EMPYREAN</instrumentControlSoftware>
					<instrumentID>0000000011260721</instrumentID>
				</source>
			</header>
			<dataPoints>
				<positions axis="2Theta" unit="deg">
					<startPosition>76.1661006050277</startPosition>
					<endPosition>79.5133703762442</endPosition>
				</positions>
				<positions axis="Omega" unit="deg">
					<commonPosition>20.436467745318</commonPosition>
				</positions>
				<positions axis="Phi" unit="deg">
					<commonPosition>93.93</commonPosition>
				</positions>
				<positions axis="Chi" unit="deg">
					<commonPosition>0</commonPosition>
				</positions>
				<positions axis="Z" unit="mm">
					<commonPosition>8.387</commonPosition>
				</positions>
				<commonCountingTime unit="seconds">0.309</commonCountingTime>
				<counts unit="counts">1 0 0 0 1 0 0 0 0 0 0 0 0 0 0 1 0 0 0 0 0 1 1 1 1 0 0 0 0 1 1 0 0 0 0 0 0 0 0 1 0 1 0 0 0 0 0 0 1 0 0 1 0 1 0 0 0 0 0 0 0 0 0 1 0 0 2 0 0 0 0 0 0 0 0 0 0 0 0 0 0 0 0 0 0 0 0 1 2 0 1 0 1 0 1 0 0 0 0 1 0 0 0 0 0 0 0 0 0 0 0 1 1 0 0 0 0 0 0 0 1 0 0 0 0 0 0 0 0 0 0 0 0 1 0 0 0 0 0 0 0 0 0 0 0 0 0 0 0 2 1 0 1 0 0 0 0 0 0 0 0 0 0 0 0 0 1 0 0 0 0 0 0 0 0 0 2 0 1 0 1 0 0 0 0 0 0 0 1 1 0 1 0 0 0 0 0 0 0 0 1 0 0 0 0 0 0 1 0 0 0 0 0 0 0 0 0 0 0 0 0 0 0 0 0 1 0 0 0 0 0 1 0 0 0 0 0 0 0 0 0 0 0 0 0 0 0 0 1 0 0 1 0 1 0</counts>
			</dataPoints>
		</scan>
		<scan status="Completed" appendNumber="0" scanAxis="2Theta" mode="Continuous">
			<header>
				<startTimeStamp>2022-11-11T16:28:16-05:00</startTimeStamp>
				<endTimeStamp>2022-11-11T16:33:14-05:00</endTimeStamp>
				<author>
					<name>User</name>
				</author>
				<source>
					<applicationSoftware version="7.1">Data Collector</applicationSoftware>
					<instrumentControlSoftware version="8.2  20201204">EMPYREAN</instrumentControlSoftware>
					<instrumentID>0000000011260721</instrumentID>
				</source>
			</header>
			<dataPoints>
				<positions axis="2Theta" unit="deg">
					<startPosition>76.1726657463655</startPosition>
					<endPosition>79.5199355175819</endPosition>
				</positions>
				<positions axis="Omega" unit="deg">
					<commonPosition>20.4397503159868</commonPosition>
				</positions>
				<positions axis="Phi" unit="deg">
					<commonPosition>93.93</commonPosition>
				</positions>
				<positions axis="Chi" unit="deg">
					<commonPosition>0</commonPosition>
				</positions>
				<positions axis="Z" unit="mm">
					<commonPosition>8.387</commonPosition>
				</positions>
				<commonCountingTime unit="seconds">0.309</commonCountingTime>
				<counts unit="counts">0 1 0 0 0 0 1 0 0 1 0 0 0 0 0 1 0 0 0 0 0 0 0 0 0 1 0 0 0 0 0 0 1 0 0 0 0 0 0 0 0 0 0 0 0 1 0 0 0 0 1 0 0 0 1 0 1 0 0 0 1 0 0 1 0 0 0 0 0 0 0 0 0 0 0 0 0 0 0 0 0 0 0 0 0 0 0 1 1 0 0 1 1 1 1 0 0 0 0 1 0 0 0 0 0 1 0 0 0 0 0 0 0 0 0 0 0 0 0 0 0 0 1 0 0 1 0 0 0 0 0 1 0 0 0 0 0 0 0 0 0 1 0 0 0 0 0 1 0 1 1 0 0 0 0 0 0 0 0 0 0 0 0 0 0 1 0 0 1 0 0 0 1 1 0 0 0 0 0 0 0 0 1 1 1 0 0 0 0 0 0 0 0 1 0 0 2 0 0 0 0 0 0 0 0 0 0 0 1 1 0 0 0 0 0 0 0 1 0 0 0 1 0 0 0 0 0 0 0 0 0 0 0 0 0 0 0 0 0 0 0 0 1 0 0 0 0 1 0 1 0 0 0 0 0</counts>
			</dataPoints>
		</scan>
		<scan status="Completed" appendNumber="0" scanAxis="2Theta" mode="Continuous">
			<header>
				<startTimeStamp>2022-11-11T16:28:16-05:00</startTimeStamp>
				<endTimeStamp>2022-11-11T16:33:14-05:00</endTimeStamp>
				<author>
					<name>User</name>
				</author>
				<source>
					<applicationSoftware version="7.1">Data Collector</applicationSoftware>
					<instrumentControlSoftware version="8.2  20201204">EMPYREAN</instrumentControlSoftware>
					<instrumentID>0000000011260721</instrumentID>
				</source>
			</header>
			<dataPoints>
				<positions axis="2Theta" unit="deg">
					<startPosition>76.1792308877032</startPosition>
					<endPosition>79.5265006589196</endPosition>
				</positions>
				<positions axis="Omega" unit="deg">
					<commonPosition>20.4430328866557</commonPosition>
				</positions>
				<positions axis="Phi" unit="deg">
					<commonPosition>93.93</commonPosition>
				</positions>
				<positions axis="Chi" unit="deg">
					<commonPosition>0</commonPosition>
				</positions>
				<positions axis="Z" unit="mm">
					<commonPosition>8.387</commonPosition>
				</positions>
				<commonCountingTime unit="seconds">0.309</commonCountingTime>
				<counts unit="counts">0 0 0 2 0 0 1 0 0 0 0 0 0 0 0 0 0 0 0 0 0 0 0 0 0 0 0 0 0 0 0 0 0 0 0 0 1 0 0 0 2 0 0 0 0 1 1 0 0 0 1 0 0 0 0 0 0 0 0 1 0 0 3 0 0 0 0 0 0 0 0 0 0 1 0 0 0 0 0 0 0 0 0 0 2 0 0 1 0 0 1 0 0 0 1 0 0 0 0 0 0 0 0 0 1 0 0 0 0 1 0 0 0 0 0 0 1 1 0 0 0 0 0 0 2 0 0 2 0 0 0 0 1 0 1 0 0 0 0 0 0 0 0 0 0 0 0 0 0 0 1 0 0 0 0 0 0 1 0 0 0 0 1 0 0 0 1 0 0 0 1 0 0 0 0 0 0 0 0 0 0 0 0 1 0 0 0 0 0 0 0 0 1 0 0 0 0 0 0 0 0 0 0 0 0 0 0 0 0 0 0 0 0 1 1 0 1 0 0 0 1 0 0 1 0 0 0 0 0 0 0 2 0 0 0 0 0 0 1 0 0 0 0 2 0 0 0 0 0 0 0 1 0 1 0</counts>
			</dataPoints>
		</scan>
		<scan status="Completed" appendNumber="0" scanAxis="2Theta" mode="Continuous">
			<header>
				<startTimeStamp>2022-11-11T16:28:16-05:00</startTimeStamp>
				<endTimeStamp>2022-11-11T16:33:14-05:00</endTimeStamp>
				<author>
					<name>User</name>
				</author>
				<source>
					<applicationSoftware version="7.1">Data Collector</applicationSoftware>
					<instrumentControlSoftware version="8.2  20201204">EMPYREAN</instrumentControlSoftware>
					<instrumentID>0000000011260721</instrumentID>
				</source>
			</header>
			<dataPoints>
				<positions axis="2Theta" unit="deg">
					<startPosition>76.1857960290409</startPosition>
					<endPosition>79.5330658002574</endPosition>
				</positions>
				<positions axis="Omega" unit="deg">
					<commonPosition>20.4463154573246</commonPosition>
				</positions>
				<positions axis="Phi" unit="deg">
					<commonPosition>93.93</commonPosition>
				</positions>
				<positions axis="Chi" unit="deg">
					<commonPosition>0</commonPosition>
				</positions>
				<positions axis="Z" unit="mm">
					<commonPosition>8.387</commonPosition>
				</positions>
				<commonCountingTime unit="seconds">0.309</commonCountingTime>
				<counts unit="counts">0 0 0 0 0 0 0 0 0 0 0 1 0 0 0 0 0 0 0 0 0 0 0 0 1 0 1 0 0 0 0 0 0 0 0 0 0 0 0 0 0 0 0 0 0 0 0 0 0 0 0 0 0 1 0 1 0 0 0 1 0 0 0 0 1 0 0 0 0 0 0 0 0 0 0 0 0 0 0 0 0 0 0 0 0 0 0 2 0 0 1 0 0 0 0 0 0 0 0 0 0 0 0 1 0 0 0 0 1 0 0 0 0 0 0 3 0 0 0 0 1 0 1 1 0 0 0 0 1 0 1 0 0 0 0 0 0 0 0 0 0 0 0 0 0 0 0 1 0 0 0 0 0 0 0 0 0 0 0 0 0 0 0 0 0 0 0 0 0 0 0 0 0 1 0 0 2 0 0 2 0 0 0 0 0 0 0 0 0 0 0 1 0 0 1 0 0 0 0 0 0 0 0 0 0 0 0 0 0 0 0 1 0 0 0 0 0 0 0 0 0 0 0 1 0 0 1 0 0 0 1 0 0 0 0 1 0 1 1 0 2 0 0 0 0 0 0 0 0 0 0 0 0 0 0</counts>
			</dataPoints>
		</scan>
		<scan status="Completed" appendNumber="0" scanAxis="2Theta" mode="Continuous">
			<header>
				<startTimeStamp>2022-11-11T16:28:16-05:00</startTimeStamp>
				<endTimeStamp>2022-11-11T16:33:14-05:00</endTimeStamp>
				<author>
					<name>User</name>
				</author>
				<source>
					<applicationSoftware version="7.1">Data Collector</applicationSoftware>
					<instrumentControlSoftware version="8.2  20201204">EMPYREAN</instrumentControlSoftware>
					<instrumentID>0000000011260721</instrumentID>
				</source>
			</header>
			<dataPoints>
				<positions axis="2Theta" unit="deg">
					<startPosition>76.1923611703786</startPosition>
					<endPosition>79.5396309415951</endPosition>
				</positions>
				<positions axis="Omega" unit="deg">
					<commonPosition>20.4495980279934</commonPosition>
				</positions>
				<positions axis="Phi" unit="deg">
					<commonPosition>93.93</commonPosition>
				</positions>
				<positions axis="Chi" unit="deg">
					<commonPosition>0</commonPosition>
				</positions>
				<positions axis="Z" unit="mm">
					<commonPosition>8.387</commonPosition>
				</positions>
				<commonCountingTime unit="seconds">0.309</commonCountingTime>
				<counts unit="counts">1 1 0 0 0 0 0 1 0 0 0 0 0 0 2 0 0 0 0 0 0 0 0 0 0 0 0 0 1 0 0 0 0 0 0 0 0 0 0 0 0 0 0 0 0 0 0 0 0 0 0 1 0 0 0 0 0 0 0 0 0 0 1 0 0 0 0 2 0 0 0 1 0 0 0 2 0 1 1 0 0 0 0 0 0 0 0 0 1 0 0 0 0 2 0 1 0 0 0 1 0 0 0 0 0 0 0 0 1 0 0 0 0 0 0 0 0 0 0 0 0 1 0 0 0 0 0 1 0 0 0 0 1 1 0 0 0 0 0 0 0 0 0 1 1 1 0 0 0 0 0 0 0 0 0 0 0 0 0 0 0 0 0 0 0 0 0 0 0 2 0 0 0 0 0 0 1 0 0 0 0 0 0 1 0 0 0 0 0 0 0 0 0 1 0 0 0 0 0 0 0 0 0 0 0 0 0 0 0 1 0 0 0 0 1 0 0 0 0 0 0 0 0 0 0 0 1 0 0 0 0 1 0 0 0 0 0 0 1 0 0 0 0 0 0 0 0 0 0 0 0 1 0 0 0</counts>
			</dataPoints>
		</scan>
		<scan status="Completed" appendNumber="0" scanAxis="2Theta" mode="Continuous">
			<header>
				<startTimeStamp>2022-11-11T16:28:16-05:00</startTimeStamp>
				<endTimeStamp>2022-11-11T16:33:14-05:00</endTimeStamp>
				<author>
					<name>User</name>
				</author>
				<source>
					<applicationSoftware version="7.1">Data Collector</applicationSoftware>
					<instrumentControlSoftware version="8.2  20201204">EMPYREAN</instrumentControlSoftware>
					<instrumentID>0000000011260721</instrumentID>
				</source>
			</header>
			<dataPoints>
				<positions axis="2Theta" unit="deg">
					<startPosition>76.1989263117163</startPosition>
					<endPosition>79.5461960829328</endPosition>
				</positions>
				<positions axis="Omega" unit="deg">
					<commonPosition>20.4528805986623</commonPosition>
				</positions>
				<positions axis="Phi" unit="deg">
					<commonPosition>93.93</commonPosition>
				</positions>
				<positions axis="Chi" unit="deg">
					<commonPosition>0</commonPosition>
				</positions>
				<positions axis="Z" unit="mm">
					<commonPosition>8.387</commonPosition>
				</positions>
				<commonCountingTime unit="seconds">0.309</commonCountingTime>
				<counts unit="counts">0 0 0 0 0 0 0 0 0 1 0 0 0 0 0 0 0 0 1 0 0 0 0 0 1 0 0 0 1 0 0 0 0 0 0 0 0 0 0 0 0 1 0 0 0 0 0 0 0 0 0 0 0 0 1 0 0 0 0 0 0 0 1 0 1 0 1 0 1 1 0 0 0 1 0 0 0 0 0 0 0 0 1 0 0 1 0 0 0 1 0 0 0 0 0 0 0 0 0 0 0 0 0 0 2 0 1 0 0 0 1 0 0 0 0 0 0 0 0 1 0 0 0 0 0 0 0 0 1 0 0 0 1 0 1 0 0 0 0 1 0 0 0 0 0 0 0 0 0 0 0 0 0 0 0 0 0 1 0 0 0 0 0 0 1 0 0 0 1 0 0 1 0 0 1 0 0 0 0 1 0 0 0 0 1 0 1 0 0 1 0 1 0 0 0 0 0 0 0 0 0 0 0 0 0 0 1 0 0 0 0 0 0 0 0 0 0 0 0 0 0 0 0 1 0 0 0 0 0 0 0 0 0 0 0 0 1 0 0 0 0 0 2 0 1 0 0 0 0 0 0 0 0 0 0</counts>
			</dataPoints>
		</scan>
		<scan status="Completed" appendNumber="0" scanAxis="2Theta" mode="Continuous">
			<header>
				<startTimeStamp>2022-11-11T16:28:16-05:00</startTimeStamp>
				<endTimeStamp>2022-11-11T16:33:14-05:00</endTimeStamp>
				<author>
					<name>User</name>
				</author>
				<source>
					<applicationSoftware version="7.1">Data Collector</applicationSoftware>
					<instrumentControlSoftware version="8.2  20201204">EMPYREAN</instrumentControlSoftware>
					<instrumentID>0000000011260721</instrumentID>
				</source>
			</header>
			<dataPoints>
				<positions axis="2Theta" unit="deg">
					<startPosition>76.205491453054</startPosition>
					<endPosition>79.5527612242705</endPosition>
				</positions>
				<positions axis="Omega" unit="deg">
					<commonPosition>20.4561631693311</commonPosition>
				</positions>
				<positions axis="Phi" unit="deg">
					<commonPosition>93.93</commonPosition>
				</positions>
				<positions axis="Chi" unit="deg">
					<commonPosition>0</commonPosition>
				</positions>
				<positions axis="Z" unit="mm">
					<commonPosition>8.387</commonPosition>
				</positions>
				<commonCountingTime unit="seconds">0.309</commonCountingTime>
				<counts unit="counts">1 1 0 0 0 0 0 0 0 0 0 0 0 0 0 0 0 0 0 0 0 0 0 0 0 0 0 0 0 0 0 0 0 0 0 0 0 0 0 0 0 0 0 0 0 0 0 0 0 0 0 0 0 0 0 0 0 0 0 0 0 0 0 1 0 0 0 1 0 0 0 0 0 0 1 0 0 1 0 0 0 1 0 0 1 0 0 0 0 0 0 0 0 0 0 0 0 2 0 0 0 0 1 0 1 1 2 0 0 0 2 0 0 1 0 0 0 0 0 0 0 0 0 1 0 0 0 0 1 0 1 0 1 0 0 0 0 0 0 0 0 0 1 0 0 0 0 0 0 1 1 0 1 0 0 0 1 0 0 0 1 0 0 0 0 0 0 1 0 0 0 0 0 1 0 0 0 0 0 0 0 0 0 0 0 0 0 0 0 0 1 0 0 0 1 0 0 0 0 0 0 0 0 0 1 0 0 0 0 0 0 0 0 0 0 1 1 0 0 0 0 0 0 1 0 0 0 0 0 0 0 0 0 0 0 0 1 0 0 0 0 0 0 0 0 1 0 0 0 0 0 0 0 0 0</counts>
			</dataPoints>
		</scan>
		<scan status="Completed" appendNumber="0" scanAxis="2Theta" mode="Continuous">
			<header>
				<startTimeStamp>2022-11-11T16:28:16-05:00</startTimeStamp>
				<endTimeStamp>2022-11-11T16:33:14-05:00</endTimeStamp>
				<author>
					<name>User</name>
				</author>
				<source>
					<applicationSoftware version="7.1">Data Collector</applicationSoftware>
					<instrumentControlSoftware version="8.2  20201204">EMPYREAN</instrumentControlSoftware>
					<instrumentID>0000000011260721</instrumentID>
				</source>
			</header>
			<dataPoints>
				<positions axis="2Theta" unit="deg">
					<startPosition>76.2120565943918</startPosition>
					<endPosition>79.5593263656082</endPosition>
				</positions>
				<positions axis="Omega" unit="deg">
					<commonPosition>20.45944574</commonPosition>
				</positions>
				<positions axis="Phi" unit="deg">
					<commonPosition>93.93</commonPosition>
				</positions>
				<positions axis="Chi" unit="deg">
					<commonPosition>0</commonPosition>
				</positions>
				<positions axis="Z" unit="mm">
					<commonPosition>8.387</commonPosition>
				</positions>
				<commonCountingTime unit="seconds">0.309</commonCountingTime>
				<counts unit="counts">0 0 0 0 0 0 0 0 1 1 0 0 0 0 0 0 0 0 0 1 0 0 0 0 1 0 1 0 0 0 0 0 0 0 0 0 0 0 0 0 0 0 0 0 0 0 0 0 0 0 0 0 0 1 0 0 1 0 0 0 0 1 0 0 0 0 0 1 0 1 0 0 0 0 0 0 0 1 0 1 0 0 0 0 0 0 0 0 0 0 0 0 0 0 1 0 0 0 1 0 1 0 0 0 0 0 0 0 0 0 0 2 0 0 0 1 1 0 0 1 0 0 0 0 0 0 0 1 0 1 0 0 0 0 1 0 0 0 0 0 2 0 0 0 0 0 0 0 0 0 1 0 0 0 0 0 0 0 0 0 0 0 0 0 0 0 0 1 0 0 0 1 0 0 0 0 0 1 0 0 0 0 0 1 0 0 0 0 0 1 1 1 0 0 0 0 0 0 0 0 0 0 0 0 0 0 0 0 0 0 1 0 1 0 1 0 0 1 0 0 0 1 0 0 1 1 1 0 0 0 0 0 0 0 1 0 0 0 0 0 0 1 0 0 0 0 1 0 0 0 1 0 0 0 0</counts>
			</dataPoints>
		</scan>
	</xrdMeasurement>
</xrdMeasurements>