File: data/XRD_RSM/YG048/YCG_048 RSM slow 3 degree_1.xrdml
<?xml version="1.0" encoding="utf-8"?>
<xrdMeasurements xmlns="http://www.xrdml.com/XRDMeasurement/2.2" xmlns:xsi="http://www.w3.org/2001/XMLSchema-instance" xsi:schemaLocation="http://www.xrdml.com/XRDMeasurement/2.2 http://www.xrdml.com/XRDMeasurement/2.2/XRDMeasurement.xsd" status="Completed">
	<comment>
		<entry>Configuration=3-axes Cradle_Reflection, Owner=lw627, Creation date=9/2/2021 3:55:24 PM</entry>
		<entry>Goniometer=Theta/Theta; Minimum step size 2Theta:0.0001; Minimum step size Omega:0.0001</entry>
		<entry>Sample stage=Chi-Phi-z stage 240 mm (reflection); Minimum step size Phi:0.01; Minimum step size Chi:0.01; Minimum step size Z:0.001</entry>
		<entry>Diffractometer system=EMPYREAN</entry>
		<entry>Measurement program=C:\PANalytical\Data Collector\Programs\Liyan Wu\Film programs\RSM slow 3 degree.xrdmp, Identifier={0351664C-55A7-43E7-B72A-7307F4B26703}</entry>
	</comment>
	<sample type="To be analyzed">
		<id/>
		<name/>
		<preparedBy/>
	</sample>
	<xrdMeasurement status="Completed" measurementType="Area measurement" measurementStepAxis="Omega-2Theta" sampleMode="Reflection">
		<comment>
			<entry>PHD Lower Level = 4.02 (keV), PHD Upper Level = 11.27 (keV)</entry>
		</comment>
		<usedWavelength intended="K-Alpha 1">
			<kAlpha1 unit="Angstrom">1.5405980</kAlpha1>
			<kAlpha2 unit="Angstrom">1.5444260</kAlpha2>
			<kBeta unit="Angstrom">1.3922500</kBeta>
			<ratioKAlpha2KAlpha1>0</ratioKAlpha2KAlpha1>
		</usedWavelength>
		<incidentBeamPath>
			<radius unit="mm">240.00</radius>
			<xRayTube id="1010048" name="Empyrean Cu LFF HR (9430 033 7310x) DK432574">
				<tension unit="kV">45.0</tension>
				<current unit="mA">40.0</current>
				<anodeMaterial>Cu</anodeMaterial>
				<focus type="Line">
					<length unit="mm">12.0</length>
					<width unit="mm">0.4</width>
					<takeOffAngle unit="deg">4.4</takeOffAngle>
				</focus>
			</xRayTube>
			<xRayMirror xsi:type="xRayMirrorType" id="27080001" name="Inc. Beam Cu W/Si (hybrid MPD)" hybrid="true">
				<crystal type="Graded" shape="Parabolic">W/Si</crystal>
				<acceptanceAngle unit="deg">0.800</acceptanceAngle>
				<length unit="mm">55.3</length>
			</xRayMirror>
			<monochromator xsi:type="monochromatorType" id="23090002" name="Hybrid monochr. 2xGe220 Cu asym." hybrid="true">
				<crystal type="Asymmetric" shape="Flat">Ge</crystal>
				<numberOfReflections>2</numberOfReflections>
				<hkl>
					<h>2</h>
					<k>2</k>
					<l>0</l>
				</hkl>
			</monochromator>
			<divergenceSlit xsi:type="fixedDivergenceSlitType" id="22010005" name="Fixed slit 1/4°">
				<distanceToSample unit="mm">179.30</distanceToSample>
				<height unit="mm">0.38</height>
			</divergenceSlit>
		</incidentBeamPath>
		<diffractedBeamPath>
			<radius unit="mm">240.00</radius>
			<antiScatterSlit xsi:type="fixedAntiScatterSlitType" id="22060009" name="Programmable anti-scatter slit">
				<angle unit="deg">4</angle>
			</antiScatterSlit>
			<detector xsi:type="areaDetectorType" id="7010020" name="PIXcel3D-Medipix3 1x1 detector">
				<phd unit="%">
					<lowerLevel>25</lowerLevel>
					<upperLevel>70</upperLevel>
				</phd>
				<mode>Scanning snapshot equatorial</mode>
				<activeChannelsEquatorial>255</activeChannelsEquatorial>
				<activeChannelsAxial>255</activeChannelsAxial>
				<pitchEquatorial unit="mm">0.05500</pitchEquatorial>
				<pitchAxial unit="mm">0.05500</pitchAxial>
				<readOutPeriod unit="seconds">0.980</readOutPeriod>
			</detector>
		</diffractedBeamPath>
		<scan status="Completed" appendNumber="0" scanAxis="2Theta" mode="Continuous">
			<header>
				<startTimeStamp>2024-05-31T14:21:45-04:00</startTimeStamp>
				<endTimeStamp>2024-05-31T14:51:48-04:00</endTimeStamp>
				<author>
					<name>lw627</name>
				</author>
				<source>
					<applicationSoftware version="7.1">Data Collector</applicationSoftware>
					<instrumentControlSoftware version="8.2  20201204">EMPYREAN</instrumentControlSoftware>
					<instrumentID>0000000011260721</instrumentID>
				</source>
			</header>
			<dataPoints>
				<positions axis="2Theta" unit="deg">
					<startPosition>72.0614063943918</startPosition>
					<endPosition>75.4086761656082</endPosition>
				</positions>
				<positions axis="Omega" unit="deg">
					<commonPosition>18.33452064</commonPosition>
				</positions>
				<positions axis="Phi" unit="deg">
					<commonPosition>-92.36</commonPosition>
				</positions>
				<positions axis="Chi" unit="deg">
					<commonPosition>0</commonPosition>
				</positions>
				<positions axis="Z" unit="mm">
					<commonPosition>8.35</commonPosition>
				</positions>
				<commonCountingTime unit="seconds">0.974</commonCountingTime>
				<counts unit="counts">0 0 0 0 0 0 0 1 2 1 0 0 1 1 0 0 0 0 0 0 0 0 0 0 1 0 0 0 1 0 0 0 0 1 0 0 0 0 1 0 1 0 1 0 1 0 0 0 1 0 0 0 0 0 1 0 0 0 0 0 0 1 0 0 1 1 0 0 0 0 0 0 0 0 0 0 0 0 1 0 0 0 0 0 0 0 1 0 1 0 0 1 0 0 0 0 0 1 0 0 0 0 0 1 0 0 0 1 1 0 1 0 1 0 0 0 0 2 1 0 0 0 0 0 0 1 1 1 1 1 1 1 0 0 0 0 0 1 0 0 0 0 0 0 0 0 0 0 0 0 1 0 1 0 0 0 0 0 1 0 0 1 0 0 0 0 0 0 0 0 1 0 0 0 1 0 0 1 1 0 1 0 0 0 0 0 0 1 0 0 1 0 0 0 2 0 0 4 0 0 1 0 0 1 0 0 0 0 0 0 0 1 0 0 2 2 1 0 0 0 0 0 3 1 0 0 0 0 0 0 2 0 0 1 0 1 0 0 0 0 1 1 0 0 0 0 0 1 0 1 1 1 0 1 1</counts>
			</dataPoints>
		</scan>
		<scan status="Completed" appendNumber="0" scanAxis="2Theta" mode="Continuous">
			<header>
				<startTimeStamp>2024-05-31T14:21:45-04:00</startTimeStamp>
				<endTimeStamp>2024-05-31T14:51:48-04:00</endTimeStamp>
				<author>
					<name>lw627</name>
				</author>
				<source>
					<applicationSoftware version="7.1">Data Collector</applicationSoftware>
					<instrumentControlSoftware version="8.2  20201204">EMPYREAN</instrumentControlSoftware>
					<instrumentID>0000000011260721</instrumentID>
				</source>
			</header>
			<dataPoints>
				<positions axis="2Theta" unit="deg">
					<startPosition>72.0646889650599</startPosition>
					<endPosition>75.4119587362764</endPosition>
				</positions>
				<positions axis="Omega" unit="deg">
					<commonPosition>18.3361619253341</commonPosition>
				</positions>
				<positions axis="Phi" unit="deg">
					<commonPosition>-92.36</commonPosition>
				</positions>
				<positions axis="Chi" unit="deg">
					<commonPosition>0</commonPosition>
				</positions>
				<positions axis="Z" unit="mm">
					<commonPosition>8.35</commonPosition>
				</positions>
				<commonCountingTime unit="seconds">0.974</commonCountingTime>
				<counts unit="counts">1 0 0 0 0 0 0 0 0 1 0 0 0 0 2 1 0 0 1 0 0 0 0 0 0 0 0 1 0 0 0 0 0 0 0 0 1 2 0 1 1 0 1 0 0 0 1 0 0 0 0 0 1 0 0 0 0 0 0 0 0 0 0 0 0 0 0 2 0 2 1 1 0 0 0 0 0 0 1 0 0 0 0 0 0 0 2 0 0 0 0 0 0 0 1 0 0 0 0 0 0 0 0 0 0 0 0 2 1 1 0 0 1 0 0 0 1 0 1 0 1 0 1 0 1 0 3 1 1 0 0 0 0 0 0 0 0 0 0 0 0 0 2 2 0 0 0 0 0 1 0 0 1 0 0 2 0 1 0 1 0 0 0 0 0 0 1 0 1 1 0 0 0 1 0 2 1 0 0 0 0 0 0 1 0 0 0 1 2 0 0 0 0 0 0 0 0 0 0 0 0 0 2 1 1 0 0 0 0 0 1 1 0 0 1 0 0 0 0 1 0 2 0 0 0 0 1 0 0 1 0 0 0 1 0 0 0 0 0 0 0 1 0 0 0 1 0 0 2 1 2 0 0 1 1</counts>
			</dataPoints>
		</scan>
		<scan status="Completed" appendNumber="0" scanAxis="2Theta" mode="Continuous">
			<header>
				<startTimeStamp>2024-05-31T14:21:45-04:00</startTimeStamp>
				<endTimeStamp>2024-05-31T14:51:48-04:00</endTimeStamp>
				<author>
					<name>lw627</name>
				</author>
				<source>
					<applicationSoftware version="7.1">Data Collector</applicationSoftware>
					<instrumentControlSoftware version="8.2  20201204">EMPYREAN</instrumentControlSoftware>
					<instrumentID>0000000011260721</instrumentID>
				</source>
			</header>
			<dataPoints>
				<positions axis="2Theta" unit="deg">
					<startPosition>72.067971535728</startPosition>
					<endPosition>75.4152413069445</endPosition>
				</positions>
				<positions axis="Omega" unit="deg">
					<commonPosition>18.3378032106681</commonPosition>
				</positions>
				<positions axis="Phi" unit="deg">
					<commonPosition>-92.36</commonPosition>
				</positions>
				<positions axis="Chi" unit="deg">
					<commonPosition>0</commonPosition>
				</positions>
				<positions axis="Z" unit="mm">
					<commonPosition>8.35</commonPosition>
				</positions>
				<commonCountingTime unit="seconds">0.974</commonCountingTime>
				<counts unit="counts">0 0 0 1 0 0 2 0 0 0 1 1 0 1 0 0 1 0 1 2 1 1 0 0 0 0 0 0 0 0 1 0 1 0 0 0 0 0 0 0 1 0 0 0 2 1 1 1 0 0 1 1 0 0 0 0 0 0 0 1 0 0 0 1 0 0 0 0 0 0 0 1 0 0 0 0 2 0 0 0 0 0 0 1 0 0 1 0 1 0 0 0 0 0 0 1 0 1 0 0 0 0 0 1 0 1 0 0 0 0 0 0 0 0 1 0 0 0 0 0 1 0 1 0 0 0 0 0 1 0 0 0 1 0 0 1 0 0 1 0 0 1 1 0 0 1 2 1 0 0 0 1 0 0 0 0 0 0 2 0 1 0 0 1 0 0 0 0 0 0 0 0 0 0 1 2 0 1 1 0 0 1 0 0 2 2 2 0 0 1 0 0 0 0 1 0 1 0 0 1 0 1 0 1 0 0 0 0 0 0 0 1 0 0 0 0 2 1 0 0 1 0 0 0 0 1 0 1 0 0 0 0 0 0 0 0 0 0 1 0 1 1 0 0 0 0 0 0 0 0 0 1 1 1 1</counts>
			</dataPoints>
		</scan>
		<scan status="Completed" appendNumber="0" scanAxis="2Theta" mode="Continuous">
			<header>
				<startTimeStamp>2024-05-31T14:21:45-04:00</startTimeStamp>
				<endTimeStamp>2024-05-31T14:51:48-04:00</endTimeStamp>
				<author>
					<name>lw627</name>
				</author>
				<source>
					<applicationSoftware version="7.1">Data Collector</applicationSoftware>
					<instrumentControlSoftware version="8.2  20201204">EMPYREAN</instrumentControlSoftware>
					<instrumentID>0000000011260721</instrumentID>
				</source>
			</header>
			<dataPoints>
				<positions axis="2Theta" unit="deg">
					<startPosition>72.0712541063961</startPosition>
					<endPosition>75.4185238776126</endPosition>
				</positions>
				<positions axis="Omega" unit="deg">
					<commonPosition>18.3394444960022</commonPosition>
				</positions>
				<positions axis="Phi" unit="deg">
					<commonPosition>-92.36</commonPosition>
				</positions>
				<positions axis="Chi" unit="deg">
					<commonPosition>0</commonPosition>
				</positions>
				<positions axis="Z" unit="mm">
					<commonPosition>8.35</commonPosition>
				</positions>
				<commonCountingTime unit="seconds">0.974</commonCountingTime>
				<counts unit="counts">0 0 0 0 0 0 0 0 0 4 0 0 0 0 0 1 1 0 1 0 1 1 0 0 0 0 0 0 0 1 1 0 0 0 0 0 0 0 0 0 1 0 1 2 1 1 0 1 1 0 1 0 1 0 0 0 0 0 0 0 0 0 0 2 0 0 0 0 0 0 0 0 0 0 1 0 0 1 0 1 0 0 0 0 0 0 0 0 0 0 1 0 1 0 0 0 0 0 0 0 0 0 0 0 1 1 0 0 0 0 1 0 0 0 0 0 2 0 0 0 0 0 0 0 1 0 0 0 0 0 0 0 1 0 2 1 0 0 0 0 0 0 0 1 1 0 0 1 0 0 0 0 0 1 0 2 0 0 1 0 0 0 0 1 1 0 0 0 0 0 0 0 1 0 0 0 1 0 0 0 1 0 0 0 0 0 1 0 0 0 0 0 1 0 0 0 0 0 0 1 0 0 0 0 0 0 0 0 0 0 0 0 0 0 0 1 0 1 1 1 0 0 0 1 0 1 1 0 0 0 0 0 0 0 0 1 0 0 0 1 0 0 0 0 0 0 0 0 0 1 0 1 0 0 0</counts>
			</dataPoints>
		</scan>
		<scan status="Completed" appendNumber="0" scanAxis="2Theta" mode="Continuous">
			<header>
				<startTimeStamp>2024-05-31T14:21:45-04:00</startTimeStamp>
				<endTimeStamp>2024-05-31T14:51:48-04:00</endTimeStamp>
				<author>
					<name>lw627</name>
				</author>
				<source>
					<applicationSoftware version="7.1">Data Collector</applicationSoftware>
					<instrumentControlSoftware version="8.2  20201204">EMPYREAN</instrumentControlSoftware>
					<instrumentID>0000000011260721</instrumentID>
				</source>
			</header>
			<dataPoints>
				<positions axis="2Theta" unit="deg">
					<startPosition>72.0745366770643</startPosition>
					<endPosition>75.4218064482807</endPosition>
				</positions>
				<positions axis="Omega" unit="deg">
					<commonPosition>18.3410857813363</commonPosition>
				</positions>
				<positions axis="Phi" unit="deg">
					<commonPosition>-92.36</commonPosition>
				</positions>
				<positions axis="Chi" unit="deg">
					<commonPosition>0</commonPosition>
				</positions>
				<positions axis="Z" unit="mm">
					<commonPosition>8.35</commonPosition>
				</positions>
				<commonCountingTime unit="seconds">0.974</commonCountingTime>
				<counts unit="counts">0 0 0 0 0 0 0 1 1 0 1 2 1 0 3 2 0 1 0 0 0 1 0 1 0 0 0 0 1 0 0 1 0 0 0 0 0 0 1 0 0 0 0 0 2 0 1 0 0 0 0 1 0 0 0 0 0 0 1 1 0 2 0 0 0 0 0 1 0 0 0 0 0 0 1 0 0 1 1 0 0 0 0 0 1 0 0 1 0 1 0 0 1 1 0 0 1 1 0 0 0 0 1 0 0 0 0 0 1 1 1 0 1 1 0 2 0 0 0 2 1 1 0 1 0 0 0 0 0 0 0 0 0 1 0 0 0 1 0 0 1 0 2 0 0 0 0 1 0 0 1 0 0 1 0 0 1 0 0 1 0 0 0 0 0 0 0 0 0 2 0 0 1 0 1 0 0 0 0 0 1 0 0 2 0 1 1 1 0 0 0 0 1 0 0 0 0 0 0 1 1 1 0 0 0 1 1 0 0 0 0 0 1 0 1 1 0 0 0 0 0 0 0 0 0 0 0 1 1 1 0 0 0 0 0 0 0 0 0 2 0 1 0 0 0 0 0 0 0 0 1 0 0 0 0</counts>
			</dataPoints>
		</scan>
		<scan status="Completed" appendNumber="0" scanAxis="2Theta" mode="Continuous">
			<header>
				<startTimeStamp>2024-05-31T14:21:45-04:00</startTimeStamp>
				<endTimeStamp>2024-05-31T14:51:48-04:00</endTimeStamp>
				<author>
					<name>lw627</name>
				</author>
				<source>
					<applicationSoftware version="7.1">Data Collector</applicationSoftware>
					<instrumentControlSoftware version="8.2  20201204">EMPYREAN</instrumentControlSoftware>
					<instrumentID>0000000011260721</instrumentID>
				</source>
			</header>
			<dataPoints>
				<positions axis="2Theta" unit="deg">
					<startPosition>72.0778192477324</startPosition>
					<endPosition>75.4250890189489</endPosition>
				</positions>
				<positions axis="Omega" unit="deg">
					<commonPosition>18.3427270666703</commonPosition>
				</positions>
				<positions axis="Phi" unit="deg">
					<commonPosition>-92.36</commonPosition>
				</positions>
				<positions axis="Chi" unit="deg">
					<commonPosition>0</commonPosition>
				</positions>
				<positions axis="Z" unit="mm">
					<commonPosition>8.35</commonPosition>
				</positions>
				<commonCountingTime unit="seconds">0.974</commonCountingTime>
				<counts unit="counts">1 0 1 0 0 0 0 0 1 0 0 1 0 0 0 0 0 0 0 1 0 1 2 1 0 0 1 0 0 0 0 0 0 0 0 0 0 0 0 0 0 1 0 0 0 1 0 1 0 0 0 0 0 1 0 0 1 0 1 2 0 0 0 0 0 0 1 1 0 0 0 1 0 0 0 0 1 0 1 0 0 0 0 0 1 0 0 0 1 0 1 2 0 0 0 0 0 1 0 0 0 0 0 0 0 1 1 0 0 1 0 0 2 0 0 0 0 0 0 0 0 1 0 1 0 0 1 0 0 0 0 0 1 0 0 0 0 0 0 0 0 2 0 0 0 1 0 0 0 0 0 2 0 0 0 0 0 0 0 1 1 0 0 1 0 0 1 2 1 0 1 0 0 0 1 0 0 0 1 0 0 0 0 1 1 0 0 0 0 0 1 0 0 1 1 1 0 0 0 0 0 0 0 1 1 1 0 1 0 0 0 0 1 0 0 1 0 0 0 0 0 0 0 0 1 0 1 0 1 1 1 0 0 1 0 0 0 1 0 0 0 0 0 0 0 0 1 0 0 0 0 0 0 0 0</counts>
			</dataPoints>
		</scan>
		<scan status="Completed" appendNumber="0" scanAxis="2Theta" mode="Continuous">
			<header>
				<startTimeStamp>2024-05-31T14:21:45-04:00</startTimeStamp>
				<endTimeStamp>2024-05-31T14:51:48-04:00</endTimeStamp>
				<author>
					<name>lw627</name>
				</author>
				<source>
					<applicationSoftware version="7.1">Data Collector</applicationSoftware>
					<instrumentControlSoftware version="8.2  20201204">EMPYREAN</instrumentControlSoftware>
					<instrumentID>0000000011260721</instrumentID>
				</source>
			</header>
			<dataPoints>
				<positions axis="2Theta" unit="deg">
					<startPosition>72.0811018184005</startPosition>
					<endPosition>75.428371589617</endPosition>
				</positions>
				<positions axis="Omega" unit="deg">
					<commonPosition>18.3443683520044</commonPosition>
				</positions>
				<positions axis="Phi" unit="deg">
					<commonPosition>-92.36</commonPosition>
				</positions>
				<positions axis="Chi" unit="deg">
					<commonPosition>0</commonPosition>
				</positions>
				<positions axis="Z" unit="mm">
					<commonPosition>8.35</commonPosition>
				</positions>
				<commonCountingTime unit="seconds">0.974</commonCountingTime>
				<counts unit="counts">1 1 1 0 0 1 0 0 0 1 0 0 1 0 0 0 0 0 0 0 1 0 0 0 0 0 0 0 0 0 0 0 1 1 0 0 0 0 0 0 0 0 1 0 0 0 0 0 2 0 0 0 1 0 0 0 0 0 1 0 0 0 0 0 0 2 0 0 0 0 0 0 0 0 1 1 2 0 0 1 0 2 0 1 0 0 0 1 1 1 0 1 0 0 0 0 0 0 0 0 0 0 1 1 0 1 0 0 0 0 1 0 1 0 0 0 0 0 0 0 0 0 0 0 1 1 0 0 1 0 0 1 0 2 1 0 0 0 0 0 1 0 0 1 1 2 0 0 0 0 1 0 1 1 0 0 0 0 0 0 0 1 1 0 0 1 2 1 1 0 0 0 1 0 0 0 0 0 0 1 0 0 0 0 1 1 0 0 0 0 1 1 0 0 0 2 0 1 0 0 0 1 0 0 0 0 0 0 0 2 0 0 0 2 1 0 1 0 0 0 0 1 0 0 1 0 0 0 0 0 2 0 0 1 2 0 0 0 0 0 1 1 0 1 0 1 0 0 0 1 1 0 0 0 0</counts>
			</dataPoints>
		</scan>
		<scan status="Completed" appendNumber="0" scanAxis="2Theta" mode="Continuous">
			<header>
				<startTimeStamp>2024-05-31T14:21:45-04:00</startTimeStamp>
				<endTimeStamp>2024-05-31T14:51:48-04:00</endTimeStamp>
				<author>
					<name>lw627</name>
				</author>
				<source>
					<applicationSoftware version="7.1">Data Collector</applicationSoftware>
					<instrumentControlSoftware version="8.2  20201204">EMPYREAN</instrumentControlSoftware>
					<instrumentID>0000000011260721</instrumentID>
				</source>
			</header>
			<dataPoints>
				<positions axis="2Theta" unit="deg">
					<startPosition>72.0843843890687</startPosition>
					<endPosition>75.4316541602851</endPosition>
				</positions>
				<positions axis="Omega" unit="deg">
					<commonPosition>18.3460096373384</commonPosition>
				</positions>
				<positions axis="Phi" unit="deg">
					<commonPosition>-92.36</commonPosition>
				</positions>
				<positions axis="Chi" unit="deg">
					<commonPosition>0</commonPosition>
				</positions>
				<positions axis="Z" unit="mm">
					<commonPosition>8.35</commonPosition>
				</positions>
				<commonCountingTime unit="seconds">0.974</commonCountingTime>
				<counts unit="counts">0 0 0 0 0 1 0 0 0 0 0 0 0 1 0 0 0 0 1 0 0 0 0 0 0 0 0 0 0 0 0 0 0 0 0 0 1 1 1 0 2 0 0 0 0 0 0 0 0 0 0 2 0 0 1 0 1 0 0 0 1 0 0 0 0 0 0 0 0 0 0 0 0 1 0 0 0 0 0 0 1 1 0 0 0 0 1 1 2 0 0 0 1 1 0 0 2 1 1 0 0 0 0 0 1 0 0 0 0 1 1 1 0 0 0 1 0 0 0 0 0 1 0 0 0 1 1 0 1 1 0 0 1 1 0 0 0 0 1 0 1 0 0 1 0 0 0 1 0 1 0 0 0 1 0 0 0 0 1 0 0 0 3 0 0 0 1 3 1 1 0 0 0 0 0 1 1 0 0 1 0 0 0 0 0 0 0 0 1 0 0 0 0 0 0 0 0 1 0 0 0 1 0 0 0 0 0 0 1 0 0 0 0 0 0 2 0 1 1 0 1 2 1 0 0 0 1 1 0 1 0 2 1 0 0 1 0 0 1 1 0 0 2 1 0 0 0 0 0 0 0 0 0 0 0</counts>
			</dataPoints>
		</scan>
		<scan status="Completed" appendNumber="0" scanAxis="2Theta" mode="Continuous">
			<header>
				<startTimeStamp>2024-05-31T14:21:45-04:00</startTimeStamp>
				<endTimeStamp>2024-05-31T14:51:48-04:00</endTimeStamp>
				<author>
					<name>lw627</name>
				</author>
				<source>
					<applicationSoftware version="7.1">Data Collector</applicationSoftware>
					<instrumentControlSoftware version="8.2  20201204">EMPYREAN</instrumentControlSoftware>
					<instrumentID>0000000011260721</instrumentID>
				</source>
			</header>
			<dataPoints>
				<positions axis="2Theta" unit="deg">
					<startPosition>72.0876669597368</startPosition>
					<endPosition>75.4349367309533</endPosition>
				</positions>
				<positions axis="Omega" unit="deg">
					<commonPosition>18.3476509226725</commonPosition>
				</positions>
				<positions axis="Phi" unit="deg">
					<commonPosition>-92.36</commonPosition>
				</positions>
				<positions axis="Chi" unit="deg">
					<commonPosition>0</commonPosition>
				</positions>
				<positions axis="Z" unit="mm">
					<commonPosition>8.35</commonPosition>
				</positions>
				<commonCountingTime unit="seconds">0.974</commonCountingTime>
				<counts unit="counts">0 1 0 1 0 1 0 0 0 1 0 0 0 0 0 1 0 0 0 0 0 0 0 0 1 0 0 1 0 0 0 1 0 0 0 1 0 0 0 0 0 0 0 1 0 2 0 0 0 0 0 0 0 1 0 1 0 0 0 2 2 0 0 0 1 0 0 0 0 0 0 0 1 0 1 1 0 0 0 0 0 0 1 0 0 0 1 0 0 1 0 1 0 2 1 0 0 1 0 0 0 0 0 0 0 1 0 0 0 1 0 0 0 1 1 3 2 0 0 0 0 0 1 0 0 0 0 0 1 0 1 0 0 0 2 0 1 0 0 0 1 0 0 1 0 0 1 0 1 0 0 1 1 1 0 1 1 0 1 2 0 0 0 0 1 0 0 0 0 1 0 1 0 0 0 1 0 0 0 0 0 0 1 0 0 1 0 0 0 0 0 0 0 0 0 2 3 0 0 0 0 0 0 2 1 1 2 1 0 1 0 0 0 1 0 0 0 0 1 0 0 0 1 1 0 0 1 0 0 0 0 0 0 1 0 0 0 0 0 0 0 0 0 1 1 1 0 0 0 0 0 0 0 0 0</counts>
			</dataPoints>
		</scan>
		<scan status="Completed" appendNumber="0" scanAxis="2Theta" mode="Continuous">
			<header>
				<startTimeStamp>2024-05-31T14:21:45-04:00</startTimeStamp>
				<endTimeStamp>2024-05-31T14:51:48-04:00</endTimeStamp>
				<author>
					<name>lw627</name>
				</author>
				<source>
					<applicationSoftware version="7.1">Data Collector</applicationSoftware>
					<instrumentControlSoftware version="8.2  20201204">EMPYREAN</instrumentControlSoftware>
					<instrumentID>0000000011260721</instrumentID>
				</source>
			</header>
			<dataPoints>
				<positions axis="2Theta" unit="deg">
					<startPosition>72.0909495304049</startPosition>
					<endPosition>75.4382193016214</endPosition>
				</positions>
				<positions axis="Omega" unit="deg">
					<commonPosition>18.3492922080066</commonPosition>
				</positions>
				<positions axis="Phi" unit="deg">
					<commonPosition>-92.36</commonPosition>
				</positions>
				<positions axis="Chi" unit="deg">
					<commonPosition>0</commonPosition>
				</positions>
				<positions axis="Z" unit="mm">
					<commonPosition>8.35</commonPosition>
				</positions>
				<commonCountingTime unit="seconds">0.974</commonCountingTime>
				<counts unit="counts">0 2 0 0 0 0 1 0 0 0 0 0 0 0 0 0 0 0 0 0 0 0 0 0 0 0 0 1 0 0 0 0 0 0 0 1 1 1 0 0 0 1 1 0 0 0 1 0 0 1 0 0 0 0 0 0 1 0 0 0 0 1 0 0 0 0 1 1 1 0 1 1 0 0 1 0 0 0 0 0 0 0 1 1 0 0 0 0 0 0 0 1 1 2 0 0 0 1 0 1 0 0 0 0 2 1 1 0 0 0 0 0 0 0 0 0 0 0 1 0 0 0 0 0 1 1 0 0 0 0 0 1 0 0 0 0 0 0 0 0 0 0 0 0 0 0 0 0 0 0 1 1 0 0 0 0 2 0 1 0 0 1 0 0 0 0 0 0 0 0 0 0 0 1 0 0 0 0 0 2 0 0 1 0 0 0 0 0 1 0 0 1 0 0 1 1 1 0 0 0 0 0 0 1 0 0 0 0 0 0 1 0 0 0 0 0 0 1 0 0 0 0 1 2 0 1 0 0 0 1 0 1 2 1 0 0 0 0 0 0 1 1 1 0 0 0 0 0 0 1 0 0 0 1 1</counts>
			</dataPoints>
		</scan>
		<scan status="Completed" appendNumber="0" scanAxis="2Theta" mode="Continuous">
			<header>
				<startTimeStamp>2024-05-31T14:21:45-04:00</startTimeStamp>
				<endTimeStamp>2024-05-31T14:51:48-04:00</endTimeStamp>
				<author>
					<name>lw627</name>
				</author>
				<source>
					<applicationSoftware version="7.1">Data Collector</applicationSoftware>
					<instrumentControlSoftware version="8.2  20201204">EMPYREAN</instrumentControlSoftware>
					<instrumentID>0000000011260721</instrumentID>
				</source>
			</header>
			<dataPoints>
				<positions axis="2Theta" unit="deg">
					<startPosition>72.094232101073</startPosition>
					<endPosition>75.4415018722895</endPosition>
				</positions>
				<positions axis="Omega" unit="deg">
					<commonPosition>18.3509334933406</commonPosition>
				</positions>
				<positions axis="Phi" unit="deg">
					<commonPosition>-92.36</commonPosition>
				</positions>
				<positions axis="Chi" unit="deg">
					<commonPosition>0</commonPosition>
				</positions>
				<positions axis="Z" unit="mm">
					<commonPosition>8.35</commonPosition>
				</positions>
				<commonCountingTime unit="seconds">0.974</commonCountingTime>
				<counts unit="counts">0 0 0 0 0 0 0 0 0 0 0 0 0 0 0 0 0 0 0 1 0 0 0 0 0 0 0 0 0 0 0 0 0 0 0 0 1 0 0 0 0 1 0 0 0 1 0 0 0 0 0 0 1 1 1 0 0 0 0 0 0 0 0 0 1 0 0 0 0 0 0 1 0 0 0 0 0 1 1 0 0 0 0 1 1 1 0 0 0 0 0 1 1 0 1 0 0 1 0 0 0 0 0 0 0 0 0 1 0 0 0 0 0 0 0 0 0 0 0 0 1 0 0 0 0 0 0 0 0 1 1 0 0 0 0 0 2 0 0 0 0 2 1 0 0 0 0 0 0 1 0 0 0 0 0 0 0 0 0 0 0 0 0 0 0 0 0 1 0 1 1 0 1 0 0 1 0 0 0 1 0 0 1 0 0 0 0 1 0 0 1 0 0 0 0 0 0 0 0 0 0 0 1 0 1 0 1 0 1 1 1 0 0 1 1 0 1 1 0 0 0 1 0 0 0 1 2 2 0 0 0 0 0 1 1 0 0 1 0 0 0 0 0 1 0 2 0 0 0 0 0 0 0 1 1</counts>
			</dataPoints>
		</scan>
		<scan status="Completed" appendNumber="0" scanAxis="2Theta" mode="Continuous">
			<header>
				<startTimeStamp>2024-05-31T14:21:45-04:00</startTimeStamp>
				<endTimeStamp>2024-05-31T14:51:48-04:00</endTimeStamp>
				<author>
					<name>lw627</name>
				</author>
				<source>
					<applicationSoftware version="7.1">Data Collector</applicationSoftware>
					<instrumentControlSoftware version="8.2  20201204">EMPYREAN</instrumentControlSoftware>
					<instrumentID>0000000011260721</instrumentID>
				</source>
			</header>
			<dataPoints>
				<positions axis="2Theta" unit="deg">
					<startPosition>72.0975146717412</startPosition>
					<endPosition>75.4447844429576</endPosition>
				</positions>
				<positions axis="Omega" unit="deg">
					<commonPosition>18.3525747786747</commonPosition>
				</positions>
				<positions axis="Phi" unit="deg">
					<commonPosition>-92.36</commonPosition>
				</positions>
				<positions axis="Chi" unit="deg">
					<commonPosition>0</commonPosition>
				</positions>
				<positions axis="Z" unit="mm">
					<commonPosition>8.35</commonPosition>
				</positions>
				<commonCountingTime unit="seconds">0.974</commonCountingTime>
				<counts unit="counts">0 0 0 1 0 1 0 1 0 0 1 1 0 0 0 0 1 0 0 0 1 0 0 0 1 0 2 0 1 1 0 0 0 1 0 0 1 0 0 0 0 0 0 0 0 0 0 0 0 1 0 0 0 0 0 0 0 2 0 0 0 0 0 0 0 0 0 0 1 0 0 0 1 0 1 0 0 0 1 0 0 0 0 0 0 1 1 0 1 0 1 1 0 2 0 2 0 0 0 0 0 0 0 0 0 0 0 1 0 0 0 1 1 0 1 0 0 0 0 1 0 0 1 0 0 0 0 0 0 0 1 0 0 0 1 2 0 2 1 0 0 0 0 0 0 0 1 1 0 0 0 0 0 0 0 0 0 0 0 1 0 1 0 0 1 0 0 0 0 0 1 0 0 0 1 0 0 0 0 0 0 0 0 0 0 0 0 0 0 0 0 1 0 0 1 2 0 2 1 2 0 0 1 0 0 2 2 0 0 0 1 0 0 1 1 0 1 0 0 0 1 1 0 1 0 0 0 1 0 0 0 0 0 0 1 0 0 0 2 0 0 1 0 0 0 0 0 0 0 0 0 0 0 0 1</counts>
			</dataPoints>
		</scan>
		<scan status="Completed" appendNumber="0" scanAxis="2Theta" mode="Continuous">
			<header>
				<startTimeStamp>2024-05-31T14:21:45-04:00</startTimeStamp>
				<endTimeStamp>2024-05-31T14:51:48-04:00</endTimeStamp>
				<author>
					<name>lw627</name>
				</author>
				<source>
					<applicationSoftware version="7.1">Data Collector</applicationSoftware>
					<instrumentControlSoftware version="8.2  20201204">EMPYREAN</instrumentControlSoftware>
					<instrumentID>0000000011260721</instrumentID>
				</source>
			</header>
			<dataPoints>
				<positions axis="2Theta" unit="deg">
					<startPosition>72.1007972424093</startPosition>
					<endPosition>75.4480670136258</endPosition>
				</positions>
				<positions axis="Omega" unit="deg">
					<commonPosition>18.3542160640088</commonPosition>
				</positions>
				<positions axis="Phi" unit="deg">
					<commonPosition>-92.36</commonPosition>
				</positions>
				<positions axis="Chi" unit="deg">
					<commonPosition>0</commonPosition>
				</positions>
				<positions axis="Z" unit="mm">
					<commonPosition>8.35</commonPosition>
				</positions>
				<commonCountingTime unit="seconds">0.974</commonCountingTime>
				<counts unit="counts">0 0 1 1 3 0 0 2 0 0 0 1 0 0 0 0 0 0 3 0 1 1 0 0 0 0 2 0 1 0 0 2 0 0 1 0 0 1 1 0 1 0 0 0 0 0 0 0 0 1 0 0 0 0 0 0 1 0 0 0 0 1 0 1 1 0 1 0 0 0 1 0 0 0 1 1 0 0 0 0 0 2 0 0 0 0 0 0 1 0 1 0 0 1 0 0 0 1 0 0 0 0 0 0 0 0 0 0 1 1 0 1 1 0 0 0 1 0 0 0 0 0 2 0 0 0 0 0 0 0 0 0 1 1 0 0 1 0 0 1 0 0 1 0 0 0 0 0 0 0 1 0 1 0 0 0 0 0 0 0 0 1 0 0 0 0 0 0 1 0 0 0 0 0 0 1 0 2 0 0 0 0 0 1 1 0 0 0 0 0 0 0 0 0 1 0 0 0 0 2 1 0 0 0 2 1 0 1 0 0 0 0 1 0 1 1 0 1 0 0 0 1 1 0 0 0 1 0 0 0 0 0 0 0 0 0 0 0 1 0 1 0 0 0 1 0 1 1 0 0 0 0 0 0 0</counts>
			</dataPoints>
		</scan>
		<scan status="Completed" appendNumber="0" scanAxis="2Theta" mode="Continuous">
			<header>
				<startTimeStamp>2024-05-31T14:21:45-04:00</startTimeStamp>
				<endTimeStamp>2024-05-31T14:51:48-04:00</endTimeStamp>
				<author>
					<name>lw627</name>
				</author>
				<source>
					<applicationSoftware version="7.1">Data Collector</applicationSoftware>
					<instrumentControlSoftware version="8.2  20201204">EMPYREAN</instrumentControlSoftware>
					<instrumentID>0000000011260721</instrumentID>
				</source>
			</header>
			<dataPoints>
				<positions axis="2Theta" unit="deg">
					<startPosition>72.1040798130774</startPosition>
					<endPosition>75.4513495842939</endPosition>
				</positions>
				<positions axis="Omega" unit="deg">
					<commonPosition>18.3558573493428</commonPosition>
				</positions>
				<positions axis="Phi" unit="deg">
					<commonPosition>-92.36</commonPosition>
				</positions>
				<positions axis="Chi" unit="deg">
					<commonPosition>0</commonPosition>
				</positions>
				<positions axis="Z" unit="mm">
					<commonPosition>8.35</commonPosition>
				</positions>
				<commonCountingTime unit="seconds">0.974</commonCountingTime>
				<counts unit="counts">1 1 2 0 1 0 1 0 1 1 0 0 0 1 0 0 1 2 0 0 0 0 1 0 0 2 0 0 1 1 0 1 0 1 1 0 0 1 1 2 0 0 0 0 1 1 0 2 0 0 0 0 0 0 1 1 0 0 0 0 0 1 1 0 1 1 0 0 1 0 0 1 0 1 1 0 0 0 1 0 0 0 0 0 1 0 0 0 0 0 0 0 0 1 0 0 0 0 0 0 0 0 0 0 0 0 0 0 0 0 1 0 0 0 0 0 1 2 0 0 0 0 0 1 1 0 0 0 0 0 0 0 1 0 0 0 0 0 0 0 1 0 0 0 1 0 0 2 1 0 1 0 0 0 0 0 1 0 0 0 0 0 0 1 0 0 0 1 0 0 0 0 0 1 0 0 0 1 0 0 0 0 1 3 0 0 1 1 1 0 0 2 1 1 2 2 0 1 0 1 0 0 0 0 0 0 1 1 0 0 1 0 0 0 0 1 0 2 0 0 0 0 0 0 0 0 0 0 0 1 1 0 0 0 0 0 0 2 0 0 0 0 0 0 0 1 1 0 0 0 0 0 0 0 1</counts>
			</dataPoints>
		</scan>
		<scan status="Completed" appendNumber="0" scanAxis="2Theta" mode="Continuous">
			<header>
				<startTimeStamp>2024-05-31T14:21:45-04:00</startTimeStamp>
				<endTimeStamp>2024-05-31T14:51:48-04:00</endTimeStamp>
				<author>
					<name>lw627</name>
				</author>
				<source>
					<applicationSoftware version="7.1">Data Collector</applicationSoftware>
					<instrumentControlSoftware version="8.2  20201204">EMPYREAN</instrumentControlSoftware>
					<instrumentID>0000000011260721</instrumentID>
				</source>
			</header>
			<dataPoints>
				<positions axis="2Theta" unit="deg">
					<startPosition>72.1073623837455</startPosition>
					<endPosition>75.454632154962</endPosition>
				</positions>
				<positions axis="Omega" unit="deg">
					<commonPosition>18.3574986346769</commonPosition>
				</positions>
				<positions axis="Phi" unit="deg">
					<commonPosition>-92.36</commonPosition>
				</positions>
				<positions axis="Chi" unit="deg">
					<commonPosition>0</commonPosition>
				</positions>
				<positions axis="Z" unit="mm">
					<commonPosition>8.35</commonPosition>
				</positions>
				<commonCountingTime unit="seconds">0.974</commonCountingTime>
				<counts unit="counts">0 0 0 0 2 1 1 0 0 0 0 0 0 0 1 0 0 0 0 0 2 1 0 0 0 0 0 2 1 0 0 0 1 1 0 0 0 1 0 0 1 0 0 1 0 1 0 1 1 0 0 0 0 0 0 0 0 0 0 0 0 0 1 0 0 0 1 0 1 0 0 1 0 0 0 0 3 0 0 0 0 0 0 0 1 0 1 1 1 1 0 0 0 1 0 0 0 0 0 1 1 0 0 0 0 0 1 0 1 0 1 0 0 0 0 0 2 1 0 1 0 0 0 0 0 0 0 0 0 1 0 0 0 0 0 0 0 0 0 1 0 1 0 1 0 0 0 0 0 1 0 1 1 0 0 0 1 0 0 0 0 0 0 0 0 0 0 0 0 1 0 0 0 1 0 0 0 1 0 0 0 0 1 1 0 0 1 2 0 1 0 0 0 0 0 0 1 0 1 1 0 1 0 1 0 0 1 0 0 1 1 0 0 0 0 0 1 0 0 0 1 0 0 0 0 0 0 0 2 2 0 0 0 1 2 1 0 0 0 0 1 1 1 1 0 0 0 0 0 0 0 0 0 0 1</counts>
			</dataPoints>
		</scan>
		<scan status="Completed" appendNumber="0" scanAxis="2Theta" mode="Continuous">
			<header>
				<startTimeStamp>2024-05-31T14:21:45-04:00</startTimeStamp>
				<endTimeStamp>2024-05-31T14:51:48-04:00</endTimeStamp>
				<author>
					<name>lw627</name>
				</author>
				<source>
					<applicationSoftware version="7.1">Data Collector</applicationSoftware>
					<instrumentControlSoftware version="8.2  20201204">EMPYREAN</instrumentControlSoftware>
					<instrumentID>0000000011260721</instrumentID>
				</source>
			</header>
			<dataPoints>
				<positions axis="2Theta" unit="deg">
					<startPosition>72.1106449544137</startPosition>
					<endPosition>75.4579147256301</endPosition>
				</positions>
				<positions axis="Omega" unit="deg">
					<commonPosition>18.359139920011</commonPosition>
				</positions>
				<positions axis="Phi" unit="deg">
					<commonPosition>-92.36</commonPosition>
				</positions>
				<positions axis="Chi" unit="deg">
					<commonPosition>0</commonPosition>
				</positions>
				<positions axis="Z" unit="mm">
					<commonPosition>8.35</commonPosition>
				</positions>
				<commonCountingTime unit="seconds">0.974</commonCountingTime>
				<counts unit="counts">0 0 0 0 0 1 0 0 0 0 0 0 0 0 2 1 1 0 0 0 2 0 0 0 1 0 1 0 0 0 1 0 1 0 0 0 1 0 1 0 0 0 1 0 0 0 1 1 1 1 0 0 0 1 0 0 1 0 0 1 0 1 0 1 1 0 0 0 0 0 0 0 0 0 0 0 0 0 0 0 1 0 1 0 0 0 0 0 1 0 0 0 0 0 0 0 0 0 0 0 0 0 0 0 0 0 1 0 0 1 0 1 0 0 1 0 0 0 0 1 0 0 0 0 0 0 0 0 0 1 0 1 0 0 0 0 2 0 0 0 0 0 0 0 1 0 0 1 0 0 0 0 0 0 0 0 0 0 0 0 1 0 0 0 0 1 0 0 0 1 0 0 2 0 0 0 0 0 1 0 1 0 0 0 0 0 0 0 2 0 1 0 0 1 1 0 1 0 0 0 0 0 0 0 0 2 1 1 0 0 0 0 0 0 1 1 0 0 0 1 0 0 0 0 0 1 1 0 0 0 1 0 0 0 0 0 1 0 2 1 1 0 1 1 1 0 0 0 0 0 0 1 0 0 1</counts>
			</dataPoints>
		</scan>
		<scan status="Completed" appendNumber="0" scanAxis="2Theta" mode="Continuous">
			<header>
				<startTimeStamp>2024-05-31T14:21:45-04:00</startTimeStamp>
				<endTimeStamp>2024-05-31T14:51:48-04:00</endTimeStamp>
				<author>
					<name>lw627</name>
				</author>
				<source>
					<applicationSoftware version="7.1">Data Collector</applicationSoftware>
					<instrumentControlSoftware version="8.2  20201204">EMPYREAN</instrumentControlSoftware>
					<instrumentID>0000000011260721</instrumentID>
				</source>
			</header>
			<dataPoints>
				<positions axis="2Theta" unit="deg">
					<startPosition>72.1139275250818</startPosition>
					<endPosition>75.4611972962983</endPosition>
				</positions>
				<positions axis="Omega" unit="deg">
					<commonPosition>18.360781205345</commonPosition>
				</positions>
				<positions axis="Phi" unit="deg">
					<commonPosition>-92.36</commonPosition>
				</positions>
				<positions axis="Chi" unit="deg">
					<commonPosition>0</commonPosition>
				</positions>
				<positions axis="Z" unit="mm">
					<commonPosition>8.35</commonPosition>
				</positions>
				<commonCountingTime unit="seconds">0.974</commonCountingTime>
				<counts unit="counts">0 0 0 0 0 2 0 0 0 0 0 1 0 0 0 0 0 1 0 0 0 0 0 0 0 1 0 1 0 0 0 0 0 0 0 1 0 1 1 0 0 0 0 0 0 0 1 0 1 0 0 0 0 0 1 1 0 0 0 0 0 0 0 0 0 0 0 1 0 1 1 0 0 1 1 0 0 0 0 0 0 0 0 0 0 0 1 0 1 1 0 0 0 0 0 1 1 0 0 0 2 0 1 0 0 0 0 0 0 0 0 0 0 1 1 0 1 0 0 1 0 0 0 0 0 0 0 0 0 1 1 0 0 0 0 0 0 0 0 0 0 0 0 0 0 0 0 0 0 0 0 0 1 0 0 1 0 0 0 0 0 0 0 0 0 0 0 0 1 1 1 0 0 0 0 1 0 0 0 0 0 0 0 0 0 0 0 0 1 0 0 0 0 1 0 0 0 0 0 0 0 0 0 0 0 1 0 0 0 1 0 0 1 0 0 0 0 0 0 0 0 0 0 0 0 0 0 0 1 1 1 1 0 1 0 1 0 0 0 2 0 0 1 0 0 0 0 0 2 1 0 0 0 0 1</counts>
			</dataPoints>
		</scan>
		<scan status="Completed" appendNumber="0" scanAxis="2Theta" mode="Continuous">
			<header>
				<startTimeStamp>2024-05-31T14:21:45-04:00</startTimeStamp>
				<endTimeStamp>2024-05-31T14:51:48-04:00</endTimeStamp>
				<author>
					<name>lw627</name>
				</author>
				<source>
					<applicationSoftware version="7.1">Data Collector</applicationSoftware>
					<instrumentControlSoftware version="8.2  20201204">EMPYREAN</instrumentControlSoftware>
					<instrumentID>0000000011260721</instrumentID>
				</source>
			</header>
			<dataPoints>
				<positions axis="2Theta" unit="deg">
					<startPosition>72.1172100957499</startPosition>
					<endPosition>75.4644798669664</endPosition>
				</positions>
				<positions axis="Omega" unit="deg">
					<commonPosition>18.3624224906791</commonPosition>
				</positions>
				<positions axis="Phi" unit="deg">
					<commonPosition>-92.36</commonPosition>
				</positions>
				<positions axis="Chi" unit="deg">
					<commonPosition>0</commonPosition>
				</positions>
				<positions axis="Z" unit="mm">
					<commonPosition>8.35</commonPosition>
				</positions>
				<commonCountingTime unit="seconds">0.974</commonCountingTime>
				<counts unit="counts">0 0 1 0 0 0 0 0 0 1 0 0 0 1 0 0 1 0 0 0 0 0 1 0 0 0 1 0 0 1 0 1 1 0 0 1 0 1 1 0 0 0 1 0 0 0 0 0 0 0 0 0 2 0 0 0 0 0 0 0 0 0 0 2 1 0 0 0 0 1 0 0 0 1 0 0 0 0 1 0 0 0 1 0 1 0 0 2 0 1 0 0 0 1 0 0 0 0 1 0 1 0 0 0 0 1 0 1 0 1 0 1 0 0 0 0 1 1 0 1 0 0 0 0 0 0 0 0 0 0 0 0 0 0 1 0 0 0 0 0 0 0 1 1 0 0 0 0 1 0 1 0 0 0 1 0 0 1 0 1 1 0 2 0 0 0 0 1 0 0 0 0 0 0 0 0 0 0 0 0 0 0 0 1 0 0 0 0 1 0 0 0 2 1 0 1 2 1 0 0 0 0 0 0 0 0 1 0 0 2 0 0 0 0 0 0 0 0 0 0 0 0 0 0 0 0 0 0 1 0 1 0 0 1 0 0 0 0 0 0 0 0 0 0 0 0 0 0 0 1 0 0 0 0 0</counts>
			</dataPoints>
		</scan>
		<scan status="Completed" appendNumber="0" scanAxis="2Theta" mode="Continuous">
			<header>
				<startTimeStamp>2024-05-31T14:21:45-04:00</startTimeStamp>
				<endTimeStamp>2024-05-31T14:51:48-04:00</endTimeStamp>
				<author>
					<name>lw627</name>
				</author>
				<source>
					<applicationSoftware version="7.1">Data Collector</applicationSoftware>
					<instrumentControlSoftware version="8.2  20201204">EMPYREAN</instrumentControlSoftware>
					<instrumentID>0000000011260721</instrumentID>
				</source>
			</header>
			<dataPoints>
				<positions axis="2Theta" unit="deg">
					<startPosition>72.120492666418</startPosition>
					<endPosition>75.4677624376345</endPosition>
				</positions>
				<positions axis="Omega" unit="deg">
					<commonPosition>18.3640637760131</commonPosition>
				</positions>
				<positions axis="Phi" unit="deg">
					<commonPosition>-92.36</commonPosition>
				</positions>
				<positions axis="Chi" unit="deg">
					<commonPosition>0</commonPosition>
				</positions>
				<positions axis="Z" unit="mm">
					<commonPosition>8.35</commonPosition>
				</positions>
				<commonCountingTime unit="seconds">0.974</commonCountingTime>
				<counts unit="counts">1 1 0 0 0 0 0 2 0 0 0 0 0 1 0 0 0 1 1 0 0 0 1 0 0 0 0 0 2 1 0 0 1 0 0 0 0 0 0 0 0 1 0 0 0 1 0 0 1 0 0 2 0 0 0 0 1 0 0 3 0 0 0 0 1 0 1 0 0 0 0 0 0 0 0 0 0 3 0 1 0 0 0 1 0 0 0 0 0 0 0 0 0 0 0 1 1 0 0 0 1 0 0 0 1 0 0 0 0 0 1 0 1 0 1 0 0 0 0 0 2 2 0 0 0 0 0 0 0 0 0 0 2 0 0 0 0 1 1 1 0 1 0 1 1 0 0 0 1 0 0 0 0 0 0 0 0 0 1 0 0 0 1 0 1 1 0 0 0 0 0 0 0 0 0 0 2 1 0 0 0 0 0 0 0 1 0 0 1 0 0 2 0 1 0 0 1 0 1 1 0 0 0 0 0 0 0 0 0 0 1 0 0 0 1 0 0 0 0 0 0 2 0 0 0 1 0 0 0 0 0 0 1 0 0 0 1 1 0 1 0 0 0 0 0 1 0 2 0 0 1 0 0 0 0</counts>
			</dataPoints>
		</scan>
		<scan status="Completed" appendNumber="0" scanAxis="2Theta" mode="Continuous">
			<header>
				<startTimeStamp>2024-05-31T14:21:45-04:00</startTimeStamp>
				<endTimeStamp>2024-05-31T14:51:48-04:00</endTimeStamp>
				<author>
					<name>lw627</name>
				</author>
				<source>
					<applicationSoftware version="7.1">Data Collector</applicationSoftware>
					<instrumentControlSoftware version="8.2  20201204">EMPYREAN</instrumentControlSoftware>
					<instrumentID>0000000011260721</instrumentID>
				</source>
			</header>
			<dataPoints>
				<positions axis="2Theta" unit="deg">
					<startPosition>72.1237752370862</startPosition>
					<endPosition>75.4710450083027</endPosition>
				</positions>
				<positions axis="Omega" unit="deg">
					<commonPosition>18.3657050613472</commonPosition>
				</positions>
				<positions axis="Phi" unit="deg">
					<commonPosition>-92.36</commonPosition>
				</positions>
				<positions axis="Chi" unit="deg">
					<commonPosition>0</commonPosition>
				</positions>
				<positions axis="Z" unit="mm">
					<commonPosition>8.35</commonPosition>
				</positions>
				<commonCountingTime unit="seconds">0.974</commonCountingTime>
				<counts unit="counts">0 0 1 0 2 0 2 1 0 0 0 0 0 0 1 0 0 0 0 0 1 2 0 0 0 0 0 0 0 0 0 0 0 0 0 0 1 0 0 0 0 0 1 0 0 0 0 1 0 0 0 0 1 1 0 0 0 0 1 0 0 0 1 1 0 0 1 0 0 0 1 0 0 0 0 0 0 0 0 1 0 0 0 0 0 1 0 0 0 1 0 0 1 0 0 1 2 0 0 0 0 0 0 0 1 0 1 0 0 0 2 0 0 0 0 0 1 0 0 1 0 0 0 0 0 0 0 0 0 0 0 0 0 0 0 0 0 0 0 0 1 0 0 0 0 1 0 0 0 0 0 0 0 0 2 0 0 0 0 0 0 1 1 2 0 0 1 0 0 0 0 0 2 0 1 0 0 0 1 1 0 0 0 0 0 0 0 0 0 1 1 0 0 0 0 0 1 1 0 0 0 0 0 0 0 0 0 0 0 1 1 0 0 0 1 0 1 1 2 0 0 0 0 0 0 2 1 0 0 1 0 1 0 1 0 0 0 0 0 0 0 0 1 0 0 0 0 1 0 0 0 0 0 0 2</counts>
			</dataPoints>
		</scan>
		<scan status="Completed" appendNumber="0" scanAxis="2Theta" mode="Continuous">
			<header>
				<startTimeStamp>2024-05-31T14:21:45-04:00</startTimeStamp>
				<endTimeStamp>2024-05-31T14:51:48-04:00</endTimeStamp>
				<author>
					<name>lw627</name>
				</author>
				<source>
					<applicationSoftware version="7.1">Data Collector</applicationSoftware>
					<instrumentControlSoftware version="8.2  20201204">EMPYREAN</instrumentControlSoftware>
					<instrumentID>0000000011260721</instrumentID>
				</source>
			</header>
			<dataPoints>
				<positions axis="2Theta" unit="deg">
					<startPosition>72.1270578077543</startPosition>
					<endPosition>75.4743275789708</endPosition>
				</positions>
				<positions axis="Omega" unit="deg">
					<commonPosition>18.3673463466813</commonPosition>
				</positions>
				<positions axis="Phi" unit="deg">
					<commonPosition>-92.36</commonPosition>
				</positions>
				<positions axis="Chi" unit="deg">
					<commonPosition>0</commonPosition>
				</positions>
				<positions axis="Z" unit="mm">
					<commonPosition>8.35</commonPosition>
				</positions>
				<commonCountingTime unit="seconds">0.974</commonCountingTime>
[...]
					<commonPosition>0</commonPosition>
				</positions>
				<positions axis="Z" unit="mm">
					<commonPosition>8.35</commonPosition>
				</positions>
				<commonCountingTime unit="seconds">0.974</commonCountingTime>
				<counts unit="counts">0 1 0 1 0 0 0 0 0 0 0 0 1 0 0 1 0 1 0 0 0 1 1 0 1 0 1 0 1 0 0 1 0 0 0 0 0 0 0 1 0 0 0 0 0 2 0 1 0 0 0 0 0 0 0 0 0 0 0 0 1 0 0 0 0 1 0 0 0 0 0 0 0 0 0 0 0 0 0 0 0 0 1 1 2 0 0 0 0 0 1 0 1 1 0 0 1 1 0 0 2 0 0 0 1 0 0 0 0 0 1 0 0 0 1 0 0 1 0 0 0 2 0 0 0 0 0 1 1 0 1 0 1 1 0 0 0 0 0 0 0 0 0 1 0 0 0 0 0 0 0 0 1 0 0 0 0 0 0 1 0 0 0 0 1 0 0 0 1 0 0 0 0 0 0 0 0 0 0 1 1 0 0 0 0 0 0 0 0 1 0 1 1 1 0 0 0 0 0 0 0 0 0 0 1 1 0 0 0 0 0 0 2 1 0 0 0 0 0 0 0 0 0 0 0 0 0 1 1 0 0 0 0 0 1 0 0 0 0 0 1 0 0 0 1 0 0 1 0 0 0 0 0 0 1</counts>
			</dataPoints>
		</scan>
		<scan status="Completed" appendNumber="0" scanAxis="2Theta" mode="Continuous">
			<header>
				<startTimeStamp>2024-05-31T14:21:45-04:00</startTimeStamp>
				<endTimeStamp>2024-05-31T14:51:48-04:00</endTimeStamp>
				<author>
					<name>lw627</name>
				</author>
				<source>
					<applicationSoftware version="7.1">Data Collector</applicationSoftware>
					<instrumentControlSoftware version="8.2  20201204">EMPYREAN</instrumentControlSoftware>
					<instrumentID>0000000011260721</instrumentID>
				</source>
			</header>
			<dataPoints>
				<positions axis="2Theta" unit="deg">
					<startPosition>78.0225547277105</startPosition>
					<endPosition>81.369824498927</endPosition>
				</positions>
				<positions axis="Omega" unit="deg">
					<commonPosition>21.3150948066594</commonPosition>
				</positions>
				<positions axis="Phi" unit="deg">
					<commonPosition>-92.36</commonPosition>
				</positions>
				<positions axis="Chi" unit="deg">
					<commonPosition>0</commonPosition>
				</positions>
				<positions axis="Z" unit="mm">
					<commonPosition>8.35</commonPosition>
				</positions>
				<commonCountingTime unit="seconds">0.974</commonCountingTime>
				<counts unit="counts">1 0 2 1 0 0 0 0 0 0 0 0 0 0 0 0 0 1 0 2 0 0 1 0 0 0 0 0 1 1 0 0 0 1 0 0 0 0 0 0 0 0 0 0 0 0 0 0 0 0 0 0 0 2 0 0 0 0 0 0 0 0 0 1 0 0 0 1 0 0 1 1 0 2 0 0 0 2 0 0 0 0 1 0 1 0 0 0 0 1 1 0 0 0 0 0 0 1 0 0 0 0 0 1 0 0 0 1 0 0 0 0 0 0 0 0 1 0 1 0 1 0 0 1 1 0 0 1 1 0 0 0 0 0 1 1 0 0 0 0 0 0 0 2 0 0 0 0 0 0 1 0 1 2 0 0 2 0 0 0 0 0 0 0 0 1 0 0 0 0 1 0 0 0 0 0 1 0 0 0 0 0 0 1 0 0 0 0 0 0 0 0 0 0 0 0 1 0 0 1 1 0 1 0 0 0 0 0 0 0 0 0 0 0 0 0 0 0 0 0 0 0 0 0 0 0 1 0 0 0 1 0 0 0 1 0 0 0 0 0 0 0 1 0 2 0 0 0 0 0 1 0 0 0 2</counts>
			</dataPoints>
		</scan>
		<scan status="Completed" appendNumber="0" scanAxis="2Theta" mode="Continuous">
			<header>
				<startTimeStamp>2024-05-31T14:21:45-04:00</startTimeStamp>
				<endTimeStamp>2024-05-31T14:51:48-04:00</endTimeStamp>
				<author>
					<name>lw627</name>
				</author>
				<source>
					<applicationSoftware version="7.1">Data Collector</applicationSoftware>
					<instrumentControlSoftware version="8.2  20201204">EMPYREAN</instrumentControlSoftware>
					<instrumentID>0000000011260721</instrumentID>
				</source>
			</header>
			<dataPoints>
				<positions axis="2Theta" unit="deg">
					<startPosition>78.0258372983786</startPosition>
					<endPosition>81.3731070695951</endPosition>
				</positions>
				<positions axis="Omega" unit="deg">
					<commonPosition>21.3167360919934</commonPosition>
				</positions>
				<positions axis="Phi" unit="deg">
					<commonPosition>-92.36</commonPosition>
				</positions>
				<positions axis="Chi" unit="deg">
					<commonPosition>0</commonPosition>
				</positions>
				<positions axis="Z" unit="mm">
					<commonPosition>8.35</commonPosition>
				</positions>
				<commonCountingTime unit="seconds">0.974</commonCountingTime>
				<counts unit="counts">0 0 0 0 0 0 0 0 0 0 1 0 0 0 0 1 0 0 0 0 0 0 0 1 0 0 0 0 0 1 1 1 0 0 0 1 0 1 1 0 1 1 1 0 0 0 0 0 0 0 0 0 0 0 0 0 0 1 0 0 0 0 0 1 0 1 0 0 0 0 0 0 0 0 2 0 0 0 0 0 0 0 0 0 0 0 0 0 0 0 1 0 0 1 0 1 0 1 1 1 0 0 0 0 1 0 0 0 1 0 0 0 0 0 0 0 0 0 0 0 2 0 0 0 0 1 1 0 0 0 0 0 0 0 0 0 0 0 0 0 0 1 1 1 1 0 0 1 1 0 0 0 0 0 1 0 0 1 0 0 0 0 0 0 0 0 0 0 0 1 0 0 0 1 1 0 2 0 1 0 0 0 0 0 1 0 0 0 1 0 0 0 1 0 0 0 0 0 1 0 1 1 1 0 0 1 0 1 0 0 0 1 0 0 1 0 1 0 0 1 0 0 0 1 0 0 0 0 0 0 0 0 0 0 1 0 0 0 0 0 0 0 0 0 0 0 0 0 1 0 0 0 0 0 0</counts>
			</dataPoints>
		</scan>
		<scan status="Completed" appendNumber="0" scanAxis="2Theta" mode="Continuous">
			<header>
				<startTimeStamp>2024-05-31T14:21:45-04:00</startTimeStamp>
				<endTimeStamp>2024-05-31T14:51:48-04:00</endTimeStamp>
				<author>
					<name>lw627</name>
				</author>
				<source>
					<applicationSoftware version="7.1">Data Collector</applicationSoftware>
					<instrumentControlSoftware version="8.2  20201204">EMPYREAN</instrumentControlSoftware>
					<instrumentID>0000000011260721</instrumentID>
				</source>
			</header>
			<dataPoints>
				<positions axis="2Theta" unit="deg">
					<startPosition>78.0291198690468</startPosition>
					<endPosition>81.3763896402632</endPosition>
				</positions>
				<positions axis="Omega" unit="deg">
					<commonPosition>21.3183773773275</commonPosition>
				</positions>
				<positions axis="Phi" unit="deg">
					<commonPosition>-92.36</commonPosition>
				</positions>
				<positions axis="Chi" unit="deg">
					<commonPosition>0</commonPosition>
				</positions>
				<positions axis="Z" unit="mm">
					<commonPosition>8.35</commonPosition>
				</positions>
				<commonCountingTime unit="seconds">0.974</commonCountingTime>
				<counts unit="counts">0 0 0 1 0 0 0 0 0 0 0 0 1 0 1 0 0 0 0 0 0 0 0 1 2 0 0 0 0 0 0 0 0 1 1 1 0 0 0 0 0 0 0 0 0 0 0 0 0 0 0 0 0 0 1 0 1 0 0 1 0 0 0 0 0 0 0 0 1 0 0 0 1 0 0 0 1 0 2 2 1 0 0 0 0 0 0 1 0 1 0 0 0 1 1 0 1 0 0 0 1 0 0 0 0 1 1 0 1 1 0 0 1 0 0 0 1 0 0 0 0 1 1 0 0 0 1 0 0 0 0 1 0 0 0 0 0 0 0 0 1 1 0 0 0 0 0 0 0 0 0 2 0 0 0 0 1 0 0 0 0 0 0 0 1 0 1 1 0 1 0 0 0 0 0 0 0 1 0 0 0 0 0 0 2 0 0 0 0 0 1 0 1 0 1 1 0 0 0 0 0 0 0 0 0 0 0 0 1 0 0 1 0 0 0 1 0 0 0 0 1 0 0 0 0 0 0 1 1 1 0 0 0 1 0 0 0 1 0 0 2 0 0 0 0 1 1 0 0 1 0 0 0 0 0</counts>
			</dataPoints>
		</scan>
		<scan status="Completed" appendNumber="0" scanAxis="2Theta" mode="Continuous">
			<header>
				<startTimeStamp>2024-05-31T14:21:45-04:00</startTimeStamp>
				<endTimeStamp>2024-05-31T14:51:48-04:00</endTimeStamp>
				<author>
					<name>lw627</name>
				</author>
				<source>
					<applicationSoftware version="7.1">Data Collector</applicationSoftware>
					<instrumentControlSoftware version="8.2  20201204">EMPYREAN</instrumentControlSoftware>
					<instrumentID>0000000011260721</instrumentID>
				</source>
			</header>
			<dataPoints>
				<positions axis="2Theta" unit="deg">
					<startPosition>78.0324024397149</startPosition>
					<endPosition>81.3796722109313</endPosition>
				</positions>
				<positions axis="Omega" unit="deg">
					<commonPosition>21.3200186626616</commonPosition>
				</positions>
				<positions axis="Phi" unit="deg">
					<commonPosition>-92.36</commonPosition>
				</positions>
				<positions axis="Chi" unit="deg">
					<commonPosition>0</commonPosition>
				</positions>
				<positions axis="Z" unit="mm">
					<commonPosition>8.35</commonPosition>
				</positions>
				<commonCountingTime unit="seconds">0.974</commonCountingTime>
				<counts unit="counts">0 1 2 1 0 0 0 0 0 1 0 1 0 0 0 1 1 0 0 0 0 1 0 0 0 0 1 0 0 0 0 0 1 0 0 0 0 0 0 0 0 1 0 0 0 0 0 0 0 0 0 0 0 2 0 0 0 0 0 0 0 1 0 1 0 0 0 0 0 0 1 0 1 2 0 0 1 0 0 1 0 0 0 0 1 0 0 0 0 0 0 0 1 0 0 0 0 1 0 0 0 0 1 0 0 0 0 0 0 1 0 2 1 0 0 0 0 0 0 0 1 0 2 0 0 0 1 0 0 0 0 0 0 0 0 0 0 0 0 0 0 2 0 0 0 0 0 1 0 0 0 0 0 0 0 1 0 0 1 0 0 0 0 0 0 0 0 0 1 1 1 1 0 0 0 1 0 0 1 0 1 1 0 0 0 0 0 0 0 1 0 0 0 0 0 0 0 0 0 0 0 0 2 0 0 0 0 0 0 0 0 0 0 0 0 0 1 0 1 0 1 0 0 0 0 0 0 0 0 0 0 1 0 0 0 0 0 0 0 0 0 0 0 0 0 0 1 0 0 0 0 1 1 0 0</counts>
			</dataPoints>
		</scan>
		<scan status="Completed" appendNumber="0" scanAxis="2Theta" mode="Continuous">
			<header>
				<startTimeStamp>2024-05-31T14:21:45-04:00</startTimeStamp>
				<endTimeStamp>2024-05-31T14:51:48-04:00</endTimeStamp>
				<author>
					<name>lw627</name>
				</author>
				<source>
					<applicationSoftware version="7.1">Data Collector</applicationSoftware>
					<instrumentControlSoftware version="8.2  20201204">EMPYREAN</instrumentControlSoftware>
					<instrumentID>0000000011260721</instrumentID>
				</source>
			</header>
			<dataPoints>
				<positions axis="2Theta" unit="deg">
					<startPosition>78.035685010383</startPosition>
					<endPosition>81.3829547815995</endPosition>
				</positions>
				<positions axis="Omega" unit="deg">
					<commonPosition>21.3216599479956</commonPosition>
				</positions>
				<positions axis="Phi" unit="deg">
					<commonPosition>-92.36</commonPosition>
				</positions>
				<positions axis="Chi" unit="deg">
					<commonPosition>0</commonPosition>
				</positions>
				<positions axis="Z" unit="mm">
					<commonPosition>8.35</commonPosition>
				</positions>
				<commonCountingTime unit="seconds">0.974</commonCountingTime>
				<counts unit="counts">0 0 1 1 1 1 0 0 1 0 1 0 0 0 0 1 0 0 1 0 0 0 1 0 1 0 0 0 1 0 0 1 0 0 0 1 0 0 2 1 0 0 1 1 0 0 0 0 0 0 1 1 0 0 0 0 0 0 0 0 1 0 0 2 0 1 0 0 0 0 0 3 0 0 1 0 0 0 0 0 0 0 0 0 2 1 0 1 0 1 1 0 0 0 0 0 0 1 0 0 0 0 0 0 0 0 0 0 0 1 1 0 0 1 0 1 0 0 1 0 0 0 0 0 0 0 0 0 0 0 1 1 0 0 0 0 0 0 0 0 0 0 0 0 0 0 0 2 1 0 0 1 0 1 0 0 0 1 1 0 0 0 0 0 2 2 0 0 0 0 0 0 0 1 1 0 0 1 1 1 0 0 1 0 0 0 1 0 0 0 0 0 0 0 1 0 0 0 0 0 0 0 0 2 0 1 0 1 0 0 1 0 0 0 1 0 0 0 0 0 1 0 0 0 0 0 0 0 0 0 0 0 0 0 0 0 0 0 0 0 1 0 0 0 0 1 0 0 0 0 0 0 0 1 0</counts>
			</dataPoints>
		</scan>
		<scan status="Completed" appendNumber="0" scanAxis="2Theta" mode="Continuous">
			<header>
				<startTimeStamp>2024-05-31T14:21:45-04:00</startTimeStamp>
				<endTimeStamp>2024-05-31T14:51:48-04:00</endTimeStamp>
				<author>
					<name>lw627</name>
				</author>
				<source>
					<applicationSoftware version="7.1">Data Collector</applicationSoftware>
					<instrumentControlSoftware version="8.2  20201204">EMPYREAN</instrumentControlSoftware>
					<instrumentID>0000000011260721</instrumentID>
				</source>
			</header>
			<dataPoints>
				<positions axis="2Theta" unit="deg">
					<startPosition>78.0389675810511</startPosition>
					<endPosition>81.3862373522676</endPosition>
				</positions>
				<positions axis="Omega" unit="deg">
					<commonPosition>21.3233012333297</commonPosition>
				</positions>
				<positions axis="Phi" unit="deg">
					<commonPosition>-92.36</commonPosition>
				</positions>
				<positions axis="Chi" unit="deg">
					<commonPosition>0</commonPosition>
				</positions>
				<positions axis="Z" unit="mm">
					<commonPosition>8.35</commonPosition>
				</positions>
				<commonCountingTime unit="seconds">0.974</commonCountingTime>
				<counts unit="counts">0 0 0 0 0 0 0 1 1 1 0 0 0 0 0 0 1 0 0 0 1 0 0 0 1 0 0 0 0 0 0 0 0 0 0 0 2 0 1 1 0 0 1 0 1 1 0 0 1 0 0 0 0 1 0 0 0 1 0 0 0 0 0 0 2 1 0 0 2 0 1 1 0 0 0 0 0 0 0 0 0 0 0 0 0 1 0 2 0 0 0 0 0 0 0 1 0 0 0 0 0 0 2 0 1 0 0 0 0 1 0 0 0 0 0 0 0 0 0 0 1 0 0 0 1 1 0 0 0 0 0 0 0 0 2 0 0 0 0 0 0 0 0 0 1 0 0 0 0 0 0 0 1 0 0 1 0 0 0 0 1 1 0 0 0 0 0 0 0 0 1 0 0 0 1 0 0 0 0 0 0 0 0 0 0 0 0 0 0 0 0 0 0 0 0 0 1 1 2 0 1 1 0 0 0 0 0 0 0 0 0 2 0 0 0 0 0 0 2 0 0 0 0 0 1 0 0 1 0 0 0 1 0 0 0 0 0 0 0 1 0 0 0 0 0 0 1 1 0 0 1 0 2 1 0</counts>
			</dataPoints>
		</scan>
		<scan status="Completed" appendNumber="0" scanAxis="2Theta" mode="Continuous">
			<header>
				<startTimeStamp>2024-05-31T14:21:45-04:00</startTimeStamp>
				<endTimeStamp>2024-05-31T14:51:48-04:00</endTimeStamp>
				<author>
					<name>lw627</name>
				</author>
				<source>
					<applicationSoftware version="7.1">Data Collector</applicationSoftware>
					<instrumentControlSoftware version="8.2  20201204">EMPYREAN</instrumentControlSoftware>
					<instrumentID>0000000011260721</instrumentID>
				</source>
			</header>
			<dataPoints>
				<positions axis="2Theta" unit="deg">
					<startPosition>78.0422501517193</startPosition>
					<endPosition>81.3895199229357</endPosition>
				</positions>
				<positions axis="Omega" unit="deg">
					<commonPosition>21.3249425186637</commonPosition>
				</positions>
				<positions axis="Phi" unit="deg">
					<commonPosition>-92.36</commonPosition>
				</positions>
				<positions axis="Chi" unit="deg">
					<commonPosition>0</commonPosition>
				</positions>
				<positions axis="Z" unit="mm">
					<commonPosition>8.35</commonPosition>
				</positions>
				<commonCountingTime unit="seconds">0.974</commonCountingTime>
				<counts unit="counts">0 1 0 0 0 0 1 1 0 0 0 0 1 0 0 0 0 0 0 0 0 0 0 0 1 1 0 2 0 0 1 1 0 2 1 0 1 0 0 0 0 1 0 0 0 0 0 0 0 0 0 1 0 0 0 0 0 0 0 0 0 1 0 0 0 0 0 0 0 0 1 0 0 1 0 0 0 0 1 0 0 0 1 2 0 0 1 1 1 0 1 0 0 0 0 0 0 0 0 0 0 2 0 1 0 0 0 0 0 2 0 0 0 0 0 1 0 1 0 0 0 0 1 1 0 0 0 0 0 1 0 0 1 0 0 0 0 1 1 0 0 0 0 1 0 0 0 0 1 0 0 0 0 2 1 2 0 0 0 0 0 0 1 1 0 1 0 0 0 1 1 0 0 0 0 0 0 0 0 0 0 2 0 0 0 1 0 1 0 0 1 0 1 0 0 0 0 0 0 0 1 0 0 0 0 0 0 0 2 0 0 0 0 0 0 0 0 0 1 0 0 1 0 0 0 2 1 0 0 0 0 1 0 0 0 0 0 0 1 0 0 0 0 0 0 0 1 0 0 0 1 0 1 0 0</counts>
			</dataPoints>
		</scan>
		<scan status="Completed" appendNumber="0" scanAxis="2Theta" mode="Continuous">
			<header>
				<startTimeStamp>2024-05-31T14:21:45-04:00</startTimeStamp>
				<endTimeStamp>2024-05-31T14:51:48-04:00</endTimeStamp>
				<author>
					<name>lw627</name>
				</author>
				<source>
					<applicationSoftware version="7.1">Data Collector</applicationSoftware>
					<instrumentControlSoftware version="8.2  20201204">EMPYREAN</instrumentControlSoftware>
					<instrumentID>0000000011260721</instrumentID>
				</source>
			</header>
			<dataPoints>
				<positions axis="2Theta" unit="deg">
					<startPosition>78.0455327223874</startPosition>
					<endPosition>81.3928024936039</endPosition>
				</positions>
				<positions axis="Omega" unit="deg">
					<commonPosition>21.3265838039978</commonPosition>
				</positions>
				<positions axis="Phi" unit="deg">
					<commonPosition>-92.36</commonPosition>
				</positions>
				<positions axis="Chi" unit="deg">
					<commonPosition>0</commonPosition>
				</positions>
				<positions axis="Z" unit="mm">
					<commonPosition>8.35</commonPosition>
				</positions>
				<commonCountingTime unit="seconds">0.974</commonCountingTime>
				<counts unit="counts">0 0 0 0 0 0 1 1 0 0 0 0 0 0 0 0 0 0 0 1 0 0 0 0 0 0 0 0 0 0 0 0 0 2 0 0 1 0 0 0 0 2 1 2 0 0 1 0 1 1 0 0 1 0 0 1 0 0 1 0 0 0 1 0 0 0 0 2 0 1 0 0 1 2 0 0 0 0 0 0 0 1 2 0 0 0 0 1 0 0 0 0 0 0 0 0 0 0 1 0 0 1 2 0 1 1 0 0 0 0 1 0 0 0 0 0 0 0 0 0 1 0 0 0 0 0 1 1 0 0 0 0 1 1 0 0 0 0 0 0 1 0 0 0 0 0 1 0 0 0 0 0 0 0 0 0 0 0 0 0 0 0 1 1 0 0 0 0 0 1 0 0 0 1 0 0 0 1 0 1 0 1 0 0 0 0 0 0 0 0 1 0 0 1 1 0 1 0 0 1 1 0 0 0 0 0 0 0 1 1 1 1 1 1 0 0 0 0 0 0 0 1 0 2 0 0 0 0 0 1 0 0 0 1 0 0 0 0 0 1 1 1 0 0 1 0 0 0 1 0 0 1 0 1 0</counts>
			</dataPoints>
		</scan>
		<scan status="Completed" appendNumber="0" scanAxis="2Theta" mode="Continuous">
			<header>
				<startTimeStamp>2024-05-31T14:21:45-04:00</startTimeStamp>
				<endTimeStamp>2024-05-31T14:51:48-04:00</endTimeStamp>
				<author>
					<name>lw627</name>
				</author>
				<source>
					<applicationSoftware version="7.1">Data Collector</applicationSoftware>
					<instrumentControlSoftware version="8.2  20201204">EMPYREAN</instrumentControlSoftware>
					<instrumentID>0000000011260721</instrumentID>
				</source>
			</header>
			<dataPoints>
				<positions axis="2Theta" unit="deg">
					<startPosition>78.0488152930555</startPosition>
					<endPosition>81.396085064272</endPosition>
				</positions>
				<positions axis="Omega" unit="deg">
					<commonPosition>21.3282250893319</commonPosition>
				</positions>
				<positions axis="Phi" unit="deg">
					<commonPosition>-92.36</commonPosition>
				</positions>
				<positions axis="Chi" unit="deg">
					<commonPosition>0</commonPosition>
				</positions>
				<positions axis="Z" unit="mm">
					<commonPosition>8.35</commonPosition>
				</positions>
				<commonCountingTime unit="seconds">0.974</commonCountingTime>
				<counts unit="counts">0 1 0 0 0 1 0 0 1 1 0 1 0 0 0 2 0 0 1 0 0 0 1 0 1 0 1 0 0 0 0 0 0 0 0 0 0 0 1 0 0 0 0 0 0 0 0 0 0 0 0 0 0 0 0 0 1 1 0 0 0 0 1 0 1 0 0 0 0 0 1 0 1 0 2 1 0 0 1 1 1 0 0 0 0 0 0 0 0 0 0 0 0 0 0 0 0 0 0 0 0 0 0 0 0 0 0 0 0 0 1 0 0 1 1 0 0 0 0 1 0 0 0 1 0 1 1 2 0 0 0 1 0 0 0 0 1 0 0 0 0 0 1 0 0 1 1 1 0 0 0 0 1 0 0 0 0 1 0 1 0 0 0 0 0 0 0 0 0 0 0 0 0 0 0 1 0 0 0 0 0 1 0 0 1 0 0 0 1 0 0 0 0 0 1 1 0 0 0 1 0 1 1 1 1 1 1 0 0 0 0 0 0 0 0 1 0 1 0 0 2 0 0 0 0 0 0 0 1 1 0 0 0 0 0 0 1 0 0 1 1 1 0 0 0 1 1 1 1 0 0 0 0 0 1</counts>
			</dataPoints>
		</scan>
		<scan status="Completed" appendNumber="0" scanAxis="2Theta" mode="Continuous">
			<header>
				<startTimeStamp>2024-05-31T14:21:45-04:00</startTimeStamp>
				<endTimeStamp>2024-05-31T14:51:48-04:00</endTimeStamp>
				<author>
					<name>lw627</name>
				</author>
				<source>
					<applicationSoftware version="7.1">Data Collector</applicationSoftware>
					<instrumentControlSoftware version="8.2  20201204">EMPYREAN</instrumentControlSoftware>
					<instrumentID>0000000011260721</instrumentID>
				</source>
			</header>
			<dataPoints>
				<positions axis="2Theta" unit="deg">
					<startPosition>78.0520978637236</startPosition>
					<endPosition>81.3993676349401</endPosition>
				</positions>
				<positions axis="Omega" unit="deg">
					<commonPosition>21.3298663746659</commonPosition>
				</positions>
				<positions axis="Phi" unit="deg">
					<commonPosition>-92.36</commonPosition>
				</positions>
				<positions axis="Chi" unit="deg">
					<commonPosition>0</commonPosition>
				</positions>
				<positions axis="Z" unit="mm">
					<commonPosition>8.35</commonPosition>
				</positions>
				<commonCountingTime unit="seconds">0.974</commonCountingTime>
				<counts unit="counts">0 0 2 0 0 0 1 0 0 0 0 1 0 1 0 0 0 0 0 0 2 0 0 1 0 1 0 0 0 1 1 1 1 0 0 0 0 2 0 0 0 1 0 0 0 0 0 0 0 0 0 0 1 0 2 2 1 0 0 1 0 1 1 0 1 0 0 1 0 0 0 0 0 0 0 0 0 0 0 0 0 0 0 0 0 0 0 0 0 0 0 0 0 0 0 0 0 0 0 0 0 0 0 0 0 1 0 0 0 1 1 2 0 1 1 0 0 1 0 0 0 0 0 0 0 0 0 1 0 2 0 0 0 0 0 0 0 0 0 0 0 0 0 0 0 0 0 1 0 0 0 0 0 0 1 0 0 0 0 1 0 1 0 1 0 1 1 0 0 0 0 0 0 0 0 0 0 0 0 0 0 0 0 0 0 0 0 0 0 0 0 1 0 0 0 0 0 0 0 0 0 1 0 1 0 0 0 0 0 0 0 1 0 0 0 0 1 0 0 0 0 1 0 0 0 0 0 0 0 0 0 0 0 0 0 0 0 0 0 0 1 0 0 1 0 0 0 1 0 0 0 0 0 0 0</counts>
			</dataPoints>
		</scan>
		<scan status="Completed" appendNumber="0" scanAxis="2Theta" mode="Continuous">
			<header>
				<startTimeStamp>2024-05-31T14:21:45-04:00</startTimeStamp>
				<endTimeStamp>2024-05-31T14:51:48-04:00</endTimeStamp>
				<author>
					<name>lw627</name>
				</author>
				<source>
					<applicationSoftware version="7.1">Data Collector</applicationSoftware>
					<instrumentControlSoftware version="8.2  20201204">EMPYREAN</instrumentControlSoftware>
					<instrumentID>0000000011260721</instrumentID>
				</source>
			</header>
			<dataPoints>
				<positions axis="2Theta" unit="deg">
					<startPosition>78.0553804343918</startPosition>
					<endPosition>81.4026502056082</endPosition>
				</positions>
				<positions axis="Omega" unit="deg">
					<commonPosition>21.33150766</commonPosition>
				</positions>
				<positions axis="Phi" unit="deg">
					<commonPosition>-92.36</commonPosition>
				</positions>
				<positions axis="Chi" unit="deg">
					<commonPosition>0</commonPosition>
				</positions>
				<positions axis="Z" unit="mm">
					<commonPosition>8.35</commonPosition>
				</positions>
				<commonCountingTime unit="seconds">0.974</commonCountingTime>
				<counts unit="counts">2 1 0 0 0 2 1 0 0 0 1 1 0 0 0 0 0 2 1 0 0 1 0 0 0 0 0 0 0 0 1 0 0 1 1 0 1 1 0 1 0 1 0 1 0 0 0 0 1 0 1 0 0 1 1 0 0 1 1 0 0 1 1 0 0 0 0 0 0 0 0 0 0 1 0 0 0 0 0 0 1 0 1 1 0 0 0 0 0 0 1 1 1 0 0 0 0 0 0 1 0 0 0 0 0 0 0 0 0 2 2 0 0 0 0 0 1 2 1 0 0 1 0 0 0 0 0 0 1 0 0 0 0 0 0 0 0 0 0 0 0 0 0 1 0 1 0 1 0 1 0 0 0 0 2 0 0 1 0 1 0 0 0 0 0 1 1 0 0 0 0 0 0 0 0 0 0 1 0 0 1 1 1 2 0 0 1 0 0 0 0 0 0 0 0 0 0 0 1 0 1 0 0 1 0 1 0 0 0 1 0 0 0 0 0 0 0 1 0 0 0 0 0 0 1 0 0 0 0 0 0 0 0 1 0 1 0 0 0 1 0 1 1 0 0 1 0 0 0 0 1 0 0 0 0</counts>
			</dataPoints>
		</scan>
	</xrdMeasurement>
</xrdMeasurements>