File: data/XRD_RSM/YG067/YG067 STO 103 phi_-183.77 RSM slow 3 degree_1.xrdml
<?xml version="1.0" encoding="utf-8"?>
<xrdMeasurements xmlns="http://www.xrdml.com/XRDMeasurement/2.2" xmlns:xsi="http://www.w3.org/2001/XMLSchema-instance" xsi:schemaLocation="http://www.xrdml.com/XRDMeasurement/2.2 http://www.xrdml.com/XRDMeasurement/2.2/XRDMeasurement.xsd" status="Completed">
	<comment>
		<entry>Configuration=3-axes Cradle_Reflection, Owner=lw627, Creation date=9/2/2021 3:55:24 PM</entry>
		<entry>Goniometer=Theta/Theta; Minimum step size 2Theta:0.0001; Minimum step size Omega:0.0001</entry>
		<entry>Sample stage=Chi-Phi-z stage 240 mm (reflection); Minimum step size Phi:0.01; Minimum step size Chi:0.01; Minimum step size Z:0.001</entry>
		<entry>Diffractometer system=EMPYREAN</entry>
		<entry>Measurement program=C:\PANalytical\Data Collector\Programs\Liyan Wu\Film programs\RSM slow 3 degree.xrdmp, Identifier={0351664C-55A7-43E7-B72A-7307F4B26703}</entry>
	</comment>
	<sample type="To be analyzed">
		<id/>
		<name/>
		<preparedBy/>
	</sample>
	<xrdMeasurement status="Completed" measurementType="Area measurement" measurementStepAxis="Omega-2Theta" sampleMode="Reflection">
		<comment>
			<entry>PHD Lower Level = 4.02 (keV), PHD Upper Level = 11.27 (keV)</entry>
		</comment>
		<usedWavelength intended="K-Alpha 1">
			<kAlpha1 unit="Angstrom">1.5405980</kAlpha1>
			<kAlpha2 unit="Angstrom">1.5444260</kAlpha2>
			<kBeta unit="Angstrom">1.3922500</kBeta>
			<ratioKAlpha2KAlpha1>0</ratioKAlpha2KAlpha1>
		</usedWavelength>
		<incidentBeamPath>
			<radius unit="mm">240.00</radius>
			<xRayTube id="1010048" name="Empyrean Cu LFF HR (9430 033 7310x) DK432574">
				<tension unit="kV">45.0</tension>
				<current unit="mA">40.0</current>
				<anodeMaterial>Cu</anodeMaterial>
				<focus type="Line">
					<length unit="mm">12.0</length>
					<width unit="mm">0.4</width>
					<takeOffAngle unit="deg">4.4</takeOffAngle>
				</focus>
			</xRayTube>
			<xRayMirror xsi:type="xRayMirrorType" id="27080001" name="Inc. Beam Cu W/Si (hybrid MPD)" hybrid="true">
				<crystal type="Graded" shape="Parabolic">W/Si</crystal>
				<acceptanceAngle unit="deg">0.800</acceptanceAngle>
				<length unit="mm">55.3</length>
			</xRayMirror>
			<monochromator xsi:type="monochromatorType" id="23090002" name="Hybrid monochr. 2xGe220 Cu asym." hybrid="true">
				<crystal type="Asymmetric" shape="Flat">Ge</crystal>
				<numberOfReflections>2</numberOfReflections>
				<hkl>
					<h>2</h>
					<k>2</k>
					<l>0</l>
				</hkl>
			</monochromator>
			<divergenceSlit xsi:type="fixedDivergenceSlitType" id="22010005" name="Fixed slit 1/4°">
				<distanceToSample unit="mm">179.30</distanceToSample>
				<height unit="mm">0.38</height>
			</divergenceSlit>
		</incidentBeamPath>
		<diffractedBeamPath>
			<radius unit="mm">240.00</radius>
			<antiScatterSlit xsi:type="fixedAntiScatterSlitType" id="22060009" name="Programmable anti-scatter slit">
				<angle unit="deg">4</angle>
			</antiScatterSlit>
			<detector xsi:type="areaDetectorType" id="7010020" name="PIXcel3D-Medipix3 1x1 detector">
				<phd unit="%">
					<lowerLevel>25</lowerLevel>
					<upperLevel>70</upperLevel>
				</phd>
				<mode>Scanning snapshot equatorial</mode>
				<activeChannelsEquatorial>255</activeChannelsEquatorial>
				<activeChannelsAxial>255</activeChannelsAxial>
				<pitchEquatorial unit="mm">0.05500</pitchEquatorial>
				<pitchAxial unit="mm">0.05500</pitchAxial>
				<readOutPeriod unit="seconds">0.980</readOutPeriod>
			</detector>
		</diffractedBeamPath>
		<scan status="Completed" appendNumber="0" scanAxis="2Theta" mode="Continuous">
			<header>
				<startTimeStamp>2024-09-13T15:19:20-04:00</startTimeStamp>
				<endTimeStamp>2024-09-13T15:49:19-04:00</endTimeStamp>
				<author>
					<name>lw627</name>
				</author>
				<source>
					<applicationSoftware version="7.1">Data Collector</applicationSoftware>
					<instrumentControlSoftware version="8.2  20201204">EMPYREAN</instrumentControlSoftware>
					<instrumentID>0000000011260721</instrumentID>
				</source>
			</header>
			<dataPoints>
				<positions axis="2Theta" unit="deg">
					<startPosition>71.5484063943918</startPosition>
					<endPosition>74.8956761656082</endPosition>
				</positions>
				<positions axis="Omega" unit="deg">
					<commonPosition>17.96952064</commonPosition>
				</positions>
				<positions axis="Phi" unit="deg">
					<commonPosition>-183.77</commonPosition>
				</positions>
				<positions axis="Chi" unit="deg">
					<commonPosition>0</commonPosition>
				</positions>
				<positions axis="Z" unit="mm">
					<commonPosition>8.327</commonPosition>
				</positions>
				<commonCountingTime unit="seconds">0.974</commonCountingTime>
				<counts unit="counts">0 0 1 1 0 0 2 0 1 0 1 0 0 0 0 0 0 1 0 0 0 0 0 0 0 0 1 0 1 0 1 2 0 1 0 0 0 1 0 1 1 0 0 0 0 1 0 0 1 0 1 0 0 0 1 0 0 0 0 0 0 1 1 1 0 3 0 1 0 1 1 0 2 0 0 1 1 0 0 0 0 0 1 1 0 1 1 0 0 0 1 0 0 0 1 0 1 1 0 0 0 0 0 0 0 0 0 0 0 0 0 0 0 0 0 0 0 0 0 0 1 1 2 0 1 0 2 0 0 0 0 1 0 0 1 0 0 1 0 1 1 1 0 0 0 0 0 0 0 0 1 0 0 0 0 0 0 2 0 1 1 0 2 0 0 0 0 0 0 1 0 0 0 0 0 0 0 0 1 0 1 1 2 0 0 0 0 0 0 0 0 0 0 0 2 0 1 1 0 0 0 1 0 0 0 0 0 0 0 0 0 0 0 0 0 0 0 1 0 0 1 0 0 0 1 0 1 0 0 0 2 0 0 1 1 0 0 0 2 1 0 0 0 0 0 0 0 0 0 1 1 2 0 1 0</counts>
			</dataPoints>
		</scan>
		<scan status="Completed" appendNumber="0" scanAxis="2Theta" mode="Continuous">
			<header>
				<startTimeStamp>2024-09-13T15:19:20-04:00</startTimeStamp>
				<endTimeStamp>2024-09-13T15:49:19-04:00</endTimeStamp>
				<author>
					<name>lw627</name>
				</author>
				<source>
					<applicationSoftware version="7.1">Data Collector</applicationSoftware>
					<instrumentControlSoftware version="8.2  20201204">EMPYREAN</instrumentControlSoftware>
					<instrumentID>0000000011260721</instrumentID>
				</source>
			</header>
			<dataPoints>
				<positions axis="2Theta" unit="deg">
					<startPosition>71.5516889650599</startPosition>
					<endPosition>74.8989587362764</endPosition>
				</positions>
				<positions axis="Omega" unit="deg">
					<commonPosition>17.9711619253341</commonPosition>
				</positions>
				<positions axis="Phi" unit="deg">
					<commonPosition>-183.77</commonPosition>
				</positions>
				<positions axis="Chi" unit="deg">
					<commonPosition>0</commonPosition>
				</positions>
				<positions axis="Z" unit="mm">
					<commonPosition>8.327</commonPosition>
				</positions>
				<commonCountingTime unit="seconds">0.974</commonCountingTime>
				<counts unit="counts">1 0 0 0 1 0 1 0 0 0 0 0 0 0 0 0 1 0 1 1 0 1 1 0 0 2 0 0 0 1 0 0 0 1 0 0 0 0 0 0 0 0 0 1 0 0 0 1 0 1 1 1 0 1 1 0 0 0 0 0 0 1 1 0 0 0 0 0 0 0 0 1 0 1 0 0 0 1 0 1 0 0 0 0 0 0 0 0 1 1 0 0 0 1 0 0 1 0 0 0 0 0 0 0 1 1 0 0 0 0 0 0 0 0 0 0 0 0 1 0 1 0 0 0 0 0 0 3 0 0 0 1 0 0 0 1 0 0 1 2 0 1 0 1 0 0 0 1 0 1 0 0 0 1 0 0 0 0 0 0 1 0 1 0 1 0 0 0 0 0 0 0 1 0 0 0 1 0 0 0 0 0 0 0 1 0 1 0 0 1 2 0 0 0 0 1 0 0 2 0 0 0 0 0 0 0 0 0 0 0 0 0 0 0 0 0 0 0 0 1 0 0 1 0 0 1 1 0 0 0 0 0 0 0 1 0 0 0 1 0 2 0 0 1 0 0 1 0 1 0 0 0 1 1 0</counts>
			</dataPoints>
		</scan>
		<scan status="Completed" appendNumber="0" scanAxis="2Theta" mode="Continuous">
			<header>
				<startTimeStamp>2024-09-13T15:19:20-04:00</startTimeStamp>
				<endTimeStamp>2024-09-13T15:49:19-04:00</endTimeStamp>
				<author>
					<name>lw627</name>
				</author>
				<source>
					<applicationSoftware version="7.1">Data Collector</applicationSoftware>
					<instrumentControlSoftware version="8.2  20201204">EMPYREAN</instrumentControlSoftware>
					<instrumentID>0000000011260721</instrumentID>
				</source>
			</header>
			<dataPoints>
				<positions axis="2Theta" unit="deg">
					<startPosition>71.554971535728</startPosition>
					<endPosition>74.9022413069445</endPosition>
				</positions>
				<positions axis="Omega" unit="deg">
					<commonPosition>17.9728032106681</commonPosition>
				</positions>
				<positions axis="Phi" unit="deg">
					<commonPosition>-183.77</commonPosition>
				</positions>
				<positions axis="Chi" unit="deg">
					<commonPosition>0</commonPosition>
				</positions>
				<positions axis="Z" unit="mm">
					<commonPosition>8.327</commonPosition>
				</positions>
				<commonCountingTime unit="seconds">0.974</commonCountingTime>
				<counts unit="counts">0 0 0 0 2 0 1 0 0 0 1 0 0 0 1 0 0 0 0 1 0 1 0 0 0 0 2 0 0 0 0 0 1 0 0 0 1 0 1 0 0 0 0 1 0 0 2 1 0 0 0 0 0 0 0 2 2 0 0 0 1 2 2 2 0 1 0 1 2 1 0 0 0 1 0 1 0 0 0 0 0 0 0 0 1 0 0 0 1 0 0 0 0 0 1 0 0 0 1 0 0 0 0 0 0 0 0 0 0 0 0 0 0 0 0 0 0 2 0 1 0 0 0 0 0 0 1 0 0 0 0 0 0 0 0 1 0 1 0 0 0 0 2 0 0 0 1 0 2 1 1 0 0 1 1 0 0 0 0 0 0 0 0 0 1 1 0 0 0 0 0 0 0 0 1 0 0 0 1 0 0 0 0 0 0 0 0 0 0 1 0 1 2 0 0 1 0 2 0 1 1 0 1 0 0 0 0 0 0 0 0 1 0 0 0 0 0 2 0 0 3 0 2 0 1 0 0 0 0 1 1 0 0 0 2 0 1 1 0 0 0 1 0 0 1 0 0 1 0 0 0 1 1 0 0</counts>
			</dataPoints>
		</scan>
		<scan status="Completed" appendNumber="0" scanAxis="2Theta" mode="Continuous">
			<header>
				<startTimeStamp>2024-09-13T15:19:20-04:00</startTimeStamp>
				<endTimeStamp>2024-09-13T15:49:19-04:00</endTimeStamp>
				<author>
					<name>lw627</name>
				</author>
				<source>
					<applicationSoftware version="7.1">Data Collector</applicationSoftware>
					<instrumentControlSoftware version="8.2  20201204">EMPYREAN</instrumentControlSoftware>
					<instrumentID>0000000011260721</instrumentID>
				</source>
			</header>
			<dataPoints>
				<positions axis="2Theta" unit="deg">
					<startPosition>71.5582541063961</startPosition>
					<endPosition>74.9055238776126</endPosition>
				</positions>
				<positions axis="Omega" unit="deg">
					<commonPosition>17.9744444960022</commonPosition>
				</positions>
				<positions axis="Phi" unit="deg">
					<commonPosition>-183.77</commonPosition>
				</positions>
				<positions axis="Chi" unit="deg">
					<commonPosition>0</commonPosition>
				</positions>
				<positions axis="Z" unit="mm">
					<commonPosition>8.327</commonPosition>
				</positions>
				<commonCountingTime unit="seconds">0.974</commonCountingTime>
				<counts unit="counts">0 0 0 2 0 1 0 0 0 0 1 0 0 0 0 0 1 1 0 0 1 1 0 1 0 0 1 0 0 0 1 0 0 0 1 0 0 0 1 0 0 0 1 1 0 1 0 0 1 2 0 0 0 0 0 0 0 0 0 0 0 0 0 0 0 0 1 0 1 0 1 0 1 0 0 0 0 0 0 0 0 0 3 1 2 0 0 1 0 1 0 0 0 2 0 1 0 0 0 1 1 0 1 0 0 0 0 0 0 0 0 0 0 0 2 1 0 1 1 3 0 0 0 1 0 0 0 0 1 1 2 1 0 0 0 0 0 1 0 0 1 0 2 0 0 0 0 0 0 0 0 0 0 2 1 3 0 1 1 0 0 0 0 0 0 0 0 1 0 1 0 0 1 0 2 0 0 0 0 0 0 0 0 0 0 0 0 0 0 0 2 0 0 0 2 2 0 0 1 1 0 0 1 0 0 0 0 0 0 0 1 0 0 1 0 0 0 0 0 0 0 2 0 0 0 0 0 0 0 1 0 1 0 1 0 0 0 0 0 0 0 0 0 1 1 0 1 0 0 1 0 0 0 0 0</counts>
			</dataPoints>
		</scan>
		<scan status="Completed" appendNumber="0" scanAxis="2Theta" mode="Continuous">
			<header>
				<startTimeStamp>2024-09-13T15:19:20-04:00</startTimeStamp>
				<endTimeStamp>2024-09-13T15:49:19-04:00</endTimeStamp>
				<author>
					<name>lw627</name>
				</author>
				<source>
					<applicationSoftware version="7.1">Data Collector</applicationSoftware>
					<instrumentControlSoftware version="8.2  20201204">EMPYREAN</instrumentControlSoftware>
					<instrumentID>0000000011260721</instrumentID>
				</source>
			</header>
			<dataPoints>
				<positions axis="2Theta" unit="deg">
					<startPosition>71.5615366770643</startPosition>
					<endPosition>74.9088064482807</endPosition>
				</positions>
				<positions axis="Omega" unit="deg">
					<commonPosition>17.9760857813363</commonPosition>
				</positions>
				<positions axis="Phi" unit="deg">
					<commonPosition>-183.77</commonPosition>
				</positions>
				<positions axis="Chi" unit="deg">
					<commonPosition>0</commonPosition>
				</positions>
				<positions axis="Z" unit="mm">
					<commonPosition>8.327</commonPosition>
				</positions>
				<commonCountingTime unit="seconds">0.974</commonCountingTime>
				<counts unit="counts">1 0 0 1 1 0 0 0 0 0 0 1 0 1 0 0 0 0 0 1 0 0 0 0 1 0 0 3 0 0 0 0 0 0 0 0 0 0 0 0 0 0 0 0 0 1 0 0 0 0 0 0 0 0 0 0 0 0 1 0 0 0 1 0 1 0 0 0 1 1 2 0 1 1 0 0 0 1 0 1 0 1 1 1 0 1 0 0 0 1 0 1 0 0 0 0 1 0 0 1 1 0 0 1 1 0 1 0 0 0 0 0 0 0 0 0 1 0 0 0 0 0 0 0 0 0 0 0 0 1 0 0 1 0 1 0 0 0 0 0 1 0 0 0 0 1 0 1 2 0 0 0 0 1 2 0 0 0 1 1 0 1 0 0 1 1 0 0 0 1 0 0 1 0 0 0 0 0 0 0 0 0 1 0 0 0 0 0 0 1 2 0 0 1 0 0 1 0 0 1 0 0 0 1 0 1 0 0 0 1 0 1 0 1 0 0 0 0 0 0 0 0 2 0 0 0 0 0 1 0 0 1 0 0 0 0 0 0 0 0 0 0 0 1 0 0 0 0 1 0 0 1 0 1 0</counts>
			</dataPoints>
		</scan>
		<scan status="Completed" appendNumber="0" scanAxis="2Theta" mode="Continuous">
			<header>
				<startTimeStamp>2024-09-13T15:19:20-04:00</startTimeStamp>
				<endTimeStamp>2024-09-13T15:49:19-04:00</endTimeStamp>
				<author>
					<name>lw627</name>
				</author>
				<source>
					<applicationSoftware version="7.1">Data Collector</applicationSoftware>
					<instrumentControlSoftware version="8.2  20201204">EMPYREAN</instrumentControlSoftware>
					<instrumentID>0000000011260721</instrumentID>
				</source>
			</header>
			<dataPoints>
				<positions axis="2Theta" unit="deg">
					<startPosition>71.5648192477324</startPosition>
					<endPosition>74.9120890189489</endPosition>
				</positions>
				<positions axis="Omega" unit="deg">
					<commonPosition>17.9777270666703</commonPosition>
				</positions>
				<positions axis="Phi" unit="deg">
					<commonPosition>-183.77</commonPosition>
				</positions>
				<positions axis="Chi" unit="deg">
					<commonPosition>0</commonPosition>
				</positions>
				<positions axis="Z" unit="mm">
					<commonPosition>8.327</commonPosition>
				</positions>
				<commonCountingTime unit="seconds">0.974</commonCountingTime>
				<counts unit="counts">2 0 1 0 0 0 0 0 0 0 1 0 1 1 0 0 0 0 0 2 0 0 0 0 2 0 2 0 1 0 0 1 0 1 0 0 0 0 0 0 0 0 0 2 0 0 0 0 1 0 0 0 0 0 1 0 1 0 0 1 0 0 1 0 0 0 0 0 1 0 0 0 0 0 0 0 0 0 0 1 0 0 1 0 0 0 2 1 1 1 0 0 0 0 0 1 0 2 0 0 0 1 0 0 0 0 2 1 0 0 0 0 0 1 0 0 1 0 0 2 0 2 0 0 0 0 1 0 0 1 0 0 0 0 1 0 0 0 0 1 0 1 1 0 0 0 1 2 0 0 0 0 0 0 0 1 0 0 0 1 0 0 0 0 0 0 0 1 0 1 0 1 1 0 1 1 0 0 0 0 1 1 0 1 0 0 0 0 0 1 0 0 0 0 0 1 0 1 0 2 0 0 0 0 1 0 1 1 0 0 1 0 1 0 0 0 0 0 0 1 0 0 0 0 0 0 1 1 0 1 0 3 0 0 0 1 0 0 0 0 1 0 0 0 0 0 0 0 1 1 2 0 1 0 0</counts>
			</dataPoints>
		</scan>
		<scan status="Completed" appendNumber="0" scanAxis="2Theta" mode="Continuous">
			<header>
				<startTimeStamp>2024-09-13T15:19:20-04:00</startTimeStamp>
				<endTimeStamp>2024-09-13T15:49:19-04:00</endTimeStamp>
				<author>
					<name>lw627</name>
				</author>
				<source>
					<applicationSoftware version="7.1">Data Collector</applicationSoftware>
					<instrumentControlSoftware version="8.2  20201204">EMPYREAN</instrumentControlSoftware>
					<instrumentID>0000000011260721</instrumentID>
				</source>
			</header>
			<dataPoints>
				<positions axis="2Theta" unit="deg">
					<startPosition>71.5681018184005</startPosition>
					<endPosition>74.915371589617</endPosition>
				</positions>
				<positions axis="Omega" unit="deg">
					<commonPosition>17.9793683520044</commonPosition>
				</positions>
				<positions axis="Phi" unit="deg">
					<commonPosition>-183.77</commonPosition>
				</positions>
				<positions axis="Chi" unit="deg">
					<commonPosition>0</commonPosition>
				</positions>
				<positions axis="Z" unit="mm">
					<commonPosition>8.327</commonPosition>
				</positions>
				<commonCountingTime unit="seconds">0.974</commonCountingTime>
				<counts unit="counts">0 0 1 0 0 0 0 1 0 1 0 1 0 0 0 1 2 0 0 0 0 0 1 0 1 0 0 0 0 1 0 0 1 0 1 1 0 0 0 0 0 2 1 0 0 0 0 0 1 0 0 1 0 0 0 0 0 0 0 0 0 0 0 0 0 0 0 0 0 0 0 0 0 0 1 0 2 0 0 0 2 2 0 0 0 0 0 0 1 0 0 0 0 1 1 1 0 0 0 1 3 0 0 1 0 0 1 0 0 0 0 0 0 0 0 2 0 1 0 1 0 1 0 0 1 0 1 1 0 1 0 0 1 0 0 1 0 0 0 1 0 1 0 0 0 0 0 0 0 0 0 0 0 0 0 0 2 0 0 0 0 1 0 0 0 0 0 0 0 0 0 0 0 0 0 1 1 0 0 0 1 1 1 0 0 0 0 0 0 2 1 1 0 1 0 0 0 0 0 0 0 0 0 0 0 0 0 0 0 2 1 0 0 1 1 1 0 0 1 0 0 1 0 1 1 1 1 1 0 1 0 0 0 1 0 0 0 1 1 0 0 0 0 1 0 0 1 2 0 0 1 0 0 1 1</counts>
			</dataPoints>
		</scan>
		<scan status="Completed" appendNumber="0" scanAxis="2Theta" mode="Continuous">
			<header>
				<startTimeStamp>2024-09-13T15:19:20-04:00</startTimeStamp>
				<endTimeStamp>2024-09-13T15:49:19-04:00</endTimeStamp>
				<author>
					<name>lw627</name>
				</author>
				<source>
					<applicationSoftware version="7.1">Data Collector</applicationSoftware>
					<instrumentControlSoftware version="8.2  20201204">EMPYREAN</instrumentControlSoftware>
					<instrumentID>0000000011260721</instrumentID>
				</source>
			</header>
			<dataPoints>
				<positions axis="2Theta" unit="deg">
					<startPosition>71.5713843890687</startPosition>
					<endPosition>74.9186541602851</endPosition>
				</positions>
				<positions axis="Omega" unit="deg">
					<commonPosition>17.9810096373384</commonPosition>
				</positions>
				<positions axis="Phi" unit="deg">
					<commonPosition>-183.77</commonPosition>
				</positions>
				<positions axis="Chi" unit="deg">
					<commonPosition>0</commonPosition>
				</positions>
				<positions axis="Z" unit="mm">
					<commonPosition>8.327</commonPosition>
				</positions>
				<commonCountingTime unit="seconds">0.974</commonCountingTime>
				<counts unit="counts">1 0 0 1 2 0 1 1 1 0 1 1 0 0 2 0 0 0 0 0 0 0 0 0 0 0 0 0 0 0 1 1 0 1 1 0 0 0 1 1 0 0 0 0 0 0 0 0 0 1 0 1 3 0 0 0 1 0 0 0 0 1 1 0 0 0 0 0 1 1 0 1 1 0 0 1 0 0 0 0 1 0 0 0 0 0 0 0 0 1 0 0 0 0 1 0 0 0 0 0 1 0 0 1 1 0 0 0 0 0 0 1 0 0 1 0 0 0 1 1 0 0 1 0 0 0 1 0 0 0 0 0 0 0 0 2 1 0 0 1 0 0 0 0 0 0 0 0 0 0 0 0 3 0 0 0 1 1 1 0 0 1 0 0 0 0 1 0 0 0 1 1 0 0 1 0 0 1 0 0 1 0 0 0 0 0 0 0 0 0 0 1 0 0 1 0 0 0 0 0 1 0 1 0 0 0 0 0 0 0 2 0 0 0 0 1 0 1 0 0 0 0 0 0 1 1 0 0 0 1 0 0 0 0 0 0 0 0 1 1 1 0 0 0 1 1 0 0 0 0 2 0 0 0 0</counts>
			</dataPoints>
		</scan>
		<scan status="Completed" appendNumber="0" scanAxis="2Theta" mode="Continuous">
			<header>
				<startTimeStamp>2024-09-13T15:19:20-04:00</startTimeStamp>
				<endTimeStamp>2024-09-13T15:49:19-04:00</endTimeStamp>
				<author>
					<name>lw627</name>
				</author>
				<source>
					<applicationSoftware version="7.1">Data Collector</applicationSoftware>
					<instrumentControlSoftware version="8.2  20201204">EMPYREAN</instrumentControlSoftware>
					<instrumentID>0000000011260721</instrumentID>
				</source>
			</header>
			<dataPoints>
				<positions axis="2Theta" unit="deg">
					<startPosition>71.5746669597368</startPosition>
					<endPosition>74.9219367309533</endPosition>
				</positions>
				<positions axis="Omega" unit="deg">
					<commonPosition>17.9826509226725</commonPosition>
				</positions>
				<positions axis="Phi" unit="deg">
					<commonPosition>-183.77</commonPosition>
				</positions>
				<positions axis="Chi" unit="deg">
					<commonPosition>0</commonPosition>
				</positions>
				<positions axis="Z" unit="mm">
					<commonPosition>8.327</commonPosition>
				</positions>
				<commonCountingTime unit="seconds">0.974</commonCountingTime>
				<counts unit="counts">2 0 1 1 0 0 0 0 0 0 0 0 0 0 1 1 0 0 0 2 1 0 1 0 0 0 0 0 0 0 0 0 0 1 0 1 0 0 0 1 2 0 0 0 1 0 0 1 0 0 0 2 0 0 0 0 0 0 0 0 0 0 0 0 2 0 0 0 0 0 0 0 0 0 0 0 0 1 0 1 1 1 0 0 0 0 0 0 0 0 1 0 0 1 1 0 0 0 0 0 1 1 0 0 0 1 2 0 0 0 0 0 0 0 0 1 0 2 0 0 0 0 0 0 0 0 0 0 1 1 0 2 0 0 0 0 0 0 1 2 0 1 1 1 0 0 0 0 1 0 1 0 0 1 0 0 0 0 1 0 0 1 0 1 0 0 0 3 1 1 0 0 0 0 1 2 0 0 1 0 0 0 0 0 0 0 0 0 1 0 2 0 1 1 0 0 0 0 0 0 1 0 0 0 1 0 0 0 1 0 0 0 1 0 0 0 0 1 0 0 0 2 0 1 0 0 0 0 0 1 0 0 0 1 0 0 0 0 0 0 0 0 0 1 1 0 2 0 0 0 0 1 0 0 0</counts>
			</dataPoints>
		</scan>
		<scan status="Completed" appendNumber="0" scanAxis="2Theta" mode="Continuous">
			<header>
				<startTimeStamp>2024-09-13T15:19:20-04:00</startTimeStamp>
				<endTimeStamp>2024-09-13T15:49:19-04:00</endTimeStamp>
				<author>
					<name>lw627</name>
				</author>
				<source>
					<applicationSoftware version="7.1">Data Collector</applicationSoftware>
					<instrumentControlSoftware version="8.2  20201204">EMPYREAN</instrumentControlSoftware>
					<instrumentID>0000000011260721</instrumentID>
				</source>
			</header>
			<dataPoints>
				<positions axis="2Theta" unit="deg">
					<startPosition>71.5779495304049</startPosition>
					<endPosition>74.9252193016214</endPosition>
				</positions>
				<positions axis="Omega" unit="deg">
					<commonPosition>17.9842922080066</commonPosition>
				</positions>
				<positions axis="Phi" unit="deg">
					<commonPosition>-183.77</commonPosition>
				</positions>
				<positions axis="Chi" unit="deg">
					<commonPosition>0</commonPosition>
				</positions>
				<positions axis="Z" unit="mm">
					<commonPosition>8.327</commonPosition>
				</positions>
				<commonCountingTime unit="seconds">0.974</commonCountingTime>
				<counts unit="counts">0 0 1 1 0 0 0 1 3 1 0 1 0 0 0 0 0 0 0 0 2 0 0 0 0 0 1 0 1 0 1 1 1 0 0 0 0 0 2 0 0 1 0 0 0 0 0 0 0 0 0 0 1 0 1 0 0 0 0 0 0 0 0 1 0 0 2 0 0 0 1 0 0 1 0 0 1 0 0 0 0 0 0 1 0 1 0 0 1 0 0 0 1 0 0 0 0 0 0 1 0 0 0 0 1 0 1 0 1 1 0 0 1 0 0 1 0 0 0 0 0 0 0 2 0 0 2 0 1 0 0 1 0 0 0 0 0 0 0 0 1 1 1 0 0 1 0 0 0 0 0 0 1 0 0 0 0 0 0 2 0 1 1 1 1 0 1 0 0 0 1 0 1 1 0 0 0 0 0 1 0 0 0 0 1 1 0 1 0 1 0 0 2 0 0 1 0 0 0 0 0 1 0 0 1 0 0 0 0 0 0 0 1 0 0 0 0 0 0 0 0 0 0 0 1 0 0 0 0 0 0 0 1 2 0 0 2 0 0 0 0 0 1 0 0 1 0 1 0 0 0 0 0 0 0</counts>
			</dataPoints>
		</scan>
		<scan status="Completed" appendNumber="0" scanAxis="2Theta" mode="Continuous">
			<header>
				<startTimeStamp>2024-09-13T15:19:20-04:00</startTimeStamp>
				<endTimeStamp>2024-09-13T15:49:19-04:00</endTimeStamp>
				<author>
					<name>lw627</name>
				</author>
				<source>
					<applicationSoftware version="7.1">Data Collector</applicationSoftware>
					<instrumentControlSoftware version="8.2  20201204">EMPYREAN</instrumentControlSoftware>
					<instrumentID>0000000011260721</instrumentID>
				</source>
			</header>
			<dataPoints>
				<positions axis="2Theta" unit="deg">
					<startPosition>71.581232101073</startPosition>
					<endPosition>74.9285018722895</endPosition>
				</positions>
				<positions axis="Omega" unit="deg">
					<commonPosition>17.9859334933406</commonPosition>
				</positions>
				<positions axis="Phi" unit="deg">
					<commonPosition>-183.77</commonPosition>
				</positions>
				<positions axis="Chi" unit="deg">
					<commonPosition>0</commonPosition>
				</positions>
				<positions axis="Z" unit="mm">
					<commonPosition>8.327</commonPosition>
				</positions>
				<commonCountingTime unit="seconds">0.974</commonCountingTime>
				<counts unit="counts">0 0 0 0 1 0 0 0 0 1 0 0 2 0 0 1 0 0 0 0 1 0 0 1 1 0 0 2 0 0 1 0 0 1 0 1 0 0 0 1 0 0 1 0 0 0 1 1 2 0 0 0 0 0 1 0 0 0 0 0 0 0 0 0 0 0 1 1 0 0 0 1 0 0 0 0 1 0 0 0 0 0 0 2 0 0 0 1 0 0 2 0 1 0 0 1 0 0 1 0 1 1 0 0 0 0 0 0 0 0 0 1 1 1 0 0 0 0 0 0 2 1 0 0 0 0 0 0 1 0 0 0 0 0 0 0 0 1 1 0 1 1 0 0 2 1 0 0 0 1 1 0 0 0 0 0 1 0 0 0 0 1 1 0 0 0 0 1 0 0 0 0 0 0 0 0 0 0 0 0 0 0 0 0 1 1 0 0 0 0 0 0 2 0 0 2 0 0 0 0 1 1 0 0 0 0 1 0 0 0 0 0 0 0 0 0 1 1 0 0 0 0 0 0 2 0 0 0 1 0 0 0 1 0 1 0 1 1 0 0 1 0 0 0 0 0 3 0 0 0 1 0 0 0 0</counts>
			</dataPoints>
		</scan>
		<scan status="Completed" appendNumber="0" scanAxis="2Theta" mode="Continuous">
			<header>
				<startTimeStamp>2024-09-13T15:19:20-04:00</startTimeStamp>
				<endTimeStamp>2024-09-13T15:49:19-04:00</endTimeStamp>
				<author>
					<name>lw627</name>
				</author>
				<source>
					<applicationSoftware version="7.1">Data Collector</applicationSoftware>
					<instrumentControlSoftware version="8.2  20201204">EMPYREAN</instrumentControlSoftware>
					<instrumentID>0000000011260721</instrumentID>
				</source>
			</header>
			<dataPoints>
				<positions axis="2Theta" unit="deg">
					<startPosition>71.5845146717412</startPosition>
					<endPosition>74.9317844429576</endPosition>
				</positions>
				<positions axis="Omega" unit="deg">
					<commonPosition>17.9875747786747</commonPosition>
				</positions>
				<positions axis="Phi" unit="deg">
					<commonPosition>-183.77</commonPosition>
				</positions>
				<positions axis="Chi" unit="deg">
					<commonPosition>0</commonPosition>
				</positions>
				<positions axis="Z" unit="mm">
					<commonPosition>8.327</commonPosition>
				</positions>
				<commonCountingTime unit="seconds">0.974</commonCountingTime>
				<counts unit="counts">0 1 1 0 0 0 0 0 0 0 1 0 0 1 0 0 0 2 0 0 0 0 0 0 0 0 0 0 1 0 0 0 1 0 0 0 0 0 0 0 0 0 0 1 1 0 1 0 0 0 0 0 0 0 1 0 0 2 0 0 0 1 0 0 0 0 0 0 0 0 0 2 0 0 0 0 0 1 0 0 1 1 0 0 0 0 0 0 2 0 0 1 0 1 0 0 1 1 0 0 0 1 0 0 0 1 1 0 0 0 0 0 1 0 0 0 1 1 0 1 0 0 1 1 1 0 0 0 0 0 0 0 1 1 1 1 0 1 0 0 0 1 0 0 1 0 0 0 0 0 0 0 2 0 1 0 2 0 0 0 0 0 0 0 1 0 2 0 0 1 1 1 0 0 2 0 0 0 1 0 1 0 1 0 1 0 0 0 0 0 0 0 0 0 1 1 0 0 0 1 0 0 0 2 0 0 1 1 0 0 0 1 0 1 1 1 1 0 0 0 1 0 0 1 0 0 0 1 1 0 0 0 0 0 2 2 1 0 0 0 0 0 0 0 0 0 0 0 0 0 0 0 0 0 1</counts>
			</dataPoints>
		</scan>
		<scan status="Completed" appendNumber="0" scanAxis="2Theta" mode="Continuous">
			<header>
				<startTimeStamp>2024-09-13T15:19:20-04:00</startTimeStamp>
				<endTimeStamp>2024-09-13T15:49:19-04:00</endTimeStamp>
				<author>
					<name>lw627</name>
				</author>
				<source>
					<applicationSoftware version="7.1">Data Collector</applicationSoftware>
					<instrumentControlSoftware version="8.2  20201204">EMPYREAN</instrumentControlSoftware>
					<instrumentID>0000000011260721</instrumentID>
				</source>
			</header>
			<dataPoints>
				<positions axis="2Theta" unit="deg">
					<startPosition>71.5877972424093</startPosition>
					<endPosition>74.9350670136258</endPosition>
				</positions>
				<positions axis="Omega" unit="deg">
					<commonPosition>17.9892160640088</commonPosition>
				</positions>
				<positions axis="Phi" unit="deg">
					<commonPosition>-183.77</commonPosition>
				</positions>
				<positions axis="Chi" unit="deg">
					<commonPosition>0</commonPosition>
				</positions>
				<positions axis="Z" unit="mm">
					<commonPosition>8.327</commonPosition>
				</positions>
				<commonCountingTime unit="seconds">0.974</commonCountingTime>
				<counts unit="counts">1 0 1 0 1 1 1 0 1 0 0 0 0 0 0 0 0 0 1 0 0 1 0 0 0 0 0 0 0 1 0 0 0 2 0 1 0 1 1 1 0 1 0 0 0 0 0 0 0 0 0 0 0 0 0 0 2 0 0 0 0 0 0 0 1 0 0 1 0 0 0 0 0 0 1 1 0 1 1 0 0 0 0 1 0 0 1 0 0 0 0 0 0 0 0 0 0 0 0 0 0 1 1 0 0 2 0 0 2 0 0 2 1 0 0 2 1 0 0 0 0 0 0 0 0 0 0 0 0 0 0 0 0 0 0 1 0 1 1 0 0 1 0 1 0 2 0 0 2 0 1 1 0 0 0 0 0 0 2 1 0 0 1 0 0 0 0 1 0 0 0 0 0 0 0 0 2 0 1 0 0 0 1 0 0 1 1 1 0 0 0 0 0 2 1 0 1 0 2 0 0 1 0 1 1 0 0 0 0 0 1 0 0 0 0 1 0 0 1 0 1 1 0 0 0 1 0 0 0 1 0 0 0 0 0 0 0 0 2 0 0 0 0 0 0 0 1 0 0 1 0 1 1 0 1</counts>
			</dataPoints>
		</scan>
		<scan status="Completed" appendNumber="0" scanAxis="2Theta" mode="Continuous">
			<header>
				<startTimeStamp>2024-09-13T15:19:20-04:00</startTimeStamp>
				<endTimeStamp>2024-09-13T15:49:19-04:00</endTimeStamp>
				<author>
					<name>lw627</name>
				</author>
				<source>
					<applicationSoftware version="7.1">Data Collector</applicationSoftware>
					<instrumentControlSoftware version="8.2  20201204">EMPYREAN</instrumentControlSoftware>
					<instrumentID>0000000011260721</instrumentID>
				</source>
			</header>
			<dataPoints>
				<positions axis="2Theta" unit="deg">
					<startPosition>71.5910798130774</startPosition>
					<endPosition>74.9383495842939</endPosition>
				</positions>
				<positions axis="Omega" unit="deg">
					<commonPosition>17.9908573493428</commonPosition>
				</positions>
				<positions axis="Phi" unit="deg">
					<commonPosition>-183.77</commonPosition>
				</positions>
				<positions axis="Chi" unit="deg">
					<commonPosition>0</commonPosition>
				</positions>
				<positions axis="Z" unit="mm">
					<commonPosition>8.327</commonPosition>
				</positions>
				<commonCountingTime unit="seconds">0.974</commonCountingTime>
				<counts unit="counts">1 0 0 1 1 0 0 0 0 0 0 0 0 0 0 0 0 1 0 1 1 0 0 0 0 0 1 0 2 0 2 0 0 0 2 0 0 1 0 0 0 0 0 0 0 0 0 0 0 0 1 0 1 0 0 0 0 0 0 1 0 1 0 0 0 1 0 0 0 1 1 0 0 1 1 0 0 0 0 0 1 0 1 0 1 0 0 0 0 0 0 0 2 0 0 2 0 0 0 0 0 0 1 0 0 0 0 0 0 0 1 0 0 0 0 1 0 0 0 0 0 1 0 0 0 1 0 0 0 1 0 0 0 0 1 0 1 1 0 0 0 1 1 1 0 0 0 0 0 0 0 0 0 1 0 0 0 0 0 0 0 0 0 0 0 1 1 0 0 0 0 0 0 0 2 0 1 0 0 0 0 1 0 1 0 1 0 0 1 0 1 1 0 0 0 0 0 0 0 0 0 0 0 0 0 1 1 0 0 0 0 0 0 2 0 0 0 0 0 0 0 0 0 0 0 1 0 0 0 0 0 0 0 0 0 0 0 0 0 0 0 0 0 2 0 0 1 0 0 0 0 0 1 1 0</counts>
			</dataPoints>
		</scan>
		<scan status="Completed" appendNumber="0" scanAxis="2Theta" mode="Continuous">
			<header>
				<startTimeStamp>2024-09-13T15:19:20-04:00</startTimeStamp>
				<endTimeStamp>2024-09-13T15:49:19-04:00</endTimeStamp>
				<author>
					<name>lw627</name>
				</author>
				<source>
					<applicationSoftware version="7.1">Data Collector</applicationSoftware>
					<instrumentControlSoftware version="8.2  20201204">EMPYREAN</instrumentControlSoftware>
					<instrumentID>0000000011260721</instrumentID>
				</source>
			</header>
			<dataPoints>
				<positions axis="2Theta" unit="deg">
					<startPosition>71.5943623837455</startPosition>
					<endPosition>74.941632154962</endPosition>
				</positions>
				<positions axis="Omega" unit="deg">
					<commonPosition>17.9924986346769</commonPosition>
				</positions>
				<positions axis="Phi" unit="deg">
					<commonPosition>-183.77</commonPosition>
				</positions>
				<positions axis="Chi" unit="deg">
					<commonPosition>0</commonPosition>
				</positions>
				<positions axis="Z" unit="mm">
					<commonPosition>8.327</commonPosition>
				</positions>
				<commonCountingTime unit="seconds">0.974</commonCountingTime>
				<counts unit="counts">0 0 1 0 0 1 1 0 1 1 0 0 1 1 0 0 0 1 0 0 0 0 0 0 1 1 1 0 1 0 0 0 0 0 0 0 0 0 0 0 0 0 1 2 0 0 0 1 1 0 0 0 0 1 0 0 0 1 0 0 1 1 0 0 0 0 0 0 0 1 0 0 0 0 0 0 0 0 0 0 0 1 1 3 1 1 0 0 0 1 0 0 0 0 1 1 0 0 0 0 0 0 0 0 0 1 0 0 0 0 0 0 0 1 0 0 0 0 1 0 0 1 0 0 0 1 0 0 0 0 1 0 0 0 0 0 0 1 0 0 0 0 0 0 0 0 0 0 0 1 0 0 1 0 0 1 0 0 0 1 0 0 0 0 0 4 0 0 0 0 0 0 0 0 1 0 1 1 0 0 0 0 0 1 0 0 1 1 1 1 0 1 0 0 0 0 0 1 0 0 0 0 0 0 0 0 0 0 0 1 0 1 1 0 0 1 0 0 1 2 1 2 0 0 0 1 0 0 0 1 1 1 0 0 0 1 0 0 0 0 0 0 1 0 0 0 0 1 0 0 1 0 0 0 0</counts>
			</dataPoints>
		</scan>
		<scan status="Completed" appendNumber="0" scanAxis="2Theta" mode="Continuous">
			<header>
				<startTimeStamp>2024-09-13T15:19:20-04:00</startTimeStamp>
				<endTimeStamp>2024-09-13T15:49:19-04:00</endTimeStamp>
				<author>
					<name>lw627</name>
				</author>
				<source>
					<applicationSoftware version="7.1">Data Collector</applicationSoftware>
					<instrumentControlSoftware version="8.2  20201204">EMPYREAN</instrumentControlSoftware>
					<instrumentID>0000000011260721</instrumentID>
				</source>
			</header>
			<dataPoints>
				<positions axis="2Theta" unit="deg">
					<startPosition>71.5976449544137</startPosition>
					<endPosition>74.9449147256301</endPosition>
				</positions>
				<positions axis="Omega" unit="deg">
					<commonPosition>17.994139920011</commonPosition>
				</positions>
				<positions axis="Phi" unit="deg">
					<commonPosition>-183.77</commonPosition>
				</positions>
				<positions axis="Chi" unit="deg">
					<commonPosition>0</commonPosition>
				</positions>
				<positions axis="Z" unit="mm">
					<commonPosition>8.327</commonPosition>
				</positions>
				<commonCountingTime unit="seconds">0.974</commonCountingTime>
				<counts unit="counts">1 0 1 0 0 0 1 0 0 1 0 0 0 0 0 0 0 0 2 0 0 0 0 0 0 2 0 1 0 1 0 0 1 0 0 0 0 0 0 1 0 0 0 0 0 1 0 0 0 0 0 0 0 2 0 0 0 0 0 0 0 1 0 0 1 0 0 1 0 0 0 1 0 1 0 0 0 0 0 1 0 0 3 0 1 2 0 0 0 0 0 0 0 0 0 1 0 0 0 1 0 0 0 0 0 2 0 0 0 1 0 0 0 0 0 0 0 1 1 1 0 0 0 0 1 0 0 0 0 0 0 1 0 0 0 0 0 0 0 0 0 0 1 0 1 0 0 0 0 1 2 0 0 1 0 1 1 0 1 1 0 0 0 1 0 0 1 2 0 0 0 0 0 0 0 1 0 2 0 0 0 0 0 0 0 0 0 0 0 0 0 0 2 2 0 1 0 0 0 1 0 0 1 0 0 0 0 0 0 1 0 0 0 0 0 0 0 1 0 0 3 0 0 0 0 0 0 1 0 0 0 0 0 0 0 0 0 0 0 0 0 0 0 0 0 0 0 0 0 0 0 0 0 0 0</counts>
			</dataPoints>
		</scan>
		<scan status="Completed" appendNumber="0" scanAxis="2Theta" mode="Continuous">
			<header>
				<startTimeStamp>2024-09-13T15:19:20-04:00</startTimeStamp>
				<endTimeStamp>2024-09-13T15:49:19-04:00</endTimeStamp>
				<author>
					<name>lw627</name>
				</author>
				<source>
					<applicationSoftware version="7.1">Data Collector</applicationSoftware>
					<instrumentControlSoftware version="8.2  20201204">EMPYREAN</instrumentControlSoftware>
					<instrumentID>0000000011260721</instrumentID>
				</source>
			</header>
			<dataPoints>
				<positions axis="2Theta" unit="deg">
					<startPosition>71.6009275250818</startPosition>
					<endPosition>74.9481972962983</endPosition>
				</positions>
				<positions axis="Omega" unit="deg">
					<commonPosition>17.995781205345</commonPosition>
				</positions>
				<positions axis="Phi" unit="deg">
					<commonPosition>-183.77</commonPosition>
				</positions>
				<positions axis="Chi" unit="deg">
					<commonPosition>0</commonPosition>
				</positions>
				<positions axis="Z" unit="mm">
					<commonPosition>8.327</commonPosition>
				</positions>
				<commonCountingTime unit="seconds">0.974</commonCountingTime>
				<counts unit="counts">0 0 0 0 0 1 0 0 0 0 0 0 0 0 1 0 0 0 0 0 2 1 1 0 0 0 0 0 1 0 0 0 0 0 0 0 1 0 1 1 1 0 1 0 1 0 0 0 1 0 0 0 0 0 0 0 0 0 1 0 0 0 0 0 0 0 0 0 0 2 0 0 1 0 0 0 0 0 0 0 0 1 0 0 0 1 1 2 1 0 0 0 0 0 0 0 1 1 0 0 1 0 0 0 0 2 0 1 1 1 2 0 0 1 0 0 1 0 0 0 0 0 1 0 0 1 0 0 0 0 1 1 0 1 0 0 0 0 1 0 0 0 0 0 1 0 2 1 0 0 0 0 1 1 0 0 0 1 0 0 1 0 0 0 1 1 0 0 0 0 0 0 0 0 0 2 1 1 0 0 0 0 1 0 0 0 1 0 1 0 1 0 1 0 1 0 0 0 1 1 0 0 0 0 0 1 0 1 0 3 0 0 0 1 0 0 0 0 0 0 0 0 1 1 0 0 0 0 0 0 0 0 1 3 1 1 1 0 1 0 0 0 2 1 0 0 1 0 0 0 0 0 0 0 0</counts>
			</dataPoints>
		</scan>
		<scan status="Completed" appendNumber="0" scanAxis="2Theta" mode="Continuous">
			<header>
				<startTimeStamp>2024-09-13T15:19:20-04:00</startTimeStamp>
				<endTimeStamp>2024-09-13T15:49:19-04:00</endTimeStamp>
				<author>
					<name>lw627</name>
				</author>
				<source>
					<applicationSoftware version="7.1">Data Collector</applicationSoftware>
					<instrumentControlSoftware version="8.2  20201204">EMPYREAN</instrumentControlSoftware>
					<instrumentID>0000000011260721</instrumentID>
				</source>
			</header>
			<dataPoints>
				<positions axis="2Theta" unit="deg">
					<startPosition>71.6042100957499</startPosition>
					<endPosition>74.9514798669664</endPosition>
				</positions>
				<positions axis="Omega" unit="deg">
					<commonPosition>17.9974224906791</commonPosition>
				</positions>
				<positions axis="Phi" unit="deg">
					<commonPosition>-183.77</commonPosition>
				</positions>
				<positions axis="Chi" unit="deg">
					<commonPosition>0</commonPosition>
				</positions>
				<positions axis="Z" unit="mm">
					<commonPosition>8.327</commonPosition>
				</positions>
				<commonCountingTime unit="seconds">0.974</commonCountingTime>
				<counts unit="counts">0 1 0 0 0 0 0 0 0 0 0 0 0 0 0 1 0 1 1 0 0 0 0 0 0 0 0 0 1 0 0 0 0 0 0 0 0 0 0 0 1 0 0 1 0 1 0 0 0 0 0 1 0 0 1 0 1 0 1 1 0 0 0 0 0 1 0 0 0 0 1 0 1 1 0 1 0 2 0 0 0 0 0 0 0 0 2 0 1 0 0 0 0 0 0 0 0 0 1 1 1 0 1 0 1 0 1 0 2 0 0 0 2 0 0 0 0 0 0 1 1 1 2 0 1 0 0 0 2 1 0 0 0 1 0 0 0 0 0 0 1 0 1 0 1 0 0 1 1 0 1 0 0 0 2 0 0 0 1 0 1 0 0 1 0 1 1 0 0 1 0 0 0 0 1 0 0 0 0 0 0 0 0 0 1 0 0 0 0 0 0 1 1 0 1 0 0 0 0 0 0 1 0 0 0 0 0 1 0 1 0 0 0 0 0 0 0 1 0 0 0 0 0 0 0 0 0 0 0 0 2 0 0 1 1 0 1 0 0 0 0 1 0 0 0 0 0 0 0 0 0 1 0 1 0</counts>
			</dataPoints>
		</scan>
		<scan status="Completed" appendNumber="0" scanAxis="2Theta" mode="Continuous">
			<header>
				<startTimeStamp>2024-09-13T15:19:20-04:00</startTimeStamp>
				<endTimeStamp>2024-09-13T15:49:19-04:00</endTimeStamp>
				<author>
					<name>lw627</name>
				</author>
				<source>
					<applicationSoftware version="7.1">Data Collector</applicationSoftware>
					<instrumentControlSoftware version="8.2  20201204">EMPYREAN</instrumentControlSoftware>
					<instrumentID>0000000011260721</instrumentID>
				</source>
			</header>
			<dataPoints>
				<positions axis="2Theta" unit="deg">
					<startPosition>71.607492666418</startPosition>
					<endPosition>74.9547624376345</endPosition>
				</positions>
				<positions axis="Omega" unit="deg">
					<commonPosition>17.9990637760131</commonPosition>
				</positions>
				<positions axis="Phi" unit="deg">
					<commonPosition>-183.77</commonPosition>
				</positions>
				<positions axis="Chi" unit="deg">
					<commonPosition>0</commonPosition>
				</positions>
				<positions axis="Z" unit="mm">
					<commonPosition>8.327</commonPosition>
				</positions>
				<commonCountingTime unit="seconds">0.974</commonCountingTime>
				<counts unit="counts">0 1 0 2 0 1 0 2 1 0 0 0 0 0 0 0 1 0 0 0 0 0 0 1 0 0 0 1 0 0 1 0 1 0 0 0 0 0 0 0 1 1 0 0 0 0 0 0 0 0 0 0 1 0 0 1 0 1 0 1 0 0 0 0 0 0 0 0 0 0 0 1 1 0 1 1 0 0 0 0 1 1 0 1 1 1 0 0 1 0 0 0 0 0 1 1 0 1 1 0 0 0 0 0 0 0 0 0 0 0 1 1 0 0 0 0 0 0 0 0 0 0 0 0 0 0 0 0 1 1 0 0 0 0 0 0 0 1 1 0 0 1 1 1 1 0 1 1 0 0 0 0 0 0 0 0 0 0 0 0 0 1 0 0 0 0 0 0 0 0 0 0 1 0 1 1 1 1 1 0 2 0 1 0 1 0 0 0 1 0 0 0 0 1 0 1 0 0 0 1 1 0 1 1 0 0 0 0 1 1 0 0 0 1 0 0 0 0 0 1 1 0 0 0 0 0 0 1 0 0 0 1 0 0 0 0 0 0 0 0 0 0 1 0 0 0 0 0 0 1 0 0 2 0 1</counts>
			</dataPoints>
		</scan>
		<scan status="Completed" appendNumber="0" scanAxis="2Theta" mode="Continuous">
			<header>
				<startTimeStamp>2024-09-13T15:19:20-04:00</startTimeStamp>
				<endTimeStamp>2024-09-13T15:49:19-04:00</endTimeStamp>
				<author>
					<name>lw627</name>
				</author>
				<source>
					<applicationSoftware version="7.1">Data Collector</applicationSoftware>
					<instrumentControlSoftware version="8.2  20201204">EMPYREAN</instrumentControlSoftware>
					<instrumentID>0000000011260721</instrumentID>
				</source>
			</header>
			<dataPoints>
				<positions axis="2Theta" unit="deg">
					<startPosition>71.6107752370862</startPosition>
					<endPosition>74.9580450083026</endPosition>
				</positions>
				<positions axis="Omega" unit="deg">
					<commonPosition>18.0007050613472</commonPosition>
				</positions>
				<positions axis="Phi" unit="deg">
					<commonPosition>-183.77</commonPosition>
				</positions>
				<positions axis="Chi" unit="deg">
					<commonPosition>0</commonPosition>
				</positions>
				<positions axis="Z" unit="mm">
					<commonPosition>8.327</commonPosition>
				</positions>
				<commonCountingTime unit="seconds">0.974</commonCountingTime>
				<counts unit="counts">1 0 0 1 1 0 0 0 1 1 0 0 1 0 1 0 2 0 0 0 1 1 0 0 0 0 0 0 0 2 1 0 1 2 1 0 0 0 0 1 1 0 0 0 1 0 0 0 0 0 0 0 0 1 0 0 1 0 0 0 0 2 0 0 0 0 0 0 1 2 0 1 0 1 0 0 0 0 1 0 0 0 0 0 0 0 1 0 2 0 1 1 1 0 0 0 0 0 0 0 1 0 0 0 0 0 0 0 1 0 0 1 0 0 0 0 1 0 0 1 0 0 0 1 1 0 1 0 0 1 0 1 0 0 1 0 0 1 1 1 4 0 0 0 0 0 0 0 0 0 0 0 0 0 0 0 1 0 1 0 0 0 1 0 0 0 1 0 0 0 0 0 0 0 0 0 0 0 0 0 0 1 1 0 0 1 1 0 0 1 0 1 0 0 0 1 1 0 1 0 0 2 1 0 1 1 0 0 0 1 0 0 0 0 1 0 0 0 0 0 0 0 0 0 0 0 0 1 0 0 0 0 0 1 0 0 1 0 0 1 1 0 0 1 0 0 0 0 0 0 0 0 4 0 0</counts>
			</dataPoints>
		</scan>
		<scan status="Completed" appendNumber="0" scanAxis="2Theta" mode="Continuous">
			<header>
				<startTimeStamp>2024-09-13T15:19:20-04:00</startTimeStamp>
				<endTimeStamp>2024-09-13T15:49:19-04:00</endTimeStamp>
				<author>
					<name>lw627</name>
				</author>
				<source>
					<applicationSoftware version="7.1">Data Collector</applicationSoftware>
					<instrumentControlSoftware version="8.2  20201204">EMPYREAN</instrumentControlSoftware>
					<instrumentID>0000000011260721</instrumentID>
				</source>
			</header>
			<dataPoints>
				<positions axis="2Theta" unit="deg">
					<startPosition>71.6140578077543</startPosition>
					<endPosition>74.9613275789708</endPosition>
				</positions>
				<positions axis="Omega" unit="deg">
					<commonPosition>18.0023463466813</commonPosition>
				</positions>
				<positions axis="Phi" unit="deg">
					<commonPosition>-183.77</commonPosition>
				</positions>
				<positions axis="Chi" unit="deg">
					<commonPosition>0</commonPosition>
				</positions>
				<positions axis="Z" unit="mm">
					<commonPosition>8.327</commonPosition>
				</positions>
				<commonCountingTime unit="seconds">0.974</commonCountingTime>
[...]
				</positions>
				<positions axis="Z" unit="mm">
					<commonPosition>8.327</commonPosition>
				</positions>
				<commonCountingTime unit="seconds">0.974</commonCountingTime>
				<counts unit="counts">1 1 1 0 0 1 1 0 0 1 0 1 0 1 0 0 0 0 0 0 0 1 0 0 0 0 0 0 0 0 2 0 1 0 0 0 0 0 0 1 0 1 0 0 1 0 0 0 0 1 0 0 0 1 0 0 0 0 1 2 0 0 0 0 1 1 0 0 0 0 0 0 1 0 0 1 1 0 0 0 0 0 0 0 0 0 1 1 0 0 0 2 1 0 1 0 0 0 0 0 0 0 1 0 0 0 0 0 0 0 0 1 0 0 0 0 0 0 0 0 0 0 0 0 0 0 0 1 0 0 0 0 0 0 0 0 1 0 0 0 0 0 1 1 1 1 0 1 0 0 0 0 0 1 0 0 2 1 0 0 0 0 1 1 0 0 1 0 0 1 0 0 0 0 1 0 0 0 0 2 0 0 0 0 0 1 1 0 0 0 0 0 0 0 0 0 0 1 0 0 0 0 0 0 1 0 1 0 0 0 0 0 1 0 2 2 0 0 0 0 0 0 0 0 0 0 0 0 0 1 0 0 1 0 1 2 0 0 0 1 0 0 0 0 0 0 1 0 0 0 1 1 1 0 0</counts>
			</dataPoints>
		</scan>
		<scan status="Completed" appendNumber="0" scanAxis="2Theta" mode="Continuous">
			<header>
				<startTimeStamp>2024-09-13T15:19:20-04:00</startTimeStamp>
				<endTimeStamp>2024-09-13T15:49:19-04:00</endTimeStamp>
				<author>
					<name>lw627</name>
				</author>
				<source>
					<applicationSoftware version="7.1">Data Collector</applicationSoftware>
					<instrumentControlSoftware version="8.2  20201204">EMPYREAN</instrumentControlSoftware>
					<instrumentID>0000000011260721</instrumentID>
				</source>
			</header>
			<dataPoints>
				<positions axis="2Theta" unit="deg">
					<startPosition>77.5095547277105</startPosition>
					<endPosition>80.856824498927</endPosition>
				</positions>
				<positions axis="Omega" unit="deg">
					<commonPosition>20.9500948066594</commonPosition>
				</positions>
				<positions axis="Phi" unit="deg">
					<commonPosition>-183.77</commonPosition>
				</positions>
				<positions axis="Chi" unit="deg">
					<commonPosition>0</commonPosition>
				</positions>
				<positions axis="Z" unit="mm">
					<commonPosition>8.327</commonPosition>
				</positions>
				<commonCountingTime unit="seconds">0.974</commonCountingTime>
				<counts unit="counts">0 0 1 0 0 1 3 1 0 1 1 0 0 0 0 0 2 0 0 0 0 1 0 0 1 1 0 1 1 1 0 0 0 1 0 0 0 0 1 1 0 1 0 0 0 1 0 1 0 0 0 0 1 1 0 1 1 0 1 1 1 0 1 0 0 0 1 1 0 1 0 0 0 0 0 2 2 0 1 0 0 0 0 0 0 0 0 1 0 1 0 0 0 2 2 0 0 0 0 1 1 1 0 0 0 0 2 0 1 0 0 0 0 0 0 1 0 0 0 0 0 0 0 0 1 0 0 0 0 1 0 0 0 0 0 0 1 0 0 0 0 0 0 0 0 0 0 0 0 1 0 0 0 0 2 0 0 0 0 0 0 0 0 0 0 0 0 0 0 0 0 0 1 0 0 0 0 0 0 0 1 0 1 0 0 0 1 0 0 2 0 0 0 2 0 0 1 0 0 0 0 0 0 0 0 0 0 1 1 0 0 0 1 1 0 0 1 1 1 0 0 0 0 0 0 1 0 1 1 0 1 0 1 1 1 0 0 0 0 0 0 0 0 1 1 0 0 0 0 0 0 1 0 1 0</counts>
			</dataPoints>
		</scan>
		<scan status="Completed" appendNumber="0" scanAxis="2Theta" mode="Continuous">
			<header>
				<startTimeStamp>2024-09-13T15:19:20-04:00</startTimeStamp>
				<endTimeStamp>2024-09-13T15:49:19-04:00</endTimeStamp>
				<author>
					<name>lw627</name>
				</author>
				<source>
					<applicationSoftware version="7.1">Data Collector</applicationSoftware>
					<instrumentControlSoftware version="8.2  20201204">EMPYREAN</instrumentControlSoftware>
					<instrumentID>0000000011260721</instrumentID>
				</source>
			</header>
			<dataPoints>
				<positions axis="2Theta" unit="deg">
					<startPosition>77.5128372983786</startPosition>
					<endPosition>80.8601070695951</endPosition>
				</positions>
				<positions axis="Omega" unit="deg">
					<commonPosition>20.9517360919934</commonPosition>
				</positions>
				<positions axis="Phi" unit="deg">
					<commonPosition>-183.77</commonPosition>
				</positions>
				<positions axis="Chi" unit="deg">
					<commonPosition>0</commonPosition>
				</positions>
				<positions axis="Z" unit="mm">
					<commonPosition>8.327</commonPosition>
				</positions>
				<commonCountingTime unit="seconds">0.974</commonCountingTime>
				<counts unit="counts">0 0 1 1 2 0 0 0 1 0 0 0 0 0 0 0 0 0 0 0 0 1 1 1 4 0 0 0 1 1 0 0 0 0 1 0 0 0 0 1 1 0 0 0 0 1 0 0 2 0 0 0 1 0 0 0 0 0 0 0 1 0 0 0 0 2 0 0 0 0 1 0 0 0 0 0 0 0 0 0 0 0 1 0 0 0 0 1 2 1 0 0 0 1 0 1 0 1 0 0 2 1 0 0 0 0 0 0 0 0 1 0 0 2 0 3 0 0 0 0 0 1 0 0 0 0 1 0 0 2 0 0 0 0 0 0 0 2 0 1 0 0 0 0 2 0 0 0 0 0 1 0 0 0 0 0 0 0 0 0 0 0 0 0 0 0 0 0 1 1 0 0 0 0 0 0 0 0 0 0 0 0 0 1 0 1 0 0 0 1 0 1 0 0 0 0 1 0 0 1 0 0 0 0 0 0 0 0 0 0 0 0 0 0 0 0 0 1 0 1 0 1 0 0 0 0 1 0 0 0 0 0 0 0 0 0 3 1 0 1 0 1 1 0 1 0 0 0 0 0 0 1 0 3 3</counts>
			</dataPoints>
		</scan>
		<scan status="Completed" appendNumber="0" scanAxis="2Theta" mode="Continuous">
			<header>
				<startTimeStamp>2024-09-13T15:19:20-04:00</startTimeStamp>
				<endTimeStamp>2024-09-13T15:49:19-04:00</endTimeStamp>
				<author>
					<name>lw627</name>
				</author>
				<source>
					<applicationSoftware version="7.1">Data Collector</applicationSoftware>
					<instrumentControlSoftware version="8.2  20201204">EMPYREAN</instrumentControlSoftware>
					<instrumentID>0000000011260721</instrumentID>
				</source>
			</header>
			<dataPoints>
				<positions axis="2Theta" unit="deg">
					<startPosition>77.5161198690467</startPosition>
					<endPosition>80.8633896402632</endPosition>
				</positions>
				<positions axis="Omega" unit="deg">
					<commonPosition>20.9533773773275</commonPosition>
				</positions>
				<positions axis="Phi" unit="deg">
					<commonPosition>-183.77</commonPosition>
				</positions>
				<positions axis="Chi" unit="deg">
					<commonPosition>0</commonPosition>
				</positions>
				<positions axis="Z" unit="mm">
					<commonPosition>8.327</commonPosition>
				</positions>
				<commonCountingTime unit="seconds">0.974</commonCountingTime>
				<counts unit="counts">0 0 0 0 1 0 0 1 1 1 1 0 0 0 1 0 0 0 1 0 0 0 0 1 1 1 1 1 0 1 0 1 0 0 0 0 0 0 0 0 0 0 0 0 0 1 0 2 0 0 0 1 0 0 0 0 0 0 0 1 0 0 1 0 1 0 0 0 1 0 0 0 0 0 1 0 0 0 0 0 0 1 0 0 1 0 0 0 1 0 1 0 0 0 0 0 0 0 0 0 0 0 0 0 0 0 0 0 0 0 0 0 0 1 0 0 0 0 0 2 0 0 0 0 0 1 1 0 1 1 0 1 0 1 1 0 0 0 0 1 0 0 0 0 0 1 0 0 0 0 0 1 0 0 0 0 1 0 0 0 1 0 0 0 0 0 0 0 0 0 0 1 0 0 0 2 0 0 1 0 0 1 0 1 0 0 0 0 0 0 1 2 0 0 1 0 0 0 0 1 0 0 0 0 0 0 2 0 0 0 0 0 0 0 0 0 0 2 0 0 0 0 0 0 0 0 0 0 0 0 0 0 0 2 0 0 0 1 0 0 0 0 0 0 0 0 0 1 1 0 1 0 1 1 0</counts>
			</dataPoints>
		</scan>
		<scan status="Completed" appendNumber="0" scanAxis="2Theta" mode="Continuous">
			<header>
				<startTimeStamp>2024-09-13T15:19:20-04:00</startTimeStamp>
				<endTimeStamp>2024-09-13T15:49:19-04:00</endTimeStamp>
				<author>
					<name>lw627</name>
				</author>
				<source>
					<applicationSoftware version="7.1">Data Collector</applicationSoftware>
					<instrumentControlSoftware version="8.2  20201204">EMPYREAN</instrumentControlSoftware>
					<instrumentID>0000000011260721</instrumentID>
				</source>
			</header>
			<dataPoints>
				<positions axis="2Theta" unit="deg">
					<startPosition>77.5194024397149</startPosition>
					<endPosition>80.8666722109313</endPosition>
				</positions>
				<positions axis="Omega" unit="deg">
					<commonPosition>20.9550186626616</commonPosition>
				</positions>
				<positions axis="Phi" unit="deg">
					<commonPosition>-183.77</commonPosition>
				</positions>
				<positions axis="Chi" unit="deg">
					<commonPosition>0</commonPosition>
				</positions>
				<positions axis="Z" unit="mm">
					<commonPosition>8.327</commonPosition>
				</positions>
				<commonCountingTime unit="seconds">0.974</commonCountingTime>
				<counts unit="counts">0 0 1 0 0 0 0 0 1 0 0 1 2 0 0 0 0 0 1 0 0 0 1 0 0 0 0 0 0 0 0 1 0 1 1 0 0 0 0 1 1 1 1 0 0 0 0 0 0 1 0 1 1 0 0 0 1 0 3 1 0 2 0 0 1 0 0 1 0 1 1 0 0 1 0 0 0 0 0 0 0 1 0 0 0 1 0 2 0 0 0 0 0 0 0 0 1 0 1 1 0 0 0 0 0 0 0 0 0 0 0 0 0 0 0 2 0 0 0 0 0 0 1 0 0 0 0 0 0 0 0 0 1 0 0 0 0 0 0 0 1 0 0 1 2 0 0 2 0 0 0 1 0 1 0 0 2 0 1 0 0 0 0 1 3 0 1 0 1 0 1 1 0 0 0 0 1 0 1 0 0 0 1 0 0 0 0 0 0 0 0 0 0 0 0 0 0 0 1 0 0 0 1 1 0 0 0 1 0 0 1 0 0 0 0 0 0 0 0 0 1 0 1 0 0 0 0 0 0 0 2 0 0 0 0 0 0 0 0 0 0 0 0 0 0 0 1 0 0 0 1 0 0 0 0</counts>
			</dataPoints>
		</scan>
		<scan status="Completed" appendNumber="0" scanAxis="2Theta" mode="Continuous">
			<header>
				<startTimeStamp>2024-09-13T15:19:20-04:00</startTimeStamp>
				<endTimeStamp>2024-09-13T15:49:19-04:00</endTimeStamp>
				<author>
					<name>lw627</name>
				</author>
				<source>
					<applicationSoftware version="7.1">Data Collector</applicationSoftware>
					<instrumentControlSoftware version="8.2  20201204">EMPYREAN</instrumentControlSoftware>
					<instrumentID>0000000011260721</instrumentID>
				</source>
			</header>
			<dataPoints>
				<positions axis="2Theta" unit="deg">
					<startPosition>77.522685010383</startPosition>
					<endPosition>80.8699547815995</endPosition>
				</positions>
				<positions axis="Omega" unit="deg">
					<commonPosition>20.9566599479956</commonPosition>
				</positions>
				<positions axis="Phi" unit="deg">
					<commonPosition>-183.77</commonPosition>
				</positions>
				<positions axis="Chi" unit="deg">
					<commonPosition>0</commonPosition>
				</positions>
				<positions axis="Z" unit="mm">
					<commonPosition>8.327</commonPosition>
				</positions>
				<commonCountingTime unit="seconds">0.974</commonCountingTime>
				<counts unit="counts">0 0 0 3 0 2 0 0 0 1 0 1 0 0 1 0 1 1 1 0 1 0 0 0 0 1 1 0 0 0 1 0 1 0 0 0 1 0 0 0 1 0 1 1 1 0 0 1 0 0 0 0 0 2 1 0 1 0 0 1 0 0 0 1 2 1 0 1 0 0 0 0 0 0 0 3 0 1 1 0 0 1 0 0 0 0 0 2 1 0 1 1 1 0 1 0 0 0 1 0 0 0 1 0 1 0 0 0 0 0 1 1 1 0 0 2 0 3 0 1 0 0 0 0 1 0 0 0 1 2 0 1 1 1 0 0 0 1 0 0 1 0 1 0 0 0 0 0 0 0 0 1 0 0 0 0 0 0 0 0 0 0 0 0 0 1 0 1 0 0 0 1 1 0 0 1 1 0 0 1 0 2 0 0 0 0 0 0 1 0 1 1 1 0 0 0 0 1 1 1 0 0 0 1 0 0 0 0 1 0 1 0 0 0 0 1 1 0 0 0 0 0 0 1 0 1 0 0 0 0 0 1 0 0 0 0 0 0 0 0 0 1 0 0 0 0 0 0 1 0 0 0 1 0 1</counts>
			</dataPoints>
		</scan>
		<scan status="Completed" appendNumber="0" scanAxis="2Theta" mode="Continuous">
			<header>
				<startTimeStamp>2024-09-13T15:19:20-04:00</startTimeStamp>
				<endTimeStamp>2024-09-13T15:49:19-04:00</endTimeStamp>
				<author>
					<name>lw627</name>
				</author>
				<source>
					<applicationSoftware version="7.1">Data Collector</applicationSoftware>
					<instrumentControlSoftware version="8.2  20201204">EMPYREAN</instrumentControlSoftware>
					<instrumentID>0000000011260721</instrumentID>
				</source>
			</header>
			<dataPoints>
				<positions axis="2Theta" unit="deg">
					<startPosition>77.5259675810511</startPosition>
					<endPosition>80.8732373522676</endPosition>
				</positions>
				<positions axis="Omega" unit="deg">
					<commonPosition>20.9583012333297</commonPosition>
				</positions>
				<positions axis="Phi" unit="deg">
					<commonPosition>-183.77</commonPosition>
				</positions>
				<positions axis="Chi" unit="deg">
					<commonPosition>0</commonPosition>
				</positions>
				<positions axis="Z" unit="mm">
					<commonPosition>8.327</commonPosition>
				</positions>
				<commonCountingTime unit="seconds">0.974</commonCountingTime>
				<counts unit="counts">2 1 0 0 1 2 0 2 0 1 0 0 0 0 0 0 0 0 0 0 0 1 0 0 1 0 0 0 1 0 1 0 0 0 0 0 0 0 0 0 2 0 0 0 0 1 0 0 0 0 2 0 1 0 0 1 0 0 0 1 1 0 1 1 0 0 0 0 0 0 0 0 1 0 1 0 0 2 1 1 1 0 0 1 0 0 1 0 1 0 0 0 0 0 0 0 0 0 0 0 0 0 0 0 0 0 0 0 1 0 0 0 0 0 1 1 0 0 0 0 1 1 2 0 0 0 0 0 0 0 1 0 0 0 0 1 0 1 1 0 0 0 0 0 0 0 0 0 0 0 0 0 0 0 0 2 1 0 0 2 0 0 0 1 0 1 1 0 0 0 0 0 1 1 0 0 0 0 1 0 0 0 0 0 0 0 0 0 1 0 0 0 0 0 0 0 0 0 0 0 0 0 0 0 0 0 0 0 0 0 1 0 0 1 0 0 0 0 0 1 1 0 0 1 0 1 1 0 0 0 0 0 0 0 0 0 1 0 0 0 0 0 0 0 1 0 0 0 0 0 0 0 0 0 0</counts>
			</dataPoints>
		</scan>
		<scan status="Completed" appendNumber="0" scanAxis="2Theta" mode="Continuous">
			<header>
				<startTimeStamp>2024-09-13T15:19:20-04:00</startTimeStamp>
				<endTimeStamp>2024-09-13T15:49:19-04:00</endTimeStamp>
				<author>
					<name>lw627</name>
				</author>
				<source>
					<applicationSoftware version="7.1">Data Collector</applicationSoftware>
					<instrumentControlSoftware version="8.2  20201204">EMPYREAN</instrumentControlSoftware>
					<instrumentID>0000000011260721</instrumentID>
				</source>
			</header>
			<dataPoints>
				<positions axis="2Theta" unit="deg">
					<startPosition>77.5292501517193</startPosition>
					<endPosition>80.8765199229357</endPosition>
				</positions>
				<positions axis="Omega" unit="deg">
					<commonPosition>20.9599425186637</commonPosition>
				</positions>
				<positions axis="Phi" unit="deg">
					<commonPosition>-183.77</commonPosition>
				</positions>
				<positions axis="Chi" unit="deg">
					<commonPosition>0</commonPosition>
				</positions>
				<positions axis="Z" unit="mm">
					<commonPosition>8.327</commonPosition>
				</positions>
				<commonCountingTime unit="seconds">0.974</commonCountingTime>
				<counts unit="counts">0 1 0 0 0 0 1 1 0 0 1 1 0 1 0 0 0 0 1 0 0 0 0 0 0 2 0 1 0 0 0 0 0 0 0 0 0 0 0 1 0 0 0 0 1 0 0 1 2 0 0 0 1 0 0 0 1 1 0 1 1 0 0 0 0 0 1 1 0 1 0 0 2 0 0 1 0 0 0 0 2 1 0 0 0 0 0 0 0 0 0 1 0 0 0 1 0 1 0 0 0 0 1 0 0 1 0 0 0 1 1 1 0 0 0 2 0 0 0 0 0 0 2 0 0 0 0 1 0 1 0 0 0 0 0 0 0 1 0 0 1 0 0 0 1 0 0 0 0 0 0 0 2 1 0 0 1 0 1 0 0 0 0 0 0 0 0 1 0 1 1 0 0 0 0 0 0 0 1 1 0 0 0 1 1 0 0 1 0 1 0 0 0 0 0 0 0 0 0 0 0 1 0 0 0 0 0 0 0 0 1 0 0 1 1 0 1 0 0 0 0 0 1 0 0 0 0 0 1 0 0 1 0 1 0 1 0 1 1 1 0 0 0 0 0 0 0 0 0 0 0 1 0 0 0</counts>
			</dataPoints>
		</scan>
		<scan status="Completed" appendNumber="0" scanAxis="2Theta" mode="Continuous">
			<header>
				<startTimeStamp>2024-09-13T15:19:20-04:00</startTimeStamp>
				<endTimeStamp>2024-09-13T15:49:19-04:00</endTimeStamp>
				<author>
					<name>lw627</name>
				</author>
				<source>
					<applicationSoftware version="7.1">Data Collector</applicationSoftware>
					<instrumentControlSoftware version="8.2  20201204">EMPYREAN</instrumentControlSoftware>
					<instrumentID>0000000011260721</instrumentID>
				</source>
			</header>
			<dataPoints>
				<positions axis="2Theta" unit="deg">
					<startPosition>77.5325327223874</startPosition>
					<endPosition>80.8798024936039</endPosition>
				</positions>
				<positions axis="Omega" unit="deg">
					<commonPosition>20.9615838039978</commonPosition>
				</positions>
				<positions axis="Phi" unit="deg">
					<commonPosition>-183.77</commonPosition>
				</positions>
				<positions axis="Chi" unit="deg">
					<commonPosition>0</commonPosition>
				</positions>
				<positions axis="Z" unit="mm">
					<commonPosition>8.327</commonPosition>
				</positions>
				<commonCountingTime unit="seconds">0.974</commonCountingTime>
				<counts unit="counts">0 2 0 0 0 3 0 0 1 0 0 0 0 0 0 0 0 2 0 0 0 0 1 0 0 1 1 1 0 0 0 0 0 0 1 0 0 1 1 0 0 0 1 0 0 1 0 0 0 1 0 1 0 0 0 0 0 0 1 0 0 0 0 0 0 0 0 0 0 1 1 0 0 0 1 3 0 0 0 0 0 0 0 0 0 0 0 0 0 0 0 0 0 0 0 1 0 0 0 1 0 0 0 1 1 1 0 0 0 0 0 0 0 0 1 0 0 1 0 0 0 0 0 0 0 1 0 0 0 1 1 1 1 0 0 1 0 0 0 0 2 1 0 0 0 0 0 0 0 0 0 0 0 0 0 0 1 0 1 0 0 1 0 1 0 0 0 0 0 1 1 0 0 0 0 1 0 0 0 0 0 2 0 1 1 0 0 0 1 0 0 0 1 2 0 1 1 0 1 0 1 0 0 0 0 0 1 0 0 0 0 0 0 0 0 0 0 0 0 0 0 0 0 0 0 0 0 0 0 0 1 0 0 1 0 0 1 1 0 1 0 0 1 0 0 0 0 0 0 1 0 1 0 0 0</counts>
			</dataPoints>
		</scan>
		<scan status="Completed" appendNumber="0" scanAxis="2Theta" mode="Continuous">
			<header>
				<startTimeStamp>2024-09-13T15:19:20-04:00</startTimeStamp>
				<endTimeStamp>2024-09-13T15:49:19-04:00</endTimeStamp>
				<author>
					<name>lw627</name>
				</author>
				<source>
					<applicationSoftware version="7.1">Data Collector</applicationSoftware>
					<instrumentControlSoftware version="8.2  20201204">EMPYREAN</instrumentControlSoftware>
					<instrumentID>0000000011260721</instrumentID>
				</source>
			</header>
			<dataPoints>
				<positions axis="2Theta" unit="deg">
					<startPosition>77.5358152930555</startPosition>
					<endPosition>80.883085064272</endPosition>
				</positions>
				<positions axis="Omega" unit="deg">
					<commonPosition>20.9632250893319</commonPosition>
				</positions>
				<positions axis="Phi" unit="deg">
					<commonPosition>-183.77</commonPosition>
				</positions>
				<positions axis="Chi" unit="deg">
					<commonPosition>0</commonPosition>
				</positions>
				<positions axis="Z" unit="mm">
					<commonPosition>8.327</commonPosition>
				</positions>
				<commonCountingTime unit="seconds">0.974</commonCountingTime>
				<counts unit="counts">1 0 1 2 0 0 0 0 0 0 1 0 1 0 0 0 0 0 0 0 0 0 0 0 0 0 0 0 1 0 1 1 1 0 1 0 1 1 0 0 1 1 1 0 0 0 0 0 0 0 0 1 0 0 2 0 1 1 0 0 1 2 0 0 1 0 0 0 0 0 0 0 0 0 0 0 0 1 0 0 1 0 1 0 0 0 0 0 0 0 0 0 0 1 0 0 0 0 1 0 0 0 1 0 0 1 0 0 1 0 0 0 0 0 0 0 0 0 0 0 1 0 0 0 0 0 1 0 0 0 0 0 0 0 0 1 0 0 0 0 1 0 0 1 1 0 0 1 1 0 0 0 0 1 0 2 0 0 0 1 1 1 0 0 0 0 0 1 2 1 0 2 0 0 0 0 0 0 0 0 0 0 0 0 0 0 0 0 1 0 0 0 0 0 0 0 0 0 0 0 0 0 2 0 1 1 0 0 0 0 2 0 0 0 0 0 0 0 1 0 0 0 0 0 2 0 1 1 0 0 0 0 0 0 0 0 1 0 0 0 0 1 0 0 0 0 0 0 0 1 0 1 1 0 0</counts>
			</dataPoints>
		</scan>
		<scan status="Completed" appendNumber="0" scanAxis="2Theta" mode="Continuous">
			<header>
				<startTimeStamp>2024-09-13T15:19:20-04:00</startTimeStamp>
				<endTimeStamp>2024-09-13T15:49:19-04:00</endTimeStamp>
				<author>
					<name>lw627</name>
				</author>
				<source>
					<applicationSoftware version="7.1">Data Collector</applicationSoftware>
					<instrumentControlSoftware version="8.2  20201204">EMPYREAN</instrumentControlSoftware>
					<instrumentID>0000000011260721</instrumentID>
				</source>
			</header>
			<dataPoints>
				<positions axis="2Theta" unit="deg">
					<startPosition>77.5390978637236</startPosition>
					<endPosition>80.8863676349401</endPosition>
				</positions>
				<positions axis="Omega" unit="deg">
					<commonPosition>20.9648663746659</commonPosition>
				</positions>
				<positions axis="Phi" unit="deg">
					<commonPosition>-183.77</commonPosition>
				</positions>
				<positions axis="Chi" unit="deg">
					<commonPosition>0</commonPosition>
				</positions>
				<positions axis="Z" unit="mm">
					<commonPosition>8.327</commonPosition>
				</positions>
				<commonCountingTime unit="seconds">0.974</commonCountingTime>
				<counts unit="counts">0 0 1 0 0 1 0 1 1 0 0 0 0 0 0 0 2 2 1 0 0 1 1 0 0 0 0 0 1 1 0 0 0 0 0 0 1 0 0 2 0 0 0 0 0 0 0 1 0 0 0 0 1 0 0 0 0 0 1 1 1 1 0 0 0 0 0 0 0 1 0 0 0 0 0 1 1 1 0 0 0 1 1 0 0 0 0 0 0 0 0 0 1 1 0 1 2 0 0 0 0 2 1 0 0 0 1 1 0 0 0 1 1 0 0 0 0 0 0 0 0 0 0 0 0 1 0 0 1 0 1 1 0 0 0 1 0 1 1 0 0 0 0 0 0 0 0 0 0 0 0 0 0 0 1 0 0 0 1 1 1 0 0 0 0 0 0 0 0 0 1 1 1 0 0 0 2 0 0 1 0 0 0 0 0 0 0 0 0 0 0 0 0 3 0 1 0 0 1 2 0 0 0 0 0 2 0 0 0 0 0 0 0 0 1 1 1 0 0 0 0 1 2 0 0 0 0 0 0 1 0 0 1 0 0 0 0 0 0 0 0 0 0 0 0 0 0 0 1 0 0 0 0 0 0</counts>
			</dataPoints>
		</scan>
		<scan status="Completed" appendNumber="0" scanAxis="2Theta" mode="Continuous">
			<header>
				<startTimeStamp>2024-09-13T15:19:20-04:00</startTimeStamp>
				<endTimeStamp>2024-09-13T15:49:19-04:00</endTimeStamp>
				<author>
					<name>lw627</name>
				</author>
				<source>
					<applicationSoftware version="7.1">Data Collector</applicationSoftware>
					<instrumentControlSoftware version="8.2  20201204">EMPYREAN</instrumentControlSoftware>
					<instrumentID>0000000011260721</instrumentID>
				</source>
			</header>
			<dataPoints>
				<positions axis="2Theta" unit="deg">
					<startPosition>77.5423804343918</startPosition>
					<endPosition>80.8896502056082</endPosition>
				</positions>
				<positions axis="Omega" unit="deg">
					<commonPosition>20.96650766</commonPosition>
				</positions>
				<positions axis="Phi" unit="deg">
					<commonPosition>-183.77</commonPosition>
				</positions>
				<positions axis="Chi" unit="deg">
					<commonPosition>0</commonPosition>
				</positions>
				<positions axis="Z" unit="mm">
					<commonPosition>8.327</commonPosition>
				</positions>
				<commonCountingTime unit="seconds">0.974</commonCountingTime>
				<counts unit="counts">1 0 0 0 0 0 0 1 1 0 0 1 0 0 0 1 0 0 0 0 0 1 0 0 1 1 0 0 0 0 1 1 1 0 0 0 0 0 0 0 0 0 2 0 1 0 1 0 1 0 0 0 0 0 1 0 2 1 1 0 1 0 1 1 0 0 0 0 0 1 1 0 0 1 0 0 0 0 0 0 0 0 1 0 0 0 0 0 0 0 1 1 0 0 0 0 1 2 0 0 0 0 0 0 0 0 0 0 2 0 0 0 0 0 0 0 0 1 0 1 0 1 1 1 1 0 0 1 0 0 1 0 0 0 0 0 0 0 0 0 0 1 0 0 0 0 1 0 0 1 1 0 0 0 0 0 0 0 0 2 0 0 1 0 0 0 0 0 0 1 1 0 0 0 0 2 0 0 0 0 0 0 0 0 1 0 0 0 0 0 0 0 0 0 0 0 0 0 0 0 1 0 1 0 0 0 0 0 0 0 1 0 0 0 0 0 1 0 0 0 0 0 1 0 0 0 0 0 0 0 1 0 0 0 0 0 0 0 1 0 1 0 1 0 0 0 0 0 0 0 0 0 1 0 1</counts>
			</dataPoints>
		</scan>
	</xrdMeasurement>
</xrdMeasurements>