File: data/XRD_RSM/YG065/YG065_RSM-103_phi-360.xrdml
<?xml version="1.0" encoding="utf-8"?>
<xrdMeasurements xmlns="http://www.xrdml.com/XRDMeasurement/2.2" xmlns:xsi="http://www.w3.org/2001/XMLSchema-instance" xsi:schemaLocation="http://www.xrdml.com/XRDMeasurement/2.2 http://www.xrdml.com/XRDMeasurement/2.2/XRDMeasurement.xsd" status="Completed">
	<comment>
		<entry>Configuration=3-axes Cradle_Reflection, Owner=lw627, Creation date=9/2/2021 3:55:24 PM</entry>
		<entry>Goniometer=Theta/Theta; Minimum step size 2Theta:0.0001; Minimum step size Omega:0.0001</entry>
		<entry>Sample stage=Chi-Phi-z stage 240 mm (reflection); Minimum step size Phi:0.01; Minimum step size Chi:0.01; Minimum step size Z:0.001</entry>
		<entry>Diffractometer system=EMPYREAN</entry>
		<entry>Measurement program=C:\PANalytical\Data Collector\Programs\Liyan Wu\Film programs\RSM slow 3 degree.xrdmp, Identifier={0351664C-55A7-43E7-B72A-7307F4B26703}</entry>
	</comment>
	<sample type="To be analyzed">
		<id/>
		<name/>
		<preparedBy/>
	</sample>
	<xrdMeasurement status="Completed" measurementType="Area measurement" measurementStepAxis="Omega-2Theta" sampleMode="Reflection">
		<comment>
			<entry>PHD Lower Level = 4.02 (keV), PHD Upper Level = 11.27 (keV)</entry>
		</comment>
		<usedWavelength intended="K-Alpha 1">
			<kAlpha1 unit="Angstrom">1.5405980</kAlpha1>
			<kAlpha2 unit="Angstrom">1.5444260</kAlpha2>
			<kBeta unit="Angstrom">1.3922500</kBeta>
			<ratioKAlpha2KAlpha1>0</ratioKAlpha2KAlpha1>
		</usedWavelength>
		<incidentBeamPath>
			<radius unit="mm">240.00</radius>
			<xRayTube id="1010048" name="Empyrean Cu LFF HR (9430 033 7310x) DK432574">
				<tension unit="kV">45.0</tension>
				<current unit="mA">40.0</current>
				<anodeMaterial>Cu</anodeMaterial>
				<focus type="Line">
					<length unit="mm">12.0</length>
					<width unit="mm">0.4</width>
					<takeOffAngle unit="deg">4.4</takeOffAngle>
				</focus>
			</xRayTube>
			<xRayMirror xsi:type="xRayMirrorType" id="27080001" name="Inc. Beam Cu W/Si (hybrid MPD)" hybrid="true">
				<crystal type="Graded" shape="Parabolic">W/Si</crystal>
				<acceptanceAngle unit="deg">0.800</acceptanceAngle>
				<length unit="mm">55.3</length>
			</xRayMirror>
			<monochromator xsi:type="monochromatorType" id="23090002" name="Hybrid monochr. 2xGe220 Cu asym." hybrid="true">
				<crystal type="Asymmetric" shape="Flat">Ge</crystal>
				<numberOfReflections>2</numberOfReflections>
				<hkl>
					<h>2</h>
					<k>2</k>
					<l>0</l>
				</hkl>
			</monochromator>
			<divergenceSlit xsi:type="fixedDivergenceSlitType" id="22010005" name="Fixed slit 1/4°">
				<distanceToSample unit="mm">179.30</distanceToSample>
				<height unit="mm">0.38</height>
			</divergenceSlit>
		</incidentBeamPath>
		<sampleOffset>
			<position axis="Omega" unit="deg">1.6961</position>
			<position axis="Chi" unit="deg">-0.23</position>
		</sampleOffset>
		<diffractedBeamPath>
			<radius unit="mm">240.00</radius>
			<antiScatterSlit xsi:type="fixedAntiScatterSlitType" id="22060009" name="Programmable anti-scatter slit">
				<angle unit="deg">4</angle>
			</antiScatterSlit>
			<detector xsi:type="areaDetectorType" id="7010020" name="PIXcel3D-Medipix3 1x1 detector">
				<phd unit="%">
					<lowerLevel>25</lowerLevel>
					<upperLevel>70</upperLevel>
				</phd>
				<mode>Scanning snapshot equatorial</mode>
				<activeChannelsEquatorial>255</activeChannelsEquatorial>
				<activeChannelsAxial>255</activeChannelsAxial>
				<pitchEquatorial unit="mm">0.05500</pitchEquatorial>
				<pitchAxial unit="mm">0.05500</pitchAxial>
				<readOutPeriod unit="seconds">0.980</readOutPeriod>
			</detector>
		</diffractedBeamPath>
		<scan status="Completed" appendNumber="0" scanAxis="2Theta" mode="Continuous">
			<header>
				<startTimeStamp>2024-09-11T18:03:22-04:00</startTimeStamp>
				<endTimeStamp>2024-09-11T18:33:21-04:00</endTimeStamp>
				<author>
					<name>lw627</name>
				</author>
				<source>
					<applicationSoftware version="7.1">Data Collector</applicationSoftware>
					<instrumentControlSoftware version="8.2  20201204">EMPYREAN</instrumentControlSoftware>
					<instrumentID>0000000011260721</instrumentID>
				</source>
			</header>
			<dataPoints>
				<positions axis="2Theta" unit="deg">
					<startPosition>71.5664063943918</startPosition>
					<endPosition>74.9136761656082</endPosition>
				</positions>
				<positions axis="Omega" unit="deg">
					<commonPosition>18.19242064</commonPosition>
				</positions>
				<positions axis="Phi" unit="deg">
					<commonPosition>0.05</commonPosition>
				</positions>
				<positions axis="Chi" unit="deg">
					<commonPosition>-0.15</commonPosition>
				</positions>
				<positions axis="Z" unit="mm">
					<commonPosition>8.355</commonPosition>
				</positions>
				<commonCountingTime unit="seconds">0.974</commonCountingTime>
				<counts unit="counts">0 0 0 0 0 1 1 0 0 0 0 0 0 0 1 0 1 1 2 2 0 0 0 1 0 0 0 0 0 0 0 0 1 1 0 1 2 0 0 0 0 0 0 0 1 0 1 0 0 0 0 0 0 1 0 0 0 0 0 1 0 0 0 1 1 0 0 0 0 0 0 0 1 1 0 2 1 0 0 1 0 0 0 0 0 0 0 0 0 0 0 1 0 0 0 0 0 0 0 1 0 0 1 0 1 0 0 0 0 0 0 0 0 0 0 0 0 0 0 0 0 1 0 0 1 0 0 1 0 0 0 0 0 1 1 1 0 0 0 0 0 0 0 0 0 1 0 0 0 0 0 0 0 1 0 0 0 0 1 0 0 0 1 0 1 0 0 0 0 0 0 0 0 1 0 0 0 0 0 1 0 0 0 1 0 0 0 0 0 2 0 0 1 1 0 0 0 0 0 0 0 0 1 1 0 1 0 0 0 1 0 2 0 0 0 0 0 0 1 0 0 0 1 0 1 0 0 0 0 0 0 0 0 0 1 0 0 0 0 0 0 0 1 1 0 0 0 0 2 0 0 0 0 0 1</counts>
			</dataPoints>
		</scan>
		<scan status="Completed" appendNumber="0" scanAxis="2Theta" mode="Continuous">
			<header>
				<startTimeStamp>2024-09-11T18:03:22-04:00</startTimeStamp>
				<endTimeStamp>2024-09-11T18:33:21-04:00</endTimeStamp>
				<author>
					<name>lw627</name>
				</author>
				<source>
					<applicationSoftware version="7.1">Data Collector</applicationSoftware>
					<instrumentControlSoftware version="8.2  20201204">EMPYREAN</instrumentControlSoftware>
					<instrumentID>0000000011260721</instrumentID>
				</source>
			</header>
			<dataPoints>
				<positions axis="2Theta" unit="deg">
					<startPosition>71.5696889650599</startPosition>
					<endPosition>74.9169587362764</endPosition>
				</positions>
				<positions axis="Omega" unit="deg">
					<commonPosition>18.1940619253341</commonPosition>
				</positions>
				<positions axis="Phi" unit="deg">
					<commonPosition>0.05</commonPosition>
				</positions>
				<positions axis="Chi" unit="deg">
					<commonPosition>-0.15</commonPosition>
				</positions>
				<positions axis="Z" unit="mm">
					<commonPosition>8.355</commonPosition>
				</positions>
				<commonCountingTime unit="seconds">0.974</commonCountingTime>
				<counts unit="counts">0 2 0 0 0 1 0 0 1 0 0 0 0 0 0 0 0 0 1 0 1 0 1 1 0 1 0 0 1 0 0 0 0 0 0 0 0 0 0 0 0 0 0 0 0 0 0 0 1 0 0 0 0 0 1 0 0 0 0 0 0 0 0 1 0 0 0 0 0 0 0 0 0 0 0 0 0 1 1 1 0 1 1 0 1 0 0 1 0 0 0 0 0 0 0 0 0 0 1 0 0 0 0 0 0 0 0 0 0 0 0 0 0 0 1 0 0 0 0 0 0 0 0 0 0 0 0 0 1 0 0 1 0 0 0 0 0 1 1 0 0 1 2 0 0 1 1 1 0 0 0 0 0 0 1 0 0 0 0 2 0 1 0 0 1 0 0 0 0 0 0 1 0 0 0 1 1 0 0 0 0 0 0 0 0 0 2 1 0 2 0 0 0 0 0 0 0 0 0 0 0 2 1 0 0 0 0 1 0 1 0 0 0 1 0 0 0 1 0 1 0 0 0 0 1 0 0 0 1 0 0 0 0 0 1 0 1 0 0 0 0 1 1 0 0 0 1 0 1 2 0 0 0 0 0</counts>
			</dataPoints>
		</scan>
		<scan status="Completed" appendNumber="0" scanAxis="2Theta" mode="Continuous">
			<header>
				<startTimeStamp>2024-09-11T18:03:22-04:00</startTimeStamp>
				<endTimeStamp>2024-09-11T18:33:21-04:00</endTimeStamp>
				<author>
					<name>lw627</name>
				</author>
				<source>
					<applicationSoftware version="7.1">Data Collector</applicationSoftware>
					<instrumentControlSoftware version="8.2  20201204">EMPYREAN</instrumentControlSoftware>
					<instrumentID>0000000011260721</instrumentID>
				</source>
			</header>
			<dataPoints>
				<positions axis="2Theta" unit="deg">
					<startPosition>71.572971535728</startPosition>
					<endPosition>74.9202413069445</endPosition>
				</positions>
				<positions axis="Omega" unit="deg">
					<commonPosition>18.1957032106681</commonPosition>
				</positions>
				<positions axis="Phi" unit="deg">
					<commonPosition>0.05</commonPosition>
				</positions>
				<positions axis="Chi" unit="deg">
					<commonPosition>-0.15</commonPosition>
				</positions>
				<positions axis="Z" unit="mm">
					<commonPosition>8.355</commonPosition>
				</positions>
				<commonCountingTime unit="seconds">0.974</commonCountingTime>
				<counts unit="counts">0 1 0 0 0 0 0 3 3 2 0 0 0 1 0 0 0 0 0 0 0 0 1 0 1 0 1 1 0 1 0 1 0 0 0 0 1 2 0 0 0 0 0 1 0 1 0 0 1 0 0 0 0 1 0 0 0 1 0 0 2 0 0 0 0 0 0 1 0 0 0 1 0 0 0 1 0 1 0 1 0 1 0 0 0 0 1 0 0 2 2 0 0 0 0 0 0 0 0 0 0 2 1 0 0 0 0 0 0 1 0 1 1 0 0 0 0 0 0 0 1 1 0 0 1 1 0 3 0 0 0 2 0 0 0 0 0 0 0 1 0 0 2 0 0 0 1 1 2 0 0 0 0 0 0 0 0 2 0 0 0 1 0 0 0 0 1 0 0 0 1 0 0 1 0 0 1 0 0 0 0 0 0 0 0 0 0 0 1 1 0 0 0 0 3 0 0 0 1 0 1 0 0 0 0 0 0 0 1 0 0 1 0 0 0 0 0 0 0 0 0 0 0 0 1 0 0 0 0 0 0 1 1 0 0 2 0 1 0 0 0 0 0 0 0 0 0 0 0 0 2 0 1 0 0</counts>
			</dataPoints>
		</scan>
		<scan status="Completed" appendNumber="0" scanAxis="2Theta" mode="Continuous">
			<header>
				<startTimeStamp>2024-09-11T18:03:22-04:00</startTimeStamp>
				<endTimeStamp>2024-09-11T18:33:21-04:00</endTimeStamp>
				<author>
					<name>lw627</name>
				</author>
				<source>
					<applicationSoftware version="7.1">Data Collector</applicationSoftware>
					<instrumentControlSoftware version="8.2  20201204">EMPYREAN</instrumentControlSoftware>
					<instrumentID>0000000011260721</instrumentID>
				</source>
			</header>
			<dataPoints>
				<positions axis="2Theta" unit="deg">
					<startPosition>71.5762541063961</startPosition>
					<endPosition>74.9235238776126</endPosition>
				</positions>
				<positions axis="Omega" unit="deg">
					<commonPosition>18.1973444960022</commonPosition>
				</positions>
				<positions axis="Phi" unit="deg">
					<commonPosition>0.05</commonPosition>
				</positions>
				<positions axis="Chi" unit="deg">
					<commonPosition>-0.15</commonPosition>
				</positions>
				<positions axis="Z" unit="mm">
					<commonPosition>8.355</commonPosition>
				</positions>
				<commonCountingTime unit="seconds">0.974</commonCountingTime>
				<counts unit="counts">1 1 0 0 0 1 0 0 2 0 0 0 0 0 0 2 1 0 0 0 0 0 0 0 0 0 0 0 0 0 0 0 0 1 0 0 0 0 0 0 0 1 0 0 0 1 1 0 0 0 0 1 0 0 0 0 1 0 0 0 0 0 0 0 0 0 0 0 0 1 1 0 0 1 0 0 0 1 1 0 0 1 1 0 1 0 0 0 3 0 0 0 0 0 0 0 0 0 0 0 0 0 0 0 2 2 1 0 0 0 0 0 2 0 0 0 0 0 1 0 0 1 0 0 2 0 0 0 0 0 0 0 1 0 0 0 1 0 0 0 0 1 1 1 1 0 0 0 0 0 2 1 0 0 0 0 1 2 0 0 1 0 0 0 0 1 0 0 0 0 0 1 0 0 1 0 1 0 0 0 0 0 0 0 0 0 0 0 0 1 0 0 0 0 0 1 0 0 0 1 0 0 0 0 0 0 0 0 0 0 0 0 1 0 0 0 0 0 3 0 3 0 0 1 0 1 0 0 1 0 0 0 0 1 0 0 2 0 0 1 0 1 0 0 0 0 0 1 0 0 2 1 2 0 0</counts>
			</dataPoints>
		</scan>
		<scan status="Completed" appendNumber="0" scanAxis="2Theta" mode="Continuous">
			<header>
				<startTimeStamp>2024-09-11T18:03:22-04:00</startTimeStamp>
				<endTimeStamp>2024-09-11T18:33:21-04:00</endTimeStamp>
				<author>
					<name>lw627</name>
				</author>
				<source>
					<applicationSoftware version="7.1">Data Collector</applicationSoftware>
					<instrumentControlSoftware version="8.2  20201204">EMPYREAN</instrumentControlSoftware>
					<instrumentID>0000000011260721</instrumentID>
				</source>
			</header>
			<dataPoints>
				<positions axis="2Theta" unit="deg">
					<startPosition>71.5795366770643</startPosition>
					<endPosition>74.9268064482807</endPosition>
				</positions>
				<positions axis="Omega" unit="deg">
					<commonPosition>18.1989857813363</commonPosition>
				</positions>
				<positions axis="Phi" unit="deg">
					<commonPosition>0.05</commonPosition>
				</positions>
				<positions axis="Chi" unit="deg">
					<commonPosition>-0.15</commonPosition>
				</positions>
				<positions axis="Z" unit="mm">
					<commonPosition>8.355</commonPosition>
				</positions>
				<commonCountingTime unit="seconds">0.974</commonCountingTime>
				<counts unit="counts">0 0 0 0 0 0 0 0 0 1 0 0 0 1 0 1 0 0 0 1 0 0 0 0 0 0 1 0 0 0 0 0 0 0 0 0 0 0 0 1 0 1 0 2 1 1 0 0 1 0 0 0 1 0 0 0 1 1 0 0 0 0 1 0 0 0 0 0 0 0 0 0 0 0 0 0 0 0 1 0 1 0 0 1 0 0 0 1 0 0 0 0 0 0 1 0 0 0 0 0 0 0 2 1 0 0 0 0 1 0 0 0 1 1 0 0 0 0 0 1 0 0 0 0 1 0 0 1 0 0 0 0 0 0 0 0 1 2 0 0 0 2 0 0 0 0 0 0 0 0 0 0 0 2 0 0 1 0 0 1 0 0 0 0 0 0 1 0 1 0 1 1 1 0 0 1 0 1 0 0 0 1 1 1 0 0 0 1 0 1 0 2 0 0 0 0 1 0 0 0 0 0 0 0 0 0 0 0 0 0 1 0 0 1 0 0 0 0 0 0 1 0 0 0 0 0 1 1 0 0 0 0 0 1 0 2 1 0 1 0 1 0 0 1 1 0 0 0 0 0 0 0 0 1 0</counts>
			</dataPoints>
		</scan>
		<scan status="Completed" appendNumber="0" scanAxis="2Theta" mode="Continuous">
			<header>
				<startTimeStamp>2024-09-11T18:03:22-04:00</startTimeStamp>
				<endTimeStamp>2024-09-11T18:33:21-04:00</endTimeStamp>
				<author>
					<name>lw627</name>
				</author>
				<source>
					<applicationSoftware version="7.1">Data Collector</applicationSoftware>
					<instrumentControlSoftware version="8.2  20201204">EMPYREAN</instrumentControlSoftware>
					<instrumentID>0000000011260721</instrumentID>
				</source>
			</header>
			<dataPoints>
				<positions axis="2Theta" unit="deg">
					<startPosition>71.5828192477324</startPosition>
					<endPosition>74.9300890189489</endPosition>
				</positions>
				<positions axis="Omega" unit="deg">
					<commonPosition>18.2006270666703</commonPosition>
				</positions>
				<positions axis="Phi" unit="deg">
					<commonPosition>0.05</commonPosition>
				</positions>
				<positions axis="Chi" unit="deg">
					<commonPosition>-0.15</commonPosition>
				</positions>
				<positions axis="Z" unit="mm">
					<commonPosition>8.355</commonPosition>
				</positions>
				<commonCountingTime unit="seconds">0.974</commonCountingTime>
				<counts unit="counts">0 1 0 0 0 0 0 0 0 0 0 0 0 0 0 0 0 0 0 0 0 1 1 0 1 0 0 1 1 2 0 0 1 0 1 0 1 0 0 1 0 1 0 0 1 0 0 0 0 0 1 0 0 0 0 0 0 0 1 0 1 0 1 0 0 0 0 0 0 0 1 0 2 0 0 0 1 0 0 0 0 2 0 0 0 0 2 0 0 0 0 0 0 1 0 0 0 1 1 0 0 0 1 1 0 0 0 0 0 0 2 0 0 0 0 0 0 0 0 0 1 0 0 0 3 0 0 1 0 1 0 1 0 1 1 1 0 1 0 0 0 1 1 1 0 1 0 0 1 1 0 0 1 0 0 0 0 0 0 1 1 1 0 0 0 1 0 0 0 1 0 0 0 0 1 0 0 0 1 1 1 0 1 0 0 0 0 0 0 0 1 1 0 1 0 1 1 0 1 1 1 1 1 0 1 0 0 1 0 0 0 0 0 0 1 0 0 0 0 1 0 0 0 0 2 1 0 2 1 0 1 0 1 0 0 0 0 0 1 0 0 0 0 0 0 0 1 0 0 0 0 0 0 0 1</counts>
			</dataPoints>
		</scan>
		<scan status="Completed" appendNumber="0" scanAxis="2Theta" mode="Continuous">
			<header>
				<startTimeStamp>2024-09-11T18:03:22-04:00</startTimeStamp>
				<endTimeStamp>2024-09-11T18:33:21-04:00</endTimeStamp>
				<author>
					<name>lw627</name>
				</author>
				<source>
					<applicationSoftware version="7.1">Data Collector</applicationSoftware>
					<instrumentControlSoftware version="8.2  20201204">EMPYREAN</instrumentControlSoftware>
					<instrumentID>0000000011260721</instrumentID>
				</source>
			</header>
			<dataPoints>
				<positions axis="2Theta" unit="deg">
					<startPosition>71.5861018184005</startPosition>
					<endPosition>74.933371589617</endPosition>
				</positions>
				<positions axis="Omega" unit="deg">
					<commonPosition>18.2022683520044</commonPosition>
				</positions>
				<positions axis="Phi" unit="deg">
					<commonPosition>0.05</commonPosition>
				</positions>
				<positions axis="Chi" unit="deg">
					<commonPosition>-0.15</commonPosition>
				</positions>
				<positions axis="Z" unit="mm">
					<commonPosition>8.355</commonPosition>
				</positions>
				<commonCountingTime unit="seconds">0.974</commonCountingTime>
				<counts unit="counts">0 1 0 2 0 0 0 0 0 0 1 0 0 0 1 2 0 0 0 0 0 0 0 0 0 0 0 0 0 0 0 0 2 0 0 0 0 0 1 0 0 0 0 0 0 0 0 0 0 0 0 0 2 0 1 0 0 0 0 0 0 1 0 1 1 0 0 0 0 0 0 0 0 1 0 0 0 0 0 0 0 1 4 0 0 1 0 1 0 0 0 1 0 0 0 0 0 0 1 0 0 0 0 0 0 0 0 0 0 0 0 1 0 0 1 0 0 0 0 0 1 0 0 0 0 0 1 1 0 0 0 0 2 0 0 1 0 1 0 0 0 0 1 1 0 0 0 0 1 0 0 1 1 0 0 0 0 1 2 0 0 0 0 1 0 0 0 0 0 0 1 0 0 0 1 0 1 1 0 0 0 0 0 0 0 2 0 1 0 0 1 1 0 0 2 1 1 0 0 0 0 1 0 0 0 0 1 0 0 1 0 0 2 0 0 0 0 0 2 0 1 0 0 0 0 0 0 1 1 1 0 0 0 0 0 0 0 0 0 0 0 1 2 1 0 0 0 0 0 0 1 0 2 1 0</counts>
			</dataPoints>
		</scan>
		<scan status="Completed" appendNumber="0" scanAxis="2Theta" mode="Continuous">
			<header>
				<startTimeStamp>2024-09-11T18:03:22-04:00</startTimeStamp>
				<endTimeStamp>2024-09-11T18:33:21-04:00</endTimeStamp>
				<author>
					<name>lw627</name>
				</author>
				<source>
					<applicationSoftware version="7.1">Data Collector</applicationSoftware>
					<instrumentControlSoftware version="8.2  20201204">EMPYREAN</instrumentControlSoftware>
					<instrumentID>0000000011260721</instrumentID>
				</source>
			</header>
			<dataPoints>
				<positions axis="2Theta" unit="deg">
					<startPosition>71.5893843890687</startPosition>
					<endPosition>74.9366541602851</endPosition>
				</positions>
				<positions axis="Omega" unit="deg">
					<commonPosition>18.2039096373384</commonPosition>
				</positions>
				<positions axis="Phi" unit="deg">
					<commonPosition>0.05</commonPosition>
				</positions>
				<positions axis="Chi" unit="deg">
					<commonPosition>-0.15</commonPosition>
				</positions>
				<positions axis="Z" unit="mm">
					<commonPosition>8.355</commonPosition>
				</positions>
				<commonCountingTime unit="seconds">0.974</commonCountingTime>
				<counts unit="counts">0 1 1 1 0 0 0 1 0 0 0 0 0 1 0 1 0 0 0 0 1 0 0 0 0 0 0 0 0 0 1 0 0 0 0 0 0 0 0 0 0 0 0 0 1 0 0 0 1 0 0 0 0 0 0 1 0 1 0 0 0 1 2 0 0 0 0 1 1 0 0 0 0 0 0 1 1 0 1 0 0 0 0 0 0 1 0 1 0 0 0 0 0 0 0 1 0 0 0 0 0 0 0 1 0 0 0 0 1 0 0 0 0 0 0 0 0 0 0 1 0 0 0 0 0 1 0 0 0 1 1 0 0 0 0 0 0 0 0 0 0 1 0 0 0 0 0 0 0 0 0 1 0 0 0 0 0 0 0 0 0 0 0 0 0 0 0 0 0 0 0 0 0 0 0 0 0 0 0 0 0 0 0 0 0 0 0 0 2 1 0 0 0 0 0 0 1 0 0 1 0 1 0 0 0 0 0 0 1 0 0 1 0 1 0 0 1 0 1 1 1 0 0 0 0 0 0 0 0 0 0 0 0 0 0 2 0 0 0 0 0 1 1 0 1 0 0 1 0 1 0 0 1 0 2</counts>
			</dataPoints>
		</scan>
		<scan status="Completed" appendNumber="0" scanAxis="2Theta" mode="Continuous">
			<header>
				<startTimeStamp>2024-09-11T18:03:22-04:00</startTimeStamp>
				<endTimeStamp>2024-09-11T18:33:21-04:00</endTimeStamp>
				<author>
					<name>lw627</name>
				</author>
				<source>
					<applicationSoftware version="7.1">Data Collector</applicationSoftware>
					<instrumentControlSoftware version="8.2  20201204">EMPYREAN</instrumentControlSoftware>
					<instrumentID>0000000011260721</instrumentID>
				</source>
			</header>
			<dataPoints>
				<positions axis="2Theta" unit="deg">
					<startPosition>71.5926669597368</startPosition>
					<endPosition>74.9399367309533</endPosition>
				</positions>
				<positions axis="Omega" unit="deg">
					<commonPosition>18.2055509226725</commonPosition>
				</positions>
				<positions axis="Phi" unit="deg">
					<commonPosition>0.05</commonPosition>
				</positions>
				<positions axis="Chi" unit="deg">
					<commonPosition>-0.15</commonPosition>
				</positions>
				<positions axis="Z" unit="mm">
					<commonPosition>8.355</commonPosition>
				</positions>
				<commonCountingTime unit="seconds">0.974</commonCountingTime>
				<counts unit="counts">0 0 0 0 0 1 0 1 0 1 0 0 1 0 0 2 0 0 0 0 0 0 0 0 1 1 1 0 0 0 0 0 0 1 0 0 0 1 0 1 0 0 0 0 0 0 1 0 0 0 0 0 1 1 0 0 1 0 0 0 0 0 0 0 0 0 0 0 0 0 0 1 0 0 0 0 0 0 0 0 0 0 0 0 0 1 0 0 0 2 0 0 0 0 1 1 0 0 0 0 1 0 0 0 1 1 0 0 1 0 0 0 0 0 0 0 0 2 0 0 0 0 0 0 0 0 1 0 1 0 0 0 1 0 0 0 0 1 2 0 0 0 0 0 0 0 0 0 0 0 0 0 0 0 0 0 0 0 2 1 0 0 1 0 1 1 0 1 0 0 1 1 1 0 0 0 0 1 0 0 1 0 1 0 2 0 0 0 0 0 0 0 0 1 0 1 1 0 0 0 0 0 1 0 1 0 0 0 0 0 0 1 0 0 0 0 0 2 1 0 0 0 0 0 0 0 1 0 0 0 0 0 0 0 0 1 1 0 0 0 0 0 1 0 0 0 0 1 0 0 0 0 0 1 1</counts>
			</dataPoints>
		</scan>
		<scan status="Completed" appendNumber="0" scanAxis="2Theta" mode="Continuous">
			<header>
				<startTimeStamp>2024-09-11T18:03:22-04:00</startTimeStamp>
				<endTimeStamp>2024-09-11T18:33:21-04:00</endTimeStamp>
				<author>
					<name>lw627</name>
				</author>
				<source>
					<applicationSoftware version="7.1">Data Collector</applicationSoftware>
					<instrumentControlSoftware version="8.2  20201204">EMPYREAN</instrumentControlSoftware>
					<instrumentID>0000000011260721</instrumentID>
				</source>
			</header>
			<dataPoints>
				<positions axis="2Theta" unit="deg">
					<startPosition>71.5959495304049</startPosition>
					<endPosition>74.9432193016214</endPosition>
				</positions>
				<positions axis="Omega" unit="deg">
					<commonPosition>18.2071922080066</commonPosition>
				</positions>
				<positions axis="Phi" unit="deg">
					<commonPosition>0.05</commonPosition>
				</positions>
				<positions axis="Chi" unit="deg">
					<commonPosition>-0.15</commonPosition>
				</positions>
				<positions axis="Z" unit="mm">
					<commonPosition>8.355</commonPosition>
				</positions>
				<commonCountingTime unit="seconds">0.974</commonCountingTime>
				<counts unit="counts">1 0 0 0 0 2 0 0 0 0 1 0 1 2 0 0 0 0 0 1 0 0 0 0 0 0 0 0 0 1 0 0 1 1 0 1 0 0 0 0 1 0 0 1 0 1 2 0 0 0 1 0 0 1 1 0 0 0 0 0 0 0 0 0 0 1 0 1 0 0 0 0 1 0 0 0 0 1 0 0 0 1 0 0 1 0 0 0 0 0 2 0 1 0 0 0 0 2 0 1 0 1 0 1 0 0 0 0 0 1 1 0 0 0 0 0 1 0 0 0 1 2 1 0 1 3 0 1 1 0 0 1 0 1 0 0 2 1 0 0 0 0 0 0 0 1 0 0 0 1 0 0 0 0 0 0 0 0 0 0 0 1 0 0 0 0 0 1 0 1 1 0 0 1 0 0 0 0 0 0 0 1 0 0 0 2 0 0 0 0 0 0 0 0 0 0 0 0 1 0 2 0 0 0 1 0 0 0 1 0 0 0 0 1 0 1 0 0 0 0 1 0 0 0 0 0 0 0 0 1 0 1 0 0 0 0 0 0 0 1 1 3 0 0 0 1 0 1 1 1 1 0 1 0 1</counts>
			</dataPoints>
		</scan>
		<scan status="Completed" appendNumber="0" scanAxis="2Theta" mode="Continuous">
			<header>
				<startTimeStamp>2024-09-11T18:03:22-04:00</startTimeStamp>
				<endTimeStamp>2024-09-11T18:33:21-04:00</endTimeStamp>
				<author>
					<name>lw627</name>
				</author>
				<source>
					<applicationSoftware version="7.1">Data Collector</applicationSoftware>
					<instrumentControlSoftware version="8.2  20201204">EMPYREAN</instrumentControlSoftware>
					<instrumentID>0000000011260721</instrumentID>
				</source>
			</header>
			<dataPoints>
				<positions axis="2Theta" unit="deg">
					<startPosition>71.599232101073</startPosition>
					<endPosition>74.9465018722895</endPosition>
				</positions>
				<positions axis="Omega" unit="deg">
					<commonPosition>18.2088334933406</commonPosition>
				</positions>
				<positions axis="Phi" unit="deg">
					<commonPosition>0.05</commonPosition>
				</positions>
				<positions axis="Chi" unit="deg">
					<commonPosition>-0.15</commonPosition>
				</positions>
				<positions axis="Z" unit="mm">
					<commonPosition>8.355</commonPosition>
				</positions>
				<commonCountingTime unit="seconds">0.974</commonCountingTime>
				<counts unit="counts">0 0 2 1 0 0 1 0 1 1 0 0 0 0 0 1 0 0 1 0 0 0 0 0 0 0 0 0 0 0 0 0 0 0 1 0 1 1 0 0 2 0 0 0 0 0 0 0 0 2 0 0 0 0 1 2 1 0 0 0 0 1 0 1 0 0 1 0 0 0 0 0 0 0 0 0 0 0 0 0 0 0 0 1 1 1 0 0 0 0 0 0 0 1 0 0 0 1 0 0 0 0 0 0 1 1 0 0 0 0 1 1 0 0 0 0 1 0 1 0 1 0 0 0 0 0 1 2 0 0 0 1 1 0 0 1 0 0 1 0 0 0 1 1 1 0 0 1 0 0 0 1 0 1 0 0 0 0 0 0 0 0 1 0 0 1 0 0 0 0 0 1 0 0 0 1 1 0 0 1 0 0 0 0 0 0 0 0 0 1 1 0 0 0 1 0 1 0 0 0 0 0 1 2 0 1 1 0 1 0 1 0 0 0 0 0 0 0 0 1 1 2 0 0 2 0 0 0 0 1 0 0 0 0 0 0 0 0 0 0 0 0 0 0 0 0 0 0 0 0 0 0 0 0 0</counts>
			</dataPoints>
		</scan>
		<scan status="Completed" appendNumber="0" scanAxis="2Theta" mode="Continuous">
			<header>
				<startTimeStamp>2024-09-11T18:03:22-04:00</startTimeStamp>
				<endTimeStamp>2024-09-11T18:33:21-04:00</endTimeStamp>
				<author>
					<name>lw627</name>
				</author>
				<source>
					<applicationSoftware version="7.1">Data Collector</applicationSoftware>
					<instrumentControlSoftware version="8.2  20201204">EMPYREAN</instrumentControlSoftware>
					<instrumentID>0000000011260721</instrumentID>
				</source>
			</header>
			<dataPoints>
				<positions axis="2Theta" unit="deg">
					<startPosition>71.6025146717412</startPosition>
					<endPosition>74.9497844429576</endPosition>
				</positions>
				<positions axis="Omega" unit="deg">
					<commonPosition>18.2104747786747</commonPosition>
				</positions>
				<positions axis="Phi" unit="deg">
					<commonPosition>0.05</commonPosition>
				</positions>
				<positions axis="Chi" unit="deg">
					<commonPosition>-0.15</commonPosition>
				</positions>
				<positions axis="Z" unit="mm">
					<commonPosition>8.355</commonPosition>
				</positions>
				<commonCountingTime unit="seconds">0.974</commonCountingTime>
				<counts unit="counts">0 1 1 1 1 0 0 0 1 0 0 0 0 2 0 0 2 0 0 1 1 0 0 0 1 0 1 0 1 0 0 0 0 0 0 1 0 1 0 0 1 0 0 2 1 0 0 0 0 0 0 0 0 0 2 1 1 1 0 0 0 0 0 0 1 1 1 0 0 0 0 2 0 0 0 1 1 0 0 0 1 2 0 0 0 0 0 0 1 1 1 0 0 0 1 1 0 1 0 0 2 0 1 1 0 0 1 0 0 1 0 0 0 1 0 0 1 0 0 0 0 0 0 0 1 1 0 0 0 0 0 1 0 0 0 0 0 1 0 0 0 1 1 0 0 1 0 0 0 0 0 0 0 0 0 0 0 0 1 0 0 0 1 0 0 0 0 0 0 0 0 0 0 0 2 0 1 0 0 0 0 0 1 0 1 2 0 1 1 0 0 0 0 0 0 0 0 1 0 0 0 0 0 0 0 0 1 0 0 0 1 0 0 1 0 0 0 2 0 0 0 1 0 0 0 1 0 2 0 0 0 0 0 0 0 1 0 2 0 0 0 0 0 0 1 0 2 0 0 1 1 0 1 0 1</counts>
			</dataPoints>
		</scan>
		<scan status="Completed" appendNumber="0" scanAxis="2Theta" mode="Continuous">
			<header>
				<startTimeStamp>2024-09-11T18:03:22-04:00</startTimeStamp>
				<endTimeStamp>2024-09-11T18:33:21-04:00</endTimeStamp>
				<author>
					<name>lw627</name>
				</author>
				<source>
					<applicationSoftware version="7.1">Data Collector</applicationSoftware>
					<instrumentControlSoftware version="8.2  20201204">EMPYREAN</instrumentControlSoftware>
					<instrumentID>0000000011260721</instrumentID>
				</source>
			</header>
			<dataPoints>
				<positions axis="2Theta" unit="deg">
					<startPosition>71.6057972424093</startPosition>
					<endPosition>74.9530670136258</endPosition>
				</positions>
				<positions axis="Omega" unit="deg">
					<commonPosition>18.2121160640088</commonPosition>
				</positions>
				<positions axis="Phi" unit="deg">
					<commonPosition>0.05</commonPosition>
				</positions>
				<positions axis="Chi" unit="deg">
					<commonPosition>-0.15</commonPosition>
				</positions>
				<positions axis="Z" unit="mm">
					<commonPosition>8.355</commonPosition>
				</positions>
				<commonCountingTime unit="seconds">0.974</commonCountingTime>
				<counts unit="counts">1 0 0 0 0 1 0 0 0 1 0 0 0 0 1 0 0 1 0 0 0 1 2 1 0 1 0 1 0 0 0 0 0 0 0 1 0 0 0 1 0 0 0 0 0 0 0 0 0 0 1 0 0 2 0 0 0 1 0 3 0 0 1 1 0 1 3 0 0 0 0 0 1 0 0 1 1 0 0 0 0 0 0 0 0 0 1 0 2 1 0 0 1 0 0 1 0 0 0 0 0 0 0 0 0 0 0 0 1 3 0 1 0 0 0 0 0 1 0 0 2 0 0 0 0 0 1 0 0 1 0 1 0 2 0 0 1 0 0 0 0 1 1 2 1 1 1 1 0 0 0 0 0 0 0 0 1 0 0 0 0 0 0 0 0 0 0 0 2 0 2 0 0 0 0 0 0 0 1 0 0 0 0 0 0 0 0 0 0 0 0 0 0 0 0 0 1 1 1 1 0 0 0 0 1 0 0 1 0 0 0 1 0 0 0 0 0 1 1 0 0 0 0 0 0 0 0 0 0 0 0 0 0 0 1 0 0 0 0 1 1 0 0 0 0 2 0 1 0 0 0 0 0 0 0</counts>
			</dataPoints>
		</scan>
		<scan status="Completed" appendNumber="0" scanAxis="2Theta" mode="Continuous">
			<header>
				<startTimeStamp>2024-09-11T18:03:22-04:00</startTimeStamp>
				<endTimeStamp>2024-09-11T18:33:21-04:00</endTimeStamp>
				<author>
					<name>lw627</name>
				</author>
				<source>
					<applicationSoftware version="7.1">Data Collector</applicationSoftware>
					<instrumentControlSoftware version="8.2  20201204">EMPYREAN</instrumentControlSoftware>
					<instrumentID>0000000011260721</instrumentID>
				</source>
			</header>
			<dataPoints>
				<positions axis="2Theta" unit="deg">
					<startPosition>71.6090798130774</startPosition>
					<endPosition>74.9563495842939</endPosition>
				</positions>
				<positions axis="Omega" unit="deg">
					<commonPosition>18.2137573493428</commonPosition>
				</positions>
				<positions axis="Phi" unit="deg">
					<commonPosition>0.05</commonPosition>
				</positions>
				<positions axis="Chi" unit="deg">
					<commonPosition>-0.15</commonPosition>
				</positions>
				<positions axis="Z" unit="mm">
					<commonPosition>8.355</commonPosition>
				</positions>
				<commonCountingTime unit="seconds">0.974</commonCountingTime>
				<counts unit="counts">1 0 0 0 0 0 0 0 1 0 0 0 0 0 0 0 0 0 0 1 0 0 0 1 0 0 0 0 1 1 0 1 0 1 0 0 1 0 0 0 0 0 0 1 0 0 0 0 0 1 0 0 1 0 2 0 0 0 0 2 1 0 0 1 0 0 0 0 0 0 0 0 0 0 0 0 1 0 0 0 0 1 0 0 0 0 0 0 1 2 0 0 0 0 1 0 1 2 0 3 1 0 1 1 0 0 1 0 0 0 0 0 1 0 0 2 0 2 0 0 0 0 0 1 0 0 2 0 0 3 0 0 0 0 1 1 0 0 0 1 0 1 0 0 0 0 0 0 1 0 0 0 0 0 0 0 0 0 0 0 0 1 1 1 0 0 0 0 0 0 0 0 0 0 0 0 0 1 0 1 0 0 0 1 0 1 1 0 0 0 1 0 1 0 0 0 0 0 0 1 0 0 0 0 1 0 0 0 0 0 0 0 0 1 0 0 0 0 3 0 0 0 0 0 0 0 0 0 0 0 0 1 0 1 0 0 0 0 0 0 0 1 0 2 0 0 1 1 0 0 0 0 0 0 1</counts>
			</dataPoints>
		</scan>
		<scan status="Completed" appendNumber="0" scanAxis="2Theta" mode="Continuous">
			<header>
				<startTimeStamp>2024-09-11T18:03:22-04:00</startTimeStamp>
				<endTimeStamp>2024-09-11T18:33:21-04:00</endTimeStamp>
				<author>
					<name>lw627</name>
				</author>
				<source>
					<applicationSoftware version="7.1">Data Collector</applicationSoftware>
					<instrumentControlSoftware version="8.2  20201204">EMPYREAN</instrumentControlSoftware>
					<instrumentID>0000000011260721</instrumentID>
				</source>
			</header>
			<dataPoints>
				<positions axis="2Theta" unit="deg">
					<startPosition>71.6123623837455</startPosition>
					<endPosition>74.959632154962</endPosition>
				</positions>
				<positions axis="Omega" unit="deg">
					<commonPosition>18.2153986346769</commonPosition>
				</positions>
				<positions axis="Phi" unit="deg">
					<commonPosition>0.05</commonPosition>
				</positions>
				<positions axis="Chi" unit="deg">
					<commonPosition>-0.15</commonPosition>
				</positions>
				<positions axis="Z" unit="mm">
					<commonPosition>8.355</commonPosition>
				</positions>
				<commonCountingTime unit="seconds">0.974</commonCountingTime>
				<counts unit="counts">2 0 0 0 0 0 0 0 0 0 0 0 0 0 0 0 1 1 0 0 1 1 0 0 0 1 0 1 0 0 0 0 0 0 0 0 0 0 0 0 0 1 0 1 1 0 2 1 0 0 0 0 0 1 0 0 0 0 0 1 0 0 0 1 1 0 0 0 2 1 0 0 0 0 1 0 0 0 0 0 0 0 0 0 1 0 0 0 1 0 0 0 0 1 0 0 0 0 2 0 1 0 1 0 2 0 0 0 0 0 1 0 1 0 0 0 0 0 0 1 0 0 2 0 0 0 0 0 0 0 0 1 0 0 0 0 0 0 1 0 0 1 0 0 1 0 0 0 0 0 0 0 0 0 0 0 1 0 0 0 0 0 0 0 0 1 0 0 0 1 0 0 0 0 1 0 0 0 0 0 0 0 0 2 1 0 1 0 0 0 0 1 0 0 0 0 0 0 0 0 1 1 1 2 1 0 0 0 1 0 1 0 2 1 0 2 1 0 2 0 0 1 0 1 1 0 1 0 0 0 0 0 0 0 0 0 0 0 0 0 0 0 0 0 0 0 0 1 0 0 0 0 1 0 0</counts>
			</dataPoints>
		</scan>
		<scan status="Completed" appendNumber="0" scanAxis="2Theta" mode="Continuous">
			<header>
				<startTimeStamp>2024-09-11T18:03:22-04:00</startTimeStamp>
				<endTimeStamp>2024-09-11T18:33:21-04:00</endTimeStamp>
				<author>
					<name>lw627</name>
				</author>
				<source>
					<applicationSoftware version="7.1">Data Collector</applicationSoftware>
					<instrumentControlSoftware version="8.2  20201204">EMPYREAN</instrumentControlSoftware>
					<instrumentID>0000000011260721</instrumentID>
				</source>
			</header>
			<dataPoints>
				<positions axis="2Theta" unit="deg">
					<startPosition>71.6156449544137</startPosition>
					<endPosition>74.9629147256301</endPosition>
				</positions>
				<positions axis="Omega" unit="deg">
					<commonPosition>18.217039920011</commonPosition>
				</positions>
				<positions axis="Phi" unit="deg">
					<commonPosition>0.05</commonPosition>
				</positions>
				<positions axis="Chi" unit="deg">
					<commonPosition>-0.15</commonPosition>
				</positions>
				<positions axis="Z" unit="mm">
					<commonPosition>8.355</commonPosition>
				</positions>
				<commonCountingTime unit="seconds">0.974</commonCountingTime>
				<counts unit="counts">0 0 0 0 1 0 0 0 0 0 0 0 0 0 0 0 1 0 0 0 0 0 1 1 0 0 0 0 0 0 1 0 0 0 0 0 1 0 0 1 1 0 1 0 0 0 1 0 0 0 0 0 0 2 0 0 0 0 0 0 0 1 0 1 0 1 1 0 0 0 0 2 1 0 0 0 1 0 0 0 1 0 1 0 0 0 1 0 0 1 1 0 0 1 0 0 0 1 0 0 0 0 1 0 0 0 0 0 0 0 0 0 0 1 1 0 0 0 0 0 0 0 0 0 0 0 0 0 0 1 0 0 1 0 1 0 0 1 1 1 1 0 1 0 0 0 1 0 0 1 0 0 0 1 0 0 0 1 0 1 0 0 0 1 1 0 0 0 0 0 0 0 0 0 0 0 0 0 0 1 1 1 0 0 0 1 0 1 0 1 0 0 0 0 0 0 1 0 0 2 0 0 1 1 0 1 1 0 3 2 1 0 2 0 0 0 0 0 0 0 0 0 1 0 0 0 1 0 0 0 0 0 0 1 0 0 0 0 1 0 0 0 0 0 1 1 2 1 1 0 0 1 1 0 0</counts>
			</dataPoints>
		</scan>
		<scan status="Completed" appendNumber="0" scanAxis="2Theta" mode="Continuous">
			<header>
				<startTimeStamp>2024-09-11T18:03:22-04:00</startTimeStamp>
				<endTimeStamp>2024-09-11T18:33:21-04:00</endTimeStamp>
				<author>
					<name>lw627</name>
				</author>
				<source>
					<applicationSoftware version="7.1">Data Collector</applicationSoftware>
					<instrumentControlSoftware version="8.2  20201204">EMPYREAN</instrumentControlSoftware>
					<instrumentID>0000000011260721</instrumentID>
				</source>
			</header>
			<dataPoints>
				<positions axis="2Theta" unit="deg">
					<startPosition>71.6189275250818</startPosition>
					<endPosition>74.9661972962983</endPosition>
				</positions>
				<positions axis="Omega" unit="deg">
					<commonPosition>18.218681205345</commonPosition>
				</positions>
				<positions axis="Phi" unit="deg">
					<commonPosition>0.05</commonPosition>
				</positions>
				<positions axis="Chi" unit="deg">
					<commonPosition>-0.15</commonPosition>
				</positions>
				<positions axis="Z" unit="mm">
					<commonPosition>8.355</commonPosition>
				</positions>
				<commonCountingTime unit="seconds">0.974</commonCountingTime>
				<counts unit="counts">0 0 0 0 0 0 0 0 0 0 1 1 0 0 0 1 0 1 1 0 1 0 0 0 1 0 0 0 0 0 0 0 1 1 0 0 0 0 0 0 0 0 1 1 1 0 0 0 0 0 0 1 1 0 0 1 2 0 0 1 0 0 0 0 0 0 1 1 0 0 0 0 0 0 0 0 0 1 0 0 0 1 0 1 0 1 1 0 0 0 0 0 0 0 0 1 1 0 0 0 0 0 0 0 0 0 0 0 0 0 0 0 0 0 0 0 1 0 0 1 1 0 1 1 1 1 0 0 0 0 1 0 0 1 0 0 0 0 0 0 0 0 0 0 0 0 0 0 0 1 0 0 0 1 0 0 0 0 1 1 0 0 0 1 0 0 0 0 0 0 1 0 0 0 1 0 1 0 0 0 0 2 1 0 0 0 0 0 0 0 1 0 0 0 0 0 0 0 1 1 1 0 1 0 0 0 0 0 1 1 2 0 0 0 0 0 1 0 0 0 0 0 1 0 0 0 0 2 0 0 0 0 0 0 0 0 0 1 1 1 0 0 0 0 0 0 0 1 1 0 0 0 0 0 0</counts>
			</dataPoints>
		</scan>
		<scan status="Completed" appendNumber="0" scanAxis="2Theta" mode="Continuous">
			<header>
				<startTimeStamp>2024-09-11T18:03:22-04:00</startTimeStamp>
				<endTimeStamp>2024-09-11T18:33:21-04:00</endTimeStamp>
				<author>
					<name>lw627</name>
				</author>
				<source>
					<applicationSoftware version="7.1">Data Collector</applicationSoftware>
					<instrumentControlSoftware version="8.2  20201204">EMPYREAN</instrumentControlSoftware>
					<instrumentID>0000000011260721</instrumentID>
				</source>
			</header>
			<dataPoints>
				<positions axis="2Theta" unit="deg">
					<startPosition>71.6222100957499</startPosition>
					<endPosition>74.9694798669664</endPosition>
				</positions>
				<positions axis="Omega" unit="deg">
					<commonPosition>18.2203224906791</commonPosition>
				</positions>
				<positions axis="Phi" unit="deg">
					<commonPosition>0.05</commonPosition>
				</positions>
				<positions axis="Chi" unit="deg">
					<commonPosition>-0.15</commonPosition>
				</positions>
				<positions axis="Z" unit="mm">
					<commonPosition>8.355</commonPosition>
				</positions>
				<commonCountingTime unit="seconds">0.974</commonCountingTime>
				<counts unit="counts">0 0 1 1 1 0 0 0 0 0 0 0 1 0 1 0 0 0 0 0 1 0 0 0 0 0 0 2 0 0 1 0 0 0 1 0 1 0 0 0 0 1 0 0 2 0 0 1 0 0 0 0 0 0 1 0 0 1 0 1 1 1 0 0 1 0 0 0 0 0 0 0 0 1 1 0 0 0 0 0 0 0 0 0 2 0 0 0 1 0 0 0 0 1 0 0 1 0 0 0 2 1 0 0 0 0 3 1 0 0 0 0 0 2 1 1 0 0 0 0 0 0 1 1 1 0 0 0 2 1 1 0 0 0 0 1 0 0 0 0 0 0 2 0 1 1 0 0 0 1 0 0 0 0 1 0 0 0 0 0 0 1 0 0 0 0 1 0 0 0 0 0 2 1 0 1 0 1 0 0 1 1 1 0 0 0 0 0 0 0 0 0 0 0 0 0 0 0 0 2 0 1 0 0 0 0 0 0 0 0 0 0 0 0 0 0 0 0 0 0 0 0 0 1 0 0 0 0 0 0 0 0 0 0 1 0 0 0 0 0 0 0 0 0 0 1 0 0 1 0 1 1 0 0 0</counts>
			</dataPoints>
		</scan>
		<scan status="Completed" appendNumber="0" scanAxis="2Theta" mode="Continuous">
			<header>
				<startTimeStamp>2024-09-11T18:03:22-04:00</startTimeStamp>
				<endTimeStamp>2024-09-11T18:33:21-04:00</endTimeStamp>
				<author>
					<name>lw627</name>
				</author>
				<source>
					<applicationSoftware version="7.1">Data Collector</applicationSoftware>
					<instrumentControlSoftware version="8.2  20201204">EMPYREAN</instrumentControlSoftware>
					<instrumentID>0000000011260721</instrumentID>
				</source>
			</header>
			<dataPoints>
				<positions axis="2Theta" unit="deg">
					<startPosition>71.625492666418</startPosition>
					<endPosition>74.9727624376345</endPosition>
				</positions>
				<positions axis="Omega" unit="deg">
					<commonPosition>18.2219637760131</commonPosition>
				</positions>
				<positions axis="Phi" unit="deg">
					<commonPosition>0.05</commonPosition>
				</positions>
				<positions axis="Chi" unit="deg">
					<commonPosition>-0.15</commonPosition>
				</positions>
				<positions axis="Z" unit="mm">
					<commonPosition>8.355</commonPosition>
				</positions>
				<commonCountingTime unit="seconds">0.974</commonCountingTime>
				<counts unit="counts">0 0 0 0 0 0 0 0 2 0 0 0 1 0 0 0 0 1 0 1 1 0 0 1 0 0 0 0 0 0 0 3 0 0 0 0 0 0 1 1 0 1 0 1 0 1 0 0 0 1 0 0 0 0 0 0 0 0 0 0 0 0 1 0 0 0 0 0 0 0 0 1 0 0 0 2 0 0 0 0 0 0 0 0 0 0 1 0 0 0 0 0 1 0 0 0 1 0 1 0 0 0 0 0 2 0 0 0 0 1 0 0 0 0 1 0 1 0 0 0 2 0 0 0 0 0 1 0 1 0 1 0 2 0 0 0 0 0 0 0 0 1 0 1 0 0 0 0 0 0 0 0 0 0 0 0 0 0 0 0 0 1 1 1 1 0 0 0 1 0 0 0 0 0 0 0 0 0 0 0 0 0 0 1 0 0 0 1 0 0 0 0 1 0 0 0 1 0 0 0 0 0 0 0 1 0 0 0 1 1 0 0 0 0 0 1 0 1 0 0 0 1 0 1 0 3 0 0 0 0 0 0 2 0 0 0 0 1 0 0 0 0 0 0 0 0 0 0 1 1 0 0 0 0 0</counts>
			</dataPoints>
		</scan>
		<scan status="Completed" appendNumber="0" scanAxis="2Theta" mode="Continuous">
			<header>
				<startTimeStamp>2024-09-11T18:03:22-04:00</startTimeStamp>
				<endTimeStamp>2024-09-11T18:33:21-04:00</endTimeStamp>
				<author>
					<name>lw627</name>
				</author>
				<source>
					<applicationSoftware version="7.1">Data Collector</applicationSoftware>
					<instrumentControlSoftware version="8.2  20201204">EMPYREAN</instrumentControlSoftware>
					<instrumentID>0000000011260721</instrumentID>
				</source>
			</header>
			<dataPoints>
				<positions axis="2Theta" unit="deg">
					<startPosition>71.6287752370862</startPosition>
					<endPosition>74.9760450083026</endPosition>
				</positions>
				<positions axis="Omega" unit="deg">
					<commonPosition>18.2236050613472</commonPosition>
				</positions>
				<positions axis="Phi" unit="deg">
					<commonPosition>0.05</commonPosition>
				</positions>
				<positions axis="Chi" unit="deg">
					<commonPosition>-0.15</commonPosition>
				</positions>
				<positions axis="Z" unit="mm">
					<commonPosition>8.355</commonPosition>
				</positions>
				<commonCountingTime unit="seconds">0.974</commonCountingTime>
				<counts unit="counts">0 0 0 0 1 0 0 0 0 1 0 1 0 1 0 0 0 0 0 0 1 0 0 0 1 0 0 0 0 0 0 1 0 0 0 0 0 0 0 0 1 0 0 0 0 0 0 0 0 0 1 0 0 1 1 1 1 0 0 1 0 1 1 0 0 0 0 0 0 0 0 0 0 0 0 1 0 1 0 0 0 0 1 0 0 1 0 0 1 0 1 1 0 1 0 1 0 0 0 0 0 0 1 0 0 0 1 1 1 0 1 0 1 0 0 1 2 0 0 0 0 0 0 0 0 0 0 0 0 0 0 0 1 0 0 0 2 1 0 0 0 1 0 0 0 0 0 1 0 0 0 0 2 0 0 0 0 0 0 0 0 0 0 0 0 0 1 0 0 1 0 0 1 0 0 0 0 0 0 0 1 0 0 0 0 0 0 0 1 0 1 0 0 1 0 1 0 0 0 0 0 0 0 0 0 0 0 0 0 0 1 0 0 0 0 1 0 0 0 0 0 0 1 0 0 1 0 0 1 1 0 0 0 0 0 1 0 0 0 0 1 0 0 0 0 2 0 0 1 1 1 0 0 1 0</counts>
			</dataPoints>
		</scan>
		<scan status="Completed" appendNumber="0" scanAxis="2Theta" mode="Continuous">
			<header>
				<startTimeStamp>2024-09-11T18:03:22-04:00</startTimeStamp>
				<endTimeStamp>2024-09-11T18:33:21-04:00</endTimeStamp>
				<author>
					<name>lw627</name>
				</author>
				<source>
					<applicationSoftware version="7.1">Data Collector</applicationSoftware>
					<instrumentControlSoftware version="8.2  20201204">EMPYREAN</instrumentControlSoftware>
					<instrumentID>0000000011260721</instrumentID>
				</source>
			</header>
			<dataPoints>
				<positions axis="2Theta" unit="deg">
					<startPosition>71.6320578077543</startPosition>
					<endPosition>74.9793275789708</endPosition>
				</positions>
				<positions axis="Omega" unit="deg">
					<commonPosition>18.2252463466813</commonPosition>
				</positions>
				<positions axis="Phi" unit="deg">
					<commonPosition>0.05</commonPosition>
				</positions>
				<positions axis="Chi" unit="deg">
					<commonPosition>-0.15</commonPosition>
				</positions>
				<positions axis="Z" unit="mm">
					<commonPosition>8.355</commonPosition>
				</positions>
				<commonCountingTime unit="seconds">0.974</commonCountingTime>
[...]
				</positions>
				<positions axis="Z" unit="mm">
					<commonPosition>8.355</commonPosition>
				</positions>
				<commonCountingTime unit="seconds">0.974</commonCountingTime>
				<counts unit="counts">0 1 0 0 1 0 0 0 1 0 0 1 0 0 1 0 0 0 0 1 0 1 0 1 0 1 1 1 0 1 0 0 0 1 0 1 1 0 0 0 0 0 0 0 0 0 1 1 0 0 0 0 0 0 1 0 0 0 1 0 0 0 0 0 2 0 0 0 0 1 0 1 1 0 0 0 0 0 0 0 0 0 0 0 0 1 0 1 1 0 0 1 0 0 1 0 0 0 0 1 0 0 0 0 0 0 0 1 1 0 0 2 0 2 1 0 0 0 0 0 0 0 0 0 0 0 0 0 1 0 0 0 0 0 0 0 0 0 0 1 0 0 0 0 0 0 0 0 0 0 2 0 0 0 0 1 0 2 0 0 0 1 0 0 0 0 1 0 0 0 0 0 0 1 0 0 0 0 0 0 0 0 0 0 0 0 0 1 0 0 0 0 0 0 0 0 1 1 0 0 0 0 0 0 0 0 0 0 0 1 0 0 2 0 0 0 0 1 0 0 0 0 0 0 1 0 0 0 0 0 0 0 1 0 1 0 0 0 0 1 0 0 0 1 0 0 0 0 0 0 0 0 0 0 0</counts>
			</dataPoints>
		</scan>
		<scan status="Completed" appendNumber="0" scanAxis="2Theta" mode="Continuous">
			<header>
				<startTimeStamp>2024-09-11T18:03:22-04:00</startTimeStamp>
				<endTimeStamp>2024-09-11T18:33:21-04:00</endTimeStamp>
				<author>
					<name>lw627</name>
				</author>
				<source>
					<applicationSoftware version="7.1">Data Collector</applicationSoftware>
					<instrumentControlSoftware version="8.2  20201204">EMPYREAN</instrumentControlSoftware>
					<instrumentID>0000000011260721</instrumentID>
				</source>
			</header>
			<dataPoints>
				<positions axis="2Theta" unit="deg">
					<startPosition>77.5275547277105</startPosition>
					<endPosition>80.874824498927</endPosition>
				</positions>
				<positions axis="Omega" unit="deg">
					<commonPosition>21.1729948066594</commonPosition>
				</positions>
				<positions axis="Phi" unit="deg">
					<commonPosition>0.05</commonPosition>
				</positions>
				<positions axis="Chi" unit="deg">
					<commonPosition>-0.15</commonPosition>
				</positions>
				<positions axis="Z" unit="mm">
					<commonPosition>8.355</commonPosition>
				</positions>
				<commonCountingTime unit="seconds">0.974</commonCountingTime>
				<counts unit="counts">2 0 1 0 0 0 0 0 0 0 0 0 0 0 0 0 1 0 0 1 0 0 0 1 0 0 0 0 0 0 0 0 0 0 0 0 0 1 0 0 0 0 1 0 0 0 0 0 0 1 0 0 0 0 0 1 1 0 0 0 0 0 1 1 0 0 0 0 0 0 0 2 0 0 0 0 0 0 2 1 1 1 0 2 0 0 0 0 0 1 0 0 0 0 0 0 0 0 0 0 0 0 0 0 0 0 0 1 0 0 0 1 0 0 0 0 0 0 0 1 0 0 1 1 0 0 0 0 2 1 0 0 0 0 1 0 0 0 0 1 1 0 0 0 1 1 0 0 1 0 0 0 0 0 0 0 0 0 2 0 0 0 0 1 0 0 1 0 1 1 0 1 1 0 0 0 0 1 0 0 1 0 0 0 0 0 0 0 0 0 1 0 0 1 2 0 0 0 0 0 0 1 1 0 0 0 1 0 0 0 0 0 0 0 0 0 0 1 0 0 0 0 0 0 0 0 0 1 0 0 0 0 0 0 1 0 0 0 0 1 1 0 0 0 0 0 0 0 0 1 0 0 0 0 1</counts>
			</dataPoints>
		</scan>
		<scan status="Completed" appendNumber="0" scanAxis="2Theta" mode="Continuous">
			<header>
				<startTimeStamp>2024-09-11T18:03:22-04:00</startTimeStamp>
				<endTimeStamp>2024-09-11T18:33:21-04:00</endTimeStamp>
				<author>
					<name>lw627</name>
				</author>
				<source>
					<applicationSoftware version="7.1">Data Collector</applicationSoftware>
					<instrumentControlSoftware version="8.2  20201204">EMPYREAN</instrumentControlSoftware>
					<instrumentID>0000000011260721</instrumentID>
				</source>
			</header>
			<dataPoints>
				<positions axis="2Theta" unit="deg">
					<startPosition>77.5308372983786</startPosition>
					<endPosition>80.8781070695951</endPosition>
				</positions>
				<positions axis="Omega" unit="deg">
					<commonPosition>21.1746360919934</commonPosition>
				</positions>
				<positions axis="Phi" unit="deg">
					<commonPosition>0.05</commonPosition>
				</positions>
				<positions axis="Chi" unit="deg">
					<commonPosition>-0.15</commonPosition>
				</positions>
				<positions axis="Z" unit="mm">
					<commonPosition>8.355</commonPosition>
				</positions>
				<commonCountingTime unit="seconds">0.974</commonCountingTime>
				<counts unit="counts">0 0 0 0 1 0 0 1 0 0 2 2 0 0 1 1 0 1 0 0 2 0 0 0 0 0 0 0 0 0 1 1 0 0 0 0 0 0 0 0 0 0 0 0 1 1 0 0 0 0 0 0 0 0 0 0 1 0 0 0 0 0 0 0 1 0 1 0 0 0 0 1 0 0 1 1 1 0 1 1 0 0 0 0 0 0 0 0 1 0 0 0 1 0 1 0 1 0 0 0 1 1 0 0 0 0 0 2 0 0 1 0 1 0 0 0 0 0 1 0 0 1 0 0 2 1 1 0 0 0 0 0 1 0 0 0 1 1 0 0 0 0 0 0 0 0 0 0 0 0 0 0 0 0 0 0 0 1 1 0 1 0 1 0 0 0 0 0 0 1 0 2 0 0 0 0 0 0 1 0 0 0 0 0 2 2 0 0 0 0 1 0 1 0 1 2 1 0 1 0 0 0 1 0 0 0 0 0 0 0 0 0 0 1 0 0 0 0 2 0 1 0 0 0 0 0 0 0 0 0 0 0 0 1 0 1 1 0 0 0 1 1 0 1 0 1 1 0 0 0 0 0 0 1 0</counts>
			</dataPoints>
		</scan>
		<scan status="Completed" appendNumber="0" scanAxis="2Theta" mode="Continuous">
			<header>
				<startTimeStamp>2024-09-11T18:03:22-04:00</startTimeStamp>
				<endTimeStamp>2024-09-11T18:33:21-04:00</endTimeStamp>
				<author>
					<name>lw627</name>
				</author>
				<source>
					<applicationSoftware version="7.1">Data Collector</applicationSoftware>
					<instrumentControlSoftware version="8.2  20201204">EMPYREAN</instrumentControlSoftware>
					<instrumentID>0000000011260721</instrumentID>
				</source>
			</header>
			<dataPoints>
				<positions axis="2Theta" unit="deg">
					<startPosition>77.5341198690467</startPosition>
					<endPosition>80.8813896402632</endPosition>
				</positions>
				<positions axis="Omega" unit="deg">
					<commonPosition>21.1762773773275</commonPosition>
				</positions>
				<positions axis="Phi" unit="deg">
					<commonPosition>0.05</commonPosition>
				</positions>
				<positions axis="Chi" unit="deg">
					<commonPosition>-0.15</commonPosition>
				</positions>
				<positions axis="Z" unit="mm">
					<commonPosition>8.355</commonPosition>
				</positions>
				<commonCountingTime unit="seconds">0.974</commonCountingTime>
				<counts unit="counts">1 0 0 0 0 0 1 1 0 0 0 0 0 0 1 0 0 0 1 1 0 0 1 0 2 0 0 0 1 0 2 0 0 2 0 0 0 0 0 0 0 0 0 0 0 1 0 1 0 0 0 0 0 0 0 0 1 0 0 0 0 0 0 0 0 1 0 0 0 0 0 0 0 1 0 0 0 1 2 0 0 0 0 1 0 0 0 1 0 1 0 1 1 1 0 0 0 1 0 0 0 0 0 0 0 0 1 0 0 0 0 0 0 0 0 0 0 1 0 0 1 0 0 0 0 0 0 0 0 0 2 0 0 0 2 1 0 0 0 1 0 0 0 0 0 0 0 2 0 0 1 0 0 1 0 0 1 0 0 1 0 0 0 0 0 0 0 0 0 0 0 0 0 0 0 0 0 0 0 0 0 1 1 0 0 0 1 2 0 0 0 0 0 0 0 0 0 0 1 1 0 1 0 0 1 0 1 0 0 0 0 0 0 0 0 0 1 0 0 0 0 0 0 0 0 0 0 0 0 0 0 0 0 0 0 0 1 1 1 0 0 0 1 1 0 0 0 0 0 0 0 0 0 1 0</counts>
			</dataPoints>
		</scan>
		<scan status="Completed" appendNumber="0" scanAxis="2Theta" mode="Continuous">
			<header>
				<startTimeStamp>2024-09-11T18:03:22-04:00</startTimeStamp>
				<endTimeStamp>2024-09-11T18:33:21-04:00</endTimeStamp>
				<author>
					<name>lw627</name>
				</author>
				<source>
					<applicationSoftware version="7.1">Data Collector</applicationSoftware>
					<instrumentControlSoftware version="8.2  20201204">EMPYREAN</instrumentControlSoftware>
					<instrumentID>0000000011260721</instrumentID>
				</source>
			</header>
			<dataPoints>
				<positions axis="2Theta" unit="deg">
					<startPosition>77.5374024397149</startPosition>
					<endPosition>80.8846722109313</endPosition>
				</positions>
				<positions axis="Omega" unit="deg">
					<commonPosition>21.1779186626616</commonPosition>
				</positions>
				<positions axis="Phi" unit="deg">
					<commonPosition>0.05</commonPosition>
				</positions>
				<positions axis="Chi" unit="deg">
					<commonPosition>-0.15</commonPosition>
				</positions>
				<positions axis="Z" unit="mm">
					<commonPosition>8.355</commonPosition>
				</positions>
				<commonCountingTime unit="seconds">0.974</commonCountingTime>
				<counts unit="counts">2 0 1 0 0 0 2 0 0 1 1 0 0 0 1 1 0 0 0 0 0 0 1 0 0 0 0 0 0 0 1 0 0 0 0 0 2 0 0 0 0 0 0 1 0 0 0 0 0 1 1 1 0 1 1 0 1 2 0 0 0 0 0 0 1 1 0 0 0 0 0 1 0 0 0 0 0 0 2 1 2 0 0 1 0 0 0 0 1 0 0 0 1 0 1 0 0 0 1 0 0 0 0 0 0 0 0 0 1 1 0 0 1 0 0 2 0 0 1 0 0 0 0 0 0 0 1 0 0 0 0 0 0 1 1 0 0 0 0 0 0 0 0 0 0 0 0 1 0 0 0 0 0 0 0 1 0 0 0 0 0 0 0 1 1 0 0 0 1 0 0 0 0 0 2 1 0 0 0 0 0 0 0 0 0 0 0 0 0 0 0 0 1 0 0 0 1 0 0 0 0 0 1 0 0 2 0 0 0 0 0 0 0 2 0 1 0 0 0 0 4 0 1 0 0 0 0 1 0 0 0 0 0 1 0 0 0 0 0 0 0 0 0 1 0 1 0 0 1 0 0 1 0 0 0</counts>
			</dataPoints>
		</scan>
		<scan status="Completed" appendNumber="0" scanAxis="2Theta" mode="Continuous">
			<header>
				<startTimeStamp>2024-09-11T18:03:22-04:00</startTimeStamp>
				<endTimeStamp>2024-09-11T18:33:21-04:00</endTimeStamp>
				<author>
					<name>lw627</name>
				</author>
				<source>
					<applicationSoftware version="7.1">Data Collector</applicationSoftware>
					<instrumentControlSoftware version="8.2  20201204">EMPYREAN</instrumentControlSoftware>
					<instrumentID>0000000011260721</instrumentID>
				</source>
			</header>
			<dataPoints>
				<positions axis="2Theta" unit="deg">
					<startPosition>77.540685010383</startPosition>
					<endPosition>80.8879547815995</endPosition>
				</positions>
				<positions axis="Omega" unit="deg">
					<commonPosition>21.1795599479956</commonPosition>
				</positions>
				<positions axis="Phi" unit="deg">
					<commonPosition>0.05</commonPosition>
				</positions>
				<positions axis="Chi" unit="deg">
					<commonPosition>-0.15</commonPosition>
				</positions>
				<positions axis="Z" unit="mm">
					<commonPosition>8.355</commonPosition>
				</positions>
				<commonCountingTime unit="seconds">0.974</commonCountingTime>
				<counts unit="counts">0 2 1 0 0 0 2 0 0 0 1 0 0 0 1 0 0 0 0 0 0 0 1 0 0 0 0 2 0 0 0 0 0 1 0 1 0 0 2 0 0 1 0 0 0 0 1 0 1 0 0 1 1 0 0 0 0 0 0 0 0 0 0 0 0 0 1 0 1 0 0 0 1 0 0 0 0 0 2 0 0 0 0 0 0 0 0 0 0 0 1 0 0 0 0 0 1 0 0 0 0 0 0 0 0 1 0 0 0 1 1 1 0 1 0 0 0 0 0 0 0 1 1 1 0 0 1 0 1 0 0 0 0 0 1 2 0 0 0 1 0 1 1 0 0 0 0 2 0 0 1 0 1 0 0 1 0 0 1 0 0 1 1 0 0 2 1 0 0 2 1 0 0 1 0 0 0 1 1 0 0 0 0 0 0 0 0 0 0 0 2 2 1 0 0 0 0 0 1 1 0 0 1 0 1 0 0 0 0 0 0 0 0 0 2 0 0 1 1 0 0 0 1 0 0 0 0 0 1 1 0 1 0 0 0 0 0 1 0 0 1 0 0 0 1 2 0 0 0 1 1 0 0 0 0</counts>
			</dataPoints>
		</scan>
		<scan status="Completed" appendNumber="0" scanAxis="2Theta" mode="Continuous">
			<header>
				<startTimeStamp>2024-09-11T18:03:22-04:00</startTimeStamp>
				<endTimeStamp>2024-09-11T18:33:21-04:00</endTimeStamp>
				<author>
					<name>lw627</name>
				</author>
				<source>
					<applicationSoftware version="7.1">Data Collector</applicationSoftware>
					<instrumentControlSoftware version="8.2  20201204">EMPYREAN</instrumentControlSoftware>
					<instrumentID>0000000011260721</instrumentID>
				</source>
			</header>
			<dataPoints>
				<positions axis="2Theta" unit="deg">
					<startPosition>77.5439675810511</startPosition>
					<endPosition>80.8912373522676</endPosition>
				</positions>
				<positions axis="Omega" unit="deg">
					<commonPosition>21.1812012333297</commonPosition>
				</positions>
				<positions axis="Phi" unit="deg">
					<commonPosition>0.05</commonPosition>
				</positions>
				<positions axis="Chi" unit="deg">
					<commonPosition>-0.15</commonPosition>
				</positions>
				<positions axis="Z" unit="mm">
					<commonPosition>8.355</commonPosition>
				</positions>
				<commonCountingTime unit="seconds">0.974</commonCountingTime>
				<counts unit="counts">0 0 3 0 0 1 0 0 0 2 0 0 0 0 0 1 1 0 0 0 0 0 0 1 1 0 0 0 0 0 1 0 1 2 0 0 0 0 0 0 0 0 0 0 0 0 1 0 1 0 0 0 0 0 1 1 0 0 0 0 0 1 0 0 0 1 1 0 0 1 0 0 0 0 0 1 0 0 1 0 1 1 0 1 0 1 0 0 0 0 0 0 1 1 0 1 0 1 0 0 0 1 1 1 0 0 0 0 0 0 0 0 0 0 1 0 0 0 2 0 0 0 0 0 0 1 0 0 0 1 1 0 0 0 0 0 0 0 1 0 1 0 0 0 1 1 0 1 0 0 0 1 0 0 1 0 0 0 0 0 0 0 1 2 1 0 0 1 0 0 0 0 0 0 0 0 0 0 0 0 0 0 0 1 0 0 0 0 1 0 0 0 0 1 0 0 2 0 0 0 0 0 0 1 0 0 0 0 1 1 0 0 0 0 0 1 0 1 0 0 0 0 0 0 0 0 0 0 0 0 0 0 1 1 1 1 1 1 0 0 0 1 0 1 0 0 0 0 0 0 0 0 0 0 0</counts>
			</dataPoints>
		</scan>
		<scan status="Completed" appendNumber="0" scanAxis="2Theta" mode="Continuous">
			<header>
				<startTimeStamp>2024-09-11T18:03:22-04:00</startTimeStamp>
				<endTimeStamp>2024-09-11T18:33:21-04:00</endTimeStamp>
				<author>
					<name>lw627</name>
				</author>
				<source>
					<applicationSoftware version="7.1">Data Collector</applicationSoftware>
					<instrumentControlSoftware version="8.2  20201204">EMPYREAN</instrumentControlSoftware>
					<instrumentID>0000000011260721</instrumentID>
				</source>
			</header>
			<dataPoints>
				<positions axis="2Theta" unit="deg">
					<startPosition>77.5472501517193</startPosition>
					<endPosition>80.8945199229357</endPosition>
				</positions>
				<positions axis="Omega" unit="deg">
					<commonPosition>21.1828425186637</commonPosition>
				</positions>
				<positions axis="Phi" unit="deg">
					<commonPosition>0.05</commonPosition>
				</positions>
				<positions axis="Chi" unit="deg">
					<commonPosition>-0.15</commonPosition>
				</positions>
				<positions axis="Z" unit="mm">
					<commonPosition>8.355</commonPosition>
				</positions>
				<commonCountingTime unit="seconds">0.974</commonCountingTime>
				<counts unit="counts">0 0 0 0 0 1 0 0 0 0 0 1 0 0 0 1 1 0 1 0 0 0 0 0 0 0 0 0 4 0 0 0 0 0 0 0 0 2 0 0 1 1 0 1 0 0 0 1 0 0 0 0 0 0 0 1 1 1 0 0 2 0 0 0 0 0 0 1 0 1 1 0 0 0 0 0 1 0 0 2 0 0 1 0 1 0 0 0 0 0 1 0 0 1 0 0 0 1 0 1 0 0 0 0 0 0 0 0 0 0 0 0 0 0 0 0 1 0 0 0 0 1 0 1 1 0 0 0 0 0 0 1 0 1 0 0 0 1 0 1 0 0 0 1 1 0 0 0 0 0 0 0 0 0 0 1 0 0 0 0 0 0 0 0 0 1 1 0 0 1 1 0 0 2 0 1 0 0 0 1 0 0 0 0 1 0 0 1 0 0 1 0 0 0 0 0 1 1 0 0 0 0 1 0 0 0 0 0 0 0 0 0 0 2 0 0 0 1 0 0 0 0 0 2 1 0 0 0 1 0 0 0 0 0 0 1 0 2 0 0 0 0 0 0 0 0 0 0 0 1 1 0 0 0 1</counts>
			</dataPoints>
		</scan>
		<scan status="Completed" appendNumber="0" scanAxis="2Theta" mode="Continuous">
			<header>
				<startTimeStamp>2024-09-11T18:03:22-04:00</startTimeStamp>
				<endTimeStamp>2024-09-11T18:33:21-04:00</endTimeStamp>
				<author>
					<name>lw627</name>
				</author>
				<source>
					<applicationSoftware version="7.1">Data Collector</applicationSoftware>
					<instrumentControlSoftware version="8.2  20201204">EMPYREAN</instrumentControlSoftware>
					<instrumentID>0000000011260721</instrumentID>
				</source>
			</header>
			<dataPoints>
				<positions axis="2Theta" unit="deg">
					<startPosition>77.5505327223874</startPosition>
					<endPosition>80.8978024936038</endPosition>
				</positions>
				<positions axis="Omega" unit="deg">
					<commonPosition>21.1844838039978</commonPosition>
				</positions>
				<positions axis="Phi" unit="deg">
					<commonPosition>0.05</commonPosition>
				</positions>
				<positions axis="Chi" unit="deg">
					<commonPosition>-0.15</commonPosition>
				</positions>
				<positions axis="Z" unit="mm">
					<commonPosition>8.355</commonPosition>
				</positions>
				<commonCountingTime unit="seconds">0.974</commonCountingTime>
				<counts unit="counts">0 2 0 0 1 0 0 0 2 0 2 1 1 0 0 1 0 0 0 0 0 1 0 0 0 0 0 1 0 1 1 0 0 2 1 0 0 1 2 0 0 0 0 0 1 0 0 0 0 0 0 0 0 0 0 0 1 1 0 0 0 0 0 0 1 0 0 0 0 0 1 0 0 0 0 1 0 0 0 0 0 0 1 0 0 0 0 0 0 0 0 2 1 0 0 1 1 1 0 2 0 0 0 1 0 0 0 0 1 0 0 0 0 1 0 0 0 0 1 0 1 1 0 1 1 0 0 0 0 0 0 0 0 0 1 0 0 0 0 1 0 0 1 0 0 2 0 0 0 0 1 0 0 0 0 0 0 1 0 0 0 0 2 0 0 0 1 0 1 0 0 0 0 0 2 0 0 0 0 1 0 1 0 0 1 0 0 0 0 0 0 0 0 1 0 0 0 1 0 1 0 0 0 0 0 0 1 0 0 0 0 0 0 0 1 0 0 1 0 0 0 0 0 0 0 1 0 1 0 1 0 0 0 0 0 0 0 1 0 1 0 0 0 0 0 1 0 0 0 0 0 1 0 0 0</counts>
			</dataPoints>
		</scan>
		<scan status="Completed" appendNumber="0" scanAxis="2Theta" mode="Continuous">
			<header>
				<startTimeStamp>2024-09-11T18:03:22-04:00</startTimeStamp>
				<endTimeStamp>2024-09-11T18:33:21-04:00</endTimeStamp>
				<author>
					<name>lw627</name>
				</author>
				<source>
					<applicationSoftware version="7.1">Data Collector</applicationSoftware>
					<instrumentControlSoftware version="8.2  20201204">EMPYREAN</instrumentControlSoftware>
					<instrumentID>0000000011260721</instrumentID>
				</source>
			</header>
			<dataPoints>
				<positions axis="2Theta" unit="deg">
					<startPosition>77.5538152930555</startPosition>
					<endPosition>80.901085064272</endPosition>
				</positions>
				<positions axis="Omega" unit="deg">
					<commonPosition>21.1861250893319</commonPosition>
				</positions>
				<positions axis="Phi" unit="deg">
					<commonPosition>0.05</commonPosition>
				</positions>
				<positions axis="Chi" unit="deg">
					<commonPosition>-0.15</commonPosition>
				</positions>
				<positions axis="Z" unit="mm">
					<commonPosition>8.355</commonPosition>
				</positions>
				<commonCountingTime unit="seconds">0.974</commonCountingTime>
				<counts unit="counts">2 0 0 0 3 1 0 0 0 0 0 0 0 0 1 0 0 0 0 0 1 0 1 0 1 0 0 0 0 1 1 0 0 0 0 0 0 0 1 1 0 0 0 1 0 0 0 0 1 0 0 0 0 0 1 0 0 0 0 0 0 0 0 0 0 0 0 1 0 0 0 0 1 1 0 0 0 0 0 1 0 0 0 0 0 1 0 0 0 0 0 1 1 0 1 0 1 1 0 0 2 0 1 0 0 1 0 0 0 0 0 0 1 0 0 0 0 0 0 0 0 1 0 0 0 1 0 0 0 0 0 0 0 0 0 0 1 0 0 1 0 0 1 0 0 0 1 2 0 0 0 0 1 0 0 0 0 1 0 0 0 0 1 0 0 0 0 0 0 0 0 0 0 0 0 0 0 0 0 0 1 1 1 0 0 1 1 1 0 0 0 1 1 1 0 0 0 0 0 1 0 0 0 0 1 1 0 0 0 0 0 0 0 0 1 1 0 0 0 1 0 1 0 0 0 0 0 0 0 0 0 0 1 0 0 0 3 1 0 0 0 0 1 0 0 1 1 0 0 0 0 0 2 0 0</counts>
			</dataPoints>
		</scan>
		<scan status="Completed" appendNumber="0" scanAxis="2Theta" mode="Continuous">
			<header>
				<startTimeStamp>2024-09-11T18:03:22-04:00</startTimeStamp>
				<endTimeStamp>2024-09-11T18:33:21-04:00</endTimeStamp>
				<author>
					<name>lw627</name>
				</author>
				<source>
					<applicationSoftware version="7.1">Data Collector</applicationSoftware>
					<instrumentControlSoftware version="8.2  20201204">EMPYREAN</instrumentControlSoftware>
					<instrumentID>0000000011260721</instrumentID>
				</source>
			</header>
			<dataPoints>
				<positions axis="2Theta" unit="deg">
					<startPosition>77.5570978637236</startPosition>
					<endPosition>80.9043676349401</endPosition>
				</positions>
				<positions axis="Omega" unit="deg">
					<commonPosition>21.1877663746659</commonPosition>
				</positions>
				<positions axis="Phi" unit="deg">
					<commonPosition>0.05</commonPosition>
				</positions>
				<positions axis="Chi" unit="deg">
					<commonPosition>-0.15</commonPosition>
				</positions>
				<positions axis="Z" unit="mm">
					<commonPosition>8.355</commonPosition>
				</positions>
				<commonCountingTime unit="seconds">0.974</commonCountingTime>
				<counts unit="counts">1 0 1 0 0 0 0 0 1 1 1 1 0 0 0 0 0 0 0 0 0 0 0 1 0 1 1 2 0 0 0 0 1 1 0 1 0 0 0 0 0 0 0 1 0 1 1 0 0 0 1 0 1 0 0 0 0 0 0 0 1 0 0 0 0 0 0 0 0 1 1 0 1 0 0 0 2 1 0 0 0 1 0 0 0 1 0 0 0 0 0 0 0 0 0 0 1 1 0 0 0 1 0 1 0 0 1 0 0 0 0 0 0 2 1 0 0 0 0 1 2 0 0 0 3 1 0 1 0 0 0 0 0 2 0 1 0 0 0 0 0 0 1 0 0 0 0 0 0 0 1 0 0 1 0 0 0 0 1 0 0 0 0 1 0 0 0 0 0 1 0 0 0 0 0 1 0 0 0 0 0 0 0 0 0 2 0 3 0 0 0 1 0 0 0 0 0 0 0 1 0 1 0 0 1 0 1 0 0 0 0 0 0 0 0 0 0 0 0 0 0 0 0 0 0 0 0 0 0 0 0 0 0 0 1 1 0 0 0 0 0 0 0 1 0 0 1 0 1 0 0 0 0 1 0</counts>
			</dataPoints>
		</scan>
		<scan status="Completed" appendNumber="0" scanAxis="2Theta" mode="Continuous">
			<header>
				<startTimeStamp>2024-09-11T18:03:22-04:00</startTimeStamp>
				<endTimeStamp>2024-09-11T18:33:21-04:00</endTimeStamp>
				<author>
					<name>lw627</name>
				</author>
				<source>
					<applicationSoftware version="7.1">Data Collector</applicationSoftware>
					<instrumentControlSoftware version="8.2  20201204">EMPYREAN</instrumentControlSoftware>
					<instrumentID>0000000011260721</instrumentID>
				</source>
			</header>
			<dataPoints>
				<positions axis="2Theta" unit="deg">
					<startPosition>77.5603804343918</startPosition>
					<endPosition>80.9076502056082</endPosition>
				</positions>
				<positions axis="Omega" unit="deg">
					<commonPosition>21.18940766</commonPosition>
				</positions>
				<positions axis="Phi" unit="deg">
					<commonPosition>0.05</commonPosition>
				</positions>
				<positions axis="Chi" unit="deg">
					<commonPosition>-0.15</commonPosition>
				</positions>
				<positions axis="Z" unit="mm">
					<commonPosition>8.355</commonPosition>
				</positions>
				<commonCountingTime unit="seconds">0.974</commonCountingTime>
				<counts unit="counts">2 0 0 1 0 0 0 0 0 0 0 1 0 0 0 0 0 0 0 0 0 1 0 0 0 0 1 0 0 0 0 0 0 0 0 0 0 0 0 0 1 1 0 1 1 0 0 1 1 1 0 1 0 0 0 1 0 0 0 0 0 1 1 1 0 0 0 0 0 1 1 0 0 0 0 0 0 0 0 0 0 0 1 0 0 2 0 0 0 0 0 1 1 0 0 0 1 0 0 0 3 1 0 0 0 0 0 0 0 0 2 0 0 0 1 0 0 0 0 1 2 1 0 0 0 1 0 0 0 0 0 0 0 0 0 1 0 1 0 0 0 1 0 0 0 1 0 0 0 2 1 2 0 0 0 0 0 0 0 0 0 0 0 0 0 0 0 0 0 0 1 1 1 0 0 0 0 0 0 0 0 0 0 0 1 0 0 0 1 0 0 0 0 0 0 1 0 0 1 0 0 0 0 1 1 0 1 1 0 0 0 0 0 1 0 0 0 0 1 0 0 0 0 0 0 0 1 0 0 0 1 0 0 0 0 0 0 0 0 0 2 0 0 0 0 1 0 0 0 0 0 0 0 0 0</counts>
			</dataPoints>
		</scan>
	</xrdMeasurement>
</xrdMeasurements>