File: data/XRD_RSM/YG058/YG058 103 phi -90 RSM slow 3 degree_1.xrdml
<?xml version="1.0" encoding="utf-8"?>
<xrdMeasurements xmlns="http://www.xrdml.com/XRDMeasurement/2.2" xmlns:xsi="http://www.w3.org/2001/XMLSchema-instance" xsi:schemaLocation="http://www.xrdml.com/XRDMeasurement/2.2 http://www.xrdml.com/XRDMeasurement/2.2/XRDMeasurement.xsd" status="Completed">
	<comment>
		<entry>Configuration=3-axes Cradle_Reflection, Owner=lw627, Creation date=9/2/2021 3:55:24 PM</entry>
		<entry>Goniometer=Theta/Theta; Minimum step size 2Theta:0.0001; Minimum step size Omega:0.0001</entry>
		<entry>Sample stage=Chi-Phi-z stage 240 mm (reflection); Minimum step size Phi:0.01; Minimum step size Chi:0.01; Minimum step size Z:0.001</entry>
		<entry>Diffractometer system=EMPYREAN</entry>
		<entry>Measurement program=C:\PANalytical\Data Collector\Programs\Liyan Wu\Film programs\RSM slow 3 degree.xrdmp, Identifier={0351664C-55A7-43E7-B72A-7307F4B26703}</entry>
	</comment>
	<sample type="To be analyzed">
		<id/>
		<name/>
		<preparedBy/>
	</sample>
	<xrdMeasurement status="Completed" measurementType="Area measurement" measurementStepAxis="Omega-2Theta" sampleMode="Reflection">
		<comment>
			<entry>PHD Lower Level = 4.02 (keV), PHD Upper Level = 11.27 (keV)</entry>
		</comment>
		<usedWavelength intended="K-Alpha 1">
			<kAlpha1 unit="Angstrom">1.5405980</kAlpha1>
			<kAlpha2 unit="Angstrom">1.5444260</kAlpha2>
			<kBeta unit="Angstrom">1.3922500</kBeta>
			<ratioKAlpha2KAlpha1>0</ratioKAlpha2KAlpha1>
		</usedWavelength>
		<incidentBeamPath>
			<radius unit="mm">240.00</radius>
			<xRayTube id="1010048" name="Empyrean Cu LFF HR (9430 033 7310x) DK432574">
				<tension unit="kV">45.0</tension>
				<current unit="mA">40.0</current>
				<anodeMaterial>Cu</anodeMaterial>
				<focus type="Line">
					<length unit="mm">12.0</length>
					<width unit="mm">0.4</width>
					<takeOffAngle unit="deg">4.4</takeOffAngle>
				</focus>
			</xRayTube>
			<xRayMirror xsi:type="xRayMirrorType" id="27080001" name="Inc. Beam Cu W/Si (hybrid MPD)" hybrid="true">
				<crystal type="Graded" shape="Parabolic">W/Si</crystal>
				<acceptanceAngle unit="deg">0.800</acceptanceAngle>
				<length unit="mm">55.3</length>
			</xRayMirror>
			<monochromator xsi:type="monochromatorType" id="23090002" name="Hybrid monochr. 2xGe220 Cu asym." hybrid="true">
				<crystal type="Asymmetric" shape="Flat">Ge</crystal>
				<numberOfReflections>2</numberOfReflections>
				<hkl>
					<h>2</h>
					<k>2</k>
					<l>0</l>
				</hkl>
			</monochromator>
			<divergenceSlit xsi:type="fixedDivergenceSlitType" id="22010005" name="Fixed slit 1/4°">
				<distanceToSample unit="mm">179.30</distanceToSample>
				<height unit="mm">0.38</height>
			</divergenceSlit>
		</incidentBeamPath>
		<diffractedBeamPath>
			<radius unit="mm">240.00</radius>
			<antiScatterSlit xsi:type="fixedAntiScatterSlitType" id="22060009" name="Programmable anti-scatter slit">
				<angle unit="deg">4</angle>
			</antiScatterSlit>
			<detector xsi:type="areaDetectorType" id="7010020" name="PIXcel3D-Medipix3 1x1 detector">
				<phd unit="%">
					<lowerLevel>25</lowerLevel>
					<upperLevel>70</upperLevel>
				</phd>
				<mode>Scanning snapshot equatorial</mode>
				<activeChannelsEquatorial>255</activeChannelsEquatorial>
				<activeChannelsAxial>255</activeChannelsAxial>
				<pitchEquatorial unit="mm">0.05500</pitchEquatorial>
				<pitchAxial unit="mm">0.05500</pitchAxial>
				<readOutPeriod unit="seconds">0.980</readOutPeriod>
			</detector>
		</diffractedBeamPath>
		<scan status="Completed" appendNumber="0" scanAxis="2Theta" mode="Continuous">
			<header>
				<startTimeStamp>2024-07-01T14:31:11-04:00</startTimeStamp>
				<endTimeStamp>2024-07-01T15:01:10-04:00</endTimeStamp>
				<author>
					<name>lw627</name>
				</author>
				<source>
					<applicationSoftware version="7.1">Data Collector</applicationSoftware>
					<instrumentControlSoftware version="8.2  20201204">EMPYREAN</instrumentControlSoftware>
					<instrumentID>0000000011260721</instrumentID>
				</source>
			</header>
			<dataPoints>
				<positions axis="2Theta" unit="deg">
					<startPosition>71.9734063943918</startPosition>
					<endPosition>75.3206761656082</endPosition>
				</positions>
				<positions axis="Omega" unit="deg">
					<commonPosition>18.26252064</commonPosition>
				</positions>
				<positions axis="Phi" unit="deg">
					<commonPosition>-88.77</commonPosition>
				</positions>
				<positions axis="Chi" unit="deg">
					<commonPosition>0</commonPosition>
				</positions>
				<positions axis="Z" unit="mm">
					<commonPosition>8.365</commonPosition>
				</positions>
				<commonCountingTime unit="seconds">0.974</commonCountingTime>
				<counts unit="counts">0 1 0 2 0 0 2 0 1 0 1 0 0 0 0 0 0 0 0 0 0 0 0 0 0 0 1 0 1 0 1 0 1 1 0 0 0 0 1 0 0 0 1 0 0 1 0 0 1 0 0 0 0 0 0 0 0 0 0 0 0 0 2 0 0 1 1 0 2 0 0 0 0 0 0 0 0 0 0 0 0 0 1 0 0 0 0 0 1 0 0 0 0 0 0 0 0 0 0 1 0 0 0 1 0 0 0 0 0 1 0 0 1 0 1 0 0 1 0 1 0 1 0 0 0 0 1 0 0 0 0 0 0 1 1 0 0 0 0 0 0 1 1 0 1 0 0 0 0 0 0 0 0 0 1 0 0 0 0 0 0 0 1 1 0 1 0 0 1 1 0 0 0 0 0 0 0 0 0 1 1 0 0 1 0 0 0 1 0 1 1 0 0 1 1 0 3 0 0 1 0 0 0 0 0 0 0 0 1 0 1 0 1 0 0 0 0 0 0 2 0 1 1 1 0 0 1 0 0 0 1 1 0 0 0 0 0 0 0 1 0 0 0 1 0 0 0 1 0 0 0 0 0 0 1</counts>
			</dataPoints>
		</scan>
		<scan status="Completed" appendNumber="0" scanAxis="2Theta" mode="Continuous">
			<header>
				<startTimeStamp>2024-07-01T14:31:11-04:00</startTimeStamp>
				<endTimeStamp>2024-07-01T15:01:10-04:00</endTimeStamp>
				<author>
					<name>lw627</name>
				</author>
				<source>
					<applicationSoftware version="7.1">Data Collector</applicationSoftware>
					<instrumentControlSoftware version="8.2  20201204">EMPYREAN</instrumentControlSoftware>
					<instrumentID>0000000011260721</instrumentID>
				</source>
			</header>
			<dataPoints>
				<positions axis="2Theta" unit="deg">
					<startPosition>71.9766889650599</startPosition>
					<endPosition>75.3239587362764</endPosition>
				</positions>
				<positions axis="Omega" unit="deg">
					<commonPosition>18.2641619253341</commonPosition>
				</positions>
				<positions axis="Phi" unit="deg">
					<commonPosition>-88.77</commonPosition>
				</positions>
				<positions axis="Chi" unit="deg">
					<commonPosition>0</commonPosition>
				</positions>
				<positions axis="Z" unit="mm">
					<commonPosition>8.365</commonPosition>
				</positions>
				<commonCountingTime unit="seconds">0.974</commonCountingTime>
				<counts unit="counts">0 1 1 1 0 0 0 0 1 2 0 0 1 0 1 0 0 2 0 0 0 0 0 0 0 0 0 0 0 2 1 0 0 0 0 1 0 0 0 0 0 1 0 0 0 0 1 0 0 0 0 0 1 0 0 0 0 0 0 0 0 0 1 0 0 0 0 0 0 0 1 1 0 0 0 0 1 0 0 0 0 0 0 0 0 0 0 0 0 0 1 0 1 0 0 0 0 0 1 0 0 0 1 0 0 0 0 1 0 1 0 0 0 0 0 0 0 0 0 0 0 0 0 0 0 1 0 0 0 0 0 0 0 0 0 0 0 0 1 0 1 0 0 0 0 0 0 0 0 1 0 0 0 1 0 0 0 0 0 0 2 0 1 0 1 1 0 1 0 0 1 0 0 2 1 0 1 0 0 0 1 1 0 0 0 1 0 0 0 0 0 0 1 0 0 3 3 1 0 0 0 0 0 0 0 0 0 1 0 0 1 0 2 0 0 0 0 0 0 1 0 0 0 0 0 0 0 0 0 0 0 0 0 0 0 2 0 0 0 0 0 0 0 0 0 0 0 1 1 0 0 0 0 2 0</counts>
			</dataPoints>
		</scan>
		<scan status="Completed" appendNumber="0" scanAxis="2Theta" mode="Continuous">
			<header>
				<startTimeStamp>2024-07-01T14:31:11-04:00</startTimeStamp>
				<endTimeStamp>2024-07-01T15:01:10-04:00</endTimeStamp>
				<author>
					<name>lw627</name>
				</author>
				<source>
					<applicationSoftware version="7.1">Data Collector</applicationSoftware>
					<instrumentControlSoftware version="8.2  20201204">EMPYREAN</instrumentControlSoftware>
					<instrumentID>0000000011260721</instrumentID>
				</source>
			</header>
			<dataPoints>
				<positions axis="2Theta" unit="deg">
					<startPosition>71.979971535728</startPosition>
					<endPosition>75.3272413069445</endPosition>
				</positions>
				<positions axis="Omega" unit="deg">
					<commonPosition>18.2658032106681</commonPosition>
				</positions>
				<positions axis="Phi" unit="deg">
					<commonPosition>-88.77</commonPosition>
				</positions>
				<positions axis="Chi" unit="deg">
					<commonPosition>0</commonPosition>
				</positions>
				<positions axis="Z" unit="mm">
					<commonPosition>8.365</commonPosition>
				</positions>
				<commonCountingTime unit="seconds">0.974</commonCountingTime>
				<counts unit="counts">1 1 0 0 0 1 0 1 0 0 0 0 0 0 0 1 1 1 0 0 1 2 0 2 0 0 0 0 0 0 0 0 0 0 0 0 0 0 1 2 0 0 1 0 0 0 0 0 0 1 2 1 0 1 0 0 0 0 0 0 0 0 0 1 1 1 0 0 1 2 1 1 0 0 0 0 1 0 0 2 0 0 0 1 1 0 0 0 0 0 0 0 0 0 0 0 0 0 0 0 0 0 0 0 0 1 2 0 2 0 0 1 0 1 0 1 0 0 0 1 0 1 0 0 0 1 0 0 1 0 3 0 0 0 0 1 1 0 0 0 0 0 1 0 0 0 1 0 0 0 0 0 0 0 0 1 2 0 1 0 0 0 0 0 0 0 0 0 1 0 0 0 0 0 0 0 0 0 0 0 1 0 0 1 0 0 0 0 1 0 0 0 2 1 0 3 1 2 1 1 0 0 0 0 0 0 0 1 0 0 1 0 0 0 0 0 0 1 0 0 0 0 0 0 1 0 0 0 0 0 0 0 0 1 1 0 0 0 0 0 0 0 0 0 0 0 0 0 0 0 0 1 0 0 0</counts>
			</dataPoints>
		</scan>
		<scan status="Completed" appendNumber="0" scanAxis="2Theta" mode="Continuous">
			<header>
				<startTimeStamp>2024-07-01T14:31:11-04:00</startTimeStamp>
				<endTimeStamp>2024-07-01T15:01:10-04:00</endTimeStamp>
				<author>
					<name>lw627</name>
				</author>
				<source>
					<applicationSoftware version="7.1">Data Collector</applicationSoftware>
					<instrumentControlSoftware version="8.2  20201204">EMPYREAN</instrumentControlSoftware>
					<instrumentID>0000000011260721</instrumentID>
				</source>
			</header>
			<dataPoints>
				<positions axis="2Theta" unit="deg">
					<startPosition>71.9832541063961</startPosition>
					<endPosition>75.3305238776126</endPosition>
				</positions>
				<positions axis="Omega" unit="deg">
					<commonPosition>18.2674444960022</commonPosition>
				</positions>
				<positions axis="Phi" unit="deg">
					<commonPosition>-88.77</commonPosition>
				</positions>
				<positions axis="Chi" unit="deg">
					<commonPosition>0</commonPosition>
				</positions>
				<positions axis="Z" unit="mm">
					<commonPosition>8.365</commonPosition>
				</positions>
				<commonCountingTime unit="seconds">0.974</commonCountingTime>
				<counts unit="counts">0 0 1 0 0 0 0 0 0 1 0 0 0 0 0 1 1 0 0 0 0 0 0 0 0 0 0 0 1 0 0 1 1 0 0 0 0 0 0 2 1 0 0 0 0 0 0 2 0 0 0 0 0 0 1 0 0 0 0 0 0 0 0 0 0 0 0 1 0 0 0 0 2 0 1 0 1 0 0 1 1 0 0 0 0 0 0 0 2 0 0 0 0 0 2 1 0 1 1 3 0 0 1 0 0 0 0 0 0 1 0 1 0 0 2 1 0 1 0 0 0 0 0 0 1 0 0 0 0 0 0 0 0 1 0 1 0 0 0 0 0 1 0 1 1 0 0 0 0 0 1 0 0 0 0 1 0 1 1 0 2 0 1 0 0 0 0 0 0 0 0 0 0 0 0 0 0 0 1 1 0 0 0 1 0 0 1 1 0 0 1 1 0 1 0 0 1 0 2 0 0 0 0 0 2 0 0 0 0 0 0 1 1 1 0 0 0 0 0 1 0 1 0 0 0 1 0 0 0 0 0 0 0 0 0 0 0 0 0 1 0 0 0 0 0 0 0 0 0 2 0 1 0 2 1</counts>
			</dataPoints>
		</scan>
		<scan status="Completed" appendNumber="0" scanAxis="2Theta" mode="Continuous">
			<header>
				<startTimeStamp>2024-07-01T14:31:11-04:00</startTimeStamp>
				<endTimeStamp>2024-07-01T15:01:10-04:00</endTimeStamp>
				<author>
					<name>lw627</name>
				</author>
				<source>
					<applicationSoftware version="7.1">Data Collector</applicationSoftware>
					<instrumentControlSoftware version="8.2  20201204">EMPYREAN</instrumentControlSoftware>
					<instrumentID>0000000011260721</instrumentID>
				</source>
			</header>
			<dataPoints>
				<positions axis="2Theta" unit="deg">
					<startPosition>71.9865366770643</startPosition>
					<endPosition>75.3338064482807</endPosition>
				</positions>
				<positions axis="Omega" unit="deg">
					<commonPosition>18.2690857813363</commonPosition>
				</positions>
				<positions axis="Phi" unit="deg">
					<commonPosition>-88.77</commonPosition>
				</positions>
				<positions axis="Chi" unit="deg">
					<commonPosition>0</commonPosition>
				</positions>
				<positions axis="Z" unit="mm">
					<commonPosition>8.365</commonPosition>
				</positions>
				<commonCountingTime unit="seconds">0.974</commonCountingTime>
				<counts unit="counts">0 1 0 0 1 0 1 0 2 0 1 0 0 0 0 0 2 0 0 0 0 1 0 1 0 0 0 1 0 0 0 0 0 0 0 0 0 0 0 0 0 0 0 0 1 1 0 0 0 0 0 0 1 0 1 0 0 0 0 0 0 0 0 0 0 0 0 0 0 0 1 0 0 1 0 0 0 1 0 1 0 0 0 0 1 0 1 0 1 1 1 0 1 0 0 0 0 0 1 0 2 0 0 1 0 0 0 0 0 0 0 0 0 0 1 0 0 0 0 2 0 0 1 0 0 1 0 0 0 0 0 0 2 0 0 0 0 0 0 1 0 0 1 0 0 1 1 0 0 0 1 0 0 0 0 0 0 0 0 0 0 0 0 1 0 0 0 0 0 0 0 2 0 0 0 0 0 1 2 0 1 0 0 0 2 1 1 0 0 0 0 0 0 1 0 2 1 0 0 0 0 0 0 0 0 1 1 0 0 0 0 0 1 0 0 1 0 0 1 0 0 0 0 0 0 0 0 0 1 0 0 0 0 0 1 0 1 0 0 0 1 0 1 0 0 0 1 0 0 0 0 0 0 0 0</counts>
			</dataPoints>
		</scan>
		<scan status="Completed" appendNumber="0" scanAxis="2Theta" mode="Continuous">
			<header>
				<startTimeStamp>2024-07-01T14:31:11-04:00</startTimeStamp>
				<endTimeStamp>2024-07-01T15:01:10-04:00</endTimeStamp>
				<author>
					<name>lw627</name>
				</author>
				<source>
					<applicationSoftware version="7.1">Data Collector</applicationSoftware>
					<instrumentControlSoftware version="8.2  20201204">EMPYREAN</instrumentControlSoftware>
					<instrumentID>0000000011260721</instrumentID>
				</source>
			</header>
			<dataPoints>
				<positions axis="2Theta" unit="deg">
					<startPosition>71.9898192477324</startPosition>
					<endPosition>75.3370890189489</endPosition>
				</positions>
				<positions axis="Omega" unit="deg">
					<commonPosition>18.2707270666703</commonPosition>
				</positions>
				<positions axis="Phi" unit="deg">
					<commonPosition>-88.77</commonPosition>
				</positions>
				<positions axis="Chi" unit="deg">
					<commonPosition>0</commonPosition>
				</positions>
				<positions axis="Z" unit="mm">
					<commonPosition>8.365</commonPosition>
				</positions>
				<commonCountingTime unit="seconds">0.974</commonCountingTime>
				<counts unit="counts">0 1 0 1 0 1 0 0 0 0 1 0 0 0 0 0 0 0 0 0 0 0 0 0 0 2 1 0 0 0 0 0 2 3 0 0 0 0 0 0 0 0 1 2 0 1 1 0 1 0 0 0 0 0 0 1 3 0 0 0 0 1 1 0 0 0 0 0 0 1 0 0 0 0 0 0 0 0 0 0 0 1 1 1 0 0 0 0 2 0 0 0 0 0 0 0 0 0 1 2 0 0 0 0 0 0 0 1 0 0 0 0 0 1 0 1 0 0 0 0 0 0 0 0 0 0 0 1 1 0 1 0 1 0 0 1 0 1 1 0 0 1 1 0 1 1 0 1 0 1 0 0 0 0 1 0 0 1 0 0 0 0 0 0 0 0 0 1 0 1 0 1 0 0 0 0 0 2 0 0 0 2 0 0 0 0 0 1 0 0 0 1 0 0 0 0 0 1 0 0 0 0 1 0 0 0 0 0 0 0 2 0 0 1 0 1 0 0 1 0 0 0 0 1 1 0 0 0 1 0 1 0 0 0 0 0 0 1 1 1 1 2 0 0 0 0 0 1 0 0 2 0 0 0 0</counts>
			</dataPoints>
		</scan>
		<scan status="Completed" appendNumber="0" scanAxis="2Theta" mode="Continuous">
			<header>
				<startTimeStamp>2024-07-01T14:31:11-04:00</startTimeStamp>
				<endTimeStamp>2024-07-01T15:01:10-04:00</endTimeStamp>
				<author>
					<name>lw627</name>
				</author>
				<source>
					<applicationSoftware version="7.1">Data Collector</applicationSoftware>
					<instrumentControlSoftware version="8.2  20201204">EMPYREAN</instrumentControlSoftware>
					<instrumentID>0000000011260721</instrumentID>
				</source>
			</header>
			<dataPoints>
				<positions axis="2Theta" unit="deg">
					<startPosition>71.9931018184005</startPosition>
					<endPosition>75.340371589617</endPosition>
				</positions>
				<positions axis="Omega" unit="deg">
					<commonPosition>18.2723683520044</commonPosition>
				</positions>
				<positions axis="Phi" unit="deg">
					<commonPosition>-88.77</commonPosition>
				</positions>
				<positions axis="Chi" unit="deg">
					<commonPosition>0</commonPosition>
				</positions>
				<positions axis="Z" unit="mm">
					<commonPosition>8.365</commonPosition>
				</positions>
				<commonCountingTime unit="seconds">0.974</commonCountingTime>
				<counts unit="counts">0 0 0 0 0 0 0 0 0 0 1 1 0 1 0 1 0 0 0 0 2 1 0 0 1 1 1 0 0 0 0 1 0 0 0 0 0 0 0 0 0 2 1 0 0 1 1 0 1 0 1 1 0 0 0 0 0 0 0 0 2 0 1 1 0 0 2 0 1 0 1 0 0 0 0 0 1 0 1 1 0 0 0 0 0 1 0 0 0 1 1 0 0 0 1 0 0 0 0 0 0 1 0 0 0 1 0 1 1 0 0 0 0 0 0 1 0 1 0 0 0 1 0 0 0 0 0 1 1 0 0 1 0 0 0 0 0 0 1 0 0 1 0 0 0 0 0 0 1 0 0 0 0 0 0 1 1 0 1 2 0 0 0 0 0 0 0 0 1 0 1 1 0 0 0 0 0 0 0 1 0 0 1 0 0 0 0 0 0 1 0 2 0 2 1 1 0 1 1 0 1 0 0 0 0 0 0 0 0 1 0 1 0 1 0 0 1 0 1 0 0 0 1 0 0 0 0 1 1 1 0 1 0 2 1 0 0 0 0 1 0 0 0 1 1 2 0 0 0 0 0 1 0 0 0</counts>
			</dataPoints>
		</scan>
		<scan status="Completed" appendNumber="0" scanAxis="2Theta" mode="Continuous">
			<header>
				<startTimeStamp>2024-07-01T14:31:11-04:00</startTimeStamp>
				<endTimeStamp>2024-07-01T15:01:10-04:00</endTimeStamp>
				<author>
					<name>lw627</name>
				</author>
				<source>
					<applicationSoftware version="7.1">Data Collector</applicationSoftware>
					<instrumentControlSoftware version="8.2  20201204">EMPYREAN</instrumentControlSoftware>
					<instrumentID>0000000011260721</instrumentID>
				</source>
			</header>
			<dataPoints>
				<positions axis="2Theta" unit="deg">
					<startPosition>71.9963843890687</startPosition>
					<endPosition>75.3436541602851</endPosition>
				</positions>
				<positions axis="Omega" unit="deg">
					<commonPosition>18.2740096373384</commonPosition>
				</positions>
				<positions axis="Phi" unit="deg">
					<commonPosition>-88.77</commonPosition>
				</positions>
				<positions axis="Chi" unit="deg">
					<commonPosition>0</commonPosition>
				</positions>
				<positions axis="Z" unit="mm">
					<commonPosition>8.365</commonPosition>
				</positions>
				<commonCountingTime unit="seconds">0.974</commonCountingTime>
				<counts unit="counts">0 0 0 0 0 0 0 0 1 2 1 1 0 0 1 0 0 0 0 0 1 0 1 0 0 0 1 0 1 0 0 0 0 0 0 0 0 1 0 1 0 0 0 0 0 0 0 0 1 0 0 0 0 0 0 1 0 0 0 0 0 1 0 0 0 0 0 0 0 1 0 0 1 0 0 0 0 2 1 0 0 1 0 0 0 0 0 0 0 0 0 1 2 0 0 1 1 0 0 1 0 0 0 0 0 0 0 0 0 0 1 0 1 0 0 0 0 0 1 0 0 0 0 0 0 0 1 0 0 0 0 0 0 0 0 0 0 0 0 0 0 0 1 0 0 0 1 0 0 1 0 0 1 0 0 0 1 1 1 0 0 0 0 0 0 1 0 0 0 1 0 0 2 1 1 0 0 0 0 0 0 0 1 0 1 0 0 0 0 0 3 0 0 0 0 1 1 0 0 0 0 0 2 1 0 0 0 1 1 1 1 0 0 0 2 0 1 0 0 1 0 0 0 0 0 0 0 0 0 0 0 1 0 1 1 0 1 0 0 0 3 0 3 0 0 1 0 0 1 0 0 0 0 0 0</counts>
			</dataPoints>
		</scan>
		<scan status="Completed" appendNumber="0" scanAxis="2Theta" mode="Continuous">
			<header>
				<startTimeStamp>2024-07-01T14:31:11-04:00</startTimeStamp>
				<endTimeStamp>2024-07-01T15:01:10-04:00</endTimeStamp>
				<author>
					<name>lw627</name>
				</author>
				<source>
					<applicationSoftware version="7.1">Data Collector</applicationSoftware>
					<instrumentControlSoftware version="8.2  20201204">EMPYREAN</instrumentControlSoftware>
					<instrumentID>0000000011260721</instrumentID>
				</source>
			</header>
			<dataPoints>
				<positions axis="2Theta" unit="deg">
					<startPosition>71.9996669597368</startPosition>
					<endPosition>75.3469367309532</endPosition>
				</positions>
				<positions axis="Omega" unit="deg">
					<commonPosition>18.2756509226725</commonPosition>
				</positions>
				<positions axis="Phi" unit="deg">
					<commonPosition>-88.77</commonPosition>
				</positions>
				<positions axis="Chi" unit="deg">
					<commonPosition>0</commonPosition>
				</positions>
				<positions axis="Z" unit="mm">
					<commonPosition>8.365</commonPosition>
				</positions>
				<commonCountingTime unit="seconds">0.974</commonCountingTime>
				<counts unit="counts">0 0 0 0 0 1 0 1 2 0 0 1 0 0 0 0 0 0 0 0 0 2 0 0 0 0 0 0 0 0 1 0 0 0 0 2 0 0 0 0 0 0 0 0 0 0 0 1 1 0 0 3 0 0 0 0 0 1 1 0 0 0 1 0 0 0 0 1 1 0 0 0 0 0 1 1 1 0 0 0 1 2 0 0 0 0 0 0 0 1 0 0 1 0 0 0 0 1 0 0 0 0 0 0 1 0 0 0 0 0 0 0 1 1 0 0 0 0 0 1 1 1 0 1 0 2 0 2 0 0 0 0 0 0 2 0 0 0 0 0 0 0 0 0 0 1 0 0 0 0 0 0 0 0 0 0 2 0 0 0 1 0 0 1 1 0 0 0 0 1 1 0 0 1 1 1 0 0 0 0 0 0 0 0 0 0 0 0 1 0 1 0 0 0 1 1 0 0 1 0 0 0 0 0 0 0 0 0 1 1 0 1 0 0 0 1 0 0 1 0 1 0 0 0 0 0 0 1 0 0 0 0 0 0 0 1 0 1 1 0 0 0 0 0 0 1 0 1 0 0 0 0 0 0 1</counts>
			</dataPoints>
		</scan>
		<scan status="Completed" appendNumber="0" scanAxis="2Theta" mode="Continuous">
			<header>
				<startTimeStamp>2024-07-01T14:31:11-04:00</startTimeStamp>
				<endTimeStamp>2024-07-01T15:01:10-04:00</endTimeStamp>
				<author>
					<name>lw627</name>
				</author>
				<source>
					<applicationSoftware version="7.1">Data Collector</applicationSoftware>
					<instrumentControlSoftware version="8.2  20201204">EMPYREAN</instrumentControlSoftware>
					<instrumentID>0000000011260721</instrumentID>
				</source>
			</header>
			<dataPoints>
				<positions axis="2Theta" unit="deg">
					<startPosition>72.0029495304049</startPosition>
					<endPosition>75.3502193016214</endPosition>
				</positions>
				<positions axis="Omega" unit="deg">
					<commonPosition>18.2772922080066</commonPosition>
				</positions>
				<positions axis="Phi" unit="deg">
					<commonPosition>-88.77</commonPosition>
				</positions>
				<positions axis="Chi" unit="deg">
					<commonPosition>0</commonPosition>
				</positions>
				<positions axis="Z" unit="mm">
					<commonPosition>8.365</commonPosition>
				</positions>
				<commonCountingTime unit="seconds">0.974</commonCountingTime>
				<counts unit="counts">0 0 0 0 0 1 0 0 0 0 0 0 0 0 0 0 0 0 0 0 0 1 0 0 1 1 1 0 1 0 0 0 0 1 0 0 0 0 2 0 0 0 0 1 0 1 0 1 0 0 0 1 0 2 0 0 0 0 0 0 1 0 0 0 0 0 0 0 1 1 0 0 0 0 0 0 0 0 0 0 0 1 0 0 1 0 1 0 0 0 0 0 0 1 0 0 1 0 1 1 1 0 0 0 0 2 0 0 1 1 0 0 0 0 0 0 0 1 0 0 1 0 0 0 1 0 0 0 0 0 1 1 0 1 0 0 1 0 0 0 1 1 1 1 0 0 0 0 2 1 0 1 0 0 0 0 0 1 0 0 1 0 1 0 0 0 0 0 0 0 0 1 1 1 0 0 0 2 0 2 0 0 1 1 0 0 0 0 0 1 1 0 1 0 1 0 2 1 0 1 0 1 1 0 0 0 0 0 0 0 0 0 0 0 2 0 0 0 1 0 0 1 0 0 0 0 0 0 1 1 1 0 2 0 0 0 0 0 0 0 0 0 0 0 0 0 0 1 0 1 0 0 0 1 1</counts>
			</dataPoints>
		</scan>
		<scan status="Completed" appendNumber="0" scanAxis="2Theta" mode="Continuous">
			<header>
				<startTimeStamp>2024-07-01T14:31:11-04:00</startTimeStamp>
				<endTimeStamp>2024-07-01T15:01:10-04:00</endTimeStamp>
				<author>
					<name>lw627</name>
				</author>
				<source>
					<applicationSoftware version="7.1">Data Collector</applicationSoftware>
					<instrumentControlSoftware version="8.2  20201204">EMPYREAN</instrumentControlSoftware>
					<instrumentID>0000000011260721</instrumentID>
				</source>
			</header>
			<dataPoints>
				<positions axis="2Theta" unit="deg">
					<startPosition>72.006232101073</startPosition>
					<endPosition>75.3535018722895</endPosition>
				</positions>
				<positions axis="Omega" unit="deg">
					<commonPosition>18.2789334933406</commonPosition>
				</positions>
				<positions axis="Phi" unit="deg">
					<commonPosition>-88.77</commonPosition>
				</positions>
				<positions axis="Chi" unit="deg">
					<commonPosition>0</commonPosition>
				</positions>
				<positions axis="Z" unit="mm">
					<commonPosition>8.365</commonPosition>
				</positions>
				<commonCountingTime unit="seconds">0.974</commonCountingTime>
				<counts unit="counts">0 0 0 0 2 0 0 2 0 0 0 0 0 0 0 0 1 0 0 0 0 0 0 0 0 0 0 2 1 0 0 1 0 0 0 0 1 0 0 1 2 0 1 0 0 2 2 0 1 0 0 0 0 0 0 0 0 0 2 1 0 1 1 1 0 0 0 0 0 0 0 0 0 0 0 0 1 0 1 0 0 0 0 0 0 0 0 1 0 0 0 0 2 0 0 0 0 0 0 0 0 0 0 1 1 0 0 0 0 1 0 0 0 0 1 0 0 0 0 0 0 0 0 1 1 0 0 0 0 0 0 1 1 0 0 1 0 0 0 0 1 0 0 0 0 0 1 0 0 0 0 0 0 0 0 0 0 0 0 0 0 0 0 1 0 0 0 1 0 1 0 0 0 0 0 0 1 0 1 0 0 0 0 0 1 1 0 0 0 2 0 0 1 1 0 0 1 1 0 1 0 0 0 0 0 1 0 0 1 0 0 0 0 0 1 0 2 0 1 0 0 1 0 0 0 1 1 0 0 0 0 1 0 0 0 2 1 0 0 0 0 0 0 0 1 0 0 0 0 1 0 0 0 1 1</counts>
			</dataPoints>
		</scan>
		<scan status="Completed" appendNumber="0" scanAxis="2Theta" mode="Continuous">
			<header>
				<startTimeStamp>2024-07-01T14:31:11-04:00</startTimeStamp>
				<endTimeStamp>2024-07-01T15:01:10-04:00</endTimeStamp>
				<author>
					<name>lw627</name>
				</author>
				<source>
					<applicationSoftware version="7.1">Data Collector</applicationSoftware>
					<instrumentControlSoftware version="8.2  20201204">EMPYREAN</instrumentControlSoftware>
					<instrumentID>0000000011260721</instrumentID>
				</source>
			</header>
			<dataPoints>
				<positions axis="2Theta" unit="deg">
					<startPosition>72.0095146717412</startPosition>
					<endPosition>75.3567844429576</endPosition>
				</positions>
				<positions axis="Omega" unit="deg">
					<commonPosition>18.2805747786747</commonPosition>
				</positions>
				<positions axis="Phi" unit="deg">
					<commonPosition>-88.77</commonPosition>
				</positions>
				<positions axis="Chi" unit="deg">
					<commonPosition>0</commonPosition>
				</positions>
				<positions axis="Z" unit="mm">
					<commonPosition>8.365</commonPosition>
				</positions>
				<commonCountingTime unit="seconds">0.974</commonCountingTime>
				<counts unit="counts">0 0 0 0 0 0 0 1 2 0 0 0 0 0 0 0 1 0 1 1 1 1 0 1 3 0 0 0 0 0 0 0 0 1 1 0 2 0 0 0 0 1 1 0 1 0 0 1 0 0 2 0 0 1 0 0 0 0 1 1 0 0 0 0 0 0 0 1 0 0 0 0 0 0 1 0 0 0 0 0 1 0 0 0 0 1 0 0 1 0 0 0 1 1 0 0 0 0 0 0 0 0 0 0 0 0 0 0 0 0 0 1 1 1 0 0 0 1 0 1 0 0 0 0 1 1 0 2 1 1 2 0 0 1 0 0 0 0 0 0 0 0 1 0 0 0 0 0 0 0 0 0 0 0 1 1 0 1 0 1 0 1 1 0 1 0 0 0 0 0 0 0 0 1 0 0 2 1 0 0 0 1 0 0 0 0 0 2 0 1 1 0 0 2 0 2 0 1 0 2 0 0 0 0 0 0 0 1 0 1 1 0 0 1 0 0 0 0 0 0 0 1 0 0 1 0 0 0 1 1 1 0 0 1 0 0 0 0 0 0 0 1 0 1 2 0 0 0 0 0 0 0 0 0 0</counts>
			</dataPoints>
		</scan>
		<scan status="Completed" appendNumber="0" scanAxis="2Theta" mode="Continuous">
			<header>
				<startTimeStamp>2024-07-01T14:31:11-04:00</startTimeStamp>
				<endTimeStamp>2024-07-01T15:01:10-04:00</endTimeStamp>
				<author>
					<name>lw627</name>
				</author>
				<source>
					<applicationSoftware version="7.1">Data Collector</applicationSoftware>
					<instrumentControlSoftware version="8.2  20201204">EMPYREAN</instrumentControlSoftware>
					<instrumentID>0000000011260721</instrumentID>
				</source>
			</header>
			<dataPoints>
				<positions axis="2Theta" unit="deg">
					<startPosition>72.0127972424093</startPosition>
					<endPosition>75.3600670136258</endPosition>
				</positions>
				<positions axis="Omega" unit="deg">
					<commonPosition>18.2822160640088</commonPosition>
				</positions>
				<positions axis="Phi" unit="deg">
					<commonPosition>-88.77</commonPosition>
				</positions>
				<positions axis="Chi" unit="deg">
					<commonPosition>0</commonPosition>
				</positions>
				<positions axis="Z" unit="mm">
					<commonPosition>8.365</commonPosition>
				</positions>
				<commonCountingTime unit="seconds">0.974</commonCountingTime>
				<counts unit="counts">0 1 0 0 2 0 0 0 3 0 0 0 0 0 0 2 0 0 0 1 2 1 0 0 0 1 1 0 1 0 1 1 0 0 0 0 0 0 0 0 1 0 0 0 1 0 1 1 0 1 1 1 1 0 0 0 0 1 1 1 1 0 0 1 0 0 1 0 0 1 0 0 0 0 0 0 0 0 0 1 1 1 0 0 0 0 0 0 0 0 0 0 1 0 2 0 0 0 0 1 0 0 0 0 1 0 0 0 0 1 0 0 0 1 0 0 0 1 1 1 0 1 0 1 1 0 0 1 0 1 1 0 1 0 0 0 1 0 0 0 0 0 0 0 0 1 1 1 0 0 0 0 0 0 2 0 0 0 1 0 0 0 0 0 1 3 0 0 0 0 0 0 1 0 0 1 0 0 0 2 0 0 0 0 2 0 0 1 0 0 2 1 0 0 1 0 0 0 0 1 0 0 1 0 0 0 1 0 0 0 0 0 0 0 0 0 1 0 1 1 0 0 0 0 0 0 0 1 2 0 1 0 0 0 1 0 1 0 0 0 1 0 1 0 0 0 1 0 0 0 0 0 1 0 0</counts>
			</dataPoints>
		</scan>
		<scan status="Completed" appendNumber="0" scanAxis="2Theta" mode="Continuous">
			<header>
				<startTimeStamp>2024-07-01T14:31:11-04:00</startTimeStamp>
				<endTimeStamp>2024-07-01T15:01:10-04:00</endTimeStamp>
				<author>
					<name>lw627</name>
				</author>
				<source>
					<applicationSoftware version="7.1">Data Collector</applicationSoftware>
					<instrumentControlSoftware version="8.2  20201204">EMPYREAN</instrumentControlSoftware>
					<instrumentID>0000000011260721</instrumentID>
				</source>
			</header>
			<dataPoints>
				<positions axis="2Theta" unit="deg">
					<startPosition>72.0160798130774</startPosition>
					<endPosition>75.3633495842939</endPosition>
				</positions>
				<positions axis="Omega" unit="deg">
					<commonPosition>18.2838573493428</commonPosition>
				</positions>
				<positions axis="Phi" unit="deg">
					<commonPosition>-88.77</commonPosition>
				</positions>
				<positions axis="Chi" unit="deg">
					<commonPosition>0</commonPosition>
				</positions>
				<positions axis="Z" unit="mm">
					<commonPosition>8.365</commonPosition>
				</positions>
				<commonCountingTime unit="seconds">0.974</commonCountingTime>
				<counts unit="counts">1 0 0 0 0 0 1 0 0 0 0 1 0 1 0 1 0 0 1 0 1 0 0 1 0 0 0 0 0 1 1 0 0 0 0 1 1 0 0 0 0 0 0 0 0 0 0 0 0 0 0 0 0 0 0 0 0 0 0 1 1 0 0 0 0 0 1 0 0 0 2 0 0 1 0 0 1 0 1 0 1 0 1 0 0 1 0 0 0 0 1 0 2 1 0 2 0 0 0 0 1 0 0 0 0 0 0 0 1 1 0 0 0 1 0 0 0 0 1 0 0 0 1 0 1 1 0 0 0 1 0 0 0 1 0 1 0 0 0 0 1 0 0 2 1 0 0 1 0 0 0 0 1 0 0 0 0 0 0 0 0 1 2 1 2 0 0 0 2 0 0 0 0 0 0 1 1 1 0 0 0 0 0 0 1 1 0 1 0 0 0 1 1 0 1 1 1 1 0 1 0 0 2 0 1 1 0 0 0 0 0 1 0 1 0 0 0 0 0 0 0 0 0 0 0 0 0 0 0 0 0 1 0 2 2 1 1 1 1 1 0 1 3 0 0 0 0 1 0 1 0 0 1 0 0</counts>
			</dataPoints>
		</scan>
		<scan status="Completed" appendNumber="0" scanAxis="2Theta" mode="Continuous">
			<header>
				<startTimeStamp>2024-07-01T14:31:11-04:00</startTimeStamp>
				<endTimeStamp>2024-07-01T15:01:10-04:00</endTimeStamp>
				<author>
					<name>lw627</name>
				</author>
				<source>
					<applicationSoftware version="7.1">Data Collector</applicationSoftware>
					<instrumentControlSoftware version="8.2  20201204">EMPYREAN</instrumentControlSoftware>
					<instrumentID>0000000011260721</instrumentID>
				</source>
			</header>
			<dataPoints>
				<positions axis="2Theta" unit="deg">
					<startPosition>72.0193623837455</startPosition>
					<endPosition>75.366632154962</endPosition>
				</positions>
				<positions axis="Omega" unit="deg">
					<commonPosition>18.2854986346769</commonPosition>
				</positions>
				<positions axis="Phi" unit="deg">
					<commonPosition>-88.77</commonPosition>
				</positions>
				<positions axis="Chi" unit="deg">
					<commonPosition>0</commonPosition>
				</positions>
				<positions axis="Z" unit="mm">
					<commonPosition>8.365</commonPosition>
				</positions>
				<commonCountingTime unit="seconds">0.974</commonCountingTime>
				<counts unit="counts">0 1 0 0 0 2 0 0 2 0 0 0 1 0 0 0 0 0 0 0 0 0 1 0 0 2 0 1 0 0 0 0 0 1 0 0 1 0 1 1 0 0 0 0 0 0 0 0 1 0 0 0 1 0 0 0 0 0 0 0 0 0 0 1 0 0 0 0 1 1 1 0 0 0 1 1 0 0 1 0 1 0 1 1 0 0 1 1 1 0 0 0 1 0 0 0 1 0 1 0 0 1 0 0 0 0 0 0 0 0 0 0 1 0 0 0 0 0 1 0 0 1 1 0 0 0 1 1 0 0 0 1 0 0 0 0 1 0 0 1 0 0 0 1 0 1 0 0 0 0 1 1 0 0 1 2 0 0 1 0 1 0 0 0 0 0 1 0 0 1 0 1 0 0 0 0 0 1 0 0 1 0 0 1 0 0 0 0 0 0 1 0 1 0 0 0 0 1 0 0 0 1 0 0 0 0 1 0 0 0 0 1 0 0 0 1 0 0 0 0 0 0 1 0 1 0 0 0 0 0 1 0 0 0 0 0 1 0 1 0 0 0 0 0 1 0 0 2 4 1 1 2 1 1 0</counts>
			</dataPoints>
		</scan>
		<scan status="Completed" appendNumber="0" scanAxis="2Theta" mode="Continuous">
			<header>
				<startTimeStamp>2024-07-01T14:31:11-04:00</startTimeStamp>
				<endTimeStamp>2024-07-01T15:01:10-04:00</endTimeStamp>
				<author>
					<name>lw627</name>
				</author>
				<source>
					<applicationSoftware version="7.1">Data Collector</applicationSoftware>
					<instrumentControlSoftware version="8.2  20201204">EMPYREAN</instrumentControlSoftware>
					<instrumentID>0000000011260721</instrumentID>
				</source>
			</header>
			<dataPoints>
				<positions axis="2Theta" unit="deg">
					<startPosition>72.0226449544137</startPosition>
					<endPosition>75.3699147256301</endPosition>
				</positions>
				<positions axis="Omega" unit="deg">
					<commonPosition>18.287139920011</commonPosition>
				</positions>
				<positions axis="Phi" unit="deg">
					<commonPosition>-88.77</commonPosition>
				</positions>
				<positions axis="Chi" unit="deg">
					<commonPosition>0</commonPosition>
				</positions>
				<positions axis="Z" unit="mm">
					<commonPosition>8.365</commonPosition>
				</positions>
				<commonCountingTime unit="seconds">0.974</commonCountingTime>
				<counts unit="counts">0 0 0 1 1 1 2 1 0 0 0 0 0 0 0 0 0 0 0 0 1 0 0 0 0 0 0 1 0 0 0 0 2 0 0 1 0 0 2 0 1 0 0 0 0 0 0 0 0 0 1 1 0 0 0 0 1 0 0 0 2 0 0 0 0 1 0 0 0 1 0 0 1 0 0 0 0 0 0 0 0 0 0 1 0 1 2 1 0 0 1 2 1 0 0 1 0 0 1 0 0 2 0 0 0 1 0 0 2 0 0 0 0 0 1 0 0 0 0 1 0 0 0 0 0 1 0 0 0 0 0 0 0 0 0 0 2 1 0 0 0 0 0 0 0 0 1 0 0 1 0 0 0 0 2 1 1 1 0 0 0 0 0 0 0 0 0 0 0 2 2 0 0 0 0 0 0 0 0 0 0 0 1 1 1 0 0 0 0 0 1 0 0 2 1 1 0 0 1 0 0 1 0 1 0 1 0 0 0 1 1 0 0 0 0 0 2 0 1 0 0 2 1 2 2 2 1 0 1 0 0 0 0 0 1 1 0 1 0 0 0 1 0 0 0 0 0 0 1 1 0 1 1 0 0</counts>
			</dataPoints>
		</scan>
		<scan status="Completed" appendNumber="0" scanAxis="2Theta" mode="Continuous">
			<header>
				<startTimeStamp>2024-07-01T14:31:11-04:00</startTimeStamp>
				<endTimeStamp>2024-07-01T15:01:10-04:00</endTimeStamp>
				<author>
					<name>lw627</name>
				</author>
				<source>
					<applicationSoftware version="7.1">Data Collector</applicationSoftware>
					<instrumentControlSoftware version="8.2  20201204">EMPYREAN</instrumentControlSoftware>
					<instrumentID>0000000011260721</instrumentID>
				</source>
			</header>
			<dataPoints>
				<positions axis="2Theta" unit="deg">
					<startPosition>72.0259275250818</startPosition>
					<endPosition>75.3731972962983</endPosition>
				</positions>
				<positions axis="Omega" unit="deg">
					<commonPosition>18.288781205345</commonPosition>
				</positions>
				<positions axis="Phi" unit="deg">
					<commonPosition>-88.77</commonPosition>
				</positions>
				<positions axis="Chi" unit="deg">
					<commonPosition>0</commonPosition>
				</positions>
				<positions axis="Z" unit="mm">
					<commonPosition>8.365</commonPosition>
				</positions>
				<commonCountingTime unit="seconds">0.974</commonCountingTime>
				<counts unit="counts">0 0 1 0 0 1 0 2 0 0 0 0 0 0 2 0 0 0 0 0 0 0 0 0 1 0 0 0 2 0 0 0 0 0 0 0 1 0 1 1 0 0 0 1 0 1 1 0 0 0 0 0 0 0 0 1 0 0 1 0 0 0 0 0 0 1 1 0 0 1 1 1 0 1 0 0 1 0 0 0 1 0 0 0 1 0 1 0 0 1 0 0 1 0 0 0 1 1 0 2 0 0 0 0 0 1 1 1 0 2 0 0 0 0 0 0 0 0 0 1 0 1 2 1 0 0 1 1 0 0 0 0 0 1 2 1 0 0 0 0 0 0 0 1 0 0 0 0 2 0 0 0 0 0 0 1 0 1 0 2 0 0 0 0 0 0 0 0 1 0 1 0 0 0 0 0 1 1 0 1 1 1 0 0 1 1 0 0 0 1 0 0 0 0 2 0 0 0 0 0 0 1 0 1 0 0 0 0 0 0 0 0 0 0 0 0 0 0 1 0 0 0 1 0 0 0 0 0 0 1 0 0 0 0 0 1 1 0 0 1 2 0 0 0 1 0 0 0 1 0 0 0 0 0 0</counts>
			</dataPoints>
		</scan>
		<scan status="Completed" appendNumber="0" scanAxis="2Theta" mode="Continuous">
			<header>
				<startTimeStamp>2024-07-01T14:31:11-04:00</startTimeStamp>
				<endTimeStamp>2024-07-01T15:01:10-04:00</endTimeStamp>
				<author>
					<name>lw627</name>
				</author>
				<source>
					<applicationSoftware version="7.1">Data Collector</applicationSoftware>
					<instrumentControlSoftware version="8.2  20201204">EMPYREAN</instrumentControlSoftware>
					<instrumentID>0000000011260721</instrumentID>
				</source>
			</header>
			<dataPoints>
				<positions axis="2Theta" unit="deg">
					<startPosition>72.0292100957499</startPosition>
					<endPosition>75.3764798669664</endPosition>
				</positions>
				<positions axis="Omega" unit="deg">
					<commonPosition>18.2904224906791</commonPosition>
				</positions>
				<positions axis="Phi" unit="deg">
					<commonPosition>-88.77</commonPosition>
				</positions>
				<positions axis="Chi" unit="deg">
					<commonPosition>0</commonPosition>
				</positions>
				<positions axis="Z" unit="mm">
					<commonPosition>8.365</commonPosition>
				</positions>
				<commonCountingTime unit="seconds">0.974</commonCountingTime>
				<counts unit="counts">0 0 0 1 0 0 0 1 0 0 0 0 1 1 0 0 1 1 0 1 0 0 0 0 1 0 0 1 1 0 0 0 0 1 1 0 0 1 0 1 0 1 0 0 0 0 0 1 0 0 0 1 0 1 1 0 0 0 1 0 0 0 0 0 0 1 1 2 0 0 0 0 1 1 1 0 1 2 0 0 0 0 1 0 0 1 0 0 1 1 0 0 1 0 0 1 0 1 0 1 1 1 0 0 0 0 0 0 0 0 0 0 0 0 0 1 0 0 1 0 0 0 1 0 0 0 1 0 1 0 0 0 0 0 0 0 2 0 0 0 1 0 2 0 0 1 0 1 0 0 0 1 1 0 0 0 0 0 0 0 1 0 0 1 1 0 0 1 1 1 0 0 1 1 0 0 1 0 1 0 0 0 1 1 0 0 0 0 0 0 0 2 1 0 0 0 0 0 1 0 0 0 0 1 0 0 0 1 0 0 0 0 0 1 1 1 0 1 0 0 1 0 0 0 1 0 0 0 1 0 0 0 1 1 0 0 0 1 0 0 0 0 2 0 0 1 1 0 0 0 0 0 1 2 0</counts>
			</dataPoints>
		</scan>
		<scan status="Completed" appendNumber="0" scanAxis="2Theta" mode="Continuous">
			<header>
				<startTimeStamp>2024-07-01T14:31:11-04:00</startTimeStamp>
				<endTimeStamp>2024-07-01T15:01:10-04:00</endTimeStamp>
				<author>
					<name>lw627</name>
				</author>
				<source>
					<applicationSoftware version="7.1">Data Collector</applicationSoftware>
					<instrumentControlSoftware version="8.2  20201204">EMPYREAN</instrumentControlSoftware>
					<instrumentID>0000000011260721</instrumentID>
				</source>
			</header>
			<dataPoints>
				<positions axis="2Theta" unit="deg">
					<startPosition>72.0324926664181</startPosition>
					<endPosition>75.3797624376345</endPosition>
				</positions>
				<positions axis="Omega" unit="deg">
					<commonPosition>18.2920637760131</commonPosition>
				</positions>
				<positions axis="Phi" unit="deg">
					<commonPosition>-88.77</commonPosition>
				</positions>
				<positions axis="Chi" unit="deg">
					<commonPosition>0</commonPosition>
				</positions>
				<positions axis="Z" unit="mm">
					<commonPosition>8.365</commonPosition>
				</positions>
				<commonCountingTime unit="seconds">0.974</commonCountingTime>
				<counts unit="counts">0 1 0 0 0 1 0 0 0 0 1 0 1 0 0 0 1 1 0 0 0 1 0 0 0 0 1 0 0 0 0 0 0 0 0 0 0 0 0 0 0 0 0 1 0 0 1 1 0 0 0 1 0 1 0 0 0 0 0 0 1 1 1 0 0 2 0 1 0 0 0 0 0 1 0 0 0 1 1 1 0 0 0 0 0 0 1 1 0 0 0 0 0 1 1 1 0 0 0 0 0 1 1 1 0 0 0 1 0 0 0 1 0 1 0 0 0 1 0 1 0 0 0 1 0 1 0 0 1 1 0 0 1 0 1 0 1 1 0 1 1 0 0 0 0 0 0 0 0 0 0 0 1 0 0 0 0 0 1 0 0 0 0 0 1 0 0 0 0 0 0 0 0 0 0 0 0 0 0 1 0 1 0 0 0 0 0 1 1 2 1 1 0 0 2 0 0 0 1 0 0 1 0 1 0 0 0 0 0 1 0 1 0 0 0 0 1 0 0 0 0 0 0 0 0 0 0 0 1 0 1 0 0 0 0 2 0 0 0 0 0 1 0 0 0 1 0 0 0 0 0 1 2 1 0</counts>
			</dataPoints>
		</scan>
		<scan status="Completed" appendNumber="0" scanAxis="2Theta" mode="Continuous">
			<header>
				<startTimeStamp>2024-07-01T14:31:11-04:00</startTimeStamp>
				<endTimeStamp>2024-07-01T15:01:10-04:00</endTimeStamp>
				<author>
					<name>lw627</name>
				</author>
				<source>
					<applicationSoftware version="7.1">Data Collector</applicationSoftware>
					<instrumentControlSoftware version="8.2  20201204">EMPYREAN</instrumentControlSoftware>
					<instrumentID>0000000011260721</instrumentID>
				</source>
			</header>
			<dataPoints>
				<positions axis="2Theta" unit="deg">
					<startPosition>72.0357752370862</startPosition>
					<endPosition>75.3830450083026</endPosition>
				</positions>
				<positions axis="Omega" unit="deg">
					<commonPosition>18.2937050613472</commonPosition>
				</positions>
				<positions axis="Phi" unit="deg">
					<commonPosition>-88.77</commonPosition>
				</positions>
				<positions axis="Chi" unit="deg">
					<commonPosition>0</commonPosition>
				</positions>
				<positions axis="Z" unit="mm">
					<commonPosition>8.365</commonPosition>
				</positions>
				<commonCountingTime unit="seconds">0.974</commonCountingTime>
				<counts unit="counts">1 1 0 0 0 0 0 0 1 0 0 0 1 1 1 0 2 0 0 1 0 0 0 0 0 0 0 0 0 0 0 0 0 0 0 1 0 1 1 0 0 0 0 0 0 0 0 0 1 1 0 1 1 0 1 0 0 0 0 2 0 0 1 0 0 0 0 0 0 0 1 0 0 0 2 0 0 1 0 1 0 0 0 0 0 0 0 0 1 0 1 0 0 1 0 0 0 0 1 1 1 0 0 0 0 0 0 0 0 1 0 0 0 0 1 0 1 0 0 0 0 0 0 1 0 1 0 0 0 0 0 0 0 1 2 0 0 1 0 0 1 0 0 0 0 0 1 0 0 0 0 0 0 0 1 0 0 1 1 0 0 0 0 0 0 1 0 1 0 0 0 0 0 0 1 0 0 0 0 0 0 0 0 0 0 1 0 0 0 0 0 1 0 0 2 0 1 0 0 1 1 0 0 0 0 0 0 0 0 1 0 0 0 1 1 0 1 1 0 0 0 0 1 0 0 1 2 0 0 0 0 0 0 1 0 0 0 0 2 0 0 0 0 0 0 0 0 0 0 0 0 0 0 0 0</counts>
			</dataPoints>
		</scan>
		<scan status="Completed" appendNumber="0" scanAxis="2Theta" mode="Continuous">
			<header>
				<startTimeStamp>2024-07-01T14:31:11-04:00</startTimeStamp>
				<endTimeStamp>2024-07-01T15:01:10-04:00</endTimeStamp>
				<author>
					<name>lw627</name>
				</author>
				<source>
					<applicationSoftware version="7.1">Data Collector</applicationSoftware>
					<instrumentControlSoftware version="8.2  20201204">EMPYREAN</instrumentControlSoftware>
					<instrumentID>0000000011260721</instrumentID>
				</source>
			</header>
			<dataPoints>
				<positions axis="2Theta" unit="deg">
					<startPosition>72.0390578077543</startPosition>
					<endPosition>75.3863275789708</endPosition>
				</positions>
				<positions axis="Omega" unit="deg">
					<commonPosition>18.2953463466813</commonPosition>
				</positions>
				<positions axis="Phi" unit="deg">
					<commonPosition>-88.77</commonPosition>
				</positions>
				<positions axis="Chi" unit="deg">
					<commonPosition>0</commonPosition>
				</positions>
				<positions axis="Z" unit="mm">
					<commonPosition>8.365</commonPosition>
				</positions>
				<commonCountingTime unit="seconds">0.974</commonCountingTime>
[...]
				</positions>
				<positions axis="Z" unit="mm">
					<commonPosition>8.365</commonPosition>
				</positions>
				<commonCountingTime unit="seconds">0.974</commonCountingTime>
				<counts unit="counts">0 1 0 0 0 0 0 0 0 0 0 1 0 1 0 0 0 0 0 0 0 0 0 0 0 1 0 0 0 1 1 0 0 0 1 1 1 0 1 0 0 0 0 0 0 1 0 1 0 1 0 1 0 0 0 0 0 1 0 1 0 1 0 0 0 0 0 1 0 0 1 0 1 3 1 0 1 1 1 0 1 0 0 1 2 0 0 0 0 1 0 1 0 1 1 0 0 0 0 0 0 1 1 0 1 0 1 2 0 0 0 0 0 0 1 0 0 2 1 0 0 0 1 0 0 0 0 0 0 0 0 0 2 1 0 0 2 1 1 0 0 0 0 1 0 0 0 0 0 0 0 1 0 0 0 0 0 0 0 1 0 0 1 0 0 0 0 0 0 0 0 0 0 0 1 1 1 0 0 0 0 1 0 0 0 0 0 0 0 0 0 0 0 0 0 0 1 0 0 0 0 0 0 0 1 0 0 0 0 0 0 1 0 0 0 0 0 1 0 0 0 0 0 2 1 1 0 0 0 0 0 0 0 0 0 1 0 0 0 0 2 0 0 0 0 1 0 0 0 0 0 0 0 0 1</counts>
			</dataPoints>
		</scan>
		<scan status="Completed" appendNumber="0" scanAxis="2Theta" mode="Continuous">
			<header>
				<startTimeStamp>2024-07-01T14:31:11-04:00</startTimeStamp>
				<endTimeStamp>2024-07-01T15:01:10-04:00</endTimeStamp>
				<author>
					<name>lw627</name>
				</author>
				<source>
					<applicationSoftware version="7.1">Data Collector</applicationSoftware>
					<instrumentControlSoftware version="8.2  20201204">EMPYREAN</instrumentControlSoftware>
					<instrumentID>0000000011260721</instrumentID>
				</source>
			</header>
			<dataPoints>
				<positions axis="2Theta" unit="deg">
					<startPosition>77.9345547277105</startPosition>
					<endPosition>81.281824498927</endPosition>
				</positions>
				<positions axis="Omega" unit="deg">
					<commonPosition>21.2430948066594</commonPosition>
				</positions>
				<positions axis="Phi" unit="deg">
					<commonPosition>-88.77</commonPosition>
				</positions>
				<positions axis="Chi" unit="deg">
					<commonPosition>0</commonPosition>
				</positions>
				<positions axis="Z" unit="mm">
					<commonPosition>8.365</commonPosition>
				</positions>
				<commonCountingTime unit="seconds">0.974</commonCountingTime>
				<counts unit="counts">0 1 0 0 0 0 1 0 1 0 1 0 0 2 0 0 0 0 0 1 0 0 0 0 0 0 1 0 0 0 1 0 0 0 0 0 0 0 1 1 0 2 0 0 0 1 0 0 0 0 0 0 0 0 0 0 0 1 1 0 0 0 0 0 1 0 0 0 0 0 1 0 0 0 0 0 1 1 0 0 0 0 0 0 0 0 2 0 1 0 0 0 1 1 0 0 0 0 0 0 0 0 1 0 1 1 1 1 1 0 1 2 0 0 0 1 1 0 1 1 0 0 1 0 1 0 0 0 0 0 0 0 0 0 0 0 0 0 0 1 0 0 0 0 0 0 0 0 0 0 0 0 0 2 0 0 0 0 1 0 0 1 0 0 1 0 0 0 0 1 0 0 0 0 0 0 1 0 0 1 0 0 0 0 1 0 0 0 0 0 0 0 1 1 1 0 0 0 0 1 1 0 0 1 2 0 0 0 0 0 0 0 0 0 0 0 0 0 1 0 0 0 0 0 0 0 1 0 0 0 0 0 0 0 0 0 1 0 0 0 0 0 0 1 0 0 0 0 0 0 0 0 0 0 0</counts>
			</dataPoints>
		</scan>
		<scan status="Completed" appendNumber="0" scanAxis="2Theta" mode="Continuous">
			<header>
				<startTimeStamp>2024-07-01T14:31:11-04:00</startTimeStamp>
				<endTimeStamp>2024-07-01T15:01:10-04:00</endTimeStamp>
				<author>
					<name>lw627</name>
				</author>
				<source>
					<applicationSoftware version="7.1">Data Collector</applicationSoftware>
					<instrumentControlSoftware version="8.2  20201204">EMPYREAN</instrumentControlSoftware>
					<instrumentID>0000000011260721</instrumentID>
				</source>
			</header>
			<dataPoints>
				<positions axis="2Theta" unit="deg">
					<startPosition>77.9378372983786</startPosition>
					<endPosition>81.2851070695951</endPosition>
				</positions>
				<positions axis="Omega" unit="deg">
					<commonPosition>21.2447360919934</commonPosition>
				</positions>
				<positions axis="Phi" unit="deg">
					<commonPosition>-88.77</commonPosition>
				</positions>
				<positions axis="Chi" unit="deg">
					<commonPosition>0</commonPosition>
				</positions>
				<positions axis="Z" unit="mm">
					<commonPosition>8.365</commonPosition>
				</positions>
				<commonCountingTime unit="seconds">0.974</commonCountingTime>
				<counts unit="counts">0 1 0 0 0 0 1 0 0 0 0 0 2 2 0 1 1 1 3 1 0 0 1 0 0 0 0 0 0 2 0 0 0 1 0 1 1 0 0 0 0 0 1 0 0 0 1 0 0 0 0 0 0 0 0 0 1 0 1 0 0 0 0 0 0 0 0 0 1 0 0 1 0 0 0 1 1 0 0 1 0 0 0 0 0 0 1 1 1 2 0 1 1 0 0 1 2 0 0 0 0 0 0 1 0 1 1 1 0 0 0 2 1 0 2 1 0 0 2 0 0 1 0 0 0 0 0 0 0 0 1 0 0 0 0 0 1 1 1 1 2 0 0 0 0 1 0 0 0 0 0 0 0 0 1 0 0 0 1 0 0 0 1 0 0 0 2 0 0 2 1 0 0 0 0 0 0 0 1 1 1 0 0 0 1 0 3 0 1 0 0 1 0 0 0 0 0 0 0 0 0 0 0 0 0 0 0 0 0 2 2 0 1 2 1 1 1 0 0 0 0 2 1 0 0 0 0 0 1 0 0 0 0 0 1 0 0 0 0 0 1 0 0 0 0 0 0 0 0 0 0 1 0 0 0</counts>
			</dataPoints>
		</scan>
		<scan status="Completed" appendNumber="0" scanAxis="2Theta" mode="Continuous">
			<header>
				<startTimeStamp>2024-07-01T14:31:11-04:00</startTimeStamp>
				<endTimeStamp>2024-07-01T15:01:10-04:00</endTimeStamp>
				<author>
					<name>lw627</name>
				</author>
				<source>
					<applicationSoftware version="7.1">Data Collector</applicationSoftware>
					<instrumentControlSoftware version="8.2  20201204">EMPYREAN</instrumentControlSoftware>
					<instrumentID>0000000011260721</instrumentID>
				</source>
			</header>
			<dataPoints>
				<positions axis="2Theta" unit="deg">
					<startPosition>77.9411198690467</startPosition>
					<endPosition>81.2883896402632</endPosition>
				</positions>
				<positions axis="Omega" unit="deg">
					<commonPosition>21.2463773773275</commonPosition>
				</positions>
				<positions axis="Phi" unit="deg">
					<commonPosition>-88.77</commonPosition>
				</positions>
				<positions axis="Chi" unit="deg">
					<commonPosition>0</commonPosition>
				</positions>
				<positions axis="Z" unit="mm">
					<commonPosition>8.365</commonPosition>
				</positions>
				<commonCountingTime unit="seconds">0.974</commonCountingTime>
				<counts unit="counts">0 0 1 0 0 0 0 0 1 1 0 1 0 0 0 0 0 0 0 1 0 0 1 1 2 0 1 0 0 0 0 1 1 0 0 1 0 0 0 0 0 0 0 0 1 0 0 0 1 1 0 0 1 0 0 0 0 0 0 0 0 2 0 0 1 0 0 0 0 0 0 0 0 0 0 0 1 0 1 2 0 1 0 0 1 1 1 0 0 0 0 0 0 0 0 0 0 1 1 0 1 1 1 1 0 0 0 0 1 0 0 0 0 0 1 0 2 2 1 1 0 1 0 0 0 0 0 0 1 0 0 0 0 0 0 0 0 1 0 0 0 0 0 0 1 1 1 0 0 1 0 0 0 0 0 1 0 0 0 0 0 0 0 1 0 0 0 0 0 1 0 0 0 0 0 1 0 0 0 1 0 1 1 0 0 0 0 0 0 0 0 0 0 0 0 1 0 0 0 0 0 0 1 0 0 0 0 0 0 1 2 0 0 0 0 1 0 0 0 0 0 0 0 1 0 0 0 0 0 0 0 0 0 0 0 1 1 0 0 0 0 0 1 0 0 0 0 0 0 0 0 0 0 0 0</counts>
			</dataPoints>
		</scan>
		<scan status="Completed" appendNumber="0" scanAxis="2Theta" mode="Continuous">
			<header>
				<startTimeStamp>2024-07-01T14:31:11-04:00</startTimeStamp>
				<endTimeStamp>2024-07-01T15:01:10-04:00</endTimeStamp>
				<author>
					<name>lw627</name>
				</author>
				<source>
					<applicationSoftware version="7.1">Data Collector</applicationSoftware>
					<instrumentControlSoftware version="8.2  20201204">EMPYREAN</instrumentControlSoftware>
					<instrumentID>0000000011260721</instrumentID>
				</source>
			</header>
			<dataPoints>
				<positions axis="2Theta" unit="deg">
					<startPosition>77.9444024397149</startPosition>
					<endPosition>81.2916722109313</endPosition>
				</positions>
				<positions axis="Omega" unit="deg">
					<commonPosition>21.2480186626616</commonPosition>
				</positions>
				<positions axis="Phi" unit="deg">
					<commonPosition>-88.77</commonPosition>
				</positions>
				<positions axis="Chi" unit="deg">
					<commonPosition>0</commonPosition>
				</positions>
				<positions axis="Z" unit="mm">
					<commonPosition>8.365</commonPosition>
				</positions>
				<commonCountingTime unit="seconds">0.974</commonCountingTime>
				<counts unit="counts">0 1 1 0 0 1 0 0 0 1 1 0 0 0 0 1 0 0 1 1 0 0 1 0 0 0 1 0 0 0 1 0 0 0 0 1 0 0 0 0 0 0 0 0 0 0 1 0 0 2 0 1 0 0 0 0 0 0 0 0 0 0 0 0 1 0 0 1 1 0 1 0 0 0 0 1 1 0 0 0 0 0 1 0 0 0 1 1 0 0 0 0 0 1 0 0 0 0 1 0 0 0 1 2 0 0 0 1 0 1 1 0 0 1 0 0 0 0 0 0 0 0 0 0 0 1 0 0 0 0 0 0 0 0 1 0 0 1 0 0 0 0 1 0 0 0 0 2 0 1 0 0 0 0 0 0 1 0 0 1 0 0 1 0 0 0 1 0 0 0 0 2 0 0 1 0 1 0 1 0 0 0 0 0 0 2 1 0 0 1 0 0 0 0 0 0 0 0 0 1 0 1 1 0 0 1 0 0 0 0 0 0 1 0 0 0 0 1 0 0 0 1 0 0 1 0 0 0 0 0 0 0 0 0 0 0 0 0 3 0 0 1 1 0 0 1 1 0 0 0 0 0 0 0 1</counts>
			</dataPoints>
		</scan>
		<scan status="Completed" appendNumber="0" scanAxis="2Theta" mode="Continuous">
			<header>
				<startTimeStamp>2024-07-01T14:31:11-04:00</startTimeStamp>
				<endTimeStamp>2024-07-01T15:01:10-04:00</endTimeStamp>
				<author>
					<name>lw627</name>
				</author>
				<source>
					<applicationSoftware version="7.1">Data Collector</applicationSoftware>
					<instrumentControlSoftware version="8.2  20201204">EMPYREAN</instrumentControlSoftware>
					<instrumentID>0000000011260721</instrumentID>
				</source>
			</header>
			<dataPoints>
				<positions axis="2Theta" unit="deg">
					<startPosition>77.947685010383</startPosition>
					<endPosition>81.2949547815995</endPosition>
				</positions>
				<positions axis="Omega" unit="deg">
					<commonPosition>21.2496599479956</commonPosition>
				</positions>
				<positions axis="Phi" unit="deg">
					<commonPosition>-88.77</commonPosition>
				</positions>
				<positions axis="Chi" unit="deg">
					<commonPosition>0</commonPosition>
				</positions>
				<positions axis="Z" unit="mm">
					<commonPosition>8.365</commonPosition>
				</positions>
				<commonCountingTime unit="seconds">0.974</commonCountingTime>
				<counts unit="counts">0 0 0 0 0 0 0 0 0 1 1 0 0 0 0 1 0 2 0 0 0 2 0 0 0 1 0 1 0 0 1 1 1 0 0 0 0 1 0 0 0 0 0 0 0 0 0 0 0 0 0 1 0 0 0 1 1 0 0 0 0 0 0 0 0 0 1 2 0 1 1 0 0 0 0 0 0 0 0 0 0 0 0 0 1 0 1 0 0 0 2 0 0 0 1 0 0 0 0 0 0 0 0 0 0 0 0 1 0 0 0 0 1 0 1 0 1 0 0 0 0 0 0 1 2 1 0 1 1 0 0 0 1 0 0 0 1 1 0 0 0 0 1 1 0 0 1 0 1 0 0 0 0 0 0 0 0 0 0 0 1 0 0 0 0 0 0 0 0 2 1 0 0 2 1 0 0 1 0 0 0 0 0 0 0 0 0 0 1 0 0 0 0 0 0 0 0 0 1 1 0 0 0 1 0 0 0 0 0 0 0 0 1 0 1 0 0 0 0 0 1 1 0 1 0 0 0 0 0 0 2 1 1 0 0 1 0 0 0 1 0 0 0 1 1 0 0 0 0 1 0 0 0 0 0</counts>
			</dataPoints>
		</scan>
		<scan status="Completed" appendNumber="0" scanAxis="2Theta" mode="Continuous">
			<header>
				<startTimeStamp>2024-07-01T14:31:11-04:00</startTimeStamp>
				<endTimeStamp>2024-07-01T15:01:10-04:00</endTimeStamp>
				<author>
					<name>lw627</name>
				</author>
				<source>
					<applicationSoftware version="7.1">Data Collector</applicationSoftware>
					<instrumentControlSoftware version="8.2  20201204">EMPYREAN</instrumentControlSoftware>
					<instrumentID>0000000011260721</instrumentID>
				</source>
			</header>
			<dataPoints>
				<positions axis="2Theta" unit="deg">
					<startPosition>77.9509675810511</startPosition>
					<endPosition>81.2982373522676</endPosition>
				</positions>
				<positions axis="Omega" unit="deg">
					<commonPosition>21.2513012333297</commonPosition>
				</positions>
				<positions axis="Phi" unit="deg">
					<commonPosition>-88.77</commonPosition>
				</positions>
				<positions axis="Chi" unit="deg">
					<commonPosition>0</commonPosition>
				</positions>
				<positions axis="Z" unit="mm">
					<commonPosition>8.365</commonPosition>
				</positions>
				<commonCountingTime unit="seconds">0.974</commonCountingTime>
				<counts unit="counts">0 0 1 0 1 0 0 1 1 0 0 0 1 1 0 0 0 0 1 1 0 1 0 0 1 0 0 0 0 0 0 0 0 1 0 0 0 0 1 1 0 0 3 0 0 1 0 0 1 0 0 0 1 0 1 2 0 1 0 0 0 0 1 1 0 0 0 0 0 1 0 1 0 0 1 0 0 1 2 0 0 0 0 0 0 1 0 1 0 0 0 0 0 0 1 1 0 1 0 0 0 2 1 1 0 0 0 1 1 1 1 0 0 1 0 0 0 1 0 0 2 0 0 0 0 0 0 0 0 1 0 0 0 0 0 0 2 0 0 0 0 0 0 0 1 0 0 2 0 0 0 1 1 0 0 0 0 0 0 0 0 0 0 0 0 0 0 0 0 0 0 0 0 0 0 1 0 0 0 0 0 1 1 0 0 0 0 0 0 0 0 0 0 0 1 0 0 1 0 0 0 0 1 0 0 0 1 0 0 0 1 0 1 1 0 0 0 0 0 0 0 0 1 2 0 0 2 0 0 2 0 0 1 0 0 0 0 0 0 0 0 0 0 0 0 0 0 0 0 0 0 0 0 0 0</counts>
			</dataPoints>
		</scan>
		<scan status="Completed" appendNumber="0" scanAxis="2Theta" mode="Continuous">
			<header>
				<startTimeStamp>2024-07-01T14:31:11-04:00</startTimeStamp>
				<endTimeStamp>2024-07-01T15:01:10-04:00</endTimeStamp>
				<author>
					<name>lw627</name>
				</author>
				<source>
					<applicationSoftware version="7.1">Data Collector</applicationSoftware>
					<instrumentControlSoftware version="8.2  20201204">EMPYREAN</instrumentControlSoftware>
					<instrumentID>0000000011260721</instrumentID>
				</source>
			</header>
			<dataPoints>
				<positions axis="2Theta" unit="deg">
					<startPosition>77.9542501517193</startPosition>
					<endPosition>81.3015199229357</endPosition>
				</positions>
				<positions axis="Omega" unit="deg">
					<commonPosition>21.2529425186637</commonPosition>
				</positions>
				<positions axis="Phi" unit="deg">
					<commonPosition>-88.77</commonPosition>
				</positions>
				<positions axis="Chi" unit="deg">
					<commonPosition>0</commonPosition>
				</positions>
				<positions axis="Z" unit="mm">
					<commonPosition>8.365</commonPosition>
				</positions>
				<commonCountingTime unit="seconds">0.974</commonCountingTime>
				<counts unit="counts">0 0 0 0 1 0 0 0 0 1 0 1 0 0 0 0 0 0 0 0 0 0 0 0 0 0 1 0 0 0 0 0 1 0 0 0 0 0 0 0 1 1 0 0 1 2 0 0 1 1 0 1 0 0 0 0 0 0 0 0 0 1 1 0 0 1 2 0 1 0 0 0 0 1 2 0 0 0 0 0 0 1 1 1 1 0 0 1 0 1 0 1 0 0 1 0 0 1 1 0 0 0 0 0 0 0 1 0 0 0 0 0 0 0 1 0 1 1 0 2 0 0 0 1 0 0 0 0 0 0 0 0 0 1 0 0 0 0 0 0 0 1 0 0 0 0 0 0 0 0 0 0 0 0 0 0 0 0 0 0 0 0 0 1 0 0 1 2 0 0 0 0 1 0 0 0 0 0 0 0 0 1 0 0 1 0 2 0 1 0 0 0 0 1 0 1 1 0 0 0 0 0 0 0 0 0 0 0 0 0 0 0 0 0 0 1 1 1 0 0 0 0 0 1 0 0 1 0 0 1 1 0 0 2 0 0 0 0 0 0 0 0 0 0 0 0 0 0 0 0 1 0 0 0 0</counts>
			</dataPoints>
		</scan>
		<scan status="Completed" appendNumber="0" scanAxis="2Theta" mode="Continuous">
			<header>
				<startTimeStamp>2024-07-01T14:31:11-04:00</startTimeStamp>
				<endTimeStamp>2024-07-01T15:01:10-04:00</endTimeStamp>
				<author>
					<name>lw627</name>
				</author>
				<source>
					<applicationSoftware version="7.1">Data Collector</applicationSoftware>
					<instrumentControlSoftware version="8.2  20201204">EMPYREAN</instrumentControlSoftware>
					<instrumentID>0000000011260721</instrumentID>
				</source>
			</header>
			<dataPoints>
				<positions axis="2Theta" unit="deg">
					<startPosition>77.9575327223874</startPosition>
					<endPosition>81.3048024936039</endPosition>
				</positions>
				<positions axis="Omega" unit="deg">
					<commonPosition>21.2545838039978</commonPosition>
				</positions>
				<positions axis="Phi" unit="deg">
					<commonPosition>-88.77</commonPosition>
				</positions>
				<positions axis="Chi" unit="deg">
					<commonPosition>0</commonPosition>
				</positions>
				<positions axis="Z" unit="mm">
					<commonPosition>8.365</commonPosition>
				</positions>
				<commonCountingTime unit="seconds">0.974</commonCountingTime>
				<counts unit="counts">0 0 0 0 0 1 0 0 1 0 0 0 0 2 0 0 0 0 0 0 0 1 0 0 0 0 0 1 1 1 1 0 0 0 0 0 0 0 1 1 1 0 0 0 0 0 1 1 1 0 0 0 0 0 0 0 0 1 0 0 0 0 0 0 0 0 0 0 0 0 0 0 0 1 0 4 0 0 0 0 0 0 0 0 1 1 0 0 1 0 1 0 0 1 0 1 0 0 0 0 0 0 0 0 0 0 1 0 0 0 0 1 1 1 0 2 0 0 1 0 0 0 0 0 0 1 0 0 0 0 0 0 0 0 0 0 0 0 0 0 0 0 1 0 0 1 0 0 1 0 0 0 1 0 1 0 0 0 0 0 1 0 0 0 0 0 0 0 1 1 0 1 0 0 0 0 2 0 0 1 0 0 0 0 0 0 0 0 2 1 0 1 0 0 1 0 0 0 0 0 2 0 0 0 2 0 1 0 0 1 1 0 0 0 0 0 0 1 1 0 1 0 1 0 0 0 0 0 0 0 0 0 0 0 2 0 0 0 1 0 0 1 0 0 0 0 0 1 0 0 1 0 0 0 0</counts>
			</dataPoints>
		</scan>
		<scan status="Completed" appendNumber="0" scanAxis="2Theta" mode="Continuous">
			<header>
				<startTimeStamp>2024-07-01T14:31:11-04:00</startTimeStamp>
				<endTimeStamp>2024-07-01T15:01:10-04:00</endTimeStamp>
				<author>
					<name>lw627</name>
				</author>
				<source>
					<applicationSoftware version="7.1">Data Collector</applicationSoftware>
					<instrumentControlSoftware version="8.2  20201204">EMPYREAN</instrumentControlSoftware>
					<instrumentID>0000000011260721</instrumentID>
				</source>
			</header>
			<dataPoints>
				<positions axis="2Theta" unit="deg">
					<startPosition>77.9608152930555</startPosition>
					<endPosition>81.308085064272</endPosition>
				</positions>
				<positions axis="Omega" unit="deg">
					<commonPosition>21.2562250893319</commonPosition>
				</positions>
				<positions axis="Phi" unit="deg">
					<commonPosition>-88.77</commonPosition>
				</positions>
				<positions axis="Chi" unit="deg">
					<commonPosition>0</commonPosition>
				</positions>
				<positions axis="Z" unit="mm">
					<commonPosition>8.365</commonPosition>
				</positions>
				<commonCountingTime unit="seconds">0.974</commonCountingTime>
				<counts unit="counts">0 1 1 1 0 0 2 2 0 0 1 0 2 0 0 1 0 0 0 0 0 1 0 0 1 1 0 1 0 1 0 1 0 1 1 0 1 0 0 1 1 0 0 0 0 1 1 0 1 0 0 0 0 1 0 0 2 0 1 0 0 0 0 0 0 0 0 3 1 0 0 0 0 0 2 1 0 0 0 0 0 0 0 1 0 0 0 0 1 0 1 0 0 0 0 0 1 0 0 0 0 0 0 0 1 0 0 0 0 0 0 0 0 1 0 0 0 0 0 1 0 1 0 1 1 1 1 0 1 0 0 0 0 1 1 0 0 0 1 0 0 1 0 0 0 1 0 0 0 0 0 0 0 0 0 2 0 0 0 1 0 0 0 1 1 0 0 0 0 0 1 0 0 0 0 1 0 0 0 0 1 0 0 0 0 1 1 0 0 0 0 0 0 1 0 0 0 1 0 1 0 1 0 0 0 0 0 1 0 1 0 0 0 0 0 0 0 0 0 0 0 0 1 2 0 0 0 0 0 0 0 0 1 0 0 0 0 0 0 0 0 0 0 0 0 0 1 1 0 0 0 1 0 2 0</counts>
			</dataPoints>
		</scan>
		<scan status="Completed" appendNumber="0" scanAxis="2Theta" mode="Continuous">
			<header>
				<startTimeStamp>2024-07-01T14:31:11-04:00</startTimeStamp>
				<endTimeStamp>2024-07-01T15:01:10-04:00</endTimeStamp>
				<author>
					<name>lw627</name>
				</author>
				<source>
					<applicationSoftware version="7.1">Data Collector</applicationSoftware>
					<instrumentControlSoftware version="8.2  20201204">EMPYREAN</instrumentControlSoftware>
					<instrumentID>0000000011260721</instrumentID>
				</source>
			</header>
			<dataPoints>
				<positions axis="2Theta" unit="deg">
					<startPosition>77.9640978637236</startPosition>
					<endPosition>81.3113676349401</endPosition>
				</positions>
				<positions axis="Omega" unit="deg">
					<commonPosition>21.2578663746659</commonPosition>
				</positions>
				<positions axis="Phi" unit="deg">
					<commonPosition>-88.77</commonPosition>
				</positions>
				<positions axis="Chi" unit="deg">
					<commonPosition>0</commonPosition>
				</positions>
				<positions axis="Z" unit="mm">
					<commonPosition>8.365</commonPosition>
				</positions>
				<commonCountingTime unit="seconds">0.974</commonCountingTime>
				<counts unit="counts">1 0 0 0 0 0 0 0 1 0 0 0 0 0 0 0 0 0 0 2 1 1 0 0 0 1 0 0 0 0 2 1 0 4 1 2 0 0 0 0 0 1 0 0 0 1 0 0 0 0 0 1 0 0 1 0 0 0 1 0 0 1 1 0 1 0 0 1 0 1 0 0 0 0 0 0 0 0 0 0 0 0 0 0 0 0 2 1 0 0 0 0 0 1 0 0 1 0 0 0 0 0 0 0 0 0 1 0 0 0 2 0 0 0 0 0 0 0 0 0 0 1 0 0 1 2 0 0 0 0 0 0 1 0 1 0 0 0 0 0 0 0 0 0 0 0 0 1 0 0 1 0 0 1 0 0 0 0 0 0 1 0 0 0 0 0 0 0 0 0 0 0 0 0 0 0 0 0 1 0 1 0 0 0 1 0 0 0 0 0 0 0 0 0 1 1 0 0 0 0 0 1 0 1 1 0 0 1 0 0 1 2 0 0 0 0 0 0 1 0 0 0 0 1 0 1 0 0 0 0 0 0 0 1 0 0 0 0 0 0 0 0 0 0 0 0 1 0 0 0 0 1 0 0 0</counts>
			</dataPoints>
		</scan>
		<scan status="Completed" appendNumber="0" scanAxis="2Theta" mode="Continuous">
			<header>
				<startTimeStamp>2024-07-01T14:31:11-04:00</startTimeStamp>
				<endTimeStamp>2024-07-01T15:01:10-04:00</endTimeStamp>
				<author>
					<name>lw627</name>
				</author>
				<source>
					<applicationSoftware version="7.1">Data Collector</applicationSoftware>
					<instrumentControlSoftware version="8.2  20201204">EMPYREAN</instrumentControlSoftware>
					<instrumentID>0000000011260721</instrumentID>
				</source>
			</header>
			<dataPoints>
				<positions axis="2Theta" unit="deg">
					<startPosition>77.9673804343918</startPosition>
					<endPosition>81.3146502056082</endPosition>
				</positions>
				<positions axis="Omega" unit="deg">
					<commonPosition>21.25950766</commonPosition>
				</positions>
				<positions axis="Phi" unit="deg">
					<commonPosition>-88.77</commonPosition>
				</positions>
				<positions axis="Chi" unit="deg">
					<commonPosition>0</commonPosition>
				</positions>
				<positions axis="Z" unit="mm">
					<commonPosition>8.365</commonPosition>
				</positions>
				<commonCountingTime unit="seconds">0.974</commonCountingTime>
				<counts unit="counts">1 2 0 0 1 0 1 0 0 0 1 1 0 0 0 0 0 0 1 0 0 0 1 0 0 0 0 0 0 0 1 0 0 0 0 2 0 1 1 0 0 0 0 0 1 0 0 0 0 0 0 0 0 1 1 1 0 1 0 0 0 0 0 0 0 1 1 0 0 2 2 0 0 1 0 0 0 0 0 1 0 0 1 0 1 1 1 0 0 1 0 0 0 0 1 1 0 0 1 1 0 1 0 0 1 0 0 0 0 1 0 0 0 1 1 1 0 0 0 0 1 0 1 0 0 0 0 0 0 0 1 0 0 0 0 0 0 0 0 0 0 0 1 0 0 0 1 0 1 0 1 0 0 0 1 0 1 0 0 0 0 0 0 0 0 0 1 1 0 0 0 1 0 2 0 0 1 0 0 0 1 0 0 0 0 0 0 1 0 2 0 0 0 0 0 1 2 0 0 0 0 1 0 1 0 1 0 2 0 0 0 0 0 1 0 0 0 1 1 0 0 0 0 0 1 0 0 0 0 0 0 0 0 1 0 1 1 0 1 1 0 0 0 0 0 0 1 0 0 0 0 0 0 0 0</counts>
			</dataPoints>
		</scan>
	</xrdMeasurement>
</xrdMeasurements>