File: data/previous_data/set_2-YG031-034/xrd/YG033-SRO001-STO001-06162022.xrdml
<xrdMeasurements xmlns="http://www.xrdml.com/XRDMeasurement/2.1" xmlns:xsi="http://www.w3.org/2001/XMLSchema-instance" xsi:schemaLocation="http://www.xrdml.com/XRDMeasurement/2.1 http://www.xrdml.com/XRDMeasurement/2.1/XRDMeasurement.xsd" status="Completed">
	<comment>
		<entry>Configuration=Main Configuration, Owner=User-1, Creation date=6/17/2015 3:36:16 PM</entry>
		<entry>Goniometer=HR HD (Theta/2Theta); Minimum step size 2Theta:0.0001; Minimum step size Omega:0.0001</entry>
		<entry>Sample stage=MRD Cradle; Minimum step size Phi:0.01; Minimum step size Chi:0.01; Minimum step size X:0.01; Minimum step size Y:0.01; Minimum step size Z:0.001</entry>
		<entry>Diffractometer system=XPERT-3</entry>
		<entry>Measurement program=C:\PANalytical\Data Collector\Programs\Yichen\regular_2theta_20-50_0.4s-20min.xrdmp, Identifier={AEA8F2F2-8BFA-4B07-A521-A571AF38E73A}</entry>
	</comment>
	<sample type="To be analyzed">
		<id></id>
		<name></name>
		<preparedBy></preparedBy>
	</sample>
	<xrdMeasurement measurementType="Scan" status="Completed" sampleMode="Reflection">
		<comment>
			<entry>PHD Lower Level = 4.02 (keV), PHD Upper Level = 11.27 (keV)</entry>
		</comment>
		<usedWavelength intended="K-Alpha 1">
			<kAlpha1 unit="Angstrom">1.5405980</kAlpha1>
			<kAlpha2 unit="Angstrom">1.5444260</kAlpha2>
			<kBeta unit="Angstrom">1.3922500</kBeta>
			<ratioKAlpha2KAlpha1>0.5000</ratioKAlpha2KAlpha1>
		</usedWavelength>
		<incidentBeamPath>
			<radius unit="mm">320.00</radius>
			<xRayTube id="1010048" name="Empyrean Cu LFF HR (9430 033 7310x) DK425175">
				<tension unit="kV">45.0</tension>
				<current unit="mA">40.0</current>
				<anodeMaterial>Cu</anodeMaterial>
				<focus type="Line">
					<length unit="mm">12.0</length>
					<width unit="mm">0.4</width>
					<takeOffAngle unit="deg">4.2</takeOffAngle>
				</focus>
			</xRayTube>
			<xRayMirror id="27090001" name="Inc. Beam Cu W/Si (hybrid MRD)" hybrid="true">
				<crystal type="Graded" shape="Parabolic">W/Si</crystal>
				<acceptanceAngle unit="deg">0.800</acceptanceAngle>
				<length unit="mm">60.0</length>
			</xRayMirror>
			<monochromator id="23090002" name="Hybrid monochr. 2xGe(220) Cu asym." hybrid="true">
				<crystal type="Asymmetric" shape="Flat">Ge</crystal>
				<numberOfReflections>2</numberOfReflections>
				<hkl>
					<h>2</h>
					<k>2</k>
					<l>0</l>
				</hkl>
			</monochromator>
			<divergenceSlit id="22010004" name="Fixed slit 1/2°" xsi:type="fixedDivergenceSlitType">
				<distanceToSample unit="mm">220.00</distanceToSample>
				<height unit="mm">0.76</height>
			</divergenceSlit>
			<beamAttenuator id="26010001" name="Progr. beam attenuator Ni 0.125 mm" xsi:type="intensitySwitchedBeamAttenuatorType">
				<factor>172.00</factor>
				<material>Ni</material>
				<activateLevel unit="counts per second">500000</activateLevel>
				<deactivateLevel unit="counts per second">400000</deactivateLevel>
			</beamAttenuator>
		</incidentBeamPath>
		<diffractedBeamPath>
			<radius unit="mm">320.00</radius>
			<antiScatterSlit id="22090009" name="AS slit 7.5 mm (PIXcel)" xsi:type="fixedAntiScatterSlitType">
				<height unit="mm">7.50</height>
			</antiScatterSlit>
			<sollerSlit id="21010002" name="Soller slits 0.04 rad.">
				<opening unit="rad">0.0400</opening>
			</sollerSlit>
			<receivingSlit id="22010004" name="Fixed slit 1/2°">
				<height unit="mm">0.76</height>
			</receivingSlit>
			<detector id="7010020" name="PIXcel3D-Medipix3 1x1 detector" xsi:type="areaDetectorType">
				<phd unit="%">
					<lowerLevel>25.0</lowerLevel>
					<upperLevel>70.0</upperLevel>
				</phd>
				<mode>Receiving slit</mode>
				<activeChannelsEquatorial>5</activeChannelsEquatorial>
				<activeChannelsAxial>255</activeChannelsAxial>
				<pitchEquatorial unit="mm">0.05500</pitchEquatorial>
				<pitchAxial unit="mm">0.05500</pitchAxial>
				<readOutPeriod unit="seconds">0.050</readOutPeriod>
			</detector>
		</diffractedBeamPath>
		<scan appendNumber="0" mode="Continuous" scanAxis="2Theta-Omega" status="Completed">
			<header>
				<startTimeStamp>2022-06-16T14:16:27-07:00</startTimeStamp>
				<endTimeStamp>2022-06-16T14:36:53-07:00</endTimeStamp>
				<author>
					<name>XRD</name>
				</author>
				<source>
					<applicationSoftware version="6.1b">Data Collector</applicationSoftware>
					<instrumentControlSoftware version="7.4b 20181204">XPERT-3</instrumentControlSoftware>
					<instrumentID>0000000011163216</instrumentID>
				</source>
			</header>
			<dataPoints>
				<positions axis="2Theta" unit="deg">
					<startPosition>20.0050</startPosition>
					<endPosition>49.9950</endPosition>
				</positions>
				<positions axis="Omega" unit="deg">
					<startPosition>10.5466</startPosition>
					<endPosition>25.5416</endPosition>
				</positions>
				<positions axis="Phi" unit="deg">
					<commonPosition>0.00</commonPosition>
				</positions>
				<positions axis="Chi" unit="deg">
					<commonPosition>-0.12</commonPosition>
				</positions>
				<positions axis="X" unit="mm">
					<commonPosition>-0.30</commonPosition>
				</positions>
				<positions axis="Y" unit="mm">
					<commonPosition>0.00</commonPosition>
				</positions>
				<positions axis="Z" unit="mm">
					<commonPosition>8.893</commonPosition>
				</positions>
				<beamAttenuationFactors>1.00 1.00 1.00 1.00 1.00 1.00 1.00 1.00 1.00 1.00 1.00 1.00 1.00 1.00 1.00 1.00 1.00 1.00 1.00 1.00 1.00 1.00 1.00 1.00 1.00 1.00 1.00 1.00 1.00 1.00 1.00 1.00 1.00 1.00 1.00 1.00 1.00 1.00 1.00 1.00 1.00 1.00 1.00 1.00 1.00 1.00 1.00 1.00 1.00 1.00 1.00 1.00 1.00 1.00 1.00 1.00 1.00 1.00 1.00 1.00 1.00 1.00 1.00 1.00 1.00 1.00 1.00 1.00 1.00 1.00 1.00 1.00 1.00 1.00 1.00 1.00 1.00 1.00 1.00 1.00 1.00 1.00 1.00 1.00 1.00 1.00 1.00 1.00 1.00 1.00 1.00 1.00 1.00 1.00 1.00 1.00 1.00 1.00 1.00 1.00 1.00 1.00 1.00 1.00 1.00 1.00 1.00 1.00 1.00 1.00 1.00 1.00 1.00 1.00 1.00 1.00 1.00 1.00 1.00 1.00 1.00 1.00 1.00 1.00 1.00 1.00 1.00 1.00 1.00 1.00 1.00 1.00 1.00 1.00 1.00 1.00 1.00 1.00 1.00 1.00 1.00 1.00 1.00 1.00 1.00 1.00 1.00 1.00 1.00 1.00 1.00 1.00 1.00 1.00 1.00 1.00 1.00 1.00 1.00 1.00 1.00 1.00 1.00 1.00 1.00 1.00 1.00 1.00 1.00 1.00 1.00 1.00 1.00 1.00 1.00 1.00 1.00 1.00 1.00 1.00 1.00 1.00 1.00 1.00 1.00 1.00 1.00 1.00 1.00 1.00 1.00 1.00 1.00 1.00 1.00 1.00 1.00 1.00 1.00 1.00 1.00 1.00 1.00 1.00 1.00 1.00 1.00 1.00 1.00 1.00 1.00 1.00 1.00 1.00 1.00 1.00 1.00 1.00 1.00 1.00 1.00 1.00 1.00 1.00 1.00 1.00 1.00 1.00 1.00 1.00 1.00 1.00 1.00 1.00 1.00 1.00 1.00 1.00 1.00 1.00 1.00 1.00 1.00 1.00 1.00 1.00 1.00 1.00 1.00 1.00 1.00 1.00 1.00 1.00 1.00 1.00 1.00 1.00 1.00 1.00 1.00 1.00 1.00 1.00 1.00 1.00 1.00 1.00 1.00 1.00 1.00 1.00 1.00 1.00 1.00 1.00 1.00 1.00 1.00 1.00 1.00 1.00 1.00 1.00 1.00 1.00 1.00 1.00 1.00 1.00 1.00 1.00 1.00 1.00 1.00 1.00 1.00 1.00 1.00 1.00 1.00 1.00 1.00 1.00 1.00 1.00 1.00 1.00 1.00 1.00 1.00 1.00 1.00 1.00 1.00 1.00 1.00 1.00 1.00 1.00 1.00 1.00 1.00 1.00 1.00 1.00 1.00 1.00 1.00 1.00 1.00 1.00 1.00 1.00 1.00 1.00 1.00 1.00 1.00 1.00 1.00 1.00 1.00 1.00 1.00 1.00 1.00 1.00 1.00 1.00 1.00 1.00 1.00 1.00 1.00 1.00 1.00 1.00 1.00 1.00 1.00 1.00 1.00 1.00 1.00 1.00 1.00 1.00 1.00 1.00 1.00 1.00 1.00 1.00 1.00 1.00 1.00 1.00 1.00 1.00 1.00 1.00 1.00 1.00 1.00 1.00 1.00 1.00 1.00 1.00 1.00 1.00 1.00 1.00 1.00 1.00 1.00 1.00 1.00 1.00 1.00 1.00 1.00 1.00 1.00 1.00 1.00 1.00 1.00 1.00 1.00 1.00 1.00 1.00 1.00 1.00 1.00 1.00 1.00 1.00 1.00 1.00 1.00 1.00 1.00 1.00 1.00 1.00 1.00 1.00 1.00 1.00 1.00 1.00 1.00 1.00 1.00 1.00 1.00 1.00 1.00 1.00 1.00 1.00 1.00 1.00 1.00 1.00 1.00 1.00 1.00 1.00 1.00 1.00 1.00 1.00 1.00 1.00 1.00 1.00 1.00 1.00 1.00 1.00 1.00 1.00 1.00 1.00 1.00 1.00 1.00 1.00 1.00 1.00 1.00 1.00 1.00 1.00 1.00 1.00 1.00 1.00 1.00 1.00 1.00 1.00 1.00 1.00 1.00 1.00 1.00 1.00 1.00 1.00 1.00 1.00 1.00 1.00 1.00 1.00 1.00 1.00 1.00 1.00 1.00 1.00 1.00 1.00 1.00 1.00 1.00 1.00 1.00 1.00 1.00 1.00 1.00 1.00 1.00 1.00 1.00 1.00 1.00 1.00 1.00 1.00 1.00 1.00 1.00 1.00 1.00 1.00 1.00 1.00 1.00 1.00 1.00 1.00 1.00 1.00 1.00 1.00 1.00 1.00 1.00 1.00 1.00 1.00 1.00 1.00 1.00 1.00 1.00 1.00 1.00 1.00 1.00 1.00 1.00 1.00 1.00 1.00 1.00 1.00 1.00 1.00 1.00 1.00 1.00 1.00 1.00 1.00 1.00 1.00 1.00 1.00 1.00 1.00 1.00 1.00 1.00 1.00 1.00 1.00 1.00 1.00 1.00 1.00 1.00 1.00 1.00 1.00 1.00 1.00 1.00 1.00 1.00 1.00 1.00 1.00 1.00 1.00 1.00 1.00 1.00 1.00 1.00 1.00 1.00 1.00 1.00 1.00 1.00 1.00 1.00 1.00 1.00 1.00 1.00 1.00 1.00 1.00 1.00 1.00 1.00 1.00 1.00 1.00 1.00 1.00 1.00 1.00 1.00 1.00 1.00 1.00 1.00 1.00 1.00 1.00 1.00 1.00 1.00 1.00 1.00 1.00 1.00 1.00 1.00 1.00 1.00 1.00 1.00 1.00 1.00 1.00 1.00 1.00 1.00 1.00 1.00 1.00 1.00 1.00 1.00 1.00 1.00 1.00 1.00 1.00 1.00 1.00 1.00 1.00 1.00 1.00 1.00 1.00 1.00 1.00 1.00 1.00 1.00 1.00 1.00 1.00 1.00 1.00 1.00 1.00 1.00 1.00 1.00 1.00 1.00 1.00 1.00 1.00 1.00 1.00 1.00 1.00 1.00 1.00 1.00 1.00 1.00 1.00 1.00 1.00 1.00 1.00 1.00 1.00 1.00 1.00 1.00 1.00 1.00 1.00 1.00 1.00 1.00 1.00 1.00 1.00 1.00 1.00 1.00 1.00 1.00 1.00 1.00 1.00 1.00 1.00 1.00 1.00 1.00 1.00 1.00 1.00 1.00 1.00 1.00 1.00 1.00 1.00 1.00 1.00 1.00 1.00 1.00 1.00 1.00 1.00 1.00 1.00 1.00 1.00 1.00 1.00 1.00 1.00 1.00 1.00 1.00 1.00 1.00 1.00 1.00 1.00 1.00 1.00 1.00 1.00 1.00 1.00 1.00 1.00 1.00 1.00 1.00 1.00 1.00 1.00 1.00 1.00 1.00 1.00 1.00 1.00 1.00 1.00 1.00 1.00 1.00 1.00 1.00 1.00 1.00 1.00 1.00 1.00 1.00 1.00 1.00 1.00 1.00 1.00 1.00 1.00 1.00 1.00 1.00 1.00 1.00 1.00 1.00 1.00 1.00 1.00 1.00 1.00 1.00 1.00 1.00 1.00 1.00 1.00 1.00 1.00 1.00 1.00 1.00 1.00 1.00 1.00 1.00 1.00 1.00 1.00 1.00 1.00 1.00 1.00 1.00 1.00 1.00 1.00 1.00 1.00 1.00 1.00 1.00 1.00 1.00 1.00 1.00 1.00 1.00 1.00 1.00 1.00 1.00 1.00 1.00 1.00 1.00 1.00 1.00 1.00 1.00 1.00 1.00 1.00 1.00 1.00 1.00 1.00 1.00 1.00 1.00 1.00 1.00 1.00 1.00 1.00 1.00 1.00 1.00 1.00 1.00 1.00 1.00 1.00 1.00 1.00 1.00 1.00 1.00 1.00 1.00 1.00 1.00 1.00 1.00 1.00 1.00 1.00 1.00 1.00 1.00 1.00 1.00 1.00 1.00 1.00 1.00 1.00 1.00 1.00 1.00 1.00 1.00 1.00 1.00 1.00 1.00 1.00 1.00 1.00 1.00 1.00 1.00 1.00 1.00 1.00 1.00 1.00 1.00 1.00 1.00 1.00 1.00 1.00 1.00 1.00 1.00 1.00 1.00 1.00 1.00 1.00 1.00 1.00 1.00 1.00 1.00 1.00 1.00 1.00 1.00 1.00 1.00 1.00 1.00 1.00 1.00 1.00 1.00 1.00 1.00 1.00 1.00 1.00 1.00 1.00 1.00 1.00 1.00 1.00 1.00 1.00 1.00 1.00 1.00 1.00 1.00 1.00 1.00 1.00 1.00 1.00 1.00 1.00 1.00 1.00 1.00 1.00 1.00 1.00 1.00 1.00 1.00 1.00 1.00 1.00 1.00 1.00 1.00 1.00 1.00 1.00 1.00 1.00 1.00 1.00 1.00 1.00 1.00 1.00 1.00 1.00 1.00 1.00 1.00 1.00 1.00 1.00 1.00 1.00 1.00 1.00 1.00 1.00 1.00 1.00 1.00 1.00 1.00 1.00 1.00 1.00 1.00 1.00 1.00 1.00 1.00 1.00 1.00 1.00 1.00 1.00 1.00 1.00 1.00 1.00 1.00 1.00 1.00 1.00 1.00 1.00 1.00 1.00 1.00 1.00 1.00 1.00 1.00 1.00 1.00 1.00 1.00 1.00 1.00 1.00 1.00 1.00 1.00 1.00 1.00 1.00 1.00 1.00 1.00 1.00 1.00 1.00 1.00 1.00 1.00 1.00 1.00 1.00 1.00 1.00 1.00 1.00 1.00 1.00 1.00 1.00 1.00 1.00 1.00 1.00 1.00 1.00 1.00 1.00 1.00 1.00 1.00 1.00 1.00 1.00 1.00 1.00 1.00 1.00 1.00 1.00 1.00 1.00 1.00 1.00 1.00 1.00 1.00 1.00 1.00 1.00 1.00 1.00 1.00 1.00 1.00 1.00 1.00 1.00 1.00 1.00 1.00 1.00 1.00 1.00 1.00 1.00 1.00 1.00 1.00 1.00 1.00 1.00 1.00 1.00 1.00 1.00 1.00 1.00 1.00 1.00 1.00 1.00 1.00 1.00 1.00 1.00 1.00 1.00 1.00 1.00 1.00 1.00 1.00 1.00 1.00 1.00 1.00 1.00 1.00 1.00 1.00 1.00 1.00 1.00 1.00 1.00 1.00 1.00 1.00 1.00 1.00 1.00 1.00 1.00 1.00 1.00 1.00 1.00 1.00 1.00 1.00 1.00 1.00 1.00 1.00 1.00 1.00 1.00 1.00 1.00 1.00 1.00 1.00 1.00 1.00 1.00 1.00 1.00 1.00 1.00 1.00 1.00 1.00 1.00 1.00 1.00 1.00 1.00 1.00 1.00 1.00 1.00 1.00 1.00 1.00 1.00 1.00 1.00 1.00 1.00 1.00 1.00 1.00 1.00 1.00 1.00 1.00 1.00 1.00 1.00 1.00 1.00 1.00 1.00 1.00 1.00 1.00 1.00 1.00 1.00 1.00 1.00 1.00 1.00 1.00 1.00 1.00 1.00 1.00 1.00 1.00 1.00 1.00 1.00 1.00 1.00 1.00 1.00 1.00 1.00 1.00 1.00 1.00 1.00 1.00 1.00 1.00 1.00 1.00 1.00 1.00 1.00 1.00 1.00 1.00 1.00 1.00 1.00 1.00 1.00 1.00 1.00 1.00 1.00 1.00 1.00 1.00 1.00 1.00 1.00 1.00 1.00 1.00 1.00 1.00 1.00 1.00 1.00 1.00 1.00 1.00 1.00 1.00 1.00 1.00 1.00 1.00 1.00 1.00 1.00 1.00 1.00 1.00 1.00 1.00 1.00 1.00 1.00 1.00 1.00 1.00 1.00 1.00 1.00 1.00 1.00 1.00 1.00 1.00 1.00 1.00 1.00 1.00 1.00 1.00 1.00 1.00 1.00 1.00 1.00 1.00 1.00 1.00 1.00 1.00 1.00 1.00 1.00 1.00 1.00 1.00 1.00 1.00 1.00 1.00 1.00 1.00 1.00 1.00 1.00 1.00 1.00 1.00 1.00 1.00 1.00 1.00 1.00 1.00 1.00 1.00 1.00 1.00 1.00 1.00 1.00 1.00 1.00 1.00 1.00 1.00 1.00 1.00 1.00 1.00 1.00 1.00 1.00 1.00 1.00 1.00 1.00 1.00 1.00 1.00 1.00 1.00 1.00 1.00 1.00 1.00 1.00 1.00 1.00 1.00 1.00 1.00 1.00 1.00 1.00 1.00 1.00 1.00 1.00 1.00 1.00 1.00 1.00 1.00 1.00 1.00 1.00 1.00 1.00 1.00 1.00 1.00 1.00 1.00 1.00 1.00 1.00 1.00 1.00 1.00 1.00 1.00 1.00 1.00 1.00 1.00 1.00 1.00 1.00 1.00 1.00 1.00 1.00 1.00 1.00 1.00 1.00 1.00 1.00 1.00 1.00 1.00 1.00 1.00 1.00 1.00 1.00 1.00 1.00 1.00 1.00 1.00 1.00 1.00 1.00 1.00 1.00 1.00 1.00 1.00 1.00 1.00 1.00 1.00 1.00 1.00 1.00 1.00 1.00 1.00 1.00 1.00 1.00 1.00 1.00 1.00 1.00 1.00 1.00 1.00 1.00 1.00 1.00 1.00 1.00 1.00 1.00 1.00 1.00 1.00 1.00 1.00 1.00 1.00 1.00 1.00 1.00 1.00 1.00 1.00 1.00 1.00 1.00 1.00 1.00 1.00 1.00 1.00 1.00 1.00 1.00 1.00 1.00 1.00 1.00 1.00 1.00 1.00 1.00 1.00 1.00 1.00 1.00 1.00 1.00 1.00 1.00 1.00 1.00 1.00 1.00 1.00 1.00 1.00 1.00 1.00 1.00 1.00 1.00 1.00 1.00 1.00 1.00 1.00 1.00 1.00 1.00 1.00 1.00 1.00 1.00 1.00 1.00 1.00 1.00 1.00 1.00 1.00 1.00 1.00 1.00 1.00 1.00 1.00 1.00 1.00 1.00 1.00 1.00 1.00 1.00 1.00 1.00 1.00 1.00 1.00 1.00 1.00 1.00 1.00 1.00 1.00 1.00 1.00 1.00 1.00 1.00 1.00 1.00 1.00 1.00 1.00 1.00 1.00 1.00 1.00 1.00 1.00 1.00 1.00 1.00 1.00 1.00 1.00 1.00 1.00 1.00 1.00 1.00 1.00 1.00 1.00 1.00 1.00 1.00 1.00 1.00 1.00 1.00 1.00 1.00 1.00 1.00 1.00 1.00 1.00 1.00 1.00 1.00 1.00 1.00 1.00 1.00 1.00 1.00 1.00 1.00 1.00 1.00 1.00 1.00 1.00 1.00 1.00 1.00 1.00 1.00 1.00 1.00 1.00 1.00 1.00 1.00 1.00 1.00 1.00 1.00 1.00 1.00 1.00 1.00 1.00 1.00 1.00 1.00 1.00 1.00 1.00 1.00 1.00 1.00 1.00 1.00 1.00 1.00 1.00 1.00 1.00 1.00 1.00 1.00 1.00 1.00 1.00 1.00 1.00 1.00 1.00 1.00 1.00 1.00 1.00 1.00 1.00 1.00 1.00 1.00 1.00 1.00 1.00 1.00 1.00 1.00 1.00 1.00 1.00 1.00 1.00 1.00 1.00 1.00 1.00 1.00 1.00 1.00 1.00 1.00 1.00 1.00 1.00 1.00 1.00 1.00 1.00 1.00 1.00 1.00 1.00 1.00 1.00 1.00 1.00 1.00 1.00 1.00 1.00 1.00 1.00 1.00 1.00 1.00 1.00 1.00 1.00 1.00 1.00 1.00 1.00 1.00 1.00 1.00 1.00 1.00 1.00 1.00 1.00 1.00 1.00 1.00 1.00 1.00 1.00 1.00 1.00 1.00 1.00 1.00 1.00 1.00 1.00 1.00 1.00 1.00 1.00 1.00 1.00 1.00 1.00 1.00 1.00 1.00 1.00 1.00 1.00 1.00 1.00 1.00 1.00 1.00 1.00 1.00 1.00 1.00 1.00 1.00 1.00 1.00 1.00 1.00 1.00 1.00 1.00 1.00 1.00 1.00 1.00 1.00 1.00 1.00 1.00 1.00 1.00 1.00 1.00 1.00 1.00 1.00 1.00 1.00 1.00 1.00 1.00 1.00 1.00 1.00 1.00 1.00 1.00 1.00 1.00 1.00 1.00 1.00 1.00 1.00 1.00 1.00 1.00 1.00 1.00 1.00 1.00 1.00 1.00 1.00 1.00 1.00 1.00 1.00 1.00 1.00 1.00 1.00 1.00 1.00 1.00 1.00 1.00 1.00 1.00 1.00 1.00 1.00 1.00 1.00 1.00 1.00 1.00 1.00 1.00 1.00 1.00 1.00 1.00 1.00 1.00 1.00 1.00 1.00 1.00 1.00 1.00 1.00 1.00 1.00 1.00 1.00 1.00 1.00 1.00 1.00 1.00 1.00 1.00 1.00 1.00 1.00 1.00 1.00 1.00 1.00 1.00 1.00 1.00 1.00 1.00 1.00 1.00 1.00 1.00 1.00 1.00 1.00 1.00 1.00 1.00 1.00 1.00 1.00 1.00 1.00 1.00 1.00 1.00 1.00 1.00 1.00 1.00 1.00 1.00 1.00 1.00 1.00 1.00 1.00 1.00 1.00 1.00 1.00 1.00 1.00 1.00 1.00 1.00 1.00 1.00 1.00 1.00 1.00 1.00 1.00 1.00 1.00 1.00 1.00 1.00 1.00 1.00 1.00 1.00 1.00 1.00 1.00 1.00 1.00 1.00 1.00 1.00 1.00 1.00 1.00 1.00 1.00 1.00 1.00 1.00 1.00 1.00 1.00 1.00 1.00 1.00 1.00 1.00 1.00 1.00 1.00 1.00 1.00 1.00 1.00 1.00 1.00 1.00 1.00 1.00 1.00 1.00 1.00 1.00 1.00 1.00 1.00 1.00 1.00 1.00 1.00 1.00 1.00 1.00 1.00 1.00 1.00 1.00 1.00 1.00 1.00 1.00 1.00 1.00 1.00 1.00 1.00 1.00 1.00 1.00 1.00 1.00 1.00 1.00 1.00 1.00 1.00 1.00 1.00 1.00 1.00 1.00 1.00 1.00 1.00 1.00 1.00 1.00 1.00 1.00 1.00 1.00 1.00 1.00 1.00 1.00 1.00 1.00 1.00 1.00 1.00 1.00 1.00 1.00 1.00 1.00 1.00 1.00 1.00 1.00 1.00 1.00 1.00 1.00 1.00 1.00 1.00 1.00 1.00 1.00 1.00 1.00 1.00 1.00 1.00 1.00 1.00 1.00 1.00 1.00 1.00 1.00 1.00 1.00 1.00 1.00 1.00 1.00 1.00 1.00 1.00 1.00 1.00 1.00 1.00 1.00 1.00 1.00 1.00 1.00 1.00 1.00 1.00 1.00 1.00 1.00 1.00 1.00 1.00 1.00 1.00 1.00 1.00 1.00 1.00 1.00 1.00 1.00 1.00 1.00 1.00 1.00 1.00 1.00 1.00 1.00 1.00 1.00 1.00 1.00 1.00 1.00 1.00 1.00 1.00 1.00 1.00 1.00 1.00 1.00 1.00 1.00 1.00 1.00 1.00 1.00 1.00 1.00 1.00 1.00 1.00 1.00 1.00 1.00 1.00 1.00 1.00 1.00 1.00 1.00 1.00 1.00 1.00 1.00 1.00 1.00 1.00 1.00 1.00 1.00 1.00 1.00 1.00 1.00 1.00 1.00 1.00 1.00 1.00 1.00 1.00 1.00 1.00 1.00 1.00 1.00 1.00 1.00 1.00 1.00 1.00 1.00 1.00 1.00 1.00 1.00 1.00 1.00 1.00 1.00 1.00 1.00 1.00 1.00 1.00 1.00 1.00 1.00 1.00 1.00 1.00 1.00 1.00 1.00 1.00 1.00 1.00 1.00 1.00 1.00 1.00 1.00 1.00 1.00 1.00 1.00 1.00 1.00 1.00 1.00 1.00 1.00 1.00 1.00 1.00 1.00 1.00 1.00 1.00 1.00 1.00 1.00 1.00 1.00 1.00 1.00 1.00 1.00 1.00 1.00 1.00 1.00 1.00 1.00 1.00 1.00 1.00 1.00 1.00 1.00 1.00 1.00 1.00 1.00 1.00 1.00 1.00 1.00 1.00 1.00 1.00 1.00 1.00 1.00 1.00 1.00 1.00 1.00 1.00 1.00 1.00 1.00 1.00 1.00 1.00 1.00 1.00 1.00 1.00 1.00 1.00 1.00 1.00 1.00 1.00 1.00 1.00 1.00 1.00 1.00 1.00 1.00 1.00 1.00 1.00 1.00 1.00 1.00 1.00 1.00 1.00 1.00 1.00 1.00 1.00 1.00 1.00 1.00 1.00 1.00 1.00 1.00 1.00 1.00 1.00 1.00 1.00 1.00 1.00 1.00 1.00 1.00 1.00 1.00 1.00 1.00 1.00 1.00 1.00 1.00 1.00 1.00 1.00 1.00 1.00 1.00 1.00 1.00 1.00 1.00 1.00 1.00 1.00 1.00 1.00 1.00 1.00 1.00 1.00 1.00 1.00 1.00 1.00 1.00 1.00 1.00 1.00 1.00 1.00 1.00 1.00 1.00 1.00 1.00 1.00 1.00 1.00 1.00 1.00 1.00 1.00 1.00 1.00 1.00 1.00 1.00 1.00 1.00 1.00 1.00 1.00 1.00 1.00 1.00 1.00 1.00 1.00 1.00 1.00 1.00 1.00 1.00 1.00 1.00 1.00 1.00 1.00 1.00 1.00 1.00 1.00 1.00 1.00 1.00 1.00 1.00 1.00 1.00 1.00 1.00 1.00 1.00 1.00 1.00 1.00 1.00 1.00 1.00 1.00 1.00 1.00 1.00 1.00 1.00 1.00 1.00 1.00 1.00 1.00 1.00 1.00 1.00 1.00 1.00 1.00 1.00 1.00 1.00 1.00 1.00 1.00 1.00 1.00 1.00 1.00 1.00 1.00 1.00 1.00 1.00 1.00 1.00 1.00 1.00 1.00 1.00 1.00 1.00 1.00 1.00 1.00 1.00 1.00 1.00 1.00 1.00 1.00 1.00 1.00 1.00 1.00 1.00 1.00 1.00 1.00 1.00 1.00 1.00 1.00 1.00 1.00 1.00 1.00 1.00 1.00 1.00 1.00 1.00 1.00 1.00 1.00 1.00 1.00 1.00 1.00 1.00 1.00 1.00 1.00 1.00 1.00 1.00 1.00 1.00 1.00 1.00 1.00 1.00 1.00 1.00 1.00 1.00 1.00 1.00 1.00 1.00 1.00 1.00 1.00 1.00 1.00 1.00 1.00 1.00 1.00 1.00 1.00 1.00 1.00 1.00 1.00 1.00 1.00 1.00 1.00 1.00 1.00 1.00 1.00 1.00 1.00 1.00 1.00 1.00 1.00 1.00 1.00 1.00 1.00 1.00 1.00 1.00 1.00 1.00 1.00 1.00 1.00 1.00 1.00 1.00 1.00 1.00 1.00 1.00 1.00 1.00 1.00 1.00 1.00 1.00 1.00 1.00 1.00 1.00 1.00 1.00 1.00 1.00 1.00 1.00 1.00 1.00 1.00 1.00 1.00 1.00 1.00 1.00 172.00 172.00 172.00 172.00 172.00 172.00 172.00 172.00 1.00 1.00 1.00 1.00 1.00 1.00 1.00 1.00 1.00 1.00 1.00 1.00 1.00 1.00 1.00 1.00 1.00 1.00 1.00 1.00 1.00 1.00 1.00 1.00 1.00 1.00 1.00 1.00 1.00 1.00 1.00 1.00 1.00 1.00 1.00 1.00 1.00 1.00 1.00 1.00 1.00 1.00 1.00 1.00 1.00 1.00 1.00 1.00 1.00 1.00 1.00 1.00 1.00 1.00 1.00 1.00 1.00 1.00 1.00 1.00 1.00 1.00 1.00 1.00 1.00 1.00 1.00 1.00 1.00 1.00 1.00 1.00 1.00 1.00 1.00 1.00 1.00 1.00 1.00 1.00 1.00 1.00 1.00 1.00 1.00 1.00 1.00 1.00 1.00 1.00 1.00 1.00 1.00 1.00 1.00 1.00 1.00 1.00 1.00 1.00 1.00 1.00 1.00 1.00 1.00 1.00 1.00 1.00 1.00 1.00 1.00 1.00 1.00 1.00 1.00 1.00 1.00 1.00 1.00 1.00 1.00 1.00 1.00 1.00 1.00 1.00 1.00 1.00 1.00 1.00 1.00 1.00 1.00 1.00 1.00 1.00 1.00 1.00 1.00 1.00 1.00 1.00 1.00 1.00 1.00 1.00 1.00 1.00 1.00 1.00 1.00 1.00 1.00 1.00 1.00 1.00 1.00 1.00 1.00 1.00 1.00 1.00 1.00 1.00 1.00 1.00 1.00 1.00 1.00 1.00 1.00 1.00 1.00 1.00 1.00 1.00 1.00 1.00 1.00 1.00 1.00 1.00 1.00 1.00 1.00 1.00 1.00 1.00 1.00 1.00 1.00 1.00 1.00 1.00 1.00 1.00 1.00 1.00 1.00 1.00 1.00 1.00 1.00 1.00 1.00 1.00 1.00 1.00 1.00 1.00 1.00 1.00 1.00 1.00 1.00 1.00 1.00 1.00 1.00 1.00 1.00 1.00 1.00 1.00 1.00 1.00 1.00 1.00 1.00 1.00 1.00 1.00 1.00 1.00 1.00 1.00 1.00 1.00 1.00 1.00 1.00 1.00 1.00 1.00 1.00 1.00 1.00 1.00 1.00 1.00 1.00 1.00 1.00 1.00 1.00 1.00 1.00 1.00 1.00 1.00 1.00 1.00 1.00 1.00 1.00 1.00 1.00 1.00 1.00 1.00 1.00 1.00 1.00 1.00 1.00 1.00 1.00 1.00 1.00 1.00 1.00 1.00 1.00 1.00 1.00 1.00 1.00 1.00 1.00 1.00 1.00 1.00 1.00 1.00 1.00 1.00 1.00 1.00 1.00 1.00 1.00 1.00 1.00 1.00 1.00 1.00 1.00 1.00 1.00 1.00 1.00 1.00 1.00 1.00 1.00 1.00 1.00 1.00 1.00 1.00 1.00 1.00 1.00 1.00 1.00 1.00 1.00 1.00 1.00 1.00 1.00 1.00 1.00 1.00 1.00 1.00 1.00 1.00 1.00 1.00 1.00 1.00 1.00 1.00 1.00 1.00 1.00 1.00 1.00</beamAttenuationFactors>
				<commonCountingTime unit="seconds">0.352</commonCountingTime>
				<counts unit="counts">27 35 31 39 36 26 34 42 40 30 38 26 35 27 33 33 28 33 48 27 30 32 41 34 45 27 25 31 39 27 34 28 31 39 33 42 29 30 46 34 34 39 34 34 32 38 36 34 50 40 47 35 41 48 38 43 37 39 38 43 37 40 45 47 32 27 29 30 35 28 39 30 33 29 27 32 35 42 29 36 38 35 31 32 45 39 32 37 33 24 35 26 35 29 33 39 23 29 29 32 32 41 33 34 32 42 38 34 46 38 42 35 32 36 30 30 34 35 35 40 43 29 25 35 33 24 26 41 35 29 39 29 28 32 26 23 39 30 32 42 43 31 43 26 37 33 40 25 30 40 34 41 31 35 37 33 29 28 31 34 28 31 28 34 33 48 34 40 42 60 45 50 37 59 44 53 38 42 39 37 29 30 41 44 29 49 38 53 39 68 64 53 42 52 63 52 46 56 36 50 41 44 30 28 39 38 37 57 60 67 83 83 92 107 127 115 108 115 107 92 84 66 61 56 43 38 53 85 92 117 194 271 393 413 515 680 752 925 1060 1139 1302 1353 1468 1684 1469 1722 1702 1613 1686 1583 1554 1449 1317 1232 1033 956 797 672 603 491 393 287 210 193 148 168 199 229 792 1704 3478 6941 16035 45044 105272 179637 125223 44464 15309 6470 3304 861 525 402 295 273 198 156 130 98 63 67 65 68 61 56 74 73 77 99 90 102 105 106 90 76 81 69 71 49 59 60 37 36 30 33 29 35 46 43 51 57 51 61 55 59 58 55 62 48 51 43 33 36 35 21 32 27 28 30 22 37 38 32 45 55 51 30 50 35 37 38 52 40 27 42 25 24 31 25 22 31 32 29 39 34 28 42 30 42 42 28 26 38 38 33 35 26 29 26 30 27 18 17 30 21 33 31 32 37 33 20 31 32 24 30 31 33 26 21 21 22 24 35 24 22 31 26 22 18 29 24 30 27 24 36 29 27 25 27 31 28 30 25 16 20 19 22 20 31 28 25 25 29 31 37 33 27 28 35 30 31 28 28 27 17 22 20 28 28 23 24 27 25 23 28 33 30 22 25 28 22 31 25 30 26 17 30 25 25 31 22 21 18 20 24 31 22 16 21 41 32 18 28 22 23 26 19 32 16 22 22 19 25 30 18 25 19 19 21 24 28 19 28 25 19 29 28 24 16 25 28 25 21 30 24 22 30 22 17 27 19 29 22 16 24 28 21 29 29 21 25 26 15 16 24 23 23 22 30 24 15 19 18 25 18 17 21 15 23 26 26 28 24 20 25 24 21 17 22 14 26 16 29 28 23 22 23 22 22 16 18 22 20 17 23 14 23 20 27 19 22 24 24 22 14 18 17 16 29 22 21 15 21 20 19 26 15 28 19 19 22 22 19 18 16 19 21 26 27 15 22 30 20 20 25 17 24 16 23 30 16 17 26 31 19 16 23 21 18 20 21 20 16 16 24 21 19 9 19 26 26 10 17 15 27 19 22 32 17 19 22 20 16 17 16 20 20 20 21 12 16 25 16 15 19 26 22 23 20 15 22 15 25 27 18 25 21 25 17 12 18 16 15 20 18 17 27 24 21 23 24 28 24 20 18 21 19 16 25 20 25 16 12 16 23 19 16 18 26 12 13 22 19 28 19 25 20 16 31 15 16 23 22 21 18 23 16 20 18 30 15 14 25 17 18 16 19 20 18 19 18 20 30 16 20 17 24 17 27 8 18 15 20 13 19 24 11 16 31 17 15 21 22 22 14 18 23 17 10 21 21 16 20 18 24 11 21 20 25 22 16 19 19 23 20 20 24 16 20 23 17 24 18 17 26 13 19 16 20 15 25 22 20 19 10 15 22 14 9 15 21 15 15 17 12 23 16 18 18 16 21 20 17 18 26 13 11 20 24 20 20 19 16 22 23 20 17 17 22 18 22 10 22 20 24 16 14 8 15 17 23 10 23 19 21 14 26 16 12 22 18 22 15 22 18 17 14 23 15 11 17 11 17 22 18 25 23 15 12 15 14 13 15 20 17 23 19 15 13 16 23 16 17 16 15 15 19 19 21 21 15 15 23 17 14 15 14 21 14 24 15 15 18 16 18 22 17 20 18 12 19 16 9 17 18 14 18 18 13 19 23 10 11 14 16 19 18 20 18 14 14 14 13 12 13 10 15 19 19 19 13 20 11 13 25 19 14 18 15 13 17 15 17 16 9 16 12 13 18 17 19 12 11 14 12 17 12 12 13 21 11 11 19 16 12 12 15 13 17 12 15 13 15 14 18 12 10 7 15 12 11 21 13 22 17 21 14 17 19 13 16 14 21 15 10 16 10 19 8 16 13 7 18 19 11 17 11 9 13 11 12 16 13 14 25 16 22 6 20 21 17 12 18 12 14 12 13 17 12 14 7 14 21 18 11 14 16 8 18 13 17 17 16 12 19 15 16 14 10 15 16 11 12 15 16 17 20 17 13 14 11 11 17 11 24 17 15 9 16 12 15 14 6 10 13 23 16 10 18 14 18 11 11 9 19 14 13 10 17 15 8 12 10 9 19 16 15 11 16 18 13 17 10 20 10 11 16 14 15 16 11 10 16 15 9 9 10 15 17 13 15 17 18 19 10 19 20 11 12 14 18 23 13 13 13 9 22 10 8 16 16 17 12 14 11 10 18 12 16 10 14 15 7 11 16 16 13 11 11 18 16 23 11 12 13 4 13 13 12 13 17 11 19 13 11 15 18 12 11 11 16 8 15 8 15 17 12 16 10 10 9 18 14 17 14 22 9 12 8 14 12 15 7 13 22 14 9 7 14 15 8 12 11 19 11 13 15 9 12 15 16 12 14 9 13 15 14 18 9 19 12 14 12 12 7 10 12 15 14 16 10 14 15 17 11 11 10 6 13 14 10 13 14 13 12 9 13 8 11 10 9 16 13 10 13 15 13 6 11 5 14 10 11 16 15 15 6 21 12 7 9 12 13 14 15 14 11 6 8 9 5 14 12 7 11 15 13 16 13 13 16 11 11 5 11 5 16 8 16 13 19 12 11 15 12 17 14 10 15 21 7 8 13 10 13 11 7 12 13 11 9 16 17 15 11 10 18 5 11 14 14 11 11 10 8 12 11 12 12 6 11 11 15 12 17 8 12 12 18 11 13 11 13 10 7 9 14 10 13 10 14 11 7 9 10 13 17 13 9 11 17 10 20 12 10 12 17 8 10 4 9 9 14 10 13 13 13 15 6 11 6 11 15 14 12 13 13 8 12 6 14 9 7 10 13 17 12 4 9 16 10 8 9 8 13 10 7 10 15 14 12 11 11 12 10 8 15 9 17 11 13 4 8 8 15 10 11 15 12 10 18 11 13 19 14 7 13 4 13 10 14 13 6 15 7 11 13 11 13 10 7 10 14 8 15 10 7 14 12 9 6 8 5 9 12 10 7 13 10 6 12 6 15 8 15 8 7 12 11 10 9 7 7 13 13 12 13 12 7 13 8 8 9 16 8 14 7 8 16 8 9 13 15 18 9 7 12 7 14 9 16 8 14 13 12 7 11 7 11 12 14 14 6 9 13 6 12 6 9 10 12 6 8 13 13 12 10 11 11 8 10 6 7 8 9 11 13 10 10 12 14 12 6 10 9 7 16 6 7 10 11 12 5 8 11 14 8 10 14 14 9 5 11 11 7 6 5 7 8 9 11 9 8 11 8 16 11 15 12 6 12 7 11 13 8 10 15 10 7 15 6 9 13 18 7 11 7 11 7 10 14 9 6 8 13 10 11 10 12 11 15 11 12 13 9 9 18 12 11 9 10 11 8 13 14 4 10 9 13 8 17 5 8 12 9 10 12 9 5 9 8 12 6 14 6 12 12 9 12 12 16 8 8 8 5 6 13 16 15 6 12 11 12 8 9 8 10 16 17 6 10 12 7 8 10 13 8 14 7 17 12 6 10 9 9 12 9 13 16 10 12 7 12 13 13 8 9 13 14 10 5 5 11 8 10 8 8 12 9 8 6 10 10 12 12 11 13 13 9 13 9 9 9 7 12 8 9 11 14 13 4 12 10 5 10 10 7 6 15 14 11 15 10 14 10 11 10 10 13 12 2 11 14 8 15 12 14 11 10 14 14 10 10 9 13 12 10 13 13 9 7 8 10 8 7 8 8 16 6 15 9 11 14 12 12 9 12 9 7 6 6 5 16 9 6 8 8 11 7 9 5 9 10 9 14 8 15 8 9 14 14 12 9 7 9 9 11 6 7 9 12 13 8 10 8 11 11 13 15 9 12 9 8 10 13 7 7 7 14 7 8 11 5 6 15 9 4 10 12 13 13 14 9 9 9 10 12 6 13 2 11 13 5 12 13 6 10 8 7 14 4 7 7 7 11 7 12 12 8 17 11 9 17 6 11 11 15 6 16 6 10 16 3 7 9 8 8 2 6 13 10 6 14 9 6 11 10 15 10 17 7 9 10 13 13 8 9 14 8 10 15 15 11 12 11 8 9 9 6 6 8 10 13 10 5 5 8 12 7 10 11 9 9 6 14 9 12 10 4 13 5 14 5 12 5 7 11 11 10 11 8 17 5 11 13 8 9 8 14 9 15 7 7 13 9 13 8 12 10 9 5 12 11 14 8 10 8 15 5 10 6 7 9 9 14 8 10 10 14 16 16 9 15 7 11 11 11 10 8 6 10 8 13 12 7 13 10 7 12 14 13 8 4 7 9 7 12 7 12 10 8 11 12 10 6 12 14 4 9 11 12 7 3 13 11 16 7 10 8 6 5 7 7 13 5 6 8 8 7 13 9 14 10 7 13 5 11 8 14 9 13 10 1 12 7 13 12 8 9 11 8 15 8 8 10 9 7 6 13 6 10 11 15 9 9 7 12 12 9 5 16 7 13 19 10 8 7 7 17 8 10 10 12 16 12 14 10 14 10 10 14 10 7 14 5 8 9 13 18 14 8 13 10 11 8 6 5 9 13 7 9 8 10 14 13 9 9 6 6 10 12 13 9 8 9 9 7 9 16 13 6 10 12 6 16 12 14 14 9 14 13 10 18 9 16 14 10 11 14 9 15 10 15 11 6 12 12 7 11 6 13 8 9 16 10 8 8 12 9 11 7 12 10 15 14 11 12 8 11 9 7 11 16 8 10 10 10 10 6 11 7 9 13 11 12 11 11 6 15 7 16 10 7 19 17 10 15 9 13 9 11 8 11 15 9 12 8 7 11 11 10 15 13 9 7 5 16 14 13 18 10 8 13 8 12 8 5 11 9 9 13 11 13 12 13 9 11 11 9 11 11 16 7 22 16 13 8 14 5 11 17 13 10 14 14 8 12 19 18 15 9 10 17 12 12 18 20 13 24 15 17 23 18 19 17 11 12 6 14 10 11 10 8 8 15 9 19 19 27 14 22 19 19 16 22 15 16 18 17 18 11 15 15 13 13 14 10 18 14 17 17 15 24 20 22 29 29 12 20 23 17 24 15 14 16 12 12 16 9 9 5 21 17 18 19 16 21 13 27 31 29 30 36 32 16 25 23 10 16 13 11 15 18 19 12 18 18 13 20 31 32 32 39 41 23 36 31 23 28 25 31 23 16 16 21 16 13 13 24 14 30 22 30 44 40 41 36 43 43 49 51 42 42 32 34 23 16 15 13 15 20 26 13 26 45 32 41 62 55 56 65 75 62 74 84 83 63 58 47 37 31 29 21 19 18 27 29 42 42 66 86 94 104 110 107 141 151 113 155 140 128 123 84 93 74 59 40 49 35 55 65 96 111 165 199 224 273 303 348 368 420 416 397 388 425 353 295 267 198 150 143 141 117 160 240 351 515 834 1043 1478 1922 2469 2981 3664 4261 5086 5812 6598 7315 7987 8642 9290 9952 10414 10898 11043 11353 11419 11530 11177 10919 10531 10045 9541 8862 8317 7422 6647 5850 5124 4411 3711 2932 2356 1824 1482 1055 764 511 419 372 333 384 453 558 709 828 943 1137 1222 1275 1270 1347 1439 1411 1327 1368 1279 1340 1317 1519 1537 2117 2999 5361 10780 19075 30236 47592 71012 93883 131195 1129 1898 3516 8115 10800 4739 2167 1305 151862 101011 66399 42999 25167 12324 5109 3116 1946 1241 1004 769 616 505 392 290 224 187 146 132 117 93 84 71 76 88 111 103 84 98 101 98 91 75 90 74 56 53 66 48 35 34 25 21 27 29 28 21 24 18 36 32 22 46 35 30 38 37 39 35 27 25 28 23 21 14 23 19 21 11 17 15 9 12 17 23 24 20 24 27 24 24 18 16 18 17 21 16 14 8 15 9 11 6 8 13 14 16 18 16 16 11 15 17 15 16 13 19 13 9 11 13 13 11 12 14 14 8 6 6 13 6 14 7 5 13 18 10 13 6 14 10 11 13 9 14 15 14 16 9 3 9 13 8 10 7 9 7 21 18 14 15 11 7 6 12 9 9 9 10 13 7 13 7 9 16 12 17 11 7 4 12 8 13 6 6 12 8 10 8 12 11 10 13 16 12 9 14 7 7 8 7 6 9 9 8 9 12 5 10 11 12 9 11 20 4 6 9 9 7 3 12 12 10 9 5 11 8 11 15 6 4 10 7 6 8 8 6 9 8 10 9 10 7 10 7 4 2 10 9 12 6 6 10 15 8 8 11 12 16 7 11 14 6 8 7 8 7 10 9 9 6 8 7 7 6 4 7 10 10 6 6 10 9 9 9 4 8 2 5 7 7 5 10 8 10 5 9 5 11 6 6 8 6 4 4 6 8 4 2 9 7 9 8 10 7 15 8 9 10 10 6 15 7 7 6 3 7 8 3 10 4 9 10 6 2 3 6 4 10 6 4 6 9 11 8 5 6 14 11 10 7 5 4 13 9 5 7 7</counts>
			</dataPoints>
		</scan>
	</xrdMeasurement>
</xrdMeasurements>