File: data/previous_data/set_2-YG031-034/xrd/YG032-SRO001-STO001-06162022.xrdml
<xrdMeasurements xmlns="http://www.xrdml.com/XRDMeasurement/2.1" xmlns:xsi="http://www.w3.org/2001/XMLSchema-instance" xsi:schemaLocation="http://www.xrdml.com/XRDMeasurement/2.1 http://www.xrdml.com/XRDMeasurement/2.1/XRDMeasurement.xsd" status="Completed">
	<comment>
		<entry>Configuration=Main Configuration, Owner=User-1, Creation date=6/17/2015 3:36:16 PM</entry>
		<entry>Goniometer=HR HD (Theta/2Theta); Minimum step size 2Theta:0.0001; Minimum step size Omega:0.0001</entry>
		<entry>Sample stage=MRD Cradle; Minimum step size Phi:0.01; Minimum step size Chi:0.01; Minimum step size X:0.01; Minimum step size Y:0.01; Minimum step size Z:0.001</entry>
		<entry>Diffractometer system=XPERT-3</entry>
		<entry>Measurement program=C:\PANalytical\Data Collector\Programs\Yichen\regular_2theta_20-50_0.4s-20min.xrdmp, Identifier={AEA8F2F2-8BFA-4B07-A521-A571AF38E73A}</entry>
	</comment>
	<sample type="To be analyzed">
		<id></id>
		<name></name>
		<preparedBy></preparedBy>
	</sample>
	<xrdMeasurement measurementType="Scan" status="Completed" sampleMode="Reflection">
		<comment>
			<entry>PHD Lower Level = 4.02 (keV), PHD Upper Level = 11.27 (keV)</entry>
		</comment>
		<usedWavelength intended="K-Alpha 1">
			<kAlpha1 unit="Angstrom">1.5405980</kAlpha1>
			<kAlpha2 unit="Angstrom">1.5444260</kAlpha2>
			<kBeta unit="Angstrom">1.3922500</kBeta>
			<ratioKAlpha2KAlpha1>0.5000</ratioKAlpha2KAlpha1>
		</usedWavelength>
		<incidentBeamPath>
			<radius unit="mm">320.00</radius>
			<xRayTube id="1010048" name="Empyrean Cu LFF HR (9430 033 7310x) DK425175">
				<tension unit="kV">45.0</tension>
				<current unit="mA">40.0</current>
				<anodeMaterial>Cu</anodeMaterial>
				<focus type="Line">
					<length unit="mm">12.0</length>
					<width unit="mm">0.4</width>
					<takeOffAngle unit="deg">4.2</takeOffAngle>
				</focus>
			</xRayTube>
			<xRayMirror id="27090001" name="Inc. Beam Cu W/Si (hybrid MRD)" hybrid="true">
				<crystal type="Graded" shape="Parabolic">W/Si</crystal>
				<acceptanceAngle unit="deg">0.800</acceptanceAngle>
				<length unit="mm">60.0</length>
			</xRayMirror>
			<monochromator id="23090002" name="Hybrid monochr. 2xGe(220) Cu asym." hybrid="true">
				<crystal type="Asymmetric" shape="Flat">Ge</crystal>
				<numberOfReflections>2</numberOfReflections>
				<hkl>
					<h>2</h>
					<k>2</k>
					<l>0</l>
				</hkl>
			</monochromator>
			<divergenceSlit id="22010004" name="Fixed slit 1/2°" xsi:type="fixedDivergenceSlitType">
				<distanceToSample unit="mm">220.00</distanceToSample>
				<height unit="mm">0.76</height>
			</divergenceSlit>
			<beamAttenuator id="26010001" name="Progr. beam attenuator Ni 0.125 mm" xsi:type="intensitySwitchedBeamAttenuatorType">
				<factor>172.00</factor>
				<material>Ni</material>
				<activateLevel unit="counts per second">500000</activateLevel>
				<deactivateLevel unit="counts per second">400000</deactivateLevel>
			</beamAttenuator>
		</incidentBeamPath>
		<diffractedBeamPath>
			<radius unit="mm">320.00</radius>
			<antiScatterSlit id="22090009" name="AS slit 7.5 mm (PIXcel)" xsi:type="fixedAntiScatterSlitType">
				<height unit="mm">7.50</height>
			</antiScatterSlit>
			<sollerSlit id="21010002" name="Soller slits 0.04 rad.">
				<opening unit="rad">0.0400</opening>
			</sollerSlit>
			<receivingSlit id="22010004" name="Fixed slit 1/2°">
				<height unit="mm">0.76</height>
			</receivingSlit>
			<detector id="7010020" name="PIXcel3D-Medipix3 1x1 detector" xsi:type="areaDetectorType">
				<phd unit="%">
					<lowerLevel>25.0</lowerLevel>
					<upperLevel>70.0</upperLevel>
				</phd>
				<mode>Receiving slit</mode>
				<activeChannelsEquatorial>5</activeChannelsEquatorial>
				<activeChannelsAxial>255</activeChannelsAxial>
				<pitchEquatorial unit="mm">0.05500</pitchEquatorial>
				<pitchAxial unit="mm">0.05500</pitchAxial>
				<readOutPeriod unit="seconds">0.050</readOutPeriod>
			</detector>
		</diffractedBeamPath>
		<scan appendNumber="0" mode="Continuous" scanAxis="2Theta-Omega" status="Completed">
			<header>
				<startTimeStamp>2022-06-16T13:45:20-07:00</startTimeStamp>
				<endTimeStamp>2022-06-16T14:05:46-07:00</endTimeStamp>
				<author>
					<name>XRD</name>
				</author>
				<source>
					<applicationSoftware version="6.1b">Data Collector</applicationSoftware>
					<instrumentControlSoftware version="7.4b 20181204">XPERT-3</instrumentControlSoftware>
					<instrumentID>0000000011163216</instrumentID>
				</source>
			</header>
			<dataPoints>
				<positions axis="2Theta" unit="deg">
					<startPosition>20.0050</startPosition>
					<endPosition>49.9950</endPosition>
				</positions>
				<positions axis="Omega" unit="deg">
					<startPosition>10.3886</startPosition>
					<endPosition>25.3836</endPosition>
				</positions>
				<positions axis="Phi" unit="deg">
					<commonPosition>0.00</commonPosition>
				</positions>
				<positions axis="Chi" unit="deg">
					<commonPosition>-0.03</commonPosition>
				</positions>
				<positions axis="X" unit="mm">
					<commonPosition>0.63</commonPosition>
				</positions>
				<positions axis="Y" unit="mm">
					<commonPosition>0.00</commonPosition>
				</positions>
				<positions axis="Z" unit="mm">
					<commonPosition>8.868</commonPosition>
				</positions>
				<beamAttenuationFactors>1.00 1.00 1.00 1.00 1.00 1.00 1.00 1.00 1.00 1.00 1.00 1.00 1.00 1.00 1.00 1.00 1.00 1.00 1.00 1.00 1.00 1.00 1.00 1.00 1.00 1.00 1.00 1.00 1.00 1.00 1.00 1.00 1.00 1.00 1.00 1.00 1.00 1.00 1.00 1.00 1.00 1.00 1.00 1.00 1.00 1.00 1.00 1.00 1.00 1.00 1.00 1.00 1.00 1.00 1.00 1.00 1.00 1.00 1.00 1.00 1.00 1.00 1.00 1.00 1.00 1.00 1.00 1.00 1.00 1.00 1.00 1.00 1.00 1.00 1.00 1.00 1.00 1.00 1.00 1.00 1.00 1.00 1.00 1.00 1.00 1.00 1.00 1.00 1.00 1.00 1.00 1.00 1.00 1.00 1.00 1.00 1.00 1.00 1.00 1.00 1.00 1.00 1.00 1.00 1.00 1.00 1.00 1.00 1.00 1.00 1.00 1.00 1.00 1.00 1.00 1.00 1.00 1.00 1.00 1.00 1.00 1.00 1.00 1.00 1.00 1.00 1.00 1.00 1.00 1.00 1.00 1.00 1.00 1.00 1.00 1.00 1.00 1.00 1.00 1.00 1.00 1.00 1.00 1.00 1.00 1.00 1.00 1.00 1.00 1.00 1.00 1.00 1.00 1.00 1.00 1.00 1.00 1.00 1.00 1.00 1.00 1.00 1.00 1.00 1.00 1.00 1.00 1.00 1.00 1.00 1.00 1.00 1.00 1.00 1.00 1.00 1.00 1.00 1.00 1.00 1.00 1.00 1.00 1.00 1.00 1.00 1.00 1.00 1.00 1.00 1.00 1.00 1.00 1.00 1.00 1.00 1.00 1.00 1.00 1.00 1.00 1.00 1.00 1.00 1.00 1.00 1.00 1.00 1.00 1.00 1.00 1.00 1.00 1.00 1.00 1.00 1.00 1.00 1.00 1.00 1.00 1.00 1.00 1.00 1.00 1.00 1.00 1.00 1.00 1.00 1.00 1.00 1.00 1.00 1.00 1.00 1.00 1.00 1.00 1.00 1.00 1.00 1.00 1.00 1.00 1.00 1.00 1.00 1.00 1.00 1.00 1.00 1.00 1.00 1.00 1.00 1.00 1.00 1.00 1.00 1.00 1.00 1.00 1.00 1.00 1.00 1.00 1.00 1.00 1.00 1.00 1.00 1.00 1.00 1.00 1.00 1.00 1.00 1.00 1.00 1.00 1.00 1.00 1.00 1.00 1.00 1.00 1.00 1.00 1.00 1.00 1.00 1.00 1.00 1.00 1.00 1.00 1.00 1.00 1.00 1.00 1.00 1.00 1.00 1.00 1.00 1.00 1.00 1.00 1.00 1.00 1.00 1.00 1.00 1.00 1.00 1.00 1.00 1.00 1.00 1.00 1.00 1.00 1.00 1.00 1.00 1.00 1.00 1.00 1.00 1.00 1.00 1.00 1.00 1.00 1.00 1.00 1.00 1.00 1.00 1.00 1.00 1.00 1.00 1.00 1.00 1.00 1.00 1.00 1.00 1.00 1.00 1.00 1.00 1.00 1.00 1.00 1.00 1.00 1.00 1.00 1.00 1.00 1.00 1.00 1.00 1.00 1.00 1.00 1.00 1.00 1.00 1.00 1.00 1.00 1.00 1.00 1.00 1.00 1.00 1.00 1.00 1.00 1.00 1.00 1.00 1.00 1.00 1.00 1.00 1.00 1.00 1.00 1.00 1.00 1.00 1.00 1.00 1.00 1.00 1.00 1.00 1.00 1.00 1.00 1.00 1.00 1.00 1.00 1.00 1.00 1.00 1.00 1.00 1.00 1.00 1.00 1.00 1.00 1.00 1.00 1.00 1.00 1.00 1.00 1.00 1.00 1.00 1.00 1.00 1.00 1.00 1.00 1.00 1.00 1.00 1.00 1.00 1.00 1.00 1.00 1.00 1.00 1.00 1.00 1.00 1.00 1.00 1.00 1.00 1.00 1.00 1.00 1.00 1.00 1.00 1.00 1.00 1.00 1.00 1.00 1.00 1.00 1.00 1.00 1.00 1.00 1.00 1.00 1.00 1.00 1.00 1.00 1.00 1.00 1.00 1.00 1.00 1.00 1.00 1.00 1.00 1.00 1.00 1.00 1.00 1.00 1.00 1.00 1.00 1.00 1.00 1.00 1.00 1.00 1.00 1.00 1.00 1.00 1.00 1.00 1.00 1.00 1.00 1.00 1.00 1.00 1.00 1.00 1.00 1.00 1.00 1.00 1.00 1.00 1.00 1.00 1.00 1.00 1.00 1.00 1.00 1.00 1.00 1.00 1.00 1.00 1.00 1.00 1.00 1.00 1.00 1.00 1.00 1.00 1.00 1.00 1.00 1.00 1.00 1.00 1.00 1.00 1.00 1.00 1.00 1.00 1.00 1.00 1.00 1.00 1.00 1.00 1.00 1.00 1.00 1.00 1.00 1.00 1.00 1.00 1.00 1.00 1.00 1.00 1.00 1.00 1.00 1.00 1.00 1.00 1.00 1.00 1.00 1.00 1.00 1.00 1.00 1.00 1.00 1.00 1.00 1.00 1.00 1.00 1.00 1.00 1.00 1.00 1.00 1.00 1.00 1.00 1.00 1.00 1.00 1.00 1.00 1.00 1.00 1.00 1.00 1.00 1.00 1.00 1.00 1.00 1.00 1.00 1.00 1.00 1.00 1.00 1.00 1.00 1.00 1.00 1.00 1.00 1.00 1.00 1.00 1.00 1.00 1.00 1.00 1.00 1.00 1.00 1.00 1.00 1.00 1.00 1.00 1.00 1.00 1.00 1.00 1.00 1.00 1.00 1.00 1.00 1.00 1.00 1.00 1.00 1.00 1.00 1.00 1.00 1.00 1.00 1.00 1.00 1.00 1.00 1.00 1.00 1.00 1.00 1.00 1.00 1.00 1.00 1.00 1.00 1.00 1.00 1.00 1.00 1.00 1.00 1.00 1.00 1.00 1.00 1.00 1.00 1.00 1.00 1.00 1.00 1.00 1.00 1.00 1.00 1.00 1.00 1.00 1.00 1.00 1.00 1.00 1.00 1.00 1.00 1.00 1.00 1.00 1.00 1.00 1.00 1.00 1.00 1.00 1.00 1.00 1.00 1.00 1.00 1.00 1.00 1.00 1.00 1.00 1.00 1.00 1.00 1.00 1.00 1.00 1.00 1.00 1.00 1.00 1.00 1.00 1.00 1.00 1.00 1.00 1.00 1.00 1.00 1.00 1.00 1.00 1.00 1.00 1.00 1.00 1.00 1.00 1.00 1.00 1.00 1.00 1.00 1.00 1.00 1.00 1.00 1.00 1.00 1.00 1.00 1.00 1.00 1.00 1.00 1.00 1.00 1.00 1.00 1.00 1.00 1.00 1.00 1.00 1.00 1.00 1.00 1.00 1.00 1.00 1.00 1.00 1.00 1.00 1.00 1.00 1.00 1.00 1.00 1.00 1.00 1.00 1.00 1.00 1.00 1.00 1.00 1.00 1.00 1.00 1.00 1.00 1.00 1.00 1.00 1.00 1.00 1.00 1.00 1.00 1.00 1.00 1.00 1.00 1.00 1.00 1.00 1.00 1.00 1.00 1.00 1.00 1.00 1.00 1.00 1.00 1.00 1.00 1.00 1.00 1.00 1.00 1.00 1.00 1.00 1.00 1.00 1.00 1.00 1.00 1.00 1.00 1.00 1.00 1.00 1.00 1.00 1.00 1.00 1.00 1.00 1.00 1.00 1.00 1.00 1.00 1.00 1.00 1.00 1.00 1.00 1.00 1.00 1.00 1.00 1.00 1.00 1.00 1.00 1.00 1.00 1.00 1.00 1.00 1.00 1.00 1.00 1.00 1.00 1.00 1.00 1.00 1.00 1.00 1.00 1.00 1.00 1.00 1.00 1.00 1.00 1.00 1.00 1.00 1.00 1.00 1.00 1.00 1.00 1.00 1.00 1.00 1.00 1.00 1.00 1.00 1.00 1.00 1.00 1.00 1.00 1.00 1.00 1.00 1.00 1.00 1.00 1.00 1.00 1.00 1.00 1.00 1.00 1.00 1.00 1.00 1.00 1.00 1.00 1.00 1.00 1.00 1.00 1.00 1.00 1.00 1.00 1.00 1.00 1.00 1.00 1.00 1.00 1.00 1.00 1.00 1.00 1.00 1.00 1.00 1.00 1.00 1.00 1.00 1.00 1.00 1.00 1.00 1.00 1.00 1.00 1.00 1.00 1.00 1.00 1.00 1.00 1.00 1.00 1.00 1.00 1.00 1.00 1.00 1.00 1.00 1.00 1.00 1.00 1.00 1.00 1.00 1.00 1.00 1.00 1.00 1.00 1.00 1.00 1.00 1.00 1.00 1.00 1.00 1.00 1.00 1.00 1.00 1.00 1.00 1.00 1.00 1.00 1.00 1.00 1.00 1.00 1.00 1.00 1.00 1.00 1.00 1.00 1.00 1.00 1.00 1.00 1.00 1.00 1.00 1.00 1.00 1.00 1.00 1.00 1.00 1.00 1.00 1.00 1.00 1.00 1.00 1.00 1.00 1.00 1.00 1.00 1.00 1.00 1.00 1.00 1.00 1.00 1.00 1.00 1.00 1.00 1.00 1.00 1.00 1.00 1.00 1.00 1.00 1.00 1.00 1.00 1.00 1.00 1.00 1.00 1.00 1.00 1.00 1.00 1.00 1.00 1.00 1.00 1.00 1.00 1.00 1.00 1.00 1.00 1.00 1.00 1.00 1.00 1.00 1.00 1.00 1.00 1.00 1.00 1.00 1.00 1.00 1.00 1.00 1.00 1.00 1.00 1.00 1.00 1.00 1.00 1.00 1.00 1.00 1.00 1.00 1.00 1.00 1.00 1.00 1.00 1.00 1.00 1.00 1.00 1.00 1.00 1.00 1.00 1.00 1.00 1.00 1.00 1.00 1.00 1.00 1.00 1.00 1.00 1.00 1.00 1.00 1.00 1.00 1.00 1.00 1.00 1.00 1.00 1.00 1.00 1.00 1.00 1.00 1.00 1.00 1.00 1.00 1.00 1.00 1.00 1.00 1.00 1.00 1.00 1.00 1.00 1.00 1.00 1.00 1.00 1.00 1.00 1.00 1.00 1.00 1.00 1.00 1.00 1.00 1.00 1.00 1.00 1.00 1.00 1.00 1.00 1.00 1.00 1.00 1.00 1.00 1.00 1.00 1.00 1.00 1.00 1.00 1.00 1.00 1.00 1.00 1.00 1.00 1.00 1.00 1.00 1.00 1.00 1.00 1.00 1.00 1.00 1.00 1.00 1.00 1.00 1.00 1.00 1.00 1.00 1.00 1.00 1.00 1.00 1.00 1.00 1.00 1.00 1.00 1.00 1.00 1.00 1.00 1.00 1.00 1.00 1.00 1.00 1.00 1.00 1.00 1.00 1.00 1.00 1.00 1.00 1.00 1.00 1.00 1.00 1.00 1.00 1.00 1.00 1.00 1.00 1.00 1.00 1.00 1.00 1.00 1.00 1.00 1.00 1.00 1.00 1.00 1.00 1.00 1.00 1.00 1.00 1.00 1.00 1.00 1.00 1.00 1.00 1.00 1.00 1.00 1.00 1.00 1.00 1.00 1.00 1.00 1.00 1.00 1.00 1.00 1.00 1.00 1.00 1.00 1.00 1.00 1.00 1.00 1.00 1.00 1.00 1.00 1.00 1.00 1.00 1.00 1.00 1.00 1.00 1.00 1.00 1.00 1.00 1.00 1.00 1.00 1.00 1.00 1.00 1.00 1.00 1.00 1.00 1.00 1.00 1.00 1.00 1.00 1.00 1.00 1.00 1.00 1.00 1.00 1.00 1.00 1.00 1.00 1.00 1.00 1.00 1.00 1.00 1.00 1.00 1.00 1.00 1.00 1.00 1.00 1.00 1.00 1.00 1.00 1.00 1.00 1.00 1.00 1.00 1.00 1.00 1.00 1.00 1.00 1.00 1.00 1.00 1.00 1.00 1.00 1.00 1.00 1.00 1.00 1.00 1.00 1.00 1.00 1.00 1.00 1.00 1.00 1.00 1.00 1.00 1.00 1.00 1.00 1.00 1.00 1.00 1.00 1.00 1.00 1.00 1.00 1.00 1.00 1.00 1.00 1.00 1.00 1.00 1.00 1.00 1.00 1.00 1.00 1.00 1.00 1.00 1.00 1.00 1.00 1.00 1.00 1.00 1.00 1.00 1.00 1.00 1.00 1.00 1.00 1.00 1.00 1.00 1.00 1.00 1.00 1.00 1.00 1.00 1.00 1.00 1.00 1.00 1.00 1.00 1.00 1.00 1.00 1.00 1.00 1.00 1.00 1.00 1.00 1.00 1.00 1.00 1.00 1.00 1.00 1.00 1.00 1.00 1.00 1.00 1.00 1.00 1.00 1.00 1.00 1.00 1.00 1.00 1.00 1.00 1.00 1.00 1.00 1.00 1.00 1.00 1.00 1.00 1.00 1.00 1.00 1.00 1.00 1.00 1.00 1.00 1.00 1.00 1.00 1.00 1.00 1.00 1.00 1.00 1.00 1.00 1.00 1.00 1.00 1.00 1.00 1.00 1.00 1.00 1.00 1.00 1.00 1.00 1.00 1.00 1.00 1.00 1.00 1.00 1.00 1.00 1.00 1.00 1.00 1.00 1.00 1.00 1.00 1.00 1.00 1.00 1.00 1.00 1.00 1.00 1.00 1.00 1.00 1.00 1.00 1.00 1.00 1.00 1.00 1.00 1.00 1.00 1.00 1.00 1.00 1.00 1.00 1.00 1.00 1.00 1.00 1.00 1.00 1.00 1.00 1.00 1.00 1.00 1.00 1.00 1.00 1.00 1.00 1.00 1.00 1.00 1.00 1.00 1.00 1.00 1.00 1.00 1.00 1.00 1.00 1.00 1.00 1.00 1.00 1.00 1.00 1.00 1.00 1.00 1.00 1.00 1.00 1.00 1.00 1.00 1.00 1.00 1.00 1.00 1.00 1.00 1.00 1.00 1.00 1.00 1.00 1.00 1.00 1.00 1.00 1.00 1.00 1.00 1.00 1.00 1.00 1.00 1.00 1.00 1.00 1.00 1.00 1.00 1.00 1.00 1.00 1.00 1.00 1.00 1.00 1.00 1.00 1.00 1.00 1.00 1.00 1.00 1.00 1.00 1.00 1.00 1.00 1.00 1.00 1.00 1.00 1.00 1.00 1.00 1.00 1.00 1.00 1.00 1.00 1.00 1.00 1.00 1.00 1.00 1.00 1.00 1.00 1.00 1.00 1.00 1.00 1.00 1.00 1.00 1.00 1.00 1.00 1.00 1.00 1.00 1.00 1.00 1.00 1.00 1.00 1.00 1.00 1.00 1.00 1.00 1.00 1.00 1.00 1.00 1.00 1.00 1.00 1.00 1.00 1.00 1.00 1.00 1.00 1.00 1.00 1.00 1.00 1.00 1.00 1.00 1.00 1.00 1.00 1.00 1.00 1.00 1.00 1.00 1.00 1.00 1.00 1.00 1.00 1.00 1.00 1.00 1.00 1.00 1.00 1.00 1.00 1.00 1.00 1.00 1.00 1.00 1.00 1.00 1.00 1.00 1.00 1.00 1.00 1.00 1.00 1.00 1.00 1.00 1.00 1.00 1.00 1.00 1.00 1.00 1.00 1.00 1.00 1.00 1.00 1.00 1.00 1.00 1.00 1.00 1.00 1.00 1.00 1.00 1.00 1.00 1.00 1.00 1.00 1.00 1.00 1.00 1.00 1.00 1.00 1.00 1.00 1.00 1.00 1.00 1.00 1.00 1.00 1.00 1.00 1.00 1.00 1.00 1.00 1.00 1.00 1.00 1.00 1.00 1.00 1.00 1.00 1.00 1.00 1.00 1.00 1.00 1.00 1.00 1.00 1.00 1.00 1.00 1.00 1.00 1.00 1.00 1.00 1.00 1.00 1.00 1.00 1.00 1.00 1.00 1.00 1.00 1.00 1.00 1.00 1.00 1.00 1.00 1.00 1.00 1.00 1.00 1.00 1.00 1.00 1.00 1.00 1.00 1.00 1.00 1.00 1.00 1.00 1.00 1.00 1.00 1.00 1.00 1.00 1.00 1.00 1.00 1.00 1.00 1.00 1.00 1.00 1.00 1.00 1.00 1.00 1.00 1.00 1.00 1.00 1.00 1.00 1.00 1.00 1.00 1.00 1.00 1.00 1.00 1.00 1.00 1.00 1.00 1.00 1.00 1.00 1.00 1.00 1.00 1.00 1.00 1.00 1.00 1.00 1.00 1.00 1.00 1.00 1.00 1.00 1.00 1.00 1.00 1.00 1.00 1.00 1.00 1.00 1.00 1.00 1.00 1.00 1.00 1.00 1.00 1.00 1.00 1.00 1.00 1.00 1.00 1.00 1.00 1.00 1.00 1.00 1.00 1.00 1.00 1.00 1.00 1.00 1.00 1.00 1.00 1.00 1.00 1.00 1.00 1.00 1.00 1.00 1.00 1.00 1.00 1.00 1.00 1.00 1.00 1.00 1.00 1.00 1.00 1.00 1.00 1.00 1.00 1.00 1.00 1.00 1.00 1.00 1.00 1.00 1.00 1.00 1.00 1.00 1.00 1.00 1.00 1.00 1.00 1.00 1.00 1.00 1.00 1.00 1.00 1.00 1.00 1.00 1.00 1.00 1.00 1.00 1.00 1.00 1.00 1.00 1.00 1.00 1.00 1.00 1.00 1.00 1.00 1.00 1.00 1.00 1.00 1.00 1.00 1.00 1.00 1.00 1.00 1.00 1.00 1.00 1.00 1.00 1.00 1.00 1.00 1.00 1.00 1.00 1.00 1.00 1.00 1.00 1.00 1.00 1.00 1.00 1.00 1.00 1.00 1.00 1.00 1.00 1.00 1.00 1.00 1.00 1.00 1.00 1.00 1.00 1.00 1.00 1.00 1.00 1.00 1.00 1.00 1.00 1.00 1.00 1.00 1.00 1.00 1.00 1.00 1.00 1.00 1.00 1.00 1.00 1.00 1.00 1.00 1.00 1.00 1.00 1.00 1.00 1.00 1.00 1.00 1.00 1.00 1.00 1.00 1.00 1.00 1.00 1.00 1.00 1.00 1.00 1.00 1.00 1.00 1.00 1.00 1.00 1.00 1.00 1.00 1.00 1.00 1.00 1.00 1.00 1.00 1.00 1.00 1.00 1.00 1.00 1.00 1.00 1.00 1.00 1.00 1.00 1.00 1.00 1.00 1.00 1.00 1.00 1.00 1.00 1.00 1.00 1.00 1.00 1.00 1.00 1.00 1.00 1.00 1.00 1.00 1.00 1.00 1.00 1.00 1.00 1.00 1.00 1.00 1.00 1.00 1.00 1.00 1.00 1.00 1.00 1.00 1.00 1.00 1.00 1.00 1.00 1.00 1.00 1.00 1.00 1.00 1.00 1.00 1.00 1.00 1.00 1.00 1.00 1.00 1.00 1.00 1.00 1.00 1.00 1.00 1.00 1.00 1.00 1.00 1.00 1.00 1.00 1.00 1.00 1.00 1.00 1.00 1.00 1.00 1.00 1.00 1.00 1.00 1.00 1.00 1.00 1.00 1.00 1.00 1.00 1.00 1.00 1.00 1.00 1.00 1.00 1.00 1.00 1.00 1.00 1.00 1.00 1.00 1.00 1.00 1.00 1.00 1.00 1.00 1.00 1.00 1.00 1.00 1.00 1.00 1.00 1.00 1.00 1.00 1.00 1.00 1.00 1.00 1.00 1.00 1.00 1.00 1.00 1.00 1.00 1.00 1.00 1.00 1.00 1.00 1.00 1.00 1.00 1.00 1.00 1.00 1.00 1.00 1.00 1.00 1.00 1.00 1.00 1.00 1.00 1.00 1.00 1.00 1.00 1.00 1.00 1.00 1.00 1.00 1.00 1.00 1.00 1.00 1.00 1.00 1.00 1.00 1.00 1.00 1.00 1.00 1.00 1.00 1.00 1.00 1.00 1.00 1.00 1.00 1.00 1.00 1.00 1.00 1.00 1.00 1.00 1.00 1.00 1.00 1.00 1.00 1.00 1.00 1.00 1.00 1.00 1.00 1.00 1.00 1.00 1.00 1.00 1.00 1.00 1.00 1.00 1.00 1.00 1.00 1.00 1.00 1.00 1.00 1.00 1.00 1.00 1.00 1.00 1.00 1.00 1.00 1.00 1.00 1.00 1.00 1.00 1.00 1.00 1.00 1.00 1.00 1.00 1.00 1.00 1.00 1.00 1.00 1.00 1.00 1.00 1.00 1.00 1.00 1.00 1.00 1.00 1.00 1.00 1.00 1.00 1.00 1.00 1.00 1.00 1.00 1.00 1.00 1.00 1.00 1.00 1.00 1.00 1.00 1.00 1.00 1.00 1.00 1.00 1.00 1.00 1.00 1.00 1.00 1.00 1.00 1.00 1.00 1.00 1.00 1.00 1.00 1.00 1.00 1.00 1.00 1.00 1.00 1.00 1.00 1.00 1.00 1.00 1.00 1.00 1.00 1.00 1.00 1.00 1.00 1.00 1.00 1.00 1.00 1.00 1.00 1.00 1.00 1.00 1.00 1.00 1.00 1.00 1.00 1.00 1.00 1.00 1.00 1.00 1.00 1.00 1.00 1.00 1.00 1.00 1.00 1.00 1.00 1.00 1.00 1.00 1.00 1.00 1.00 1.00 1.00 1.00 1.00 1.00 1.00 1.00 1.00 1.00 1.00 1.00 1.00 1.00 1.00 1.00 1.00 1.00 1.00 1.00 1.00 1.00 1.00 1.00 1.00 1.00 1.00 1.00 1.00 1.00 1.00 1.00 1.00 1.00 1.00 1.00 1.00 1.00 1.00 1.00 1.00 1.00 1.00 1.00 1.00 1.00 1.00 1.00 1.00 1.00 1.00 1.00 1.00 1.00 1.00 1.00 1.00 1.00 1.00 1.00 1.00 1.00 1.00 1.00 1.00 1.00 1.00 1.00 1.00 1.00 1.00 1.00 1.00 1.00 1.00 1.00 1.00 1.00 1.00 1.00 1.00 1.00 1.00 1.00 1.00 1.00 1.00 1.00 1.00 1.00 1.00 1.00 1.00 1.00 1.00 1.00 1.00 1.00 1.00 1.00 1.00 1.00 1.00 1.00 1.00 1.00 1.00 1.00 1.00 1.00 1.00 1.00 1.00 1.00 1.00 1.00 1.00 1.00 1.00 1.00 1.00 1.00 1.00 1.00 1.00 1.00 1.00 1.00 1.00 1.00 1.00 1.00 1.00 1.00 1.00 1.00 1.00 1.00 1.00 1.00 1.00 1.00 1.00 1.00 1.00 1.00 1.00 1.00 1.00 1.00 1.00 1.00 1.00 1.00 1.00 1.00 1.00 1.00 1.00 1.00 1.00 1.00 1.00 1.00 1.00 1.00 1.00 1.00 1.00 1.00 1.00 1.00 1.00 1.00 1.00 1.00 1.00 1.00 1.00 1.00 1.00 1.00 1.00 1.00 1.00 1.00 1.00 1.00 1.00 1.00 1.00 1.00 1.00 1.00 1.00 1.00 1.00 1.00 1.00 1.00 1.00 1.00 1.00 1.00 1.00 1.00 1.00 1.00 1.00 1.00 1.00 1.00 1.00 1.00 1.00 1.00 1.00 1.00 1.00 1.00 1.00 1.00 1.00 1.00 1.00 1.00 1.00 1.00 1.00 1.00 1.00 1.00 1.00 1.00 1.00 1.00 172.00 172.00 172.00 172.00 172.00 172.00 172.00 172.00 1.00 1.00 1.00 1.00 1.00 1.00 1.00 1.00 1.00 1.00 1.00 1.00 1.00 1.00 1.00 1.00 1.00 1.00 1.00 1.00 1.00 1.00 1.00 1.00 1.00 1.00 1.00 1.00 1.00 1.00 1.00 1.00 1.00 1.00 1.00 1.00 1.00 1.00 1.00 1.00 1.00 1.00 1.00 1.00 1.00 1.00 1.00 1.00 1.00 1.00 1.00 1.00 1.00 1.00 1.00 1.00 1.00 1.00 1.00 1.00 1.00 1.00 1.00 1.00 1.00 1.00 1.00 1.00 1.00 1.00 1.00 1.00 1.00 1.00 1.00 1.00 1.00 1.00 1.00 1.00 1.00 1.00 1.00 1.00 1.00 1.00 1.00 1.00 1.00 1.00 1.00 1.00 1.00 1.00 1.00 1.00 1.00 1.00 1.00 1.00 1.00 1.00 1.00 1.00 1.00 1.00 1.00 1.00 1.00 1.00 1.00 1.00 1.00 1.00 1.00 1.00 1.00 1.00 1.00 1.00 1.00 1.00 1.00 1.00 1.00 1.00 1.00 1.00 1.00 1.00 1.00 1.00 1.00 1.00 1.00 1.00 1.00 1.00 1.00 1.00 1.00 1.00 1.00 1.00 1.00 1.00 1.00 1.00 1.00 1.00 1.00 1.00 1.00 1.00 1.00 1.00 1.00 1.00 1.00 1.00 1.00 1.00 1.00 1.00 1.00 1.00 1.00 1.00 1.00 1.00 1.00 1.00 1.00 1.00 1.00 1.00 1.00 1.00 1.00 1.00 1.00 1.00 1.00 1.00 1.00 1.00 1.00 1.00 1.00 1.00 1.00 1.00 1.00 1.00 1.00 1.00 1.00 1.00 1.00 1.00 1.00 1.00 1.00 1.00 1.00 1.00 1.00 1.00 1.00 1.00 1.00 1.00 1.00 1.00 1.00 1.00 1.00 1.00 1.00 1.00 1.00 1.00 1.00 1.00 1.00 1.00 1.00 1.00 1.00 1.00 1.00 1.00 1.00 1.00 1.00 1.00 1.00 1.00 1.00 1.00 1.00 1.00 1.00 1.00 1.00 1.00 1.00 1.00 1.00 1.00 1.00 1.00 1.00 1.00 1.00 1.00 1.00 1.00 1.00 1.00 1.00 1.00 1.00 1.00 1.00 1.00 1.00 1.00 1.00 1.00 1.00 1.00 1.00 1.00 1.00 1.00 1.00 1.00 1.00 1.00 1.00 1.00 1.00 1.00 1.00 1.00 1.00 1.00 1.00 1.00 1.00 1.00 1.00 1.00 1.00 1.00 1.00 1.00 1.00 1.00 1.00 1.00 1.00 1.00 1.00 1.00 1.00 1.00 1.00 1.00 1.00 1.00 1.00 1.00 1.00 1.00 1.00 1.00 1.00 1.00 1.00 1.00 1.00 1.00 1.00 1.00 1.00 1.00 1.00 1.00 1.00 1.00 1.00 1.00 1.00 1.00 1.00 1.00 1.00 1.00 1.00 1.00 1.00 1.00 1.00 1.00 1.00 1.00 1.00 1.00</beamAttenuationFactors>
				<commonCountingTime unit="seconds">0.352</commonCountingTime>
				<counts unit="counts">33 47 32 32 50 35 32 54 30 46 36 29 44 33 36 28 40 31 30 49 43 32 39 28 32 32 44 35 37 50 28 36 38 44 38 38 46 42 39 38 37 33 33 42 31 38 34 38 28 30 42 27 32 36 43 39 38 30 33 31 27 36 44 36 40 47 39 36 30 39 40 38 26 38 32 28 33 30 36 33 39 31 33 35 37 35 39 36 38 33 32 31 38 34 37 31 36 26 43 17 31 30 29 41 30 37 34 38 33 32 38 31 46 29 27 40 36 29 36 38 27 35 26 36 41 45 38 38 31 31 31 42 37 34 37 38 44 28 39 24 29 19 35 36 25 36 41 28 32 43 37 37 42 44 35 33 35 42 26 40 38 31 35 39 35 28 36 37 41 24 48 39 42 47 39 26 49 41 41 43 49 32 33 32 28 44 33 38 46 50 41 52 42 47 61 60 53 59 57 54 40 33 38 30 26 27 35 46 46 49 58 65 78 79 112 114 95 95 79 80 65 57 58 40 44 51 65 79 110 133 194 278 319 459 495 548 733 762 908 1011 1008 1157 1150 1206 1241 1168 1194 1133 1058 1009 894 801 769 569 532 449 347 276 242 189 164 125 106 106 112 180 245 1112 2072 3410 7575 12425 21233 37874 67109 97354 55032 16776 4429 702 387 280 197 157 115 66 72 56 61 78 58 62 82 75 95 97 80 92 57 72 55 71 64 35 47 43 31 31 36 36 34 31 32 47 44 54 53 42 57 35 41 51 34 53 39 51 45 37 51 54 50 52 71 52 59 47 33 53 39 43 38 30 36 38 33 37 33 29 32 24 30 34 26 30 35 28 30 30 33 34 30 28 28 29 24 27 22 37 34 25 23 28 15 23 28 38 33 33 31 34 29 23 25 39 28 23 38 22 25 25 19 24 20 25 20 25 38 23 27 33 33 20 37 28 17 23 22 32 21 22 32 22 22 23 30 22 24 29 30 30 27 30 31 40 33 20 21 33 24 21 36 27 22 21 23 25 29 26 34 24 30 32 29 35 30 22 29 25 30 23 24 20 27 32 25 18 40 24 32 32 25 23 29 32 18 19 20 23 24 27 29 31 15 18 28 28 31 30 24 35 18 26 31 21 26 22 25 30 19 23 23 23 22 22 26 21 20 18 24 28 24 25 33 17 28 32 19 20 21 25 22 15 19 21 30 27 21 21 19 26 21 28 19 20 24 17 23 30 28 17 14 24 21 20 19 25 14 19 24 25 26 29 21 27 21 17 21 21 30 24 27 22 20 21 24 15 21 24 22 25 21 18 28 25 18 22 20 23 23 21 22 26 18 21 23 22 21 20 25 24 19 18 22 19 20 24 20 22 16 19 19 25 19 28 21 30 23 19 23 20 20 18 25 18 19 17 16 34 26 23 29 15 21 20 18 25 15 21 25 26 22 21 19 16 21 24 22 20 25 19 20 32 21 19 18 15 14 22 21 20 19 15 15 24 22 17 21 14 30 23 24 14 18 15 16 23 18 20 22 17 16 19 11 15 17 24 18 26 18 18 23 22 23 22 23 24 17 27 21 21 17 16 16 14 28 21 24 16 21 21 14 22 18 17 14 13 20 13 18 18 14 25 15 19 18 22 23 13 22 17 22 20 19 19 29 18 13 23 23 12 19 16 22 26 17 15 19 25 18 14 21 18 18 22 18 13 21 26 19 24 18 15 17 16 10 23 27 19 11 12 17 20 27 16 27 12 17 19 18 20 18 14 21 13 18 17 27 20 20 19 19 15 25 18 20 16 17 15 17 18 19 24 21 23 22 22 23 13 20 24 16 29 10 10 14 22 16 18 17 15 10 27 18 18 16 18 18 19 22 11 18 17 18 26 17 13 16 25 18 16 28 13 24 25 23 19 16 24 19 23 20 17 18 19 17 22 29 27 23 26 18 24 19 29 24 25 23 30 17 18 16 16 31 18 11 22 14 14 21 27 17 17 12 20 17 10 21 20 12 13 18 18 15 16 19 15 11 18 18 20 18 26 14 25 17 11 27 24 23 18 21 15 20 19 17 15 14 17 16 18 16 18 24 15 17 18 29 26 12 17 14 16 17 17 12 20 20 17 13 21 12 16 16 11 15 25 12 19 19 23 15 16 8 7 21 25 15 19 11 15 12 13 15 18 19 17 12 11 12 9 10 21 9 18 15 11 19 5 16 18 23 20 13 17 13 20 16 19 18 18 11 22 16 7 22 21 17 13 17 14 9 13 22 12 11 15 12 18 12 15 15 18 14 14 17 20 10 20 16 12 10 16 17 15 20 16 12 16 18 14 13 14 12 10 16 20 12 12 20 19 19 20 10 19 22 16 16 15 10 21 10 25 14 18 9 16 21 23 9 15 17 16 14 13 13 9 14 12 20 13 9 18 9 16 13 13 19 10 20 10 15 20 11 9 18 17 25 12 11 15 16 14 14 12 17 19 18 16 20 14 16 15 12 17 7 16 17 11 14 15 27 13 15 15 14 18 11 13 22 16 20 12 25 15 18 10 7 16 8 14 9 16 11 14 13 19 14 17 9 9 22 13 14 23 13 15 9 12 7 11 12 11 14 21 11 18 9 12 13 16 12 13 7 17 7 13 16 19 17 7 18 15 10 20 12 13 10 16 18 8 13 16 17 13 17 7 13 10 18 12 18 12 19 7 14 19 19 17 15 13 11 24 13 12 19 20 14 7 15 6 13 11 8 20 15 9 20 7 13 13 11 10 13 11 10 9 14 13 11 10 14 20 9 8 12 11 14 10 13 13 8 17 6 12 9 5 10 18 12 13 20 16 12 10 14 13 14 11 7 17 13 15 10 9 17 20 9 11 16 15 16 15 16 9 18 16 15 10 16 11 17 14 13 13 18 10 15 12 11 17 8 12 12 13 18 8 12 5 9 15 16 11 6 12 10 11 16 16 10 12 14 8 19 14 16 12 19 15 11 15 11 8 16 16 13 7 14 14 11 8 10 12 19 15 11 18 13 8 14 9 7 15 12 16 10 18 10 11 15 14 14 15 13 12 9 7 10 21 8 10 11 6 9 10 8 11 10 12 14 10 15 20 13 11 17 14 16 16 10 9 11 9 15 8 8 9 11 15 12 11 15 11 9 14 16 8 9 12 11 13 8 14 17 18 5 10 9 11 10 7 9 15 8 10 14 13 11 11 14 15 18 11 21 15 10 14 15 13 12 9 11 13 10 13 7 7 8 4 6 14 10 15 10 9 13 15 15 11 9 12 17 21 11 14 13 13 10 5 14 13 12 13 17 8 12 12 9 9 9 14 13 13 10 15 7 15 7 12 11 11 12 22 16 12 7 9 8 15 10 11 7 9 6 11 10 17 9 8 20 11 10 18 14 11 16 17 9 11 8 9 8 13 9 11 11 15 12 18 11 16 12 14 12 8 13 11 16 16 19 12 14 11 11 3 11 9 13 13 9 12 12 6 10 9 12 8 12 14 9 5 13 10 12 10 18 7 8 11 11 10 10 12 15 7 7 7 11 9 10 10 13 7 7 10 9 14 8 16 10 11 10 13 21 9 8 15 16 9 8 11 14 13 12 18 11 10 9 6 4 13 17 11 11 13 4 13 13 12 8 11 10 5 6 16 12 11 14 14 11 13 7 9 14 10 9 9 14 14 10 10 8 12 7 12 10 13 13 16 4 8 13 19 10 9 14 14 9 13 12 12 13 13 12 5 11 14 10 16 11 9 12 7 9 12 12 10 9 10 5 12 14 9 11 7 8 6 20 5 12 18 11 11 9 9 8 8 8 10 11 13 11 11 5 8 9 13 11 6 11 15 11 9 4 11 10 5 8 7 11 15 10 6 10 6 5 15 9 9 7 9 10 5 11 10 15 9 9 8 4 11 11 8 7 5 15 7 7 8 12 13 6 13 9 15 10 8 8 5 8 5 13 9 11 9 14 8 14 14 7 16 9 7 5 9 10 20 11 8 9 4 8 6 12 9 7 7 13 15 12 15 7 13 6 11 7 7 14 9 12 10 8 14 7 2 5 12 10 8 8 10 11 15 11 12 9 14 16 11 12 12 16 10 16 6 9 9 12 9 11 8 7 8 9 8 11 5 11 11 8 14 16 7 14 16 6 11 8 10 4 13 14 9 7 9 12 8 10 5 10 6 9 12 8 11 9 7 11 9 5 9 4 10 11 6 13 12 10 4 14 14 10 12 7 9 11 6 12 11 9 9 10 9 11 11 7 10 8 11 10 11 10 4 8 12 14 12 11 8 11 7 12 10 7 11 8 9 10 9 10 6 15 10 7 12 16 7 6 6 11 6 16 10 9 7 11 13 11 10 10 14 11 7 15 11 7 8 11 11 14 14 9 9 7 11 16 14 14 12 14 6 8 13 8 6 11 9 10 13 8 12 10 4 2 8 10 8 8 9 14 8 10 14 13 13 12 12 4 14 11 4 18 14 7 14 10 8 16 15 11 10 6 10 6 5 15 5 13 8 7 12 12 10 9 9 16 19 10 17 12 7 12 9 7 9 6 5 11 9 12 10 16 9 12 9 11 11 10 9 3 11 7 6 9 13 10 10 12 5 9 12 7 10 14 10 13 11 15 11 11 14 14 8 13 11 11 9 4 12 5 8 10 9 11 8 16 16 8 7 11 10 12 6 8 12 2 6 13 12 12 4 8 11 11 10 7 7 11 11 12 18 9 10 11 19 6 15 10 10 6 5 13 9 10 12 9 7 9 9 9 7 12 14 12 12 5 4 7 7 12 7 6 12 6 15 6 11 11 10 11 11 16 11 8 13 13 8 14 11 12 16 13 15 8 16 10 13 3 8 11 17 8 14 13 9 8 11 8 6 6 14 4 9 8 7 13 10 14 3 9 8 8 16 11 11 19 10 13 12 6 9 9 8 7 9 12 9 9 13 6 15 13 16 8 19 13 11 9 10 10 8 9 11 10 12 8 8 8 10 9 10 10 5 13 15 8 15 17 11 14 10 15 9 10 8 12 8 9 19 16 12 11 9 14 9 11 7 7 8 10 8 10 12 12 11 10 9 11 11 10 10 9 10 10 7 12 17 11 13 15 10 18 13 9 10 11 11 19 15 14 11 11 7 9 8 14 6 6 8 15 12 8 7 13 12 11 11 14 15 18 17 11 12 16 10 8 8 11 13 9 13 8 12 9 8 17 17 13 12 10 10 13 15 18 7 11 10 12 14 11 7 17 9 6 15 13 7 16 12 12 16 19 11 10 10 14 10 13 8 7 22 11 9 14 12 13 11 11 13 16 17 16 19 18 9 15 12 7 13 7 6 9 14 15 15 13 13 14 9 13 14 15 17 16 15 11 14 11 7 8 11 16 12 12 8 6 11 15 14 11 16 17 13 14 18 21 13 25 16 17 18 11 5 10 10 6 7 15 8 6 16 12 18 20 16 14 16 18 14 8 26 19 22 16 17 20 12 14 9 18 17 18 15 19 20 14 22 16 25 18 28 18 19 21 15 11 21 19 11 16 19 14 12 18 20 14 17 26 32 31 22 28 28 22 21 30 28 13 20 18 15 17 9 12 16 11 10 17 24 29 26 29 27 46 41 38 29 30 33 27 27 22 16 21 19 23 17 18 26 30 30 49 37 36 46 48 49 41 54 31 44 25 33 31 26 23 28 15 18 24 37 30 46 54 52 64 75 75 88 68 82 66 64 58 54 46 42 23 25 25 34 37 44 73 84 83 100 107 127 138 139 137 133 129 110 109 108 74 70 55 50 49 54 74 105 143 166 227 240 323 354 367 432 382 425 377 378 358 306 253 225 190 184 205 271 401 592 829 1127 1564 2031 2631 3239 4019 4678 5727 6502 7258 8338 8928 9738 10431 11106 11372 11915 11769 11655 12006 11618 11267 10320 9937 9234 8427 7735 6657 5760 5045 4226 3305 2728 2023 1534 1121 860 595 418 389 382 429 526 678 754 895 1031 1184 1229 1239 1263 1312 1226 1186 1106 1107 1029 1004 1035 1030 1108 1342 1711 2459 3373 5732 10915 17619 26050 36291 48344 61941 77622 108751 155863 1280 1599 2138 2955 5838 8075 3639 1333 104396 32358 13150 5745 2846 1745 1219 894 607 463 338 294 245 200 184 170 170 177 187 178 169 177 151 113 135 126 103 74 66 53 36 28 27 21 33 32 24 28 32 26 43 42 55 53 37 42 45 38 38 25 26 25 15 20 9 11 14 13 15 20 25 20 20 27 22 24 18 26 23 21 25 11 13 16 11 13 8 14 8 11 13 13 16 10 30 9 24 31 20 18 20 13 22 16 14 13 9 9 10 9 7 12 10 10 5 14 9 8 14 21 10 14 12 14 16 10 16 8 7 9 8 7 3 12 6 7 13 10 10 17 7 12 12 16 13 11 15 12 6 11 12 7 5 6 9 6 12 5 12 12 4 16 6 17 8 12 8 9 19 7 11 8 5 8 4 8 6 9 9 7 8 7 6 9 7 9 4 7 11 10 12 9 9 18 8 14 10 10 13 11 8 7 8 10 12 8 14 13 10 9 10 8 9 9 10 8 11 8 6 10 11 8 13 7 4 6 9 10 12 14 10 12 7 5 9 16 10 5 6 9 8 7 8 9 9 16 7 4 6 11 13 11 9 9 8 9 10 11 7 5 12 6 11 5 5 6 7 7 8 9 5 10 5 8 9 11 8 12 5 7 14 6 7 10 9 6 3 3 11 8 9 7 10 21 8 3 15 4 14 9 4 11 5 16 9 9 8 6 11 4 4 5 8 9 5 5 7 5 6 6 7 7 7 11 7 7 4 8 8 3 8 7 5 6 5 6 3 6 5 9 7 4 8 9 6 10 7 13 5 5 4 7 7 9 10 9 8 10 8 9</counts>
			</dataPoints>
		</scan>
	</xrdMeasurement>
</xrdMeasurements>