File: data/XRD_RSM/YG068/YG068_RSM-002.xrdml
<?xml version="1.0" encoding="utf-8"?>
<xrdMeasurements xmlns="http://www.xrdml.com/XRDMeasurement/2.2" xmlns:xsi="http://www.w3.org/2001/XMLSchema-instance" xsi:schemaLocation="http://www.xrdml.com/XRDMeasurement/2.2 http://www.xrdml.com/XRDMeasurement/2.2/XRDMeasurement.xsd" status="Completed">
	<comment>
		<entry>Configuration=3-axes Cradle_Reflection, Owner=lw627, Creation date=9/2/2021 3:55:24 PM</entry>
		<entry>Goniometer=Theta/Theta; Minimum step size 2Theta:0.0001; Minimum step size Omega:0.0001</entry>
		<entry>Sample stage=Chi-Phi-z stage 240 mm (reflection); Minimum step size Phi:0.01; Minimum step size Chi:0.01; Minimum step size Z:0.001</entry>
		<entry>Diffractometer system=EMPYREAN</entry>
		<entry>Measurement program=C:\PANalytical\Data Collector\Programs\Liyan Wu\Film programs\RSM slow 3 degree.xrdmp, Identifier={0351664C-55A7-43E7-B72A-7307F4B26703}</entry>
	</comment>
	<sample type="To be analyzed">
		<id/>
		<name/>
		<preparedBy/>
	</sample>
	<xrdMeasurement status="Completed" measurementType="Area measurement" measurementStepAxis="Omega-2Theta" sampleMode="Reflection">
		<comment>
			<entry>PHD Lower Level = 4.02 (keV), PHD Upper Level = 11.27 (keV)</entry>
		</comment>
		<usedWavelength intended="K-Alpha 1">
			<kAlpha1 unit="Angstrom">1.5405980</kAlpha1>
			<kAlpha2 unit="Angstrom">1.5444260</kAlpha2>
			<kBeta unit="Angstrom">1.3922500</kBeta>
			<ratioKAlpha2KAlpha1>0</ratioKAlpha2KAlpha1>
		</usedWavelength>
		<incidentBeamPath>
			<radius unit="mm">240.00</radius>
			<xRayTube id="1010048" name="Empyrean Cu LFF HR (9430 033 7310x) DK432574">
				<tension unit="kV">45.0</tension>
				<current unit="mA">40.0</current>
				<anodeMaterial>Cu</anodeMaterial>
				<focus type="Line">
					<length unit="mm">12.0</length>
					<width unit="mm">0.4</width>
					<takeOffAngle unit="deg">4.4</takeOffAngle>
				</focus>
			</xRayTube>
			<xRayMirror xsi:type="xRayMirrorType" id="27080001" name="Inc. Beam Cu W/Si (hybrid MPD)" hybrid="true">
				<crystal type="Graded" shape="Parabolic">W/Si</crystal>
				<acceptanceAngle unit="deg">0.800</acceptanceAngle>
				<length unit="mm">55.3</length>
			</xRayMirror>
			<monochromator xsi:type="monochromatorType" id="23090002" name="Hybrid monochr. 2xGe220 Cu asym." hybrid="true">
				<crystal type="Asymmetric" shape="Flat">Ge</crystal>
				<numberOfReflections>2</numberOfReflections>
				<hkl>
					<h>2</h>
					<k>2</k>
					<l>0</l>
				</hkl>
			</monochromator>
			<mask xsi:type="maskType" id="22030008" name="Fixed mask 4 mm">
				<distanceToSample unit="mm">171.00</distanceToSample>
				<width unit="mm">4.00</width>
			</mask>
			<divergenceSlit xsi:type="fixedDivergenceSlitType" id="22010005" name="Fixed slit 1/4°">
				<distanceToSample unit="mm">179.30</distanceToSample>
				<height unit="mm">0.38</height>
			</divergenceSlit>
		</incidentBeamPath>
		<diffractedBeamPath>
			<radius unit="mm">240.00</radius>
			<antiScatterSlit xsi:type="fixedAntiScatterSlitType" id="22060009" name="Programmable anti-scatter slit">
				<angle unit="deg">4</angle>
			</antiScatterSlit>
			<detector xsi:type="areaDetectorType" id="7010020" name="PIXcel3D-Medipix3 1x1 detector">
				<phd unit="%">
					<lowerLevel>25</lowerLevel>
					<upperLevel>70</upperLevel>
				</phd>
				<mode>Scanning snapshot equatorial</mode>
				<activeChannelsEquatorial>255</activeChannelsEquatorial>
				<activeChannelsAxial>255</activeChannelsAxial>
				<pitchEquatorial unit="mm">0.05500</pitchEquatorial>
				<pitchAxial unit="mm">0.05500</pitchAxial>
				<readOutPeriod unit="seconds">0.980</readOutPeriod>
			</detector>
		</diffractedBeamPath>
		<scan status="Completed" appendNumber="0" scanAxis="2Theta" mode="Continuous">
			<header>
				<startTimeStamp>2024-11-01T13:58:14-04:00</startTimeStamp>
				<endTimeStamp>2024-11-01T14:28:19-04:00</endTimeStamp>
				<author>
					<name>lw627</name>
				</author>
				<source>
					<applicationSoftware version="7.1">Data Collector</applicationSoftware>
					<instrumentControlSoftware version="8.2  20201204">EMPYREAN</instrumentControlSoftware>
					<instrumentID>0000000011260721</instrumentID>
				</source>
			</header>
			<dataPoints>
				<positions axis="2Theta" unit="deg">
					<startPosition>41.2294063943918</startPosition>
					<endPosition>44.5766761656082</endPosition>
				</positions>
				<positions axis="Omega" unit="deg">
					<commonPosition>21.45152064</commonPosition>
				</positions>
				<positions axis="Phi" unit="deg">
					<commonPosition>3.05</commonPosition>
				</positions>
				<positions axis="Chi" unit="deg">
					<commonPosition>0</commonPosition>
				</positions>
				<positions axis="Z" unit="mm">
					<commonPosition>8.407</commonPosition>
				</positions>
				<commonCountingTime unit="seconds">0.974</commonCountingTime>
				<counts unit="counts">1 0 0 1 0 0 0 2 1 0 0 0 1 0 0 1 2 0 0 0 0 0 1 1 0 0 0 0 0 0 1 0 0 1 0 0 0 0 0 0 0 1 0 0 1 0 0 0 0 0 0 0 0 0 0 1 1 1 0 2 1 0 0 1 0 0 0 1 0 0 0 0 0 2 0 0 0 0 0 2 0 1 1 0 0 0 0 2 0 0 0 0 0 2 0 1 0 0 0 1 0 1 1 0 0 0 1 1 0 0 1 0 0 0 0 2 0 0 0 1 0 0 0 1 0 0 1 1 1 0 0 1 0 0 0 1 0 0 0 1 0 0 0 0 0 1 0 0 0 1 0 0 0 0 0 1 1 0 0 1 0 0 0 1 0 0 0 0 0 0 0 0 0 0 0 1 0 0 0 0 0 1 0 0 0 2 0 0 0 0 0 0 2 0 1 0 0 0 0 1 1 0 0 1 0 0 1 0 1 0 0 2 0 0 0 0 1 1 0 1 0 1 0 0 0 0 0 1 0 1 0 0 0 1 1 2 1 1 0 0 0 1 0 1 0 0 0 0 0 2 0 0 0 0 2</counts>
			</dataPoints>
		</scan>
		<scan status="Completed" appendNumber="0" scanAxis="2Theta" mode="Continuous">
			<header>
				<startTimeStamp>2024-11-01T13:58:14-04:00</startTimeStamp>
				<endTimeStamp>2024-11-01T14:28:19-04:00</endTimeStamp>
				<author>
					<name>lw627</name>
				</author>
				<source>
					<applicationSoftware version="7.1">Data Collector</applicationSoftware>
					<instrumentControlSoftware version="8.2  20201204">EMPYREAN</instrumentControlSoftware>
					<instrumentID>0000000011260721</instrumentID>
				</source>
			</header>
			<dataPoints>
				<positions axis="2Theta" unit="deg">
					<startPosition>41.2326889650599</startPosition>
					<endPosition>44.5799587362764</endPosition>
				</positions>
				<positions axis="Omega" unit="deg">
					<commonPosition>21.4531619253341</commonPosition>
				</positions>
				<positions axis="Phi" unit="deg">
					<commonPosition>3.05</commonPosition>
				</positions>
				<positions axis="Chi" unit="deg">
					<commonPosition>0</commonPosition>
				</positions>
				<positions axis="Z" unit="mm">
					<commonPosition>8.407</commonPosition>
				</positions>
				<commonCountingTime unit="seconds">0.974</commonCountingTime>
				<counts unit="counts">0 1 0 0 1 1 0 0 0 1 1 1 0 0 0 0 0 0 1 0 1 0 1 1 0 1 0 1 0 2 1 0 1 1 0 0 1 0 0 0 0 0 1 0 0 0 0 0 0 2 0 0 0 0 0 1 1 0 1 0 0 0 0 1 0 1 1 0 0 0 0 0 0 0 1 2 1 0 0 0 0 0 0 1 0 0 0 1 0 0 0 0 0 0 0 0 2 1 0 0 0 0 0 2 0 0 0 1 0 0 1 0 0 0 0 1 0 1 0 0 0 0 0 1 0 1 2 1 0 1 1 0 0 0 0 0 0 0 0 0 0 0 0 0 2 1 0 0 1 0 0 1 1 1 0 0 0 0 0 0 1 2 1 0 0 0 1 0 0 0 0 2 1 0 1 0 1 1 0 1 2 0 0 1 0 0 0 0 0 0 0 1 0 0 0 0 0 0 0 0 0 0 0 0 1 0 0 0 0 0 0 0 0 1 0 0 1 0 1 1 0 0 0 0 0 0 0 0 0 0 0 1 0 1 0 0 2 0 0 0 0 1 0 1 0 0 0 2 1 1 0 0 1 1 0</counts>
			</dataPoints>
		</scan>
		<scan status="Completed" appendNumber="0" scanAxis="2Theta" mode="Continuous">
			<header>
				<startTimeStamp>2024-11-01T13:58:14-04:00</startTimeStamp>
				<endTimeStamp>2024-11-01T14:28:19-04:00</endTimeStamp>
				<author>
					<name>lw627</name>
				</author>
				<source>
					<applicationSoftware version="7.1">Data Collector</applicationSoftware>
					<instrumentControlSoftware version="8.2  20201204">EMPYREAN</instrumentControlSoftware>
					<instrumentID>0000000011260721</instrumentID>
				</source>
			</header>
			<dataPoints>
				<positions axis="2Theta" unit="deg">
					<startPosition>41.235971535728</startPosition>
					<endPosition>44.5832413069445</endPosition>
				</positions>
				<positions axis="Omega" unit="deg">
					<commonPosition>21.4548032106681</commonPosition>
				</positions>
				<positions axis="Phi" unit="deg">
					<commonPosition>3.05</commonPosition>
				</positions>
				<positions axis="Chi" unit="deg">
					<commonPosition>0</commonPosition>
				</positions>
				<positions axis="Z" unit="mm">
					<commonPosition>8.407</commonPosition>
				</positions>
				<commonCountingTime unit="seconds">0.974</commonCountingTime>
				<counts unit="counts">2 0 1 0 0 1 1 0 0 1 1 0 0 0 2 1 1 0 0 1 1 0 0 0 0 0 0 0 1 1 0 2 0 1 0 0 0 0 2 1 1 0 0 0 0 1 1 0 0 0 1 2 0 0 1 0 0 1 0 1 0 0 0 1 0 0 0 0 1 1 0 0 0 1 0 2 0 0 0 1 0 2 0 0 1 0 1 1 0 0 1 0 0 0 0 0 1 0 0 1 1 0 0 0 0 0 1 0 0 0 0 0 1 1 0 0 0 0 0 0 0 0 0 0 1 2 0 0 0 1 1 1 0 1 0 0 0 0 0 0 0 1 0 0 1 0 0 2 0 2 1 0 0 0 1 1 1 1 1 1 1 1 1 0 0 0 0 3 0 1 1 1 0 0 0 3 0 2 1 0 0 0 0 0 0 0 0 0 0 0 0 1 0 0 0 0 0 0 1 0 0 1 0 0 0 1 0 0 0 1 0 0 0 0 0 0 0 0 0 1 0 0 0 0 0 0 0 0 1 0 0 0 0 0 0 1 0 0 2 0 0 0 0 0 0 0 0 1 0 0 1 0 0 0 0</counts>
			</dataPoints>
		</scan>
		<scan status="Completed" appendNumber="0" scanAxis="2Theta" mode="Continuous">
			<header>
				<startTimeStamp>2024-11-01T13:58:14-04:00</startTimeStamp>
				<endTimeStamp>2024-11-01T14:28:19-04:00</endTimeStamp>
				<author>
					<name>lw627</name>
				</author>
				<source>
					<applicationSoftware version="7.1">Data Collector</applicationSoftware>
					<instrumentControlSoftware version="8.2  20201204">EMPYREAN</instrumentControlSoftware>
					<instrumentID>0000000011260721</instrumentID>
				</source>
			</header>
			<dataPoints>
				<positions axis="2Theta" unit="deg">
					<startPosition>41.2392541063961</startPosition>
					<endPosition>44.5865238776126</endPosition>
				</positions>
				<positions axis="Omega" unit="deg">
					<commonPosition>21.4564444960022</commonPosition>
				</positions>
				<positions axis="Phi" unit="deg">
					<commonPosition>3.05</commonPosition>
				</positions>
				<positions axis="Chi" unit="deg">
					<commonPosition>0</commonPosition>
				</positions>
				<positions axis="Z" unit="mm">
					<commonPosition>8.407</commonPosition>
				</positions>
				<commonCountingTime unit="seconds">0.974</commonCountingTime>
				<counts unit="counts">0 0 3 0 1 0 3 1 0 1 1 0 0 0 0 0 0 0 1 0 0 0 0 1 1 0 0 0 1 0 0 0 0 1 1 0 0 0 0 1 0 0 0 0 0 1 0 2 0 0 1 0 1 0 0 1 0 0 0 1 1 1 1 0 0 1 1 0 0 1 0 0 1 0 0 2 0 1 0 0 0 0 0 2 1 0 1 0 0 1 1 0 0 0 1 1 0 0 1 1 0 1 0 0 0 0 0 0 1 0 0 1 0 0 1 0 0 1 0 0 0 0 0 2 0 0 0 0 0 1 1 0 0 1 0 0 0 0 0 0 0 0 0 1 0 0 0 0 0 0 0 1 0 0 0 1 0 0 0 0 1 0 1 0 0 0 0 0 0 1 0 0 0 0 0 0 1 0 1 0 1 1 0 0 1 1 0 1 0 0 1 0 0 0 1 0 0 0 2 0 0 0 0 0 0 0 1 1 0 0 1 0 0 0 0 1 0 1 2 0 1 0 0 0 0 0 0 2 0 0 0 0 0 1 0 0 1 0 0 0 1 0 0 1 0 0 0 0 0 0 0 1 0 0 0</counts>
			</dataPoints>
		</scan>
		<scan status="Completed" appendNumber="0" scanAxis="2Theta" mode="Continuous">
			<header>
				<startTimeStamp>2024-11-01T13:58:14-04:00</startTimeStamp>
				<endTimeStamp>2024-11-01T14:28:19-04:00</endTimeStamp>
				<author>
					<name>lw627</name>
				</author>
				<source>
					<applicationSoftware version="7.1">Data Collector</applicationSoftware>
					<instrumentControlSoftware version="8.2  20201204">EMPYREAN</instrumentControlSoftware>
					<instrumentID>0000000011260721</instrumentID>
				</source>
			</header>
			<dataPoints>
				<positions axis="2Theta" unit="deg">
					<startPosition>41.2425366770643</startPosition>
					<endPosition>44.5898064482807</endPosition>
				</positions>
				<positions axis="Omega" unit="deg">
					<commonPosition>21.4580857813363</commonPosition>
				</positions>
				<positions axis="Phi" unit="deg">
					<commonPosition>3.05</commonPosition>
				</positions>
				<positions axis="Chi" unit="deg">
					<commonPosition>0</commonPosition>
				</positions>
				<positions axis="Z" unit="mm">
					<commonPosition>8.407</commonPosition>
				</positions>
				<commonCountingTime unit="seconds">0.974</commonCountingTime>
				<counts unit="counts">1 0 0 0 0 0 0 0 0 1 0 0 0 0 1 0 0 1 0 1 0 0 0 0 1 0 0 0 0 0 0 0 1 0 0 0 1 0 0 0 0 0 0 0 1 0 0 1 1 1 0 0 0 1 1 0 0 1 1 0 0 0 0 0 0 0 0 0 0 0 1 1 0 0 0 0 0 0 0 0 0 1 0 0 0 2 1 0 1 1 1 0 0 0 0 0 0 0 0 0 1 0 0 0 0 0 0 1 2 0 0 0 0 0 0 0 0 0 0 0 0 0 1 0 2 0 1 1 0 1 0 0 0 1 1 0 0 0 0 1 0 0 0 0 0 0 0 0 0 1 0 1 0 0 1 1 0 0 0 0 0 0 1 0 0 1 0 0 0 0 0 1 1 0 0 0 0 0 0 0 0 0 1 1 1 0 0 0 0 0 0 0 0 0 0 0 1 0 0 1 0 0 0 0 1 0 0 0 0 0 0 0 1 0 0 0 1 1 2 0 2 1 0 0 0 0 1 0 0 1 0 0 0 0 0 0 0 0 0 0 0 1 0 0 0 1 0 0 0 0 0 0 0 0 1</counts>
			</dataPoints>
		</scan>
		<scan status="Completed" appendNumber="0" scanAxis="2Theta" mode="Continuous">
			<header>
				<startTimeStamp>2024-11-01T13:58:14-04:00</startTimeStamp>
				<endTimeStamp>2024-11-01T14:28:19-04:00</endTimeStamp>
				<author>
					<name>lw627</name>
				</author>
				<source>
					<applicationSoftware version="7.1">Data Collector</applicationSoftware>
					<instrumentControlSoftware version="8.2  20201204">EMPYREAN</instrumentControlSoftware>
					<instrumentID>0000000011260721</instrumentID>
				</source>
			</header>
			<dataPoints>
				<positions axis="2Theta" unit="deg">
					<startPosition>41.2458192477324</startPosition>
					<endPosition>44.5930890189489</endPosition>
				</positions>
				<positions axis="Omega" unit="deg">
					<commonPosition>21.4597270666703</commonPosition>
				</positions>
				<positions axis="Phi" unit="deg">
					<commonPosition>3.05</commonPosition>
				</positions>
				<positions axis="Chi" unit="deg">
					<commonPosition>0</commonPosition>
				</positions>
				<positions axis="Z" unit="mm">
					<commonPosition>8.407</commonPosition>
				</positions>
				<commonCountingTime unit="seconds">0.974</commonCountingTime>
				<counts unit="counts">0 1 0 1 1 1 0 0 1 0 0 0 2 0 3 1 1 2 0 0 2 0 0 1 1 0 0 0 0 0 0 1 0 2 0 0 1 0 0 0 0 0 0 0 0 0 1 0 0 3 0 0 0 0 0 0 0 0 0 0 0 0 0 0 0 0 0 0 0 1 0 0 0 0 0 0 0 1 0 0 1 0 0 0 0 0 0 1 0 0 0 0 1 0 0 0 0 0 1 1 0 0 0 0 0 0 0 0 0 0 0 0 0 0 0 1 1 0 0 0 0 0 0 0 0 0 1 1 2 0 0 0 1 0 1 0 0 2 0 0 1 0 1 0 1 1 0 0 0 0 0 0 0 0 0 0 0 0 0 0 0 0 0 1 0 0 3 2 0 0 0 0 0 1 0 0 0 2 0 0 0 0 0 0 0 0 2 0 1 0 0 0 1 0 0 0 0 0 1 1 0 0 0 0 0 0 1 0 0 0 0 0 0 1 0 0 0 0 0 0 0 0 1 0 0 0 1 1 0 0 0 0 0 1 0 0 0 0 0 0 0 0 0 1 0 1 0 0 0 0 0 0 0 1 0</counts>
			</dataPoints>
		</scan>
		<scan status="Completed" appendNumber="0" scanAxis="2Theta" mode="Continuous">
			<header>
				<startTimeStamp>2024-11-01T13:58:14-04:00</startTimeStamp>
				<endTimeStamp>2024-11-01T14:28:19-04:00</endTimeStamp>
				<author>
					<name>lw627</name>
				</author>
				<source>
					<applicationSoftware version="7.1">Data Collector</applicationSoftware>
					<instrumentControlSoftware version="8.2  20201204">EMPYREAN</instrumentControlSoftware>
					<instrumentID>0000000011260721</instrumentID>
				</source>
			</header>
			<dataPoints>
				<positions axis="2Theta" unit="deg">
					<startPosition>41.2491018184005</startPosition>
					<endPosition>44.596371589617</endPosition>
				</positions>
				<positions axis="Omega" unit="deg">
					<commonPosition>21.4613683520044</commonPosition>
				</positions>
				<positions axis="Phi" unit="deg">
					<commonPosition>3.05</commonPosition>
				</positions>
				<positions axis="Chi" unit="deg">
					<commonPosition>0</commonPosition>
				</positions>
				<positions axis="Z" unit="mm">
					<commonPosition>8.407</commonPosition>
				</positions>
				<commonCountingTime unit="seconds">0.974</commonCountingTime>
				<counts unit="counts">2 0 2 0 0 0 0 0 0 0 1 1 0 0 1 0 0 2 0 1 0 0 0 0 0 0 0 0 0 0 0 0 0 0 0 1 0 2 1 0 0 0 0 2 0 0 1 0 0 0 2 0 0 1 0 0 0 0 1 0 0 0 1 0 1 0 1 0 0 0 0 1 0 0 0 0 0 0 1 1 0 1 1 0 1 1 1 0 0 0 0 1 0 0 0 0 0 0 0 0 0 0 1 0 2 0 0 0 0 0 0 2 0 0 0 0 0 1 0 0 0 1 2 0 0 1 0 0 2 0 0 1 1 0 1 0 0 0 1 0 0 0 0 0 0 0 0 0 0 3 2 0 0 0 0 0 1 0 0 0 0 0 0 0 0 0 0 0 0 0 0 0 0 0 1 0 1 0 0 0 0 0 0 0 1 0 0 0 3 1 0 0 0 0 3 0 0 0 0 0 0 1 0 0 2 0 0 0 1 1 1 0 0 1 1 0 0 0 0 1 0 0 1 0 1 0 0 0 1 0 0 0 1 1 0 0 0 0 1 1 0 1 0 0 0 0 0 0 0 0 2 0 0 1 1</counts>
			</dataPoints>
		</scan>
		<scan status="Completed" appendNumber="0" scanAxis="2Theta" mode="Continuous">
			<header>
				<startTimeStamp>2024-11-01T13:58:14-04:00</startTimeStamp>
				<endTimeStamp>2024-11-01T14:28:19-04:00</endTimeStamp>
				<author>
					<name>lw627</name>
				</author>
				<source>
					<applicationSoftware version="7.1">Data Collector</applicationSoftware>
					<instrumentControlSoftware version="8.2  20201204">EMPYREAN</instrumentControlSoftware>
					<instrumentID>0000000011260721</instrumentID>
				</source>
			</header>
			<dataPoints>
				<positions axis="2Theta" unit="deg">
					<startPosition>41.2523843890686</startPosition>
					<endPosition>44.5996541602851</endPosition>
				</positions>
				<positions axis="Omega" unit="deg">
					<commonPosition>21.4630096373384</commonPosition>
				</positions>
				<positions axis="Phi" unit="deg">
					<commonPosition>3.05</commonPosition>
				</positions>
				<positions axis="Chi" unit="deg">
					<commonPosition>0</commonPosition>
				</positions>
				<positions axis="Z" unit="mm">
					<commonPosition>8.407</commonPosition>
				</positions>
				<commonCountingTime unit="seconds">0.974</commonCountingTime>
				<counts unit="counts">0 0 0 1 0 0 2 0 2 0 0 0 1 0 1 0 0 1 0 3 1 0 0 0 0 0 0 0 0 0 0 1 0 0 0 0 2 0 0 0 1 0 1 0 0 0 0 1 1 2 0 0 1 1 0 0 0 0 2 0 0 1 0 0 1 0 0 0 0 1 0 0 1 0 0 0 0 0 0 0 0 0 1 0 1 0 1 0 0 0 0 0 0 0 0 0 0 0 0 0 0 0 1 1 1 0 0 0 0 0 2 0 0 0 0 0 0 0 0 1 0 0 0 0 0 0 0 0 0 1 0 0 1 0 1 0 0 0 1 0 0 0 0 2 0 1 0 0 0 0 0 0 0 0 0 0 0 0 0 0 0 0 0 0 0 0 1 1 0 0 0 0 0 0 0 2 0 0 0 0 0 0 0 0 0 0 0 0 2 1 0 0 0 1 0 0 0 0 0 0 0 0 0 1 1 1 0 1 0 1 0 0 2 0 0 0 0 0 0 0 0 0 1 0 0 1 0 0 1 0 0 1 0 0 0 0 0 0 0 1 1 1 0 0 0 1 0 0 1 0 0 0 0 1 0</counts>
			</dataPoints>
		</scan>
		<scan status="Completed" appendNumber="0" scanAxis="2Theta" mode="Continuous">
			<header>
				<startTimeStamp>2024-11-01T13:58:14-04:00</startTimeStamp>
				<endTimeStamp>2024-11-01T14:28:19-04:00</endTimeStamp>
				<author>
					<name>lw627</name>
				</author>
				<source>
					<applicationSoftware version="7.1">Data Collector</applicationSoftware>
					<instrumentControlSoftware version="8.2  20201204">EMPYREAN</instrumentControlSoftware>
					<instrumentID>0000000011260721</instrumentID>
				</source>
			</header>
			<dataPoints>
				<positions axis="2Theta" unit="deg">
					<startPosition>41.2556669597368</startPosition>
					<endPosition>44.6029367309533</endPosition>
				</positions>
				<positions axis="Omega" unit="deg">
					<commonPosition>21.4646509226725</commonPosition>
				</positions>
				<positions axis="Phi" unit="deg">
					<commonPosition>3.05</commonPosition>
				</positions>
				<positions axis="Chi" unit="deg">
					<commonPosition>0</commonPosition>
				</positions>
				<positions axis="Z" unit="mm">
					<commonPosition>8.407</commonPosition>
				</positions>
				<commonCountingTime unit="seconds">0.974</commonCountingTime>
				<counts unit="counts">0 1 1 1 0 0 0 1 0 0 0 0 0 1 0 0 1 0 0 0 0 0 0 1 0 0 0 0 0 0 0 0 0 1 3 0 0 0 0 1 0 1 0 1 1 2 0 1 0 0 1 0 0 1 2 0 1 0 1 0 0 0 0 0 1 0 0 0 0 0 0 1 0 0 0 0 0 1 0 0 0 1 1 0 0 0 0 0 1 2 0 1 1 0 3 1 0 1 0 0 0 0 1 0 1 0 0 0 0 1 0 0 0 0 1 0 0 0 1 0 0 2 0 0 0 0 0 0 2 1 0 1 0 0 1 0 1 1 0 0 0 0 0 0 0 1 0 0 1 1 0 0 0 1 1 0 0 0 0 0 0 0 0 0 0 0 0 0 0 1 0 0 0 0 1 0 0 0 0 1 0 0 0 0 1 0 0 0 0 0 0 0 0 0 1 1 0 0 0 1 0 0 1 0 1 0 0 0 1 1 1 0 1 0 1 0 0 0 1 0 1 1 0 0 0 1 2 0 2 1 0 0 0 1 0 0 0 0 1 1 0 1 1 0 0 0 0 0 1 0 0 0 1 0 0</counts>
			</dataPoints>
		</scan>
		<scan status="Completed" appendNumber="0" scanAxis="2Theta" mode="Continuous">
			<header>
				<startTimeStamp>2024-11-01T13:58:14-04:00</startTimeStamp>
				<endTimeStamp>2024-11-01T14:28:19-04:00</endTimeStamp>
				<author>
					<name>lw627</name>
				</author>
				<source>
					<applicationSoftware version="7.1">Data Collector</applicationSoftware>
					<instrumentControlSoftware version="8.2  20201204">EMPYREAN</instrumentControlSoftware>
					<instrumentID>0000000011260721</instrumentID>
				</source>
			</header>
			<dataPoints>
				<positions axis="2Theta" unit="deg">
					<startPosition>41.2589495304049</startPosition>
					<endPosition>44.6062193016214</endPosition>
				</positions>
				<positions axis="Omega" unit="deg">
					<commonPosition>21.4662922080066</commonPosition>
				</positions>
				<positions axis="Phi" unit="deg">
					<commonPosition>3.05</commonPosition>
				</positions>
				<positions axis="Chi" unit="deg">
					<commonPosition>0</commonPosition>
				</positions>
				<positions axis="Z" unit="mm">
					<commonPosition>8.407</commonPosition>
				</positions>
				<commonCountingTime unit="seconds">0.974</commonCountingTime>
				<counts unit="counts">0 0 1 0 0 0 0 0 1 0 0 0 0 1 1 0 0 0 0 1 0 1 0 1 0 0 1 0 0 0 0 0 0 0 1 1 0 0 1 0 0 2 0 0 0 1 0 0 1 0 0 0 0 1 1 0 0 0 1 0 0 0 0 0 1 1 0 0 0 0 0 0 0 0 0 0 0 0 0 1 2 2 0 0 0 0 0 0 1 0 0 2 0 0 1 0 1 0 0 0 0 1 1 0 0 0 0 0 0 0 0 0 0 1 0 0 0 0 0 0 0 0 0 0 0 0 1 0 0 1 0 1 1 2 0 0 1 0 0 0 0 0 0 1 1 0 0 0 0 0 0 0 0 0 1 0 1 1 0 0 2 0 1 2 1 1 0 0 0 1 1 0 0 0 0 0 0 1 0 0 0 1 0 0 1 0 1 0 2 0 0 0 0 1 0 0 0 0 0 0 0 0 0 0 0 0 0 1 0 0 1 1 0 0 0 0 1 0 0 0 0 1 0 0 1 1 2 2 1 0 0 0 0 0 0 0 0 1 0 0 0 1 0 1 0 0 1 2 0 4 1 0 0 1 1</counts>
			</dataPoints>
		</scan>
		<scan status="Completed" appendNumber="0" scanAxis="2Theta" mode="Continuous">
			<header>
				<startTimeStamp>2024-11-01T13:58:14-04:00</startTimeStamp>
				<endTimeStamp>2024-11-01T14:28:19-04:00</endTimeStamp>
				<author>
					<name>lw627</name>
				</author>
				<source>
					<applicationSoftware version="7.1">Data Collector</applicationSoftware>
					<instrumentControlSoftware version="8.2  20201204">EMPYREAN</instrumentControlSoftware>
					<instrumentID>0000000011260721</instrumentID>
				</source>
			</header>
			<dataPoints>
				<positions axis="2Theta" unit="deg">
					<startPosition>41.262232101073</startPosition>
					<endPosition>44.6095018722895</endPosition>
				</positions>
				<positions axis="Omega" unit="deg">
					<commonPosition>21.4679334933406</commonPosition>
				</positions>
				<positions axis="Phi" unit="deg">
					<commonPosition>3.05</commonPosition>
				</positions>
				<positions axis="Chi" unit="deg">
					<commonPosition>0</commonPosition>
				</positions>
				<positions axis="Z" unit="mm">
					<commonPosition>8.407</commonPosition>
				</positions>
				<commonCountingTime unit="seconds">0.974</commonCountingTime>
				<counts unit="counts">0 1 0 0 0 0 0 0 0 1 0 0 0 0 0 0 0 0 0 0 1 0 0 1 0 1 1 0 0 0 1 2 0 0 0 0 0 1 1 0 1 2 0 0 0 0 0 0 0 0 1 0 0 0 0 0 0 0 1 1 1 0 0 0 0 2 0 0 1 2 0 0 0 0 0 0 0 0 1 0 0 0 0 0 1 1 0 0 0 0 0 1 0 0 1 0 0 0 0 1 1 0 0 0 0 0 0 0 0 0 0 0 0 0 0 0 0 1 1 0 0 0 0 2 1 0 0 0 0 0 1 0 0 1 0 1 1 1 1 0 0 1 0 1 0 0 0 2 1 0 0 0 0 0 0 0 0 1 0 0 0 1 0 1 0 0 0 1 0 0 0 0 0 1 0 1 1 0 0 0 1 0 0 1 0 1 1 1 0 0 0 0 1 0 0 0 1 0 0 0 0 0 1 0 0 1 1 0 0 2 0 0 0 2 0 0 1 0 0 0 0 0 0 0 1 0 1 0 0 0 0 1 1 1 0 1 1 0 0 1 0 0 0 0 0 0 1 0 0 0 0 1 0 0 0</counts>
			</dataPoints>
		</scan>
		<scan status="Completed" appendNumber="0" scanAxis="2Theta" mode="Continuous">
			<header>
				<startTimeStamp>2024-11-01T13:58:14-04:00</startTimeStamp>
				<endTimeStamp>2024-11-01T14:28:19-04:00</endTimeStamp>
				<author>
					<name>lw627</name>
				</author>
				<source>
					<applicationSoftware version="7.1">Data Collector</applicationSoftware>
					<instrumentControlSoftware version="8.2  20201204">EMPYREAN</instrumentControlSoftware>
					<instrumentID>0000000011260721</instrumentID>
				</source>
			</header>
			<dataPoints>
				<positions axis="2Theta" unit="deg">
					<startPosition>41.2655146717412</startPosition>
					<endPosition>44.6127844429576</endPosition>
				</positions>
				<positions axis="Omega" unit="deg">
					<commonPosition>21.4695747786747</commonPosition>
				</positions>
				<positions axis="Phi" unit="deg">
					<commonPosition>3.05</commonPosition>
				</positions>
				<positions axis="Chi" unit="deg">
					<commonPosition>0</commonPosition>
				</positions>
				<positions axis="Z" unit="mm">
					<commonPosition>8.407</commonPosition>
				</positions>
				<commonCountingTime unit="seconds">0.974</commonCountingTime>
				<counts unit="counts">0 1 0 0 0 0 0 0 0 0 0 0 0 0 0 0 1 0 0 0 2 1 2 1 0 0 1 1 0 0 0 2 0 0 1 1 0 1 0 0 0 0 0 0 0 0 1 0 0 0 0 0 0 0 0 0 0 1 1 0 0 0 0 0 2 0 1 0 0 0 0 0 0 1 1 0 0 1 1 0 0 0 0 1 1 0 1 0 1 0 0 0 0 0 0 0 0 0 0 0 2 1 0 0 0 0 0 0 0 1 0 0 0 0 0 0 0 0 1 1 0 1 0 0 0 0 0 0 0 1 0 1 0 0 0 1 1 0 0 0 1 1 0 1 1 0 1 1 0 0 0 0 0 0 0 1 1 0 1 0 1 0 0 1 1 0 0 0 1 0 0 1 0 0 0 1 0 0 0 1 0 0 0 0 0 0 0 1 2 1 0 0 0 1 0 1 0 0 0 0 0 0 0 0 0 0 0 0 0 0 0 0 0 0 0 0 0 0 0 1 0 0 0 1 0 0 0 0 0 0 0 0 0 0 0 0 1 1 0 0 1 1 0 0 0 1 0 1 1 0 1 0 1 0 0</counts>
			</dataPoints>
		</scan>
		<scan status="Completed" appendNumber="0" scanAxis="2Theta" mode="Continuous">
			<header>
				<startTimeStamp>2024-11-01T13:58:14-04:00</startTimeStamp>
				<endTimeStamp>2024-11-01T14:28:19-04:00</endTimeStamp>
				<author>
					<name>lw627</name>
				</author>
				<source>
					<applicationSoftware version="7.1">Data Collector</applicationSoftware>
					<instrumentControlSoftware version="8.2  20201204">EMPYREAN</instrumentControlSoftware>
					<instrumentID>0000000011260721</instrumentID>
				</source>
			</header>
			<dataPoints>
				<positions axis="2Theta" unit="deg">
					<startPosition>41.2687972424093</startPosition>
					<endPosition>44.6160670136258</endPosition>
				</positions>
				<positions axis="Omega" unit="deg">
					<commonPosition>21.4712160640088</commonPosition>
				</positions>
				<positions axis="Phi" unit="deg">
					<commonPosition>3.05</commonPosition>
				</positions>
				<positions axis="Chi" unit="deg">
					<commonPosition>0</commonPosition>
				</positions>
				<positions axis="Z" unit="mm">
					<commonPosition>8.407</commonPosition>
				</positions>
				<commonCountingTime unit="seconds">0.974</commonCountingTime>
				<counts unit="counts">0 1 0 0 0 0 0 0 0 0 1 0 0 1 0 0 0 1 2 0 0 2 0 0 0 2 1 0 1 1 1 1 0 1 1 0 0 0 0 0 2 1 0 0 0 0 1 0 1 0 0 0 0 0 0 1 1 1 0 0 0 1 0 0 0 0 1 1 0 1 1 0 0 0 0 0 0 1 0 0 0 0 1 1 1 0 1 0 0 0 1 0 0 0 1 0 0 0 1 0 0 0 1 0 1 0 1 1 0 0 1 0 1 0 0 0 0 1 0 0 0 0 0 0 1 0 0 1 0 0 1 0 2 1 0 0 1 0 1 0 0 0 0 0 0 0 0 0 0 0 0 1 0 0 0 0 0 0 0 0 0 0 1 1 1 0 0 0 0 0 0 0 1 2 0 0 0 0 1 0 0 0 0 0 0 0 1 1 0 0 0 0 1 0 0 0 0 0 0 0 2 0 0 0 0 0 1 0 1 1 1 0 1 0 0 0 0 0 0 1 1 2 0 0 0 0 0 0 1 0 0 1 0 0 0 0 0 1 0 0 1 1 1 1 0 0 0 1 1 0 0 0 0 0 2</counts>
			</dataPoints>
		</scan>
		<scan status="Completed" appendNumber="0" scanAxis="2Theta" mode="Continuous">
			<header>
				<startTimeStamp>2024-11-01T13:58:14-04:00</startTimeStamp>
				<endTimeStamp>2024-11-01T14:28:19-04:00</endTimeStamp>
				<author>
					<name>lw627</name>
				</author>
				<source>
					<applicationSoftware version="7.1">Data Collector</applicationSoftware>
					<instrumentControlSoftware version="8.2  20201204">EMPYREAN</instrumentControlSoftware>
					<instrumentID>0000000011260721</instrumentID>
				</source>
			</header>
			<dataPoints>
				<positions axis="2Theta" unit="deg">
					<startPosition>41.2720798130774</startPosition>
					<endPosition>44.6193495842939</endPosition>
				</positions>
				<positions axis="Omega" unit="deg">
					<commonPosition>21.4728573493428</commonPosition>
				</positions>
				<positions axis="Phi" unit="deg">
					<commonPosition>3.05</commonPosition>
				</positions>
				<positions axis="Chi" unit="deg">
					<commonPosition>0</commonPosition>
				</positions>
				<positions axis="Z" unit="mm">
					<commonPosition>8.407</commonPosition>
				</positions>
				<commonCountingTime unit="seconds">0.974</commonCountingTime>
				<counts unit="counts">0 0 0 0 0 0 0 0 0 0 0 0 1 1 1 0 1 1 1 1 0 1 0 0 1 0 0 0 0 0 0 1 2 0 0 0 3 0 1 0 0 0 1 0 1 1 0 0 0 0 0 1 0 0 0 0 0 0 2 0 0 1 1 0 1 0 0 0 0 0 0 0 0 0 0 1 0 2 1 0 0 1 0 0 0 1 1 0 0 0 0 0 1 0 0 0 1 0 0 0 0 0 2 0 1 0 0 1 0 1 0 0 0 0 1 0 0 0 2 0 0 0 0 0 0 1 0 1 0 0 0 0 0 0 0 0 0 0 0 0 0 0 0 0 0 0 3 1 0 0 0 0 0 0 0 0 0 0 0 0 0 1 0 0 0 0 1 0 0 0 0 0 1 0 1 0 0 3 0 1 0 0 1 0 0 0 0 0 0 1 0 0 0 0 0 2 1 0 0 0 1 0 1 0 1 0 0 1 2 0 0 0 1 0 1 0 1 0 0 0 1 0 0 0 0 0 1 0 0 0 0 1 0 0 0 0 0 0 0 0 1 1 0 0 1 0 1 0 0 0 0 0 0 1 1</counts>
			</dataPoints>
		</scan>
		<scan status="Completed" appendNumber="0" scanAxis="2Theta" mode="Continuous">
			<header>
				<startTimeStamp>2024-11-01T13:58:14-04:00</startTimeStamp>
				<endTimeStamp>2024-11-01T14:28:19-04:00</endTimeStamp>
				<author>
					<name>lw627</name>
				</author>
				<source>
					<applicationSoftware version="7.1">Data Collector</applicationSoftware>
					<instrumentControlSoftware version="8.2  20201204">EMPYREAN</instrumentControlSoftware>
					<instrumentID>0000000011260721</instrumentID>
				</source>
			</header>
			<dataPoints>
				<positions axis="2Theta" unit="deg">
					<startPosition>41.2753623837455</startPosition>
					<endPosition>44.622632154962</endPosition>
				</positions>
				<positions axis="Omega" unit="deg">
					<commonPosition>21.4744986346769</commonPosition>
				</positions>
				<positions axis="Phi" unit="deg">
					<commonPosition>3.05</commonPosition>
				</positions>
				<positions axis="Chi" unit="deg">
					<commonPosition>0</commonPosition>
				</positions>
				<positions axis="Z" unit="mm">
					<commonPosition>8.407</commonPosition>
				</positions>
				<commonCountingTime unit="seconds">0.974</commonCountingTime>
				<counts unit="counts">0 0 0 0 0 0 0 0 0 0 0 0 0 1 0 0 2 0 1 0 0 0 1 0 0 0 0 0 0 3 0 2 0 1 0 0 0 0 1 1 1 0 1 0 0 1 1 0 0 0 0 0 1 1 0 2 0 0 0 0 1 0 0 2 0 0 0 0 0 0 0 0 0 0 0 0 0 1 0 0 1 1 0 0 0 1 1 1 0 0 1 0 0 0 0 1 0 1 1 0 0 0 0 1 0 2 0 0 1 1 1 1 0 0 1 2 0 0 0 0 1 1 0 0 0 1 1 1 0 2 0 0 2 0 0 1 0 0 0 0 0 1 0 0 0 1 0 0 0 2 0 0 0 0 0 0 2 0 1 1 0 0 0 1 0 0 0 1 1 0 0 2 1 1 0 0 0 1 0 1 0 0 1 0 1 1 0 1 0 0 1 0 0 0 0 0 0 0 0 0 0 2 2 0 2 1 1 0 0 0 0 0 0 2 0 0 1 1 0 0 0 0 0 0 0 0 0 1 0 1 1 0 0 0 0 0 0 0 1 0 1 0 0 0 1 0 1 1 0 1 0 0 1 0 1</counts>
			</dataPoints>
		</scan>
		<scan status="Completed" appendNumber="0" scanAxis="2Theta" mode="Continuous">
			<header>
				<startTimeStamp>2024-11-01T13:58:14-04:00</startTimeStamp>
				<endTimeStamp>2024-11-01T14:28:19-04:00</endTimeStamp>
				<author>
					<name>lw627</name>
				</author>
				<source>
					<applicationSoftware version="7.1">Data Collector</applicationSoftware>
					<instrumentControlSoftware version="8.2  20201204">EMPYREAN</instrumentControlSoftware>
					<instrumentID>0000000011260721</instrumentID>
				</source>
			</header>
			<dataPoints>
				<positions axis="2Theta" unit="deg">
					<startPosition>41.2786449544137</startPosition>
					<endPosition>44.6259147256301</endPosition>
				</positions>
				<positions axis="Omega" unit="deg">
					<commonPosition>21.476139920011</commonPosition>
				</positions>
				<positions axis="Phi" unit="deg">
					<commonPosition>3.05</commonPosition>
				</positions>
				<positions axis="Chi" unit="deg">
					<commonPosition>0</commonPosition>
				</positions>
				<positions axis="Z" unit="mm">
					<commonPosition>8.407</commonPosition>
				</positions>
				<commonCountingTime unit="seconds">0.974</commonCountingTime>
				<counts unit="counts">1 1 1 0 1 0 1 0 1 0 0 1 0 0 0 0 1 0 0 0 0 0 0 0 0 0 0 0 2 0 0 0 1 1 0 0 0 0 1 0 0 0 0 0 0 1 0 0 0 0 0 0 0 0 0 0 0 0 0 2 0 0 0 2 0 2 0 0 0 0 0 1 0 0 0 1 0 0 0 0 0 0 0 0 1 0 0 1 1 0 1 0 1 1 0 0 0 0 0 0 1 1 0 0 1 0 0 2 0 0 3 0 0 1 0 0 0 1 0 0 0 0 0 0 0 0 0 1 0 1 1 0 0 0 0 0 1 0 1 0 0 1 0 0 1 0 0 0 0 0 0 0 0 0 0 1 0 0 0 0 1 0 0 0 0 1 0 0 1 0 0 0 0 1 0 0 1 0 1 1 1 0 0 0 1 0 0 0 0 0 0 0 0 0 0 1 1 0 1 0 0 0 0 1 0 1 0 0 1 0 0 0 0 1 0 0 0 0 1 0 0 0 0 0 1 1 0 2 1 1 0 1 1 0 1 0 0 0 0 0 0 0 0 1 0 0 0 0 0 0 0 1 1 0 0</counts>
			</dataPoints>
		</scan>
		<scan status="Completed" appendNumber="0" scanAxis="2Theta" mode="Continuous">
			<header>
				<startTimeStamp>2024-11-01T13:58:14-04:00</startTimeStamp>
				<endTimeStamp>2024-11-01T14:28:19-04:00</endTimeStamp>
				<author>
					<name>lw627</name>
				</author>
				<source>
					<applicationSoftware version="7.1">Data Collector</applicationSoftware>
					<instrumentControlSoftware version="8.2  20201204">EMPYREAN</instrumentControlSoftware>
					<instrumentID>0000000011260721</instrumentID>
				</source>
			</header>
			<dataPoints>
				<positions axis="2Theta" unit="deg">
					<startPosition>41.2819275250818</startPosition>
					<endPosition>44.6291972962983</endPosition>
				</positions>
				<positions axis="Omega" unit="deg">
					<commonPosition>21.477781205345</commonPosition>
				</positions>
				<positions axis="Phi" unit="deg">
					<commonPosition>3.05</commonPosition>
				</positions>
				<positions axis="Chi" unit="deg">
					<commonPosition>0</commonPosition>
				</positions>
				<positions axis="Z" unit="mm">
					<commonPosition>8.407</commonPosition>
				</positions>
				<commonCountingTime unit="seconds">0.974</commonCountingTime>
				<counts unit="counts">0 0 1 0 1 1 1 0 0 1 2 2 0 0 0 0 1 0 0 1 1 1 0 0 0 0 0 0 1 0 0 0 0 0 0 0 1 1 0 0 0 0 1 0 0 2 0 1 0 0 0 0 0 1 0 0 0 0 0 0 0 1 1 0 0 1 0 0 0 0 1 0 0 0 0 0 0 0 0 0 0 0 0 0 3 0 0 0 1 0 0 0 0 2 2 0 0 0 0 0 0 0 1 0 1 1 0 0 0 1 0 1 0 0 0 0 0 1 0 0 0 0 0 1 0 0 0 1 0 0 1 0 1 0 0 1 1 0 0 0 0 0 1 0 0 0 0 0 1 0 0 0 0 0 0 1 0 0 1 0 0 0 0 0 1 0 0 0 0 1 0 1 0 0 2 0 0 0 1 0 0 0 0 0 0 0 0 0 0 0 0 0 0 1 0 0 0 1 0 0 1 0 0 1 1 0 0 0 0 0 0 0 0 2 1 0 0 0 1 0 1 0 0 0 1 0 0 0 1 0 0 0 0 0 0 0 0 1 0 0 0 0 0 0 0 0 1 0 0 0 0 0 0 0 1</counts>
			</dataPoints>
		</scan>
		<scan status="Completed" appendNumber="0" scanAxis="2Theta" mode="Continuous">
			<header>
				<startTimeStamp>2024-11-01T13:58:14-04:00</startTimeStamp>
				<endTimeStamp>2024-11-01T14:28:19-04:00</endTimeStamp>
				<author>
					<name>lw627</name>
				</author>
				<source>
					<applicationSoftware version="7.1">Data Collector</applicationSoftware>
					<instrumentControlSoftware version="8.2  20201204">EMPYREAN</instrumentControlSoftware>
					<instrumentID>0000000011260721</instrumentID>
				</source>
			</header>
			<dataPoints>
				<positions axis="2Theta" unit="deg">
					<startPosition>41.2852100957499</startPosition>
					<endPosition>44.6324798669664</endPosition>
				</positions>
				<positions axis="Omega" unit="deg">
					<commonPosition>21.4794224906791</commonPosition>
				</positions>
				<positions axis="Phi" unit="deg">
					<commonPosition>3.05</commonPosition>
				</positions>
				<positions axis="Chi" unit="deg">
					<commonPosition>0</commonPosition>
				</positions>
				<positions axis="Z" unit="mm">
					<commonPosition>8.407</commonPosition>
				</positions>
				<commonCountingTime unit="seconds">0.974</commonCountingTime>
				<counts unit="counts">0 2 0 0 0 0 0 1 2 0 0 0 0 1 0 0 1 0 0 0 1 0 0 1 0 0 0 3 1 0 1 0 0 0 0 0 0 0 0 0 0 0 2 0 0 1 0 0 0 0 1 0 0 0 0 1 0 1 0 0 0 0 0 0 0 0 0 0 0 1 1 0 0 0 2 0 0 1 0 0 0 1 0 2 0 1 0 0 0 0 0 0 0 0 0 0 0 0 0 1 0 1 0 0 3 0 0 0 0 1 0 1 0 1 0 0 0 1 0 1 1 0 0 2 0 2 0 1 0 0 0 0 0 0 0 0 0 0 1 0 0 1 1 2 0 0 0 0 0 1 0 0 0 0 0 0 0 0 0 0 0 1 0 0 0 0 0 0 0 0 2 1 1 0 0 0 0 1 0 0 0 0 0 0 0 0 0 0 0 0 0 0 0 0 1 1 0 0 0 1 0 0 0 0 0 0 0 1 0 0 0 0 0 0 0 0 0 0 0 0 1 1 1 0 0 2 0 0 0 0 0 0 0 0 0 0 1 0 0 0 0 0 0 0 1 1 0 0 1 0 0 0 0 1 0</counts>
			</dataPoints>
		</scan>
		<scan status="Completed" appendNumber="0" scanAxis="2Theta" mode="Continuous">
			<header>
				<startTimeStamp>2024-11-01T13:58:14-04:00</startTimeStamp>
				<endTimeStamp>2024-11-01T14:28:19-04:00</endTimeStamp>
				<author>
					<name>lw627</name>
				</author>
				<source>
					<applicationSoftware version="7.1">Data Collector</applicationSoftware>
					<instrumentControlSoftware version="8.2  20201204">EMPYREAN</instrumentControlSoftware>
					<instrumentID>0000000011260721</instrumentID>
				</source>
			</header>
			<dataPoints>
				<positions axis="2Theta" unit="deg">
					<startPosition>41.288492666418</startPosition>
					<endPosition>44.6357624376345</endPosition>
				</positions>
				<positions axis="Omega" unit="deg">
					<commonPosition>21.4810637760131</commonPosition>
				</positions>
				<positions axis="Phi" unit="deg">
					<commonPosition>3.05</commonPosition>
				</positions>
				<positions axis="Chi" unit="deg">
					<commonPosition>0</commonPosition>
				</positions>
				<positions axis="Z" unit="mm">
					<commonPosition>8.407</commonPosition>
				</positions>
				<commonCountingTime unit="seconds">0.974</commonCountingTime>
				<counts unit="counts">0 0 0 0 0 0 0 0 0 0 0 0 1 0 0 1 0 0 0 0 1 0 0 0 0 0 0 0 0 0 0 0 1 0 0 0 1 0 0 1 0 1 0 0 0 2 0 1 1 1 0 0 1 1 0 0 0 1 0 0 0 1 0 0 1 1 1 1 0 0 0 0 1 0 0 0 0 1 0 1 0 0 0 0 1 0 0 1 1 0 1 1 1 0 0 2 1 0 0 1 1 4 0 0 1 0 0 0 1 2 0 0 0 1 0 0 0 0 0 0 0 0 0 0 0 0 1 0 1 0 0 0 1 0 0 0 1 0 0 2 0 1 0 0 0 1 0 0 0 1 0 0 0 0 0 0 1 0 0 0 0 1 0 0 0 0 0 1 0 0 0 0 0 0 0 0 0 1 0 1 1 0 1 0 1 0 0 0 1 0 0 5 0 0 0 0 1 0 0 0 0 0 1 0 0 2 2 2 1 0 1 0 0 0 0 1 0 0 0 1 0 0 0 1 0 0 1 0 0 0 0 0 1 0 1 0 0 0 1 0 0 1 1 1 0 0 0 0 0 0 0 0 0 0 0</counts>
			</dataPoints>
		</scan>
		<scan status="Completed" appendNumber="0" scanAxis="2Theta" mode="Continuous">
			<header>
				<startTimeStamp>2024-11-01T13:58:14-04:00</startTimeStamp>
				<endTimeStamp>2024-11-01T14:28:19-04:00</endTimeStamp>
				<author>
					<name>lw627</name>
				</author>
				<source>
					<applicationSoftware version="7.1">Data Collector</applicationSoftware>
					<instrumentControlSoftware version="8.2  20201204">EMPYREAN</instrumentControlSoftware>
					<instrumentID>0000000011260721</instrumentID>
				</source>
			</header>
			<dataPoints>
				<positions axis="2Theta" unit="deg">
					<startPosition>41.2917752370862</startPosition>
					<endPosition>44.6390450083027</endPosition>
				</positions>
				<positions axis="Omega" unit="deg">
					<commonPosition>21.4827050613472</commonPosition>
				</positions>
				<positions axis="Phi" unit="deg">
					<commonPosition>3.05</commonPosition>
				</positions>
				<positions axis="Chi" unit="deg">
					<commonPosition>0</commonPosition>
				</positions>
				<positions axis="Z" unit="mm">
					<commonPosition>8.407</commonPosition>
				</positions>
				<commonCountingTime unit="seconds">0.974</commonCountingTime>
				<counts unit="counts">0 2 0 0 0 0 0 1 0 1 1 1 0 0 0 0 0 0 1 0 0 1 2 2 0 0 0 0 0 0 0 2 0 1 0 1 0 1 0 0 0 1 0 0 0 0 0 0 0 2 0 0 2 0 0 0 0 0 1 0 2 1 0 0 0 0 0 1 0 0 0 3 1 1 2 0 0 1 0 0 2 0 2 0 0 0 0 0 0 0 0 1 1 0 1 0 0 0 1 0 0 0 0 0 0 1 0 0 2 0 0 0 0 1 0 0 1 1 0 0 1 0 0 1 0 0 0 2 1 0 1 1 0 0 0 2 0 0 0 0 2 0 0 2 2 0 0 0 0 0 0 2 0 1 0 0 0 0 0 0 0 1 0 0 0 0 0 1 0 1 0 0 1 0 0 1 0 0 0 1 1 0 0 0 0 0 0 0 0 0 0 1 0 1 0 0 1 0 0 0 0 0 0 0 0 0 1 0 1 0 0 0 0 0 0 0 1 0 0 0 0 0 0 0 0 0 0 0 1 0 0 0 0 1 0 1 0 0 0 0 0 0 1 0 0 0 1 1 0 0 0 0 0 0 0</counts>
			</dataPoints>
		</scan>
		<scan status="Completed" appendNumber="0" scanAxis="2Theta" mode="Continuous">
			<header>
				<startTimeStamp>2024-11-01T13:58:14-04:00</startTimeStamp>
				<endTimeStamp>2024-11-01T14:28:19-04:00</endTimeStamp>
				<author>
					<name>lw627</name>
				</author>
				<source>
					<applicationSoftware version="7.1">Data Collector</applicationSoftware>
					<instrumentControlSoftware version="8.2  20201204">EMPYREAN</instrumentControlSoftware>
					<instrumentID>0000000011260721</instrumentID>
				</source>
			</header>
			<dataPoints>
				<positions axis="2Theta" unit="deg">
					<startPosition>41.2950578077543</startPosition>
					<endPosition>44.6423275789708</endPosition>
				</positions>
				<positions axis="Omega" unit="deg">
					<commonPosition>21.4843463466813</commonPosition>
				</positions>
				<positions axis="Phi" unit="deg">
					<commonPosition>3.05</commonPosition>
				</positions>
				<positions axis="Chi" unit="deg">
					<commonPosition>0</commonPosition>
				</positions>
				<positions axis="Z" unit="mm">
					<commonPosition>8.407</commonPosition>
				</positions>
				<commonCountingTime unit="seconds">0.974</commonCountingTime>
[...]
					<commonPosition>0</commonPosition>
				</positions>
				<positions axis="Z" unit="mm">
					<commonPosition>8.407</commonPosition>
				</positions>
				<commonCountingTime unit="seconds">0.974</commonCountingTime>
				<counts unit="counts">0 0 0 0 1 0 1 0 1 1 0 0 0 2 0 0 0 1 0 2 1 0 0 0 0 0 0 0 1 1 0 0 0 0 1 1 0 2 0 0 1 1 0 0 0 0 0 1 0 0 0 1 0 1 1 0 0 0 0 0 0 0 1 0 0 0 0 0 0 0 0 0 0 1 0 0 1 1 0 0 0 0 0 0 0 1 0 0 0 0 0 0 0 0 0 1 0 0 0 0 0 0 0 0 0 0 0 0 0 1 0 1 1 0 0 1 1 0 0 3 1 0 0 2 0 0 1 0 1 1 0 1 0 0 0 0 0 0 0 0 0 0 0 0 1 0 0 0 0 0 1 0 0 0 0 0 0 0 0 0 0 0 2 0 1 0 0 0 1 0 0 1 1 1 2 2 0 0 2 0 1 1 0 0 1 0 0 0 0 0 1 0 0 0 1 0 0 2 0 0 0 0 0 1 0 0 0 1 0 1 0 0 0 0 0 0 0 0 0 0 0 0 1 0 1 1 1 0 0 0 0 0 0 1 0 2 1 0 0 0 2 0 1 0 0 0 0 0 0 0 1 0 0 1 0</counts>
			</dataPoints>
		</scan>
		<scan status="Completed" appendNumber="0" scanAxis="2Theta" mode="Continuous">
			<header>
				<startTimeStamp>2024-11-01T13:58:14-04:00</startTimeStamp>
				<endTimeStamp>2024-11-01T14:28:19-04:00</endTimeStamp>
				<author>
					<name>lw627</name>
				</author>
				<source>
					<applicationSoftware version="7.1">Data Collector</applicationSoftware>
					<instrumentControlSoftware version="8.2  20201204">EMPYREAN</instrumentControlSoftware>
					<instrumentID>0000000011260721</instrumentID>
				</source>
			</header>
			<dataPoints>
				<positions axis="2Theta" unit="deg">
					<startPosition>47.1905547277105</startPosition>
					<endPosition>50.537824498927</endPosition>
				</positions>
				<positions axis="Omega" unit="deg">
					<commonPosition>24.4320948066594</commonPosition>
				</positions>
				<positions axis="Phi" unit="deg">
					<commonPosition>3.05</commonPosition>
				</positions>
				<positions axis="Chi" unit="deg">
					<commonPosition>0</commonPosition>
				</positions>
				<positions axis="Z" unit="mm">
					<commonPosition>8.407</commonPosition>
				</positions>
				<commonCountingTime unit="seconds">0.974</commonCountingTime>
				<counts unit="counts">1 1 0 0 0 1 0 0 0 0 0 1 1 0 0 0 0 0 0 0 0 0 1 0 0 1 0 1 1 0 0 0 0 0 0 1 0 0 0 0 0 1 0 1 0 0 0 0 0 1 0 1 0 1 0 1 0 0 0 0 2 0 0 0 0 1 0 0 0 0 0 0 0 0 0 0 0 0 1 0 0 0 0 0 0 0 0 0 0 1 0 1 0 0 0 0 0 0 0 0 0 0 0 1 0 0 1 0 1 0 0 0 0 1 0 1 0 0 1 0 0 0 0 0 0 0 1 0 0 1 1 0 0 1 0 1 0 0 0 0 0 0 0 2 0 0 2 2 0 0 1 0 0 0 1 0 0 0 1 0 0 1 0 1 0 0 1 0 1 1 0 0 0 0 0 0 1 0 1 0 0 1 0 1 0 0 0 0 1 0 0 0 0 0 2 0 1 0 0 1 0 0 0 1 1 0 0 1 1 0 0 0 1 0 0 0 0 1 0 0 0 1 0 1 0 1 1 0 0 0 1 0 0 0 0 0 0 0 0 0 0 0 0 0 1 1 0 0 0 0 0 0 1 0 0</counts>
			</dataPoints>
		</scan>
		<scan status="Completed" appendNumber="0" scanAxis="2Theta" mode="Continuous">
			<header>
				<startTimeStamp>2024-11-01T13:58:14-04:00</startTimeStamp>
				<endTimeStamp>2024-11-01T14:28:19-04:00</endTimeStamp>
				<author>
					<name>lw627</name>
				</author>
				<source>
					<applicationSoftware version="7.1">Data Collector</applicationSoftware>
					<instrumentControlSoftware version="8.2  20201204">EMPYREAN</instrumentControlSoftware>
					<instrumentID>0000000011260721</instrumentID>
				</source>
			</header>
			<dataPoints>
				<positions axis="2Theta" unit="deg">
					<startPosition>47.1938372983786</startPosition>
					<endPosition>50.5411070695951</endPosition>
				</positions>
				<positions axis="Omega" unit="deg">
					<commonPosition>24.4337360919934</commonPosition>
				</positions>
				<positions axis="Phi" unit="deg">
					<commonPosition>3.05</commonPosition>
				</positions>
				<positions axis="Chi" unit="deg">
					<commonPosition>0</commonPosition>
				</positions>
				<positions axis="Z" unit="mm">
					<commonPosition>8.407</commonPosition>
				</positions>
				<commonCountingTime unit="seconds">0.974</commonCountingTime>
				<counts unit="counts">0 2 0 0 0 0 0 0 0 0 1 0 0 0 0 1 0 0 0 0 1 0 0 1 0 1 0 0 0 0 0 0 1 0 0 0 0 1 1 1 0 0 0 0 0 1 1 0 0 0 1 1 0 1 0 0 0 0 1 0 0 2 0 0 0 0 0 0 0 1 2 0 0 0 0 1 1 0 0 0 0 1 0 1 0 0 0 0 0 1 1 0 0 0 1 0 0 0 0 0 0 0 1 1 0 1 0 1 0 0 3 0 0 0 1 0 1 0 0 0 0 0 1 0 0 1 1 0 1 0 1 0 0 0 0 0 0 0 0 0 0 0 1 0 0 0 0 0 1 0 0 0 0 1 0 1 0 0 0 1 0 1 1 0 1 1 0 0 0 0 1 0 0 0 1 0 0 0 0 2 0 0 1 0 0 0 0 0 1 0 1 1 0 0 0 0 0 0 0 0 0 0 0 0 0 0 2 1 1 0 1 0 0 0 0 1 1 0 0 0 1 0 0 1 0 0 0 0 0 0 0 0 0 0 0 0 0 0 0 0 0 1 1 0 0 0 0 0 0 0 0 0 0 0 0</counts>
			</dataPoints>
		</scan>
		<scan status="Completed" appendNumber="0" scanAxis="2Theta" mode="Continuous">
			<header>
				<startTimeStamp>2024-11-01T13:58:14-04:00</startTimeStamp>
				<endTimeStamp>2024-11-01T14:28:19-04:00</endTimeStamp>
				<author>
					<name>lw627</name>
				</author>
				<source>
					<applicationSoftware version="7.1">Data Collector</applicationSoftware>
					<instrumentControlSoftware version="8.2  20201204">EMPYREAN</instrumentControlSoftware>
					<instrumentID>0000000011260721</instrumentID>
				</source>
			</header>
			<dataPoints>
				<positions axis="2Theta" unit="deg">
					<startPosition>47.1971198690467</startPosition>
					<endPosition>50.5443896402632</endPosition>
				</positions>
				<positions axis="Omega" unit="deg">
					<commonPosition>24.4353773773275</commonPosition>
				</positions>
				<positions axis="Phi" unit="deg">
					<commonPosition>3.05</commonPosition>
				</positions>
				<positions axis="Chi" unit="deg">
					<commonPosition>0</commonPosition>
				</positions>
				<positions axis="Z" unit="mm">
					<commonPosition>8.407</commonPosition>
				</positions>
				<commonCountingTime unit="seconds">0.974</commonCountingTime>
				<counts unit="counts">0 0 1 0 0 1 0 0 0 0 0 0 2 0 1 0 0 0 1 0 1 1 0 0 0 0 0 1 0 2 0 0 0 0 1 0 0 0 0 0 0 0 0 0 0 0 0 0 0 0 0 0 0 2 1 0 0 0 1 0 0 1 0 0 1 0 0 2 0 0 0 0 0 0 0 0 0 0 0 1 0 0 0 0 0 1 0 0 0 1 0 0 0 0 0 0 0 1 1 0 0 1 0 1 0 0 0 0 1 0 0 0 0 1 0 0 1 0 0 1 0 2 0 1 0 0 0 0 0 1 0 0 1 0 0 0 0 0 1 0 0 0 0 1 0 0 0 0 0 0 2 1 0 1 0 0 1 0 0 0 0 0 0 0 1 0 0 0 0 0 0 0 0 0 0 0 0 0 0 3 0 0 0 0 0 2 0 0 0 1 0 0 1 0 0 1 0 0 0 0 0 0 1 0 0 0 0 0 0 0 0 0 0 0 0 0 0 0 0 0 0 0 0 0 1 1 0 1 0 1 0 0 0 1 0 1 1 0 2 0 0 0 1 0 0 0 0 0 0 0 0 1 0 1 0</counts>
			</dataPoints>
		</scan>
		<scan status="Completed" appendNumber="0" scanAxis="2Theta" mode="Continuous">
			<header>
				<startTimeStamp>2024-11-01T13:58:14-04:00</startTimeStamp>
				<endTimeStamp>2024-11-01T14:28:19-04:00</endTimeStamp>
				<author>
					<name>lw627</name>
				</author>
				<source>
					<applicationSoftware version="7.1">Data Collector</applicationSoftware>
					<instrumentControlSoftware version="8.2  20201204">EMPYREAN</instrumentControlSoftware>
					<instrumentID>0000000011260721</instrumentID>
				</source>
			</header>
			<dataPoints>
				<positions axis="2Theta" unit="deg">
					<startPosition>47.2004024397149</startPosition>
					<endPosition>50.5476722109314</endPosition>
				</positions>
				<positions axis="Omega" unit="deg">
					<commonPosition>24.4370186626616</commonPosition>
				</positions>
				<positions axis="Phi" unit="deg">
					<commonPosition>3.05</commonPosition>
				</positions>
				<positions axis="Chi" unit="deg">
					<commonPosition>0</commonPosition>
				</positions>
				<positions axis="Z" unit="mm">
					<commonPosition>8.407</commonPosition>
				</positions>
				<commonCountingTime unit="seconds">0.974</commonCountingTime>
				<counts unit="counts">0 0 0 0 0 0 0 0 1 0 0 2 0 0 0 0 0 0 0 0 0 3 0 1 1 0 1 0 0 0 0 2 0 0 0 1 0 0 0 0 1 0 0 0 0 0 0 2 0 0 0 2 0 0 1 0 0 2 0 0 1 0 1 0 0 0 0 0 1 0 1 1 0 1 0 2 1 0 0 1 1 0 0 0 0 0 0 0 0 0 0 0 1 0 0 0 0 1 0 1 0 0 0 0 0 1 0 0 1 0 0 0 0 0 0 2 0 0 0 0 1 0 0 2 1 1 0 0 2 1 1 1 0 0 1 0 0 0 0 1 0 1 0 0 0 0 0 0 0 1 1 0 0 0 0 0 0 1 0 0 0 1 0 0 0 0 0 0 0 0 0 0 1 0 1 0 0 0 0 1 0 0 0 0 0 0 1 0 0 0 0 0 0 0 0 1 0 1 1 0 0 2 0 0 1 1 0 0 0 0 0 1 0 0 0 0 0 0 0 0 0 0 0 1 1 1 0 0 0 0 0 0 0 1 0 1 1 0 1 1 0 0 0 0 0 0 0 1 0 0 0 0 0 0 1</counts>
			</dataPoints>
		</scan>
		<scan status="Completed" appendNumber="0" scanAxis="2Theta" mode="Continuous">
			<header>
				<startTimeStamp>2024-11-01T13:58:14-04:00</startTimeStamp>
				<endTimeStamp>2024-11-01T14:28:19-04:00</endTimeStamp>
				<author>
					<name>lw627</name>
				</author>
				<source>
					<applicationSoftware version="7.1">Data Collector</applicationSoftware>
					<instrumentControlSoftware version="8.2  20201204">EMPYREAN</instrumentControlSoftware>
					<instrumentID>0000000011260721</instrumentID>
				</source>
			</header>
			<dataPoints>
				<positions axis="2Theta" unit="deg">
					<startPosition>47.203685010383</startPosition>
					<endPosition>50.5509547815995</endPosition>
				</positions>
				<positions axis="Omega" unit="deg">
					<commonPosition>24.4386599479956</commonPosition>
				</positions>
				<positions axis="Phi" unit="deg">
					<commonPosition>3.05</commonPosition>
				</positions>
				<positions axis="Chi" unit="deg">
					<commonPosition>0</commonPosition>
				</positions>
				<positions axis="Z" unit="mm">
					<commonPosition>8.407</commonPosition>
				</positions>
				<commonCountingTime unit="seconds">0.974</commonCountingTime>
				<counts unit="counts">0 0 0 0 0 0 2 0 0 1 0 0 0 0 1 0 0 0 0 0 1 0 0 1 2 1 0 0 0 0 1 0 0 0 0 1 0 1 0 1 0 0 1 1 0 0 0 0 0 0 0 1 0 0 1 1 0 0 1 0 0 1 0 0 1 1 0 1 0 0 1 0 0 0 0 0 0 0 0 0 1 0 1 1 0 0 0 2 0 1 1 1 2 1 0 0 1 0 0 1 0 0 0 0 0 2 0 0 0 0 0 0 3 0 0 2 2 1 1 0 0 0 0 0 0 0 0 1 0 0 0 0 1 2 0 0 1 0 0 0 0 0 0 0 0 0 0 1 0 0 0 0 1 1 0 1 1 0 0 0 0 0 0 0 0 0 1 0 0 1 0 1 0 0 0 0 0 0 0 0 0 0 3 1 0 0 0 0 0 0 0 1 0 2 0 0 0 0 0 1 0 0 0 0 0 1 0 0 0 0 0 0 0 0 0 0 0 1 0 0 0 0 1 0 0 0 1 1 0 2 0 0 0 0 1 0 0 0 0 0 0 0 0 0 0 0 0 0 0 1 1 0 0 0 1</counts>
			</dataPoints>
		</scan>
		<scan status="Completed" appendNumber="0" scanAxis="2Theta" mode="Continuous">
			<header>
				<startTimeStamp>2024-11-01T13:58:14-04:00</startTimeStamp>
				<endTimeStamp>2024-11-01T14:28:19-04:00</endTimeStamp>
				<author>
					<name>lw627</name>
				</author>
				<source>
					<applicationSoftware version="7.1">Data Collector</applicationSoftware>
					<instrumentControlSoftware version="8.2  20201204">EMPYREAN</instrumentControlSoftware>
					<instrumentID>0000000011260721</instrumentID>
				</source>
			</header>
			<dataPoints>
				<positions axis="2Theta" unit="deg">
					<startPosition>47.2069675810511</startPosition>
					<endPosition>50.5542373522676</endPosition>
				</positions>
				<positions axis="Omega" unit="deg">
					<commonPosition>24.4403012333297</commonPosition>
				</positions>
				<positions axis="Phi" unit="deg">
					<commonPosition>3.05</commonPosition>
				</positions>
				<positions axis="Chi" unit="deg">
					<commonPosition>0</commonPosition>
				</positions>
				<positions axis="Z" unit="mm">
					<commonPosition>8.407</commonPosition>
				</positions>
				<commonCountingTime unit="seconds">0.974</commonCountingTime>
				<counts unit="counts">0 0 0 1 0 0 1 0 0 0 0 2 0 0 1 0 0 1 0 0 1 1 0 1 0 2 0 1 0 0 0 1 0 1 0 1 0 0 0 0 0 0 0 0 0 0 0 2 0 0 1 0 0 1 4 2 0 1 0 0 0 0 1 0 0 2 0 0 0 0 0 0 0 0 2 0 1 0 0 0 0 0 0 0 0 1 0 1 0 0 1 1 0 2 0 0 1 0 0 0 0 0 0 0 0 0 0 0 1 1 0 0 1 0 0 0 0 1 0 0 0 0 0 0 0 1 0 0 0 0 1 1 0 1 0 0 0 0 0 0 0 0 0 1 0 0 0 0 0 1 1 0 0 0 0 0 0 0 2 0 0 1 0 0 1 0 1 1 0 0 0 0 0 0 0 0 1 0 0 0 0 0 1 0 0 0 1 0 0 1 1 0 0 1 0 0 0 1 0 0 1 1 1 1 0 0 0 1 0 0 0 0 0 0 1 1 1 0 0 0 0 0 0 0 1 0 0 0 0 0 0 0 1 1 1 0 0 0 0 0 0 0 1 0 1 0 0 0 0 0 0 0 1 0 0</counts>
			</dataPoints>
		</scan>
		<scan status="Completed" appendNumber="0" scanAxis="2Theta" mode="Continuous">
			<header>
				<startTimeStamp>2024-11-01T13:58:14-04:00</startTimeStamp>
				<endTimeStamp>2024-11-01T14:28:19-04:00</endTimeStamp>
				<author>
					<name>lw627</name>
				</author>
				<source>
					<applicationSoftware version="7.1">Data Collector</applicationSoftware>
					<instrumentControlSoftware version="8.2  20201204">EMPYREAN</instrumentControlSoftware>
					<instrumentID>0000000011260721</instrumentID>
				</source>
			</header>
			<dataPoints>
				<positions axis="2Theta" unit="deg">
					<startPosition>47.2102501517193</startPosition>
					<endPosition>50.5575199229357</endPosition>
				</positions>
				<positions axis="Omega" unit="deg">
					<commonPosition>24.4419425186637</commonPosition>
				</positions>
				<positions axis="Phi" unit="deg">
					<commonPosition>3.05</commonPosition>
				</positions>
				<positions axis="Chi" unit="deg">
					<commonPosition>0</commonPosition>
				</positions>
				<positions axis="Z" unit="mm">
					<commonPosition>8.407</commonPosition>
				</positions>
				<commonCountingTime unit="seconds">0.974</commonCountingTime>
				<counts unit="counts">1 1 1 0 0 0 0 1 0 0 0 0 0 0 0 1 0 0 0 0 0 0 0 1 0 0 0 1 0 1 1 0 0 0 1 1 1 0 0 0 1 0 0 1 0 0 0 1 3 0 1 0 2 2 0 1 0 1 2 1 1 0 0 0 0 0 0 1 0 0 0 0 1 0 0 0 0 0 1 1 0 0 0 0 0 0 0 0 0 0 0 3 0 1 1 0 0 0 0 1 1 1 0 0 0 0 0 0 0 0 0 0 1 1 0 0 1 0 0 1 0 0 0 0 0 2 0 0 0 1 0 0 1 0 0 1 0 0 0 0 0 0 1 0 0 0 0 0 0 0 0 0 0 0 0 0 2 1 1 0 0 0 0 0 0 0 1 1 0 0 0 0 1 0 0 0 2 0 0 1 0 0 0 1 0 0 0 0 0 0 0 1 1 0 0 0 1 0 0 0 0 0 1 0 0 0 1 0 0 0 0 1 0 0 0 0 0 1 0 0 0 0 0 0 0 1 0 0 1 1 0 0 1 2 0 2 0 0 0 0 0 0 1 0 0 0 0 1 1 1 0 1 0 0 1</counts>
			</dataPoints>
		</scan>
		<scan status="Completed" appendNumber="0" scanAxis="2Theta" mode="Continuous">
			<header>
				<startTimeStamp>2024-11-01T13:58:14-04:00</startTimeStamp>
				<endTimeStamp>2024-11-01T14:28:19-04:00</endTimeStamp>
				<author>
					<name>lw627</name>
				</author>
				<source>
					<applicationSoftware version="7.1">Data Collector</applicationSoftware>
					<instrumentControlSoftware version="8.2  20201204">EMPYREAN</instrumentControlSoftware>
					<instrumentID>0000000011260721</instrumentID>
				</source>
			</header>
			<dataPoints>
				<positions axis="2Theta" unit="deg">
					<startPosition>47.2135327223874</startPosition>
					<endPosition>50.5608024936039</endPosition>
				</positions>
				<positions axis="Omega" unit="deg">
					<commonPosition>24.4435838039978</commonPosition>
				</positions>
				<positions axis="Phi" unit="deg">
					<commonPosition>3.05</commonPosition>
				</positions>
				<positions axis="Chi" unit="deg">
					<commonPosition>0</commonPosition>
				</positions>
				<positions axis="Z" unit="mm">
					<commonPosition>8.407</commonPosition>
				</positions>
				<commonCountingTime unit="seconds">0.974</commonCountingTime>
				<counts unit="counts">2 0 1 0 0 1 0 0 3 0 0 1 0 0 1 0 0 1 0 1 0 0 0 0 0 0 1 0 0 1 1 0 1 0 0 0 0 0 0 1 1 0 0 0 0 0 0 1 0 0 0 0 0 1 0 0 1 0 0 1 0 0 1 0 0 0 0 0 0 0 0 0 1 0 1 0 0 0 0 0 0 0 0 0 0 0 0 1 0 0 1 0 0 0 1 0 0 0 0 0 0 1 0 1 0 0 0 0 1 2 0 0 1 0 1 0 0 0 0 0 0 1 2 0 1 0 1 2 0 1 0 0 1 0 0 1 0 0 0 0 0 0 0 0 0 2 0 0 0 0 0 1 0 0 0 0 0 0 2 0 2 0 0 0 2 1 0 1 0 1 0 0 0 0 0 1 0 1 1 0 0 0 0 0 0 0 1 0 0 0 0 1 1 0 1 0 0 0 0 0 1 0 0 1 2 1 1 0 0 0 0 1 0 0 0 1 0 0 1 0 0 0 0 3 1 0 0 0 0 1 0 0 0 0 0 0 0 0 0 1 0 0 0 0 0 0 0 1 0 0 1 0 0 1 0</counts>
			</dataPoints>
		</scan>
		<scan status="Completed" appendNumber="0" scanAxis="2Theta" mode="Continuous">
			<header>
				<startTimeStamp>2024-11-01T13:58:14-04:00</startTimeStamp>
				<endTimeStamp>2024-11-01T14:28:19-04:00</endTimeStamp>
				<author>
					<name>lw627</name>
				</author>
				<source>
					<applicationSoftware version="7.1">Data Collector</applicationSoftware>
					<instrumentControlSoftware version="8.2  20201204">EMPYREAN</instrumentControlSoftware>
					<instrumentID>0000000011260721</instrumentID>
				</source>
			</header>
			<dataPoints>
				<positions axis="2Theta" unit="deg">
					<startPosition>47.2168152930555</startPosition>
					<endPosition>50.564085064272</endPosition>
				</positions>
				<positions axis="Omega" unit="deg">
					<commonPosition>24.4452250893319</commonPosition>
				</positions>
				<positions axis="Phi" unit="deg">
					<commonPosition>3.05</commonPosition>
				</positions>
				<positions axis="Chi" unit="deg">
					<commonPosition>0</commonPosition>
				</positions>
				<positions axis="Z" unit="mm">
					<commonPosition>8.407</commonPosition>
				</positions>
				<commonCountingTime unit="seconds">0.974</commonCountingTime>
				<counts unit="counts">0 1 0 0 0 0 0 0 1 1 1 0 0 0 1 0 0 0 0 0 0 0 0 1 0 1 0 0 0 1 1 0 0 0 0 0 1 1 0 0 0 1 1 0 1 0 1 0 1 0 1 1 0 1 0 1 1 0 1 0 0 0 0 0 0 0 1 0 2 0 0 1 0 0 0 0 1 0 1 0 0 1 0 0 0 0 1 0 0 0 0 0 0 2 1 0 0 0 0 1 0 1 0 0 0 0 0 0 0 0 1 0 0 0 1 2 0 0 0 0 0 0 0 0 0 0 0 0 1 0 1 0 0 1 2 0 0 0 0 0 0 0 0 1 1 0 1 0 0 0 0 0 0 0 0 0 0 0 0 0 1 0 1 0 1 0 1 0 1 0 2 0 2 0 0 0 0 1 1 0 1 0 1 0 0 0 0 0 0 0 0 1 0 0 0 0 1 0 1 0 0 0 1 0 0 0 0 0 0 0 0 0 0 0 0 0 0 0 1 0 1 0 0 0 0 0 0 1 0 0 0 0 0 0 0 0 0 0 0 0 0 0 0 0 0 1 0 0 0 0 1 0 0 1 0</counts>
			</dataPoints>
		</scan>
		<scan status="Completed" appendNumber="0" scanAxis="2Theta" mode="Continuous">
			<header>
				<startTimeStamp>2024-11-01T13:58:14-04:00</startTimeStamp>
				<endTimeStamp>2024-11-01T14:28:19-04:00</endTimeStamp>
				<author>
					<name>lw627</name>
				</author>
				<source>
					<applicationSoftware version="7.1">Data Collector</applicationSoftware>
					<instrumentControlSoftware version="8.2  20201204">EMPYREAN</instrumentControlSoftware>
					<instrumentID>0000000011260721</instrumentID>
				</source>
			</header>
			<dataPoints>
				<positions axis="2Theta" unit="deg">
					<startPosition>47.2200978637236</startPosition>
					<endPosition>50.5673676349401</endPosition>
				</positions>
				<positions axis="Omega" unit="deg">
					<commonPosition>24.4468663746659</commonPosition>
				</positions>
				<positions axis="Phi" unit="deg">
					<commonPosition>3.05</commonPosition>
				</positions>
				<positions axis="Chi" unit="deg">
					<commonPosition>0</commonPosition>
				</positions>
				<positions axis="Z" unit="mm">
					<commonPosition>8.407</commonPosition>
				</positions>
				<commonCountingTime unit="seconds">0.974</commonCountingTime>
				<counts unit="counts">1 1 0 1 0 2 1 1 1 1 3 2 2 0 0 0 1 1 1 1 0 1 1 1 0 0 0 0 1 1 0 1 0 1 0 0 0 3 0 0 0 1 0 1 1 0 1 0 0 1 1 0 0 1 0 0 0 0 0 0 0 0 0 0 1 0 1 0 0 1 0 0 0 0 2 0 1 2 0 0 1 0 0 0 0 1 0 0 0 0 1 0 0 0 0 0 0 0 0 0 1 1 0 0 0 2 0 0 0 1 0 0 1 0 0 0 0 0 0 0 0 0 0 0 0 1 1 0 0 0 0 1 1 0 0 0 1 0 0 0 0 0 0 1 1 0 0 0 0 1 0 1 1 0 0 0 0 2 0 0 1 1 0 0 0 0 1 0 0 0 0 1 0 1 0 0 0 0 0 0 0 0 0 1 0 0 0 0 1 0 1 0 1 0 0 1 0 0 1 0 0 0 0 0 0 1 0 1 0 0 0 0 0 0 0 1 0 1 0 0 0 0 0 1 0 0 0 0 0 0 0 0 0 0 3 0 0 1 0 0 0 0 1 1 1 0 0 0 2 0 0 0 0 0 0</counts>
			</dataPoints>
		</scan>
		<scan status="Completed" appendNumber="0" scanAxis="2Theta" mode="Continuous">
			<header>
				<startTimeStamp>2024-11-01T13:58:14-04:00</startTimeStamp>
				<endTimeStamp>2024-11-01T14:28:19-04:00</endTimeStamp>
				<author>
					<name>lw627</name>
				</author>
				<source>
					<applicationSoftware version="7.1">Data Collector</applicationSoftware>
					<instrumentControlSoftware version="8.2  20201204">EMPYREAN</instrumentControlSoftware>
					<instrumentID>0000000011260721</instrumentID>
				</source>
			</header>
			<dataPoints>
				<positions axis="2Theta" unit="deg">
					<startPosition>47.2233804343918</startPosition>
					<endPosition>50.5706502056082</endPosition>
				</positions>
				<positions axis="Omega" unit="deg">
					<commonPosition>24.44850766</commonPosition>
				</positions>
				<positions axis="Phi" unit="deg">
					<commonPosition>3.05</commonPosition>
				</positions>
				<positions axis="Chi" unit="deg">
					<commonPosition>0</commonPosition>
				</positions>
				<positions axis="Z" unit="mm">
					<commonPosition>8.407</commonPosition>
				</positions>
				<commonCountingTime unit="seconds">0.974</commonCountingTime>
				<counts unit="counts">1 2 1 0 0 0 0 1 1 0 1 0 0 1 1 0 0 0 0 0 0 0 1 0 0 0 1 0 0 0 0 1 0 0 0 1 0 0 0 0 0 0 1 0 1 0 0 1 1 1 0 0 0 2 0 1 0 2 1 0 0 0 0 0 1 1 0 0 0 0 0 0 0 0 0 0 0 0 2 1 0 0 0 0 1 1 0 0 0 1 0 0 0 0 1 0 2 0 1 0 1 1 0 0 0 0 0 0 0 0 0 0 0 0 0 0 1 0 1 0 0 0 0 0 1 1 0 0 0 0 1 1 1 1 1 0 2 0 0 0 0 0 0 0 0 0 0 0 1 0 0 0 1 0 0 0 0 0 0 1 0 0 0 0 0 0 0 1 0 0 0 0 0 0 0 1 0 0 0 0 1 1 1 0 0 0 0 0 0 1 0 0 0 0 0 0 0 2 1 0 0 1 0 1 0 0 0 1 0 0 0 0 0 0 0 0 0 0 0 0 0 0 0 0 0 0 0 1 0 3 0 0 0 0 0 0 0 0 0 0 1 0 0 1 0 0 1 1 0 0 0 0 0 0 0</counts>
			</dataPoints>
		</scan>
	</xrdMeasurement>
</xrdMeasurements>