File: data/previous_data/set_5-YG042-044/xrd/YG042-SRO001-STO001-07172022.xrdml
<xrdMeasurements xmlns="http://www.xrdml.com/XRDMeasurement/2.1" xmlns:xsi="http://www.w3.org/2001/XMLSchema-instance" xsi:schemaLocation="http://www.xrdml.com/XRDMeasurement/2.1 http://www.xrdml.com/XRDMeasurement/2.1/XRDMeasurement.xsd" status="Completed">
	<comment>
		<entry>Configuration=Main Configuration, Owner=User-1, Creation date=6/17/2015 3:36:16 PM</entry>
		<entry>Goniometer=HR HD (Theta/2Theta); Minimum step size 2Theta:0.0001; Minimum step size Omega:0.0001</entry>
		<entry>Sample stage=MRD Cradle; Minimum step size Phi:0.01; Minimum step size Chi:0.01; Minimum step size X:0.01; Minimum step size Y:0.01; Minimum step size Z:0.001</entry>
		<entry>Diffractometer system=XPERT-3</entry>
		<entry>Measurement program=C:\PANalytical\Data Collector\Programs\Yichen\regular_2theta_20-50_0.4s-20min.xrdmp, Identifier={AEA8F2F2-8BFA-4B07-A521-A571AF38E73A}</entry>
	</comment>
	<sample type="To be analyzed">
		<id></id>
		<name></name>
		<preparedBy></preparedBy>
	</sample>
	<xrdMeasurement measurementType="Scan" status="Completed" sampleMode="Reflection">
		<comment>
			<entry>PHD Lower Level = 4.02 (keV), PHD Upper Level = 11.27 (keV)</entry>
		</comment>
		<usedWavelength intended="K-Alpha 1">
			<kAlpha1 unit="Angstrom">1.5405980</kAlpha1>
			<kAlpha2 unit="Angstrom">1.5444260</kAlpha2>
			<kBeta unit="Angstrom">1.3922500</kBeta>
			<ratioKAlpha2KAlpha1>0.5000</ratioKAlpha2KAlpha1>
		</usedWavelength>
		<incidentBeamPath>
			<radius unit="mm">320.00</radius>
			<xRayTube id="1010048" name="Empyrean Cu LFF HR (9430 033 7310x) DK425175">
				<tension unit="kV">45.0</tension>
				<current unit="mA">40.0</current>
				<anodeMaterial>Cu</anodeMaterial>
				<focus type="Line">
					<length unit="mm">12.0</length>
					<width unit="mm">0.4</width>
					<takeOffAngle unit="deg">4.2</takeOffAngle>
				</focus>
			</xRayTube>
			<xRayMirror id="27090001" name="Inc. Beam Cu W/Si (hybrid MRD)" hybrid="true">
				<crystal type="Graded" shape="Parabolic">W/Si</crystal>
				<acceptanceAngle unit="deg">0.800</acceptanceAngle>
				<length unit="mm">60.0</length>
			</xRayMirror>
			<monochromator id="23090002" name="Hybrid monochr. 2xGe(220) Cu asym." hybrid="true">
				<crystal type="Asymmetric" shape="Flat">Ge</crystal>
				<numberOfReflections>2</numberOfReflections>
				<hkl>
					<h>2</h>
					<k>2</k>
					<l>0</l>
				</hkl>
			</monochromator>
			<divergenceSlit id="22010004" name="Fixed slit 1/2°" xsi:type="fixedDivergenceSlitType">
				<distanceToSample unit="mm">220.00</distanceToSample>
				<height unit="mm">0.76</height>
			</divergenceSlit>
			<beamAttenuator id="26010001" name="Progr. beam attenuator Ni 0.125 mm" xsi:type="intensitySwitchedBeamAttenuatorType">
				<factor>172.00</factor>
				<material>Ni</material>
				<activateLevel unit="counts per second">500000</activateLevel>
				<deactivateLevel unit="counts per second">400000</deactivateLevel>
			</beamAttenuator>
		</incidentBeamPath>
		<diffractedBeamPath>
			<radius unit="mm">320.00</radius>
			<antiScatterSlit id="22090009" name="AS slit 7.5 mm (PIXcel)" xsi:type="fixedAntiScatterSlitType">
				<height unit="mm">7.50</height>
			</antiScatterSlit>
			<sollerSlit id="21010002" name="Soller slits 0.04 rad.">
				<opening unit="rad">0.0400</opening>
			</sollerSlit>
			<receivingSlit id="22010004" name="Fixed slit 1/2°">
				<height unit="mm">0.76</height>
			</receivingSlit>
			<detector id="7010020" name="PIXcel3D-Medipix3 1x1 detector" xsi:type="areaDetectorType">
				<phd unit="%">
					<lowerLevel>25.0</lowerLevel>
					<upperLevel>70.0</upperLevel>
				</phd>
				<mode>Receiving slit</mode>
				<activeChannelsEquatorial>5</activeChannelsEquatorial>
				<activeChannelsAxial>255</activeChannelsAxial>
				<pitchEquatorial unit="mm">0.05500</pitchEquatorial>
				<pitchAxial unit="mm">0.05500</pitchAxial>
				<readOutPeriod unit="seconds">0.050</readOutPeriod>
			</detector>
		</diffractedBeamPath>
		<scan appendNumber="0" mode="Continuous" scanAxis="2Theta-Omega" status="Completed">
			<header>
				<startTimeStamp>2022-07-17T16:58:08-07:00</startTimeStamp>
				<endTimeStamp>2022-07-17T17:18:35-07:00</endTimeStamp>
				<author>
					<name>XRD</name>
				</author>
				<source>
					<applicationSoftware version="6.1b">Data Collector</applicationSoftware>
					<instrumentControlSoftware version="7.4b 20181204">XPERT-3</instrumentControlSoftware>
					<instrumentID>0000000011163216</instrumentID>
				</source>
			</header>
			<dataPoints>
				<positions axis="2Theta" unit="deg">
					<startPosition>20.0050</startPosition>
					<endPosition>49.9950</endPosition>
				</positions>
				<positions axis="Omega" unit="deg">
					<startPosition>9.7732</startPosition>
					<endPosition>24.7682</endPosition>
				</positions>
				<positions axis="Phi" unit="deg">
					<commonPosition>0.00</commonPosition>
				</positions>
				<positions axis="Chi" unit="deg">
					<commonPosition>-0.12</commonPosition>
				</positions>
				<positions axis="X" unit="mm">
					<commonPosition>0.44</commonPosition>
				</positions>
				<positions axis="Y" unit="mm">
					<commonPosition>0.00</commonPosition>
				</positions>
				<positions axis="Z" unit="mm">
					<commonPosition>8.345</commonPosition>
				</positions>
				<beamAttenuationFactors>1.00 1.00 1.00 1.00 1.00 1.00 1.00 1.00 1.00 1.00 1.00 1.00 1.00 1.00 1.00 1.00 1.00 1.00 1.00 1.00 1.00 1.00 1.00 1.00 1.00 1.00 1.00 1.00 1.00 1.00 1.00 1.00 1.00 1.00 1.00 1.00 1.00 1.00 1.00 1.00 1.00 1.00 1.00 1.00 1.00 1.00 1.00 1.00 1.00 1.00 1.00 1.00 1.00 1.00 1.00 1.00 1.00 1.00 1.00 1.00 1.00 1.00 1.00 1.00 1.00 1.00 1.00 1.00 1.00 1.00 1.00 1.00 1.00 1.00 1.00 1.00 1.00 1.00 1.00 1.00 1.00 1.00 1.00 1.00 1.00 1.00 1.00 1.00 1.00 1.00 1.00 1.00 1.00 1.00 1.00 1.00 1.00 1.00 1.00 1.00 1.00 1.00 1.00 1.00 1.00 1.00 1.00 1.00 1.00 1.00 1.00 1.00 1.00 1.00 1.00 1.00 1.00 1.00 1.00 1.00 1.00 1.00 1.00 1.00 1.00 1.00 1.00 1.00 1.00 1.00 1.00 1.00 1.00 1.00 1.00 1.00 1.00 1.00 1.00 1.00 1.00 1.00 1.00 1.00 1.00 1.00 1.00 1.00 1.00 1.00 1.00 1.00 1.00 1.00 1.00 1.00 1.00 1.00 1.00 1.00 1.00 1.00 1.00 1.00 1.00 1.00 1.00 1.00 1.00 1.00 1.00 1.00 1.00 1.00 1.00 1.00 1.00 1.00 1.00 1.00 1.00 1.00 1.00 1.00 1.00 1.00 1.00 1.00 1.00 1.00 1.00 1.00 1.00 1.00 1.00 1.00 1.00 1.00 1.00 1.00 1.00 1.00 1.00 1.00 1.00 1.00 1.00 1.00 1.00 1.00 1.00 1.00 1.00 1.00 1.00 1.00 1.00 1.00 1.00 1.00 1.00 1.00 1.00 1.00 1.00 1.00 1.00 1.00 1.00 1.00 1.00 1.00 1.00 1.00 1.00 1.00 1.00 1.00 1.00 1.00 1.00 1.00 1.00 1.00 1.00 1.00 1.00 1.00 1.00 1.00 1.00 1.00 1.00 1.00 1.00 1.00 1.00 1.00 1.00 1.00 1.00 1.00 1.00 1.00 1.00 1.00 1.00 1.00 1.00 1.00 1.00 1.00 1.00 1.00 1.00 1.00 1.00 1.00 1.00 1.00 1.00 1.00 1.00 1.00 1.00 1.00 1.00 1.00 1.00 1.00 1.00 1.00 1.00 1.00 1.00 1.00 1.00 1.00 1.00 1.00 1.00 1.00 1.00 1.00 1.00 1.00 1.00 1.00 1.00 1.00 1.00 1.00 1.00 1.00 1.00 1.00 1.00 1.00 1.00 1.00 1.00 1.00 1.00 1.00 1.00 1.00 1.00 1.00 1.00 1.00 1.00 1.00 1.00 1.00 1.00 1.00 1.00 1.00 1.00 1.00 1.00 1.00 1.00 1.00 1.00 1.00 1.00 1.00 1.00 1.00 1.00 1.00 1.00 1.00 1.00 1.00 1.00 1.00 1.00 1.00 1.00 1.00 1.00 1.00 1.00 1.00 1.00 1.00 1.00 1.00 1.00 1.00 1.00 1.00 1.00 1.00 1.00 1.00 1.00 1.00 1.00 1.00 1.00 1.00 1.00 1.00 1.00 1.00 1.00 1.00 1.00 1.00 1.00 1.00 1.00 1.00 1.00 1.00 1.00 1.00 1.00 1.00 1.00 1.00 1.00 1.00 1.00 1.00 1.00 1.00 1.00 1.00 1.00 1.00 1.00 1.00 1.00 1.00 1.00 1.00 1.00 1.00 1.00 1.00 1.00 1.00 1.00 1.00 1.00 1.00 1.00 1.00 1.00 1.00 1.00 1.00 1.00 1.00 1.00 1.00 1.00 1.00 1.00 1.00 1.00 1.00 1.00 1.00 1.00 1.00 1.00 1.00 1.00 1.00 1.00 1.00 1.00 1.00 1.00 1.00 1.00 1.00 1.00 1.00 1.00 1.00 1.00 1.00 1.00 1.00 1.00 1.00 1.00 1.00 1.00 1.00 1.00 1.00 1.00 1.00 1.00 1.00 1.00 1.00 1.00 1.00 1.00 1.00 1.00 1.00 1.00 1.00 1.00 1.00 1.00 1.00 1.00 1.00 1.00 1.00 1.00 1.00 1.00 1.00 1.00 1.00 1.00 1.00 1.00 1.00 1.00 1.00 1.00 1.00 1.00 1.00 1.00 1.00 1.00 1.00 1.00 1.00 1.00 1.00 1.00 1.00 1.00 1.00 1.00 1.00 1.00 1.00 1.00 1.00 1.00 1.00 1.00 1.00 1.00 1.00 1.00 1.00 1.00 1.00 1.00 1.00 1.00 1.00 1.00 1.00 1.00 1.00 1.00 1.00 1.00 1.00 1.00 1.00 1.00 1.00 1.00 1.00 1.00 1.00 1.00 1.00 1.00 1.00 1.00 1.00 1.00 1.00 1.00 1.00 1.00 1.00 1.00 1.00 1.00 1.00 1.00 1.00 1.00 1.00 1.00 1.00 1.00 1.00 1.00 1.00 1.00 1.00 1.00 1.00 1.00 1.00 1.00 1.00 1.00 1.00 1.00 1.00 1.00 1.00 1.00 1.00 1.00 1.00 1.00 1.00 1.00 1.00 1.00 1.00 1.00 1.00 1.00 1.00 1.00 1.00 1.00 1.00 1.00 1.00 1.00 1.00 1.00 1.00 1.00 1.00 1.00 1.00 1.00 1.00 1.00 1.00 1.00 1.00 1.00 1.00 1.00 1.00 1.00 1.00 1.00 1.00 1.00 1.00 1.00 1.00 1.00 1.00 1.00 1.00 1.00 1.00 1.00 1.00 1.00 1.00 1.00 1.00 1.00 1.00 1.00 1.00 1.00 1.00 1.00 1.00 1.00 1.00 1.00 1.00 1.00 1.00 1.00 1.00 1.00 1.00 1.00 1.00 1.00 1.00 1.00 1.00 1.00 1.00 1.00 1.00 1.00 1.00 1.00 1.00 1.00 1.00 1.00 1.00 1.00 1.00 1.00 1.00 1.00 1.00 1.00 1.00 1.00 1.00 1.00 1.00 1.00 1.00 1.00 1.00 1.00 1.00 1.00 1.00 1.00 1.00 1.00 1.00 1.00 1.00 1.00 1.00 1.00 1.00 1.00 1.00 1.00 1.00 1.00 1.00 1.00 1.00 1.00 1.00 1.00 1.00 1.00 1.00 1.00 1.00 1.00 1.00 1.00 1.00 1.00 1.00 1.00 1.00 1.00 1.00 1.00 1.00 1.00 1.00 1.00 1.00 1.00 1.00 1.00 1.00 1.00 1.00 1.00 1.00 1.00 1.00 1.00 1.00 1.00 1.00 1.00 1.00 1.00 1.00 1.00 1.00 1.00 1.00 1.00 1.00 1.00 1.00 1.00 1.00 1.00 1.00 1.00 1.00 1.00 1.00 1.00 1.00 1.00 1.00 1.00 1.00 1.00 1.00 1.00 1.00 1.00 1.00 1.00 1.00 1.00 1.00 1.00 1.00 1.00 1.00 1.00 1.00 1.00 1.00 1.00 1.00 1.00 1.00 1.00 1.00 1.00 1.00 1.00 1.00 1.00 1.00 1.00 1.00 1.00 1.00 1.00 1.00 1.00 1.00 1.00 1.00 1.00 1.00 1.00 1.00 1.00 1.00 1.00 1.00 1.00 1.00 1.00 1.00 1.00 1.00 1.00 1.00 1.00 1.00 1.00 1.00 1.00 1.00 1.00 1.00 1.00 1.00 1.00 1.00 1.00 1.00 1.00 1.00 1.00 1.00 1.00 1.00 1.00 1.00 1.00 1.00 1.00 1.00 1.00 1.00 1.00 1.00 1.00 1.00 1.00 1.00 1.00 1.00 1.00 1.00 1.00 1.00 1.00 1.00 1.00 1.00 1.00 1.00 1.00 1.00 1.00 1.00 1.00 1.00 1.00 1.00 1.00 1.00 1.00 1.00 1.00 1.00 1.00 1.00 1.00 1.00 1.00 1.00 1.00 1.00 1.00 1.00 1.00 1.00 1.00 1.00 1.00 1.00 1.00 1.00 1.00 1.00 1.00 1.00 1.00 1.00 1.00 1.00 1.00 1.00 1.00 1.00 1.00 1.00 1.00 1.00 1.00 1.00 1.00 1.00 1.00 1.00 1.00 1.00 1.00 1.00 1.00 1.00 1.00 1.00 1.00 1.00 1.00 1.00 1.00 1.00 1.00 1.00 1.00 1.00 1.00 1.00 1.00 1.00 1.00 1.00 1.00 1.00 1.00 1.00 1.00 1.00 1.00 1.00 1.00 1.00 1.00 1.00 1.00 1.00 1.00 1.00 1.00 1.00 1.00 1.00 1.00 1.00 1.00 1.00 1.00 1.00 1.00 1.00 1.00 1.00 1.00 1.00 1.00 1.00 1.00 1.00 1.00 1.00 1.00 1.00 1.00 1.00 1.00 1.00 1.00 1.00 1.00 1.00 1.00 1.00 1.00 1.00 1.00 1.00 1.00 1.00 1.00 1.00 1.00 1.00 1.00 1.00 1.00 1.00 1.00 1.00 1.00 1.00 1.00 1.00 1.00 1.00 1.00 1.00 1.00 1.00 1.00 1.00 1.00 1.00 1.00 1.00 1.00 1.00 1.00 1.00 1.00 1.00 1.00 1.00 1.00 1.00 1.00 1.00 1.00 1.00 1.00 1.00 1.00 1.00 1.00 1.00 1.00 1.00 1.00 1.00 1.00 1.00 1.00 1.00 1.00 1.00 1.00 1.00 1.00 1.00 1.00 1.00 1.00 1.00 1.00 1.00 1.00 1.00 1.00 1.00 1.00 1.00 1.00 1.00 1.00 1.00 1.00 1.00 1.00 1.00 1.00 1.00 1.00 1.00 1.00 1.00 1.00 1.00 1.00 1.00 1.00 1.00 1.00 1.00 1.00 1.00 1.00 1.00 1.00 1.00 1.00 1.00 1.00 1.00 1.00 1.00 1.00 1.00 1.00 1.00 1.00 1.00 1.00 1.00 1.00 1.00 1.00 1.00 1.00 1.00 1.00 1.00 1.00 1.00 1.00 1.00 1.00 1.00 1.00 1.00 1.00 1.00 1.00 1.00 1.00 1.00 1.00 1.00 1.00 1.00 1.00 1.00 1.00 1.00 1.00 1.00 1.00 1.00 1.00 1.00 1.00 1.00 1.00 1.00 1.00 1.00 1.00 1.00 1.00 1.00 1.00 1.00 1.00 1.00 1.00 1.00 1.00 1.00 1.00 1.00 1.00 1.00 1.00 1.00 1.00 1.00 1.00 1.00 1.00 1.00 1.00 1.00 1.00 1.00 1.00 1.00 1.00 1.00 1.00 1.00 1.00 1.00 1.00 1.00 1.00 1.00 1.00 1.00 1.00 1.00 1.00 1.00 1.00 1.00 1.00 1.00 1.00 1.00 1.00 1.00 1.00 1.00 1.00 1.00 1.00 1.00 1.00 1.00 1.00 1.00 1.00 1.00 1.00 1.00 1.00 1.00 1.00 1.00 1.00 1.00 1.00 1.00 1.00 1.00 1.00 1.00 1.00 1.00 1.00 1.00 1.00 1.00 1.00 1.00 1.00 1.00 1.00 1.00 1.00 1.00 1.00 1.00 1.00 1.00 1.00 1.00 1.00 1.00 1.00 1.00 1.00 1.00 1.00 1.00 1.00 1.00 1.00 1.00 1.00 1.00 1.00 1.00 1.00 1.00 1.00 1.00 1.00 1.00 1.00 1.00 1.00 1.00 1.00 1.00 1.00 1.00 1.00 1.00 1.00 1.00 1.00 1.00 1.00 1.00 1.00 1.00 1.00 1.00 1.00 1.00 1.00 1.00 1.00 1.00 1.00 1.00 1.00 1.00 1.00 1.00 1.00 1.00 1.00 1.00 1.00 1.00 1.00 1.00 1.00 1.00 1.00 1.00 1.00 1.00 1.00 1.00 1.00 1.00 1.00 1.00 1.00 1.00 1.00 1.00 1.00 1.00 1.00 1.00 1.00 1.00 1.00 1.00 1.00 1.00 1.00 1.00 1.00 1.00 1.00 1.00 1.00 1.00 1.00 1.00 1.00 1.00 1.00 1.00 1.00 1.00 1.00 1.00 1.00 1.00 1.00 1.00 1.00 1.00 1.00 1.00 1.00 1.00 1.00 1.00 1.00 1.00 1.00 1.00 1.00 1.00 1.00 1.00 1.00 1.00 1.00 1.00 1.00 1.00 1.00 1.00 1.00 1.00 1.00 1.00 1.00 1.00 1.00 1.00 1.00 1.00 1.00 1.00 1.00 1.00 1.00 1.00 1.00 1.00 1.00 1.00 1.00 1.00 1.00 1.00 1.00 1.00 1.00 1.00 1.00 1.00 1.00 1.00 1.00 1.00 1.00 1.00 1.00 1.00 1.00 1.00 1.00 1.00 1.00 1.00 1.00 1.00 1.00 1.00 1.00 1.00 1.00 1.00 1.00 1.00 1.00 1.00 1.00 1.00 1.00 1.00 1.00 1.00 1.00 1.00 1.00 1.00 1.00 1.00 1.00 1.00 1.00 1.00 1.00 1.00 1.00 1.00 1.00 1.00 1.00 1.00 1.00 1.00 1.00 1.00 1.00 1.00 1.00 1.00 1.00 1.00 1.00 1.00 1.00 1.00 1.00 1.00 1.00 1.00 1.00 1.00 1.00 1.00 1.00 1.00 1.00 1.00 1.00 1.00 1.00 1.00 1.00 1.00 1.00 1.00 1.00 1.00 1.00 1.00 1.00 1.00 1.00 1.00 1.00 1.00 1.00 1.00 1.00 1.00 1.00 1.00 1.00 1.00 1.00 1.00 1.00 1.00 1.00 1.00 1.00 1.00 1.00 1.00 1.00 1.00 1.00 1.00 1.00 1.00 1.00 1.00 1.00 1.00 1.00 1.00 1.00 1.00 1.00 1.00 1.00 1.00 1.00 1.00 1.00 1.00 1.00 1.00 1.00 1.00 1.00 1.00 1.00 1.00 1.00 1.00 1.00 1.00 1.00 1.00 1.00 1.00 1.00 1.00 1.00 1.00 1.00 1.00 1.00 1.00 1.00 1.00 1.00 1.00 1.00 1.00 1.00 1.00 1.00 1.00 1.00 1.00 1.00 1.00 1.00 1.00 1.00 1.00 1.00 1.00 1.00 1.00 1.00 1.00 1.00 1.00 1.00 1.00 1.00 1.00 1.00 1.00 1.00 1.00 1.00 1.00 1.00 1.00 1.00 1.00 1.00 1.00 1.00 1.00 1.00 1.00 1.00 1.00 1.00 1.00 1.00 1.00 1.00 1.00 1.00 1.00 1.00 1.00 1.00 1.00 1.00 1.00 1.00 1.00 1.00 1.00 1.00 1.00 1.00 1.00 1.00 1.00 1.00 1.00 1.00 1.00 1.00 1.00 1.00 1.00 1.00 1.00 1.00 1.00 1.00 1.00 1.00 1.00 1.00 1.00 1.00 1.00 1.00 1.00 1.00 1.00 1.00 1.00 1.00 1.00 1.00 1.00 1.00 1.00 1.00 1.00 1.00 1.00 1.00 1.00 1.00 1.00 1.00 1.00 1.00 1.00 1.00 1.00 1.00 1.00 1.00 1.00 1.00 1.00 1.00 1.00 1.00 1.00 1.00 1.00 1.00 1.00 1.00 1.00 1.00 1.00 1.00 1.00 1.00 1.00 1.00 1.00 1.00 1.00 1.00 1.00 1.00 1.00 1.00 1.00 1.00 1.00 1.00 1.00 1.00 1.00 1.00 1.00 1.00 1.00 1.00 1.00 1.00 1.00 1.00 1.00 1.00 1.00 1.00 1.00 1.00 1.00 1.00 1.00 1.00 1.00 1.00 1.00 1.00 1.00 1.00 1.00 1.00 1.00 1.00 1.00 1.00 1.00 1.00 1.00 1.00 1.00 1.00 1.00 1.00 1.00 1.00 1.00 1.00 1.00 1.00 1.00 1.00 1.00 1.00 1.00 1.00 1.00 1.00 1.00 1.00 1.00 1.00 1.00 1.00 1.00 1.00 1.00 1.00 1.00 1.00 1.00 1.00 1.00 1.00 1.00 1.00 1.00 1.00 1.00 1.00 1.00 1.00 1.00 1.00 1.00 1.00 1.00 1.00 1.00 1.00 1.00 1.00 1.00 1.00 1.00 1.00 1.00 1.00 1.00 1.00 1.00 1.00 1.00 1.00 1.00 1.00 1.00 1.00 1.00 1.00 1.00 1.00 1.00 1.00 1.00 1.00 1.00 1.00 1.00 1.00 1.00 1.00 1.00 1.00 1.00 1.00 1.00 1.00 1.00 1.00 1.00 1.00 1.00 1.00 1.00 1.00 1.00 1.00 1.00 1.00 1.00 1.00 1.00 1.00 1.00 1.00 1.00 1.00 1.00 1.00 1.00 1.00 1.00 1.00 1.00 1.00 1.00 1.00 1.00 1.00 1.00 1.00 1.00 1.00 1.00 1.00 1.00 1.00 1.00 1.00 1.00 1.00 1.00 1.00 1.00 1.00 1.00 1.00 1.00 1.00 1.00 1.00 1.00 1.00 1.00 1.00 1.00 1.00 1.00 1.00 1.00 1.00 1.00 1.00 1.00 1.00 1.00 1.00 1.00 1.00 1.00 1.00 1.00 1.00 1.00 1.00 1.00 1.00 1.00 1.00 1.00 1.00 1.00 1.00 1.00 1.00 1.00 1.00 1.00 1.00 1.00 1.00 1.00 1.00 1.00 1.00 1.00 1.00 1.00 1.00 1.00 1.00 1.00 1.00 1.00 1.00 1.00 1.00 1.00 1.00 1.00 1.00 1.00 1.00 1.00 1.00 1.00 1.00 1.00 1.00 1.00 1.00 1.00 1.00 1.00 1.00 1.00 1.00 1.00 1.00 1.00 1.00 1.00 1.00 1.00 1.00 1.00 1.00 1.00 1.00 1.00 1.00 1.00 1.00 1.00 1.00 1.00 1.00 1.00 1.00 1.00 1.00 1.00 1.00 1.00 1.00 1.00 1.00 1.00 1.00 1.00 1.00 1.00 1.00 1.00 1.00 1.00 1.00 1.00 1.00 1.00 1.00 1.00 1.00 1.00 1.00 1.00 1.00 1.00 1.00 1.00 1.00 1.00 1.00 1.00 1.00 1.00 1.00 1.00 1.00 1.00 1.00 1.00 1.00 1.00 1.00 1.00 1.00 1.00 1.00 1.00 1.00 1.00 1.00 1.00 1.00 1.00 1.00 1.00 1.00 1.00 1.00 1.00 1.00 1.00 1.00 1.00 1.00 1.00 1.00 1.00 1.00 1.00 1.00 1.00 1.00 1.00 1.00 1.00 1.00 1.00 1.00 1.00 1.00 1.00 1.00 1.00 1.00 1.00 1.00 1.00 1.00 1.00 1.00 1.00 1.00 1.00 1.00 1.00 1.00 1.00 1.00 1.00 1.00 1.00 1.00 1.00 1.00 1.00 1.00 1.00 1.00 1.00 1.00 1.00 1.00 1.00 1.00 1.00 1.00 1.00 1.00 1.00 1.00 1.00 1.00 1.00 1.00 1.00 1.00 1.00 1.00 1.00 1.00 1.00 1.00 1.00 1.00 1.00 1.00 1.00 1.00 1.00 1.00 1.00 1.00 1.00 1.00 1.00 1.00 1.00 1.00 1.00 1.00 1.00 1.00 1.00 1.00 1.00 1.00 1.00 1.00 1.00 1.00 1.00 1.00 1.00 1.00 1.00 1.00 1.00 1.00 1.00 1.00 1.00 1.00 1.00 1.00 1.00 1.00 1.00 1.00 1.00 1.00 1.00 1.00 1.00 1.00 1.00 1.00 1.00 1.00 1.00 1.00 1.00 1.00 1.00 1.00 1.00 1.00 1.00 1.00 1.00 1.00 1.00 1.00 1.00 1.00 1.00 1.00 1.00 1.00 1.00 1.00 1.00 1.00 1.00 1.00 1.00 1.00 1.00 1.00 1.00 1.00 1.00 1.00 1.00 1.00 1.00 1.00 1.00 1.00 1.00 1.00 1.00 1.00 1.00 1.00 1.00 1.00 1.00 1.00 1.00 1.00 1.00 1.00 1.00 1.00 1.00 1.00 1.00 1.00 1.00 1.00 1.00 1.00 1.00 1.00 1.00 1.00 1.00 1.00 1.00 1.00 1.00 1.00 1.00 1.00 1.00 1.00 1.00 1.00 1.00 1.00 1.00 1.00 1.00 1.00 1.00 1.00 1.00 1.00 1.00 1.00 1.00 1.00 1.00 1.00 1.00 1.00 1.00 1.00 1.00 1.00 1.00 1.00 1.00 1.00 1.00 1.00 1.00 1.00 1.00 1.00 1.00 1.00 1.00 1.00 1.00 1.00 1.00 1.00 1.00 1.00 1.00 1.00 1.00 1.00 1.00 1.00 1.00 1.00 1.00 1.00 1.00 1.00 1.00 1.00 1.00 1.00 1.00 1.00 1.00 1.00 1.00 1.00 1.00 1.00 1.00 1.00 1.00 1.00 1.00 1.00 1.00 1.00 1.00 1.00 1.00 1.00 1.00 1.00 1.00 1.00 1.00 1.00 1.00 1.00 1.00 1.00 1.00 1.00 1.00 1.00 1.00 1.00 1.00 1.00 1.00 1.00 1.00 1.00 1.00 1.00 1.00 1.00 1.00 1.00 1.00 1.00 1.00 1.00 1.00 1.00 1.00 1.00 1.00 1.00 1.00 1.00 1.00 1.00 1.00 1.00 1.00 1.00 1.00 1.00 1.00 1.00 1.00 1.00 1.00 1.00 1.00 1.00 1.00 1.00 1.00 1.00 1.00 1.00 1.00 1.00 1.00 1.00 1.00 1.00 1.00 1.00 1.00 1.00 1.00 1.00 1.00 1.00 1.00 1.00 1.00 1.00 1.00 1.00 1.00 1.00 1.00 1.00 1.00 1.00 1.00 1.00 1.00 1.00 1.00 1.00 1.00 1.00 1.00 1.00 1.00 1.00 1.00 1.00 1.00 1.00 1.00 1.00 1.00 1.00 1.00 1.00 1.00 1.00 1.00 1.00 1.00 1.00 1.00 1.00 1.00 1.00 1.00 1.00 1.00 1.00 1.00 1.00 1.00 1.00 1.00 1.00 1.00 1.00 1.00 1.00 1.00 1.00 1.00 1.00 1.00 1.00 1.00 1.00 1.00 1.00 1.00 1.00 1.00 1.00 1.00 1.00 1.00 1.00 1.00 1.00 1.00 1.00 1.00 1.00 1.00 1.00 1.00 1.00 1.00 1.00 1.00 1.00 1.00 1.00 1.00 1.00 1.00 1.00 1.00 1.00 1.00 1.00 1.00 1.00 1.00 1.00 1.00 1.00 1.00 1.00 1.00 1.00 1.00 1.00 1.00 1.00 1.00 1.00 1.00 1.00 1.00 1.00 1.00 1.00 1.00 1.00 1.00 1.00 1.00 1.00 1.00 1.00 1.00 1.00 1.00 1.00 1.00 1.00 1.00 1.00 1.00 1.00 1.00 1.00 1.00 1.00 1.00 1.00 1.00 1.00 1.00 1.00 1.00 1.00 1.00 1.00 1.00 1.00 1.00 1.00 1.00 1.00 1.00 1.00 1.00 1.00 1.00 1.00 1.00 1.00 1.00 1.00 172.00 172.00 172.00 172.00 172.00 172.00 1.00 1.00 1.00 1.00 1.00 1.00 1.00 1.00 1.00 1.00 1.00 1.00 1.00 1.00 1.00 1.00 1.00 1.00 1.00 1.00 1.00 1.00 1.00 1.00 1.00 1.00 1.00 1.00 1.00 1.00 1.00 1.00 1.00 1.00 1.00 1.00 1.00 1.00 1.00 1.00 1.00 1.00 1.00 1.00 1.00 1.00 1.00 1.00 1.00 1.00 1.00 1.00 1.00 1.00 1.00 1.00 1.00 1.00 1.00 1.00 1.00 1.00 1.00 1.00 1.00 1.00 1.00 1.00 1.00 1.00 1.00 1.00 1.00 1.00 1.00 1.00 1.00 1.00 1.00 1.00 1.00 1.00 1.00 1.00 1.00 1.00 1.00 1.00 1.00 1.00 1.00 1.00 1.00 1.00 1.00 1.00 1.00 1.00 1.00 1.00 1.00 1.00 1.00 1.00 1.00 1.00 1.00 1.00 1.00 1.00 1.00 1.00 1.00 1.00 1.00 1.00 1.00 1.00 1.00 1.00 1.00 1.00 1.00 1.00 1.00 1.00 1.00 1.00 1.00 1.00 1.00 1.00 1.00 1.00 1.00 1.00 1.00 1.00 1.00 1.00 1.00 1.00 1.00 1.00 1.00 1.00 1.00 1.00 1.00 1.00 1.00 1.00 1.00 1.00 1.00 1.00 1.00 1.00 1.00 1.00 1.00 1.00 1.00 1.00 1.00 1.00 1.00 1.00 1.00 1.00 1.00 1.00 1.00 1.00 1.00 1.00 1.00 1.00 1.00 1.00 1.00 1.00 1.00 1.00 1.00 1.00 1.00 1.00 1.00 1.00 1.00 1.00 1.00 1.00 1.00 1.00 1.00 1.00 1.00 1.00 1.00 1.00 1.00 1.00 1.00 1.00 1.00 1.00 1.00 1.00 1.00 1.00 1.00 1.00 1.00 1.00 1.00 1.00 1.00 1.00 1.00 1.00 1.00 1.00 1.00 1.00 1.00 1.00 1.00 1.00 1.00 1.00 1.00 1.00 1.00 1.00 1.00 1.00 1.00 1.00 1.00 1.00 1.00 1.00 1.00 1.00 1.00 1.00 1.00 1.00 1.00 1.00 1.00 1.00 1.00 1.00 1.00 1.00 1.00 1.00 1.00 1.00 1.00 1.00 1.00 1.00 1.00 1.00 1.00 1.00 1.00 1.00 1.00 1.00 1.00 1.00 1.00 1.00 1.00 1.00 1.00 1.00 1.00 1.00 1.00 1.00 1.00 1.00 1.00 1.00 1.00 1.00 1.00 1.00 1.00 1.00 1.00 1.00 1.00 1.00 1.00 1.00 1.00 1.00 1.00 1.00 1.00 1.00 1.00 1.00 1.00 1.00 1.00 1.00 1.00 1.00 1.00 1.00 1.00 1.00 1.00 1.00 1.00 1.00 1.00 1.00 1.00 1.00 1.00 1.00 1.00 1.00 1.00 1.00 1.00 1.00 1.00 1.00 1.00 1.00 1.00 1.00 1.00 1.00 1.00 1.00 1.00 1.00 1.00 1.00 1.00 1.00 1.00</beamAttenuationFactors>
				<commonCountingTime unit="seconds">0.352</commonCountingTime>
				<counts unit="counts">34 33 30 39 31 42 39 34 30 34 32 42 29 36 36 40 34 25 39 47 30 33 39 36 30 31 26 37 41 34 33 27 31 35 23 33 40 27 28 27 42 23 27 41 30 36 35 35 33 31 25 33 27 49 30 34 34 24 34 37 33 25 26 32 37 22 34 32 35 20 32 27 19 33 31 29 41 29 37 24 27 32 40 28 32 38 39 32 29 30 36 35 34 38 38 29 31 33 28 38 40 34 34 36 29 38 38 32 40 36 34 34 35 30 41 29 33 31 31 43 25 26 34 40 28 35 32 29 26 28 43 35 28 19 20 21 25 24 27 28 22 40 33 43 35 28 41 40 37 38 30 30 42 33 46 34 24 45 30 29 33 28 31 36 40 32 20 29 35 42 39 43 34 42 35 30 40 43 34 58 30 52 36 36 42 34 34 43 39 44 38 37 36 29 30 27 38 50 33 44 38 54 61 55 51 72 53 68 79 87 68 58 78 53 60 54 49 43 44 41 38 47 33 53 64 73 94 135 154 159 191 267 301 313 375 423 456 522 616 622 701 773 787 719 813 773 822 880 850 756 783 749 663 753 595 557 523 484 399 359 296 221 184 144 154 126 212 456 1506 3288 10273 30349 64478 104196 127901 101605 32733 8151 3529 1557 320 273 232 234 195 198 208 158 145 144 169 139 130 99 101 87 82 67 56 42 38 35 41 37 33 35 42 42 34 65 43 59 60 73 56 58 48 63 44 43 57 52 60 40 45 44 45 37 26 34 28 26 25 24 27 30 35 41 34 36 34 35 42 42 42 51 34 44 34 35 34 40 32 35 23 33 21 34 22 21 29 27 34 32 30 33 44 27 25 24 41 42 45 34 35 30 37 29 29 32 24 28 28 34 24 30 21 25 30 29 23 23 36 23 33 25 25 28 25 26 30 27 29 26 31 25 24 24 22 26 25 23 22 28 26 27 26 26 24 20 30 24 21 31 28 30 18 25 37 27 30 30 25 24 21 35 39 25 18 31 25 22 21 16 29 19 24 28 25 32 22 23 25 22 26 22 19 21 24 20 19 30 24 23 25 17 19 23 19 20 24 28 25 20 26 21 25 24 19 20 28 31 24 23 16 11 23 28 35 26 27 29 23 25 19 15 28 22 17 30 24 16 16 11 24 24 14 22 22 19 28 27 30 23 33 19 22 18 24 24 27 21 31 22 31 21 32 22 22 23 18 21 18 18 29 28 20 34 36 14 23 13 18 18 20 22 20 30 24 18 15 28 26 15 20 19 33 21 23 28 23 25 21 29 24 20 23 26 24 18 17 20 27 20 31 14 29 21 24 15 20 20 18 26 17 18 19 14 23 28 21 13 20 20 31 29 16 20 20 18 17 13 22 23 17 27 19 25 19 16 16 10 26 17 20 17 16 14 30 17 15 32 18 29 24 17 24 22 23 23 16 19 13 23 21 26 17 14 25 20 22 23 17 16 21 14 17 17 19 20 17 31 18 18 20 20 21 22 15 20 24 15 16 20 17 22 14 25 23 25 16 19 24 21 20 29 11 21 20 15 15 21 17 19 23 24 15 16 15 21 21 25 21 17 19 19 27 12 20 23 17 21 17 20 18 19 16 19 21 19 24 27 21 24 19 18 18 24 20 20 25 18 14 17 9 20 25 28 14 17 12 20 22 15 19 18 16 19 15 19 14 18 14 17 19 25 20 17 22 21 19 19 15 25 22 18 17 17 18 20 21 20 32 17 23 7 21 27 17 21 15 15 16 16 20 24 19 19 10 23 16 15 24 23 13 20 19 13 21 12 22 22 15 25 19 14 16 13 14 17 18 16 11 17 20 12 16 24 22 13 11 21 18 19 22 22 18 17 28 16 25 13 26 16 23 21 23 18 19 20 21 18 20 19 17 22 22 11 19 11 24 16 29 23 17 16 13 13 25 17 20 19 19 16 24 13 12 15 22 16 14 22 18 13 18 12 10 13 15 9 8 20 19 11 7 21 11 11 21 24 13 25 17 21 17 18 17 13 23 13 20 21 7 18 12 17 21 18 19 13 17 19 21 21 19 14 19 16 12 13 15 12 23 20 19 25 23 20 12 20 19 12 14 12 15 14 11 18 17 15 15 12 10 19 10 12 25 17 16 16 13 14 12 11 15 11 15 16 12 25 17 14 14 19 15 14 9 22 18 15 10 14 20 12 19 6 13 18 16 11 10 14 19 15 18 17 19 20 12 16 18 18 14 9 11 15 21 15 13 14 14 14 21 19 14 19 18 13 8 10 17 16 16 20 12 17 24 11 12 16 20 16 10 15 13 24 20 18 17 18 12 21 11 8 16 19 23 8 17 9 10 16 13 18 19 16 19 15 14 16 5 8 14 9 19 23 17 17 12 16 15 16 18 20 16 24 13 16 20 15 22 13 11 13 17 16 12 11 14 15 16 14 19 19 15 8 10 18 11 15 14 8 11 20 13 14 17 12 14 17 13 7 15 23 10 14 12 11 21 14 16 6 12 17 16 13 6 16 12 19 20 25 12 20 15 13 12 19 12 13 15 10 17 15 10 14 16 9 15 14 10 15 14 18 16 9 6 20 9 15 15 11 15 18 12 18 14 13 11 18 16 15 10 15 17 14 14 8 8 19 13 16 21 13 12 20 16 9 12 13 15 12 13 17 17 9 16 11 14 16 16 10 13 12 13 13 17 16 18 12 13 16 12 15 13 10 16 12 14 15 19 6 13 10 12 17 13 5 17 15 16 11 14 12 18 19 15 15 20 18 10 16 12 13 16 10 11 11 12 11 9 12 13 10 17 10 7 7 12 23 15 13 14 12 9 11 14 9 13 7 10 9 9 15 8 16 12 13 10 16 11 5 14 11 12 19 15 11 12 14 8 16 16 11 14 10 23 18 13 11 14 9 12 15 9 11 15 15 13 10 8 11 13 11 6 11 8 13 8 15 12 11 7 18 10 14 17 8 12 8 13 8 14 12 12 12 10 9 11 9 9 13 8 14 18 16 7 13 7 11 8 13 12 11 9 9 11 12 13 7 14 13 13 7 13 11 9 11 12 9 11 7 14 8 9 12 18 10 13 8 11 12 12 14 8 9 13 11 13 11 11 6 9 10 14 14 10 10 19 9 21 16 7 13 10 14 17 13 11 7 15 12 8 8 8 8 10 17 7 16 14 10 12 11 17 12 13 16 6 14 5 7 11 13 10 12 13 8 14 11 10 10 12 14 9 12 8 13 10 8 13 9 11 8 6 11 16 8 13 17 7 13 14 5 5 13 7 16 16 11 13 13 13 12 11 5 12 13 18 18 9 14 15 11 10 7 15 12 8 9 8 3 17 10 8 14 15 11 7 18 7 9 15 18 19 11 9 5 13 5 12 9 7 16 11 10 12 12 8 10 10 8 7 9 12 11 7 10 7 11 10 9 11 13 11 16 12 12 8 10 4 13 10 5 9 9 17 10 14 12 5 5 11 7 10 14 13 11 5 13 6 5 8 7 17 6 12 14 11 9 12 13 7 12 17 11 13 9 11 10 13 8 8 10 8 9 11 11 12 12 5 12 13 10 8 12 7 10 8 6 11 14 12 11 16 11 9 7 14 14 6 6 12 12 10 9 8 9 10 16 12 4 10 9 17 17 14 10 12 10 10 12 11 11 12 15 20 7 8 12 11 12 10 11 9 9 12 14 9 7 12 12 9 9 11 11 9 6 9 7 9 9 11 8 14 9 7 11 9 10 10 13 10 10 7 8 17 17 9 15 13 5 13 10 8 6 16 9 9 7 13 11 7 17 13 15 6 5 5 14 10 8 8 14 10 15 10 8 11 11 14 8 9 7 12 6 6 4 12 13 7 12 7 8 13 9 12 10 6 14 12 9 9 9 8 8 10 10 13 11 15 9 9 14 10 8 10 18 15 10 11 12 9 14 10 14 15 7 14 14 11 12 9 5 10 6 11 10 9 10 11 11 9 9 1 15 5 9 4 9 13 12 14 11 11 14 14 6 15 8 7 9 10 6 8 7 11 11 8 14 4 14 11 8 13 6 11 11 6 8 9 8 10 4 9 13 14 5 8 11 15 9 9 10 10 10 13 8 10 7 6 11 9 10 5 12 18 16 15 18 14 17 13 15 10 6 13 9 11 12 11 10 13 6 12 8 9 7 11 7 13 13 5 7 3 11 9 12 10 14 7 10 14 9 10 12 12 19 5 9 11 10 13 15 6 9 11 10 7 7 15 8 8 8 12 11 13 9 11 7 10 3 8 11 9 8 11 9 9 6 9 9 14 7 7 12 9 9 9 12 11 7 5 14 9 9 14 12 9 11 11 18 9 11 7 8 5 6 12 12 13 8 11 4 9 14 6 6 11 5 12 10 9 10 8 9 8 11 9 7 13 15 11 14 10 6 4 6 10 15 6 9 10 9 8 17 6 9 10 11 9 6 11 7 9 10 9 12 10 9 10 9 8 12 15 8 9 7 8 10 13 13 12 11 16 12 11 13 4 9 10 9 11 13 10 10 19 8 9 12 12 10 6 13 7 12 11 12 14 11 10 12 12 7 11 10 8 7 7 7 4 11 6 6 8 13 13 10 5 4 9 7 9 11 12 12 10 6 6 4 7 7 7 15 12 12 9 10 12 13 9 15 6 12 12 14 9 6 7 6 8 11 11 8 9 10 4 8 12 11 11 8 8 11 7 10 3 13 15 8 15 9 11 4 3 15 9 11 5 4 6 7 10 6 9 8 11 13 5 11 7 10 12 8 14 12 6 4 4 11 8 5 14 9 11 13 9 17 11 7 12 9 7 5 14 9 5 7 8 11 17 10 6 9 14 15 10 14 11 4 11 6 6 7 16 15 14 13 12 6 11 6 4 11 8 5 12 8 6 2 7 9 14 9 16 10 11 15 12 14 9 11 10 15 11 7 10 13 10 7 9 8 9 8 13 8 9 7 7 10 11 18 14 8 11 15 13 9 11 4 11 8 6 12 11 13 9 11 6 10 5 14 8 10 10 12 11 11 6 11 9 13 12 9 13 9 9 8 11 9 10 4 5 8 6 9 8 3 6 13 8 10 9 11 14 9 13 3 17 8 11 5 6 5 7 10 15 9 14 15 8 7 15 15 17 4 12 8 5 6 13 7 9 13 5 12 12 10 13 7 12 11 8 8 6 7 16 6 9 11 9 11 17 7 7 10 11 9 9 6 12 14 12 15 10 8 7 23 9 12 8 15 9 10 9 12 10 11 6 11 7 10 11 7 10 12 8 9 10 13 8 18 9 15 16 9 14 11 8 9 12 15 15 10 14 16 15 8 11 10 12 6 8 12 11 7 6 8 16 16 14 5 12 18 7 7 15 15 13 18 15 11 10 7 12 16 10 6 7 13 11 10 9 10 10 14 19 13 12 16 9 8 15 10 11 17 16 14 15 11 14 9 15 8 7 11 9 5 14 7 8 13 9 15 13 10 6 16 16 15 20 6 12 14 23 16 19 18 20 17 13 8 10 14 15 19 15 14 12 14 14 15 13 13 21 17 14 23 15 20 22 17 17 15 19 19 27 13 19 18 18 11 19 18 13 8 10 8 12 11 9 11 9 17 18 13 19 19 17 18 30 17 18 27 23 23 31 25 30 28 27 27 24 25 24 12 18 12 13 13 15 17 26 14 25 25 29 26 41 46 37 49 41 59 53 51 56 52 44 53 55 55 25 30 23 27 21 24 18 28 27 23 21 44 45 59 74 74 70 104 114 108 130 160 132 121 139 144 133 124 117 131 117 80 66 71 61 53 56 78 93 105 141 199 286 334 436 499 668 771 958 1177 1403 1492 1635 1855 2118 2428 2582 2827 3128 3286 3485 3735 3709 4128 3971 4236 4255 4293 4411 4382 4426 4263 4238 4072 3868 3783 3689 3400 3283 2974 2734 2473 2226 2109 1776 1602 1431 1218 1045 847 758 616 554 438 398 384 377 385 415 465 544 603 683 798 984 1138 1301 1496 1994 2728 4749 8203 12802 19146 28687 40654 53539 70459 103799 1339 3029 5267 7456 4919 1445 151943 119996 85211 57293 35308 18465 7127 3023 1652 1035 667 497 345 288 212 164 151 126 107 100 87 88 84 89 80 77 66 90 84 77 85 76 50 45 61 50 52 40 36 33 22 26 22 21 17 15 20 16 13 20 21 25 20 20 21 28 33 20 27 21 21 22 21 19 25 22 12 15 19 9 11 15 11 11 13 11 7 9 8 10 11 16 12 14 16 16 5 23 14 9 17 15 13 10 8 14 13 8 7 8 7 12 13 8 11 6 9 10 16 11 8 19 11 12 13 7 10 8 3 8 10 12 12 10 14 9 9 9 7 7 7 10 9 6 11 10 8 7 8 11 9 15 9 11 11 10 15 5 12 8 5 18 13 12 7 6 7 4 9 7 11 13 5 11 4 6 6 9 5 14 9 7 6 7 9 2 6 6 9 9 13 12 5 11 12 12 6 5 8 9 4 12 7 5 6 9 12 7 9 11 10 9 7 4 3 7 5 9 12 13 7 8 8 10 10 9 2 7 4 8 8 6 8 6 6 13 3 9 7 11 13 6 4 4 8 12 7 5 7 5 5 6 8 5 7 9 6 8 5 13 8 5 8 9 4 4 6 11 8 8 8 9 5 14 6 11 9 6 1 5 12 4 2 6 2 2 8 6 7 5 7 3 7 7 10 2 11 8 5 2 6 5 5 4 7 7 7 10 7 2 7 8 6 7 8 8 11 4 8 9 5 8 7 7 4 3 9 8 6 4 9 4 6 8 9 8 3 7 3 11 8 7 6 5 8 8 5 5 9 3 9 5 4 2 7 4 4 10 4 6 7 9 6</counts>
			</dataPoints>
		</scan>
	</xrdMeasurement>
</xrdMeasurements>