File: data/RSM YY128/YY128_NSO_420_RSM SLOW.xrdml
<?xml version="1.0" encoding="utf-8"?>
<xrdMeasurements xmlns="http://www.xrdml.com/XRDMeasurement/2.2" xmlns:xsi="http://www.w3.org/2001/XMLSchema-instance" xsi:schemaLocation="http://www.xrdml.com/XRDMeasurement/2.2 http://www.xrdml.com/XRDMeasurement/2.2/XRDMeasurement.xsd" status="Completed">
	<comment>
		<entry>Configuration=3-axes Cradle_Reflection, Owner=User, Creation date=9/2/2021 3:55:24 PM</entry>
		<entry>Goniometer=Theta/Theta; Minimum step size 2Theta:0.0001; Minimum step size Omega:0.0001</entry>
		<entry>Sample stage=Chi-Phi-z stage 240 mm (reflection); Minimum step size Phi:0.01; Minimum step size Chi:0.01; Minimum step size Z:0.001</entry>
		<entry>Diffractometer system=EMPYREAN</entry>
		<entry>Measurement program=C:\PANalytical\Data Collector\Programs\Yu Yun\RSM\RSM 3degree_high resolution_ultra slow.xrdmp, Identifier={7AB59E42-5401-414A-835E-03917DBC5AB8}</entry>
	</comment>
	<sample type="To be analyzed">
		<id/>
		<name/>
		<preparedBy/>
	</sample>
	<xrdMeasurement status="Completed" measurementType="Area measurement" measurementStepAxis="Omega-2Theta" sampleMode="Reflection">
		<comment>
			<entry>PHD Lower Level = 4.02 (keV), PHD Upper Level = 11.26 (keV)</entry>
		</comment>
		<usedWavelength intended="K-Alpha">
			<kAlpha1 unit="Angstrom">1.5405980</kAlpha1>
			<kAlpha2 unit="Angstrom">1.5444260</kAlpha2>
			<kBeta unit="Angstrom">1.3922500</kBeta>
			<ratioKAlpha2KAlpha1>0</ratioKAlpha2KAlpha1>
		</usedWavelength>
		<incidentBeamPath>
			<radius unit="mm">240.00</radius>
			<xRayTube id="1010048" name="Empyrean Cu LFF HR (9430 033 7310x) DK432574">
				<tension unit="kV">45.0</tension>
				<current unit="mA">40.0</current>
				<anodeMaterial>Cu</anodeMaterial>
				<focus type="Line">
					<length unit="mm">12.0</length>
					<width unit="mm">0.4</width>
					<takeOffAngle unit="deg">4.4</takeOffAngle>
				</focus>
			</xRayTube>
			<xRayMirror xsi:type="xRayMirrorType" id="27080001" name="Inc. Beam Cu W/Si (hybrid MPD)" hybrid="true">
				<crystal type="Graded" shape="Parabolic">W/Si</crystal>
				<acceptanceAngle unit="deg">0.800</acceptanceAngle>
				<length unit="mm">55.3</length>
			</xRayMirror>
			<monochromator xsi:type="monochromatorType" id="23090002" name="Hybrid monochr. 2xGe220 Cu asym." hybrid="true">
				<crystal type="Asymmetric" shape="Flat">Ge</crystal>
				<numberOfReflections>2</numberOfReflections>
				<hkl>
					<h>2</h>
					<k>2</k>
					<l>0</l>
				</hkl>
			</monochromator>
			<mask xsi:type="maskType" id="22030008" name="Fixed mask 4 mm">
				<distanceToSample unit="mm">171.00</distanceToSample>
				<width unit="mm">4.00</width>
			</mask>
			<divergenceSlit xsi:type="fixedDivergenceSlitType" id="22010007" name="Fixed slit 1/8°">
				<distanceToSample unit="mm">179.30</distanceToSample>
				<height unit="mm">0.19</height>
			</divergenceSlit>
		</incidentBeamPath>
		<diffractedBeamPath>
			<radius unit="mm">240.00</radius>
			<antiScatterSlit xsi:type="fixedAntiScatterSlitType" id="22060009" name="Programmable anti-scatter slit">
				<angle unit="deg">4</angle>
			</antiScatterSlit>
			<detector xsi:type="areaDetectorType" id="7010020" name="PIXcel3D-Medipix3 1x1 detector">
				<phd unit="%">
					<lowerLevel>25</lowerLevel>
					<upperLevel>70</upperLevel>
				</phd>
				<mode>Scanning snapshot equatorial</mode>
				<activeChannelsEquatorial>255</activeChannelsEquatorial>
				<activeChannelsAxial>255</activeChannelsAxial>
				<pitchEquatorial unit="mm">0.05500</pitchEquatorial>
				<pitchAxial unit="mm">0.05500</pitchAxial>
				<readOutPeriod unit="seconds">0.980</readOutPeriod>
			</detector>
		</diffractedBeamPath>
		<scan status="Completed" appendNumber="0" scanAxis="2Theta" mode="Continuous">
			<header>
				<startTimeStamp>2022-11-11T16:03:56-05:00</startTimeStamp>
				<endTimeStamp>2022-11-11T16:23:58-05:00</endTimeStamp>
				<author>
					<name>User</name>
				</author>
				<source>
					<applicationSoftware version="7.1">Data Collector</applicationSoftware>
					<instrumentControlSoftware version="8.2  20201204">EMPYREAN</instrumentControlSoftware>
					<instrumentID>0000000011260721</instrumentID>
				</source>
			</header>
			<dataPoints>
				<positions axis="2Theta" unit="deg">
					<startPosition>71.6426063943918</startPosition>
					<endPosition>74.9898761656082</endPosition>
				</positions>
				<positions axis="Omega" unit="deg">
					<commonPosition>18.36812064</commonPosition>
				</positions>
				<positions axis="Phi" unit="deg">
					<commonPosition>183.93</commonPosition>
				</positions>
				<positions axis="Chi" unit="deg">
					<commonPosition>0</commonPosition>
				</positions>
				<positions axis="Z" unit="mm">
					<commonPosition>8.387</commonPosition>
				</positions>
				<commonCountingTime unit="seconds">0.974</commonCountingTime>
				<counts unit="counts">0 1 0 1 1 1 0 0 0 0 0 2 1 0 1 1 1 2 1 0 1 0 0 1 0 0 1 1 1 0 1 0 0 0 1 1 1 1 0 1 1 0 0 0 1 0 1 0 0 1 0 0 1 1 1 0 1 0 0 1 1 0 1 1 0 2 0 1 0 0 2 2 1 0 0 2 0 0 1 2 1 0 0 0 0 0 2 0 0 0 1 0 1 0 1 1 0 0 2 0 0 0 0 0 0 0 0 0 0 3 1 0 0 0 2 1 0 2 0 1 0 0 0 0 0 0 0 0 0 0 0 0 1 0 1 0 2 0 0 2 3 1 0 1 1 0 1 2 2 2 0 2 0 1 0 0 0 1 2 1 1 1 1 0 0 1 0 1 0 1 1 1 1 2 2 0 0 1 0 1 1 0 2 1 1 0 0 1 1 1 0 0 0 1 0 1 0 1 1 1 0 1 0 0 1 0 1 1 0 1 0 1 1 1 1 3 0 0 0 0 0 1 0 0 2 2 0 0 0 2 0 1 2 2 1 0 2 0 1 2 2 1 0 1 1 2 0 0 1 0 0 1 0 2 0</counts>
			</dataPoints>
		</scan>
		<scan status="Completed" appendNumber="0" scanAxis="2Theta" mode="Continuous">
			<header>
				<startTimeStamp>2022-11-11T16:03:56-05:00</startTimeStamp>
				<endTimeStamp>2022-11-11T16:23:58-05:00</endTimeStamp>
				<author>
					<name>User</name>
				</author>
				<source>
					<applicationSoftware version="7.1">Data Collector</applicationSoftware>
					<instrumentControlSoftware version="8.2  20201204">EMPYREAN</instrumentControlSoftware>
					<instrumentID>0000000011260721</instrumentID>
				</source>
			</header>
			<dataPoints>
				<positions axis="2Theta" unit="deg">
					<startPosition>71.6458889650661</startPosition>
					<endPosition>74.9931587362826</endPosition>
				</positions>
				<positions axis="Omega" unit="deg">
					<commonPosition>18.3697619253372</commonPosition>
				</positions>
				<positions axis="Phi" unit="deg">
					<commonPosition>183.93</commonPosition>
				</positions>
				<positions axis="Chi" unit="deg">
					<commonPosition>0</commonPosition>
				</positions>
				<positions axis="Z" unit="mm">
					<commonPosition>8.387</commonPosition>
				</positions>
				<commonCountingTime unit="seconds">0.974</commonCountingTime>
				<counts unit="counts">0 0 0 0 0 1 2 0 1 2 1 0 1 2 0 0 2 1 1 0 0 1 0 0 0 0 1 0 2 0 0 0 0 0 0 0 0 2 0 0 0 1 1 2 1 0 1 0 0 0 0 1 2 1 1 0 0 0 1 0 0 0 2 1 1 1 2 0 0 0 2 0 1 1 0 0 1 1 0 1 0 0 0 0 1 1 2 0 0 1 0 0 2 0 1 1 0 1 0 0 0 0 0 1 1 0 0 0 0 0 1 1 0 0 0 0 2 0 0 0 0 0 1 4 0 0 1 0 1 1 0 0 1 1 0 0 1 0 0 0 0 1 0 1 0 2 1 0 1 2 0 1 1 0 0 0 0 2 0 0 2 1 2 0 0 1 0 2 2 3 2 1 0 3 2 4 1 1 1 1 0 0 1 0 1 3 1 0 0 1 1 0 1 1 0 0 0 1 1 1 0 0 2 0 2 0 0 0 0 0 0 0 1 1 1 2 0 1 0 1 1 0 0 0 0 0 1 0 1 2 1 0 2 0 2 1 1 0 0 2 1 2 1 0 1 0 1 0 0 0 1 0 1 0 0</counts>
			</dataPoints>
		</scan>
		<scan status="Completed" appendNumber="0" scanAxis="2Theta" mode="Continuous">
			<header>
				<startTimeStamp>2022-11-11T16:03:56-05:00</startTimeStamp>
				<endTimeStamp>2022-11-11T16:23:58-05:00</endTimeStamp>
				<author>
					<name>User</name>
				</author>
				<source>
					<applicationSoftware version="7.1">Data Collector</applicationSoftware>
					<instrumentControlSoftware version="8.2  20201204">EMPYREAN</instrumentControlSoftware>
					<instrumentID>0000000011260721</instrumentID>
				</source>
			</header>
			<dataPoints>
				<positions axis="2Theta" unit="deg">
					<startPosition>71.6491715357405</startPosition>
					<endPosition>74.9964413069569</endPosition>
				</positions>
				<positions axis="Omega" unit="deg">
					<commonPosition>18.3714032106743</commonPosition>
				</positions>
				<positions axis="Phi" unit="deg">
					<commonPosition>183.93</commonPosition>
				</positions>
				<positions axis="Chi" unit="deg">
					<commonPosition>0</commonPosition>
				</positions>
				<positions axis="Z" unit="mm">
					<commonPosition>8.387</commonPosition>
				</positions>
				<commonCountingTime unit="seconds">0.974</commonCountingTime>
				<counts unit="counts">0 0 0 1 0 0 0 0 1 0 0 0 1 1 1 0 0 1 0 0 0 1 0 0 0 2 0 0 0 0 0 1 1 0 0 0 2 1 0 0 1 1 1 0 0 1 0 0 1 0 1 0 0 0 4 0 0 1 0 2 0 0 0 0 0 0 0 1 0 1 2 0 1 1 0 1 1 1 1 0 1 2 1 0 1 0 0 0 0 0 2 0 3 1 1 0 1 0 0 1 3 0 0 0 0 0 0 0 0 0 0 0 0 1 1 3 0 2 0 0 0 1 1 1 0 0 0 0 1 0 1 1 1 1 0 0 2 0 1 1 0 1 0 0 0 2 1 0 0 1 0 1 1 0 0 0 0 1 0 0 0 1 0 0 1 0 1 0 3 1 0 1 3 3 1 1 0 0 0 0 1 0 1 0 0 2 0 2 1 0 0 1 1 1 0 0 0 1 0 1 0 0 0 2 2 1 1 1 0 0 1 2 0 0 1 0 1 0 0 0 1 0 1 0 1 0 2 0 0 1 0 1 0 0 0 0 1 0 0 0 0 2 0 0 0 0 0 1 2 1 0 0 0 1 0</counts>
			</dataPoints>
		</scan>
		<scan status="Completed" appendNumber="0" scanAxis="2Theta" mode="Continuous">
			<header>
				<startTimeStamp>2022-11-11T16:03:56-05:00</startTimeStamp>
				<endTimeStamp>2022-11-11T16:23:58-05:00</endTimeStamp>
				<author>
					<name>User</name>
				</author>
				<source>
					<applicationSoftware version="7.1">Data Collector</applicationSoftware>
					<instrumentControlSoftware version="8.2  20201204">EMPYREAN</instrumentControlSoftware>
					<instrumentID>0000000011260721</instrumentID>
				</source>
			</header>
			<dataPoints>
				<positions axis="2Theta" unit="deg">
					<startPosition>71.6524541064148</startPosition>
					<endPosition>74.9997238776313</endPosition>
				</positions>
				<positions axis="Omega" unit="deg">
					<commonPosition>18.3730444960115</commonPosition>
				</positions>
				<positions axis="Phi" unit="deg">
					<commonPosition>183.93</commonPosition>
				</positions>
				<positions axis="Chi" unit="deg">
					<commonPosition>0</commonPosition>
				</positions>
				<positions axis="Z" unit="mm">
					<commonPosition>8.387</commonPosition>
				</positions>
				<commonCountingTime unit="seconds">0.974</commonCountingTime>
				<counts unit="counts">0 0 0 2 1 0 0 0 1 0 0 0 0 1 0 1 0 0 0 0 1 0 0 0 1 1 0 0 0 1 2 0 0 0 0 1 0 0 1 0 0 1 0 2 1 1 0 0 0 1 1 1 2 0 1 0 0 4 0 0 0 1 0 0 0 0 0 1 0 0 1 2 0 0 0 0 2 0 0 0 0 0 0 0 2 0 1 1 0 1 0 0 1 0 0 0 0 0 0 1 0 1 0 0 1 1 1 0 1 1 0 0 1 0 2 1 1 2 0 0 1 1 1 0 0 0 0 0 0 2 0 1 1 1 0 1 0 1 0 1 1 2 1 1 1 0 1 0 1 0 1 1 1 1 0 1 0 1 0 0 0 4 0 0 0 1 1 0 2 3 0 3 1 4 1 1 1 1 0 0 1 0 1 0 1 0 1 0 0 1 1 0 0 1 0 2 2 0 0 1 0 0 1 0 0 1 1 0 2 1 1 1 0 0 0 0 1 2 1 2 1 0 0 0 0 2 0 0 1 0 0 0 1 0 0 2 0 0 2 0 1 2 0 0 0 2 0 0 0 0 1 1 1 0 1</counts>
			</dataPoints>
		</scan>
		<scan status="Completed" appendNumber="0" scanAxis="2Theta" mode="Continuous">
			<header>
				<startTimeStamp>2022-11-11T16:03:56-05:00</startTimeStamp>
				<endTimeStamp>2022-11-11T16:23:58-05:00</endTimeStamp>
				<author>
					<name>User</name>
				</author>
				<source>
					<applicationSoftware version="7.1">Data Collector</applicationSoftware>
					<instrumentControlSoftware version="8.2  20201204">EMPYREAN</instrumentControlSoftware>
					<instrumentID>0000000011260721</instrumentID>
				</source>
			</header>
			<dataPoints>
				<positions axis="2Theta" unit="deg">
					<startPosition>71.6557366770891</startPosition>
					<endPosition>75.0030064483056</endPosition>
				</positions>
				<positions axis="Omega" unit="deg">
					<commonPosition>18.3746857813487</commonPosition>
				</positions>
				<positions axis="Phi" unit="deg">
					<commonPosition>183.93</commonPosition>
				</positions>
				<positions axis="Chi" unit="deg">
					<commonPosition>0</commonPosition>
				</positions>
				<positions axis="Z" unit="mm">
					<commonPosition>8.387</commonPosition>
				</positions>
				<commonCountingTime unit="seconds">0.974</commonCountingTime>
				<counts unit="counts">1 1 0 1 1 0 0 1 2 0 0 0 1 0 0 0 1 0 0 0 1 0 1 0 1 1 0 0 0 0 0 1 0 0 0 1 0 0 0 1 1 0 0 1 1 1 1 0 0 0 0 1 0 1 0 0 1 2 1 0 1 0 1 1 0 0 1 1 0 0 0 2 0 2 0 1 0 0 0 0 0 1 1 0 0 1 0 1 0 0 0 0 2 0 0 0 0 1 2 1 1 0 0 2 0 0 1 0 1 0 0 3 1 1 0 0 0 1 0 1 0 1 0 0 3 0 1 0 1 0 0 1 0 0 1 0 2 0 1 1 0 2 0 0 0 0 0 1 0 1 1 2 1 2 1 1 0 2 2 0 0 1 1 2 0 3 0 1 1 1 0 0 1 4 3 0 0 0 1 0 1 0 1 1 0 1 1 0 0 1 1 1 0 1 0 1 1 1 1 0 0 0 1 0 3 1 2 0 1 0 0 2 0 0 0 1 1 0 2 0 1 1 2 2 1 0 0 0 2 1 0 0 0 1 0 0 0 0 3 0 0 0 3 2 1 2 1 1 1 0 1 0 0 0 0</counts>
			</dataPoints>
		</scan>
		<scan status="Completed" appendNumber="0" scanAxis="2Theta" mode="Continuous">
			<header>
				<startTimeStamp>2022-11-11T16:03:56-05:00</startTimeStamp>
				<endTimeStamp>2022-11-11T16:23:58-05:00</endTimeStamp>
				<author>
					<name>User</name>
				</author>
				<source>
					<applicationSoftware version="7.1">Data Collector</applicationSoftware>
					<instrumentControlSoftware version="8.2  20201204">EMPYREAN</instrumentControlSoftware>
					<instrumentID>0000000011260721</instrumentID>
				</source>
			</header>
			<dataPoints>
				<positions axis="2Theta" unit="deg">
					<startPosition>71.6590192477635</startPosition>
					<endPosition>75.0062890189799</endPosition>
				</positions>
				<positions axis="Omega" unit="deg">
					<commonPosition>18.3763270666859</commonPosition>
				</positions>
				<positions axis="Phi" unit="deg">
					<commonPosition>183.93</commonPosition>
				</positions>
				<positions axis="Chi" unit="deg">
					<commonPosition>0</commonPosition>
				</positions>
				<positions axis="Z" unit="mm">
					<commonPosition>8.387</commonPosition>
				</positions>
				<commonCountingTime unit="seconds">0.974</commonCountingTime>
				<counts unit="counts">0 0 2 1 0 1 0 1 0 2 0 0 0 0 1 1 1 0 0 0 1 0 0 2 1 0 0 1 0 2 0 1 0 0 0 3 1 1 0 0 0 0 0 3 0 1 2 0 0 1 1 1 2 0 1 0 0 0 2 0 1 0 0 0 0 0 3 0 0 1 0 0 0 0 0 0 1 0 1 2 1 1 0 0 0 0 0 2 2 1 0 0 0 0 1 2 3 0 1 0 0 2 0 1 3 0 0 2 1 1 0 2 0 1 0 0 0 0 0 1 1 0 0 1 0 0 0 1 0 1 0 1 0 0 2 0 1 0 1 0 1 0 0 1 1 1 1 1 1 1 0 3 0 1 1 1 0 0 2 1 1 2 0 0 0 1 1 1 2 2 1 4 3 2 2 1 0 1 2 2 0 1 0 1 1 1 1 0 1 0 0 1 1 0 2 1 1 2 0 2 0 0 0 1 1 2 0 2 1 1 0 0 1 0 0 1 1 1 0 0 1 1 0 1 2 1 0 0 1 1 3 0 1 0 0 0 1 0 1 1 0 1 1 1 2 1 0 0 0 1 2 2 0 0 0</counts>
			</dataPoints>
		</scan>
		<scan status="Completed" appendNumber="0" scanAxis="2Theta" mode="Continuous">
			<header>
				<startTimeStamp>2022-11-11T16:03:56-05:00</startTimeStamp>
				<endTimeStamp>2022-11-11T16:23:58-05:00</endTimeStamp>
				<author>
					<name>User</name>
				</author>
				<source>
					<applicationSoftware version="7.1">Data Collector</applicationSoftware>
					<instrumentControlSoftware version="8.2  20201204">EMPYREAN</instrumentControlSoftware>
					<instrumentID>0000000011260721</instrumentID>
				</source>
			</header>
			<dataPoints>
				<positions axis="2Theta" unit="deg">
					<startPosition>71.6623018184378</startPosition>
					<endPosition>75.0095715896543</endPosition>
				</positions>
				<positions axis="Omega" unit="deg">
					<commonPosition>18.377968352023</commonPosition>
				</positions>
				<positions axis="Phi" unit="deg">
					<commonPosition>183.93</commonPosition>
				</positions>
				<positions axis="Chi" unit="deg">
					<commonPosition>0</commonPosition>
				</positions>
				<positions axis="Z" unit="mm">
					<commonPosition>8.387</commonPosition>
				</positions>
				<commonCountingTime unit="seconds">0.974</commonCountingTime>
				<counts unit="counts">0 0 1 2 1 0 1 0 1 2 1 2 0 0 0 0 0 0 0 0 1 0 0 0 0 2 1 0 0 0 1 0 2 0 0 1 1 1 0 0 0 0 0 0 0 0 0 0 0 0 0 0 0 0 0 0 0 1 0 2 0 0 1 1 0 0 2 0 0 1 1 0 1 2 0 2 1 0 1 1 0 1 0 0 0 1 0 0 0 2 1 0 3 0 0 0 0 0 1 0 0 1 0 1 0 0 1 1 0 0 1 2 0 1 0 0 4 0 1 0 0 0 0 0 1 0 1 0 1 0 0 0 0 0 2 0 1 0 0 1 1 0 0 3 0 1 0 1 1 0 1 1 0 1 0 0 0 0 1 0 0 0 1 0 2 0 1 0 0 2 1 4 0 4 2 0 0 1 0 0 1 0 1 1 0 2 1 1 0 0 1 2 1 0 0 0 1 0 0 0 0 0 1 0 0 0 0 0 1 1 0 1 2 0 0 2 1 2 1 1 0 1 0 0 4 0 1 1 0 0 2 0 0 0 1 1 1 0 0 0 2 0 1 1 1 0 1 0 1 1 0 2 1 0 1</counts>
			</dataPoints>
		</scan>
		<scan status="Completed" appendNumber="0" scanAxis="2Theta" mode="Continuous">
			<header>
				<startTimeStamp>2022-11-11T16:03:56-05:00</startTimeStamp>
				<endTimeStamp>2022-11-11T16:23:58-05:00</endTimeStamp>
				<author>
					<name>User</name>
				</author>
				<source>
					<applicationSoftware version="7.1">Data Collector</applicationSoftware>
					<instrumentControlSoftware version="8.2  20201204">EMPYREAN</instrumentControlSoftware>
					<instrumentID>0000000011260721</instrumentID>
				</source>
			</header>
			<dataPoints>
				<positions axis="2Theta" unit="deg">
					<startPosition>71.6655843891122</startPosition>
					<endPosition>75.0128541603286</endPosition>
				</positions>
				<positions axis="Omega" unit="deg">
					<commonPosition>18.3796096373602</commonPosition>
				</positions>
				<positions axis="Phi" unit="deg">
					<commonPosition>183.93</commonPosition>
				</positions>
				<positions axis="Chi" unit="deg">
					<commonPosition>0</commonPosition>
				</positions>
				<positions axis="Z" unit="mm">
					<commonPosition>8.387</commonPosition>
				</positions>
				<commonCountingTime unit="seconds">0.974</commonCountingTime>
				<counts unit="counts">1 1 0 2 2 3 0 1 0 0 0 0 1 1 0 1 1 1 2 0 0 0 2 1 0 0 1 0 1 1 0 0 0 2 1 0 0 1 1 0 0 0 2 1 1 0 2 3 1 0 0 0 0 1 0 1 0 0 0 1 0 0 0 0 0 1 1 0 2 2 0 1 0 0 0 1 2 0 0 2 0 0 1 1 0 2 1 0 1 0 0 0 0 2 1 0 1 0 0 1 0 0 1 1 0 0 0 1 1 1 0 1 0 0 0 0 2 0 0 0 0 0 0 1 0 1 0 0 0 1 0 0 0 1 1 0 0 2 1 1 1 1 1 1 1 0 0 0 0 0 1 1 1 0 0 1 1 1 0 0 0 0 0 0 0 0 2 1 1 0 4 1 8 4 0 1 2 0 1 0 0 0 0 0 0 0 0 0 0 1 0 0 0 3 1 1 1 1 2 1 2 0 0 3 0 0 0 0 2 0 1 1 0 1 0 1 2 0 1 0 1 0 1 2 0 0 1 1 0 1 1 0 0 2 2 0 2 0 1 2 2 0 1 0 0 2 1 0 0 2 1 0 0 0 0</counts>
			</dataPoints>
		</scan>
		<scan status="Completed" appendNumber="0" scanAxis="2Theta" mode="Continuous">
			<header>
				<startTimeStamp>2022-11-11T16:03:56-05:00</startTimeStamp>
				<endTimeStamp>2022-11-11T16:23:58-05:00</endTimeStamp>
				<author>
					<name>User</name>
				</author>
				<source>
					<applicationSoftware version="7.1">Data Collector</applicationSoftware>
					<instrumentControlSoftware version="8.2  20201204">EMPYREAN</instrumentControlSoftware>
					<instrumentID>0000000011260721</instrumentID>
				</source>
			</header>
			<dataPoints>
				<positions axis="2Theta" unit="deg">
					<startPosition>71.6688669597865</startPosition>
					<endPosition>75.016136731003</endPosition>
				</positions>
				<positions axis="Omega" unit="deg">
					<commonPosition>18.3812509226974</commonPosition>
				</positions>
				<positions axis="Phi" unit="deg">
					<commonPosition>183.93</commonPosition>
				</positions>
				<positions axis="Chi" unit="deg">
					<commonPosition>0</commonPosition>
				</positions>
				<positions axis="Z" unit="mm">
					<commonPosition>8.387</commonPosition>
				</positions>
				<commonCountingTime unit="seconds">0.974</commonCountingTime>
				<counts unit="counts">3 1 0 1 0 1 0 1 0 1 2 2 1 0 0 0 0 1 1 0 0 0 1 1 0 0 0 0 0 2 1 0 0 0 0 0 1 3 0 0 0 1 0 1 0 1 0 1 0 1 0 0 1 1 0 0 0 0 1 0 0 1 3 0 2 1 1 1 0 2 1 1 2 1 0 0 1 0 3 2 0 0 0 0 0 0 1 0 0 1 0 0 0 0 0 0 0 1 0 0 0 0 1 1 1 0 0 1 0 0 1 1 0 0 0 0 0 2 0 2 0 0 0 0 0 0 2 0 0 2 1 0 0 0 0 2 0 1 1 0 0 0 0 0 1 0 1 2 1 0 0 0 0 1 1 0 3 1 0 1 0 1 0 0 1 0 1 0 1 3 4 9 2 3 2 0 0 0 1 0 0 0 0 1 0 1 0 1 0 0 0 2 1 0 0 0 0 0 1 0 0 1 0 0 0 0 0 0 0 0 1 2 0 0 0 0 1 0 2 0 0 0 0 1 2 0 1 2 0 1 1 0 1 0 2 2 0 1 1 1 1 0 1 0 1 0 0 0 1 0 0 0 1 0 0</counts>
			</dataPoints>
		</scan>
		<scan status="Completed" appendNumber="0" scanAxis="2Theta" mode="Continuous">
			<header>
				<startTimeStamp>2022-11-11T16:03:56-05:00</startTimeStamp>
				<endTimeStamp>2022-11-11T16:23:58-05:00</endTimeStamp>
				<author>
					<name>User</name>
				</author>
				<source>
					<applicationSoftware version="7.1">Data Collector</applicationSoftware>
					<instrumentControlSoftware version="8.2  20201204">EMPYREAN</instrumentControlSoftware>
					<instrumentID>0000000011260721</instrumentID>
				</source>
			</header>
			<dataPoints>
				<positions axis="2Theta" unit="deg">
					<startPosition>71.6721495304608</startPosition>
					<endPosition>75.0194193016773</endPosition>
				</positions>
				<positions axis="Omega" unit="deg">
					<commonPosition>18.3828922080345</commonPosition>
				</positions>
				<positions axis="Phi" unit="deg">
					<commonPosition>183.93</commonPosition>
				</positions>
				<positions axis="Chi" unit="deg">
					<commonPosition>0</commonPosition>
				</positions>
				<positions axis="Z" unit="mm">
					<commonPosition>8.387</commonPosition>
				</positions>
				<commonCountingTime unit="seconds">0.974</commonCountingTime>
				<counts unit="counts">1 1 1 1 1 0 1 0 1 0 0 1 0 0 3 0 0 0 0 0 0 0 0 1 0 0 0 0 0 0 0 1 1 0 0 0 0 0 0 1 0 0 0 1 1 0 0 0 2 1 1 0 2 0 0 0 0 0 0 0 0 2 2 0 0 0 0 0 0 3 0 1 0 0 0 0 1 1 4 3 0 0 0 0 0 4 1 2 1 1 0 1 0 0 0 0 0 0 1 1 0 1 0 0 0 2 1 0 2 1 0 0 0 1 0 1 1 1 0 0 0 1 1 1 1 0 1 1 0 1 2 1 0 2 1 2 0 0 0 0 0 0 0 0 1 0 0 1 0 0 0 0 5 0 0 0 0 1 0 1 0 0 0 0 0 1 1 1 0 1 3 7 5 5 3 0 0 2 1 1 1 0 0 0 1 1 0 0 0 1 0 0 1 1 0 0 0 1 0 0 0 0 2 1 0 2 1 0 1 1 0 1 2 1 0 0 0 0 0 1 2 1 0 1 1 1 0 1 1 0 0 0 0 0 0 2 0 1 0 0 0 1 1 2 1 2 1 1 0 1 0 1 3 0 0</counts>
			</dataPoints>
		</scan>
		<scan status="Completed" appendNumber="0" scanAxis="2Theta" mode="Continuous">
			<header>
				<startTimeStamp>2022-11-11T16:03:56-05:00</startTimeStamp>
				<endTimeStamp>2022-11-11T16:23:58-05:00</endTimeStamp>
				<author>
					<name>User</name>
				</author>
				<source>
					<applicationSoftware version="7.1">Data Collector</applicationSoftware>
					<instrumentControlSoftware version="8.2  20201204">EMPYREAN</instrumentControlSoftware>
					<instrumentID>0000000011260721</instrumentID>
				</source>
			</header>
			<dataPoints>
				<positions axis="2Theta" unit="deg">
					<startPosition>71.6754321011352</startPosition>
					<endPosition>75.0227018723517</endPosition>
				</positions>
				<positions axis="Omega" unit="deg">
					<commonPosition>18.3845334933717</commonPosition>
				</positions>
				<positions axis="Phi" unit="deg">
					<commonPosition>183.93</commonPosition>
				</positions>
				<positions axis="Chi" unit="deg">
					<commonPosition>0</commonPosition>
				</positions>
				<positions axis="Z" unit="mm">
					<commonPosition>8.387</commonPosition>
				</positions>
				<commonCountingTime unit="seconds">0.974</commonCountingTime>
				<counts unit="counts">0 0 0 0 0 1 1 1 0 1 1 1 1 2 1 0 0 0 0 0 1 1 0 0 0 1 0 0 1 1 0 0 0 0 0 2 0 1 1 2 0 2 0 0 0 0 0 0 0 0 0 0 1 0 0 0 1 1 0 0 1 0 2 0 0 0 0 0 1 0 2 1 1 1 1 0 0 0 0 0 0 0 0 0 0 0 2 0 1 0 1 1 0 1 0 1 0 0 0 0 0 2 2 1 2 1 0 2 0 0 0 1 3 0 0 0 0 1 0 0 2 1 3 0 1 2 1 1 0 0 0 0 0 0 0 0 2 0 0 2 1 0 1 0 0 0 0 1 1 0 1 1 2 0 0 1 0 1 1 0 0 1 0 0 1 0 1 0 2 1 0 3 5 5 2 1 0 1 0 1 2 0 1 0 1 1 1 0 1 3 1 0 0 1 0 0 0 1 1 0 0 0 1 0 0 0 0 1 0 1 0 0 0 1 1 1 1 1 1 1 4 0 0 0 0 0 2 0 0 0 0 1 1 0 0 1 0 0 1 0 6 0 0 1 0 0 0 0 0 0 0 0 0 0 1</counts>
			</dataPoints>
		</scan>
		<scan status="Completed" appendNumber="0" scanAxis="2Theta" mode="Continuous">
			<header>
				<startTimeStamp>2022-11-11T16:03:56-05:00</startTimeStamp>
				<endTimeStamp>2022-11-11T16:23:58-05:00</endTimeStamp>
				<author>
					<name>User</name>
				</author>
				<source>
					<applicationSoftware version="7.1">Data Collector</applicationSoftware>
					<instrumentControlSoftware version="8.2  20201204">EMPYREAN</instrumentControlSoftware>
					<instrumentID>0000000011260721</instrumentID>
				</source>
			</header>
			<dataPoints>
				<positions axis="2Theta" unit="deg">
					<startPosition>71.6787146718095</startPosition>
					<endPosition>75.025984443026</endPosition>
				</positions>
				<positions axis="Omega" unit="deg">
					<commonPosition>18.3861747787089</commonPosition>
				</positions>
				<positions axis="Phi" unit="deg">
					<commonPosition>183.93</commonPosition>
				</positions>
				<positions axis="Chi" unit="deg">
					<commonPosition>0</commonPosition>
				</positions>
				<positions axis="Z" unit="mm">
					<commonPosition>8.387</commonPosition>
				</positions>
				<commonCountingTime unit="seconds">0.974</commonCountingTime>
				<counts unit="counts">1 1 1 1 1 1 1 0 0 1 0 2 0 0 0 0 0 0 1 1 0 1 0 1 0 1 0 1 0 0 1 0 0 1 1 0 1 0 0 0 0 0 1 0 1 1 0 1 3 0 0 1 0 1 0 0 0 1 1 1 0 2 0 1 0 0 3 0 1 0 1 0 0 0 1 0 1 0 2 1 1 0 1 0 0 0 0 0 1 0 0 2 1 1 0 1 1 2 1 0 0 0 1 0 1 0 1 1 1 1 0 0 0 1 1 1 0 0 0 1 0 1 0 0 0 0 0 1 0 2 0 2 0 0 1 3 1 1 0 2 1 0 1 1 0 0 0 1 0 0 0 1 1 0 0 0 0 1 1 0 0 0 0 1 1 0 0 0 1 0 4 15 4 5 2 1 2 0 1 0 1 0 1 1 1 1 0 2 0 1 1 0 1 1 0 0 1 1 0 0 1 0 2 0 0 1 0 1 0 1 1 1 0 0 0 1 0 2 0 0 0 1 0 1 1 0 2 1 1 1 1 0 0 0 2 1 1 2 3 0 0 0 1 2 1 2 1 1 0 0 1 2 1 1 1</counts>
			</dataPoints>
		</scan>
		<scan status="Completed" appendNumber="0" scanAxis="2Theta" mode="Continuous">
			<header>
				<startTimeStamp>2022-11-11T16:03:56-05:00</startTimeStamp>
				<endTimeStamp>2022-11-11T16:23:58-05:00</endTimeStamp>
				<author>
					<name>User</name>
				</author>
				<source>
					<applicationSoftware version="7.1">Data Collector</applicationSoftware>
					<instrumentControlSoftware version="8.2  20201204">EMPYREAN</instrumentControlSoftware>
					<instrumentID>0000000011260721</instrumentID>
				</source>
			</header>
			<dataPoints>
				<positions axis="2Theta" unit="deg">
					<startPosition>71.6819972424839</startPosition>
					<endPosition>75.0292670137003</endPosition>
				</positions>
				<positions axis="Omega" unit="deg">
					<commonPosition>18.3878160640461</commonPosition>
				</positions>
				<positions axis="Phi" unit="deg">
					<commonPosition>183.93</commonPosition>
				</positions>
				<positions axis="Chi" unit="deg">
					<commonPosition>0</commonPosition>
				</positions>
				<positions axis="Z" unit="mm">
					<commonPosition>8.387</commonPosition>
				</positions>
				<commonCountingTime unit="seconds">0.974</commonCountingTime>
				<counts unit="counts">0 0 1 0 1 1 0 0 0 1 0 3 0 0 1 2 0 0 0 0 0 1 0 1 0 0 0 0 0 1 1 0 0 0 0 1 0 0 0 1 1 1 2 1 1 0 0 0 1 0 0 0 0 1 0 1 0 1 0 0 0 0 1 2 1 0 0 1 0 0 0 1 0 0 2 0 0 0 0 1 1 0 3 0 0 0 0 0 0 1 0 0 0 1 0 1 0 2 1 0 1 0 0 1 1 0 2 0 1 0 1 0 0 0 1 2 1 0 0 1 2 0 0 1 0 0 0 0 1 0 1 0 1 1 0 0 1 1 1 1 0 0 3 0 0 1 0 0 0 0 0 0 2 0 0 1 0 0 0 2 0 1 0 0 1 0 1 0 1 1 2 2 2 6 1 0 1 6 1 1 0 1 0 0 0 1 0 0 0 2 0 1 1 1 0 0 0 1 2 1 0 1 0 0 1 0 0 1 0 0 0 0 0 0 0 1 0 0 0 1 1 1 0 0 0 0 0 1 0 1 1 2 0 0 0 2 1 0 0 0 0 2 0 1 0 0 1 0 0 0 1 2 0 1 0</counts>
			</dataPoints>
		</scan>
		<scan status="Completed" appendNumber="0" scanAxis="2Theta" mode="Continuous">
			<header>
				<startTimeStamp>2022-11-11T16:03:56-05:00</startTimeStamp>
				<endTimeStamp>2022-11-11T16:23:58-05:00</endTimeStamp>
				<author>
					<name>User</name>
				</author>
				<source>
					<applicationSoftware version="7.1">Data Collector</applicationSoftware>
					<instrumentControlSoftware version="8.2  20201204">EMPYREAN</instrumentControlSoftware>
					<instrumentID>0000000011260721</instrumentID>
				</source>
			</header>
			<dataPoints>
				<positions axis="2Theta" unit="deg">
					<startPosition>71.6852798131582</startPosition>
					<endPosition>75.0325495843747</endPosition>
				</positions>
				<positions axis="Omega" unit="deg">
					<commonPosition>18.3894573493832</commonPosition>
				</positions>
				<positions axis="Phi" unit="deg">
					<commonPosition>183.93</commonPosition>
				</positions>
				<positions axis="Chi" unit="deg">
					<commonPosition>0</commonPosition>
				</positions>
				<positions axis="Z" unit="mm">
					<commonPosition>8.387</commonPosition>
				</positions>
				<commonCountingTime unit="seconds">0.974</commonCountingTime>
				<counts unit="counts">0 0 1 1 1 1 1 0 0 1 1 0 0 0 1 1 0 1 0 2 0 0 0 1 0 0 1 0 0 0 0 1 0 0 0 0 0 1 0 1 1 0 0 0 0 0 0 1 0 1 1 1 1 1 0 1 0 0 0 0 0 0 0 2 1 0 0 1 1 1 0 0 1 0 1 0 1 0 1 1 1 2 0 0 2 0 0 1 0 1 1 0 0 1 0 0 2 1 0 0 0 0 0 0 0 0 0 3 3 0 2 1 1 0 0 0 0 0 0 1 1 0 0 1 0 1 1 1 0 0 2 0 0 0 0 0 0 0 1 0 2 0 2 2 0 1 0 0 0 1 0 0 1 1 0 0 0 1 2 1 1 1 0 0 1 0 2 0 1 6 4 5 3 5 2 2 1 0 1 0 0 0 0 0 0 2 0 1 0 2 0 0 0 1 0 2 0 0 0 1 0 1 1 1 0 0 0 0 0 1 0 0 1 1 0 1 0 1 0 1 0 0 0 2 1 0 0 0 0 1 0 0 0 1 0 2 1 0 0 0 2 1 0 1 0 1 1 0 1 1 1 1 3 0 2</counts>
			</dataPoints>
		</scan>
		<scan status="Completed" appendNumber="0" scanAxis="2Theta" mode="Continuous">
			<header>
				<startTimeStamp>2022-11-11T16:03:56-05:00</startTimeStamp>
				<endTimeStamp>2022-11-11T16:23:58-05:00</endTimeStamp>
				<author>
					<name>User</name>
				</author>
				<source>
					<applicationSoftware version="7.1">Data Collector</applicationSoftware>
					<instrumentControlSoftware version="8.2  20201204">EMPYREAN</instrumentControlSoftware>
					<instrumentID>0000000011260721</instrumentID>
				</source>
			</header>
			<dataPoints>
				<positions axis="2Theta" unit="deg">
					<startPosition>71.6885623838326</startPosition>
					<endPosition>75.035832155049</endPosition>
				</positions>
				<positions axis="Omega" unit="deg">
					<commonPosition>18.3910986347204</commonPosition>
				</positions>
				<positions axis="Phi" unit="deg">
					<commonPosition>183.93</commonPosition>
				</positions>
				<positions axis="Chi" unit="deg">
					<commonPosition>0</commonPosition>
				</positions>
				<positions axis="Z" unit="mm">
					<commonPosition>8.387</commonPosition>
				</positions>
				<commonCountingTime unit="seconds">0.974</commonCountingTime>
				<counts unit="counts">0 0 0 0 1 0 1 1 1 0 1 1 0 1 0 0 0 0 1 0 2 1 1 0 0 0 1 1 1 2 1 1 1 1 0 0 0 2 1 1 0 1 1 1 1 1 0 0 1 0 1 0 1 4 0 2 1 0 0 0 0 1 0 1 1 0 0 1 0 0 0 2 1 0 1 2 0 1 1 0 0 0 0 2 1 1 0 0 0 0 1 0 0 0 1 0 0 0 0 0 1 0 0 0 1 0 1 1 0 0 0 1 1 0 2 1 0 0 0 0 0 0 1 1 2 0 1 0 2 0 0 0 0 0 0 2 0 0 1 1 0 2 1 1 0 0 2 0 0 1 0 0 0 2 1 3 0 1 0 1 0 0 2 1 2 1 1 1 1 2 4 6 6 8 2 1 1 0 3 3 1 0 1 1 1 0 0 1 1 1 2 1 0 0 0 1 0 1 0 0 0 1 1 0 1 1 1 2 0 0 0 1 2 1 0 0 0 1 0 0 1 0 1 1 0 1 0 0 0 1 2 0 0 0 1 0 0 0 1 0 0 1 1 0 0 0 0 0 0 1 1 0 1 1 1</counts>
			</dataPoints>
		</scan>
		<scan status="Completed" appendNumber="0" scanAxis="2Theta" mode="Continuous">
			<header>
				<startTimeStamp>2022-11-11T16:03:56-05:00</startTimeStamp>
				<endTimeStamp>2022-11-11T16:23:58-05:00</endTimeStamp>
				<author>
					<name>User</name>
				</author>
				<source>
					<applicationSoftware version="7.1">Data Collector</applicationSoftware>
					<instrumentControlSoftware version="8.2  20201204">EMPYREAN</instrumentControlSoftware>
					<instrumentID>0000000011260721</instrumentID>
				</source>
			</header>
			<dataPoints>
				<positions axis="2Theta" unit="deg">
					<startPosition>71.6918449545069</startPosition>
					<endPosition>75.0391147257234</endPosition>
				</positions>
				<positions axis="Omega" unit="deg">
					<commonPosition>18.3927399200576</commonPosition>
				</positions>
				<positions axis="Phi" unit="deg">
					<commonPosition>183.93</commonPosition>
				</positions>
				<positions axis="Chi" unit="deg">
					<commonPosition>0</commonPosition>
				</positions>
				<positions axis="Z" unit="mm">
					<commonPosition>8.387</commonPosition>
				</positions>
				<commonCountingTime unit="seconds">0.974</commonCountingTime>
				<counts unit="counts">0 0 1 0 0 1 1 1 0 1 0 0 1 0 0 1 1 0 3 0 0 1 2 1 0 1 1 2 0 1 0 0 0 1 0 0 1 0 0 2 0 0 1 0 0 0 0 0 0 0 0 1 0 1 0 1 0 0 0 0 1 2 0 2 1 1 0 1 0 0 0 2 0 0 1 2 1 1 1 2 0 0 0 1 0 0 0 0 4 1 1 2 1 0 0 0 0 1 0 1 1 0 1 0 0 0 1 0 0 1 0 1 0 1 1 0 1 1 0 1 0 1 1 0 0 0 0 0 1 0 0 0 2 0 0 0 0 0 1 0 0 0 0 1 1 0 0 0 0 1 1 1 1 0 0 0 1 1 1 1 0 0 0 0 0 0 1 2 2 2 2 3 4 7 1 1 0 0 2 2 1 0 1 1 1 1 0 0 0 0 0 0 0 1 1 0 0 1 1 1 0 0 2 1 0 2 0 0 0 0 0 0 1 1 1 0 1 1 0 0 0 1 0 0 0 0 0 2 1 0 0 1 0 1 1 0 0 0 0 1 0 1 0 0 0 1 0 1 0 1 1 1 0 0 0</counts>
			</dataPoints>
		</scan>
		<scan status="Completed" appendNumber="0" scanAxis="2Theta" mode="Continuous">
			<header>
				<startTimeStamp>2022-11-11T16:03:56-05:00</startTimeStamp>
				<endTimeStamp>2022-11-11T16:23:58-05:00</endTimeStamp>
				<author>
					<name>User</name>
				</author>
				<source>
					<applicationSoftware version="7.1">Data Collector</applicationSoftware>
					<instrumentControlSoftware version="8.2  20201204">EMPYREAN</instrumentControlSoftware>
					<instrumentID>0000000011260721</instrumentID>
				</source>
			</header>
			<dataPoints>
				<positions axis="2Theta" unit="deg">
					<startPosition>71.6951275251812</startPosition>
					<endPosition>75.0423972963977</endPosition>
				</positions>
				<positions axis="Omega" unit="deg">
					<commonPosition>18.3943812053947</commonPosition>
				</positions>
				<positions axis="Phi" unit="deg">
					<commonPosition>183.93</commonPosition>
				</positions>
				<positions axis="Chi" unit="deg">
					<commonPosition>0</commonPosition>
				</positions>
				<positions axis="Z" unit="mm">
					<commonPosition>8.387</commonPosition>
				</positions>
				<commonCountingTime unit="seconds">0.974</commonCountingTime>
				<counts unit="counts">0 1 0 0 0 0 0 2 0 2 0 2 0 0 0 0 0 2 0 1 0 0 1 0 2 1 0 0 2 0 2 2 0 1 0 0 0 0 0 2 0 0 0 2 1 0 0 0 0 1 0 0 1 0 0 2 1 1 0 1 0 0 1 0 1 1 1 0 1 0 1 0 1 0 1 1 0 0 0 1 1 1 2 1 0 1 0 0 1 4 1 1 0 0 0 0 1 0 0 1 0 2 2 1 0 0 1 0 1 0 1 2 0 0 0 1 1 0 0 0 0 0 0 1 1 1 0 0 1 0 1 0 3 2 1 1 1 0 0 1 1 4 1 0 4 1 0 1 1 0 1 0 0 1 1 1 0 0 0 0 1 2 0 1 2 0 0 0 1 4 6 9 8 5 1 0 4 3 0 0 0 0 0 0 1 0 1 1 0 1 2 0 0 2 0 0 3 0 0 2 0 2 0 2 0 0 0 0 0 0 1 0 1 1 1 2 0 1 2 0 0 2 1 0 2 3 1 0 0 1 1 0 1 1 0 2 2 0 1 0 1 1 1 0 0 0 1 0 0 0 1 1 1 0 1</counts>
			</dataPoints>
		</scan>
		<scan status="Completed" appendNumber="0" scanAxis="2Theta" mode="Continuous">
			<header>
				<startTimeStamp>2022-11-11T16:03:56-05:00</startTimeStamp>
				<endTimeStamp>2022-11-11T16:23:58-05:00</endTimeStamp>
				<author>
					<name>User</name>
				</author>
				<source>
					<applicationSoftware version="7.1">Data Collector</applicationSoftware>
					<instrumentControlSoftware version="8.2  20201204">EMPYREAN</instrumentControlSoftware>
					<instrumentID>0000000011260721</instrumentID>
				</source>
			</header>
			<dataPoints>
				<positions axis="2Theta" unit="deg">
					<startPosition>71.6984100958556</startPosition>
					<endPosition>75.0456798670721</endPosition>
				</positions>
				<positions axis="Omega" unit="deg">
					<commonPosition>18.3960224907319</commonPosition>
				</positions>
				<positions axis="Phi" unit="deg">
					<commonPosition>183.93</commonPosition>
				</positions>
				<positions axis="Chi" unit="deg">
					<commonPosition>0</commonPosition>
				</positions>
				<positions axis="Z" unit="mm">
					<commonPosition>8.387</commonPosition>
				</positions>
				<commonCountingTime unit="seconds">0.974</commonCountingTime>
				<counts unit="counts">0 1 2 0 1 2 0 2 1 1 0 2 0 0 0 0 0 0 1 0 0 0 0 1 2 1 0 1 0 2 1 0 1 0 1 0 1 1 2 0 0 0 0 0 0 1 1 0 0 1 0 1 0 1 1 0 0 0 0 1 1 1 1 1 1 0 1 4 0 0 0 0 0 0 1 1 0 0 0 1 0 2 1 2 1 0 0 2 2 0 0 1 2 0 1 1 0 1 0 0 0 0 0 0 0 1 1 1 1 1 2 1 0 1 0 0 1 1 1 0 0 1 1 0 0 1 0 2 0 0 1 0 0 1 0 1 0 0 0 0 0 0 0 0 0 0 0 1 0 1 0 0 0 1 3 0 1 0 2 1 0 1 2 0 0 1 0 1 1 2 5 5 7 2 0 0 3 0 0 1 0 0 3 2 0 0 1 0 0 2 1 1 0 1 0 0 1 0 1 3 0 1 0 3 0 0 0 1 0 0 0 0 1 2 0 0 0 1 1 0 1 0 2 0 0 0 1 0 0 0 2 1 1 2 1 0 0 0 1 1 1 1 0 2 3 1 0 1 0 0 0 2 0 0 0</counts>
			</dataPoints>
		</scan>
		<scan status="Completed" appendNumber="0" scanAxis="2Theta" mode="Continuous">
			<header>
				<startTimeStamp>2022-11-11T16:03:56-05:00</startTimeStamp>
				<endTimeStamp>2022-11-11T16:23:58-05:00</endTimeStamp>
				<author>
					<name>User</name>
				</author>
				<source>
					<applicationSoftware version="7.1">Data Collector</applicationSoftware>
					<instrumentControlSoftware version="8.2  20201204">EMPYREAN</instrumentControlSoftware>
					<instrumentID>0000000011260721</instrumentID>
				</source>
			</header>
			<dataPoints>
				<positions axis="2Theta" unit="deg">
					<startPosition>71.7016926665299</startPosition>
					<endPosition>75.0489624377464</endPosition>
				</positions>
				<positions axis="Omega" unit="deg">
					<commonPosition>18.3976637760691</commonPosition>
				</positions>
				<positions axis="Phi" unit="deg">
					<commonPosition>183.93</commonPosition>
				</positions>
				<positions axis="Chi" unit="deg">
					<commonPosition>0</commonPosition>
				</positions>
				<positions axis="Z" unit="mm">
					<commonPosition>8.387</commonPosition>
				</positions>
				<commonCountingTime unit="seconds">0.974</commonCountingTime>
				<counts unit="counts">1 0 0 0 1 2 0 0 2 1 0 0 1 0 1 0 1 1 0 1 0 0 1 2 0 1 0 0 0 1 1 0 0 0 0 1 1 0 0 2 1 0 0 1 0 2 0 0 2 1 1 1 0 2 2 1 0 0 0 0 2 0 0 1 0 0 0 0 1 0 0 0 0 0 1 0 2 0 0 1 0 1 0 2 1 0 0 1 0 1 0 1 0 1 0 0 2 0 0 0 0 1 0 0 0 1 0 1 1 1 0 1 0 0 0 1 0 0 2 0 2 1 0 2 2 0 2 1 0 0 0 0 0 1 0 0 0 1 1 0 0 1 2 0 0 3 0 1 2 0 1 0 1 0 0 0 0 1 1 2 0 0 0 0 0 0 0 0 0 5 8 8 8 5 2 1 1 0 0 1 2 1 0 0 3 1 0 0 0 1 0 0 0 0 1 0 1 1 0 0 1 0 2 0 4 0 1 0 0 3 0 0 1 1 1 0 0 0 1 3 1 0 0 2 0 0 0 2 0 0 0 0 1 1 1 1 1 2 0 1 1 1 1 0 0 1 0 4 1 1 0 0 1 2 0</counts>
			</dataPoints>
		</scan>
		<scan status="Completed" appendNumber="0" scanAxis="2Theta" mode="Continuous">
			<header>
				<startTimeStamp>2022-11-11T16:03:56-05:00</startTimeStamp>
				<endTimeStamp>2022-11-11T16:23:58-05:00</endTimeStamp>
				<author>
					<name>User</name>
				</author>
				<source>
					<applicationSoftware version="7.1">Data Collector</applicationSoftware>
					<instrumentControlSoftware version="8.2  20201204">EMPYREAN</instrumentControlSoftware>
					<instrumentID>0000000011260721</instrumentID>
				</source>
			</header>
			<dataPoints>
				<positions axis="2Theta" unit="deg">
					<startPosition>71.7049752372043</startPosition>
					<endPosition>75.0522450084207</endPosition>
				</positions>
				<positions axis="Omega" unit="deg">
					<commonPosition>18.3993050614063</commonPosition>
				</positions>
				<positions axis="Phi" unit="deg">
					<commonPosition>183.93</commonPosition>
				</positions>
				<positions axis="Chi" unit="deg">
					<commonPosition>0</commonPosition>
				</positions>
				<positions axis="Z" unit="mm">
					<commonPosition>8.387</commonPosition>
				</positions>
				<commonCountingTime unit="seconds">0.974</commonCountingTime>
				<counts unit="counts">0 0 0 0 0 0 2 1 0 0 1 1 1 1 0 0 1 0 0 2 1 0 0 1 1 0 0 1 1 0 0 0 0 0 0 1 0 0 0 1 0 1 0 1 0 0 0 0 0 2 2 0 0 1 1 0 1 0 0 0 0 0 1 0 1 1 2 0 0 0 1 0 1 1 2 0 1 0 2 0 1 0 1 0 2 1 0 0 0 1 0 0 0 1 0 1 0 0 1 0 0 1 0 0 1 1 2 0 0 0 0 1 0 0 0 2 3 1 3 0 0 1 0 1 0 0 0 0 1 0 1 1 2 0 0 0 0 0 2 1 1 0 1 1 0 0 0 0 0 1 1 2 0 0 0 0 0 0 1 0 0 0 0 0 0 0 1 2 1 1 3 8 5 7 3 1 2 0 0 1 1 1 0 2 0 0 1 0 0 1 1 1 0 1 0 0 1 0 0 0 1 0 0 0 1 1 0 3 0 2 2 0 0 1 1 0 2 0 0 0 1 1 1 0 0 1 1 2 1 1 0 1 0 3 1 0 0 2 2 2 2 0 0 2 1 1 0 0 0 0 0 1 3 0 1</counts>
			</dataPoints>
		</scan>
		<scan status="Completed" appendNumber="0" scanAxis="2Theta" mode="Continuous">
			<header>
				<startTimeStamp>2022-11-11T16:03:56-05:00</startTimeStamp>
				<endTimeStamp>2022-11-11T16:23:58-05:00</endTimeStamp>
				<author>
					<name>User</name>
				</author>
				<source>
					<applicationSoftware version="7.1">Data Collector</applicationSoftware>
					<instrumentControlSoftware version="8.2  20201204">EMPYREAN</instrumentControlSoftware>
					<instrumentID>0000000011260721</instrumentID>
				</source>
			</header>
			<dataPoints>
				<positions axis="2Theta" unit="deg">
					<startPosition>71.7082578078786</startPosition>
					<endPosition>75.0555275790951</endPosition>
				</positions>
				<positions axis="Omega" unit="deg">
					<commonPosition>18.4009463467434</commonPosition>
				</positions>
				<positions axis="Phi" unit="deg">
					<commonPosition>183.93</commonPosition>
				</positions>
				<positions axis="Chi" unit="deg">
					<commonPosition>0</commonPosition>
				</positions>
				<positions axis="Z" unit="mm">
					<commonPosition>8.387</commonPosition>
				</positions>
				<commonCountingTime unit="seconds">0.974</commonCountingTime>
[...]
					<commonPosition>0</commonPosition>
				</positions>
				<positions axis="Z" unit="mm">
					<commonPosition>8.387</commonPosition>
				</positions>
				<commonCountingTime unit="seconds">0.974</commonCountingTime>
				<counts unit="counts">0 1 0 0 0 0 0 0 0 0 0 2 1 3 0 2 1 2 0 0 1 0 1 0 0 0 0 1 0 0 0 0 1 0 0 0 0 0 0 0 1 1 0 1 1 0 0 3 1 2 1 1 0 0 2 0 1 0 0 1 1 0 0 3 1 2 1 0 0 0 0 1 1 1 0 1 0 0 1 1 3 1 0 0 0 2 1 0 2 0 1 0 1 0 1 1 0 0 2 1 0 1 0 0 0 1 1 0 0 0 0 3 1 1 1 1 0 0 1 1 0 0 1 1 0 1 2 0 1 0 1 0 0 0 0 0 0 0 1 0 1 0 1 0 0 1 0 0 1 1 0 1 1 1 0 0 0 0 1 1 1 1 1 1 0 0 0 0 1 0 2 1 0 1 0 0 0 1 0 1 1 0 0 1 1 1 0 0 0 1 0 1 0 1 0 0 0 0 1 0 0 2 1 0 1 0 0 1 0 0 1 0 0 1 1 1 1 1 0 1 0 0 1 1 0 0 0 0 0 2 0 1 1 1 0 1 1 0 1 0 1 1 0 0 1 0 2 0 2 0 1 0 1 0 1</counts>
			</dataPoints>
		</scan>
		<scan status="Completed" appendNumber="0" scanAxis="2Theta" mode="Continuous">
			<header>
				<startTimeStamp>2022-11-11T16:03:56-05:00</startTimeStamp>
				<endTimeStamp>2022-11-11T16:23:58-05:00</endTimeStamp>
				<author>
					<name>User</name>
				</author>
				<source>
					<applicationSoftware version="7.1">Data Collector</applicationSoftware>
					<instrumentControlSoftware version="8.2  20201204">EMPYREAN</instrumentControlSoftware>
					<instrumentID>0000000011260721</instrumentID>
				</source>
			</header>
			<dataPoints>
				<positions axis="2Theta" unit="deg">
					<startPosition>75.6013866276483</startPosition>
					<endPosition>78.9486563988648</endPosition>
				</positions>
				<positions axis="Omega" unit="deg">
					<commonPosition>20.3475107566283</commonPosition>
				</positions>
				<positions axis="Phi" unit="deg">
					<commonPosition>183.93</commonPosition>
				</positions>
				<positions axis="Chi" unit="deg">
					<commonPosition>0</commonPosition>
				</positions>
				<positions axis="Z" unit="mm">
					<commonPosition>8.387</commonPosition>
				</positions>
				<commonCountingTime unit="seconds">0.974</commonCountingTime>
				<counts unit="counts">3 0 1 0 0 0 0 1 0 4 0 0 0 0 0 0 0 0 0 0 1 0 0 2 0 1 0 1 0 0 0 0 0 1 1 1 0 0 2 3 0 0 1 0 0 1 3 0 0 0 0 0 0 1 0 0 0 1 0 0 1 0 0 1 2 1 1 0 1 2 2 2 0 1 1 0 1 0 0 0 1 1 1 1 0 2 0 0 2 1 1 0 1 3 1 0 0 1 1 1 2 0 1 0 0 0 0 0 0 0 0 0 0 0 0 0 2 0 0 2 1 0 0 0 1 0 0 0 0 0 0 0 0 2 1 2 0 0 0 0 0 0 1 2 1 1 0 0 1 0 0 1 1 1 1 0 1 0 0 1 1 0 1 0 0 0 1 0 0 1 1 1 0 2 2 0 0 0 0 1 0 1 0 0 0 0 0 1 1 1 1 2 1 0 1 0 0 0 0 0 0 0 1 0 0 1 3 1 0 0 0 0 0 1 2 0 0 1 0 1 0 1 0 2 0 0 0 0 2 0 0 1 0 0 1 0 0 0 0 1 0 0 1 2 0 0 1 0 1 0 0 0 0 1 1</counts>
			</dataPoints>
		</scan>
		<scan status="Completed" appendNumber="0" scanAxis="2Theta" mode="Continuous">
			<header>
				<startTimeStamp>2022-11-11T16:03:56-05:00</startTimeStamp>
				<endTimeStamp>2022-11-11T16:23:58-05:00</endTimeStamp>
				<author>
					<name>User</name>
				</author>
				<source>
					<applicationSoftware version="7.1">Data Collector</applicationSoftware>
					<instrumentControlSoftware version="8.2  20201204">EMPYREAN</instrumentControlSoftware>
					<instrumentID>0000000011260721</instrumentID>
				</source>
			</header>
			<dataPoints>
				<positions axis="2Theta" unit="deg">
					<startPosition>75.6046691983227</startPosition>
					<endPosition>78.9519389695392</endPosition>
				</positions>
				<positions axis="Omega" unit="deg">
					<commonPosition>20.3491520419655</commonPosition>
				</positions>
				<positions axis="Phi" unit="deg">
					<commonPosition>183.93</commonPosition>
				</positions>
				<positions axis="Chi" unit="deg">
					<commonPosition>0</commonPosition>
				</positions>
				<positions axis="Z" unit="mm">
					<commonPosition>8.387</commonPosition>
				</positions>
				<commonCountingTime unit="seconds">0.974</commonCountingTime>
				<counts unit="counts">2 2 0 1 0 0 2 1 0 1 1 0 0 1 0 0 0 0 1 0 0 1 1 2 2 1 0 3 0 0 1 0 0 0 0 0 1 1 1 2 1 1 1 1 0 1 0 0 0 3 1 1 0 1 0 1 1 2 0 1 0 0 1 1 0 0 1 0 0 0 1 0 2 1 1 1 0 1 0 0 0 0 1 0 3 0 0 0 0 0 3 3 2 1 0 0 0 2 1 1 0 1 0 0 0 0 0 3 1 0 0 0 0 0 1 1 0 0 0 0 0 0 0 2 0 1 2 1 0 0 2 0 0 1 1 0 0 2 1 0 1 0 0 1 0 0 0 0 0 0 0 2 3 0 2 0 3 1 1 1 0 0 2 1 0 0 0 0 1 1 0 0 1 0 0 0 1 1 1 2 0 0 0 1 1 2 2 0 0 0 0 1 0 0 0 0 0 1 2 1 1 1 1 0 2 1 0 0 1 1 0 1 0 0 1 0 0 0 0 1 1 1 0 2 0 2 1 2 1 0 0 0 0 1 1 1 1 2 1 0 0 0 0 0 0 0 1 0 0 2 0 0 0 0 1</counts>
			</dataPoints>
		</scan>
		<scan status="Completed" appendNumber="0" scanAxis="2Theta" mode="Continuous">
			<header>
				<startTimeStamp>2022-11-11T16:03:56-05:00</startTimeStamp>
				<endTimeStamp>2022-11-11T16:23:58-05:00</endTimeStamp>
				<author>
					<name>User</name>
				</author>
				<source>
					<applicationSoftware version="7.1">Data Collector</applicationSoftware>
					<instrumentControlSoftware version="8.2  20201204">EMPYREAN</instrumentControlSoftware>
					<instrumentID>0000000011260721</instrumentID>
				</source>
			</header>
			<dataPoints>
				<positions axis="2Theta" unit="deg">
					<startPosition>75.607951768997</startPosition>
					<endPosition>78.9552215402135</endPosition>
				</positions>
				<positions axis="Omega" unit="deg">
					<commonPosition>20.3507933273026</commonPosition>
				</positions>
				<positions axis="Phi" unit="deg">
					<commonPosition>183.93</commonPosition>
				</positions>
				<positions axis="Chi" unit="deg">
					<commonPosition>0</commonPosition>
				</positions>
				<positions axis="Z" unit="mm">
					<commonPosition>8.387</commonPosition>
				</positions>
				<commonCountingTime unit="seconds">0.974</commonCountingTime>
				<counts unit="counts">0 0 1 1 1 1 2 1 1 0 0 1 0 0 0 1 0 2 0 0 1 0 0 0 2 3 0 0 0 0 0 2 0 1 1 0 0 1 0 2 0 1 0 1 0 1 2 1 2 0 0 1 0 0 0 1 1 0 0 2 1 2 0 1 0 1 1 1 0 1 1 0 0 0 0 0 0 2 2 1 2 1 0 1 1 4 1 1 2 0 1 1 0 0 1 1 1 1 0 2 3 0 0 0 0 0 0 1 2 2 1 0 0 0 0 1 0 0 0 0 1 0 1 0 0 0 0 1 0 2 0 2 0 0 0 0 1 0 0 0 0 0 0 0 0 1 0 0 0 0 0 1 0 0 0 1 0 0 1 2 3 1 1 0 2 0 0 0 0 1 0 2 0 1 0 0 2 0 1 1 0 0 1 0 0 0 0 0 0 0 0 2 1 0 0 0 0 0 1 1 1 1 0 0 0 1 0 0 0 0 0 0 0 3 1 0 1 1 1 2 1 0 0 0 0 0 1 0 1 0 0 0 0 2 0 0 0 1 1 2 0 1 0 1 2 0 0 1 0 1 0 1 2 0 0</counts>
			</dataPoints>
		</scan>
		<scan status="Completed" appendNumber="0" scanAxis="2Theta" mode="Continuous">
			<header>
				<startTimeStamp>2022-11-11T16:03:56-05:00</startTimeStamp>
				<endTimeStamp>2022-11-11T16:23:58-05:00</endTimeStamp>
				<author>
					<name>User</name>
				</author>
				<source>
					<applicationSoftware version="7.1">Data Collector</applicationSoftware>
					<instrumentControlSoftware version="8.2  20201204">EMPYREAN</instrumentControlSoftware>
					<instrumentID>0000000011260721</instrumentID>
				</source>
			</header>
			<dataPoints>
				<positions axis="2Theta" unit="deg">
					<startPosition>75.6112343396714</startPosition>
					<endPosition>78.9585041108878</endPosition>
				</positions>
				<positions axis="Omega" unit="deg">
					<commonPosition>20.3524346126398</commonPosition>
				</positions>
				<positions axis="Phi" unit="deg">
					<commonPosition>183.93</commonPosition>
				</positions>
				<positions axis="Chi" unit="deg">
					<commonPosition>0</commonPosition>
				</positions>
				<positions axis="Z" unit="mm">
					<commonPosition>8.387</commonPosition>
				</positions>
				<commonCountingTime unit="seconds">0.974</commonCountingTime>
				<counts unit="counts">2 1 0 1 1 0 1 0 1 1 1 0 1 0 0 1 0 0 1 1 0 0 1 1 0 0 0 0 1 0 0 0 0 0 2 0 1 0 0 0 0 1 0 0 0 0 0 0 0 3 1 0 0 2 0 0 0 0 1 0 0 0 1 0 1 0 0 0 0 0 0 1 2 0 0 1 0 1 0 0 0 0 1 0 0 0 2 1 0 0 0 0 0 1 0 0 0 2 1 0 0 1 2 0 0 0 1 1 0 0 0 2 0 1 1 2 0 0 0 2 0 0 2 1 0 0 1 0 0 1 0 0 0 2 0 1 1 1 1 2 0 2 0 0 0 0 2 0 0 0 0 1 0 2 0 0 1 3 0 2 1 1 1 0 0 0 1 1 0 1 1 0 1 0 0 0 1 0 0 0 0 0 1 0 0 0 1 0 0 0 1 0 0 1 0 0 0 2 1 0 0 0 0 1 1 1 0 0 0 0 1 0 1 1 0 0 0 1 1 0 0 0 0 1 2 1 1 1 0 0 0 0 1 1 0 0 0 0 0 1 2 0 1 1 0 0 1 0 1 1 1 0 0 1 1</counts>
			</dataPoints>
		</scan>
		<scan status="Completed" appendNumber="0" scanAxis="2Theta" mode="Continuous">
			<header>
				<startTimeStamp>2022-11-11T16:03:56-05:00</startTimeStamp>
				<endTimeStamp>2022-11-11T16:23:58-05:00</endTimeStamp>
				<author>
					<name>User</name>
				</author>
				<source>
					<applicationSoftware version="7.1">Data Collector</applicationSoftware>
					<instrumentControlSoftware version="8.2  20201204">EMPYREAN</instrumentControlSoftware>
					<instrumentID>0000000011260721</instrumentID>
				</source>
			</header>
			<dataPoints>
				<positions axis="2Theta" unit="deg">
					<startPosition>75.6145169103457</startPosition>
					<endPosition>78.9617866815622</endPosition>
				</positions>
				<positions axis="Omega" unit="deg">
					<commonPosition>20.354075897977</commonPosition>
				</positions>
				<positions axis="Phi" unit="deg">
					<commonPosition>183.93</commonPosition>
				</positions>
				<positions axis="Chi" unit="deg">
					<commonPosition>0</commonPosition>
				</positions>
				<positions axis="Z" unit="mm">
					<commonPosition>8.387</commonPosition>
				</positions>
				<commonCountingTime unit="seconds">0.974</commonCountingTime>
				<counts unit="counts">0 2 1 0 0 1 0 1 1 2 0 1 0 0 1 1 1 0 0 1 0 0 0 0 0 1 0 0 0 1 0 0 0 1 0 0 0 0 0 1 0 1 1 1 1 0 1 0 1 0 0 0 0 2 0 2 0 0 0 1 1 0 1 0 1 0 3 0 1 1 0 0 0 0 1 0 0 0 0 1 0 1 5 1 1 2 1 0 0 0 0 0 2 0 2 0 0 0 1 0 0 0 1 0 0 0 0 1 0 0 3 1 0 0 2 0 2 0 0 0 0 1 1 0 1 0 0 0 1 0 0 0 1 2 0 1 1 3 0 0 0 0 0 1 0 0 1 1 0 0 0 0 1 0 0 0 0 0 2 1 0 0 0 3 1 0 0 2 0 0 0 0 3 1 0 0 1 1 0 0 1 0 1 0 1 1 1 2 0 0 2 1 0 1 1 0 0 1 1 0 0 0 2 0 0 2 0 3 2 1 0 1 1 0 0 1 1 0 1 1 0 1 0 0 0 1 0 0 0 2 2 1 0 0 0 2 1 0 1 0 1 0 0 0 0 0 0 0 0 1 1 0 0 0 0</counts>
			</dataPoints>
		</scan>
		<scan status="Completed" appendNumber="0" scanAxis="2Theta" mode="Continuous">
			<header>
				<startTimeStamp>2022-11-11T16:03:56-05:00</startTimeStamp>
				<endTimeStamp>2022-11-11T16:23:58-05:00</endTimeStamp>
				<author>
					<name>User</name>
				</author>
				<source>
					<applicationSoftware version="7.1">Data Collector</applicationSoftware>
					<instrumentControlSoftware version="8.2  20201204">EMPYREAN</instrumentControlSoftware>
					<instrumentID>0000000011260721</instrumentID>
				</source>
			</header>
			<dataPoints>
				<positions axis="2Theta" unit="deg">
					<startPosition>75.6177994810201</startPosition>
					<endPosition>78.9650692522365</endPosition>
				</positions>
				<positions axis="Omega" unit="deg">
					<commonPosition>20.3557171833141</commonPosition>
				</positions>
				<positions axis="Phi" unit="deg">
					<commonPosition>183.93</commonPosition>
				</positions>
				<positions axis="Chi" unit="deg">
					<commonPosition>0</commonPosition>
				</positions>
				<positions axis="Z" unit="mm">
					<commonPosition>8.387</commonPosition>
				</positions>
				<commonCountingTime unit="seconds">0.974</commonCountingTime>
				<counts unit="counts">1 0 0 2 2 1 1 1 0 1 0 1 0 0 1 1 1 1 0 1 3 1 1 1 2 1 1 1 2 0 1 0 0 1 0 0 1 1 1 1 2 2 0 0 1 0 2 1 2 1 0 1 0 0 0 0 0 0 0 0 2 0 2 0 0 0 0 0 1 0 1 1 0 1 1 3 1 0 0 0 2 0 0 0 0 1 0 1 0 0 1 1 0 0 1 0 0 0 0 1 0 1 1 0 1 1 0 1 1 2 0 1 0 1 0 1 1 2 0 0 1 0 0 2 0 0 0 0 2 0 1 2 1 0 1 0 0 0 0 1 0 0 0 1 0 0 0 1 1 2 0 1 0 4 0 1 1 0 1 1 0 1 0 1 1 1 0 1 0 1 1 0 3 0 1 0 1 0 1 0 0 0 0 1 1 1 1 1 3 0 1 0 0 1 0 0 0 0 1 1 0 0 1 0 0 2 2 0 0 0 1 0 0 0 1 0 0 1 0 1 0 0 2 0 0 0 2 0 3 0 0 0 0 1 0 0 0 0 1 0 0 0 0 0 0 1 1 3 0 1 1 0 1 0 0</counts>
			</dataPoints>
		</scan>
		<scan status="Completed" appendNumber="0" scanAxis="2Theta" mode="Continuous">
			<header>
				<startTimeStamp>2022-11-11T16:03:56-05:00</startTimeStamp>
				<endTimeStamp>2022-11-11T16:23:58-05:00</endTimeStamp>
				<author>
					<name>User</name>
				</author>
				<source>
					<applicationSoftware version="7.1">Data Collector</applicationSoftware>
					<instrumentControlSoftware version="8.2  20201204">EMPYREAN</instrumentControlSoftware>
					<instrumentID>0000000011260721</instrumentID>
				</source>
			</header>
			<dataPoints>
				<positions axis="2Theta" unit="deg">
					<startPosition>75.6210820516944</startPosition>
					<endPosition>78.9683518229109</endPosition>
				</positions>
				<positions axis="Omega" unit="deg">
					<commonPosition>20.3573584686513</commonPosition>
				</positions>
				<positions axis="Phi" unit="deg">
					<commonPosition>183.93</commonPosition>
				</positions>
				<positions axis="Chi" unit="deg">
					<commonPosition>0</commonPosition>
				</positions>
				<positions axis="Z" unit="mm">
					<commonPosition>8.387</commonPosition>
				</positions>
				<commonCountingTime unit="seconds">0.974</commonCountingTime>
				<counts unit="counts">0 0 1 0 1 0 2 0 0 1 1 0 0 0 1 0 0 0 0 0 1 2 0 0 1 1 0 1 0 1 2 0 0 0 0 1 1 1 0 0 0 0 1 0 1 0 4 4 0 0 0 0 0 1 1 0 2 0 2 1 0 1 0 0 0 0 0 0 0 0 0 0 0 0 1 1 0 0 0 0 0 0 0 2 2 0 1 0 1 0 0 0 2 2 2 0 2 0 0 1 2 1 2 1 2 1 0 2 3 0 2 0 1 1 0 0 0 1 1 0 2 0 0 0 0 1 2 0 0 0 0 0 1 0 0 1 1 2 1 2 0 1 0 0 1 0 0 0 0 0 0 2 1 0 0 1 0 1 1 0 0 0 0 1 0 0 0 0 0 1 1 0 1 0 0 2 0 1 1 1 1 0 0 0 0 0 0 0 1 1 0 2 0 0 1 0 1 1 1 1 1 1 0 1 0 0 1 0 0 0 1 2 0 0 1 0 0 1 0 0 1 0 2 0 0 1 0 1 2 0 1 1 0 1 0 1 3 1 1 0 0 0 0 0 0 0 0 0 0 0 0 0 1 2 0</counts>
			</dataPoints>
		</scan>
		<scan status="Completed" appendNumber="0" scanAxis="2Theta" mode="Continuous">
			<header>
				<startTimeStamp>2022-11-11T16:03:56-05:00</startTimeStamp>
				<endTimeStamp>2022-11-11T16:23:58-05:00</endTimeStamp>
				<author>
					<name>User</name>
				</author>
				<source>
					<applicationSoftware version="7.1">Data Collector</applicationSoftware>
					<instrumentControlSoftware version="8.2  20201204">EMPYREAN</instrumentControlSoftware>
					<instrumentID>0000000011260721</instrumentID>
				</source>
			</header>
			<dataPoints>
				<positions axis="2Theta" unit="deg">
					<startPosition>75.6243646223687</startPosition>
					<endPosition>78.9716343935852</endPosition>
				</positions>
				<positions axis="Omega" unit="deg">
					<commonPosition>20.3589997539885</commonPosition>
				</positions>
				<positions axis="Phi" unit="deg">
					<commonPosition>183.93</commonPosition>
				</positions>
				<positions axis="Chi" unit="deg">
					<commonPosition>0</commonPosition>
				</positions>
				<positions axis="Z" unit="mm">
					<commonPosition>8.387</commonPosition>
				</positions>
				<commonCountingTime unit="seconds">0.974</commonCountingTime>
				<counts unit="counts">1 0 0 1 0 0 0 1 0 1 0 0 1 0 0 0 1 0 1 0 0 2 1 0 2 1 0 1 2 0 2 0 0 1 0 0 1 1 0 0 0 0 1 1 0 0 1 1 0 0 2 1 0 1 1 0 0 2 0 1 0 0 1 0 0 1 1 0 1 0 0 0 0 3 0 3 0 1 2 0 0 1 1 1 0 0 1 0 0 0 1 0 4 0 0 0 0 1 0 2 0 0 2 1 0 1 0 0 0 0 0 1 1 0 0 0 0 1 1 1 1 1 0 1 0 0 0 0 0 0 0 0 0 0 0 0 1 0 1 0 0 1 0 0 0 0 0 1 0 1 0 3 2 0 2 1 1 0 1 0 1 0 0 0 0 2 0 0 1 2 0 1 0 0 0 0 1 1 0 0 0 0 1 1 0 1 0 2 0 1 0 0 2 2 0 0 2 2 1 0 0 0 1 0 0 0 1 2 0 0 0 0 1 1 0 0 1 0 1 0 0 0 1 0 0 0 0 0 0 0 0 0 1 1 0 1 0 0 0 1 0 2 0 1 1 1 1 1 0 0 1 0 0 0 1</counts>
			</dataPoints>
		</scan>
		<scan status="Completed" appendNumber="0" scanAxis="2Theta" mode="Continuous">
			<header>
				<startTimeStamp>2022-11-11T16:03:56-05:00</startTimeStamp>
				<endTimeStamp>2022-11-11T16:23:58-05:00</endTimeStamp>
				<author>
					<name>User</name>
				</author>
				<source>
					<applicationSoftware version="7.1">Data Collector</applicationSoftware>
					<instrumentControlSoftware version="8.2  20201204">EMPYREAN</instrumentControlSoftware>
					<instrumentID>0000000011260721</instrumentID>
				</source>
			</header>
			<dataPoints>
				<positions axis="2Theta" unit="deg">
					<startPosition>75.6276471930431</startPosition>
					<endPosition>78.9749169642596</endPosition>
				</positions>
				<positions axis="Omega" unit="deg">
					<commonPosition>20.3606410393257</commonPosition>
				</positions>
				<positions axis="Phi" unit="deg">
					<commonPosition>183.93</commonPosition>
				</positions>
				<positions axis="Chi" unit="deg">
					<commonPosition>0</commonPosition>
				</positions>
				<positions axis="Z" unit="mm">
					<commonPosition>8.387</commonPosition>
				</positions>
				<commonCountingTime unit="seconds">0.974</commonCountingTime>
				<counts unit="counts">0 0 1 2 0 1 0 0 3 0 0 0 1 0 1 3 0 0 1 0 0 0 0 0 1 0 0 2 1 0 2 0 1 1 0 1 0 0 2 1 1 1 1 0 1 2 0 1 0 0 0 1 1 1 1 2 3 0 0 0 0 1 0 0 1 1 0 1 1 0 0 0 0 2 0 1 0 0 3 0 0 2 1 0 0 1 2 0 0 0 1 0 0 0 1 0 0 1 1 0 0 0 4 1 1 0 0 0 2 0 2 0 0 1 0 1 0 0 1 2 1 0 0 0 1 0 0 1 0 0 0 1 1 1 1 1 0 0 0 1 0 0 0 0 0 0 1 1 0 1 0 1 2 0 0 1 1 0 2 1 0 0 0 0 0 0 0 0 1 0 1 2 0 1 1 1 0 1 0 0 0 1 0 0 0 0 0 0 0 1 0 0 2 0 0 0 0 0 0 0 0 0 0 0 1 0 2 0 0 0 1 0 0 0 0 1 0 0 1 1 0 0 0 0 0 1 0 1 1 0 0 0 0 0 0 1 0 0 0 0 0 0 0 2 1 0 0 1 2 0 1 0 0 0 0</counts>
			</dataPoints>
		</scan>
		<scan status="Completed" appendNumber="0" scanAxis="2Theta" mode="Continuous">
			<header>
				<startTimeStamp>2022-11-11T16:03:56-05:00</startTimeStamp>
				<endTimeStamp>2022-11-11T16:23:58-05:00</endTimeStamp>
				<author>
					<name>User</name>
				</author>
				<source>
					<applicationSoftware version="7.1">Data Collector</applicationSoftware>
					<instrumentControlSoftware version="8.2  20201204">EMPYREAN</instrumentControlSoftware>
					<instrumentID>0000000011260721</instrumentID>
				</source>
			</header>
			<dataPoints>
				<positions axis="2Theta" unit="deg">
					<startPosition>75.6309297637174</startPosition>
					<endPosition>78.9781995349339</endPosition>
				</positions>
				<positions axis="Omega" unit="deg">
					<commonPosition>20.3622823246628</commonPosition>
				</positions>
				<positions axis="Phi" unit="deg">
					<commonPosition>183.93</commonPosition>
				</positions>
				<positions axis="Chi" unit="deg">
					<commonPosition>0</commonPosition>
				</positions>
				<positions axis="Z" unit="mm">
					<commonPosition>8.387</commonPosition>
				</positions>
				<commonCountingTime unit="seconds">0.974</commonCountingTime>
				<counts unit="counts">0 0 0 0 2 0 0 0 0 0 1 1 1 0 0 0 1 1 1 1 0 1 0 3 1 0 2 1 0 1 0 0 0 0 1 1 0 2 1 0 0 0 1 2 0 0 0 1 1 1 0 1 0 1 0 1 0 0 2 2 0 0 0 1 0 0 0 1 0 0 2 0 0 0 3 0 0 1 1 0 1 1 0 0 0 0 0 0 0 0 2 0 1 0 2 0 1 1 2 0 0 0 3 0 1 0 0 1 0 0 0 0 0 2 1 0 1 0 0 0 0 0 0 3 0 0 0 2 1 2 0 1 0 2 0 0 0 0 0 0 1 1 0 2 0 0 1 1 0 1 1 0 0 1 0 1 0 0 0 0 0 0 1 0 0 0 1 0 0 0 0 1 0 0 0 0 0 1 2 1 2 1 0 1 0 1 0 0 1 0 0 1 0 0 1 1 0 0 2 0 0 0 0 1 0 0 0 2 0 0 0 1 0 0 0 0 0 2 1 0 1 0 1 1 0 0 0 0 1 0 0 0 0 1 0 0 0 0 1 1 0 0 0 0 0 0 0 0 0 1 1 0 0 0 0</counts>
			</dataPoints>
		</scan>
		<scan status="Completed" appendNumber="0" scanAxis="2Theta" mode="Continuous">
			<header>
				<startTimeStamp>2022-11-11T16:03:56-05:00</startTimeStamp>
				<endTimeStamp>2022-11-11T16:23:58-05:00</endTimeStamp>
				<author>
					<name>User</name>
				</author>
				<source>
					<applicationSoftware version="7.1">Data Collector</applicationSoftware>
					<instrumentControlSoftware version="8.2  20201204">EMPYREAN</instrumentControlSoftware>
					<instrumentID>0000000011260721</instrumentID>
				</source>
			</header>
			<dataPoints>
				<positions axis="2Theta" unit="deg">
					<startPosition>75.6342123343918</startPosition>
					<endPosition>78.9814821056082</endPosition>
				</positions>
				<positions axis="Omega" unit="deg">
					<commonPosition>20.36392361</commonPosition>
				</positions>
				<positions axis="Phi" unit="deg">
					<commonPosition>183.93</commonPosition>
				</positions>
				<positions axis="Chi" unit="deg">
					<commonPosition>0</commonPosition>
				</positions>
				<positions axis="Z" unit="mm">
					<commonPosition>8.387</commonPosition>
				</positions>
				<commonCountingTime unit="seconds">0.974</commonCountingTime>
				<counts unit="counts">1 2 0 0 0 2 0 0 0 2 0 2 0 0 1 1 1 0 1 3 1 1 0 2 2 0 1 0 0 0 0 0 0 0 0 2 1 0 3 1 0 3 0 1 2 1 0 0 0 0 0 1 1 1 0 1 0 0 1 0 1 1 0 0 1 0 3 1 1 2 1 1 0 2 0 0 1 1 2 1 0 1 0 2 0 2 0 1 0 1 0 0 2 1 0 0 2 0 1 0 0 0 0 0 1 0 0 1 0 0 0 0 1 0 0 0 2 0 2 2 1 0 0 0 0 0 1 1 1 0 1 2 0 0 0 1 1 0 0 0 1 0 2 0 1 0 0 2 1 1 2 0 1 1 1 1 1 0 0 1 0 1 0 1 0 1 1 0 1 0 1 0 1 1 0 3 0 0 3 0 0 0 1 1 1 0 1 0 0 1 0 1 0 2 1 2 0 0 0 0 1 0 1 0 0 1 0 0 0 0 2 0 0 0 1 1 2 0 0 0 1 1 0 0 0 0 0 0 0 0 0 1 0 0 0 1 0 0 0 0 0 0 2 1 1 0 0 0 0 1 0 0 1 0 2</counts>
			</dataPoints>
		</scan>
	</xrdMeasurement>
</xrdMeasurements>