File: data/XRD_RSM/YG053/YCG_053 S1 RSM slow 3 degree_1.xrdml
<?xml version="1.0" encoding="utf-8"?>
<xrdMeasurements xmlns="http://www.xrdml.com/XRDMeasurement/2.2" xmlns:xsi="http://www.w3.org/2001/XMLSchema-instance" xsi:schemaLocation="http://www.xrdml.com/XRDMeasurement/2.2 http://www.xrdml.com/XRDMeasurement/2.2/XRDMeasurement.xsd" status="Completed">
	<comment>
		<entry>Configuration=3-axes Cradle_Reflection, Owner=lw627, Creation date=9/2/2021 3:55:24 PM</entry>
		<entry>Goniometer=Theta/Theta; Minimum step size 2Theta:0.0001; Minimum step size Omega:0.0001</entry>
		<entry>Sample stage=Chi-Phi-z stage 240 mm (reflection); Minimum step size Phi:0.01; Minimum step size Chi:0.01; Minimum step size Z:0.001</entry>
		<entry>Diffractometer system=EMPYREAN</entry>
		<entry>Measurement program=C:\PANalytical\Data Collector\Programs\Liyan Wu\Film programs\RSM slow 3 degree.xrdmp, Identifier={0351664C-55A7-43E7-B72A-7307F4B26703}</entry>
	</comment>
	<sample type="To be analyzed">
		<id/>
		<name/>
		<preparedBy/>
	</sample>
	<xrdMeasurement status="Completed" measurementType="Area measurement" measurementStepAxis="Omega-2Theta" sampleMode="Reflection">
		<comment>
			<entry>PHD Lower Level = 4.02 (keV), PHD Upper Level = 11.27 (keV)</entry>
		</comment>
		<usedWavelength intended="K-Alpha 1">
			<kAlpha1 unit="Angstrom">1.5405980</kAlpha1>
			<kAlpha2 unit="Angstrom">1.5444260</kAlpha2>
			<kBeta unit="Angstrom">1.3922500</kBeta>
			<ratioKAlpha2KAlpha1>0</ratioKAlpha2KAlpha1>
		</usedWavelength>
		<incidentBeamPath>
			<radius unit="mm">240.00</radius>
			<xRayTube id="1010048" name="Empyrean Cu LFF HR (9430 033 7310x) DK432574">
				<tension unit="kV">45.0</tension>
				<current unit="mA">40.0</current>
				<anodeMaterial>Cu</anodeMaterial>
				<focus type="Line">
					<length unit="mm">12.0</length>
					<width unit="mm">0.4</width>
					<takeOffAngle unit="deg">4.4</takeOffAngle>
				</focus>
			</xRayTube>
			<xRayMirror xsi:type="xRayMirrorType" id="27080001" name="Inc. Beam Cu W/Si (hybrid MPD)" hybrid="true">
				<crystal type="Graded" shape="Parabolic">W/Si</crystal>
				<acceptanceAngle unit="deg">0.800</acceptanceAngle>
				<length unit="mm">55.3</length>
			</xRayMirror>
			<monochromator xsi:type="monochromatorType" id="23090002" name="Hybrid monochr. 2xGe220 Cu asym." hybrid="true">
				<crystal type="Asymmetric" shape="Flat">Ge</crystal>
				<numberOfReflections>2</numberOfReflections>
				<hkl>
					<h>2</h>
					<k>2</k>
					<l>0</l>
				</hkl>
			</monochromator>
			<divergenceSlit xsi:type="fixedDivergenceSlitType" id="22010005" name="Fixed slit 1/4°">
				<distanceToSample unit="mm">179.30</distanceToSample>
				<height unit="mm">0.38</height>
			</divergenceSlit>
		</incidentBeamPath>
		<diffractedBeamPath>
			<radius unit="mm">240.00</radius>
			<antiScatterSlit xsi:type="fixedAntiScatterSlitType" id="22060009" name="Programmable anti-scatter slit">
				<angle unit="deg">4</angle>
			</antiScatterSlit>
			<detector xsi:type="areaDetectorType" id="7010020" name="PIXcel3D-Medipix3 1x1 detector">
				<phd unit="%">
					<lowerLevel>25</lowerLevel>
					<upperLevel>70</upperLevel>
				</phd>
				<mode>Scanning snapshot equatorial</mode>
				<activeChannelsEquatorial>255</activeChannelsEquatorial>
				<activeChannelsAxial>255</activeChannelsAxial>
				<pitchEquatorial unit="mm">0.05500</pitchEquatorial>
				<pitchAxial unit="mm">0.05500</pitchAxial>
				<readOutPeriod unit="seconds">0.980</readOutPeriod>
			</detector>
		</diffractedBeamPath>
		<scan status="Completed" appendNumber="0" scanAxis="2Theta" mode="Continuous">
			<header>
				<startTimeStamp>2024-06-28T16:36:56-04:00</startTimeStamp>
				<endTimeStamp>2024-06-28T17:06:56-04:00</endTimeStamp>
				<author>
					<name>lw627</name>
				</author>
				<source>
					<applicationSoftware version="7.1">Data Collector</applicationSoftware>
					<instrumentControlSoftware version="8.2  20201204">EMPYREAN</instrumentControlSoftware>
					<instrumentID>0000000011260721</instrumentID>
				</source>
			</header>
			<dataPoints>
				<positions axis="2Theta" unit="deg">
					<startPosition>71.9594063943918</startPosition>
					<endPosition>75.3066761656082</endPosition>
				</positions>
				<positions axis="Omega" unit="deg">
					<commonPosition>18.25552064</commonPosition>
				</positions>
				<positions axis="Phi" unit="deg">
					<commonPosition>-94.99</commonPosition>
				</positions>
				<positions axis="Chi" unit="deg">
					<commonPosition>0</commonPosition>
				</positions>
				<positions axis="Z" unit="mm">
					<commonPosition>8.33</commonPosition>
				</positions>
				<commonCountingTime unit="seconds">0.974</commonCountingTime>
				<counts unit="counts">0 1 0 0 0 0 0 0 0 0 0 1 1 1 0 1 0 0 0 2 0 0 0 1 1 0 0 0 0 1 1 0 2 0 2 0 0 0 0 0 4 1 0 0 1 0 0 0 0 2 0 0 1 0 0 0 0 0 0 0 0 0 1 2 0 0 0 0 0 1 0 1 0 0 0 0 0 0 0 0 0 0 0 0 0 1 0 0 0 1 1 0 1 0 0 0 0 1 0 0 1 0 0 0 0 0 1 0 0 0 0 0 1 0 1 0 0 0 2 0 0 0 0 1 0 0 0 0 1 1 0 0 0 0 0 0 0 0 0 0 0 0 0 0 0 0 0 0 0 0 0 0 0 0 0 0 1 0 0 0 0 1 0 0 0 0 1 0 0 1 0 0 0 0 0 0 1 1 1 0 0 1 0 0 1 0 0 0 0 0 0 0 1 0 0 1 1 0 0 0 0 0 0 2 0 3 0 0 0 0 0 0 0 0 0 0 0 0 1 0 0 1 0 2 0 0 2 2 0 0 0 2 2 0 1 0 3 2 0 2 1 2 0 0 0 0 0 0 0 0 0 1 0 1 0</counts>
			</dataPoints>
		</scan>
		<scan status="Completed" appendNumber="0" scanAxis="2Theta" mode="Continuous">
			<header>
				<startTimeStamp>2024-06-28T16:36:56-04:00</startTimeStamp>
				<endTimeStamp>2024-06-28T17:06:56-04:00</endTimeStamp>
				<author>
					<name>lw627</name>
				</author>
				<source>
					<applicationSoftware version="7.1">Data Collector</applicationSoftware>
					<instrumentControlSoftware version="8.2  20201204">EMPYREAN</instrumentControlSoftware>
					<instrumentID>0000000011260721</instrumentID>
				</source>
			</header>
			<dataPoints>
				<positions axis="2Theta" unit="deg">
					<startPosition>71.9626889650599</startPosition>
					<endPosition>75.3099587362764</endPosition>
				</positions>
				<positions axis="Omega" unit="deg">
					<commonPosition>18.2571619253341</commonPosition>
				</positions>
				<positions axis="Phi" unit="deg">
					<commonPosition>-94.99</commonPosition>
				</positions>
				<positions axis="Chi" unit="deg">
					<commonPosition>0</commonPosition>
				</positions>
				<positions axis="Z" unit="mm">
					<commonPosition>8.33</commonPosition>
				</positions>
				<commonCountingTime unit="seconds">0.974</commonCountingTime>
				<counts unit="counts">0 0 3 0 2 0 0 0 0 0 1 0 0 0 2 0 0 0 0 0 0 0 0 1 0 1 0 0 0 0 1 0 0 1 1 0 0 0 0 2 1 0 0 0 0 0 0 0 0 0 0 1 0 1 0 0 1 0 0 1 1 0 0 0 0 0 0 1 1 0 0 1 0 0 0 0 0 0 0 0 0 1 0 0 0 0 0 0 0 0 2 0 1 0 0 0 1 0 2 1 0 2 0 0 0 0 0 0 0 1 0 0 0 0 0 0 0 1 0 2 0 0 0 0 0 1 0 1 1 1 0 1 0 2 1 0 0 1 1 0 1 0 0 0 0 0 2 1 0 0 1 0 0 0 1 2 0 0 0 0 0 0 3 0 1 1 0 0 0 0 0 1 1 0 0 0 0 1 0 0 0 0 0 0 0 1 0 0 0 0 0 0 0 0 0 1 2 0 0 0 0 1 0 3 0 0 0 0 0 0 0 1 0 0 0 0 0 0 0 0 0 1 0 1 0 0 1 1 0 0 1 0 0 0 2 0 0 0 0 0 0 1 0 0 0 0 0 0 1 0 0 0 0 0 0</counts>
			</dataPoints>
		</scan>
		<scan status="Completed" appendNumber="0" scanAxis="2Theta" mode="Continuous">
			<header>
				<startTimeStamp>2024-06-28T16:36:56-04:00</startTimeStamp>
				<endTimeStamp>2024-06-28T17:06:56-04:00</endTimeStamp>
				<author>
					<name>lw627</name>
				</author>
				<source>
					<applicationSoftware version="7.1">Data Collector</applicationSoftware>
					<instrumentControlSoftware version="8.2  20201204">EMPYREAN</instrumentControlSoftware>
					<instrumentID>0000000011260721</instrumentID>
				</source>
			</header>
			<dataPoints>
				<positions axis="2Theta" unit="deg">
					<startPosition>71.965971535728</startPosition>
					<endPosition>75.3132413069445</endPosition>
				</positions>
				<positions axis="Omega" unit="deg">
					<commonPosition>18.2588032106681</commonPosition>
				</positions>
				<positions axis="Phi" unit="deg">
					<commonPosition>-94.99</commonPosition>
				</positions>
				<positions axis="Chi" unit="deg">
					<commonPosition>0</commonPosition>
				</positions>
				<positions axis="Z" unit="mm">
					<commonPosition>8.33</commonPosition>
				</positions>
				<commonCountingTime unit="seconds">0.974</commonCountingTime>
				<counts unit="counts">1 0 0 0 1 0 0 0 0 0 0 0 0 0 0 2 1 0 0 0 0 0 0 0 1 0 0 0 0 0 0 0 0 0 1 1 0 0 0 0 2 0 0 0 0 1 0 0 0 1 0 0 0 0 1 0 1 1 0 0 1 0 0 0 0 1 0 1 0 1 0 0 0 0 1 0 0 1 1 0 0 0 0 1 0 0 0 0 0 1 0 0 0 1 1 0 0 0 0 1 1 1 1 1 0 0 0 0 1 0 0 0 0 0 0 0 1 0 0 0 0 1 0 0 0 0 0 0 0 1 1 0 0 3 1 0 0 0 0 0 1 0 1 1 1 0 2 0 0 0 0 1 0 0 0 0 0 0 0 0 1 0 0 0 1 1 0 1 0 0 1 0 0 0 0 1 0 0 1 1 0 0 2 0 0 0 0 0 0 0 0 0 0 0 0 1 0 0 0 0 1 1 0 0 1 0 0 0 0 0 0 0 0 0 1 0 0 0 0 1 1 0 0 0 0 0 0 1 0 1 1 0 0 0 0 0 0 1 0 0 0 0 0 0 0 0 0 0 0 0 0 0 1 0 1</counts>
			</dataPoints>
		</scan>
		<scan status="Completed" appendNumber="0" scanAxis="2Theta" mode="Continuous">
			<header>
				<startTimeStamp>2024-06-28T16:36:56-04:00</startTimeStamp>
				<endTimeStamp>2024-06-28T17:06:56-04:00</endTimeStamp>
				<author>
					<name>lw627</name>
				</author>
				<source>
					<applicationSoftware version="7.1">Data Collector</applicationSoftware>
					<instrumentControlSoftware version="8.2  20201204">EMPYREAN</instrumentControlSoftware>
					<instrumentID>0000000011260721</instrumentID>
				</source>
			</header>
			<dataPoints>
				<positions axis="2Theta" unit="deg">
					<startPosition>71.9692541063961</startPosition>
					<endPosition>75.3165238776126</endPosition>
				</positions>
				<positions axis="Omega" unit="deg">
					<commonPosition>18.2604444960022</commonPosition>
				</positions>
				<positions axis="Phi" unit="deg">
					<commonPosition>-94.99</commonPosition>
				</positions>
				<positions axis="Chi" unit="deg">
					<commonPosition>0</commonPosition>
				</positions>
				<positions axis="Z" unit="mm">
					<commonPosition>8.33</commonPosition>
				</positions>
				<commonCountingTime unit="seconds">0.974</commonCountingTime>
				<counts unit="counts">0 0 1 0 0 1 0 0 0 0 0 0 0 0 0 1 0 1 0 0 0 0 0 0 0 1 0 0 0 0 0 0 0 0 1 0 1 0 0 0 0 0 2 1 0 1 0 0 0 1 0 0 0 1 0 0 0 0 0 0 0 0 0 1 0 0 0 1 0 1 0 0 0 0 0 0 0 0 0 1 0 0 0 1 0 0 0 1 0 0 0 2 2 0 0 0 0 0 1 0 0 0 0 0 0 0 0 0 0 0 0 0 0 0 0 0 0 0 1 1 0 0 0 0 0 1 1 1 0 0 0 1 0 0 0 1 1 1 0 0 0 0 0 0 0 0 0 1 1 0 0 0 0 0 0 0 0 0 0 0 0 0 0 0 0 1 0 0 1 0 1 1 0 0 1 0 1 0 1 0 0 0 0 0 1 1 0 0 0 0 1 0 0 1 0 0 2 0 2 0 1 0 0 1 0 0 0 1 0 0 2 0 0 0 1 1 0 0 0 0 0 0 2 0 1 0 2 0 1 0 0 0 0 2 0 1 0 0 1 0 0 0 0 0 1 0 0 0 0 1 0 0 0 0 0</counts>
			</dataPoints>
		</scan>
		<scan status="Completed" appendNumber="0" scanAxis="2Theta" mode="Continuous">
			<header>
				<startTimeStamp>2024-06-28T16:36:56-04:00</startTimeStamp>
				<endTimeStamp>2024-06-28T17:06:56-04:00</endTimeStamp>
				<author>
					<name>lw627</name>
				</author>
				<source>
					<applicationSoftware version="7.1">Data Collector</applicationSoftware>
					<instrumentControlSoftware version="8.2  20201204">EMPYREAN</instrumentControlSoftware>
					<instrumentID>0000000011260721</instrumentID>
				</source>
			</header>
			<dataPoints>
				<positions axis="2Theta" unit="deg">
					<startPosition>71.9725366770643</startPosition>
					<endPosition>75.3198064482807</endPosition>
				</positions>
				<positions axis="Omega" unit="deg">
					<commonPosition>18.2620857813363</commonPosition>
				</positions>
				<positions axis="Phi" unit="deg">
					<commonPosition>-94.99</commonPosition>
				</positions>
				<positions axis="Chi" unit="deg">
					<commonPosition>0</commonPosition>
				</positions>
				<positions axis="Z" unit="mm">
					<commonPosition>8.33</commonPosition>
				</positions>
				<commonCountingTime unit="seconds">0.974</commonCountingTime>
				<counts unit="counts">0 0 0 0 0 0 0 0 0 0 1 0 1 0 0 0 1 0 0 0 1 0 0 0 0 2 0 0 1 1 1 1 0 2 0 0 1 0 1 1 0 1 0 0 1 0 0 0 0 1 0 0 1 0 0 0 0 0 1 0 0 1 0 0 1 0 1 0 0 0 0 0 1 0 1 1 0 1 0 0 1 2 1 1 0 0 0 0 0 1 0 0 0 0 0 1 0 0 0 1 0 0 1 0 0 0 0 1 0 0 0 0 0 0 0 1 1 0 1 0 0 0 1 0 0 0 0 0 2 0 3 0 0 0 1 1 1 0 1 0 2 1 0 1 1 0 0 0 0 1 0 0 0 1 0 0 0 1 0 0 0 2 1 0 1 0 0 0 0 0 0 0 1 0 0 0 0 1 0 0 0 0 1 0 1 0 0 0 0 0 0 1 0 0 0 0 3 1 1 0 1 0 0 1 1 1 0 1 0 1 0 0 0 1 0 0 0 0 0 0 1 0 0 1 0 0 0 0 0 0 0 0 1 2 0 0 0 0 0 0 1 0 0 1 1 1 0 2 0 1 2 0 1 0 0</counts>
			</dataPoints>
		</scan>
		<scan status="Completed" appendNumber="0" scanAxis="2Theta" mode="Continuous">
			<header>
				<startTimeStamp>2024-06-28T16:36:56-04:00</startTimeStamp>
				<endTimeStamp>2024-06-28T17:06:56-04:00</endTimeStamp>
				<author>
					<name>lw627</name>
				</author>
				<source>
					<applicationSoftware version="7.1">Data Collector</applicationSoftware>
					<instrumentControlSoftware version="8.2  20201204">EMPYREAN</instrumentControlSoftware>
					<instrumentID>0000000011260721</instrumentID>
				</source>
			</header>
			<dataPoints>
				<positions axis="2Theta" unit="deg">
					<startPosition>71.9758192477324</startPosition>
					<endPosition>75.3230890189489</endPosition>
				</positions>
				<positions axis="Omega" unit="deg">
					<commonPosition>18.2637270666703</commonPosition>
				</positions>
				<positions axis="Phi" unit="deg">
					<commonPosition>-94.99</commonPosition>
				</positions>
				<positions axis="Chi" unit="deg">
					<commonPosition>0</commonPosition>
				</positions>
				<positions axis="Z" unit="mm">
					<commonPosition>8.33</commonPosition>
				</positions>
				<commonCountingTime unit="seconds">0.974</commonCountingTime>
				<counts unit="counts">2 0 0 0 0 0 0 0 0 1 1 0 0 0 1 2 0 0 0 0 1 0 0 1 0 1 0 1 0 0 0 0 0 0 0 0 0 0 0 0 2 0 0 0 1 2 0 0 0 0 0 0 0 0 0 0 0 1 0 0 0 0 0 0 0 0 0 0 1 0 0 0 0 1 0 1 0 0 0 0 0 0 0 0 0 0 0 2 0 1 3 1 0 0 1 0 0 0 0 0 0 0 0 0 0 0 0 0 1 0 0 0 0 1 0 0 0 0 0 0 0 0 0 1 0 0 0 1 0 1 0 0 0 0 1 1 2 0 0 0 2 0 0 1 0 0 0 0 1 1 1 1 1 1 0 0 0 1 0 3 1 2 0 0 1 1 0 0 0 1 0 1 1 1 3 1 1 1 0 0 0 0 0 0 0 1 0 0 0 1 0 1 0 0 0 0 1 0 0 0 0 0 0 0 0 0 1 0 0 0 2 0 0 0 0 0 1 0 1 0 1 1 0 0 0 0 0 0 0 0 0 0 1 0 0 0 0 0 0 1 0 1 0 1 1 0 0 0 0 1 0 0 0 1 1</counts>
			</dataPoints>
		</scan>
		<scan status="Completed" appendNumber="0" scanAxis="2Theta" mode="Continuous">
			<header>
				<startTimeStamp>2024-06-28T16:36:56-04:00</startTimeStamp>
				<endTimeStamp>2024-06-28T17:06:56-04:00</endTimeStamp>
				<author>
					<name>lw627</name>
				</author>
				<source>
					<applicationSoftware version="7.1">Data Collector</applicationSoftware>
					<instrumentControlSoftware version="8.2  20201204">EMPYREAN</instrumentControlSoftware>
					<instrumentID>0000000011260721</instrumentID>
				</source>
			</header>
			<dataPoints>
				<positions axis="2Theta" unit="deg">
					<startPosition>71.9791018184005</startPosition>
					<endPosition>75.326371589617</endPosition>
				</positions>
				<positions axis="Omega" unit="deg">
					<commonPosition>18.2653683520044</commonPosition>
				</positions>
				<positions axis="Phi" unit="deg">
					<commonPosition>-94.99</commonPosition>
				</positions>
				<positions axis="Chi" unit="deg">
					<commonPosition>0</commonPosition>
				</positions>
				<positions axis="Z" unit="mm">
					<commonPosition>8.33</commonPosition>
				</positions>
				<commonCountingTime unit="seconds">0.974</commonCountingTime>
				<counts unit="counts">0 1 0 0 0 0 0 0 0 0 1 0 1 0 0 0 0 0 0 0 0 0 1 1 1 0 0 1 1 0 1 0 0 0 0 0 1 1 1 0 1 1 0 0 0 0 0 0 0 0 2 0 1 1 0 0 0 1 0 0 0 0 0 0 0 0 0 0 0 1 0 0 0 0 0 0 1 0 0 1 1 0 0 1 0 0 1 0 0 0 1 1 0 0 0 0 1 0 0 0 0 0 0 0 1 0 0 0 0 1 0 0 0 0 0 0 0 0 0 0 0 0 1 0 1 0 0 0 0 0 0 0 0 0 0 0 0 1 0 0 0 0 2 0 1 0 0 1 2 0 1 0 0 0 0 0 0 0 0 0 2 0 1 0 1 0 0 0 0 0 0 2 0 0 0 1 2 0 0 0 0 0 0 0 0 0 0 0 0 0 0 1 1 1 0 0 2 0 0 0 0 0 0 0 0 1 0 0 2 0 0 0 0 0 1 0 1 0 0 0 0 0 0 0 0 0 1 0 0 0 0 1 0 0 1 1 0 0 0 0 0 0 0 1 2 0 0 0 0 1 0 1 0 0 0</counts>
			</dataPoints>
		</scan>
		<scan status="Completed" appendNumber="0" scanAxis="2Theta" mode="Continuous">
			<header>
				<startTimeStamp>2024-06-28T16:36:56-04:00</startTimeStamp>
				<endTimeStamp>2024-06-28T17:06:56-04:00</endTimeStamp>
				<author>
					<name>lw627</name>
				</author>
				<source>
					<applicationSoftware version="7.1">Data Collector</applicationSoftware>
					<instrumentControlSoftware version="8.2  20201204">EMPYREAN</instrumentControlSoftware>
					<instrumentID>0000000011260721</instrumentID>
				</source>
			</header>
			<dataPoints>
				<positions axis="2Theta" unit="deg">
					<startPosition>71.9823843890687</startPosition>
					<endPosition>75.3296541602851</endPosition>
				</positions>
				<positions axis="Omega" unit="deg">
					<commonPosition>18.2670096373384</commonPosition>
				</positions>
				<positions axis="Phi" unit="deg">
					<commonPosition>-94.99</commonPosition>
				</positions>
				<positions axis="Chi" unit="deg">
					<commonPosition>0</commonPosition>
				</positions>
				<positions axis="Z" unit="mm">
					<commonPosition>8.33</commonPosition>
				</positions>
				<commonCountingTime unit="seconds">0.974</commonCountingTime>
				<counts unit="counts">0 0 0 0 0 0 0 0 0 1 0 0 0 0 0 0 0 2 1 1 1 0 0 0 0 0 0 0 0 0 0 0 0 1 0 0 1 0 0 2 0 0 0 0 0 1 0 0 0 0 1 1 0 0 0 0 0 0 1 1 0 0 0 0 0 0 0 0 1 0 0 0 0 0 0 0 0 0 0 0 0 0 0 0 1 0 0 1 0 1 0 1 0 0 0 0 0 1 0 0 0 2 1 0 1 0 0 0 0 0 1 0 0 1 1 1 0 0 0 1 0 0 0 0 0 1 0 2 0 0 0 0 0 0 0 0 0 0 0 1 0 1 0 0 0 0 0 2 0 0 0 0 0 0 1 0 0 1 0 0 0 0 0 1 0 0 0 0 0 1 0 0 0 0 0 0 1 0 0 0 0 0 0 0 0 0 0 0 1 0 0 0 0 0 0 0 0 0 2 0 0 0 0 0 0 0 0 0 0 0 0 0 0 0 0 0 0 0 0 0 1 1 0 0 0 0 0 0 0 0 0 1 0 1 1 0 1 0 0 2 0 1 0 0 0 0 1 2 1 0 0 0 0 0 0</counts>
			</dataPoints>
		</scan>
		<scan status="Completed" appendNumber="0" scanAxis="2Theta" mode="Continuous">
			<header>
				<startTimeStamp>2024-06-28T16:36:56-04:00</startTimeStamp>
				<endTimeStamp>2024-06-28T17:06:56-04:00</endTimeStamp>
				<author>
					<name>lw627</name>
				</author>
				<source>
					<applicationSoftware version="7.1">Data Collector</applicationSoftware>
					<instrumentControlSoftware version="8.2  20201204">EMPYREAN</instrumentControlSoftware>
					<instrumentID>0000000011260721</instrumentID>
				</source>
			</header>
			<dataPoints>
				<positions axis="2Theta" unit="deg">
					<startPosition>71.9856669597368</startPosition>
					<endPosition>75.3329367309533</endPosition>
				</positions>
				<positions axis="Omega" unit="deg">
					<commonPosition>18.2686509226725</commonPosition>
				</positions>
				<positions axis="Phi" unit="deg">
					<commonPosition>-94.99</commonPosition>
				</positions>
				<positions axis="Chi" unit="deg">
					<commonPosition>0</commonPosition>
				</positions>
				<positions axis="Z" unit="mm">
					<commonPosition>8.33</commonPosition>
				</positions>
				<commonCountingTime unit="seconds">0.974</commonCountingTime>
				<counts unit="counts">0 0 0 0 1 0 0 0 0 1 0 1 1 0 1 0 0 0 0 0 0 0 1 0 0 0 0 0 0 0 0 0 0 0 0 0 0 0 0 0 0 0 1 0 0 2 1 0 0 1 1 0 0 0 0 0 0 1 1 0 2 0 1 0 0 0 0 2 0 0 0 0 0 1 0 1 0 0 1 0 0 0 0 0 0 0 0 1 1 1 0 0 0 0 0 0 0 0 0 0 0 1 0 0 0 0 1 0 1 1 0 0 0 0 0 2 0 0 0 0 0 1 0 0 0 0 0 0 0 1 0 0 0 0 0 0 2 0 0 0 1 0 0 0 0 0 0 1 2 3 0 0 0 1 0 0 0 0 0 0 0 1 0 0 1 0 0 0 0 0 0 1 0 0 0 0 0 0 0 0 1 0 0 0 0 0 0 0 0 0 2 0 0 0 2 0 0 0 0 0 0 0 0 0 1 0 0 1 1 0 0 0 0 0 0 0 1 2 1 0 0 0 0 1 0 0 0 1 0 0 0 0 0 2 0 0 0 0 1 0 0 0 1 0 1 0 0 0 0 0 0 2 0 0 2</counts>
			</dataPoints>
		</scan>
		<scan status="Completed" appendNumber="0" scanAxis="2Theta" mode="Continuous">
			<header>
				<startTimeStamp>2024-06-28T16:36:56-04:00</startTimeStamp>
				<endTimeStamp>2024-06-28T17:06:56-04:00</endTimeStamp>
				<author>
					<name>lw627</name>
				</author>
				<source>
					<applicationSoftware version="7.1">Data Collector</applicationSoftware>
					<instrumentControlSoftware version="8.2  20201204">EMPYREAN</instrumentControlSoftware>
					<instrumentID>0000000011260721</instrumentID>
				</source>
			</header>
			<dataPoints>
				<positions axis="2Theta" unit="deg">
					<startPosition>71.9889495304049</startPosition>
					<endPosition>75.3362193016214</endPosition>
				</positions>
				<positions axis="Omega" unit="deg">
					<commonPosition>18.2702922080066</commonPosition>
				</positions>
				<positions axis="Phi" unit="deg">
					<commonPosition>-94.99</commonPosition>
				</positions>
				<positions axis="Chi" unit="deg">
					<commonPosition>0</commonPosition>
				</positions>
				<positions axis="Z" unit="mm">
					<commonPosition>8.33</commonPosition>
				</positions>
				<commonCountingTime unit="seconds">0.974</commonCountingTime>
				<counts unit="counts">1 2 1 0 0 1 1 0 0 2 2 0 1 0 0 1 0 0 0 0 1 0 0 0 0 0 1 0 2 0 0 0 0 1 0 1 0 0 0 0 0 0 1 0 0 1 1 0 2 0 0 2 0 1 0 0 0 0 0 2 0 0 2 0 0 0 1 0 0 1 0 0 1 1 0 2 0 0 2 0 1 0 0 0 0 0 0 0 0 0 1 0 0 0 0 0 0 0 1 0 0 0 1 0 0 1 0 0 0 0 0 0 0 1 1 0 0 0 0 0 0 0 1 0 0 0 0 2 0 0 1 0 0 1 0 0 1 0 1 0 1 0 0 0 0 0 1 1 0 0 0 0 0 0 0 0 0 0 0 1 0 0 1 0 0 1 0 1 0 0 0 0 0 0 0 1 1 0 0 2 0 0 1 0 0 0 0 1 1 0 0 1 0 0 0 0 0 0 0 0 0 0 0 0 0 1 0 0 1 1 0 0 0 0 1 0 0 0 0 0 1 1 2 0 0 0 0 0 0 0 0 0 0 0 0 0 0 0 1 0 1 0 0 0 1 1 0 1 0 0 0 0 0 0 0</counts>
			</dataPoints>
		</scan>
		<scan status="Completed" appendNumber="0" scanAxis="2Theta" mode="Continuous">
			<header>
				<startTimeStamp>2024-06-28T16:36:56-04:00</startTimeStamp>
				<endTimeStamp>2024-06-28T17:06:56-04:00</endTimeStamp>
				<author>
					<name>lw627</name>
				</author>
				<source>
					<applicationSoftware version="7.1">Data Collector</applicationSoftware>
					<instrumentControlSoftware version="8.2  20201204">EMPYREAN</instrumentControlSoftware>
					<instrumentID>0000000011260721</instrumentID>
				</source>
			</header>
			<dataPoints>
				<positions axis="2Theta" unit="deg">
					<startPosition>71.992232101073</startPosition>
					<endPosition>75.3395018722895</endPosition>
				</positions>
				<positions axis="Omega" unit="deg">
					<commonPosition>18.2719334933406</commonPosition>
				</positions>
				<positions axis="Phi" unit="deg">
					<commonPosition>-94.99</commonPosition>
				</positions>
				<positions axis="Chi" unit="deg">
					<commonPosition>0</commonPosition>
				</positions>
				<positions axis="Z" unit="mm">
					<commonPosition>8.33</commonPosition>
				</positions>
				<commonCountingTime unit="seconds">0.974</commonCountingTime>
				<counts unit="counts">0 1 0 0 0 0 0 0 0 1 0 0 0 0 0 0 0 0 1 0 1 0 0 0 0 0 0 0 0 0 0 0 0 0 0 0 0 1 0 0 0 0 0 0 0 0 0 1 0 0 0 1 0 0 0 2 1 0 0 0 0 0 0 0 1 0 0 0 1 0 1 0 0 0 1 0 0 1 0 0 0 0 0 0 0 0 0 0 0 0 0 0 0 0 1 0 0 0 0 0 0 0 1 1 1 0 0 0 1 0 0 0 0 0 0 1 0 0 0 1 0 2 0 0 0 0 0 0 0 0 1 0 0 0 1 0 0 0 1 0 1 0 1 0 1 0 0 0 0 0 1 3 1 2 0 0 0 1 0 1 0 0 0 0 0 0 0 0 0 0 1 1 0 0 0 0 0 0 0 0 0 1 0 1 0 0 0 0 0 1 0 0 0 0 2 1 0 0 2 0 0 0 0 0 0 0 0 0 0 0 0 1 0 1 1 0 0 0 1 0 1 0 0 0 0 0 0 0 1 1 0 0 0 2 0 0 0 0 1 0 0 0 1 0 0 0 0 1 0 1 0 0 1 2 0</counts>
			</dataPoints>
		</scan>
		<scan status="Completed" appendNumber="0" scanAxis="2Theta" mode="Continuous">
			<header>
				<startTimeStamp>2024-06-28T16:36:56-04:00</startTimeStamp>
				<endTimeStamp>2024-06-28T17:06:56-04:00</endTimeStamp>
				<author>
					<name>lw627</name>
				</author>
				<source>
					<applicationSoftware version="7.1">Data Collector</applicationSoftware>
					<instrumentControlSoftware version="8.2  20201204">EMPYREAN</instrumentControlSoftware>
					<instrumentID>0000000011260721</instrumentID>
				</source>
			</header>
			<dataPoints>
				<positions axis="2Theta" unit="deg">
					<startPosition>71.9955146717412</startPosition>
					<endPosition>75.3427844429576</endPosition>
				</positions>
				<positions axis="Omega" unit="deg">
					<commonPosition>18.2735747786747</commonPosition>
				</positions>
				<positions axis="Phi" unit="deg">
					<commonPosition>-94.99</commonPosition>
				</positions>
				<positions axis="Chi" unit="deg">
					<commonPosition>0</commonPosition>
				</positions>
				<positions axis="Z" unit="mm">
					<commonPosition>8.33</commonPosition>
				</positions>
				<commonCountingTime unit="seconds">0.974</commonCountingTime>
				<counts unit="counts">0 1 0 1 0 0 1 0 0 0 0 0 0 1 0 0 1 0 0 0 0 0 1 0 1 0 1 1 0 1 0 1 0 1 0 0 1 0 0 1 1 0 0 0 0 1 0 0 0 0 0 0 0 0 0 2 0 0 0 0 0 1 2 0 0 0 1 0 0 1 0 0 0 0 0 0 0 0 0 1 1 0 0 0 0 1 0 0 2 1 1 1 0 0 0 3 0 0 1 0 0 0 0 0 1 0 0 1 1 1 0 0 1 0 1 0 1 0 0 0 0 0 0 0 1 1 0 0 0 0 3 0 0 2 0 0 1 1 0 0 0 0 1 1 0 0 1 0 0 0 0 0 0 0 1 0 0 0 0 1 1 1 0 1 0 1 0 0 0 1 1 0 1 1 1 0 0 0 0 0 1 0 0 1 0 0 1 1 1 0 0 2 0 0 0 1 0 0 0 1 0 0 0 0 0 0 0 0 0 0 0 0 1 0 0 0 0 1 1 0 0 0 0 0 0 0 0 0 1 0 0 0 0 1 0 0 0 2 0 1 0 1 0 0 0 1 0 0 0 1 0 1 0 0 2</counts>
			</dataPoints>
		</scan>
		<scan status="Completed" appendNumber="0" scanAxis="2Theta" mode="Continuous">
			<header>
				<startTimeStamp>2024-06-28T16:36:56-04:00</startTimeStamp>
				<endTimeStamp>2024-06-28T17:06:56-04:00</endTimeStamp>
				<author>
					<name>lw627</name>
				</author>
				<source>
					<applicationSoftware version="7.1">Data Collector</applicationSoftware>
					<instrumentControlSoftware version="8.2  20201204">EMPYREAN</instrumentControlSoftware>
					<instrumentID>0000000011260721</instrumentID>
				</source>
			</header>
			<dataPoints>
				<positions axis="2Theta" unit="deg">
					<startPosition>71.9987972424093</startPosition>
					<endPosition>75.3460670136258</endPosition>
				</positions>
				<positions axis="Omega" unit="deg">
					<commonPosition>18.2752160640088</commonPosition>
				</positions>
				<positions axis="Phi" unit="deg">
					<commonPosition>-94.99</commonPosition>
				</positions>
				<positions axis="Chi" unit="deg">
					<commonPosition>0</commonPosition>
				</positions>
				<positions axis="Z" unit="mm">
					<commonPosition>8.33</commonPosition>
				</positions>
				<commonCountingTime unit="seconds">0.974</commonCountingTime>
				<counts unit="counts">0 0 1 0 0 0 0 0 0 0 0 0 0 0 0 0 0 0 1 0 0 0 2 1 0 0 0 0 0 0 0 0 0 2 0 0 0 0 0 0 0 0 0 0 0 0 0 0 0 1 0 1 0 0 0 0 0 0 0 0 1 0 0 0 0 1 0 0 0 1 0 0 0 1 0 0 0 0 0 0 0 0 0 0 1 0 0 0 0 1 0 1 1 0 0 0 0 0 0 0 1 0 0 0 0 0 1 0 1 0 0 0 0 0 0 0 0 0 0 1 0 0 0 1 0 1 0 0 0 0 0 0 0 0 0 1 0 1 1 0 0 0 0 0 0 0 0 0 0 0 0 1 0 2 0 0 0 0 0 0 0 1 0 0 1 0 1 0 0 0 0 0 0 0 0 0 0 0 0 0 0 0 0 0 0 0 2 0 0 0 0 0 0 0 1 1 1 0 0 0 0 0 0 0 1 1 0 0 0 2 1 1 1 1 0 0 0 1 0 0 1 0 0 0 0 1 0 1 0 0 0 0 0 1 0 0 1 0 0 0 0 0 0 0 0 0 0 0 0 0 0 1 0 0 0</counts>
			</dataPoints>
		</scan>
		<scan status="Completed" appendNumber="0" scanAxis="2Theta" mode="Continuous">
			<header>
				<startTimeStamp>2024-06-28T16:36:56-04:00</startTimeStamp>
				<endTimeStamp>2024-06-28T17:06:56-04:00</endTimeStamp>
				<author>
					<name>lw627</name>
				</author>
				<source>
					<applicationSoftware version="7.1">Data Collector</applicationSoftware>
					<instrumentControlSoftware version="8.2  20201204">EMPYREAN</instrumentControlSoftware>
					<instrumentID>0000000011260721</instrumentID>
				</source>
			</header>
			<dataPoints>
				<positions axis="2Theta" unit="deg">
					<startPosition>72.0020798130774</startPosition>
					<endPosition>75.3493495842939</endPosition>
				</positions>
				<positions axis="Omega" unit="deg">
					<commonPosition>18.2768573493428</commonPosition>
				</positions>
				<positions axis="Phi" unit="deg">
					<commonPosition>-94.99</commonPosition>
				</positions>
				<positions axis="Chi" unit="deg">
					<commonPosition>0</commonPosition>
				</positions>
				<positions axis="Z" unit="mm">
					<commonPosition>8.33</commonPosition>
				</positions>
				<commonCountingTime unit="seconds">0.974</commonCountingTime>
				<counts unit="counts">1 0 0 0 0 1 0 0 0 0 1 0 0 0 0 0 0 0 0 2 0 0 0 0 2 0 0 0 1 0 1 0 1 0 1 0 0 0 0 0 0 0 0 1 0 0 1 0 1 1 0 1 0 1 1 1 0 1 1 0 0 1 0 0 1 0 0 0 0 0 0 0 0 0 0 0 0 0 0 0 0 1 1 0 1 0 0 2 0 0 0 0 0 0 1 0 0 0 0 1 0 0 0 0 0 0 0 0 0 1 0 0 1 0 0 0 0 0 0 1 0 0 0 0 0 0 0 0 0 0 0 0 0 1 1 0 0 0 1 0 0 1 0 0 0 0 0 0 1 0 0 0 0 0 0 1 1 0 2 0 0 0 0 0 1 0 0 1 0 0 0 0 0 0 0 0 0 1 0 0 0 1 0 0 0 1 0 0 1 1 0 1 0 0 0 0 1 0 0 0 1 0 0 1 0 1 0 0 0 0 0 0 0 0 0 0 0 1 0 1 0 0 0 0 0 0 0 0 0 0 0 0 2 2 0 0 0 0 0 0 0 0 1 0 0 0 0 1 1 1 1 0 1 0 0</counts>
			</dataPoints>
		</scan>
		<scan status="Completed" appendNumber="0" scanAxis="2Theta" mode="Continuous">
			<header>
				<startTimeStamp>2024-06-28T16:36:56-04:00</startTimeStamp>
				<endTimeStamp>2024-06-28T17:06:56-04:00</endTimeStamp>
				<author>
					<name>lw627</name>
				</author>
				<source>
					<applicationSoftware version="7.1">Data Collector</applicationSoftware>
					<instrumentControlSoftware version="8.2  20201204">EMPYREAN</instrumentControlSoftware>
					<instrumentID>0000000011260721</instrumentID>
				</source>
			</header>
			<dataPoints>
				<positions axis="2Theta" unit="deg">
					<startPosition>72.0053623837455</startPosition>
					<endPosition>75.352632154962</endPosition>
				</positions>
				<positions axis="Omega" unit="deg">
					<commonPosition>18.2784986346769</commonPosition>
				</positions>
				<positions axis="Phi" unit="deg">
					<commonPosition>-94.99</commonPosition>
				</positions>
				<positions axis="Chi" unit="deg">
					<commonPosition>0</commonPosition>
				</positions>
				<positions axis="Z" unit="mm">
					<commonPosition>8.33</commonPosition>
				</positions>
				<commonCountingTime unit="seconds">0.974</commonCountingTime>
				<counts unit="counts">1 0 0 0 0 2 1 0 0 0 0 1 1 1 0 0 0 0 2 0 0 0 0 0 0 0 1 0 0 0 0 0 0 0 3 1 0 0 0 0 0 1 0 0 0 1 0 0 0 1 0 1 0 0 0 0 0 0 1 0 0 0 1 1 1 1 0 1 0 0 0 0 0 0 0 1 1 0 2 0 0 0 0 0 1 0 0 0 0 1 0 0 0 1 0 1 0 0 0 0 2 0 0 0 0 2 1 0 0 1 1 0 1 0 0 0 0 0 1 0 0 0 1 0 2 0 0 0 1 0 0 0 0 0 0 1 0 0 0 0 0 0 1 1 0 1 0 0 1 0 0 1 1 1 0 0 0 0 0 0 0 0 0 1 1 0 0 0 0 0 0 0 0 0 0 0 0 1 0 0 0 0 0 0 0 0 0 0 0 0 0 0 2 0 1 0 0 0 0 0 0 0 1 0 0 0 0 0 1 1 1 0 1 0 0 0 0 0 0 0 0 1 0 0 0 0 0 0 0 0 0 0 0 0 0 3 1 1 0 0 0 0 0 0 1 1 0 0 0 1 0 0 0 1 2</counts>
			</dataPoints>
		</scan>
		<scan status="Completed" appendNumber="0" scanAxis="2Theta" mode="Continuous">
			<header>
				<startTimeStamp>2024-06-28T16:36:56-04:00</startTimeStamp>
				<endTimeStamp>2024-06-28T17:06:56-04:00</endTimeStamp>
				<author>
					<name>lw627</name>
				</author>
				<source>
					<applicationSoftware version="7.1">Data Collector</applicationSoftware>
					<instrumentControlSoftware version="8.2  20201204">EMPYREAN</instrumentControlSoftware>
					<instrumentID>0000000011260721</instrumentID>
				</source>
			</header>
			<dataPoints>
				<positions axis="2Theta" unit="deg">
					<startPosition>72.0086449544137</startPosition>
					<endPosition>75.3559147256301</endPosition>
				</positions>
				<positions axis="Omega" unit="deg">
					<commonPosition>18.280139920011</commonPosition>
				</positions>
				<positions axis="Phi" unit="deg">
					<commonPosition>-94.99</commonPosition>
				</positions>
				<positions axis="Chi" unit="deg">
					<commonPosition>0</commonPosition>
				</positions>
				<positions axis="Z" unit="mm">
					<commonPosition>8.33</commonPosition>
				</positions>
				<commonCountingTime unit="seconds">0.974</commonCountingTime>
				<counts unit="counts">0 0 1 0 1 0 0 0 0 0 0 0 0 0 0 0 0 0 1 0 0 0 0 0 0 0 0 1 0 0 0 0 0 1 0 0 0 1 1 0 2 0 1 0 0 0 0 1 0 0 0 0 0 1 0 0 2 0 0 1 0 0 0 0 0 2 1 0 1 0 0 1 0 0 0 0 0 0 0 0 1 0 0 1 0 0 1 0 1 0 2 0 0 1 0 0 0 0 0 1 1 0 0 0 0 0 0 0 0 0 2 0 1 0 0 1 0 1 0 0 0 1 0 0 0 1 1 0 0 0 0 0 1 0 0 0 1 0 0 0 0 0 0 0 0 1 0 0 2 0 1 0 1 0 0 0 0 1 0 0 0 0 0 1 0 1 0 0 0 0 0 0 0 1 0 0 0 0 0 1 1 0 0 0 0 0 0 1 2 0 0 1 0 1 0 0 0 1 0 0 0 0 0 0 0 1 0 0 0 0 0 0 0 0 1 0 1 0 0 0 0 0 0 0 0 0 0 1 0 1 0 0 1 0 0 0 1 1 0 0 0 0 0 0 0 2 1 1 0 0 1 0 0 0 1</counts>
			</dataPoints>
		</scan>
		<scan status="Completed" appendNumber="0" scanAxis="2Theta" mode="Continuous">
			<header>
				<startTimeStamp>2024-06-28T16:36:56-04:00</startTimeStamp>
				<endTimeStamp>2024-06-28T17:06:56-04:00</endTimeStamp>
				<author>
					<name>lw627</name>
				</author>
				<source>
					<applicationSoftware version="7.1">Data Collector</applicationSoftware>
					<instrumentControlSoftware version="8.2  20201204">EMPYREAN</instrumentControlSoftware>
					<instrumentID>0000000011260721</instrumentID>
				</source>
			</header>
			<dataPoints>
				<positions axis="2Theta" unit="deg">
					<startPosition>72.0119275250818</startPosition>
					<endPosition>75.3591972962983</endPosition>
				</positions>
				<positions axis="Omega" unit="deg">
					<commonPosition>18.281781205345</commonPosition>
				</positions>
				<positions axis="Phi" unit="deg">
					<commonPosition>-94.99</commonPosition>
				</positions>
				<positions axis="Chi" unit="deg">
					<commonPosition>0</commonPosition>
				</positions>
				<positions axis="Z" unit="mm">
					<commonPosition>8.33</commonPosition>
				</positions>
				<commonCountingTime unit="seconds">0.974</commonCountingTime>
				<counts unit="counts">0 1 0 1 0 0 0 0 0 0 0 0 0 2 0 0 1 0 0 1 0 1 0 0 1 1 0 1 0 1 0 0 0 0 0 1 0 1 0 0 0 0 0 0 1 0 0 0 0 0 0 0 0 1 0 0 0 0 0 0 1 0 0 1 0 0 0 0 1 0 1 0 0 0 1 0 0 0 2 1 0 0 0 3 2 2 0 0 0 0 0 1 0 0 0 1 0 0 0 0 0 0 0 1 1 1 0 0 0 0 1 0 0 0 0 0 1 0 0 0 0 0 0 0 0 1 0 0 1 0 0 1 0 0 1 0 0 0 0 0 0 0 0 0 0 0 2 0 0 3 0 0 1 0 0 1 1 0 0 0 0 1 0 1 0 0 0 0 0 0 0 2 0 0 0 2 0 2 0 0 0 0 0 0 0 0 1 0 0 0 0 1 0 0 1 0 0 1 1 0 0 0 1 1 1 0 0 0 0 0 0 1 0 0 1 0 0 0 0 1 0 0 0 0 0 0 1 1 0 1 0 0 0 0 1 3 0 0 0 1 0 0 0 0 0 0 0 0 1 0 0 0 0 1 0</counts>
			</dataPoints>
		</scan>
		<scan status="Completed" appendNumber="0" scanAxis="2Theta" mode="Continuous">
			<header>
				<startTimeStamp>2024-06-28T16:36:56-04:00</startTimeStamp>
				<endTimeStamp>2024-06-28T17:06:56-04:00</endTimeStamp>
				<author>
					<name>lw627</name>
				</author>
				<source>
					<applicationSoftware version="7.1">Data Collector</applicationSoftware>
					<instrumentControlSoftware version="8.2  20201204">EMPYREAN</instrumentControlSoftware>
					<instrumentID>0000000011260721</instrumentID>
				</source>
			</header>
			<dataPoints>
				<positions axis="2Theta" unit="deg">
					<startPosition>72.0152100957499</startPosition>
					<endPosition>75.3624798669664</endPosition>
				</positions>
				<positions axis="Omega" unit="deg">
					<commonPosition>18.2834224906791</commonPosition>
				</positions>
				<positions axis="Phi" unit="deg">
					<commonPosition>-94.99</commonPosition>
				</positions>
				<positions axis="Chi" unit="deg">
					<commonPosition>0</commonPosition>
				</positions>
				<positions axis="Z" unit="mm">
					<commonPosition>8.33</commonPosition>
				</positions>
				<commonCountingTime unit="seconds">0.974</commonCountingTime>
				<counts unit="counts">0 1 0 0 0 1 1 0 0 0 0 0 0 0 1 1 0 1 0 0 2 0 0 0 0 0 0 1 1 0 0 1 1 0 0 0 1 2 0 1 2 0 0 0 1 0 0 0 0 0 0 0 0 0 0 0 0 0 0 0 0 1 0 0 0 0 0 0 1 0 0 0 1 0 0 0 0 0 1 0 0 0 0 0 0 0 1 0 0 0 0 1 1 0 1 0 0 1 0 1 1 0 0 1 0 0 0 0 0 0 0 0 0 0 0 0 0 0 0 0 0 0 0 1 2 1 0 1 1 0 0 0 0 0 0 0 0 3 0 0 0 1 0 0 1 0 1 0 0 0 0 0 0 0 1 0 1 0 1 0 0 0 0 0 0 1 0 0 1 1 1 0 0 0 1 0 1 0 0 0 0 0 0 0 1 0 2 0 1 0 0 0 0 0 1 2 0 0 0 1 1 0 1 0 0 1 1 0 1 1 0 0 0 0 0 0 1 0 1 0 0 0 0 0 0 0 1 1 0 0 2 1 0 0 1 0 0 0 1 0 0 1 0 1 0 2 0 0 0 0 1 1 0 0 0</counts>
			</dataPoints>
		</scan>
		<scan status="Completed" appendNumber="0" scanAxis="2Theta" mode="Continuous">
			<header>
				<startTimeStamp>2024-06-28T16:36:56-04:00</startTimeStamp>
				<endTimeStamp>2024-06-28T17:06:56-04:00</endTimeStamp>
				<author>
					<name>lw627</name>
				</author>
				<source>
					<applicationSoftware version="7.1">Data Collector</applicationSoftware>
					<instrumentControlSoftware version="8.2  20201204">EMPYREAN</instrumentControlSoftware>
					<instrumentID>0000000011260721</instrumentID>
				</source>
			</header>
			<dataPoints>
				<positions axis="2Theta" unit="deg">
					<startPosition>72.018492666418</startPosition>
					<endPosition>75.3657624376345</endPosition>
				</positions>
				<positions axis="Omega" unit="deg">
					<commonPosition>18.2850637760131</commonPosition>
				</positions>
				<positions axis="Phi" unit="deg">
					<commonPosition>-94.99</commonPosition>
				</positions>
				<positions axis="Chi" unit="deg">
					<commonPosition>0</commonPosition>
				</positions>
				<positions axis="Z" unit="mm">
					<commonPosition>8.33</commonPosition>
				</positions>
				<commonCountingTime unit="seconds">0.974</commonCountingTime>
				<counts unit="counts">0 1 0 0 0 0 0 0 0 0 0 0 1 1 0 0 0 0 2 0 2 1 0 0 0 0 1 1 0 0 0 0 1 0 2 1 0 0 2 2 0 1 0 0 1 0 0 0 0 0 0 0 0 0 0 0 0 2 1 0 0 1 0 1 0 0 0 0 1 0 1 0 1 1 1 0 0 0 0 0 1 0 0 0 2 0 0 0 0 0 1 1 1 2 0 0 0 1 0 0 0 0 0 0 0 0 0 1 0 0 0 1 0 0 0 0 0 1 0 0 1 2 0 0 0 0 0 0 0 0 0 0 0 0 0 0 2 0 0 1 0 0 1 0 0 1 0 1 0 1 2 0 0 1 1 0 0 0 0 1 1 1 1 1 0 0 0 0 0 0 0 0 1 0 0 1 1 0 0 0 0 0 1 0 0 0 1 0 2 0 0 0 0 1 0 1 1 1 0 0 1 0 0 0 0 0 2 1 0 0 0 0 0 0 1 0 0 0 1 1 0 0 0 0 0 0 0 0 0 0 0 0 0 0 0 0 0 0 0 0 0 1 0 0 0 1 1 0 0 1 1 0 0 0 1</counts>
			</dataPoints>
		</scan>
		<scan status="Completed" appendNumber="0" scanAxis="2Theta" mode="Continuous">
			<header>
				<startTimeStamp>2024-06-28T16:36:56-04:00</startTimeStamp>
				<endTimeStamp>2024-06-28T17:06:56-04:00</endTimeStamp>
				<author>
					<name>lw627</name>
				</author>
				<source>
					<applicationSoftware version="7.1">Data Collector</applicationSoftware>
					<instrumentControlSoftware version="8.2  20201204">EMPYREAN</instrumentControlSoftware>
					<instrumentID>0000000011260721</instrumentID>
				</source>
			</header>
			<dataPoints>
				<positions axis="2Theta" unit="deg">
					<startPosition>72.0217752370862</startPosition>
					<endPosition>75.3690450083026</endPosition>
				</positions>
				<positions axis="Omega" unit="deg">
					<commonPosition>18.2867050613472</commonPosition>
				</positions>
				<positions axis="Phi" unit="deg">
					<commonPosition>-94.99</commonPosition>
				</positions>
				<positions axis="Chi" unit="deg">
					<commonPosition>0</commonPosition>
				</positions>
				<positions axis="Z" unit="mm">
					<commonPosition>8.33</commonPosition>
				</positions>
				<commonCountingTime unit="seconds">0.974</commonCountingTime>
				<counts unit="counts">0 0 1 1 1 1 0 1 0 0 0 0 0 1 0 0 1 0 0 0 0 1 1 0 0 0 1 0 0 0 0 0 0 1 1 0 0 0 0 0 1 0 1 0 0 0 1 0 0 3 0 0 0 0 0 1 1 0 0 0 0 1 0 0 0 1 0 1 1 0 0 0 0 0 0 1 0 0 1 0 0 0 0 1 0 0 0 0 0 0 0 0 0 0 0 1 0 1 0 0 1 0 0 0 0 1 0 1 1 0 0 0 0 0 0 0 0 0 0 0 1 0 0 0 0 0 0 0 0 0 0 0 0 0 1 0 0 0 0 0 0 0 1 0 0 0 0 0 0 0 0 1 1 0 0 0 0 0 0 0 1 0 0 0 0 0 0 0 0 1 0 0 0 1 1 0 0 0 0 0 0 0 0 0 2 0 0 0 0 0 0 1 1 0 0 0 0 0 0 0 0 0 0 0 0 0 0 0 0 0 0 0 0 0 0 1 0 0 0 0 1 0 1 0 0 0 0 0 0 0 0 0 0 0 0 0 0 1 0 0 1 0 0 1 0 0 0 0 0 0 0 0 1 0 1</counts>
			</dataPoints>
		</scan>
		<scan status="Completed" appendNumber="0" scanAxis="2Theta" mode="Continuous">
			<header>
				<startTimeStamp>2024-06-28T16:36:56-04:00</startTimeStamp>
				<endTimeStamp>2024-06-28T17:06:56-04:00</endTimeStamp>
				<author>
					<name>lw627</name>
				</author>
				<source>
					<applicationSoftware version="7.1">Data Collector</applicationSoftware>
					<instrumentControlSoftware version="8.2  20201204">EMPYREAN</instrumentControlSoftware>
					<instrumentID>0000000011260721</instrumentID>
				</source>
			</header>
			<dataPoints>
				<positions axis="2Theta" unit="deg">
					<startPosition>72.0250578077543</startPosition>
					<endPosition>75.3723275789708</endPosition>
				</positions>
				<positions axis="Omega" unit="deg">
					<commonPosition>18.2883463466813</commonPosition>
				</positions>
				<positions axis="Phi" unit="deg">
					<commonPosition>-94.99</commonPosition>
				</positions>
				<positions axis="Chi" unit="deg">
					<commonPosition>0</commonPosition>
				</positions>
				<positions axis="Z" unit="mm">
					<commonPosition>8.33</commonPosition>
				</positions>
				<commonCountingTime unit="seconds">0.974</commonCountingTime>
[...]
					<commonPosition>0</commonPosition>
				</positions>
				<positions axis="Z" unit="mm">
					<commonPosition>8.33</commonPosition>
				</positions>
				<commonCountingTime unit="seconds">0.974</commonCountingTime>
				<counts unit="counts">2 0 0 1 0 0 0 0 0 0 0 0 1 2 0 1 0 0 1 0 1 1 0 0 0 0 0 0 0 0 0 0 0 0 0 1 0 1 0 0 1 0 1 0 2 1 0 0 2 0 0 0 0 0 0 0 1 0 0 0 0 1 0 0 0 0 0 0 0 0 1 0 1 0 0 1 0 0 0 0 0 1 0 0 0 0 0 0 0 0 1 0 0 0 1 0 0 0 2 0 1 0 1 1 0 0 0 0 0 0 0 0 0 1 0 0 0 0 0 0 0 0 0 0 1 0 0 0 1 1 0 0 1 1 0 0 0 1 0 0 0 0 0 0 0 0 1 0 0 0 1 0 0 1 0 0 0 1 1 0 1 0 0 0 0 0 0 1 1 0 0 0 0 0 1 0 1 0 0 0 0 0 1 0 1 0 0 0 0 0 0 1 0 1 0 1 3 0 0 0 1 0 0 0 1 0 0 0 1 0 0 0 0 0 0 1 0 0 0 0 1 2 0 0 0 0 0 0 1 0 1 0 0 0 1 1 0 1 0 0 0 0 0 0 0 0 1 0 0 0 1 0 0 0 0</counts>
			</dataPoints>
		</scan>
		<scan status="Completed" appendNumber="0" scanAxis="2Theta" mode="Continuous">
			<header>
				<startTimeStamp>2024-06-28T16:36:56-04:00</startTimeStamp>
				<endTimeStamp>2024-06-28T17:06:56-04:00</endTimeStamp>
				<author>
					<name>lw627</name>
				</author>
				<source>
					<applicationSoftware version="7.1">Data Collector</applicationSoftware>
					<instrumentControlSoftware version="8.2  20201204">EMPYREAN</instrumentControlSoftware>
					<instrumentID>0000000011260721</instrumentID>
				</source>
			</header>
			<dataPoints>
				<positions axis="2Theta" unit="deg">
					<startPosition>77.9205547277105</startPosition>
					<endPosition>81.267824498927</endPosition>
				</positions>
				<positions axis="Omega" unit="deg">
					<commonPosition>21.2360948066594</commonPosition>
				</positions>
				<positions axis="Phi" unit="deg">
					<commonPosition>-94.99</commonPosition>
				</positions>
				<positions axis="Chi" unit="deg">
					<commonPosition>0</commonPosition>
				</positions>
				<positions axis="Z" unit="mm">
					<commonPosition>8.33</commonPosition>
				</positions>
				<commonCountingTime unit="seconds">0.974</commonCountingTime>
				<counts unit="counts">0 0 0 1 0 0 0 0 0 1 0 0 1 1 1 2 0 0 0 0 0 1 0 0 0 0 0 0 1 0 0 1 0 0 0 0 0 0 0 0 0 0 1 1 0 1 0 0 0 0 1 0 0 0 0 0 0 0 0 0 0 2 0 0 0 0 0 0 1 1 0 0 1 1 0 0 0 0 1 0 0 0 2 0 0 1 0 0 0 2 0 0 0 0 2 1 0 1 0 2 1 0 0 0 0 0 1 0 0 0 0 0 0 0 0 0 1 0 2 0 0 0 0 0 0 0 1 0 0 0 0 0 0 0 0 0 0 0 0 2 0 0 0 0 2 0 0 0 0 0 0 1 1 0 1 0 0 0 1 0 0 0 1 0 0 0 0 1 0 0 0 1 2 0 0 0 0 0 0 0 0 0 0 1 0 1 0 1 0 0 0 0 1 0 0 1 1 0 0 1 1 0 0 0 0 0 1 0 0 0 0 0 0 0 0 0 0 1 1 0 1 0 0 0 0 0 0 0 1 0 0 0 0 0 0 0 0 0 0 0 2 1 0 0 0 0 0 0 0 0 0 0 0 0 0</counts>
			</dataPoints>
		</scan>
		<scan status="Completed" appendNumber="0" scanAxis="2Theta" mode="Continuous">
			<header>
				<startTimeStamp>2024-06-28T16:36:56-04:00</startTimeStamp>
				<endTimeStamp>2024-06-28T17:06:56-04:00</endTimeStamp>
				<author>
					<name>lw627</name>
				</author>
				<source>
					<applicationSoftware version="7.1">Data Collector</applicationSoftware>
					<instrumentControlSoftware version="8.2  20201204">EMPYREAN</instrumentControlSoftware>
					<instrumentID>0000000011260721</instrumentID>
				</source>
			</header>
			<dataPoints>
				<positions axis="2Theta" unit="deg">
					<startPosition>77.9238372983786</startPosition>
					<endPosition>81.2711070695951</endPosition>
				</positions>
				<positions axis="Omega" unit="deg">
					<commonPosition>21.2377360919934</commonPosition>
				</positions>
				<positions axis="Phi" unit="deg">
					<commonPosition>-94.99</commonPosition>
				</positions>
				<positions axis="Chi" unit="deg">
					<commonPosition>0</commonPosition>
				</positions>
				<positions axis="Z" unit="mm">
					<commonPosition>8.33</commonPosition>
				</positions>
				<commonCountingTime unit="seconds">0.974</commonCountingTime>
				<counts unit="counts">1 0 1 2 0 1 0 0 0 0 0 1 0 0 0 0 0 0 0 0 0 0 0 2 0 1 0 2 0 1 1 0 2 0 0 0 0 0 0 0 1 1 0 0 0 0 1 0 0 0 0 1 0 0 0 1 0 0 1 1 0 0 0 1 1 0 0 0 1 0 0 0 0 0 0 0 1 1 0 0 1 0 0 0 0 0 0 0 0 0 0 0 0 0 0 1 0 2 0 0 0 0 0 0 0 1 0 0 1 1 0 0 0 1 0 0 1 1 0 1 1 2 0 0 0 0 0 1 0 1 0 0 0 1 0 1 0 0 1 0 1 0 0 1 0 0 0 2 1 0 0 0 0 0 0 0 1 0 0 0 1 1 0 0 1 1 0 0 1 0 0 0 0 0 0 0 0 1 0 0 0 0 0 0 0 0 1 1 0 0 1 0 0 0 0 0 1 0 0 0 0 0 0 0 2 1 0 0 0 1 1 0 0 0 1 0 0 0 0 0 0 0 1 0 0 1 0 0 1 0 0 0 0 0 1 0 0 0 0 0 0 0 0 2 0 0 0 0 1 0 0 0 0 0 0</counts>
			</dataPoints>
		</scan>
		<scan status="Completed" appendNumber="0" scanAxis="2Theta" mode="Continuous">
			<header>
				<startTimeStamp>2024-06-28T16:36:56-04:00</startTimeStamp>
				<endTimeStamp>2024-06-28T17:06:56-04:00</endTimeStamp>
				<author>
					<name>lw627</name>
				</author>
				<source>
					<applicationSoftware version="7.1">Data Collector</applicationSoftware>
					<instrumentControlSoftware version="8.2  20201204">EMPYREAN</instrumentControlSoftware>
					<instrumentID>0000000011260721</instrumentID>
				</source>
			</header>
			<dataPoints>
				<positions axis="2Theta" unit="deg">
					<startPosition>77.9271198690467</startPosition>
					<endPosition>81.2743896402632</endPosition>
				</positions>
				<positions axis="Omega" unit="deg">
					<commonPosition>21.2393773773275</commonPosition>
				</positions>
				<positions axis="Phi" unit="deg">
					<commonPosition>-94.99</commonPosition>
				</positions>
				<positions axis="Chi" unit="deg">
					<commonPosition>0</commonPosition>
				</positions>
				<positions axis="Z" unit="mm">
					<commonPosition>8.33</commonPosition>
				</positions>
				<commonCountingTime unit="seconds">0.974</commonCountingTime>
				<counts unit="counts">0 0 0 0 1 0 1 0 1 0 0 0 0 0 0 0 0 0 1 0 0 1 0 0 0 0 0 1 1 0 0 0 0 1 0 0 0 1 0 1 1 1 0 0 1 0 0 1 0 1 0 0 1 0 0 0 1 0 0 0 1 1 1 0 0 0 0 2 0 0 0 1 0 0 0 0 0 0 0 0 0 1 3 0 0 0 0 0 0 0 0 1 0 0 1 1 1 0 0 1 0 0 0 0 1 1 0 0 1 0 1 0 1 0 0 1 0 0 0 1 0 0 0 0 0 0 0 1 0 0 0 0 0 1 0 0 0 0 0 0 1 0 1 0 0 0 0 0 0 0 0 0 0 0 0 0 0 0 0 0 2 0 0 0 1 0 0 1 0 0 1 0 0 1 0 0 1 0 0 0 0 0 0 0 0 0 0 1 0 0 0 0 1 0 0 0 0 0 0 0 0 0 0 0 0 0 1 1 0 0 0 0 0 0 0 0 0 0 0 0 0 0 0 0 0 0 1 0 0 1 0 0 1 0 1 0 0 0 0 1 0 1 0 0 0 0 0 0 0 0 0 0 0 0 0</counts>
			</dataPoints>
		</scan>
		<scan status="Completed" appendNumber="0" scanAxis="2Theta" mode="Continuous">
			<header>
				<startTimeStamp>2024-06-28T16:36:56-04:00</startTimeStamp>
				<endTimeStamp>2024-06-28T17:06:56-04:00</endTimeStamp>
				<author>
					<name>lw627</name>
				</author>
				<source>
					<applicationSoftware version="7.1">Data Collector</applicationSoftware>
					<instrumentControlSoftware version="8.2  20201204">EMPYREAN</instrumentControlSoftware>
					<instrumentID>0000000011260721</instrumentID>
				</source>
			</header>
			<dataPoints>
				<positions axis="2Theta" unit="deg">
					<startPosition>77.9304024397149</startPosition>
					<endPosition>81.2776722109313</endPosition>
				</positions>
				<positions axis="Omega" unit="deg">
					<commonPosition>21.2410186626616</commonPosition>
				</positions>
				<positions axis="Phi" unit="deg">
					<commonPosition>-94.99</commonPosition>
				</positions>
				<positions axis="Chi" unit="deg">
					<commonPosition>0</commonPosition>
				</positions>
				<positions axis="Z" unit="mm">
					<commonPosition>8.33</commonPosition>
				</positions>
				<commonCountingTime unit="seconds">0.974</commonCountingTime>
				<counts unit="counts">0 1 0 0 1 0 2 0 1 0 0 0 0 0 0 0 2 1 0 0 0 1 0 1 2 0 0 0 0 0 0 1 0 0 1 0 0 0 0 0 0 0 1 1 0 0 0 0 0 0 0 0 0 0 0 0 0 0 0 2 0 0 0 0 0 0 0 0 0 0 2 0 0 0 0 0 0 1 0 0 0 0 0 1 0 0 0 0 0 0 0 0 0 0 0 0 0 0 0 0 0 0 0 0 0 1 1 0 0 0 0 1 1 1 0 1 0 1 0 0 0 0 0 0 1 0 1 1 0 0 0 0 0 0 0 0 0 0 0 0 1 1 0 0 0 0 0 0 0 0 0 0 0 0 0 0 0 1 0 0 0 1 0 0 1 0 0 0 0 0 0 0 0 0 0 1 0 0 0 0 0 0 1 0 0 0 2 1 0 0 0 0 0 0 0 0 0 0 0 0 0 0 0 1 1 0 0 0 1 1 0 0 1 2 0 0 0 1 0 0 1 1 1 0 0 0 0 0 0 0 0 2 0 0 0 1 0 1 0 1 1 0 0 0 0 0 0 1 0 0 1 0 0 0 1</counts>
			</dataPoints>
		</scan>
		<scan status="Completed" appendNumber="0" scanAxis="2Theta" mode="Continuous">
			<header>
				<startTimeStamp>2024-06-28T16:36:56-04:00</startTimeStamp>
				<endTimeStamp>2024-06-28T17:06:56-04:00</endTimeStamp>
				<author>
					<name>lw627</name>
				</author>
				<source>
					<applicationSoftware version="7.1">Data Collector</applicationSoftware>
					<instrumentControlSoftware version="8.2  20201204">EMPYREAN</instrumentControlSoftware>
					<instrumentID>0000000011260721</instrumentID>
				</source>
			</header>
			<dataPoints>
				<positions axis="2Theta" unit="deg">
					<startPosition>77.933685010383</startPosition>
					<endPosition>81.2809547815995</endPosition>
				</positions>
				<positions axis="Omega" unit="deg">
					<commonPosition>21.2426599479956</commonPosition>
				</positions>
				<positions axis="Phi" unit="deg">
					<commonPosition>-94.99</commonPosition>
				</positions>
				<positions axis="Chi" unit="deg">
					<commonPosition>0</commonPosition>
				</positions>
				<positions axis="Z" unit="mm">
					<commonPosition>8.33</commonPosition>
				</positions>
				<commonCountingTime unit="seconds">0.974</commonCountingTime>
				<counts unit="counts">0 2 0 0 1 0 0 0 0 0 0 0 0 0 0 0 0 0 0 0 0 0 0 0 0 0 1 1 0 0 0 0 0 2 2 0 0 1 2 1 1 0 1 0 0 0 0 0 0 1 1 0 0 0 0 0 0 0 0 0 0 0 0 1 1 1 0 0 0 0 0 0 0 0 2 0 0 1 0 0 1 0 0 0 0 0 1 1 1 0 0 0 1 0 1 0 0 0 0 0 0 0 0 0 0 1 0 0 1 0 0 0 1 0 0 0 0 0 0 0 0 1 0 0 0 1 1 0 0 1 0 0 0 0 1 1 0 0 0 0 1 0 0 0 0 0 0 0 2 0 0 1 1 1 0 1 0 1 0 0 1 2 0 1 0 1 0 0 0 0 0 1 0 0 0 0 1 0 0 0 0 0 0 0 1 0 1 0 0 0 0 0 1 0 0 0 0 1 0 0 0 0 0 0 0 1 1 0 1 0 1 0 1 0 0 0 0 1 0 0 0 0 0 0 0 1 0 0 0 1 0 0 0 0 0 0 0 0 0 1 0 0 0 0 0 0 0 0 0 0 0 0 0 0 0</counts>
			</dataPoints>
		</scan>
		<scan status="Completed" appendNumber="0" scanAxis="2Theta" mode="Continuous">
			<header>
				<startTimeStamp>2024-06-28T16:36:56-04:00</startTimeStamp>
				<endTimeStamp>2024-06-28T17:06:56-04:00</endTimeStamp>
				<author>
					<name>lw627</name>
				</author>
				<source>
					<applicationSoftware version="7.1">Data Collector</applicationSoftware>
					<instrumentControlSoftware version="8.2  20201204">EMPYREAN</instrumentControlSoftware>
					<instrumentID>0000000011260721</instrumentID>
				</source>
			</header>
			<dataPoints>
				<positions axis="2Theta" unit="deg">
					<startPosition>77.9369675810511</startPosition>
					<endPosition>81.2842373522676</endPosition>
				</positions>
				<positions axis="Omega" unit="deg">
					<commonPosition>21.2443012333297</commonPosition>
				</positions>
				<positions axis="Phi" unit="deg">
					<commonPosition>-94.99</commonPosition>
				</positions>
				<positions axis="Chi" unit="deg">
					<commonPosition>0</commonPosition>
				</positions>
				<positions axis="Z" unit="mm">
					<commonPosition>8.33</commonPosition>
				</positions>
				<commonCountingTime unit="seconds">0.974</commonCountingTime>
				<counts unit="counts">0 0 0 0 0 0 1 1 1 0 0 0 0 1 2 0 0 0 1 0 0 0 0 0 0 0 0 0 0 0 1 0 0 0 0 0 0 0 0 0 0 0 0 0 1 1 0 0 0 0 0 0 1 1 0 1 1 0 0 0 0 1 0 0 0 0 0 0 0 0 0 0 2 0 0 0 0 0 1 1 0 0 0 1 0 0 0 0 1 0 0 0 0 0 0 2 1 0 0 0 0 2 0 0 0 2 0 0 0 0 1 0 0 0 0 0 0 0 0 0 0 0 0 0 1 0 0 0 1 0 0 0 0 0 0 0 1 0 0 0 0 0 0 0 1 0 0 0 0 0 0 1 0 1 1 0 2 0 1 0 0 0 0 0 0 0 0 0 0 0 0 0 0 0 1 0 0 0 1 0 0 0 0 0 0 0 0 0 0 0 0 0 0 0 0 0 0 1 0 2 0 0 1 0 0 0 0 1 0 0 0 0 1 0 0 0 1 0 0 0 0 0 0 0 1 0 0 1 0 0 0 0 0 1 0 0 0 0 0 0 0 2 0 0 0 0 0 0 0 0 0 0 0 0 0</counts>
			</dataPoints>
		</scan>
		<scan status="Completed" appendNumber="0" scanAxis="2Theta" mode="Continuous">
			<header>
				<startTimeStamp>2024-06-28T16:36:56-04:00</startTimeStamp>
				<endTimeStamp>2024-06-28T17:06:56-04:00</endTimeStamp>
				<author>
					<name>lw627</name>
				</author>
				<source>
					<applicationSoftware version="7.1">Data Collector</applicationSoftware>
					<instrumentControlSoftware version="8.2  20201204">EMPYREAN</instrumentControlSoftware>
					<instrumentID>0000000011260721</instrumentID>
				</source>
			</header>
			<dataPoints>
				<positions axis="2Theta" unit="deg">
					<startPosition>77.9402501517193</startPosition>
					<endPosition>81.2875199229357</endPosition>
				</positions>
				<positions axis="Omega" unit="deg">
					<commonPosition>21.2459425186637</commonPosition>
				</positions>
				<positions axis="Phi" unit="deg">
					<commonPosition>-94.99</commonPosition>
				</positions>
				<positions axis="Chi" unit="deg">
					<commonPosition>0</commonPosition>
				</positions>
				<positions axis="Z" unit="mm">
					<commonPosition>8.33</commonPosition>
				</positions>
				<commonCountingTime unit="seconds">0.974</commonCountingTime>
				<counts unit="counts">0 1 0 1 0 0 0 0 0 0 0 0 0 0 1 0 0 0 1 0 0 1 1 0 0 2 0 1 1 0 0 0 0 0 0 1 1 0 0 0 0 0 1 0 1 0 0 0 1 0 1 0 0 0 0 0 0 0 0 1 0 1 0 0 0 1 0 0 0 0 0 1 0 0 0 0 2 0 0 0 1 0 0 0 1 1 0 0 0 0 0 0 1 1 1 1 0 0 0 0 0 0 0 1 0 0 0 1 1 0 0 0 0 1 1 2 0 0 0 0 0 0 1 1 0 1 0 0 0 0 0 0 0 0 0 1 0 0 0 0 0 1 0 0 0 0 0 0 0 0 0 0 0 0 0 0 0 0 0 0 1 0 0 0 2 0 0 1 0 1 0 0 0 0 0 0 0 0 0 0 2 0 0 1 0 0 0 0 0 0 0 0 1 0 0 0 0 0 1 0 0 0 0 0 0 0 0 0 0 0 0 0 0 0 0 0 0 0 0 0 0 0 0 0 1 0 0 0 0 0 0 0 0 0 1 0 0 0 0 0 0 1 2 1 0 0 2 0 0 0 0 0 0 0 0</counts>
			</dataPoints>
		</scan>
		<scan status="Completed" appendNumber="0" scanAxis="2Theta" mode="Continuous">
			<header>
				<startTimeStamp>2024-06-28T16:36:56-04:00</startTimeStamp>
				<endTimeStamp>2024-06-28T17:06:56-04:00</endTimeStamp>
				<author>
					<name>lw627</name>
				</author>
				<source>
					<applicationSoftware version="7.1">Data Collector</applicationSoftware>
					<instrumentControlSoftware version="8.2  20201204">EMPYREAN</instrumentControlSoftware>
					<instrumentID>0000000011260721</instrumentID>
				</source>
			</header>
			<dataPoints>
				<positions axis="2Theta" unit="deg">
					<startPosition>77.9435327223874</startPosition>
					<endPosition>81.2908024936038</endPosition>
				</positions>
				<positions axis="Omega" unit="deg">
					<commonPosition>21.2475838039978</commonPosition>
				</positions>
				<positions axis="Phi" unit="deg">
					<commonPosition>-94.99</commonPosition>
				</positions>
				<positions axis="Chi" unit="deg">
					<commonPosition>0</commonPosition>
				</positions>
				<positions axis="Z" unit="mm">
					<commonPosition>8.33</commonPosition>
				</positions>
				<commonCountingTime unit="seconds">0.974</commonCountingTime>
				<counts unit="counts">1 0 0 1 0 0 0 1 1 2 0 0 0 0 0 0 0 0 1 0 0 0 1 0 0 2 0 0 0 0 0 0 0 0 0 1 0 0 0 0 0 0 0 1 0 1 0 0 0 0 0 0 0 0 1 0 0 0 0 0 0 0 1 1 0 0 0 0 0 1 0 0 1 0 1 0 1 0 0 0 0 0 0 1 0 0 0 0 0 0 1 0 0 0 1 0 1 0 0 0 0 0 1 0 1 0 0 0 0 0 1 0 0 0 0 0 0 0 0 0 0 0 0 0 0 0 0 0 0 0 0 0 0 0 0 0 0 0 0 0 0 0 0 0 0 0 0 1 0 0 0 0 0 0 1 0 0 0 0 0 1 0 2 0 0 0 1 0 0 0 0 0 0 0 0 1 1 0 0 2 0 0 0 0 0 0 0 1 0 0 1 0 2 1 0 0 0 0 1 1 0 0 1 0 0 0 0 1 0 0 0 0 0 0 0 0 0 0 1 0 1 1 1 0 0 1 0 0 0 0 0 1 0 1 0 0 0 0 0 0 1 0 0 0 0 0 0 1 0 0 0 0 2 0 1</counts>
			</dataPoints>
		</scan>
		<scan status="Completed" appendNumber="0" scanAxis="2Theta" mode="Continuous">
			<header>
				<startTimeStamp>2024-06-28T16:36:56-04:00</startTimeStamp>
				<endTimeStamp>2024-06-28T17:06:56-04:00</endTimeStamp>
				<author>
					<name>lw627</name>
				</author>
				<source>
					<applicationSoftware version="7.1">Data Collector</applicationSoftware>
					<instrumentControlSoftware version="8.2  20201204">EMPYREAN</instrumentControlSoftware>
					<instrumentID>0000000011260721</instrumentID>
				</source>
			</header>
			<dataPoints>
				<positions axis="2Theta" unit="deg">
					<startPosition>77.9468152930555</startPosition>
					<endPosition>81.294085064272</endPosition>
				</positions>
				<positions axis="Omega" unit="deg">
					<commonPosition>21.2492250893319</commonPosition>
				</positions>
				<positions axis="Phi" unit="deg">
					<commonPosition>-94.99</commonPosition>
				</positions>
				<positions axis="Chi" unit="deg">
					<commonPosition>0</commonPosition>
				</positions>
				<positions axis="Z" unit="mm">
					<commonPosition>8.33</commonPosition>
				</positions>
				<commonCountingTime unit="seconds">0.974</commonCountingTime>
				<counts unit="counts">0 0 0 0 0 0 0 0 0 1 1 0 0 1 0 1 0 1 0 0 0 0 0 0 0 0 0 0 0 1 0 0 1 0 1 0 0 0 0 0 0 0 1 1 0 0 0 0 0 1 0 0 0 0 0 0 0 0 1 0 0 0 0 0 0 0 1 1 1 0 0 0 0 1 0 0 0 0 1 0 0 0 0 0 0 0 1 0 0 1 0 0 0 0 0 1 0 0 0 0 0 0 0 0 1 0 1 1 0 1 0 0 0 0 0 0 0 1 0 0 0 0 0 0 1 0 0 2 0 0 0 1 0 0 0 0 0 0 0 0 1 0 0 0 0 0 2 1 1 0 0 0 0 1 1 1 0 0 0 0 0 0 0 0 0 0 0 0 0 0 0 0 1 0 1 0 0 0 1 0 0 0 0 1 0 1 0 0 0 0 0 0 1 0 1 0 0 0 0 0 0 0 0 0 0 0 0 2 0 0 0 0 0 1 1 0 0 0 0 0 0 0 0 0 0 0 1 1 0 0 0 0 1 0 0 0 0 1 0 0 0 1 0 0 0 0 1 2 1 0 1 0 0 0 0</counts>
			</dataPoints>
		</scan>
		<scan status="Completed" appendNumber="0" scanAxis="2Theta" mode="Continuous">
			<header>
				<startTimeStamp>2024-06-28T16:36:56-04:00</startTimeStamp>
				<endTimeStamp>2024-06-28T17:06:56-04:00</endTimeStamp>
				<author>
					<name>lw627</name>
				</author>
				<source>
					<applicationSoftware version="7.1">Data Collector</applicationSoftware>
					<instrumentControlSoftware version="8.2  20201204">EMPYREAN</instrumentControlSoftware>
					<instrumentID>0000000011260721</instrumentID>
				</source>
			</header>
			<dataPoints>
				<positions axis="2Theta" unit="deg">
					<startPosition>77.9500978637236</startPosition>
					<endPosition>81.2973676349401</endPosition>
				</positions>
				<positions axis="Omega" unit="deg">
					<commonPosition>21.2508663746659</commonPosition>
				</positions>
				<positions axis="Phi" unit="deg">
					<commonPosition>-94.99</commonPosition>
				</positions>
				<positions axis="Chi" unit="deg">
					<commonPosition>0</commonPosition>
				</positions>
				<positions axis="Z" unit="mm">
					<commonPosition>8.33</commonPosition>
				</positions>
				<commonCountingTime unit="seconds">0.974</commonCountingTime>
				<counts unit="counts">0 0 0 0 0 1 0 0 1 0 0 1 0 1 0 0 0 0 1 0 0 1 0 0 0 1 0 1 1 1 1 0 0 0 0 0 1 1 0 0 0 0 0 1 0 0 0 0 1 2 0 0 0 0 0 0 0 0 0 0 0 0 0 0 0 0 0 0 0 0 0 1 0 1 0 0 0 2 1 0 1 0 1 1 0 0 0 0 0 0 1 0 0 0 0 0 1 0 2 0 0 2 1 3 0 0 0 0 0 1 0 0 0 0 0 0 0 0 0 0 0 0 0 0 0 0 0 0 0 1 0 0 0 0 0 0 0 0 0 0 0 0 0 2 0 0 0 0 0 0 0 0 2 0 1 0 0 2 0 0 0 0 0 0 0 0 0 0 1 0 0 0 0 0 0 0 0 1 1 1 0 0 0 0 0 0 0 0 0 0 0 0 0 0 1 0 0 0 0 0 1 0 1 0 0 0 0 0 0 0 0 0 0 1 0 0 0 0 0 0 0 0 0 0 0 0 0 0 0 0 0 0 0 0 0 0 0 0 0 0 0 0 1 1 0 0 0 1 0 0 0 1 1 1 1</counts>
			</dataPoints>
		</scan>
		<scan status="Completed" appendNumber="0" scanAxis="2Theta" mode="Continuous">
			<header>
				<startTimeStamp>2024-06-28T16:36:56-04:00</startTimeStamp>
				<endTimeStamp>2024-06-28T17:06:56-04:00</endTimeStamp>
				<author>
					<name>lw627</name>
				</author>
				<source>
					<applicationSoftware version="7.1">Data Collector</applicationSoftware>
					<instrumentControlSoftware version="8.2  20201204">EMPYREAN</instrumentControlSoftware>
					<instrumentID>0000000011260721</instrumentID>
				</source>
			</header>
			<dataPoints>
				<positions axis="2Theta" unit="deg">
					<startPosition>77.9533804343918</startPosition>
					<endPosition>81.3006502056082</endPosition>
				</positions>
				<positions axis="Omega" unit="deg">
					<commonPosition>21.25250766</commonPosition>
				</positions>
				<positions axis="Phi" unit="deg">
					<commonPosition>-94.99</commonPosition>
				</positions>
				<positions axis="Chi" unit="deg">
					<commonPosition>0</commonPosition>
				</positions>
				<positions axis="Z" unit="mm">
					<commonPosition>8.33</commonPosition>
				</positions>
				<commonCountingTime unit="seconds">0.974</commonCountingTime>
				<counts unit="counts">0 1 0 1 0 1 0 0 0 0 0 0 0 0 2 0 1 1 0 0 0 0 0 0 0 2 0 0 0 0 0 0 2 0 0 0 0 0 0 0 0 1 0 0 0 0 0 0 0 0 2 1 0 1 0 1 1 1 0 1 0 1 1 0 0 0 0 1 0 0 0 1 0 0 1 0 0 0 0 0 0 0 1 0 0 0 0 1 0 0 0 0 1 0 0 0 1 0 0 0 0 0 1 0 0 0 0 0 1 0 0 0 0 1 0 2 0 0 0 0 2 0 0 0 0 0 0 0 0 0 0 0 0 0 1 0 0 0 0 0 0 1 0 1 1 0 0 0 0 0 2 0 0 1 1 0 0 0 0 1 0 1 1 0 2 0 0 0 0 0 1 1 0 0 0 0 0 0 0 0 0 0 0 0 0 0 0 1 0 1 0 1 0 0 0 1 0 0 1 1 0 0 0 0 0 2 0 0 1 0 0 0 0 0 0 1 0 0 0 0 0 0 2 0 0 0 0 0 0 0 1 0 0 1 1 0 0 0 0 1 0 1 0 0 0 0 0 0 1 0 0 0 0 0 0</counts>
			</dataPoints>
		</scan>
	</xrdMeasurement>
</xrdMeasurements>