File: data/XRD_RSM/YG053/YCG_053 S2 2nd RSM slow 1.5 degree_1.xrdml
<?xml version="1.0" encoding="utf-8"?>
<xrdMeasurements xmlns="http://www.xrdml.com/XRDMeasurement/2.2" xmlns:xsi="http://www.w3.org/2001/XMLSchema-instance" xsi:schemaLocation="http://www.xrdml.com/XRDMeasurement/2.2 http://www.xrdml.com/XRDMeasurement/2.2/XRDMeasurement.xsd" status="Completed">
	<comment>
		<entry>Configuration=3-axes Cradle_Reflection, Owner=lw627, Creation date=9/2/2021 3:55:24 PM</entry>
		<entry>Goniometer=Theta/Theta; Minimum step size 2Theta:0.0001; Minimum step size Omega:0.0001</entry>
		<entry>Sample stage=Chi-Phi-z stage 240 mm (reflection); Minimum step size Phi:0.01; Minimum step size Chi:0.01; Minimum step size Z:0.001</entry>
		<entry>Diffractometer system=EMPYREAN</entry>
		<entry>Measurement program=C:\PANalytical\Data Collector\Programs\Liyan Wu\Film programs\RSM slow 1.5 degree.xrdmp, Identifier={0A137119-D990-4D5D-A198-A9BB75A0EC1A}</entry>
	</comment>
	<sample type="To be analyzed">
		<id/>
		<name/>
		<preparedBy/>
	</sample>
	<xrdMeasurement status="Completed" measurementType="Area measurement" measurementStepAxis="Omega-2Theta" sampleMode="Reflection">
		<comment>
			<entry>PHD Lower Level = 4.02 (keV), PHD Upper Level = 11.27 (keV)</entry>
		</comment>
		<usedWavelength intended="K-Alpha 1">
			<kAlpha1 unit="Angstrom">1.5405980</kAlpha1>
			<kAlpha2 unit="Angstrom">1.5444260</kAlpha2>
			<kBeta unit="Angstrom">1.3922500</kBeta>
			<ratioKAlpha2KAlpha1>0</ratioKAlpha2KAlpha1>
		</usedWavelength>
		<incidentBeamPath>
			<radius unit="mm">240.00</radius>
			<xRayTube id="1010048" name="Empyrean Cu LFF HR (9430 033 7310x) DK432574">
				<tension unit="kV">45.0</tension>
				<current unit="mA">40.0</current>
				<anodeMaterial>Cu</anodeMaterial>
				<focus type="Line">
					<length unit="mm">12.0</length>
					<width unit="mm">0.4</width>
					<takeOffAngle unit="deg">4.4</takeOffAngle>
				</focus>
			</xRayTube>
			<xRayMirror xsi:type="xRayMirrorType" id="27080001" name="Inc. Beam Cu W/Si (hybrid MPD)" hybrid="true">
				<crystal type="Graded" shape="Parabolic">W/Si</crystal>
				<acceptanceAngle unit="deg">0.800</acceptanceAngle>
				<length unit="mm">55.3</length>
			</xRayMirror>
			<monochromator xsi:type="monochromatorType" id="23090002" name="Hybrid monochr. 2xGe220 Cu asym." hybrid="true">
				<crystal type="Asymmetric" shape="Flat">Ge</crystal>
				<numberOfReflections>2</numberOfReflections>
				<hkl>
					<h>2</h>
					<k>2</k>
					<l>0</l>
				</hkl>
			</monochromator>
			<divergenceSlit xsi:type="fixedDivergenceSlitType" id="22010005" name="Fixed slit 1/4°">
				<distanceToSample unit="mm">179.30</distanceToSample>
				<height unit="mm">0.38</height>
			</divergenceSlit>
		</incidentBeamPath>
		<diffractedBeamPath>
			<radius unit="mm">240.00</radius>
			<antiScatterSlit xsi:type="fixedAntiScatterSlitType" id="22060009" name="Programmable anti-scatter slit">
				<angle unit="deg">4</angle>
			</antiScatterSlit>
			<detector xsi:type="areaDetectorType" id="7010020" name="PIXcel3D-Medipix3 1x1 detector">
				<phd unit="%">
					<lowerLevel>25</lowerLevel>
					<upperLevel>70</upperLevel>
				</phd>
				<mode>Scanning snapshot equatorial</mode>
				<activeChannelsEquatorial>255</activeChannelsEquatorial>
				<activeChannelsAxial>255</activeChannelsAxial>
				<pitchEquatorial unit="mm">0.05500</pitchEquatorial>
				<pitchAxial unit="mm">0.05500</pitchAxial>
				<readOutPeriod unit="seconds">0.980</readOutPeriod>
			</detector>
		</diffractedBeamPath>
		<scan status="Completed" appendNumber="0" scanAxis="2Theta" mode="Continuous">
			<header>
				<startTimeStamp>2024-06-29T16:44:15-04:00</startTimeStamp>
				<endTimeStamp>2024-06-29T16:59:18-04:00</endTimeStamp>
				<author>
					<name>lw627</name>
				</author>
				<source>
					<applicationSoftware version="7.1">Data Collector</applicationSoftware>
					<instrumentControlSoftware version="8.2  20201204">EMPYREAN</instrumentControlSoftware>
					<instrumentID>0000000011260721</instrumentID>
				</source>
			</header>
			<dataPoints>
				<positions axis="2Theta" unit="deg">
					<startPosition>73.5796063943918</startPosition>
					<endPosition>76.9268761656082</endPosition>
				</positions>
				<positions axis="Omega" unit="deg">
					<commonPosition>19.09962064</commonPosition>
				</positions>
				<positions axis="Phi" unit="deg">
					<commonPosition>-4.15</commonPosition>
				</positions>
				<positions axis="Chi" unit="deg">
					<commonPosition>0</commonPosition>
				</positions>
				<positions axis="Z" unit="mm">
					<commonPosition>8.386</commonPosition>
				</positions>
				<commonCountingTime unit="seconds">0.974</commonCountingTime>
				<counts unit="counts">1 1 0 0 0 0 0 0 1 0 0 0 1 0 0 0 1 1 0 0 1 0 1 0 1 0 2 1 0 0 0 2 0 2 0 0 1 0 0 0 0 0 1 0 0 2 1 1 1 0 1 0 1 0 0 1 0 0 0 1 0 0 1 1 0 0 0 0 0 0 0 0 0 0 0 0 0 0 1 0 0 0 0 1 0 0 0 0 0 2 0 0 0 0 0 0 1 0 0 0 0 1 0 0 0 0 0 0 1 0 0 0 0 0 0 0 0 0 0 1 1 0 0 0 1 0 0 0 0 1 0 0 0 1 0 0 1 0 0 0 0 1 0 1 0 1 1 0 0 0 0 0 2 2 0 0 1 0 0 0 1 0 1 0 0 0 0 1 1 0 0 0 0 0 1 0 0 0 0 1 0 0 0 0 0 0 1 0 1 1 1 0 0 1 0 0 1 1 0 0 0 0 2 0 0 0 0 1 0 0 0 0 0 0 1 0 0 1 0 1 3 0 0 0 0 0 0 0 0 0 1 0 0 0 1 0 2 0 0 0 2 0 2 0 0 0 0 0 0 0 0 0 1 0 0</counts>
			</dataPoints>
		</scan>
		<scan status="Completed" appendNumber="0" scanAxis="2Theta" mode="Continuous">
			<header>
				<startTimeStamp>2024-06-29T16:44:15-04:00</startTimeStamp>
				<endTimeStamp>2024-06-29T16:59:18-04:00</endTimeStamp>
				<author>
					<name>lw627</name>
				</author>
				<source>
					<applicationSoftware version="7.1">Data Collector</applicationSoftware>
					<instrumentControlSoftware version="8.2  20201204">EMPYREAN</instrumentControlSoftware>
					<instrumentID>0000000011260721</instrumentID>
				</source>
			</header>
			<dataPoints>
				<positions axis="2Theta" unit="deg">
					<startPosition>73.5828889650716</startPosition>
					<endPosition>76.9301587362881</endPosition>
				</positions>
				<positions axis="Omega" unit="deg">
					<commonPosition>19.1012619253399</commonPosition>
				</positions>
				<positions axis="Phi" unit="deg">
					<commonPosition>-4.15</commonPosition>
				</positions>
				<positions axis="Chi" unit="deg">
					<commonPosition>0</commonPosition>
				</positions>
				<positions axis="Z" unit="mm">
					<commonPosition>8.386</commonPosition>
				</positions>
				<commonCountingTime unit="seconds">0.974</commonCountingTime>
				<counts unit="counts">0 1 1 0 1 0 0 0 1 0 1 1 0 0 0 1 0 0 0 0 0 0 0 0 0 0 1 0 0 2 1 1 0 0 0 1 0 0 0 0 0 0 0 0 0 0 0 1 0 1 2 0 1 0 1 0 0 0 1 1 2 0 1 0 0 1 0 0 1 0 0 1 1 0 1 0 0 0 0 0 0 0 1 1 0 0 1 0 0 1 1 1 0 0 0 0 1 0 0 0 0 0 1 0 0 1 0 0 0 1 1 0 2 0 0 2 0 2 0 0 0 0 0 0 0 0 0 0 0 0 1 0 1 0 1 2 1 0 0 0 0 0 1 0 1 0 0 0 0 3 0 0 1 0 0 0 0 0 0 1 0 3 0 2 1 0 0 0 0 2 0 1 0 0 1 0 0 0 1 0 0 0 0 1 1 0 0 0 1 1 0 0 0 1 0 1 2 2 0 2 0 1 0 0 0 1 0 1 0 0 0 0 0 0 0 1 0 0 1 0 1 0 1 1 0 0 1 0 0 0 1 0 0 1 2 0 0 0 0 1 0 2 0 0 1 1 0 0 1 0 0 0 0 1 0</counts>
			</dataPoints>
		</scan>
		<scan status="Completed" appendNumber="0" scanAxis="2Theta" mode="Continuous">
			<header>
				<startTimeStamp>2024-06-29T16:44:15-04:00</startTimeStamp>
				<endTimeStamp>2024-06-29T16:59:18-04:00</endTimeStamp>
				<author>
					<name>lw627</name>
				</author>
				<source>
					<applicationSoftware version="7.1">Data Collector</applicationSoftware>
					<instrumentControlSoftware version="8.2  20201204">EMPYREAN</instrumentControlSoftware>
					<instrumentID>0000000011260721</instrumentID>
				</source>
			</header>
			<dataPoints>
				<positions axis="2Theta" unit="deg">
					<startPosition>73.5861715357514</startPosition>
					<endPosition>76.9334413069679</endPosition>
				</positions>
				<positions axis="Omega" unit="deg">
					<commonPosition>19.1029032106798</commonPosition>
				</positions>
				<positions axis="Phi" unit="deg">
					<commonPosition>-4.15</commonPosition>
				</positions>
				<positions axis="Chi" unit="deg">
					<commonPosition>0</commonPosition>
				</positions>
				<positions axis="Z" unit="mm">
					<commonPosition>8.386</commonPosition>
				</positions>
				<commonCountingTime unit="seconds">0.974</commonCountingTime>
				<counts unit="counts">0 0 0 0 0 0 1 0 0 0 0 0 0 0 0 1 0 0 0 0 0 0 0 0 1 1 0 1 0 0 0 1 0 1 0 2 1 0 1 1 0 0 0 1 0 0 0 0 0 0 0 1 0 0 0 0 0 0 0 0 0 0 0 0 0 0 0 0 0 0 0 0 0 0 2 1 1 0 0 0 0 0 1 0 0 0 0 1 0 0 0 0 0 0 0 0 1 0 0 1 0 0 0 0 1 0 0 0 1 0 1 0 0 0 0 1 1 0 0 0 1 0 0 0 0 1 0 0 1 1 0 0 0 1 1 0 0 0 1 1 0 0 1 1 2 0 0 1 0 0 0 1 1 1 0 1 2 0 2 0 0 2 1 1 0 0 1 0 0 1 0 1 0 0 0 0 1 0 0 0 0 0 0 1 1 0 0 0 1 1 0 0 1 0 2 0 0 0 1 0 1 0 0 0 0 0 0 0 2 0 0 1 0 2 0 0 0 0 0 1 0 0 1 0 0 2 0 0 1 1 1 0 0 2 1 0 0 0 0 0 0 1 0 1 0 0 0 0 0 1 0 1 0 0 0</counts>
			</dataPoints>
		</scan>
		<scan status="Completed" appendNumber="0" scanAxis="2Theta" mode="Continuous">
			<header>
				<startTimeStamp>2024-06-29T16:44:15-04:00</startTimeStamp>
				<endTimeStamp>2024-06-29T16:59:18-04:00</endTimeStamp>
				<author>
					<name>lw627</name>
				</author>
				<source>
					<applicationSoftware version="7.1">Data Collector</applicationSoftware>
					<instrumentControlSoftware version="8.2  20201204">EMPYREAN</instrumentControlSoftware>
					<instrumentID>0000000011260721</instrumentID>
				</source>
			</header>
			<dataPoints>
				<positions axis="2Theta" unit="deg">
					<startPosition>73.5894541064312</startPosition>
					<endPosition>76.9367238776477</endPosition>
				</positions>
				<positions axis="Omega" unit="deg">
					<commonPosition>19.1045444960197</commonPosition>
				</positions>
				<positions axis="Phi" unit="deg">
					<commonPosition>-4.15</commonPosition>
				</positions>
				<positions axis="Chi" unit="deg">
					<commonPosition>0</commonPosition>
				</positions>
				<positions axis="Z" unit="mm">
					<commonPosition>8.386</commonPosition>
				</positions>
				<commonCountingTime unit="seconds">0.974</commonCountingTime>
				<counts unit="counts">0 0 0 0 0 0 1 0 0 0 0 1 0 0 0 0 0 1 0 0 0 0 0 0 1 0 0 0 0 0 1 0 0 0 0 0 0 0 0 0 0 2 0 1 0 0 0 1 2 0 2 0 0 0 1 1 0 1 0 0 0 0 0 0 0 1 0 0 0 0 0 0 0 0 0 0 0 0 1 0 1 0 1 1 0 0 0 0 0 1 0 0 0 0 0 0 0 0 0 1 1 0 1 0 0 0 1 0 0 0 0 0 1 0 1 0 0 0 0 0 0 0 0 0 0 1 0 0 1 0 0 0 1 0 1 0 0 0 3 0 0 1 1 0 0 0 0 1 0 0 1 0 0 0 0 0 2 1 0 1 1 1 1 0 0 1 0 0 0 0 0 0 1 0 0 0 0 0 1 1 0 0 0 0 0 0 0 0 1 0 0 0 1 0 1 1 1 0 1 0 0 0 0 1 1 0 0 0 1 1 0 2 0 0 0 0 0 0 1 0 0 0 0 0 0 0 0 0 1 0 0 0 0 1 0 1 0 0 1 0 0 0 0 0 1 1 0 0 0 0 0 0 0 1 0</counts>
			</dataPoints>
		</scan>
		<scan status="Completed" appendNumber="0" scanAxis="2Theta" mode="Continuous">
			<header>
				<startTimeStamp>2024-06-29T16:44:15-04:00</startTimeStamp>
				<endTimeStamp>2024-06-29T16:59:18-04:00</endTimeStamp>
				<author>
					<name>lw627</name>
				</author>
				<source>
					<applicationSoftware version="7.1">Data Collector</applicationSoftware>
					<instrumentControlSoftware version="8.2  20201204">EMPYREAN</instrumentControlSoftware>
					<instrumentID>0000000011260721</instrumentID>
				</source>
			</header>
			<dataPoints>
				<positions axis="2Theta" unit="deg">
					<startPosition>73.592736677111</startPosition>
					<endPosition>76.9400064483275</endPosition>
				</positions>
				<positions axis="Omega" unit="deg">
					<commonPosition>19.1061857813596</commonPosition>
				</positions>
				<positions axis="Phi" unit="deg">
					<commonPosition>-4.15</commonPosition>
				</positions>
				<positions axis="Chi" unit="deg">
					<commonPosition>0</commonPosition>
				</positions>
				<positions axis="Z" unit="mm">
					<commonPosition>8.386</commonPosition>
				</positions>
				<commonCountingTime unit="seconds">0.974</commonCountingTime>
				<counts unit="counts">1 0 0 0 0 0 0 0 1 1 0 0 0 0 0 0 0 0 0 0 0 0 0 0 0 0 0 3 0 0 0 0 0 0 1 0 1 0 0 0 1 0 1 1 0 1 0 0 0 0 0 0 0 0 0 1 0 0 1 1 0 0 0 0 0 0 1 1 2 1 0 0 0 0 0 0 0 0 0 1 0 0 0 0 1 0 0 0 0 0 1 0 0 0 2 0 0 0 0 0 0 1 0 2 0 0 0 1 0 1 2 0 0 2 0 0 0 0 0 1 0 0 1 1 0 1 0 1 1 0 0 0 0 0 0 1 0 0 0 0 0 0 0 2 0 0 0 0 0 1 0 0 0 1 2 0 0 0 1 0 0 0 1 0 0 0 0 0 0 0 1 0 0 0 0 1 0 0 1 0 0 2 0 0 0 2 0 0 0 1 0 1 0 0 0 0 1 0 0 0 1 2 0 0 0 1 0 0 0 1 0 1 0 1 0 0 1 1 0 1 0 1 0 0 0 0 0 1 0 0 0 0 0 0 0 0 0 0 0 1 0 0 0 1 0 0 0 0 0 0 0 0 0 0 1</counts>
			</dataPoints>
		</scan>
		<scan status="Completed" appendNumber="0" scanAxis="2Theta" mode="Continuous">
			<header>
				<startTimeStamp>2024-06-29T16:44:15-04:00</startTimeStamp>
				<endTimeStamp>2024-06-29T16:59:18-04:00</endTimeStamp>
				<author>
					<name>lw627</name>
				</author>
				<source>
					<applicationSoftware version="7.1">Data Collector</applicationSoftware>
					<instrumentControlSoftware version="8.2  20201204">EMPYREAN</instrumentControlSoftware>
					<instrumentID>0000000011260721</instrumentID>
				</source>
			</header>
			<dataPoints>
				<positions axis="2Theta" unit="deg">
					<startPosition>73.5960192477909</startPosition>
					<endPosition>76.9432890190074</endPosition>
				</positions>
				<positions axis="Omega" unit="deg">
					<commonPosition>19.1078270666996</commonPosition>
				</positions>
				<positions axis="Phi" unit="deg">
					<commonPosition>-4.15</commonPosition>
				</positions>
				<positions axis="Chi" unit="deg">
					<commonPosition>0</commonPosition>
				</positions>
				<positions axis="Z" unit="mm">
					<commonPosition>8.386</commonPosition>
				</positions>
				<commonCountingTime unit="seconds">0.974</commonCountingTime>
				<counts unit="counts">2 0 0 0 0 0 0 0 0 1 0 0 1 0 0 0 0 0 0 1 0 0 0 1 0 0 0 0 1 1 0 0 0 0 0 0 0 0 1 1 0 0 0 0 0 0 0 0 1 1 0 1 1 0 0 0 1 0 0 1 2 0 0 0 0 0 0 0 1 0 0 0 1 0 1 1 0 0 1 1 0 1 0 0 0 0 0 0 0 2 1 0 0 0 0 0 0 0 1 0 0 0 0 0 1 0 0 0 0 1 0 0 0 0 0 0 0 0 0 0 0 0 0 0 1 1 1 0 0 0 0 1 1 0 0 0 0 0 0 0 0 0 0 0 0 3 0 0 1 0 0 2 0 0 0 0 1 1 0 0 2 4 1 0 0 1 0 0 0 0 0 0 0 0 0 0 0 0 0 0 1 1 1 0 0 1 0 1 0 0 0 1 0 0 0 0 1 0 0 0 0 0 0 0 0 0 0 0 0 1 0 0 0 1 0 0 0 1 0 0 0 0 1 1 0 1 0 2 0 2 0 1 0 1 1 0 1 1 0 1 0 0 0 0 0 1 0 0 0 0 1 0 0 0 1</counts>
			</dataPoints>
		</scan>
		<scan status="Completed" appendNumber="0" scanAxis="2Theta" mode="Continuous">
			<header>
				<startTimeStamp>2024-06-29T16:44:15-04:00</startTimeStamp>
				<endTimeStamp>2024-06-29T16:59:18-04:00</endTimeStamp>
				<author>
					<name>lw627</name>
				</author>
				<source>
					<applicationSoftware version="7.1">Data Collector</applicationSoftware>
					<instrumentControlSoftware version="8.2  20201204">EMPYREAN</instrumentControlSoftware>
					<instrumentID>0000000011260721</instrumentID>
				</source>
			</header>
			<dataPoints>
				<positions axis="2Theta" unit="deg">
					<startPosition>73.5993018184707</startPosition>
					<endPosition>76.9465715896872</endPosition>
				</positions>
				<positions axis="Omega" unit="deg">
					<commonPosition>19.1094683520395</commonPosition>
				</positions>
				<positions axis="Phi" unit="deg">
					<commonPosition>-4.15</commonPosition>
				</positions>
				<positions axis="Chi" unit="deg">
					<commonPosition>0</commonPosition>
				</positions>
				<positions axis="Z" unit="mm">
					<commonPosition>8.386</commonPosition>
				</positions>
				<commonCountingTime unit="seconds">0.974</commonCountingTime>
				<counts unit="counts">0 0 0 0 1 0 0 0 0 1 0 0 0 0 0 0 0 0 0 1 0 0 2 0 1 1 0 1 1 0 1 1 0 0 2 0 0 0 0 0 0 0 0 1 1 0 0 0 2 0 1 0 0 0 0 1 1 0 0 0 0 0 0 0 0 0 1 0 0 0 0 1 0 0 1 0 1 0 1 0 0 0 0 0 0 0 1 0 0 0 0 0 1 0 0 0 1 0 0 1 0 0 0 1 0 0 0 0 0 0 1 0 1 1 1 0 0 1 0 0 0 0 0 0 3 0 1 0 0 0 1 0 0 0 0 0 0 0 1 0 0 1 0 0 0 1 1 0 1 0 0 0 0 0 0 1 0 0 0 1 3 2 0 0 2 0 0 0 0 0 0 0 1 0 0 1 0 0 0 0 0 0 0 1 0 1 1 0 1 0 0 0 0 0 1 0 1 1 0 0 2 0 1 0 0 0 0 0 0 1 0 0 0 0 0 1 1 0 0 0 0 1 1 0 1 0 0 0 0 0 0 0 1 0 1 0 0 0 0 0 0 0 0 0 0 0 0 0 2 0 0 0 0 1 1</counts>
			</dataPoints>
		</scan>
		<scan status="Completed" appendNumber="0" scanAxis="2Theta" mode="Continuous">
			<header>
				<startTimeStamp>2024-06-29T16:44:15-04:00</startTimeStamp>
				<endTimeStamp>2024-06-29T16:59:18-04:00</endTimeStamp>
				<author>
					<name>lw627</name>
				</author>
				<source>
					<applicationSoftware version="7.1">Data Collector</applicationSoftware>
					<instrumentControlSoftware version="8.2  20201204">EMPYREAN</instrumentControlSoftware>
					<instrumentID>0000000011260721</instrumentID>
				</source>
			</header>
			<dataPoints>
				<positions axis="2Theta" unit="deg">
					<startPosition>73.6025843891505</startPosition>
					<endPosition>76.949854160367</endPosition>
				</positions>
				<positions axis="Omega" unit="deg">
					<commonPosition>19.1111096373794</commonPosition>
				</positions>
				<positions axis="Phi" unit="deg">
					<commonPosition>-4.15</commonPosition>
				</positions>
				<positions axis="Chi" unit="deg">
					<commonPosition>0</commonPosition>
				</positions>
				<positions axis="Z" unit="mm">
					<commonPosition>8.386</commonPosition>
				</positions>
				<commonCountingTime unit="seconds">0.974</commonCountingTime>
				<counts unit="counts">1 1 0 0 1 1 0 0 0 0 0 0 0 0 0 0 0 1 1 1 0 0 0 1 0 1 0 0 0 0 0 1 2 2 2 0 0 0 0 0 1 0 0 0 0 0 0 0 0 0 0 0 0 0 1 1 0 0 0 0 2 0 0 0 0 1 0 0 0 0 0 0 0 0 0 1 0 0 1 1 0 0 1 0 1 0 0 1 1 0 2 1 0 0 1 0 0 0 1 0 1 0 0 0 0 0 0 0 0 0 0 0 0 0 1 0 0 0 0 0 0 0 1 0 1 0 0 1 0 0 0 1 0 2 0 1 1 0 0 0 1 1 0 1 0 0 3 0 0 0 0 0 0 0 0 0 1 0 0 0 0 1 1 0 1 0 0 0 1 0 0 0 0 0 1 0 0 0 0 0 0 0 0 0 1 1 0 0 0 0 0 0 1 0 0 1 0 0 1 0 0 1 0 0 0 1 0 1 0 1 3 0 0 1 0 1 0 0 0 0 1 0 0 0 0 0 0 1 1 0 0 0 1 0 1 0 1 1 1 0 1 0 0 0 0 0 0 0 1 0 0 0 0 0 0</counts>
			</dataPoints>
		</scan>
		<scan status="Completed" appendNumber="0" scanAxis="2Theta" mode="Continuous">
			<header>
				<startTimeStamp>2024-06-29T16:44:15-04:00</startTimeStamp>
				<endTimeStamp>2024-06-29T16:59:18-04:00</endTimeStamp>
				<author>
					<name>lw627</name>
				</author>
				<source>
					<applicationSoftware version="7.1">Data Collector</applicationSoftware>
					<instrumentControlSoftware version="8.2  20201204">EMPYREAN</instrumentControlSoftware>
					<instrumentID>0000000011260721</instrumentID>
				</source>
			</header>
			<dataPoints>
				<positions axis="2Theta" unit="deg">
					<startPosition>73.6058669598304</startPosition>
					<endPosition>76.9531367310468</endPosition>
				</positions>
				<positions axis="Omega" unit="deg">
					<commonPosition>19.1127509227193</commonPosition>
				</positions>
				<positions axis="Phi" unit="deg">
					<commonPosition>-4.15</commonPosition>
				</positions>
				<positions axis="Chi" unit="deg">
					<commonPosition>0</commonPosition>
				</positions>
				<positions axis="Z" unit="mm">
					<commonPosition>8.386</commonPosition>
				</positions>
				<commonCountingTime unit="seconds">0.974</commonCountingTime>
				<counts unit="counts">0 0 1 0 0 1 0 0 0 0 1 0 0 1 1 0 0 1 0 0 1 0 2 1 0 0 0 0 0 0 0 0 0 1 0 1 0 0 1 1 0 0 0 2 0 0 0 0 0 0 0 0 0 0 0 1 0 0 1 0 0 0 0 0 0 0 0 1 0 3 0 0 1 0 0 0 0 0 0 0 0 0 0 0 0 0 0 0 0 1 0 1 0 1 0 1 1 0 1 0 1 0 0 0 0 0 0 0 0 0 1 0 0 0 1 0 0 0 0 0 0 2 0 0 0 2 0 0 0 0 0 1 0 0 2 0 0 0 0 1 2 1 0 0 0 0 0 0 0 1 1 0 0 0 0 0 0 1 1 3 1 0 0 0 0 0 1 0 0 1 0 0 0 0 2 0 0 0 0 0 0 0 0 0 0 0 1 0 0 0 0 0 1 0 0 0 1 0 0 0 1 0 1 0 0 0 1 1 1 1 1 0 0 0 0 0 0 0 0 0 1 0 0 0 0 1 0 0 0 0 1 0 0 0 0 2 0 0 1 0 1 0 0 0 0 0 1 1 0 0 0 0 0 2 1</counts>
			</dataPoints>
		</scan>
		<scan status="Completed" appendNumber="0" scanAxis="2Theta" mode="Continuous">
			<header>
				<startTimeStamp>2024-06-29T16:44:15-04:00</startTimeStamp>
				<endTimeStamp>2024-06-29T16:59:18-04:00</endTimeStamp>
				<author>
					<name>lw627</name>
				</author>
				<source>
					<applicationSoftware version="7.1">Data Collector</applicationSoftware>
					<instrumentControlSoftware version="8.2  20201204">EMPYREAN</instrumentControlSoftware>
					<instrumentID>0000000011260721</instrumentID>
				</source>
			</header>
			<dataPoints>
				<positions axis="2Theta" unit="deg">
					<startPosition>73.6091495305102</startPosition>
					<endPosition>76.9564193017267</endPosition>
				</positions>
				<positions axis="Omega" unit="deg">
					<commonPosition>19.1143922080592</commonPosition>
				</positions>
				<positions axis="Phi" unit="deg">
					<commonPosition>-4.15</commonPosition>
				</positions>
				<positions axis="Chi" unit="deg">
					<commonPosition>0</commonPosition>
				</positions>
				<positions axis="Z" unit="mm">
					<commonPosition>8.386</commonPosition>
				</positions>
				<commonCountingTime unit="seconds">0.974</commonCountingTime>
				<counts unit="counts">0 0 0 1 1 0 0 0 0 1 1 1 0 0 0 1 0 1 0 0 0 0 0 0 0 0 0 0 0 0 0 0 0 2 1 1 0 1 0 0 0 0 0 0 0 0 0 0 0 1 1 0 0 1 2 0 0 0 2 0 0 0 3 1 0 0 0 0 0 0 0 0 0 0 1 0 0 0 1 0 0 0 0 0 0 0 0 0 0 0 0 0 0 0 0 0 0 1 1 0 0 0 0 0 0 0 0 0 0 0 0 0 0 0 0 1 0 0 0 0 1 0 1 1 0 1 0 0 0 0 0 1 0 0 0 0 0 0 0 0 0 0 0 1 0 1 1 1 0 0 0 1 0 0 1 0 0 0 1 1 1 2 1 0 0 1 0 0 0 1 1 1 0 0 0 2 0 0 0 1 0 1 0 0 0 2 0 1 0 0 0 0 1 0 0 0 2 0 0 1 0 0 0 0 1 0 0 0 0 0 2 1 0 0 0 0 0 1 0 0 0 0 0 0 0 0 0 0 0 0 0 0 1 0 0 1 0 0 0 0 0 0 0 0 0 0 0 0 0 0 0 0 0 1 0</counts>
			</dataPoints>
		</scan>
		<scan status="Completed" appendNumber="0" scanAxis="2Theta" mode="Continuous">
			<header>
				<startTimeStamp>2024-06-29T16:44:15-04:00</startTimeStamp>
				<endTimeStamp>2024-06-29T16:59:18-04:00</endTimeStamp>
				<author>
					<name>lw627</name>
				</author>
				<source>
					<applicationSoftware version="7.1">Data Collector</applicationSoftware>
					<instrumentControlSoftware version="8.2  20201204">EMPYREAN</instrumentControlSoftware>
					<instrumentID>0000000011260721</instrumentID>
				</source>
			</header>
			<dataPoints>
				<positions axis="2Theta" unit="deg">
					<startPosition>73.61243210119</startPosition>
					<endPosition>76.9597018724065</endPosition>
				</positions>
				<positions axis="Omega" unit="deg">
					<commonPosition>19.1160334933991</commonPosition>
				</positions>
				<positions axis="Phi" unit="deg">
					<commonPosition>-4.15</commonPosition>
				</positions>
				<positions axis="Chi" unit="deg">
					<commonPosition>0</commonPosition>
				</positions>
				<positions axis="Z" unit="mm">
					<commonPosition>8.386</commonPosition>
				</positions>
				<commonCountingTime unit="seconds">0.974</commonCountingTime>
				<counts unit="counts">1 0 0 1 0 0 0 0 0 1 0 1 0 0 0 0 0 1 0 0 1 2 0 2 0 1 1 1 0 0 0 2 0 0 1 1 0 0 1 0 0 1 0 0 0 0 0 0 0 0 1 0 0 0 1 0 0 0 0 1 0 1 0 0 0 2 0 0 0 1 0 3 0 1 0 0 2 1 1 0 0 1 0 0 0 0 0 0 0 2 0 0 0 0 0 1 0 1 0 0 0 0 0 0 0 0 0 0 1 0 0 0 0 2 2 0 0 0 0 0 0 0 0 0 0 0 0 1 0 0 0 1 0 2 0 0 0 0 0 0 1 0 1 0 1 1 0 0 0 0 0 0 1 0 0 0 0 0 0 0 2 1 2 0 0 0 0 0 0 0 1 1 0 0 2 1 1 0 0 0 0 0 0 0 0 0 1 1 0 0 0 0 0 1 0 2 0 0 0 0 0 1 0 1 0 0 0 2 0 0 0 0 0 0 0 0 0 1 1 2 0 2 2 0 1 1 1 0 0 0 0 0 0 1 0 0 1 0 1 0 1 0 0 1 0 0 1 0 0 0 0 0 0 1 0</counts>
			</dataPoints>
		</scan>
		<scan status="Completed" appendNumber="0" scanAxis="2Theta" mode="Continuous">
			<header>
				<startTimeStamp>2024-06-29T16:44:15-04:00</startTimeStamp>
				<endTimeStamp>2024-06-29T16:59:18-04:00</endTimeStamp>
				<author>
					<name>lw627</name>
				</author>
				<source>
					<applicationSoftware version="7.1">Data Collector</applicationSoftware>
					<instrumentControlSoftware version="8.2  20201204">EMPYREAN</instrumentControlSoftware>
					<instrumentID>0000000011260721</instrumentID>
				</source>
			</header>
			<dataPoints>
				<positions axis="2Theta" unit="deg">
					<startPosition>73.6157146718698</startPosition>
					<endPosition>76.9629844430863</endPosition>
				</positions>
				<positions axis="Omega" unit="deg">
					<commonPosition>19.117674778739</commonPosition>
				</positions>
				<positions axis="Phi" unit="deg">
					<commonPosition>-4.15</commonPosition>
				</positions>
				<positions axis="Chi" unit="deg">
					<commonPosition>0</commonPosition>
				</positions>
				<positions axis="Z" unit="mm">
					<commonPosition>8.386</commonPosition>
				</positions>
				<commonCountingTime unit="seconds">0.974</commonCountingTime>
				<counts unit="counts">0 1 0 0 0 0 0 0 0 1 1 0 0 0 0 0 1 0 0 0 2 1 0 1 0 0 0 0 0 0 1 1 0 0 1 0 0 0 0 0 0 0 0 1 0 1 0 0 0 0 0 0 0 0 0 0 0 1 0 0 0 0 0 1 0 1 0 0 0 0 0 0 1 0 0 0 0 0 0 2 1 0 0 0 0 0 0 1 1 3 0 2 0 1 1 1 0 0 0 0 1 1 1 0 0 1 0 0 0 1 0 0 0 0 1 2 0 0 2 0 0 1 0 1 0 1 0 0 0 0 0 0 1 0 0 1 0 0 0 0 0 1 0 0 0 0 0 0 1 0 0 0 0 0 0 2 1 0 1 0 2 2 0 1 0 0 0 1 0 1 0 0 0 0 1 1 0 1 0 0 0 0 0 1 1 1 0 0 0 0 0 0 3 1 0 0 0 2 1 0 1 1 0 0 0 0 1 0 1 1 0 0 0 0 0 0 0 0 1 0 3 0 0 0 0 0 0 0 1 0 0 0 0 0 0 0 1 2 2 2 1 1 0 0 0 1 0 0 0 0 0 0 0 0 1</counts>
			</dataPoints>
		</scan>
		<scan status="Completed" appendNumber="0" scanAxis="2Theta" mode="Continuous">
			<header>
				<startTimeStamp>2024-06-29T16:44:15-04:00</startTimeStamp>
				<endTimeStamp>2024-06-29T16:59:18-04:00</endTimeStamp>
				<author>
					<name>lw627</name>
				</author>
				<source>
					<applicationSoftware version="7.1">Data Collector</applicationSoftware>
					<instrumentControlSoftware version="8.2  20201204">EMPYREAN</instrumentControlSoftware>
					<instrumentID>0000000011260721</instrumentID>
				</source>
			</header>
			<dataPoints>
				<positions axis="2Theta" unit="deg">
					<startPosition>73.6189972425497</startPosition>
					<endPosition>76.9662670137661</endPosition>
				</positions>
				<positions axis="Omega" unit="deg">
					<commonPosition>19.1193160640789</commonPosition>
				</positions>
				<positions axis="Phi" unit="deg">
					<commonPosition>-4.15</commonPosition>
				</positions>
				<positions axis="Chi" unit="deg">
					<commonPosition>0</commonPosition>
				</positions>
				<positions axis="Z" unit="mm">
					<commonPosition>8.386</commonPosition>
				</positions>
				<commonCountingTime unit="seconds">0.974</commonCountingTime>
				<counts unit="counts">1 0 0 0 0 0 0 0 0 0 1 0 0 1 1 0 0 0 0 0 2 1 0 0 1 0 0 0 0 0 0 0 0 0 1 0 0 0 0 0 0 1 1 0 0 0 1 0 0 1 0 0 0 0 1 1 2 0 0 0 2 0 0 0 0 2 0 0 0 0 0 1 1 0 0 1 0 0 0 1 0 0 0 0 0 0 0 0 0 0 0 0 2 0 0 0 0 0 0 0 0 0 0 0 0 0 0 0 0 0 0 0 1 0 0 0 0 0 1 1 0 1 0 0 0 0 0 0 0 0 0 0 0 1 1 0 1 1 0 0 1 0 0 0 0 0 0 0 0 0 0 0 0 0 0 1 1 1 2 4 0 0 0 0 1 0 0 0 0 0 0 1 0 0 0 0 0 0 1 0 1 0 0 1 0 0 0 0 0 0 1 0 0 3 0 1 0 1 0 0 1 0 2 0 0 0 1 1 1 0 0 2 0 1 1 0 0 0 0 0 0 0 1 1 0 0 0 1 1 0 1 0 0 1 2 0 0 0 2 0 0 0 0 0 0 0 1 0 0 0 0 1 0 0 0</counts>
			</dataPoints>
		</scan>
		<scan status="Completed" appendNumber="0" scanAxis="2Theta" mode="Continuous">
			<header>
				<startTimeStamp>2024-06-29T16:44:15-04:00</startTimeStamp>
				<endTimeStamp>2024-06-29T16:59:18-04:00</endTimeStamp>
				<author>
					<name>lw627</name>
				</author>
				<source>
					<applicationSoftware version="7.1">Data Collector</applicationSoftware>
					<instrumentControlSoftware version="8.2  20201204">EMPYREAN</instrumentControlSoftware>
					<instrumentID>0000000011260721</instrumentID>
				</source>
			</header>
			<dataPoints>
				<positions axis="2Theta" unit="deg">
					<startPosition>73.6222798132295</startPosition>
					<endPosition>76.969549584446</endPosition>
				</positions>
				<positions axis="Omega" unit="deg">
					<commonPosition>19.1209573494189</commonPosition>
				</positions>
				<positions axis="Phi" unit="deg">
					<commonPosition>-4.15</commonPosition>
				</positions>
				<positions axis="Chi" unit="deg">
					<commonPosition>0</commonPosition>
				</positions>
				<positions axis="Z" unit="mm">
					<commonPosition>8.386</commonPosition>
				</positions>
				<commonCountingTime unit="seconds">0.974</commonCountingTime>
				<counts unit="counts">0 1 0 0 0 0 0 0 1 0 0 0 0 0 3 0 0 0 1 0 1 0 1 0 0 0 0 1 1 0 2 2 1 0 0 1 1 0 2 0 0 0 1 0 0 0 0 0 0 0 0 0 1 0 0 0 0 0 0 0 0 0 0 0 1 0 0 0 1 1 1 0 0 0 0 2 0 0 0 0 1 1 0 0 0 0 0 0 1 0 0 0 0 2 0 1 0 0 0 0 1 1 0 0 0 0 0 0 0 0 0 1 0 0 1 0 0 0 0 4 0 0 0 0 0 0 0 1 0 0 0 0 0 0 0 0 0 0 0 0 1 1 2 0 1 0 0 1 1 0 1 0 0 0 0 2 0 2 0 0 0 2 1 1 0 0 0 2 0 0 1 0 0 0 0 0 1 0 0 0 0 0 1 0 0 0 0 0 0 0 0 0 0 0 0 0 0 3 0 0 0 0 1 0 0 0 0 0 1 1 0 0 0 0 0 1 0 1 0 1 2 0 1 0 0 1 0 1 1 0 0 0 0 0 0 0 0 0 0 0 0 0 0 1 0 0 0 2 0 0 1 2 1 1 0</counts>
			</dataPoints>
		</scan>
		<scan status="Completed" appendNumber="0" scanAxis="2Theta" mode="Continuous">
			<header>
				<startTimeStamp>2024-06-29T16:44:15-04:00</startTimeStamp>
				<endTimeStamp>2024-06-29T16:59:18-04:00</endTimeStamp>
				<author>
					<name>lw627</name>
				</author>
				<source>
					<applicationSoftware version="7.1">Data Collector</applicationSoftware>
					<instrumentControlSoftware version="8.2  20201204">EMPYREAN</instrumentControlSoftware>
					<instrumentID>0000000011260721</instrumentID>
				</source>
			</header>
			<dataPoints>
				<positions axis="2Theta" unit="deg">
					<startPosition>73.6255623839093</startPosition>
					<endPosition>76.9728321551258</endPosition>
				</positions>
				<positions axis="Omega" unit="deg">
					<commonPosition>19.1225986347588</commonPosition>
				</positions>
				<positions axis="Phi" unit="deg">
					<commonPosition>-4.15</commonPosition>
				</positions>
				<positions axis="Chi" unit="deg">
					<commonPosition>0</commonPosition>
				</positions>
				<positions axis="Z" unit="mm">
					<commonPosition>8.386</commonPosition>
				</positions>
				<commonCountingTime unit="seconds">0.974</commonCountingTime>
				<counts unit="counts">0 3 0 1 0 0 0 0 0 0 0 0 0 0 0 2 0 0 0 1 0 2 0 0 0 1 0 0 0 1 0 1 1 0 0 0 0 0 2 1 0 1 0 0 0 0 0 0 0 0 0 0 0 0 1 0 0 0 0 0 0 0 0 0 0 1 1 0 0 1 0 0 0 0 0 0 0 1 0 0 0 0 0 0 0 1 0 2 1 0 0 1 0 0 1 0 0 1 1 0 1 0 0 0 0 1 0 0 1 0 0 1 1 0 1 1 0 0 0 0 0 1 2 1 0 0 0 0 0 0 0 0 0 2 0 0 0 1 0 0 0 0 0 1 0 0 1 0 1 0 0 0 0 0 0 0 0 0 3 1 1 2 1 0 1 0 2 0 0 1 1 0 0 0 1 0 1 0 1 0 0 1 0 0 0 2 0 0 0 0 2 0 0 0 1 0 1 1 0 0 0 0 0 1 0 0 1 0 1 0 0 0 1 0 0 1 0 0 0 1 0 0 1 1 0 0 0 0 0 0 0 1 0 0 0 0 0 0 1 1 1 1 0 1 0 0 0 0 0 0 0 1 0 0 0</counts>
			</dataPoints>
		</scan>
		<scan status="Completed" appendNumber="0" scanAxis="2Theta" mode="Continuous">
			<header>
				<startTimeStamp>2024-06-29T16:44:15-04:00</startTimeStamp>
				<endTimeStamp>2024-06-29T16:59:18-04:00</endTimeStamp>
				<author>
					<name>lw627</name>
				</author>
				<source>
					<applicationSoftware version="7.1">Data Collector</applicationSoftware>
					<instrumentControlSoftware version="8.2  20201204">EMPYREAN</instrumentControlSoftware>
					<instrumentID>0000000011260721</instrumentID>
				</source>
			</header>
			<dataPoints>
				<positions axis="2Theta" unit="deg">
					<startPosition>73.6288449545891</startPosition>
					<endPosition>76.9761147258056</endPosition>
				</positions>
				<positions axis="Omega" unit="deg">
					<commonPosition>19.1242399200987</commonPosition>
				</positions>
				<positions axis="Phi" unit="deg">
					<commonPosition>-4.15</commonPosition>
				</positions>
				<positions axis="Chi" unit="deg">
					<commonPosition>0</commonPosition>
				</positions>
				<positions axis="Z" unit="mm">
					<commonPosition>8.386</commonPosition>
				</positions>
				<commonCountingTime unit="seconds">0.974</commonCountingTime>
				<counts unit="counts">1 0 0 0 1 0 0 1 2 1 0 0 0 0 0 1 0 0 1 0 1 0 0 0 0 0 0 0 1 1 0 1 1 0 0 0 1 1 1 0 1 0 0 0 0 0 0 0 2 1 0 0 2 0 1 0 0 1 0 0 0 0 0 0 0 0 0 0 0 0 0 1 0 0 0 0 0 2 0 0 0 0 0 0 1 0 0 1 0 0 0 0 0 1 0 0 0 1 0 0 0 0 0 0 0 1 1 0 0 0 0 0 0 1 1 0 0 0 0 1 1 0 0 1 0 0 0 0 0 0 0 0 0 0 3 2 1 0 0 0 0 0 0 0 0 1 0 0 0 0 0 0 0 0 0 0 2 1 0 1 2 0 1 0 0 0 0 0 0 0 1 0 0 1 1 0 0 0 0 0 0 0 0 0 0 1 1 0 0 0 1 0 0 0 0 0 1 0 0 0 0 0 0 0 0 1 0 0 1 0 0 1 2 1 0 0 0 0 0 0 0 0 0 0 0 0 0 1 1 0 0 1 0 0 0 0 0 1 0 0 0 1 0 1 1 0 1 0 0 0 2 1 1 0 0</counts>
			</dataPoints>
		</scan>
		<scan status="Completed" appendNumber="0" scanAxis="2Theta" mode="Continuous">
			<header>
				<startTimeStamp>2024-06-29T16:44:15-04:00</startTimeStamp>
				<endTimeStamp>2024-06-29T16:59:18-04:00</endTimeStamp>
				<author>
					<name>lw627</name>
				</author>
				<source>
					<applicationSoftware version="7.1">Data Collector</applicationSoftware>
					<instrumentControlSoftware version="8.2  20201204">EMPYREAN</instrumentControlSoftware>
					<instrumentID>0000000011260721</instrumentID>
				</source>
			</header>
			<dataPoints>
				<positions axis="2Theta" unit="deg">
					<startPosition>73.632127525269</startPosition>
					<endPosition>76.9793972964854</endPosition>
				</positions>
				<positions axis="Omega" unit="deg">
					<commonPosition>19.1258812054386</commonPosition>
				</positions>
				<positions axis="Phi" unit="deg">
					<commonPosition>-4.15</commonPosition>
				</positions>
				<positions axis="Chi" unit="deg">
					<commonPosition>0</commonPosition>
				</positions>
				<positions axis="Z" unit="mm">
					<commonPosition>8.386</commonPosition>
				</positions>
				<commonCountingTime unit="seconds">0.974</commonCountingTime>
				<counts unit="counts">0 1 0 0 2 0 0 0 0 0 0 0 0 0 0 0 0 0 0 0 0 1 0 1 1 0 0 1 0 1 0 0 0 0 0 0 1 0 0 0 0 0 0 2 0 1 0 1 1 1 1 1 0 1 1 1 0 0 3 1 0 0 0 0 1 0 0 0 0 0 0 0 0 0 0 1 0 1 0 1 0 0 1 1 0 0 2 0 0 0 0 0 0 0 0 0 0 0 0 1 1 0 0 0 0 0 0 0 0 0 1 0 0 0 0 1 0 0 0 0 0 0 0 0 0 0 1 0 1 1 0 0 0 1 0 0 0 1 0 0 0 0 0 0 0 0 1 1 0 0 0 0 0 0 0 1 0 0 1 3 2 0 0 0 1 0 3 1 0 0 0 2 0 1 0 0 0 0 0 0 0 0 1 0 1 1 1 0 0 0 1 0 0 0 0 0 0 0 1 1 0 0 0 1 0 0 1 0 1 3 0 1 2 1 1 0 0 1 0 1 1 0 0 2 0 0 0 0 0 2 0 2 0 1 1 0 0 0 1 0 1 1 1 0 0 0 0 0 0 1 0 0 0 0 1</counts>
			</dataPoints>
		</scan>
		<scan status="Completed" appendNumber="0" scanAxis="2Theta" mode="Continuous">
			<header>
				<startTimeStamp>2024-06-29T16:44:15-04:00</startTimeStamp>
				<endTimeStamp>2024-06-29T16:59:18-04:00</endTimeStamp>
				<author>
					<name>lw627</name>
				</author>
				<source>
					<applicationSoftware version="7.1">Data Collector</applicationSoftware>
					<instrumentControlSoftware version="8.2  20201204">EMPYREAN</instrumentControlSoftware>
					<instrumentID>0000000011260721</instrumentID>
				</source>
			</header>
			<dataPoints>
				<positions axis="2Theta" unit="deg">
					<startPosition>73.6354100959488</startPosition>
					<endPosition>76.9826798671652</endPosition>
				</positions>
				<positions axis="Omega" unit="deg">
					<commonPosition>19.1275224907785</commonPosition>
				</positions>
				<positions axis="Phi" unit="deg">
					<commonPosition>-4.15</commonPosition>
				</positions>
				<positions axis="Chi" unit="deg">
					<commonPosition>0</commonPosition>
				</positions>
				<positions axis="Z" unit="mm">
					<commonPosition>8.386</commonPosition>
				</positions>
				<commonCountingTime unit="seconds">0.974</commonCountingTime>
				<counts unit="counts">0 1 0 1 0 0 1 0 0 1 0 0 2 0 1 0 0 0 0 0 0 0 0 0 1 0 0 0 0 0 0 0 0 0 1 0 1 0 0 1 0 0 0 0 1 0 0 1 1 0 0 1 2 3 0 0 1 0 0 0 0 0 0 1 0 0 0 1 0 0 0 0 0 0 0 1 0 1 0 1 0 0 1 0 0 0 0 2 1 0 0 0 0 0 2 0 0 0 1 0 0 0 0 1 0 0 0 0 0 0 0 0 0 0 1 0 0 0 1 0 1 0 0 0 0 0 1 0 0 0 0 0 0 0 0 0 0 0 0 0 1 0 0 0 0 1 0 0 0 1 1 0 0 2 1 1 1 0 2 3 3 1 0 0 0 1 1 1 0 0 0 0 0 0 1 1 1 0 0 0 0 0 1 0 0 0 0 0 0 3 0 0 0 0 0 1 0 0 0 0 0 0 1 2 2 1 0 0 0 0 0 0 0 0 0 1 0 0 0 0 0 0 0 2 0 0 0 0 0 0 0 0 0 1 2 0 0 1 1 0 0 1 0 1 0 0 0 0 1 1 0 0 1 1 0</counts>
			</dataPoints>
		</scan>
		<scan status="Completed" appendNumber="0" scanAxis="2Theta" mode="Continuous">
			<header>
				<startTimeStamp>2024-06-29T16:44:15-04:00</startTimeStamp>
				<endTimeStamp>2024-06-29T16:59:18-04:00</endTimeStamp>
				<author>
					<name>lw627</name>
				</author>
				<source>
					<applicationSoftware version="7.1">Data Collector</applicationSoftware>
					<instrumentControlSoftware version="8.2  20201204">EMPYREAN</instrumentControlSoftware>
					<instrumentID>0000000011260721</instrumentID>
				</source>
			</header>
			<dataPoints>
				<positions axis="2Theta" unit="deg">
					<startPosition>73.6386926666286</startPosition>
					<endPosition>76.9859624378451</endPosition>
				</positions>
				<positions axis="Omega" unit="deg">
					<commonPosition>19.1291637761184</commonPosition>
				</positions>
				<positions axis="Phi" unit="deg">
					<commonPosition>-4.15</commonPosition>
				</positions>
				<positions axis="Chi" unit="deg">
					<commonPosition>0</commonPosition>
				</positions>
				<positions axis="Z" unit="mm">
					<commonPosition>8.386</commonPosition>
				</positions>
				<commonCountingTime unit="seconds">0.974</commonCountingTime>
				<counts unit="counts">0 2 0 0 0 2 0 0 1 0 0 1 0 1 0 0 0 0 1 0 1 0 1 0 0 0 0 1 0 0 0 0 0 0 0 0 0 2 1 1 1 0 0 0 0 1 1 1 0 0 1 1 1 0 0 0 0 0 0 0 0 1 0 0 1 1 0 0 0 1 0 1 0 1 2 1 0 0 0 0 0 1 0 0 0 0 1 1 1 1 0 1 0 0 0 1 0 0 0 0 0 0 2 1 0 0 0 0 1 1 0 0 0 0 2 0 0 0 0 1 1 0 0 0 0 0 1 0 0 1 0 0 0 0 2 0 0 0 1 0 0 0 0 0 0 0 0 0 0 0 0 0 2 0 0 1 0 0 2 2 2 1 0 0 0 0 0 0 0 0 0 0 1 0 0 0 0 0 1 0 0 0 1 0 0 0 0 1 1 0 0 0 4 0 0 0 0 0 0 0 0 0 0 1 0 0 0 0 1 0 2 0 1 0 2 0 2 0 0 0 1 1 0 2 1 0 1 1 0 0 0 2 1 0 0 1 0 0 0 1 1 0 1 0 0 0 0 0 0 0 1 0 0 0 0</counts>
			</dataPoints>
		</scan>
		<scan status="Completed" appendNumber="0" scanAxis="2Theta" mode="Continuous">
			<header>
				<startTimeStamp>2024-06-29T16:44:15-04:00</startTimeStamp>
				<endTimeStamp>2024-06-29T16:59:18-04:00</endTimeStamp>
				<author>
					<name>lw627</name>
				</author>
				<source>
					<applicationSoftware version="7.1">Data Collector</applicationSoftware>
					<instrumentControlSoftware version="8.2  20201204">EMPYREAN</instrumentControlSoftware>
					<instrumentID>0000000011260721</instrumentID>
				</source>
			</header>
			<dataPoints>
				<positions axis="2Theta" unit="deg">
					<startPosition>73.6419752373084</startPosition>
					<endPosition>76.9892450085249</endPosition>
				</positions>
				<positions axis="Omega" unit="deg">
					<commonPosition>19.1308050614583</commonPosition>
				</positions>
				<positions axis="Phi" unit="deg">
					<commonPosition>-4.15</commonPosition>
				</positions>
				<positions axis="Chi" unit="deg">
					<commonPosition>0</commonPosition>
				</positions>
				<positions axis="Z" unit="mm">
					<commonPosition>8.386</commonPosition>
				</positions>
				<commonCountingTime unit="seconds">0.974</commonCountingTime>
				<counts unit="counts">0 1 1 0 0 1 0 0 0 0 0 0 2 0 0 2 0 0 0 3 0 0 0 0 0 0 0 0 0 0 0 0 1 0 0 0 0 1 2 0 0 0 0 0 0 0 1 2 1 0 0 0 1 0 0 0 0 0 0 0 0 0 0 0 0 0 1 0 0 0 0 0 0 2 0 0 1 0 0 0 0 0 0 0 0 0 1 0 0 1 1 1 0 0 1 1 0 0 0 0 0 0 0 0 0 0 0 0 0 0 1 1 1 1 0 1 0 0 1 1 0 1 0 0 0 1 0 0 0 0 1 0 0 2 0 1 0 0 0 1 0 0 0 0 0 0 0 1 0 0 0 0 0 0 1 0 0 1 2 4 1 0 1 0 1 0 1 1 0 0 0 0 1 0 0 2 0 0 0 0 2 0 0 0 0 0 0 0 0 2 0 1 0 0 0 1 0 1 0 0 0 0 0 0 0 0 1 0 0 0 0 0 2 0 0 0 0 0 0 0 0 0 1 1 0 0 1 0 0 0 0 0 0 0 2 0 2 0 0 1 0 0 0 0 0 0 1 0 0 0 2 1 1 0 0</counts>
			</dataPoints>
		</scan>
		<scan status="Completed" appendNumber="0" scanAxis="2Theta" mode="Continuous">
			<header>
				<startTimeStamp>2024-06-29T16:44:15-04:00</startTimeStamp>
				<endTimeStamp>2024-06-29T16:59:18-04:00</endTimeStamp>
				<author>
					<name>lw627</name>
				</author>
				<source>
					<applicationSoftware version="7.1">Data Collector</applicationSoftware>
					<instrumentControlSoftware version="8.2  20201204">EMPYREAN</instrumentControlSoftware>
					<instrumentID>0000000011260721</instrumentID>
				</source>
			</header>
			<dataPoints>
				<positions axis="2Theta" unit="deg">
					<startPosition>73.6452578079883</startPosition>
					<endPosition>76.9925275792047</endPosition>
				</positions>
				<positions axis="Omega" unit="deg">
					<commonPosition>19.1324463467982</commonPosition>
				</positions>
				<positions axis="Phi" unit="deg">
					<commonPosition>-4.15</commonPosition>
				</positions>
				<positions axis="Chi" unit="deg">
					<commonPosition>0</commonPosition>
				</positions>
				<positions axis="Z" unit="mm">
					<commonPosition>8.386</commonPosition>
				</positions>
				<commonCountingTime unit="seconds">0.974</commonCountingTime>
[...]
					<commonPosition>0</commonPosition>
				</positions>
				<positions axis="Z" unit="mm">
					<commonPosition>8.386</commonPosition>
				</positions>
				<commonCountingTime unit="seconds">0.974</commonCountingTime>
				<counts unit="counts">0 0 0 0 0 0 0 0 0 0 0 0 0 1 0 0 1 1 1 0 0 1 1 0 0 0 0 1 0 1 1 0 1 2 0 2 0 0 1 0 2 2 2 2 4 0 1 1 0 0 2 0 1 1 1 1 1 2 2 0 0 1 2 0 2 0 0 3 0 0 1 1 0 0 2 1 1 1 0 1 1 1 2 1 0 0 1 1 2 0 1 0 0 1 2 3 0 0 0 0 0 0 0 1 1 1 0 0 0 0 0 0 0 0 0 0 0 1 0 0 0 1 1 1 0 0 1 0 1 0 1 0 0 0 0 1 0 0 0 0 0 1 1 0 1 2 0 1 1 1 0 0 0 1 0 0 1 0 1 0 2 0 2 0 0 0 0 0 0 0 0 0 0 0 0 0 0 0 0 1 0 1 0 1 0 0 0 1 0 0 0 0 0 0 0 0 0 0 0 0 0 0 0 0 1 0 1 0 0 0 0 1 1 0 0 0 1 0 0 1 1 0 1 0 0 2 0 0 0 2 0 0 0 0 0 0 0 2 0 0 1 2 0 0 0 0 0 0 0 0 0 0 0 0 0</counts>
			</dataPoints>
		</scan>
		<scan status="Completed" appendNumber="0" scanAxis="2Theta" mode="Continuous">
			<header>
				<startTimeStamp>2024-06-29T16:44:15-04:00</startTimeStamp>
				<endTimeStamp>2024-06-29T16:59:18-04:00</endTimeStamp>
				<author>
					<name>lw627</name>
				</author>
				<source>
					<applicationSoftware version="7.1">Data Collector</applicationSoftware>
					<instrumentControlSoftware version="8.2  20201204">EMPYREAN</instrumentControlSoftware>
					<instrumentID>0000000011260721</instrumentID>
				</source>
			</header>
			<dataPoints>
				<positions axis="2Theta" unit="deg">
					<startPosition>76.5404851475935</startPosition>
					<endPosition>79.88775491881</endPosition>
				</positions>
				<positions axis="Omega" unit="deg">
					<commonPosition>20.5800600166009</commonPosition>
				</positions>
				<positions axis="Phi" unit="deg">
					<commonPosition>-4.15</commonPosition>
				</positions>
				<positions axis="Chi" unit="deg">
					<commonPosition>0</commonPosition>
				</positions>
				<positions axis="Z" unit="mm">
					<commonPosition>8.386</commonPosition>
				</positions>
				<commonCountingTime unit="seconds">0.974</commonCountingTime>
				<counts unit="counts">1 0 1 1 0 0 0 0 0 2 0 1 1 0 1 0 0 2 0 1 0 0 1 1 0 1 1 4 0 0 0 1 1 0 0 0 0 2 0 0 1 0 2 0 2 0 1 0 0 2 1 0 1 0 1 1 0 0 1 1 0 1 0 3 0 1 0 0 0 0 0 1 0 1 0 1 2 0 1 0 1 0 0 0 0 1 1 0 1 2 0 0 1 0 0 1 1 0 0 1 0 1 0 0 0 1 0 0 0 0 0 0 0 0 0 0 0 0 0 0 0 0 0 0 0 1 0 1 1 0 1 1 1 0 0 2 1 0 0 0 0 1 0 0 0 1 1 0 0 0 1 1 0 0 0 1 0 1 1 0 1 1 0 1 0 0 0 0 0 0 1 0 0 0 0 0 0 0 0 1 0 1 1 0 1 1 0 1 1 0 0 0 0 0 0 0 0 0 0 0 0 1 0 0 0 1 0 1 0 0 0 0 0 0 0 3 0 0 0 0 0 1 0 0 0 0 0 0 0 0 1 0 0 0 0 0 1 0 0 0 0 0 0 0 0 0 0 0 1 0 0 0 0 0 0</counts>
			</dataPoints>
		</scan>
		<scan status="Completed" appendNumber="0" scanAxis="2Theta" mode="Continuous">
			<header>
				<startTimeStamp>2024-06-29T16:44:15-04:00</startTimeStamp>
				<endTimeStamp>2024-06-29T16:59:18-04:00</endTimeStamp>
				<author>
					<name>lw627</name>
				</author>
				<source>
					<applicationSoftware version="7.1">Data Collector</applicationSoftware>
					<instrumentControlSoftware version="8.2  20201204">EMPYREAN</instrumentControlSoftware>
					<instrumentID>0000000011260721</instrumentID>
				</source>
			</header>
			<dataPoints>
				<positions axis="2Theta" unit="deg">
					<startPosition>76.5437677182733</startPosition>
					<endPosition>79.8910374894898</endPosition>
				</positions>
				<positions axis="Omega" unit="deg">
					<commonPosition>20.5817013019408</commonPosition>
				</positions>
				<positions axis="Phi" unit="deg">
					<commonPosition>-4.15</commonPosition>
				</positions>
				<positions axis="Chi" unit="deg">
					<commonPosition>0</commonPosition>
				</positions>
				<positions axis="Z" unit="mm">
					<commonPosition>8.386</commonPosition>
				</positions>
				<commonCountingTime unit="seconds">0.974</commonCountingTime>
				<counts unit="counts">0 0 0 1 0 1 0 1 0 0 2 1 0 1 0 3 2 0 1 0 1 0 0 0 1 0 0 1 0 1 2 0 1 1 0 1 1 1 0 1 0 0 0 0 1 1 2 0 2 1 1 0 2 1 1 2 0 2 0 0 0 0 1 1 0 1 2 2 1 0 1 3 1 1 0 0 0 0 0 0 1 1 0 0 1 0 1 1 0 1 0 0 1 0 0 0 2 1 0 0 0 0 0 0 0 1 0 0 0 0 0 0 0 1 1 2 0 0 0 1 0 3 0 0 0 0 0 0 0 1 2 0 0 1 0 0 1 0 0 1 0 0 0 0 0 0 1 0 1 0 0 0 0 0 0 0 0 1 1 1 1 0 0 0 0 0 0 0 1 1 1 1 0 0 1 0 1 0 0 0 0 0 0 0 1 0 0 0 0 0 0 0 1 0 1 0 0 1 1 1 0 2 0 1 0 0 0 0 0 0 0 0 0 1 0 0 0 1 2 0 0 0 0 1 1 1 0 0 0 0 0 0 0 1 0 1 2 0 0 0 0 0 0 0 0 1 1 0 0 0 0 0 0 0 0</counts>
			</dataPoints>
		</scan>
		<scan status="Completed" appendNumber="0" scanAxis="2Theta" mode="Continuous">
			<header>
				<startTimeStamp>2024-06-29T16:44:15-04:00</startTimeStamp>
				<endTimeStamp>2024-06-29T16:59:18-04:00</endTimeStamp>
				<author>
					<name>lw627</name>
				</author>
				<source>
					<applicationSoftware version="7.1">Data Collector</applicationSoftware>
					<instrumentControlSoftware version="8.2  20201204">EMPYREAN</instrumentControlSoftware>
					<instrumentID>0000000011260721</instrumentID>
				</source>
			</header>
			<dataPoints>
				<positions axis="2Theta" unit="deg">
					<startPosition>76.5470502889532</startPosition>
					<endPosition>79.8943200601696</endPosition>
				</positions>
				<positions axis="Omega" unit="deg">
					<commonPosition>20.5833425872807</commonPosition>
				</positions>
				<positions axis="Phi" unit="deg">
					<commonPosition>-4.15</commonPosition>
				</positions>
				<positions axis="Chi" unit="deg">
					<commonPosition>0</commonPosition>
				</positions>
				<positions axis="Z" unit="mm">
					<commonPosition>8.386</commonPosition>
				</positions>
				<commonCountingTime unit="seconds">0.974</commonCountingTime>
				<counts unit="counts">2 1 0 0 0 0 0 0 0 0 0 0 0 0 0 0 0 1 0 1 1 0 0 0 0 1 1 0 0 0 3 0 0 1 0 1 0 1 0 0 1 2 2 2 1 2 2 2 1 0 0 2 0 1 0 0 1 0 2 1 3 1 2 0 0 1 1 0 0 0 2 0 0 1 0 2 0 0 0 0 1 1 0 0 0 2 0 0 3 2 0 0 0 2 0 0 0 1 0 0 1 0 0 0 1 0 2 0 0 1 0 1 0 0 0 0 1 1 0 0 0 0 0 0 0 0 1 0 0 0 1 0 0 0 2 0 0 1 0 1 0 0 0 1 0 0 0 0 0 1 0 1 0 0 0 0 0 0 1 0 0 0 1 1 1 0 0 0 0 1 0 0 1 0 1 0 0 0 0 0 0 0 1 0 0 0 0 1 0 0 0 0 0 0 0 0 0 0 1 0 0 2 0 0 0 0 0 0 0 0 1 0 0 0 1 0 1 0 1 1 0 1 0 3 0 0 0 0 0 0 0 0 0 0 0 0 0 0 0 0 1 1 0 1 0 0 0 1 0 0 1 0 2 0 0</counts>
			</dataPoints>
		</scan>
		<scan status="Completed" appendNumber="0" scanAxis="2Theta" mode="Continuous">
			<header>
				<startTimeStamp>2024-06-29T16:44:15-04:00</startTimeStamp>
				<endTimeStamp>2024-06-29T16:59:18-04:00</endTimeStamp>
				<author>
					<name>lw627</name>
				</author>
				<source>
					<applicationSoftware version="7.1">Data Collector</applicationSoftware>
					<instrumentControlSoftware version="8.2  20201204">EMPYREAN</instrumentControlSoftware>
					<instrumentID>0000000011260721</instrumentID>
				</source>
			</header>
			<dataPoints>
				<positions axis="2Theta" unit="deg">
					<startPosition>76.550332859633</startPosition>
					<endPosition>79.8976026308495</endPosition>
				</positions>
				<positions axis="Omega" unit="deg">
					<commonPosition>20.5849838726206</commonPosition>
				</positions>
				<positions axis="Phi" unit="deg">
					<commonPosition>-4.15</commonPosition>
				</positions>
				<positions axis="Chi" unit="deg">
					<commonPosition>0</commonPosition>
				</positions>
				<positions axis="Z" unit="mm">
					<commonPosition>8.386</commonPosition>
				</positions>
				<commonCountingTime unit="seconds">0.974</commonCountingTime>
				<counts unit="counts">0 1 0 2 1 0 0 0 0 0 1 0 1 0 0 0 1 1 0 1 0 0 0 1 0 0 0 0 2 0 0 0 1 2 0 0 0 0 2 2 3 2 0 4 0 1 0 2 1 0 0 1 2 0 1 0 1 3 1 2 2 0 0 1 0 1 0 1 1 0 1 0 1 0 0 0 2 0 0 0 0 0 0 2 1 0 0 0 0 0 0 0 1 1 0 0 1 0 0 2 1 0 0 2 0 0 0 0 0 0 0 0 0 0 0 0 0 1 0 0 1 1 1 0 1 0 2 1 1 0 0 0 0 0 0 0 0 1 0 0 1 0 0 0 0 0 0 0 0 1 0 0 0 0 1 0 1 2 2 0 1 0 0 0 1 0 0 0 0 0 0 0 0 0 2 0 1 0 0 0 1 0 0 0 1 0 1 0 0 0 0 0 0 0 0 1 0 1 0 0 0 0 0 0 0 0 0 0 0 0 1 0 0 0 0 0 1 0 0 0 0 0 0 0 1 0 0 1 0 0 1 0 0 0 0 1 0 1 0 0 1 0 0 0 0 1 0 0 1 0 0 0 0 0 0</counts>
			</dataPoints>
		</scan>
		<scan status="Completed" appendNumber="0" scanAxis="2Theta" mode="Continuous">
			<header>
				<startTimeStamp>2024-06-29T16:44:15-04:00</startTimeStamp>
				<endTimeStamp>2024-06-29T16:59:18-04:00</endTimeStamp>
				<author>
					<name>lw627</name>
				</author>
				<source>
					<applicationSoftware version="7.1">Data Collector</applicationSoftware>
					<instrumentControlSoftware version="8.2  20201204">EMPYREAN</instrumentControlSoftware>
					<instrumentID>0000000011260721</instrumentID>
				</source>
			</header>
			<dataPoints>
				<positions axis="2Theta" unit="deg">
					<startPosition>76.5536154303128</startPosition>
					<endPosition>79.9008852015293</endPosition>
				</positions>
				<positions axis="Omega" unit="deg">
					<commonPosition>20.5866251579605</commonPosition>
				</positions>
				<positions axis="Phi" unit="deg">
					<commonPosition>-4.15</commonPosition>
				</positions>
				<positions axis="Chi" unit="deg">
					<commonPosition>0</commonPosition>
				</positions>
				<positions axis="Z" unit="mm">
					<commonPosition>8.386</commonPosition>
				</positions>
				<commonCountingTime unit="seconds">0.974</commonCountingTime>
				<counts unit="counts">1 0 0 0 2 1 0 1 0 0 1 0 2 0 0 0 1 1 0 0 3 1 0 2 0 2 0 0 0 1 0 0 0 0 0 0 0 0 1 1 3 2 3 2 1 0 2 4 1 2 2 1 0 1 3 1 0 1 2 1 0 0 0 2 0 0 0 0 1 5 0 0 0 0 1 0 0 0 1 1 0 0 1 0 1 0 0 0 1 0 0 0 1 1 1 1 1 3 1 0 2 0 1 1 0 0 2 0 0 0 1 0 1 0 0 0 0 1 0 0 0 0 2 0 0 0 1 0 0 0 1 1 0 0 0 0 0 0 0 1 0 0 0 1 0 0 0 0 0 0 0 0 0 0 1 0 1 0 0 0 0 0 0 0 0 1 0 0 0 0 0 1 0 0 0 0 0 0 0 0 0 0 0 0 0 0 0 0 0 0 0 1 1 0 1 0 0 0 0 0 0 0 0 0 1 0 0 1 0 1 1 0 2 0 2 0 1 0 1 1 0 0 0 0 0 0 0 0 0 0 0 0 0 1 1 0 1 1 2 0 0 0 1 0 1 0 0 0 1 0 0 1 0 1 0</counts>
			</dataPoints>
		</scan>
		<scan status="Completed" appendNumber="0" scanAxis="2Theta" mode="Continuous">
			<header>
				<startTimeStamp>2024-06-29T16:44:15-04:00</startTimeStamp>
				<endTimeStamp>2024-06-29T16:59:18-04:00</endTimeStamp>
				<author>
					<name>lw627</name>
				</author>
				<source>
					<applicationSoftware version="7.1">Data Collector</applicationSoftware>
					<instrumentControlSoftware version="8.2  20201204">EMPYREAN</instrumentControlSoftware>
					<instrumentID>0000000011260721</instrumentID>
				</source>
			</header>
			<dataPoints>
				<positions axis="2Theta" unit="deg">
					<startPosition>76.5568980009926</startPosition>
					<endPosition>79.9041677722091</endPosition>
				</positions>
				<positions axis="Omega" unit="deg">
					<commonPosition>20.5882664433004</commonPosition>
				</positions>
				<positions axis="Phi" unit="deg">
					<commonPosition>-4.15</commonPosition>
				</positions>
				<positions axis="Chi" unit="deg">
					<commonPosition>0</commonPosition>
				</positions>
				<positions axis="Z" unit="mm">
					<commonPosition>8.386</commonPosition>
				</positions>
				<commonCountingTime unit="seconds">0.974</commonCountingTime>
				<counts unit="counts">0 1 2 1 1 0 0 1 0 0 0 0 1 0 0 1 0 0 0 0 1 0 0 0 0 0 0 0 0 0 0 0 3 1 0 0 1 0 2 1 2 0 3 2 2 2 2 1 2 0 1 0 2 2 2 3 1 0 0 0 0 0 1 2 0 1 1 0 0 0 1 1 2 0 0 1 0 0 2 0 2 0 0 2 0 0 0 1 0 0 2 1 0 1 2 1 0 1 0 1 0 1 1 0 0 0 1 0 0 1 0 0 0 0 0 1 1 0 0 1 0 1 1 0 0 1 0 1 0 0 0 0 0 0 0 1 0 0 0 0 0 0 1 0 1 2 0 0 0 0 0 0 2 0 0 0 0 0 0 1 0 0 0 0 0 1 0 0 0 0 0 0 0 1 0 0 0 0 0 0 0 0 1 0 0 0 0 0 0 0 0 1 0 1 0 0 0 0 0 0 0 1 0 0 0 0 1 1 0 0 0 1 1 1 0 0 0 0 0 1 0 1 0 0 0 1 1 1 0 1 0 0 1 0 0 0 0 0 0 0 0 0 0 1 0 0 0 0 0 0 1 1 0 0 0</counts>
			</dataPoints>
		</scan>
		<scan status="Completed" appendNumber="0" scanAxis="2Theta" mode="Continuous">
			<header>
				<startTimeStamp>2024-06-29T16:44:15-04:00</startTimeStamp>
				<endTimeStamp>2024-06-29T16:59:18-04:00</endTimeStamp>
				<author>
					<name>lw627</name>
				</author>
				<source>
					<applicationSoftware version="7.1">Data Collector</applicationSoftware>
					<instrumentControlSoftware version="8.2  20201204">EMPYREAN</instrumentControlSoftware>
					<instrumentID>0000000011260721</instrumentID>
				</source>
			</header>
			<dataPoints>
				<positions axis="2Theta" unit="deg">
					<startPosition>76.5601805716725</startPosition>
					<endPosition>79.9074503428889</endPosition>
				</positions>
				<positions axis="Omega" unit="deg">
					<commonPosition>20.5899077286404</commonPosition>
				</positions>
				<positions axis="Phi" unit="deg">
					<commonPosition>-4.15</commonPosition>
				</positions>
				<positions axis="Chi" unit="deg">
					<commonPosition>0</commonPosition>
				</positions>
				<positions axis="Z" unit="mm">
					<commonPosition>8.386</commonPosition>
				</positions>
				<commonCountingTime unit="seconds">0.974</commonCountingTime>
				<counts unit="counts">0 0 0 0 0 2 0 0 1 2 0 0 0 0 0 2 0 1 1 0 1 0 0 0 1 0 1 0 0 1 0 1 0 1 1 1 1 0 1 0 0 1 1 0 0 0 2 1 1 1 0 0 0 0 1 1 0 0 1 1 0 0 3 0 2 0 1 0 0 0 0 0 0 1 0 0 0 1 0 0 0 0 0 0 1 0 0 0 0 1 1 0 0 0 2 2 0 1 2 0 0 0 0 0 0 0 1 0 2 0 0 0 0 0 0 0 0 0 1 1 0 0 1 0 0 0 0 0 0 2 0 0 1 0 2 0 0 0 0 0 1 0 1 2 1 0 0 0 0 0 1 0 0 0 0 1 1 0 1 0 0 0 0 0 0 1 1 0 0 2 0 0 0 1 0 0 0 0 0 0 0 1 0 1 0 0 0 0 0 1 0 0 0 0 0 1 0 2 0 1 0 0 1 3 2 0 0 0 0 0 0 1 0 0 1 0 0 1 0 0 0 0 0 1 0 0 0 1 0 0 1 0 1 0 0 0 1 0 1 0 0 0 0 0 0 0 0 0 0 0 0 0 1 1 0</counts>
			</dataPoints>
		</scan>
		<scan status="Completed" appendNumber="0" scanAxis="2Theta" mode="Continuous">
			<header>
				<startTimeStamp>2024-06-29T16:44:15-04:00</startTimeStamp>
				<endTimeStamp>2024-06-29T16:59:18-04:00</endTimeStamp>
				<author>
					<name>lw627</name>
				</author>
				<source>
					<applicationSoftware version="7.1">Data Collector</applicationSoftware>
					<instrumentControlSoftware version="8.2  20201204">EMPYREAN</instrumentControlSoftware>
					<instrumentID>0000000011260721</instrumentID>
				</source>
			</header>
			<dataPoints>
				<positions axis="2Theta" unit="deg">
					<startPosition>76.5634631423523</startPosition>
					<endPosition>79.9107329135688</endPosition>
				</positions>
				<positions axis="Omega" unit="deg">
					<commonPosition>20.5915490139803</commonPosition>
				</positions>
				<positions axis="Phi" unit="deg">
					<commonPosition>-4.15</commonPosition>
				</positions>
				<positions axis="Chi" unit="deg">
					<commonPosition>0</commonPosition>
				</positions>
				<positions axis="Z" unit="mm">
					<commonPosition>8.386</commonPosition>
				</positions>
				<commonCountingTime unit="seconds">0.974</commonCountingTime>
				<counts unit="counts">0 0 0 1 0 0 0 1 1 0 2 0 0 0 2 0 1 0 0 0 1 1 0 2 0 1 1 0 0 1 0 1 0 0 0 0 0 2 1 1 2 1 2 2 2 0 2 0 2 1 1 1 0 0 0 0 1 1 1 2 0 0 0 1 0 1 0 0 2 2 0 0 0 1 0 0 0 0 1 0 0 0 0 0 2 0 0 0 0 1 0 1 1 0 2 1 1 0 0 1 0 0 0 0 0 0 0 1 0 0 2 1 0 0 1 0 0 0 1 1 0 0 0 0 0 0 1 0 0 0 0 0 1 0 0 0 1 0 0 0 1 0 0 1 0 0 1 0 0 0 1 0 2 1 0 1 0 1 0 1 0 0 0 1 0 0 0 0 0 0 1 0 0 0 0 0 0 1 1 1 0 0 0 0 0 0 0 0 0 0 1 1 0 0 0 1 0 0 1 0 0 0 0 0 0 0 0 0 1 0 2 0 0 0 0 0 0 0 0 0 0 0 0 0 0 0 0 0 0 1 1 1 0 0 1 0 0 0 0 0 1 0 0 0 0 0 1 0 0 0 0 0 0 0 0</counts>
			</dataPoints>
		</scan>
		<scan status="Completed" appendNumber="0" scanAxis="2Theta" mode="Continuous">
			<header>
				<startTimeStamp>2024-06-29T16:44:15-04:00</startTimeStamp>
				<endTimeStamp>2024-06-29T16:59:18-04:00</endTimeStamp>
				<author>
					<name>lw627</name>
				</author>
				<source>
					<applicationSoftware version="7.1">Data Collector</applicationSoftware>
					<instrumentControlSoftware version="8.2  20201204">EMPYREAN</instrumentControlSoftware>
					<instrumentID>0000000011260721</instrumentID>
				</source>
			</header>
			<dataPoints>
				<positions axis="2Theta" unit="deg">
					<startPosition>76.5667457130321</startPosition>
					<endPosition>79.9140154842486</endPosition>
				</positions>
				<positions axis="Omega" unit="deg">
					<commonPosition>20.5931902993202</commonPosition>
				</positions>
				<positions axis="Phi" unit="deg">
					<commonPosition>-4.15</commonPosition>
				</positions>
				<positions axis="Chi" unit="deg">
					<commonPosition>0</commonPosition>
				</positions>
				<positions axis="Z" unit="mm">
					<commonPosition>8.386</commonPosition>
				</positions>
				<commonCountingTime unit="seconds">0.974</commonCountingTime>
				<counts unit="counts">0 0 1 0 0 0 0 1 0 0 0 0 0 0 0 0 0 0 0 1 0 0 1 0 0 1 1 1 0 1 0 2 0 0 0 0 1 0 1 2 3 3 2 1 0 1 2 0 1 2 1 3 0 1 0 1 0 1 0 1 0 0 1 0 2 0 1 0 1 0 0 0 0 0 1 1 1 3 1 0 0 1 1 0 0 0 0 0 1 0 0 0 1 2 1 1 1 0 0 0 0 1 0 0 0 0 0 1 1 1 0 0 0 0 1 0 0 0 1 1 0 0 1 0 1 1 0 1 0 0 1 1 0 0 0 0 0 1 1 0 0 0 0 0 1 1 0 0 0 0 1 0 0 1 0 0 0 0 0 1 0 0 0 0 0 0 1 1 0 0 0 0 1 0 0 1 0 0 0 1 0 0 0 0 0 0 0 0 0 0 0 0 0 0 0 0 0 0 0 0 0 2 1 1 0 0 0 0 1 0 0 0 0 0 0 0 0 0 0 0 0 0 0 0 0 1 0 0 0 1 0 0 0 0 0 0 0 0 0 0 0 0 0 0 0 2 1 0 0 0 0 0 1 0 0</counts>
			</dataPoints>
		</scan>
		<scan status="Completed" appendNumber="0" scanAxis="2Theta" mode="Continuous">
			<header>
				<startTimeStamp>2024-06-29T16:44:15-04:00</startTimeStamp>
				<endTimeStamp>2024-06-29T16:59:18-04:00</endTimeStamp>
				<author>
					<name>lw627</name>
				</author>
				<source>
					<applicationSoftware version="7.1">Data Collector</applicationSoftware>
					<instrumentControlSoftware version="8.2  20201204">EMPYREAN</instrumentControlSoftware>
					<instrumentID>0000000011260721</instrumentID>
				</source>
			</header>
			<dataPoints>
				<positions axis="2Theta" unit="deg">
					<startPosition>76.5700282837119</startPosition>
					<endPosition>79.9172980549284</endPosition>
				</positions>
				<positions axis="Omega" unit="deg">
					<commonPosition>20.5948315846601</commonPosition>
				</positions>
				<positions axis="Phi" unit="deg">
					<commonPosition>-4.15</commonPosition>
				</positions>
				<positions axis="Chi" unit="deg">
					<commonPosition>0</commonPosition>
				</positions>
				<positions axis="Z" unit="mm">
					<commonPosition>8.386</commonPosition>
				</positions>
				<commonCountingTime unit="seconds">0.974</commonCountingTime>
				<counts unit="counts">0 0 0 0 0 1 0 0 0 0 0 1 0 1 1 2 0 0 0 0 0 0 0 2 0 0 0 1 1 1 2 0 1 0 0 2 1 2 1 4 1 1 1 2 1 4 2 0 1 0 1 0 0 0 1 0 0 2 0 1 0 0 1 2 0 0 0 0 0 1 0 0 0 1 0 1 0 1 0 0 1 0 1 0 1 0 0 1 1 0 1 0 0 0 1 0 1 0 0 0 1 0 1 1 0 1 0 0 0 0 0 0 1 0 0 0 0 0 0 0 0 0 0 0 0 0 1 0 0 2 0 1 0 0 0 0 0 0 0 0 0 0 0 0 0 0 1 0 0 0 1 1 0 1 0 0 1 0 0 0 0 0 0 0 0 0 0 0 1 1 0 0 0 1 0 0 0 1 0 0 0 0 1 0 0 0 0 0 1 0 0 0 0 0 0 0 2 0 1 1 0 0 1 0 1 0 1 0 0 0 0 0 1 1 0 0 2 1 0 0 1 0 0 0 0 0 0 0 0 0 0 1 0 0 0 0 0 0 0 0 0 0 1 0 0 0 0 1 2 1 1 0 0 1 0</counts>
			</dataPoints>
		</scan>
		<scan status="Completed" appendNumber="0" scanAxis="2Theta" mode="Continuous">
			<header>
				<startTimeStamp>2024-06-29T16:44:15-04:00</startTimeStamp>
				<endTimeStamp>2024-06-29T16:59:18-04:00</endTimeStamp>
				<author>
					<name>lw627</name>
				</author>
				<source>
					<applicationSoftware version="7.1">Data Collector</applicationSoftware>
					<instrumentControlSoftware version="8.2  20201204">EMPYREAN</instrumentControlSoftware>
					<instrumentID>0000000011260721</instrumentID>
				</source>
			</header>
			<dataPoints>
				<positions axis="2Theta" unit="deg">
					<startPosition>76.5733108543918</startPosition>
					<endPosition>79.9205806256082</endPosition>
				</positions>
				<positions axis="Omega" unit="deg">
					<commonPosition>20.59647287</commonPosition>
				</positions>
				<positions axis="Phi" unit="deg">
					<commonPosition>-4.15</commonPosition>
				</positions>
				<positions axis="Chi" unit="deg">
					<commonPosition>0</commonPosition>
				</positions>
				<positions axis="Z" unit="mm">
					<commonPosition>8.386</commonPosition>
				</positions>
				<commonCountingTime unit="seconds">0.974</commonCountingTime>
				<counts unit="counts">1 0 0 0 0 0 1 0 0 1 0 0 0 0 0 0 1 0 0 1 0 0 0 1 0 0 0 0 2 0 2 1 0 1 1 1 0 0 1 1 1 0 2 1 3 1 1 0 0 1 0 1 1 1 2 2 1 0 1 1 1 0 0 2 0 0 1 0 0 1 1 1 0 0 0 0 0 0 1 0 0 0 0 0 0 1 1 2 0 0 0 1 1 0 0 0 0 0 0 0 0 1 0 0 0 1 1 0 0 1 0 0 1 0 1 0 1 0 0 1 0 0 1 2 0 0 0 1 0 1 0 0 1 0 1 0 0 1 1 0 0 0 0 0 0 1 0 0 1 2 0 1 0 0 0 0 0 1 0 0 0 0 1 0 0 0 0 1 0 1 0 1 0 0 1 0 0 0 1 0 0 0 0 0 1 1 3 0 1 0 0 0 0 1 1 0 0 1 0 0 0 0 0 0 0 0 1 1 1 0 2 0 0 0 0 0 0 0 0 0 0 0 1 0 1 0 0 0 0 0 0 0 2 1 1 0 0 1 1 0 0 0 1 1 0 1 0 0 1 0 0 0 0 1 0</counts>
			</dataPoints>
		</scan>
	</xrdMeasurement>
</xrdMeasurements>