File: data/previous_data/set_4-YG039-041/xrd/YG039-SRO001-STO001-07142022.xrdml
<xrdMeasurements xmlns="http://www.xrdml.com/XRDMeasurement/2.1" xmlns:xsi="http://www.w3.org/2001/XMLSchema-instance" xsi:schemaLocation="http://www.xrdml.com/XRDMeasurement/2.1 http://www.xrdml.com/XRDMeasurement/2.1/XRDMeasurement.xsd" status="Completed">
	<comment>
		<entry>Configuration=Main Configuration, Owner=User-1, Creation date=6/17/2015 3:36:16 PM</entry>
		<entry>Goniometer=HR HD (Theta/2Theta); Minimum step size 2Theta:0.0001; Minimum step size Omega:0.0001</entry>
		<entry>Sample stage=MRD Cradle; Minimum step size Phi:0.01; Minimum step size Chi:0.01; Minimum step size X:0.01; Minimum step size Y:0.01; Minimum step size Z:0.001</entry>
		<entry>Diffractometer system=XPERT-3</entry>
		<entry>Measurement program=C:\PANalytical\Data Collector\Programs\Yichen\regular_2theta_20-50_0.4s-20min.xrdmp, Identifier={AEA8F2F2-8BFA-4B07-A521-A571AF38E73A}</entry>
	</comment>
	<sample type="To be analyzed">
		<id></id>
		<name></name>
		<preparedBy></preparedBy>
	</sample>
	<xrdMeasurement measurementType="Scan" status="Completed" sampleMode="Reflection">
		<comment>
			<entry>PHD Lower Level = 4.02 (keV), PHD Upper Level = 11.27 (keV)</entry>
		</comment>
		<usedWavelength intended="K-Alpha 1">
			<kAlpha1 unit="Angstrom">1.5405980</kAlpha1>
			<kAlpha2 unit="Angstrom">1.5444260</kAlpha2>
			<kBeta unit="Angstrom">1.3922500</kBeta>
			<ratioKAlpha2KAlpha1>0.5000</ratioKAlpha2KAlpha1>
		</usedWavelength>
		<incidentBeamPath>
			<radius unit="mm">320.00</radius>
			<xRayTube id="1010048" name="Empyrean Cu LFF HR (9430 033 7310x) DK425175">
				<tension unit="kV">45.0</tension>
				<current unit="mA">40.0</current>
				<anodeMaterial>Cu</anodeMaterial>
				<focus type="Line">
					<length unit="mm">12.0</length>
					<width unit="mm">0.4</width>
					<takeOffAngle unit="deg">4.2</takeOffAngle>
				</focus>
			</xRayTube>
			<xRayMirror id="27090001" name="Inc. Beam Cu W/Si (hybrid MRD)" hybrid="true">
				<crystal type="Graded" shape="Parabolic">W/Si</crystal>
				<acceptanceAngle unit="deg">0.800</acceptanceAngle>
				<length unit="mm">60.0</length>
			</xRayMirror>
			<monochromator id="23090002" name="Hybrid monochr. 2xGe(220) Cu asym." hybrid="true">
				<crystal type="Asymmetric" shape="Flat">Ge</crystal>
				<numberOfReflections>2</numberOfReflections>
				<hkl>
					<h>2</h>
					<k>2</k>
					<l>0</l>
				</hkl>
			</monochromator>
			<divergenceSlit id="22010004" name="Fixed slit 1/2°" xsi:type="fixedDivergenceSlitType">
				<distanceToSample unit="mm">220.00</distanceToSample>
				<height unit="mm">0.76</height>
			</divergenceSlit>
			<beamAttenuator id="26010001" name="Progr. beam attenuator Ni 0.125 mm" xsi:type="intensitySwitchedBeamAttenuatorType">
				<factor>172.00</factor>
				<material>Ni</material>
				<activateLevel unit="counts per second">500000</activateLevel>
				<deactivateLevel unit="counts per second">400000</deactivateLevel>
			</beamAttenuator>
		</incidentBeamPath>
		<diffractedBeamPath>
			<radius unit="mm">320.00</radius>
			<antiScatterSlit id="22090009" name="AS slit 7.5 mm (PIXcel)" xsi:type="fixedAntiScatterSlitType">
				<height unit="mm">7.50</height>
			</antiScatterSlit>
			<sollerSlit id="21010002" name="Soller slits 0.04 rad.">
				<opening unit="rad">0.0400</opening>
			</sollerSlit>
			<receivingSlit id="22010004" name="Fixed slit 1/2°">
				<height unit="mm">0.76</height>
			</receivingSlit>
			<detector id="7010020" name="PIXcel3D-Medipix3 1x1 detector" xsi:type="areaDetectorType">
				<phd unit="%">
					<lowerLevel>25.0</lowerLevel>
					<upperLevel>70.0</upperLevel>
				</phd>
				<mode>Receiving slit</mode>
				<activeChannelsEquatorial>5</activeChannelsEquatorial>
				<activeChannelsAxial>255</activeChannelsAxial>
				<pitchEquatorial unit="mm">0.05500</pitchEquatorial>
				<pitchAxial unit="mm">0.05500</pitchAxial>
				<readOutPeriod unit="seconds">0.050</readOutPeriod>
			</detector>
		</diffractedBeamPath>
		<scan appendNumber="0" mode="Continuous" scanAxis="2Theta-Omega" status="Completed">
			<header>
				<startTimeStamp>2022-07-14T14:24:00-07:00</startTimeStamp>
				<endTimeStamp>2022-07-14T14:44:26-07:00</endTimeStamp>
				<author>
					<name>XRD</name>
				</author>
				<source>
					<applicationSoftware version="6.1b">Data Collector</applicationSoftware>
					<instrumentControlSoftware version="7.4b 20181204">XPERT-3</instrumentControlSoftware>
					<instrumentID>0000000011163216</instrumentID>
				</source>
			</header>
			<dataPoints>
				<positions axis="2Theta" unit="deg">
					<startPosition>20.0050</startPosition>
					<endPosition>49.9950</endPosition>
				</positions>
				<positions axis="Omega" unit="deg">
					<startPosition>9.7655</startPosition>
					<endPosition>24.7605</endPosition>
				</positions>
				<positions axis="Phi" unit="deg">
					<commonPosition>0.00</commonPosition>
				</positions>
				<positions axis="Chi" unit="deg">
					<commonPosition>-0.06</commonPosition>
				</positions>
				<positions axis="X" unit="mm">
					<commonPosition>0.04</commonPosition>
				</positions>
				<positions axis="Y" unit="mm">
					<commonPosition>0.00</commonPosition>
				</positions>
				<positions axis="Z" unit="mm">
					<commonPosition>8.280</commonPosition>
				</positions>
				<beamAttenuationFactors>1.00 1.00 1.00 1.00 1.00 1.00 1.00 1.00 1.00 1.00 1.00 1.00 1.00 1.00 1.00 1.00 1.00 1.00 1.00 1.00 1.00 1.00 1.00 1.00 1.00 1.00 1.00 1.00 1.00 1.00 1.00 1.00 1.00 1.00 1.00 1.00 1.00 1.00 1.00 1.00 1.00 1.00 1.00 1.00 1.00 1.00 1.00 1.00 1.00 1.00 1.00 1.00 1.00 1.00 1.00 1.00 1.00 1.00 1.00 1.00 1.00 1.00 1.00 1.00 1.00 1.00 1.00 1.00 1.00 1.00 1.00 1.00 1.00 1.00 1.00 1.00 1.00 1.00 1.00 1.00 1.00 1.00 1.00 1.00 1.00 1.00 1.00 1.00 1.00 1.00 1.00 1.00 1.00 1.00 1.00 1.00 1.00 1.00 1.00 1.00 1.00 1.00 1.00 1.00 1.00 1.00 1.00 1.00 1.00 1.00 1.00 1.00 1.00 1.00 1.00 1.00 1.00 1.00 1.00 1.00 1.00 1.00 1.00 1.00 1.00 1.00 1.00 1.00 1.00 1.00 1.00 1.00 1.00 1.00 1.00 1.00 1.00 1.00 1.00 1.00 1.00 1.00 1.00 1.00 1.00 1.00 1.00 1.00 1.00 1.00 1.00 1.00 1.00 1.00 1.00 1.00 1.00 1.00 1.00 1.00 1.00 1.00 1.00 1.00 1.00 1.00 1.00 1.00 1.00 1.00 1.00 1.00 1.00 1.00 1.00 1.00 1.00 1.00 1.00 1.00 1.00 1.00 1.00 1.00 1.00 1.00 1.00 1.00 1.00 1.00 1.00 1.00 1.00 1.00 1.00 1.00 1.00 1.00 1.00 1.00 1.00 1.00 1.00 1.00 1.00 1.00 1.00 1.00 1.00 1.00 1.00 1.00 1.00 1.00 1.00 1.00 1.00 1.00 1.00 1.00 1.00 1.00 1.00 1.00 1.00 1.00 1.00 1.00 1.00 1.00 1.00 1.00 1.00 1.00 1.00 1.00 1.00 1.00 1.00 1.00 1.00 1.00 1.00 1.00 1.00 1.00 1.00 1.00 1.00 1.00 1.00 1.00 1.00 1.00 1.00 1.00 1.00 1.00 1.00 1.00 1.00 1.00 1.00 1.00 1.00 1.00 1.00 1.00 1.00 1.00 1.00 1.00 1.00 1.00 1.00 1.00 1.00 1.00 1.00 1.00 1.00 1.00 1.00 1.00 1.00 1.00 1.00 1.00 1.00 1.00 1.00 1.00 1.00 1.00 1.00 1.00 1.00 1.00 1.00 1.00 1.00 1.00 1.00 1.00 1.00 1.00 1.00 1.00 1.00 1.00 1.00 1.00 1.00 1.00 1.00 1.00 1.00 1.00 1.00 1.00 1.00 1.00 1.00 1.00 1.00 1.00 1.00 1.00 1.00 1.00 1.00 1.00 1.00 1.00 1.00 1.00 1.00 1.00 1.00 1.00 1.00 1.00 1.00 1.00 1.00 1.00 1.00 1.00 1.00 1.00 1.00 1.00 1.00 1.00 1.00 1.00 1.00 1.00 1.00 1.00 1.00 1.00 1.00 1.00 1.00 1.00 1.00 1.00 1.00 1.00 1.00 1.00 1.00 1.00 1.00 1.00 1.00 1.00 1.00 1.00 1.00 1.00 1.00 1.00 1.00 1.00 1.00 1.00 1.00 1.00 1.00 1.00 1.00 1.00 1.00 1.00 1.00 1.00 1.00 1.00 1.00 1.00 1.00 1.00 1.00 1.00 1.00 1.00 1.00 1.00 1.00 1.00 1.00 1.00 1.00 1.00 1.00 1.00 1.00 1.00 1.00 1.00 1.00 1.00 1.00 1.00 1.00 1.00 1.00 1.00 1.00 1.00 1.00 1.00 1.00 1.00 1.00 1.00 1.00 1.00 1.00 1.00 1.00 1.00 1.00 1.00 1.00 1.00 1.00 1.00 1.00 1.00 1.00 1.00 1.00 1.00 1.00 1.00 1.00 1.00 1.00 1.00 1.00 1.00 1.00 1.00 1.00 1.00 1.00 1.00 1.00 1.00 1.00 1.00 1.00 1.00 1.00 1.00 1.00 1.00 1.00 1.00 1.00 1.00 1.00 1.00 1.00 1.00 1.00 1.00 1.00 1.00 1.00 1.00 1.00 1.00 1.00 1.00 1.00 1.00 1.00 1.00 1.00 1.00 1.00 1.00 1.00 1.00 1.00 1.00 1.00 1.00 1.00 1.00 1.00 1.00 1.00 1.00 1.00 1.00 1.00 1.00 1.00 1.00 1.00 1.00 1.00 1.00 1.00 1.00 1.00 1.00 1.00 1.00 1.00 1.00 1.00 1.00 1.00 1.00 1.00 1.00 1.00 1.00 1.00 1.00 1.00 1.00 1.00 1.00 1.00 1.00 1.00 1.00 1.00 1.00 1.00 1.00 1.00 1.00 1.00 1.00 1.00 1.00 1.00 1.00 1.00 1.00 1.00 1.00 1.00 1.00 1.00 1.00 1.00 1.00 1.00 1.00 1.00 1.00 1.00 1.00 1.00 1.00 1.00 1.00 1.00 1.00 1.00 1.00 1.00 1.00 1.00 1.00 1.00 1.00 1.00 1.00 1.00 1.00 1.00 1.00 1.00 1.00 1.00 1.00 1.00 1.00 1.00 1.00 1.00 1.00 1.00 1.00 1.00 1.00 1.00 1.00 1.00 1.00 1.00 1.00 1.00 1.00 1.00 1.00 1.00 1.00 1.00 1.00 1.00 1.00 1.00 1.00 1.00 1.00 1.00 1.00 1.00 1.00 1.00 1.00 1.00 1.00 1.00 1.00 1.00 1.00 1.00 1.00 1.00 1.00 1.00 1.00 1.00 1.00 1.00 1.00 1.00 1.00 1.00 1.00 1.00 1.00 1.00 1.00 1.00 1.00 1.00 1.00 1.00 1.00 1.00 1.00 1.00 1.00 1.00 1.00 1.00 1.00 1.00 1.00 1.00 1.00 1.00 1.00 1.00 1.00 1.00 1.00 1.00 1.00 1.00 1.00 1.00 1.00 1.00 1.00 1.00 1.00 1.00 1.00 1.00 1.00 1.00 1.00 1.00 1.00 1.00 1.00 1.00 1.00 1.00 1.00 1.00 1.00 1.00 1.00 1.00 1.00 1.00 1.00 1.00 1.00 1.00 1.00 1.00 1.00 1.00 1.00 1.00 1.00 1.00 1.00 1.00 1.00 1.00 1.00 1.00 1.00 1.00 1.00 1.00 1.00 1.00 1.00 1.00 1.00 1.00 1.00 1.00 1.00 1.00 1.00 1.00 1.00 1.00 1.00 1.00 1.00 1.00 1.00 1.00 1.00 1.00 1.00 1.00 1.00 1.00 1.00 1.00 1.00 1.00 1.00 1.00 1.00 1.00 1.00 1.00 1.00 1.00 1.00 1.00 1.00 1.00 1.00 1.00 1.00 1.00 1.00 1.00 1.00 1.00 1.00 1.00 1.00 1.00 1.00 1.00 1.00 1.00 1.00 1.00 1.00 1.00 1.00 1.00 1.00 1.00 1.00 1.00 1.00 1.00 1.00 1.00 1.00 1.00 1.00 1.00 1.00 1.00 1.00 1.00 1.00 1.00 1.00 1.00 1.00 1.00 1.00 1.00 1.00 1.00 1.00 1.00 1.00 1.00 1.00 1.00 1.00 1.00 1.00 1.00 1.00 1.00 1.00 1.00 1.00 1.00 1.00 1.00 1.00 1.00 1.00 1.00 1.00 1.00 1.00 1.00 1.00 1.00 1.00 1.00 1.00 1.00 1.00 1.00 1.00 1.00 1.00 1.00 1.00 1.00 1.00 1.00 1.00 1.00 1.00 1.00 1.00 1.00 1.00 1.00 1.00 1.00 1.00 1.00 1.00 1.00 1.00 1.00 1.00 1.00 1.00 1.00 1.00 1.00 1.00 1.00 1.00 1.00 1.00 1.00 1.00 1.00 1.00 1.00 1.00 1.00 1.00 1.00 1.00 1.00 1.00 1.00 1.00 1.00 1.00 1.00 1.00 1.00 1.00 1.00 1.00 1.00 1.00 1.00 1.00 1.00 1.00 1.00 1.00 1.00 1.00 1.00 1.00 1.00 1.00 1.00 1.00 1.00 1.00 1.00 1.00 1.00 1.00 1.00 1.00 1.00 1.00 1.00 1.00 1.00 1.00 1.00 1.00 1.00 1.00 1.00 1.00 1.00 1.00 1.00 1.00 1.00 1.00 1.00 1.00 1.00 1.00 1.00 1.00 1.00 1.00 1.00 1.00 1.00 1.00 1.00 1.00 1.00 1.00 1.00 1.00 1.00 1.00 1.00 1.00 1.00 1.00 1.00 1.00 1.00 1.00 1.00 1.00 1.00 1.00 1.00 1.00 1.00 1.00 1.00 1.00 1.00 1.00 1.00 1.00 1.00 1.00 1.00 1.00 1.00 1.00 1.00 1.00 1.00 1.00 1.00 1.00 1.00 1.00 1.00 1.00 1.00 1.00 1.00 1.00 1.00 1.00 1.00 1.00 1.00 1.00 1.00 1.00 1.00 1.00 1.00 1.00 1.00 1.00 1.00 1.00 1.00 1.00 1.00 1.00 1.00 1.00 1.00 1.00 1.00 1.00 1.00 1.00 1.00 1.00 1.00 1.00 1.00 1.00 1.00 1.00 1.00 1.00 1.00 1.00 1.00 1.00 1.00 1.00 1.00 1.00 1.00 1.00 1.00 1.00 1.00 1.00 1.00 1.00 1.00 1.00 1.00 1.00 1.00 1.00 1.00 1.00 1.00 1.00 1.00 1.00 1.00 1.00 1.00 1.00 1.00 1.00 1.00 1.00 1.00 1.00 1.00 1.00 1.00 1.00 1.00 1.00 1.00 1.00 1.00 1.00 1.00 1.00 1.00 1.00 1.00 1.00 1.00 1.00 1.00 1.00 1.00 1.00 1.00 1.00 1.00 1.00 1.00 1.00 1.00 1.00 1.00 1.00 1.00 1.00 1.00 1.00 1.00 1.00 1.00 1.00 1.00 1.00 1.00 1.00 1.00 1.00 1.00 1.00 1.00 1.00 1.00 1.00 1.00 1.00 1.00 1.00 1.00 1.00 1.00 1.00 1.00 1.00 1.00 1.00 1.00 1.00 1.00 1.00 1.00 1.00 1.00 1.00 1.00 1.00 1.00 1.00 1.00 1.00 1.00 1.00 1.00 1.00 1.00 1.00 1.00 1.00 1.00 1.00 1.00 1.00 1.00 1.00 1.00 1.00 1.00 1.00 1.00 1.00 1.00 1.00 1.00 1.00 1.00 1.00 1.00 1.00 1.00 1.00 1.00 1.00 1.00 1.00 1.00 1.00 1.00 1.00 1.00 1.00 1.00 1.00 1.00 1.00 1.00 1.00 1.00 1.00 1.00 1.00 1.00 1.00 1.00 1.00 1.00 1.00 1.00 1.00 1.00 1.00 1.00 1.00 1.00 1.00 1.00 1.00 1.00 1.00 1.00 1.00 1.00 1.00 1.00 1.00 1.00 1.00 1.00 1.00 1.00 1.00 1.00 1.00 1.00 1.00 1.00 1.00 1.00 1.00 1.00 1.00 1.00 1.00 1.00 1.00 1.00 1.00 1.00 1.00 1.00 1.00 1.00 1.00 1.00 1.00 1.00 1.00 1.00 1.00 1.00 1.00 1.00 1.00 1.00 1.00 1.00 1.00 1.00 1.00 1.00 1.00 1.00 1.00 1.00 1.00 1.00 1.00 1.00 1.00 1.00 1.00 1.00 1.00 1.00 1.00 1.00 1.00 1.00 1.00 1.00 1.00 1.00 1.00 1.00 1.00 1.00 1.00 1.00 1.00 1.00 1.00 1.00 1.00 1.00 1.00 1.00 1.00 1.00 1.00 1.00 1.00 1.00 1.00 1.00 1.00 1.00 1.00 1.00 1.00 1.00 1.00 1.00 1.00 1.00 1.00 1.00 1.00 1.00 1.00 1.00 1.00 1.00 1.00 1.00 1.00 1.00 1.00 1.00 1.00 1.00 1.00 1.00 1.00 1.00 1.00 1.00 1.00 1.00 1.00 1.00 1.00 1.00 1.00 1.00 1.00 1.00 1.00 1.00 1.00 1.00 1.00 1.00 1.00 1.00 1.00 1.00 1.00 1.00 1.00 1.00 1.00 1.00 1.00 1.00 1.00 1.00 1.00 1.00 1.00 1.00 1.00 1.00 1.00 1.00 1.00 1.00 1.00 1.00 1.00 1.00 1.00 1.00 1.00 1.00 1.00 1.00 1.00 1.00 1.00 1.00 1.00 1.00 1.00 1.00 1.00 1.00 1.00 1.00 1.00 1.00 1.00 1.00 1.00 1.00 1.00 1.00 1.00 1.00 1.00 1.00 1.00 1.00 1.00 1.00 1.00 1.00 1.00 1.00 1.00 1.00 1.00 1.00 1.00 1.00 1.00 1.00 1.00 1.00 1.00 1.00 1.00 1.00 1.00 1.00 1.00 1.00 1.00 1.00 1.00 1.00 1.00 1.00 1.00 1.00 1.00 1.00 1.00 1.00 1.00 1.00 1.00 1.00 1.00 1.00 1.00 1.00 1.00 1.00 1.00 1.00 1.00 1.00 1.00 1.00 1.00 1.00 1.00 1.00 1.00 1.00 1.00 1.00 1.00 1.00 1.00 1.00 1.00 1.00 1.00 1.00 1.00 1.00 1.00 1.00 1.00 1.00 1.00 1.00 1.00 1.00 1.00 1.00 1.00 1.00 1.00 1.00 1.00 1.00 1.00 1.00 1.00 1.00 1.00 1.00 1.00 1.00 1.00 1.00 1.00 1.00 1.00 1.00 1.00 1.00 1.00 1.00 1.00 1.00 1.00 1.00 1.00 1.00 1.00 1.00 1.00 1.00 1.00 1.00 1.00 1.00 1.00 1.00 1.00 1.00 1.00 1.00 1.00 1.00 1.00 1.00 1.00 1.00 1.00 1.00 1.00 1.00 1.00 1.00 1.00 1.00 1.00 1.00 1.00 1.00 1.00 1.00 1.00 1.00 1.00 1.00 1.00 1.00 1.00 1.00 1.00 1.00 1.00 1.00 1.00 1.00 1.00 1.00 1.00 1.00 1.00 1.00 1.00 1.00 1.00 1.00 1.00 1.00 1.00 1.00 1.00 1.00 1.00 1.00 1.00 1.00 1.00 1.00 1.00 1.00 1.00 1.00 1.00 1.00 1.00 1.00 1.00 1.00 1.00 1.00 1.00 1.00 1.00 1.00 1.00 1.00 1.00 1.00 1.00 1.00 1.00 1.00 1.00 1.00 1.00 1.00 1.00 1.00 1.00 1.00 1.00 1.00 1.00 1.00 1.00 1.00 1.00 1.00 1.00 1.00 1.00 1.00 1.00 1.00 1.00 1.00 1.00 1.00 1.00 1.00 1.00 1.00 1.00 1.00 1.00 1.00 1.00 1.00 1.00 1.00 1.00 1.00 1.00 1.00 1.00 1.00 1.00 1.00 1.00 1.00 1.00 1.00 1.00 1.00 1.00 1.00 1.00 1.00 1.00 1.00 1.00 1.00 1.00 1.00 1.00 1.00 1.00 1.00 1.00 1.00 1.00 1.00 1.00 1.00 1.00 1.00 1.00 1.00 1.00 1.00 1.00 1.00 1.00 1.00 1.00 1.00 1.00 1.00 1.00 1.00 1.00 1.00 1.00 1.00 1.00 1.00 1.00 1.00 1.00 1.00 1.00 1.00 1.00 1.00 1.00 1.00 1.00 1.00 1.00 1.00 1.00 1.00 1.00 1.00 1.00 1.00 1.00 1.00 1.00 1.00 1.00 1.00 1.00 1.00 1.00 1.00 1.00 1.00 1.00 1.00 1.00 1.00 1.00 1.00 1.00 1.00 1.00 1.00 1.00 1.00 1.00 1.00 1.00 1.00 1.00 1.00 1.00 1.00 1.00 1.00 1.00 1.00 1.00 1.00 1.00 1.00 1.00 1.00 1.00 1.00 1.00 1.00 1.00 1.00 1.00 1.00 1.00 1.00 1.00 1.00 1.00 1.00 1.00 1.00 1.00 1.00 1.00 1.00 1.00 1.00 1.00 1.00 1.00 1.00 1.00 1.00 1.00 1.00 1.00 1.00 1.00 1.00 1.00 1.00 1.00 1.00 1.00 1.00 1.00 1.00 1.00 1.00 1.00 1.00 1.00 1.00 1.00 1.00 1.00 1.00 1.00 1.00 1.00 1.00 1.00 1.00 1.00 1.00 1.00 1.00 1.00 1.00 1.00 1.00 1.00 1.00 1.00 1.00 1.00 1.00 1.00 1.00 1.00 1.00 1.00 1.00 1.00 1.00 1.00 1.00 1.00 1.00 1.00 1.00 1.00 1.00 1.00 1.00 1.00 1.00 1.00 1.00 1.00 1.00 1.00 1.00 1.00 1.00 1.00 1.00 1.00 1.00 1.00 1.00 1.00 1.00 1.00 1.00 1.00 1.00 1.00 1.00 1.00 1.00 1.00 1.00 1.00 1.00 1.00 1.00 1.00 1.00 1.00 1.00 1.00 1.00 1.00 1.00 1.00 1.00 1.00 1.00 1.00 1.00 1.00 1.00 1.00 1.00 1.00 1.00 1.00 1.00 1.00 1.00 1.00 1.00 1.00 1.00 1.00 1.00 1.00 1.00 1.00 1.00 1.00 1.00 1.00 1.00 1.00 1.00 1.00 1.00 1.00 1.00 1.00 1.00 1.00 1.00 1.00 1.00 1.00 1.00 1.00 1.00 1.00 1.00 1.00 1.00 1.00 1.00 1.00 1.00 1.00 1.00 1.00 1.00 1.00 1.00 1.00 1.00 1.00 1.00 1.00 1.00 1.00 1.00 1.00 1.00 1.00 1.00 1.00 1.00 1.00 1.00 1.00 1.00 1.00 1.00 1.00 1.00 1.00 1.00 1.00 1.00 1.00 1.00 1.00 1.00 1.00 1.00 1.00 1.00 1.00 1.00 1.00 1.00 1.00 1.00 1.00 1.00 1.00 1.00 1.00 1.00 1.00 1.00 1.00 1.00 1.00 1.00 1.00 1.00 1.00 1.00 1.00 1.00 1.00 1.00 1.00 1.00 1.00 1.00 1.00 1.00 1.00 1.00 1.00 1.00 1.00 1.00 1.00 1.00 1.00 1.00 1.00 1.00 1.00 1.00 1.00 1.00 1.00 1.00 1.00 1.00 1.00 1.00 1.00 1.00 1.00 1.00 1.00 1.00 1.00 1.00 1.00 1.00 1.00 1.00 1.00 1.00 1.00 1.00 1.00 1.00 1.00 1.00 1.00 1.00 1.00 1.00 1.00 1.00 1.00 1.00 1.00 1.00 1.00 1.00 1.00 1.00 1.00 1.00 1.00 1.00 1.00 1.00 1.00 1.00 1.00 1.00 1.00 1.00 1.00 1.00 1.00 1.00 1.00 1.00 1.00 1.00 1.00 1.00 1.00 1.00 1.00 1.00 1.00 1.00 1.00 1.00 1.00 1.00 1.00 1.00 1.00 1.00 1.00 1.00 1.00 1.00 1.00 1.00 1.00 1.00 1.00 1.00 1.00 1.00 1.00 1.00 1.00 1.00 1.00 1.00 1.00 1.00 1.00 1.00 1.00 1.00 1.00 1.00 1.00 1.00 1.00 1.00 1.00 1.00 1.00 1.00 1.00 1.00 1.00 1.00 1.00 1.00 1.00 1.00 1.00 1.00 1.00 1.00 1.00 1.00 1.00 1.00 1.00 1.00 1.00 1.00 1.00 1.00 1.00 1.00 1.00 1.00 1.00 1.00 1.00 1.00 1.00 1.00 1.00 1.00 1.00 1.00 1.00 1.00 1.00 1.00 1.00 1.00 1.00 1.00 1.00 1.00 1.00 1.00 1.00 1.00 1.00 1.00 1.00 1.00 1.00 1.00 1.00 1.00 1.00 1.00 1.00 1.00 1.00 1.00 1.00 1.00 1.00 1.00 1.00 1.00 1.00 1.00 1.00 1.00 1.00 1.00 1.00 1.00 1.00 1.00 1.00 1.00 1.00 1.00 1.00 1.00 1.00 1.00 1.00 1.00 1.00 1.00 1.00 1.00 1.00 1.00 1.00 1.00 1.00 1.00 1.00 1.00 1.00 1.00 1.00 1.00 1.00 1.00 1.00 1.00 1.00 1.00 1.00 1.00 1.00 1.00 1.00 1.00 1.00 1.00 1.00 1.00 1.00 1.00 1.00 1.00 1.00 1.00 1.00 1.00 1.00 1.00 1.00 1.00 1.00 1.00 1.00 1.00 1.00 1.00 1.00 1.00 1.00 1.00 1.00 1.00 1.00 1.00 1.00 1.00 1.00 1.00 1.00 1.00 1.00 1.00 1.00 1.00 1.00 1.00 1.00 1.00 1.00 1.00 1.00 1.00 1.00 1.00 1.00 1.00 1.00 1.00 1.00 1.00 1.00 1.00 1.00 1.00 1.00 1.00 1.00 1.00 1.00 1.00 1.00 1.00 1.00 1.00 1.00 1.00 1.00 1.00 1.00 1.00 1.00 1.00 1.00 1.00 1.00 1.00 1.00 1.00 1.00 1.00 1.00 1.00 1.00 1.00 1.00 1.00 1.00 1.00 1.00 1.00 1.00 1.00 1.00 1.00 1.00 1.00 1.00 1.00 1.00 1.00 1.00 1.00 1.00 1.00 1.00 1.00 1.00 1.00 1.00 1.00 1.00 1.00 1.00 1.00 1.00 1.00 1.00 1.00 1.00 1.00 1.00 1.00 1.00 1.00 1.00 1.00 1.00 1.00 1.00 1.00 1.00 1.00 1.00 1.00 1.00 1.00 1.00 1.00 1.00 1.00 1.00 1.00 1.00 1.00 1.00 1.00 1.00 1.00 1.00 1.00 1.00 1.00 1.00 1.00 1.00 1.00 1.00 1.00 1.00 1.00 1.00 1.00 1.00 1.00 1.00 1.00 1.00 1.00 1.00 1.00 1.00 1.00 1.00 1.00 1.00 1.00 1.00 1.00 1.00 1.00 1.00 1.00 1.00 1.00 1.00 1.00 1.00 1.00 1.00 1.00 1.00 1.00 1.00 1.00 1.00 1.00 1.00 1.00 1.00 1.00 1.00 1.00 1.00 1.00 1.00 1.00 1.00 1.00 1.00 1.00 1.00 1.00 1.00 1.00 1.00 1.00 1.00 1.00 1.00 1.00 1.00 1.00 1.00 1.00 1.00 1.00 1.00 1.00 1.00 1.00 1.00 1.00 1.00 1.00 1.00 1.00 1.00 1.00 1.00 1.00 1.00 1.00 1.00 1.00 1.00 1.00 1.00 1.00 1.00 1.00 1.00 1.00 1.00 1.00 1.00 1.00 1.00 1.00 1.00 1.00 1.00 1.00 1.00 1.00 1.00 1.00 1.00 1.00 1.00 1.00 1.00 1.00 1.00 1.00 1.00 1.00 1.00 1.00 1.00 1.00 1.00 1.00 1.00 1.00 1.00 1.00 1.00 1.00 1.00 1.00 1.00 1.00 1.00 1.00 1.00 1.00 1.00 1.00 1.00 1.00 1.00 1.00 1.00 1.00 1.00 1.00 1.00 1.00 1.00 1.00 1.00 1.00 1.00 1.00 1.00 1.00 1.00 1.00 1.00 1.00 1.00 1.00 1.00 1.00 1.00 172.00 172.00 172.00 172.00 172.00 172.00 1.00 1.00 1.00 1.00 1.00 1.00 1.00 1.00 1.00 1.00 1.00 1.00 1.00 1.00 1.00 1.00 1.00 1.00 1.00 1.00 1.00 1.00 1.00 1.00 1.00 1.00 1.00 1.00 1.00 1.00 1.00 1.00 1.00 1.00 1.00 1.00 1.00 1.00 1.00 1.00 1.00 1.00 1.00 1.00 1.00 1.00 1.00 1.00 1.00 1.00 1.00 1.00 1.00 1.00 1.00 1.00 1.00 1.00 1.00 1.00 1.00 1.00 1.00 1.00 1.00 1.00 1.00 1.00 1.00 1.00 1.00 1.00 1.00 1.00 1.00 1.00 1.00 1.00 1.00 1.00 1.00 1.00 1.00 1.00 1.00 1.00 1.00 1.00 1.00 1.00 1.00 1.00 1.00 1.00 1.00 1.00 1.00 1.00 1.00 1.00 1.00 1.00 1.00 1.00 1.00 1.00 1.00 1.00 1.00 1.00 1.00 1.00 1.00 1.00 1.00 1.00 1.00 1.00 1.00 1.00 1.00 1.00 1.00 1.00 1.00 1.00 1.00 1.00 1.00 1.00 1.00 1.00 1.00 1.00 1.00 1.00 1.00 1.00 1.00 1.00 1.00 1.00 1.00 1.00 1.00 1.00 1.00 1.00 1.00 1.00 1.00 1.00 1.00 1.00 1.00 1.00 1.00 1.00 1.00 1.00 1.00 1.00 1.00 1.00 1.00 1.00 1.00 1.00 1.00 1.00 1.00 1.00 1.00 1.00 1.00 1.00 1.00 1.00 1.00 1.00 1.00 1.00 1.00 1.00 1.00 1.00 1.00 1.00 1.00 1.00 1.00 1.00 1.00 1.00 1.00 1.00 1.00 1.00 1.00 1.00 1.00 1.00 1.00 1.00 1.00 1.00 1.00 1.00 1.00 1.00 1.00 1.00 1.00 1.00 1.00 1.00 1.00 1.00 1.00 1.00 1.00 1.00 1.00 1.00 1.00 1.00 1.00 1.00 1.00 1.00 1.00 1.00 1.00 1.00 1.00 1.00 1.00 1.00 1.00 1.00 1.00 1.00 1.00 1.00 1.00 1.00 1.00 1.00 1.00 1.00 1.00 1.00 1.00 1.00 1.00 1.00 1.00 1.00 1.00 1.00 1.00 1.00 1.00 1.00 1.00 1.00 1.00 1.00 1.00 1.00 1.00 1.00 1.00 1.00 1.00 1.00 1.00 1.00 1.00 1.00 1.00 1.00 1.00 1.00 1.00 1.00 1.00 1.00 1.00 1.00 1.00 1.00 1.00 1.00 1.00 1.00 1.00 1.00 1.00 1.00 1.00 1.00 1.00 1.00 1.00 1.00 1.00 1.00 1.00 1.00 1.00 1.00 1.00 1.00 1.00 1.00 1.00 1.00 1.00 1.00 1.00 1.00 1.00 1.00 1.00 1.00 1.00 1.00 1.00 1.00 1.00 1.00 1.00 1.00 1.00 1.00 1.00 1.00 1.00 1.00 1.00 1.00 1.00 1.00 1.00 1.00 1.00 1.00 1.00 1.00</beamAttenuationFactors>
				<commonCountingTime unit="seconds">0.352</commonCountingTime>
				<counts unit="counts">38 35 44 31 35 48 38 42 46 35 37 27 40 33 27 45 31 46 33 41 35 41 35 40 30 39 44 46 37 51 37 38 44 44 36 35 47 44 34 39 31 28 41 43 38 35 32 29 39 23 31 40 49 27 40 33 34 34 38 29 40 36 48 41 32 33 41 38 41 36 30 31 41 29 29 40 32 36 34 45 47 38 31 30 45 33 36 35 39 28 35 31 35 22 21 29 41 33 36 38 35 49 42 41 38 26 40 28 27 38 29 28 30 29 39 46 37 36 41 50 39 38 44 36 34 37 43 28 38 38 36 35 51 41 44 35 52 29 59 44 41 40 40 40 40 37 25 39 40 32 45 37 46 40 31 43 39 49 57 32 42 40 41 41 38 39 52 44 37 40 23 47 39 55 46 48 63 59 47 50 63 62 55 54 42 49 45 42 38 42 50 55 57 70 69 87 79 89 82 113 78 79 70 71 60 50 50 37 44 51 69 69 92 112 135 155 154 188 176 179 195 143 144 138 113 96 72 62 108 111 202 295 398 532 743 990 1115 1332 1586 1871 2083 2331 2584 2537 2699 2979 2782 2617 2744 2649 2384 2282 2038 1860 1524 1278 1071 902 677 537 403 334 228 199 184 180 432 2088 3477 4786 7150 13542 38536 98802 140126 144449 154108 81631 21236 7278 1563 650 451 372 244 166 165 123 116 133 131 162 141 156 171 156 182 156 138 113 101 94 72 54 58 53 33 51 46 52 51 60 77 76 91 67 85 82 71 51 57 42 54 39 35 42 38 27 41 40 45 44 41 42 55 66 59 55 53 34 46 36 40 28 40 27 23 37 32 23 35 35 47 57 40 32 45 46 37 40 40 37 30 23 29 24 22 33 32 23 37 36 30 30 38 47 34 37 33 31 36 33 33 36 30 21 33 24 27 27 36 33 25 41 31 33 35 37 42 36 21 31 30 24 21 30 29 22 23 22 34 37 39 34 20 35 38 25 26 18 21 35 27 21 35 16 29 22 25 24 29 25 28 34 21 30 27 27 28 29 28 26 11 17 31 40 25 26 31 28 18 25 21 27 26 26 28 19 39 23 33 35 26 26 17 29 20 25 17 29 32 24 24 27 24 25 31 27 30 27 26 27 26 17 31 26 18 20 18 27 33 25 22 26 25 25 24 22 22 22 25 22 20 26 22 28 21 27 27 30 29 27 21 21 19 23 23 20 31 21 25 23 35 17 21 23 25 23 32 27 24 21 21 24 27 31 24 21 31 23 40 20 21 28 19 28 18 24 19 24 18 20 30 22 31 26 19 23 20 25 32 23 19 23 21 22 23 22 36 22 20 35 33 24 18 24 20 30 24 27 19 19 24 24 21 22 23 10 29 26 24 19 24 19 25 23 35 17 31 28 22 24 24 27 32 25 20 22 22 16 22 14 27 20 22 26 29 22 31 26 21 11 33 23 13 24 19 24 31 16 21 23 29 24 20 21 16 15 22 18 24 26 23 16 23 21 17 26 25 17 16 22 20 17 33 21 21 20 17 19 12 20 14 16 10 21 17 27 20 21 22 24 23 29 27 25 29 18 22 18 20 20 12 13 12 24 17 32 27 16 23 17 17 19 25 25 24 16 20 19 17 29 23 15 19 30 20 29 18 15 14 27 15 16 23 20 22 12 16 16 17 22 16 14 28 19 21 20 16 19 28 22 28 23 28 15 22 16 17 31 20 20 22 24 25 22 18 22 26 12 21 16 23 18 18 18 15 16 11 14 32 20 17 16 19 24 20 19 14 18 21 12 22 19 18 17 20 27 16 15 18 20 16 13 19 20 19 21 22 15 15 15 12 11 16 21 22 19 27 24 16 17 17 20 15 17 8 20 19 17 23 22 18 20 17 19 17 24 18 20 14 14 23 18 14 18 25 20 21 22 24 20 23 17 25 20 25 22 23 16 26 11 27 21 19 23 20 22 27 21 23 15 21 22 15 20 21 12 18 14 19 21 17 19 15 14 10 20 19 18 18 14 13 14 15 13 18 11 13 16 20 19 17 18 14 14 19 14 17 8 13 11 15 17 18 19 19 19 9 10 14 19 25 20 14 16 17 22 15 12 21 13 19 18 14 19 14 10 17 14 18 13 18 10 18 15 19 19 20 20 11 17 13 15 13 20 20 10 16 17 15 11 19 17 19 11 26 22 16 14 12 18 16 12 12 18 13 13 15 17 21 16 20 20 23 14 8 10 19 15 22 15 18 14 12 13 11 16 14 15 15 17 17 15 19 19 21 13 15 15 18 14 19 24 18 13 14 17 16 16 19 16 13 21 13 15 16 17 18 15 11 14 15 18 7 11 14 15 9 19 13 16 14 17 11 18 13 14 18 11 12 14 17 10 20 18 16 12 16 19 15 18 10 14 8 13 13 13 12 12 10 19 14 20 12 14 15 17 15 11 11 16 13 7 14 16 18 11 21 9 15 15 14 19 20 6 9 10 12 20 16 22 13 13 9 15 11 18 19 10 6 17 13 9 11 9 20 14 12 19 7 13 10 20 17 16 9 20 15 14 19 11 16 11 11 15 14 19 18 13 13 14 14 15 11 14 17 17 16 17 15 16 13 13 17 18 12 13 14 15 12 8 21 10 14 8 12 20 22 16 8 15 14 13 15 13 12 9 14 11 12 10 18 11 18 14 13 13 11 16 18 15 15 15 17 9 16 16 16 16 9 13 11 10 18 11 19 16 13 19 16 4 18 13 15 15 11 7 12 15 9 12 12 11 19 5 12 13 13 23 15 13 14 12 14 14 14 15 9 5 14 15 17 14 15 16 16 7 12 19 10 12 6 14 14 13 16 12 13 19 12 8 13 14 19 8 8 13 9 13 12 10 11 15 10 14 9 13 15 13 13 11 15 19 10 12 16 19 11 9 13 9 14 10 15 12 14 9 15 16 9 22 21 18 12 15 18 15 15 19 15 15 14 14 13 16 8 11 16 12 13 14 13 11 15 14 11 8 13 14 9 10 11 14 10 14 13 13 13 12 9 13 12 9 11 11 10 14 14 9 11 11 9 20 13 10 7 11 16 12 11 15 9 13 12 15 8 11 11 18 11 16 10 12 17 17 19 11 11 11 13 12 11 10 12 14 17 15 12 11 13 8 8 18 11 15 20 16 12 4 9 11 9 7 12 10 17 10 6 16 10 16 13 11 9 15 11 12 7 15 11 12 17 19 12 13 16 16 13 11 9 10 7 14 12 5 13 13 12 8 14 17 9 3 10 4 5 10 7 11 13 17 13 6 12 16 13 9 7 9 7 14 15 14 17 13 17 14 16 8 6 12 8 22 5 12 11 12 12 17 7 9 17 10 7 10 12 12 8 15 12 4 7 12 15 16 9 6 9 9 12 11 13 13 15 10 17 16 21 15 12 6 13 6 14 12 18 14 4 8 11 13 8 13 16 9 16 12 8 15 13 18 4 4 9 15 11 9 6 14 8 13 9 13 11 14 7 11 14 6 7 11 7 12 10 16 12 6 11 9 13 17 7 8 10 6 13 12 16 8 11 12 14 10 5 13 9 10 11 13 10 6 9 10 16 9 6 7 6 9 14 9 10 16 13 7 10 17 14 12 15 13 17 11 18 17 13 8 9 9 7 10 11 11 16 17 11 8 18 15 12 16 6 15 10 11 12 9 8 12 14 14 12 14 6 8 9 9 12 6 7 15 12 12 9 8 13 9 8 7 11 14 12 12 16 14 8 7 14 13 12 4 10 13 9 8 9 12 9 15 11 10 12 10 12 12 12 8 13 12 12 8 12 11 11 17 10 9 14 14 5 9 16 9 8 11 9 7 15 9 12 4 11 11 8 7 3 15 10 14 13 12 12 9 8 9 10 17 10 14 15 6 13 11 13 10 6 11 14 13 9 12 13 10 8 14 12 15 14 18 9 11 8 16 12 12 14 12 6 9 12 9 8 11 10 13 11 16 11 9 11 13 11 12 10 9 12 8 5 9 12 11 11 5 13 13 11 13 12 11 16 13 8 15 9 9 13 6 6 9 11 12 10 9 10 9 11 12 9 11 12 12 12 13 11 16 10 7 8 10 12 12 5 12 15 10 8 9 10 11 8 10 9 12 13 11 11 11 12 12 14 14 15 10 5 10 16 14 11 9 10 12 7 14 11 13 14 12 11 15 10 13 9 10 9 13 11 9 12 9 7 11 11 9 9 10 8 14 17 9 7 14 10 8 11 11 7 5 12 17 11 12 15 6 12 11 7 14 9 10 16 4 11 11 8 15 12 9 13 7 11 13 11 12 9 11 12 7 10 10 15 19 15 6 12 12 13 10 15 8 15 9 7 8 10 8 14 15 10 6 11 13 10 11 9 5 7 8 9 7 10 11 10 6 8 11 10 9 20 5 13 11 11 9 7 5 11 12 7 6 12 9 16 12 10 15 9 11 16 18 8 6 11 6 11 11 5 4 11 15 10 13 9 11 9 12 9 9 10 12 11 8 9 9 10 14 8 12 13 8 11 18 12 12 19 6 6 12 7 7 10 11 11 12 11 8 14 14 7 10 9 10 9 12 7 13 6 12 7 7 10 11 4 14 9 14 11 16 12 8 12 9 18 5 10 8 7 9 7 12 12 10 11 8 16 12 10 13 10 12 13 11 5 14 14 6 13 16 7 17 13 10 8 10 11 10 6 13 12 10 15 8 17 12 12 10 6 6 11 14 7 4 8 10 11 8 12 19 5 15 9 6 5 10 5 8 11 12 12 10 14 14 12 10 8 6 8 8 2 8 11 12 8 10 7 15 11 13 11 10 12 11 10 10 10 10 10 7 6 11 9 11 11 15 14 16 8 8 15 12 8 9 11 7 12 14 12 14 16 11 9 12 11 9 13 14 17 15 13 9 12 9 7 13 9 6 9 15 7 13 12 14 12 8 9 8 7 7 17 6 14 8 10 12 15 16 11 15 12 17 12 22 19 12 8 13 9 10 7 9 13 9 8 15 12 16 8 14 9 23 12 13 12 13 8 12 11 17 13 9 7 11 12 5 5 11 10 16 21 10 9 11 7 13 11 12 13 10 7 10 16 7 13 8 9 16 6 13 10 15 14 11 16 12 10 6 11 7 13 12 9 9 16 8 14 15 10 19 17 12 14 11 12 19 14 10 15 12 11 10 7 10 8 8 11 9 9 12 13 10 21 18 9 11 17 13 15 11 12 6 7 15 11 6 13 12 5 7 18 12 8 16 13 16 15 15 10 12 15 14 12 14 18 10 9 7 19 13 14 14 15 17 15 17 25 21 16 18 15 10 17 16 7 10 8 4 12 12 7 10 17 18 19 16 16 20 11 16 21 15 14 13 13 14 11 9 13 12 16 8 11 14 18 14 26 16 12 28 13 19 11 16 17 21 12 14 9 12 19 8 17 12 17 21 30 23 13 23 13 21 13 16 15 21 14 18 19 16 14 11 19 13 14 22 18 19 18 23 29 20 19 17 13 25 12 22 14 16 11 20 13 22 21 18 18 28 26 28 30 38 28 31 26 17 35 19 21 21 10 12 7 17 22 27 33 26 30 24 34 33 38 36 36 31 29 22 32 29 21 22 20 14 12 21 26 23 42 30 44 38 35 42 40 46 43 32 35 24 29 26 20 29 24 30 32 32 21 45 41 56 51 60 70 77 65 57 49 51 37 38 23 24 32 34 35 41 48 68 70 60 86 92 92 93 107 101 83 88 79 60 57 55 46 35 33 51 48 74 106 133 151 143 183 193 228 218 204 187 188 153 113 116 93 72 77 107 99 114 176 207 327 345 447 512 545 567 671 641 588 562 527 445 436 387 339 415 452 667 887 1245 1795 2507 3132 3969 4926 6188 7305 8542 10118 11110 12543 13630 14644 15526 16648 17269 17522 17788 17647 17368 16743 15999 15138 14052 12800 11591 10021 8808 7468 6144 5067 4027 3035 2267 1697 1117 852 659 592 616 688 782 990 1089 1293 1464 1500 1605 1631 1569 1503 1394 1292 1138 1070 907 898 898 954 1047 1370 2048 4368 11248 21066 33256 45832 66994 79488 61553 50021 54573 75308 112533 1438 4583 10160 10216 4423 966 67518 19447 9428 4455 2740 1789 1287 907 654 493 357 299 259 232 248 227 242 218 239 207 230 188 189 166 130 120 90 74 60 54 42 44 34 30 50 46 50 63 54 70 62 62 63 47 57 47 45 29 32 20 20 21 22 16 19 22 22 18 21 31 25 31 33 27 36 33 20 24 10 14 17 12 15 15 16 16 13 13 17 18 20 24 28 22 23 21 30 15 12 18 16 10 16 10 14 6 13 18 8 8 12 5 14 15 10 20 15 15 24 13 18 11 16 11 6 13 16 14 10 16 10 6 14 13 13 6 14 9 12 5 7 13 7 10 11 17 10 15 17 10 10 12 15 9 18 11 8 13 14 8 17 15 5 9 3 7 11 10 12 7 8 7 10 7 11 9 11 9 15 14 9 10 9 10 10 8 12 6 6 9 7 5 15 11 12 9 13 14 12 8 9 8 15 12 9 8 12 3 5 11 9 7 3 7 8 11 6 11 7 13 11 17 6 12 5 10 8 10 4 6 8 9 8 13 5 6 19 9 11 9 6 9 6 7 5 11 6 10 6 9 9 4 8 5 6 7 7 8 5 7 7 9 9 13 11 14 7 5 9 3 7 8 8 5 8 12 9 12 9 7 12 7 6 7 10 9 8 5 4 9 8 8 14 12 6 3 11 7 5 12 10 8 7 7 8 9 12 8 2 5 5 10 6 7 7 9 9 8 12 10 3 6 7 7 4 8 6 8 5 9 8 4 4 5 6 16 8 6 9 4 7 7 6 7 5 10 9 7 11 10 12 3 10 5 8 9 3 5 5 6</counts>
			</dataPoints>
		</scan>
	</xrdMeasurement>
</xrdMeasurements>