File: data/previous_data/set_4-YG039-041/xrd/YG040-SRO001-STO001-07142022.xrdml
<xrdMeasurements xmlns="http://www.xrdml.com/XRDMeasurement/2.1" xmlns:xsi="http://www.w3.org/2001/XMLSchema-instance" xsi:schemaLocation="http://www.xrdml.com/XRDMeasurement/2.1 http://www.xrdml.com/XRDMeasurement/2.1/XRDMeasurement.xsd" status="Completed">
	<comment>
		<entry>Configuration=Main Configuration, Owner=User-1, Creation date=6/17/2015 3:36:16 PM</entry>
		<entry>Goniometer=HR HD (Theta/2Theta); Minimum step size 2Theta:0.0001; Minimum step size Omega:0.0001</entry>
		<entry>Sample stage=MRD Cradle; Minimum step size Phi:0.01; Minimum step size Chi:0.01; Minimum step size X:0.01; Minimum step size Y:0.01; Minimum step size Z:0.001</entry>
		<entry>Diffractometer system=XPERT-3</entry>
		<entry>Measurement program=C:\PANalytical\Data Collector\Programs\Yichen\regular_2theta_20-50_0.4s-20min.xrdmp, Identifier={AEA8F2F2-8BFA-4B07-A521-A571AF38E73A}</entry>
	</comment>
	<sample type="To be analyzed">
		<id></id>
		<name></name>
		<preparedBy></preparedBy>
	</sample>
	<xrdMeasurement measurementType="Scan" status="Completed" sampleMode="Reflection">
		<comment>
			<entry>PHD Lower Level = 4.02 (keV), PHD Upper Level = 11.27 (keV)</entry>
		</comment>
		<usedWavelength intended="K-Alpha 1">
			<kAlpha1 unit="Angstrom">1.5405980</kAlpha1>
			<kAlpha2 unit="Angstrom">1.5444260</kAlpha2>
			<kBeta unit="Angstrom">1.3922500</kBeta>
			<ratioKAlpha2KAlpha1>0.5000</ratioKAlpha2KAlpha1>
		</usedWavelength>
		<incidentBeamPath>
			<radius unit="mm">320.00</radius>
			<xRayTube id="1010048" name="Empyrean Cu LFF HR (9430 033 7310x) DK425175">
				<tension unit="kV">45.0</tension>
				<current unit="mA">40.0</current>
				<anodeMaterial>Cu</anodeMaterial>
				<focus type="Line">
					<length unit="mm">12.0</length>
					<width unit="mm">0.4</width>
					<takeOffAngle unit="deg">4.2</takeOffAngle>
				</focus>
			</xRayTube>
			<xRayMirror id="27090001" name="Inc. Beam Cu W/Si (hybrid MRD)" hybrid="true">
				<crystal type="Graded" shape="Parabolic">W/Si</crystal>
				<acceptanceAngle unit="deg">0.800</acceptanceAngle>
				<length unit="mm">60.0</length>
			</xRayMirror>
			<monochromator id="23090002" name="Hybrid monochr. 2xGe(220) Cu asym." hybrid="true">
				<crystal type="Asymmetric" shape="Flat">Ge</crystal>
				<numberOfReflections>2</numberOfReflections>
				<hkl>
					<h>2</h>
					<k>2</k>
					<l>0</l>
				</hkl>
			</monochromator>
			<divergenceSlit id="22010004" name="Fixed slit 1/2°" xsi:type="fixedDivergenceSlitType">
				<distanceToSample unit="mm">220.00</distanceToSample>
				<height unit="mm">0.76</height>
			</divergenceSlit>
			<beamAttenuator id="26010001" name="Progr. beam attenuator Ni 0.125 mm" xsi:type="intensitySwitchedBeamAttenuatorType">
				<factor>172.00</factor>
				<material>Ni</material>
				<activateLevel unit="counts per second">500000</activateLevel>
				<deactivateLevel unit="counts per second">400000</deactivateLevel>
			</beamAttenuator>
		</incidentBeamPath>
		<diffractedBeamPath>
			<radius unit="mm">320.00</radius>
			<antiScatterSlit id="22090009" name="AS slit 7.5 mm (PIXcel)" xsi:type="fixedAntiScatterSlitType">
				<height unit="mm">7.50</height>
			</antiScatterSlit>
			<sollerSlit id="21010002" name="Soller slits 0.04 rad.">
				<opening unit="rad">0.0400</opening>
			</sollerSlit>
			<receivingSlit id="22010004" name="Fixed slit 1/2°">
				<height unit="mm">0.76</height>
			</receivingSlit>
			<detector id="7010020" name="PIXcel3D-Medipix3 1x1 detector" xsi:type="areaDetectorType">
				<phd unit="%">
					<lowerLevel>25.0</lowerLevel>
					<upperLevel>70.0</upperLevel>
				</phd>
				<mode>Receiving slit</mode>
				<activeChannelsEquatorial>5</activeChannelsEquatorial>
				<activeChannelsAxial>255</activeChannelsAxial>
				<pitchEquatorial unit="mm">0.05500</pitchEquatorial>
				<pitchAxial unit="mm">0.05500</pitchAxial>
				<readOutPeriod unit="seconds">0.050</readOutPeriod>
			</detector>
		</diffractedBeamPath>
		<scan appendNumber="0" mode="Continuous" scanAxis="2Theta-Omega" status="Completed">
			<header>
				<startTimeStamp>2022-07-14T15:49:46-07:00</startTimeStamp>
				<endTimeStamp>2022-07-14T16:10:12-07:00</endTimeStamp>
				<author>
					<name>XRD</name>
				</author>
				<source>
					<applicationSoftware version="6.1b">Data Collector</applicationSoftware>
					<instrumentControlSoftware version="7.4b 20181204">XPERT-3</instrumentControlSoftware>
					<instrumentID>0000000011163216</instrumentID>
				</source>
			</header>
			<dataPoints>
				<positions axis="2Theta" unit="deg">
					<startPosition>20.0050</startPosition>
					<endPosition>49.9950</endPosition>
				</positions>
				<positions axis="Omega" unit="deg">
					<startPosition>9.7735</startPosition>
					<endPosition>24.7685</endPosition>
				</positions>
				<positions axis="Phi" unit="deg">
					<commonPosition>0.00</commonPosition>
				</positions>
				<positions axis="Chi" unit="deg">
					<commonPosition>-0.11</commonPosition>
				</positions>
				<positions axis="X" unit="mm">
					<commonPosition>0.05</commonPosition>
				</positions>
				<positions axis="Y" unit="mm">
					<commonPosition>0.00</commonPosition>
				</positions>
				<positions axis="Z" unit="mm">
					<commonPosition>8.432</commonPosition>
				</positions>
				<beamAttenuationFactors>1.00 1.00 1.00 1.00 1.00 1.00 1.00 1.00 1.00 1.00 1.00 1.00 1.00 1.00 1.00 1.00 1.00 1.00 1.00 1.00 1.00 1.00 1.00 1.00 1.00 1.00 1.00 1.00 1.00 1.00 1.00 1.00 1.00 1.00 1.00 1.00 1.00 1.00 1.00 1.00 1.00 1.00 1.00 1.00 1.00 1.00 1.00 1.00 1.00 1.00 1.00 1.00 1.00 1.00 1.00 1.00 1.00 1.00 1.00 1.00 1.00 1.00 1.00 1.00 1.00 1.00 1.00 1.00 1.00 1.00 1.00 1.00 1.00 1.00 1.00 1.00 1.00 1.00 1.00 1.00 1.00 1.00 1.00 1.00 1.00 1.00 1.00 1.00 1.00 1.00 1.00 1.00 1.00 1.00 1.00 1.00 1.00 1.00 1.00 1.00 1.00 1.00 1.00 1.00 1.00 1.00 1.00 1.00 1.00 1.00 1.00 1.00 1.00 1.00 1.00 1.00 1.00 1.00 1.00 1.00 1.00 1.00 1.00 1.00 1.00 1.00 1.00 1.00 1.00 1.00 1.00 1.00 1.00 1.00 1.00 1.00 1.00 1.00 1.00 1.00 1.00 1.00 1.00 1.00 1.00 1.00 1.00 1.00 1.00 1.00 1.00 1.00 1.00 1.00 1.00 1.00 1.00 1.00 1.00 1.00 1.00 1.00 1.00 1.00 1.00 1.00 1.00 1.00 1.00 1.00 1.00 1.00 1.00 1.00 1.00 1.00 1.00 1.00 1.00 1.00 1.00 1.00 1.00 1.00 1.00 1.00 1.00 1.00 1.00 1.00 1.00 1.00 1.00 1.00 1.00 1.00 1.00 1.00 1.00 1.00 1.00 1.00 1.00 1.00 1.00 1.00 1.00 1.00 1.00 1.00 1.00 1.00 1.00 1.00 1.00 1.00 1.00 1.00 1.00 1.00 1.00 1.00 1.00 1.00 1.00 1.00 1.00 1.00 1.00 1.00 1.00 1.00 1.00 1.00 1.00 1.00 1.00 1.00 1.00 1.00 1.00 1.00 1.00 1.00 1.00 1.00 1.00 1.00 1.00 1.00 1.00 1.00 1.00 1.00 1.00 1.00 1.00 1.00 1.00 1.00 1.00 1.00 1.00 1.00 1.00 1.00 1.00 1.00 1.00 1.00 1.00 1.00 1.00 1.00 1.00 1.00 1.00 1.00 1.00 1.00 1.00 1.00 1.00 1.00 1.00 1.00 1.00 1.00 1.00 1.00 1.00 1.00 1.00 1.00 1.00 1.00 1.00 1.00 1.00 1.00 1.00 1.00 1.00 1.00 1.00 1.00 1.00 1.00 1.00 1.00 1.00 1.00 1.00 1.00 1.00 1.00 1.00 1.00 1.00 1.00 1.00 1.00 1.00 1.00 1.00 1.00 1.00 1.00 1.00 1.00 1.00 1.00 1.00 1.00 1.00 1.00 1.00 1.00 1.00 1.00 1.00 1.00 1.00 1.00 1.00 1.00 1.00 1.00 1.00 1.00 1.00 1.00 1.00 1.00 1.00 1.00 1.00 1.00 1.00 1.00 1.00 1.00 1.00 1.00 1.00 1.00 1.00 1.00 1.00 1.00 1.00 1.00 1.00 1.00 1.00 1.00 1.00 1.00 1.00 1.00 1.00 1.00 1.00 1.00 1.00 1.00 1.00 1.00 1.00 1.00 1.00 1.00 1.00 1.00 1.00 1.00 1.00 1.00 1.00 1.00 1.00 1.00 1.00 1.00 1.00 1.00 1.00 1.00 1.00 1.00 1.00 1.00 1.00 1.00 1.00 1.00 1.00 1.00 1.00 1.00 1.00 1.00 1.00 1.00 1.00 1.00 1.00 1.00 1.00 1.00 1.00 1.00 1.00 1.00 1.00 1.00 1.00 1.00 1.00 1.00 1.00 1.00 1.00 1.00 1.00 1.00 1.00 1.00 1.00 1.00 1.00 1.00 1.00 1.00 1.00 1.00 1.00 1.00 1.00 1.00 1.00 1.00 1.00 1.00 1.00 1.00 1.00 1.00 1.00 1.00 1.00 1.00 1.00 1.00 1.00 1.00 1.00 1.00 1.00 1.00 1.00 1.00 1.00 1.00 1.00 1.00 1.00 1.00 1.00 1.00 1.00 1.00 1.00 1.00 1.00 1.00 1.00 1.00 1.00 1.00 1.00 1.00 1.00 1.00 1.00 1.00 1.00 1.00 1.00 1.00 1.00 1.00 1.00 1.00 1.00 1.00 1.00 1.00 1.00 1.00 1.00 1.00 1.00 1.00 1.00 1.00 1.00 1.00 1.00 1.00 1.00 1.00 1.00 1.00 1.00 1.00 1.00 1.00 1.00 1.00 1.00 1.00 1.00 1.00 1.00 1.00 1.00 1.00 1.00 1.00 1.00 1.00 1.00 1.00 1.00 1.00 1.00 1.00 1.00 1.00 1.00 1.00 1.00 1.00 1.00 1.00 1.00 1.00 1.00 1.00 1.00 1.00 1.00 1.00 1.00 1.00 1.00 1.00 1.00 1.00 1.00 1.00 1.00 1.00 1.00 1.00 1.00 1.00 1.00 1.00 1.00 1.00 1.00 1.00 1.00 1.00 1.00 1.00 1.00 1.00 1.00 1.00 1.00 1.00 1.00 1.00 1.00 1.00 1.00 1.00 1.00 1.00 1.00 1.00 1.00 1.00 1.00 1.00 1.00 1.00 1.00 1.00 1.00 1.00 1.00 1.00 1.00 1.00 1.00 1.00 1.00 1.00 1.00 1.00 1.00 1.00 1.00 1.00 1.00 1.00 1.00 1.00 1.00 1.00 1.00 1.00 1.00 1.00 1.00 1.00 1.00 1.00 1.00 1.00 1.00 1.00 1.00 1.00 1.00 1.00 1.00 1.00 1.00 1.00 1.00 1.00 1.00 1.00 1.00 1.00 1.00 1.00 1.00 1.00 1.00 1.00 1.00 1.00 1.00 1.00 1.00 1.00 1.00 1.00 1.00 1.00 1.00 1.00 1.00 1.00 1.00 1.00 1.00 1.00 1.00 1.00 1.00 1.00 1.00 1.00 1.00 1.00 1.00 1.00 1.00 1.00 1.00 1.00 1.00 1.00 1.00 1.00 1.00 1.00 1.00 1.00 1.00 1.00 1.00 1.00 1.00 1.00 1.00 1.00 1.00 1.00 1.00 1.00 1.00 1.00 1.00 1.00 1.00 1.00 1.00 1.00 1.00 1.00 1.00 1.00 1.00 1.00 1.00 1.00 1.00 1.00 1.00 1.00 1.00 1.00 1.00 1.00 1.00 1.00 1.00 1.00 1.00 1.00 1.00 1.00 1.00 1.00 1.00 1.00 1.00 1.00 1.00 1.00 1.00 1.00 1.00 1.00 1.00 1.00 1.00 1.00 1.00 1.00 1.00 1.00 1.00 1.00 1.00 1.00 1.00 1.00 1.00 1.00 1.00 1.00 1.00 1.00 1.00 1.00 1.00 1.00 1.00 1.00 1.00 1.00 1.00 1.00 1.00 1.00 1.00 1.00 1.00 1.00 1.00 1.00 1.00 1.00 1.00 1.00 1.00 1.00 1.00 1.00 1.00 1.00 1.00 1.00 1.00 1.00 1.00 1.00 1.00 1.00 1.00 1.00 1.00 1.00 1.00 1.00 1.00 1.00 1.00 1.00 1.00 1.00 1.00 1.00 1.00 1.00 1.00 1.00 1.00 1.00 1.00 1.00 1.00 1.00 1.00 1.00 1.00 1.00 1.00 1.00 1.00 1.00 1.00 1.00 1.00 1.00 1.00 1.00 1.00 1.00 1.00 1.00 1.00 1.00 1.00 1.00 1.00 1.00 1.00 1.00 1.00 1.00 1.00 1.00 1.00 1.00 1.00 1.00 1.00 1.00 1.00 1.00 1.00 1.00 1.00 1.00 1.00 1.00 1.00 1.00 1.00 1.00 1.00 1.00 1.00 1.00 1.00 1.00 1.00 1.00 1.00 1.00 1.00 1.00 1.00 1.00 1.00 1.00 1.00 1.00 1.00 1.00 1.00 1.00 1.00 1.00 1.00 1.00 1.00 1.00 1.00 1.00 1.00 1.00 1.00 1.00 1.00 1.00 1.00 1.00 1.00 1.00 1.00 1.00 1.00 1.00 1.00 1.00 1.00 1.00 1.00 1.00 1.00 1.00 1.00 1.00 1.00 1.00 1.00 1.00 1.00 1.00 1.00 1.00 1.00 1.00 1.00 1.00 1.00 1.00 1.00 1.00 1.00 1.00 1.00 1.00 1.00 1.00 1.00 1.00 1.00 1.00 1.00 1.00 1.00 1.00 1.00 1.00 1.00 1.00 1.00 1.00 1.00 1.00 1.00 1.00 1.00 1.00 1.00 1.00 1.00 1.00 1.00 1.00 1.00 1.00 1.00 1.00 1.00 1.00 1.00 1.00 1.00 1.00 1.00 1.00 1.00 1.00 1.00 1.00 1.00 1.00 1.00 1.00 1.00 1.00 1.00 1.00 1.00 1.00 1.00 1.00 1.00 1.00 1.00 1.00 1.00 1.00 1.00 1.00 1.00 1.00 1.00 1.00 1.00 1.00 1.00 1.00 1.00 1.00 1.00 1.00 1.00 1.00 1.00 1.00 1.00 1.00 1.00 1.00 1.00 1.00 1.00 1.00 1.00 1.00 1.00 1.00 1.00 1.00 1.00 1.00 1.00 1.00 1.00 1.00 1.00 1.00 1.00 1.00 1.00 1.00 1.00 1.00 1.00 1.00 1.00 1.00 1.00 1.00 1.00 1.00 1.00 1.00 1.00 1.00 1.00 1.00 1.00 1.00 1.00 1.00 1.00 1.00 1.00 1.00 1.00 1.00 1.00 1.00 1.00 1.00 1.00 1.00 1.00 1.00 1.00 1.00 1.00 1.00 1.00 1.00 1.00 1.00 1.00 1.00 1.00 1.00 1.00 1.00 1.00 1.00 1.00 1.00 1.00 1.00 1.00 1.00 1.00 1.00 1.00 1.00 1.00 1.00 1.00 1.00 1.00 1.00 1.00 1.00 1.00 1.00 1.00 1.00 1.00 1.00 1.00 1.00 1.00 1.00 1.00 1.00 1.00 1.00 1.00 1.00 1.00 1.00 1.00 1.00 1.00 1.00 1.00 1.00 1.00 1.00 1.00 1.00 1.00 1.00 1.00 1.00 1.00 1.00 1.00 1.00 1.00 1.00 1.00 1.00 1.00 1.00 1.00 1.00 1.00 1.00 1.00 1.00 1.00 1.00 1.00 1.00 1.00 1.00 1.00 1.00 1.00 1.00 1.00 1.00 1.00 1.00 1.00 1.00 1.00 1.00 1.00 1.00 1.00 1.00 1.00 1.00 1.00 1.00 1.00 1.00 1.00 1.00 1.00 1.00 1.00 1.00 1.00 1.00 1.00 1.00 1.00 1.00 1.00 1.00 1.00 1.00 1.00 1.00 1.00 1.00 1.00 1.00 1.00 1.00 1.00 1.00 1.00 1.00 1.00 1.00 1.00 1.00 1.00 1.00 1.00 1.00 1.00 1.00 1.00 1.00 1.00 1.00 1.00 1.00 1.00 1.00 1.00 1.00 1.00 1.00 1.00 1.00 1.00 1.00 1.00 1.00 1.00 1.00 1.00 1.00 1.00 1.00 1.00 1.00 1.00 1.00 1.00 1.00 1.00 1.00 1.00 1.00 1.00 1.00 1.00 1.00 1.00 1.00 1.00 1.00 1.00 1.00 1.00 1.00 1.00 1.00 1.00 1.00 1.00 1.00 1.00 1.00 1.00 1.00 1.00 1.00 1.00 1.00 1.00 1.00 1.00 1.00 1.00 1.00 1.00 1.00 1.00 1.00 1.00 1.00 1.00 1.00 1.00 1.00 1.00 1.00 1.00 1.00 1.00 1.00 1.00 1.00 1.00 1.00 1.00 1.00 1.00 1.00 1.00 1.00 1.00 1.00 1.00 1.00 1.00 1.00 1.00 1.00 1.00 1.00 1.00 1.00 1.00 1.00 1.00 1.00 1.00 1.00 1.00 1.00 1.00 1.00 1.00 1.00 1.00 1.00 1.00 1.00 1.00 1.00 1.00 1.00 1.00 1.00 1.00 1.00 1.00 1.00 1.00 1.00 1.00 1.00 1.00 1.00 1.00 1.00 1.00 1.00 1.00 1.00 1.00 1.00 1.00 1.00 1.00 1.00 1.00 1.00 1.00 1.00 1.00 1.00 1.00 1.00 1.00 1.00 1.00 1.00 1.00 1.00 1.00 1.00 1.00 1.00 1.00 1.00 1.00 1.00 1.00 1.00 1.00 1.00 1.00 1.00 1.00 1.00 1.00 1.00 1.00 1.00 1.00 1.00 1.00 1.00 1.00 1.00 1.00 1.00 1.00 1.00 1.00 1.00 1.00 1.00 1.00 1.00 1.00 1.00 1.00 1.00 1.00 1.00 1.00 1.00 1.00 1.00 1.00 1.00 1.00 1.00 1.00 1.00 1.00 1.00 1.00 1.00 1.00 1.00 1.00 1.00 1.00 1.00 1.00 1.00 1.00 1.00 1.00 1.00 1.00 1.00 1.00 1.00 1.00 1.00 1.00 1.00 1.00 1.00 1.00 1.00 1.00 1.00 1.00 1.00 1.00 1.00 1.00 1.00 1.00 1.00 1.00 1.00 1.00 1.00 1.00 1.00 1.00 1.00 1.00 1.00 1.00 1.00 1.00 1.00 1.00 1.00 1.00 1.00 1.00 1.00 1.00 1.00 1.00 1.00 1.00 1.00 1.00 1.00 1.00 1.00 1.00 1.00 1.00 1.00 1.00 1.00 1.00 1.00 1.00 1.00 1.00 1.00 1.00 1.00 1.00 1.00 1.00 1.00 1.00 1.00 1.00 1.00 1.00 1.00 1.00 1.00 1.00 1.00 1.00 1.00 1.00 1.00 1.00 1.00 1.00 1.00 1.00 1.00 1.00 1.00 1.00 1.00 1.00 1.00 1.00 1.00 1.00 1.00 1.00 1.00 1.00 1.00 1.00 1.00 1.00 1.00 1.00 1.00 1.00 1.00 1.00 1.00 1.00 1.00 1.00 1.00 1.00 1.00 1.00 1.00 1.00 1.00 1.00 1.00 1.00 1.00 1.00 1.00 1.00 1.00 1.00 1.00 1.00 1.00 1.00 1.00 1.00 1.00 1.00 1.00 1.00 1.00 1.00 1.00 1.00 1.00 1.00 1.00 1.00 1.00 1.00 1.00 1.00 1.00 1.00 1.00 1.00 1.00 1.00 1.00 1.00 1.00 1.00 1.00 1.00 1.00 1.00 1.00 1.00 1.00 1.00 1.00 1.00 1.00 1.00 1.00 1.00 1.00 1.00 1.00 1.00 1.00 1.00 1.00 1.00 1.00 1.00 1.00 1.00 1.00 1.00 1.00 1.00 1.00 1.00 1.00 1.00 1.00 1.00 1.00 1.00 1.00 1.00 1.00 1.00 1.00 1.00 1.00 1.00 1.00 1.00 1.00 1.00 1.00 1.00 1.00 1.00 1.00 1.00 1.00 1.00 1.00 1.00 1.00 1.00 1.00 1.00 1.00 1.00 1.00 1.00 1.00 1.00 1.00 1.00 1.00 1.00 1.00 1.00 1.00 1.00 1.00 1.00 1.00 1.00 1.00 1.00 1.00 1.00 1.00 1.00 1.00 1.00 1.00 1.00 1.00 1.00 1.00 1.00 1.00 1.00 1.00 1.00 1.00 1.00 1.00 1.00 1.00 1.00 1.00 1.00 1.00 1.00 1.00 1.00 1.00 1.00 1.00 1.00 1.00 1.00 1.00 1.00 1.00 1.00 1.00 1.00 1.00 1.00 1.00 1.00 1.00 1.00 1.00 1.00 1.00 1.00 1.00 1.00 1.00 1.00 1.00 1.00 1.00 1.00 1.00 1.00 1.00 1.00 1.00 1.00 1.00 1.00 1.00 1.00 1.00 1.00 1.00 1.00 1.00 1.00 1.00 1.00 1.00 1.00 1.00 1.00 1.00 1.00 1.00 1.00 1.00 1.00 1.00 1.00 1.00 1.00 1.00 1.00 1.00 1.00 1.00 1.00 1.00 1.00 1.00 1.00 1.00 1.00 1.00 1.00 1.00 1.00 1.00 1.00 1.00 1.00 1.00 1.00 1.00 1.00 1.00 1.00 1.00 1.00 1.00 1.00 1.00 1.00 1.00 1.00 1.00 1.00 1.00 1.00 1.00 1.00 1.00 1.00 1.00 1.00 1.00 1.00 1.00 1.00 1.00 1.00 1.00 1.00 1.00 1.00 1.00 1.00 1.00 1.00 1.00 1.00 1.00 1.00 1.00 1.00 1.00 1.00 1.00 1.00 1.00 1.00 1.00 1.00 1.00 1.00 1.00 1.00 1.00 1.00 1.00 1.00 1.00 1.00 1.00 1.00 1.00 1.00 1.00 1.00 1.00 1.00 1.00 1.00 1.00 1.00 1.00 1.00 1.00 1.00 1.00 1.00 1.00 1.00 1.00 1.00 1.00 1.00 1.00 1.00 1.00 1.00 1.00 1.00 1.00 1.00 1.00 1.00 1.00 1.00 1.00 1.00 1.00 1.00 1.00 1.00 1.00 1.00 1.00 1.00 1.00 1.00 1.00 1.00 1.00 1.00 1.00 1.00 1.00 1.00 1.00 1.00 1.00 1.00 1.00 1.00 1.00 1.00 1.00 1.00 1.00 1.00 1.00 1.00 1.00 1.00 1.00 1.00 1.00 1.00 1.00 1.00 1.00 1.00 1.00 1.00 1.00 1.00 1.00 1.00 1.00 1.00 1.00 1.00 1.00 1.00 1.00 1.00 1.00 1.00 1.00 1.00 1.00 1.00 1.00 1.00 1.00 1.00 1.00 1.00 1.00 1.00 1.00 1.00 1.00 1.00 1.00 1.00 1.00 1.00 1.00 1.00 1.00 1.00 1.00 1.00 1.00 1.00 1.00 1.00 1.00 1.00 1.00 1.00 1.00 1.00 1.00 1.00 1.00 1.00 1.00 1.00 1.00 1.00 1.00 1.00 1.00 1.00 1.00 1.00 1.00 1.00 1.00 1.00 1.00 1.00 1.00 1.00 1.00 1.00 1.00 1.00 1.00 1.00 1.00 1.00 1.00 1.00 1.00 1.00 1.00 1.00 1.00 1.00 1.00 1.00 1.00 1.00 1.00 1.00 1.00 1.00 1.00 1.00 1.00 1.00 1.00 1.00 1.00 1.00 1.00 1.00 1.00 1.00 1.00 1.00 1.00 1.00 1.00 1.00 1.00 1.00 1.00 1.00 1.00 1.00 1.00 1.00 1.00 1.00 1.00 1.00 1.00 1.00 1.00 1.00 1.00 1.00 1.00 1.00 1.00 1.00 1.00 1.00 1.00 1.00 1.00 1.00 1.00 1.00 1.00 1.00 1.00 1.00 1.00 1.00 1.00 1.00 1.00 1.00 1.00 1.00 1.00 1.00 1.00 1.00 1.00 1.00 1.00 1.00 1.00 1.00 1.00 1.00 1.00 1.00 1.00 1.00 1.00 1.00 1.00 1.00 1.00 1.00 1.00 1.00 1.00 1.00 1.00 1.00 1.00 1.00 1.00 1.00 1.00 1.00 1.00 1.00 1.00 1.00 1.00 1.00 1.00 1.00 1.00 1.00 1.00 1.00 1.00 1.00 1.00 1.00 1.00 1.00 1.00 1.00 1.00 1.00 1.00 1.00 1.00 1.00 1.00 1.00 1.00 1.00 1.00 1.00 1.00 1.00 1.00 1.00 1.00 1.00 1.00 1.00 1.00 1.00 1.00 1.00 1.00 1.00 1.00 1.00 1.00 1.00 1.00 1.00 1.00 1.00 1.00 1.00 1.00 1.00 1.00 1.00 1.00 1.00 1.00 1.00 1.00 1.00 1.00 1.00 1.00 1.00 1.00 1.00 1.00 1.00 1.00 1.00 1.00 1.00 1.00 1.00 1.00 1.00 1.00 1.00 1.00 1.00 1.00 1.00 1.00 1.00 1.00 1.00 1.00 1.00 1.00 1.00 1.00 1.00 1.00 1.00 1.00 1.00 1.00 1.00 1.00 1.00 1.00 1.00 1.00 1.00 1.00 1.00 1.00 1.00 1.00 1.00 1.00 1.00 1.00 1.00 1.00 1.00 1.00 1.00 1.00 1.00 1.00 1.00 1.00 1.00 1.00 1.00 1.00 1.00 1.00 1.00 1.00 1.00 1.00 1.00 1.00 1.00 1.00 1.00 1.00 1.00 1.00 1.00 1.00 1.00 1.00 1.00 1.00 1.00 1.00 1.00 1.00 1.00 1.00 1.00 1.00 1.00 1.00 1.00 1.00 1.00 1.00 1.00 1.00 1.00 1.00 1.00 1.00 1.00 1.00 1.00 1.00 1.00 1.00 1.00 1.00 1.00 1.00 1.00 1.00 1.00 1.00 1.00 1.00 1.00 1.00 1.00 1.00 1.00 1.00 1.00 1.00 1.00 1.00 1.00 1.00 1.00 1.00 1.00 1.00 1.00 1.00 1.00 1.00 1.00 1.00 1.00 1.00 1.00 1.00 1.00 1.00 1.00 1.00 1.00 1.00 1.00 1.00 1.00 1.00 1.00 1.00 1.00 1.00 1.00 1.00 1.00 1.00 1.00 1.00 1.00 1.00 1.00 1.00 1.00 1.00 1.00 1.00 1.00 1.00 1.00 1.00 1.00 1.00 1.00 1.00 1.00 1.00 1.00 1.00 1.00 1.00 1.00 1.00 1.00 1.00 1.00 1.00 1.00 1.00 1.00 1.00 1.00 1.00 1.00 1.00 1.00 1.00 1.00 1.00 1.00 1.00 1.00 1.00 1.00 1.00 1.00 1.00 1.00 1.00 1.00 1.00 1.00 1.00 1.00 1.00 1.00 1.00 1.00 1.00 1.00 1.00 1.00 1.00 1.00 1.00 1.00 1.00 1.00 1.00 1.00 1.00 1.00 1.00 1.00 1.00 1.00 1.00 1.00 1.00 1.00 1.00 1.00 1.00 1.00 1.00 1.00 1.00 1.00 1.00 1.00 1.00 1.00 1.00 1.00 1.00 1.00 1.00 1.00 1.00 1.00 1.00 1.00 1.00 1.00 1.00 1.00 1.00 1.00 1.00 1.00 1.00 1.00 1.00 1.00 1.00 1.00 1.00 1.00 1.00 1.00 1.00 1.00 1.00 1.00 1.00 1.00 1.00 1.00 1.00 1.00 1.00 1.00 1.00 1.00 1.00 1.00 1.00 1.00 1.00 1.00 1.00 1.00 1.00 1.00 1.00 1.00 1.00 1.00 1.00 1.00 1.00 1.00 1.00 1.00 1.00 1.00 1.00 1.00 1.00 1.00 1.00 1.00 1.00 1.00 1.00 1.00 1.00 1.00 1.00 1.00 1.00 1.00 1.00 1.00 1.00 1.00 1.00 1.00 1.00 1.00 1.00 1.00 1.00 1.00 1.00 1.00 1.00 1.00 1.00 1.00 1.00 1.00 1.00 1.00 1.00 1.00 1.00 1.00 1.00 1.00 1.00 1.00 1.00 1.00 1.00 1.00 1.00 1.00 1.00 1.00 1.00 1.00 1.00 1.00 1.00 1.00 1.00 1.00 1.00 1.00 1.00 1.00 1.00 1.00 172.00 172.00 172.00 172.00 172.00 172.00 172.00 172.00 172.00 172.00 1.00 1.00 1.00 1.00 1.00 1.00 1.00 1.00 1.00 1.00 1.00 1.00 1.00 1.00 1.00 1.00 1.00 1.00 1.00 1.00 1.00 1.00 1.00 1.00 1.00 1.00 1.00 1.00 1.00 1.00 1.00 1.00 1.00 1.00 1.00 1.00 1.00 1.00 1.00 1.00 1.00 1.00 1.00 1.00 1.00 1.00 1.00 1.00 1.00 1.00 1.00 1.00 1.00 1.00 1.00 1.00 1.00 1.00 1.00 1.00 1.00 1.00 1.00 1.00 1.00 1.00 1.00 1.00 1.00 1.00 1.00 1.00 1.00 1.00 1.00 1.00 1.00 1.00 1.00 1.00 1.00 1.00 1.00 1.00 1.00 1.00 1.00 1.00 1.00 1.00 1.00 1.00 1.00 1.00 1.00 1.00 1.00 1.00 1.00 1.00 1.00 1.00 1.00 1.00 1.00 1.00 1.00 1.00 1.00 1.00 1.00 1.00 1.00 1.00 1.00 1.00 1.00 1.00 1.00 1.00 1.00 1.00 1.00 1.00 1.00 1.00 1.00 1.00 1.00 1.00 1.00 1.00 1.00 1.00 1.00 1.00 1.00 1.00 1.00 1.00 1.00 1.00 1.00 1.00 1.00 1.00 1.00 1.00 1.00 1.00 1.00 1.00 1.00 1.00 1.00 1.00 1.00 1.00 1.00 1.00 1.00 1.00 1.00 1.00 1.00 1.00 1.00 1.00 1.00 1.00 1.00 1.00 1.00 1.00 1.00 1.00 1.00 1.00 1.00 1.00 1.00 1.00 1.00 1.00 1.00 1.00 1.00 1.00 1.00 1.00 1.00 1.00 1.00 1.00 1.00 1.00 1.00 1.00 1.00 1.00 1.00 1.00 1.00 1.00 1.00 1.00 1.00 1.00 1.00 1.00 1.00 1.00 1.00 1.00 1.00 1.00 1.00 1.00 1.00 1.00 1.00 1.00 1.00 1.00 1.00 1.00 1.00 1.00 1.00 1.00 1.00 1.00 1.00 1.00 1.00 1.00 1.00 1.00 1.00 1.00 1.00 1.00 1.00 1.00 1.00 1.00 1.00 1.00 1.00 1.00 1.00 1.00 1.00 1.00 1.00 1.00 1.00 1.00 1.00 1.00 1.00 1.00 1.00 1.00 1.00 1.00 1.00 1.00 1.00 1.00 1.00 1.00 1.00 1.00 1.00 1.00 1.00 1.00 1.00 1.00 1.00 1.00 1.00 1.00 1.00 1.00 1.00 1.00 1.00 1.00 1.00 1.00 1.00 1.00 1.00 1.00 1.00 1.00 1.00 1.00 1.00 1.00 1.00 1.00 1.00 1.00 1.00 1.00 1.00 1.00 1.00 1.00 1.00 1.00 1.00 1.00 1.00 1.00 1.00 1.00 1.00 1.00 1.00 1.00 1.00 1.00 1.00 1.00 1.00 1.00 1.00 1.00 1.00 1.00 1.00 1.00 1.00 1.00 1.00 1.00 1.00 1.00 1.00 1.00 1.00</beamAttenuationFactors>
				<commonCountingTime unit="seconds">0.352</commonCountingTime>
				<counts unit="counts">48 33 42 31 37 31 38 34 29 30 38 35 27 39 42 42 33 33 37 22 42 40 30 43 22 39 39 40 42 31 34 41 34 46 37 25 34 34 39 28 27 50 42 28 35 32 36 46 42 25 37 29 32 35 33 33 38 35 31 40 37 32 27 25 32 31 33 31 45 27 40 34 26 37 33 40 38 32 36 33 29 33 34 30 39 39 36 38 35 33 36 27 43 31 39 39 28 31 34 30 42 27 45 43 35 41 39 46 36 24 42 36 29 35 45 30 29 31 29 33 26 31 38 37 30 33 39 37 31 51 24 36 27 36 31 29 32 28 31 26 31 35 34 43 28 29 52 37 39 46 51 51 36 40 27 43 32 30 52 22 24 31 31 25 38 44 35 42 58 48 49 38 43 47 38 36 39 38 38 36 39 33 34 29 30 40 30 44 57 44 44 58 56 57 63 58 46 50 52 40 33 32 45 42 39 34 49 49 45 67 65 77 88 94 95 98 105 124 106 93 100 86 83 62 44 61 52 58 85 111 153 179 235 338 414 483 595 732 800 925 1054 1127 1182 1388 1421 1489 1457 1538 1536 1415 1366 1344 1238 1188 1082 954 862 736 644 539 425 359 299 202 188 162 172 204 208 879 2590 5597 11556 24202 57331 121103 135855 75860 37186 22004 18634 18493 13550 1995 504 360 264 202 158 145 106 92 62 73 65 68 71 81 78 88 86 91 95 89 111 83 95 72 59 62 42 52 38 39 42 32 34 36 34 36 45 53 61 55 47 68 54 50 38 47 54 33 39 41 36 35 20 41 32 36 30 21 32 36 35 45 50 62 57 41 40 39 40 34 37 35 35 32 29 29 19 30 26 26 27 31 34 38 35 39 27 28 31 37 34 44 34 35 34 31 32 16 28 17 22 27 32 20 37 28 24 29 51 29 35 33 23 23 21 30 26 26 26 24 23 25 25 23 26 27 28 25 14 26 37 27 31 23 25 17 26 29 30 25 21 27 31 20 23 25 31 25 25 24 29 20 18 28 31 36 25 36 31 23 20 24 19 22 16 20 27 29 25 25 22 30 13 31 36 27 39 34 21 25 18 19 23 24 21 26 19 24 27 24 17 15 31 32 24 25 30 20 29 24 19 27 16 16 33 27 19 23 27 27 24 34 27 24 28 27 24 20 23 22 27 24 19 32 24 26 21 29 17 24 30 24 23 22 24 18 22 16 22 29 19 19 34 16 23 22 25 12 20 31 20 28 18 16 20 20 20 25 32 27 22 28 20 15 24 30 23 18 32 26 29 32 22 31 15 27 24 17 21 19 27 23 25 29 24 28 23 26 25 27 23 22 24 27 24 30 26 31 28 23 21 19 15 30 10 18 16 19 27 20 16 20 17 23 11 24 29 16 19 21 16 25 21 26 22 22 18 22 21 28 19 20 20 28 18 23 20 20 26 20 21 23 17 14 17 18 18 13 22 21 19 23 21 23 21 25 23 20 27 24 26 26 24 16 19 15 26 30 9 15 15 22 24 28 32 16 23 20 20 25 25 13 17 19 17 21 28 18 17 17 15 20 20 16 15 16 18 25 24 14 19 20 15 29 24 17 18 18 20 22 25 27 25 8 23 21 15 18 16 16 20 20 21 29 19 12 14 21 25 21 22 17 20 19 24 24 17 26 17 16 27 18 22 12 22 19 21 20 22 20 19 24 12 21 17 17 23 18 14 18 19 27 19 18 19 22 12 16 26 17 23 21 12 18 20 17 19 17 24 16 12 16 19 19 17 24 16 20 20 19 13 19 18 21 27 10 20 14 25 21 19 13 17 17 25 16 15 17 18 26 23 15 13 22 12 15 16 19 15 16 20 20 22 15 20 22 16 19 14 19 20 13 11 25 17 19 22 16 15 19 27 21 18 22 22 20 24 25 23 27 13 15 18 10 19 39 19 18 17 19 14 31 16 14 17 17 17 17 24 14 15 20 19 16 16 21 17 15 15 22 13 16 17 13 16 19 17 21 22 20 17 20 21 16 16 18 17 12 15 17 22 26 9 12 16 17 19 13 15 15 15 9 25 18 13 22 12 21 16 16 22 18 12 22 13 16 16 20 15 23 17 8 11 22 19 21 29 14 13 12 13 14 14 15 20 16 11 17 16 17 14 15 20 19 21 11 18 17 13 24 13 26 16 18 7 11 19 12 17 17 17 15 11 20 14 13 9 17 11 8 15 17 17 16 26 17 20 11 15 11 12 19 13 19 22 12 18 19 14 15 8 20 11 15 12 16 12 19 16 13 20 12 18 19 11 16 14 14 18 15 19 12 10 19 14 14 16 15 8 17 18 10 16 8 21 19 16 10 12 10 15 13 18 13 17 8 10 15 16 13 9 15 9 11 18 11 16 10 21 16 18 17 16 15 14 7 16 21 9 10 14 12 12 17 15 16 20 11 17 12 25 14 8 16 10 24 12 12 12 19 17 18 17 13 11 15 11 9 14 15 7 13 12 11 10 22 16 8 11 10 17 16 13 14 15 14 16 15 7 7 18 14 13 14 14 19 17 19 5 12 12 11 14 16 15 14 18 16 13 16 20 16 14 11 15 11 10 17 16 17 12 6 13 16 13 15 5 12 12 6 12 10 14 14 18 17 9 13 15 9 8 16 21 16 11 17 14 16 14 12 14 14 9 9 11 10 14 8 14 13 10 19 11 11 17 14 18 3 17 10 12 10 20 12 21 13 15 16 11 11 18 9 7 12 16 9 7 20 10 15 11 11 6 17 18 8 12 18 11 12 18 10 16 6 14 5 9 11 15 13 12 8 18 9 7 10 14 14 13 12 10 13 12 12 15 12 12 14 14 11 20 15 13 12 11 18 16 13 15 14 11 13 12 10 23 10 9 22 15 17 16 6 12 10 8 10 21 12 17 11 14 15 13 9 11 15 15 13 12 17 15 12 10 19 13 13 14 10 10 11 9 14 14 8 12 9 18 12 7 21 14 10 11 18 9 12 3 12 11 14 21 9 10 16 8 14 18 7 7 12 9 14 10 11 12 14 11 11 16 12 11 12 14 15 10 10 15 9 14 10 13 9 12 15 12 7 17 14 10 8 7 12 11 12 13 10 12 15 14 12 5 11 13 14 9 11 12 14 14 12 13 12 11 8 10 14 17 16 17 10 13 6 7 14 11 15 6 7 15 13 12 12 9 11 15 11 6 12 6 10 14 14 14 15 12 14 14 16 14 8 9 10 10 13 10 11 11 13 15 16 10 12 10 8 9 8 6 9 7 11 12 12 8 5 11 13 10 15 8 5 7 17 8 9 7 18 11 8 15 11 10 12 5 11 13 11 10 15 8 12 11 13 10 6 16 14 13 7 10 6 14 3 10 3 12 10 9 10 17 11 8 10 8 11 9 11 12 10 12 10 7 10 8 12 8 5 13 7 7 7 13 11 5 13 5 12 15 11 11 9 6 14 5 5 7 10 6 13 9 14 5 11 13 11 9 8 5 11 9 14 12 11 10 14 7 14 7 20 8 2 12 1 13 14 8 10 21 10 8 7 11 8 20 17 12 14 9 10 12 9 20 10 11 15 13 9 7 9 12 10 10 11 8 11 7 6 12 12 11 11 7 7 11 12 8 9 14 7 9 10 9 8 13 12 9 6 10 10 13 12 10 8 15 11 12 10 14 8 12 8 9 8 8 12 10 13 7 13 9 9 9 15 7 11 16 5 11 9 8 9 13 15 11 18 14 8 15 12 15 13 9 7 10 4 11 6 12 11 7 12 13 11 16 10 8 15 4 8 7 8 15 12 8 13 5 7 7 5 13 12 3 11 5 9 7 17 8 10 14 8 7 19 7 8 7 11 9 11 7 7 10 10 12 11 7 12 16 20 13 8 12 9 8 9 7 7 10 18 8 10 10 8 6 7 12 6 13 16 14 9 10 9 6 8 6 16 18 5 10 12 13 6 11 10 10 10 6 10 13 7 11 10 9 6 12 15 8 9 18 10 8 12 12 8 10 9 13 6 14 10 9 9 14 7 9 9 6 12 5 5 7 16 11 9 10 7 7 7 14 16 8 8 8 9 9 9 20 6 8 13 14 13 13 9 14 5 13 16 9 14 9 11 15 10 4 9 15 12 9 9 16 5 15 8 14 11 4 18 18 13 12 8 11 6 12 12 11 12 9 11 10 15 10 5 16 14 9 14 13 11 6 8 15 10 8 12 13 9 16 12 6 11 10 10 12 5 11 10 12 12 7 6 10 11 10 12 5 9 11 9 8 7 13 7 9 10 6 3 7 6 14 8 10 7 4 3 7 3 10 5 8 6 10 6 8 10 11 11 12 7 9 10 8 18 8 11 9 6 13 8 12 8 12 8 10 9 6 14 12 8 9 6 8 10 17 13 14 8 19 10 8 16 10 7 6 12 7 6 7 11 10 11 13 15 8 16 10 6 15 9 14 11 9 5 12 11 5 8 8 14 11 8 11 7 8 9 11 6 11 7 10 11 9 11 13 14 7 13 9 9 5 7 8 12 9 12 15 7 11 12 8 10 6 18 13 9 8 11 9 8 9 7 3 9 10 12 12 8 16 10 10 4 9 7 14 14 11 13 15 9 12 9 12 11 11 5 13 12 6 10 13 11 7 15 11 8 5 11 13 8 5 7 16 7 11 7 9 10 14 9 10 4 14 12 11 8 8 10 9 9 4 7 15 9 10 6 5 11 10 8 12 13 14 15 13 13 13 13 7 8 11 11 10 13 4 9 7 7 10 7 10 10 8 9 11 11 7 16 13 15 12 8 9 11 6 10 19 8 6 5 8 11 12 5 9 14 8 10 13 12 14 10 7 10 10 11 9 11 9 12 9 12 15 6 10 8 10 12 14 15 5 9 8 7 10 14 11 10 14 10 10 9 12 12 15 9 6 16 12 13 12 11 12 7 13 12 10 8 15 7 10 12 11 12 17 10 8 9 11 5 15 10 4 7 8 15 15 10 13 8 7 8 11 8 16 7 6 6 17 11 12 11 11 12 7 16 10 10 6 12 9 12 17 14 10 8 9 9 13 11 13 12 15 13 21 8 10 6 7 10 10 6 8 10 13 9 6 8 14 11 12 9 8 9 17 20 15 5 9 10 10 10 7 8 6 14 7 9 12 12 16 10 8 8 11 11 15 13 7 14 13 21 14 14 11 13 8 9 7 18 7 12 6 12 5 17 11 10 17 5 12 16 16 9 10 6 16 10 7 10 12 12 12 10 15 11 12 15 11 15 17 15 13 14 15 9 10 13 3 7 7 9 10 11 11 11 8 11 9 22 17 16 15 8 7 24 11 14 16 16 14 17 21 7 8 16 13 10 12 8 10 8 14 8 11 14 17 15 10 17 22 15 15 17 15 17 12 13 14 9 19 13 12 15 13 19 9 11 22 18 15 10 15 22 19 16 9 21 20 18 12 16 13 12 16 9 14 18 12 14 14 15 16 17 21 9 19 29 26 15 28 20 20 20 14 10 15 14 16 17 16 12 10 20 15 27 27 19 22 23 18 32 18 19 27 20 20 24 20 20 15 16 21 13 18 14 22 19 20 29 32 21 30 30 26 33 29 36 26 27 17 20 24 26 18 18 15 24 28 16 27 28 33 21 36 54 43 43 38 45 38 41 30 23 23 25 26 24 17 17 18 25 28 21 37 30 45 53 52 66 56 62 75 66 70 59 41 46 55 46 42 36 29 39 32 28 50 57 42 75 84 81 87 115 133 122 119 114 122 119 91 89 81 64 55 64 49 62 67 81 92 106 152 192 234 241 257 291 316 347 359 340 352 336 323 280 245 208 190 178 220 235 294 420 579 743 1012 1290 1796 2115 2599 3136 3798 4431 5142 5811 6516 7376 7869 8508 8887 9584 9898 10294 10381 10714 10768 10651 10283 10045 9653 9378 8913 8004 7467 6796 5988 5328 4699 3979 3427 2829 2355 1854 1496 1228 958 813 653 659 610 634 691 728 851 938 1029 1084 1137 1224 1245 1237 1213 1270 1286 1289 1342 1390 1699 2260 3655 7053 14272 24898 36500 49704 64822 78345 91410 115054 159354 1362 2638 6004 8179 6193 3296 1816 1571 1355 1081 144092 64855 25942 7151 2915 1797 1177 874 653 503 434 298 263 189 146 138 107 98 97 78 56 83 92 99 75 94 78 98 82 65 70 72 52 56 52 27 44 31 13 27 24 28 26 23 17 28 32 21 36 33 28 41 34 40 34 20 28 23 21 16 21 16 20 14 10 11 13 10 17 13 12 17 25 20 13 14 21 18 18 19 25 9 19 20 7 11 16 6 10 10 13 8 13 10 10 16 18 14 16 17 13 10 17 7 13 5 14 9 6 13 5 14 11 12 11 10 8 7 11 14 10 8 9 16 13 15 6 14 16 11 8 7 5 19 13 12 11 10 9 11 13 12 10 15 9 7 21 10 8 10 16 13 11 6 13 8 13 9 12 9 11 9 8 8 2 11 11 8 10 3 6 9 3 11 10 12 7 9 12 11 16 11 15 10 6 7 13 8 10 9 13 10 11 9 7 8 8 10 8 3 10 10 8 6 13 9 8 9 12 12 7 7 5 4 12 6 11 8 3 7 6 13 3 7 8 8 12 8 6 6 10 9 11 11 6 8 7 7 7 6 7 11 13 6 11 15 12 5 11 12 13 7 12 11 6 6 15 3 8 7 6 9 7 9 9 4 8 8 6 3 13 5 6 7 10 8 5 7 9 9 9 6 6 15 7 6 7 4 5 1 6 7 4 11 9 6 7 4 8 10 5 8 8 12 7 8 4 6 9 3 5 4 7 10 4 9 7 12 9 7 9 9 8 5 3 7 8 2 6 8 10 9 8 7 4 8 10 6 5 7 6 6 13 7 7</counts>
			</dataPoints>
		</scan>
	</xrdMeasurement>
</xrdMeasurements>