File: data/previous_data/set_4-YG039-041/xrd/YG040-SRO001-STO001-07172022.xrdml
<xrdMeasurements xmlns="http://www.xrdml.com/XRDMeasurement/2.1" xmlns:xsi="http://www.w3.org/2001/XMLSchema-instance" xsi:schemaLocation="http://www.xrdml.com/XRDMeasurement/2.1 http://www.xrdml.com/XRDMeasurement/2.1/XRDMeasurement.xsd" status="Completed">
	<comment>
		<entry>Configuration=Main Configuration, Owner=User-1, Creation date=6/17/2015 3:36:16 PM</entry>
		<entry>Goniometer=HR HD (Theta/2Theta); Minimum step size 2Theta:0.0001; Minimum step size Omega:0.0001</entry>
		<entry>Sample stage=MRD Cradle; Minimum step size Phi:0.01; Minimum step size Chi:0.01; Minimum step size X:0.01; Minimum step size Y:0.01; Minimum step size Z:0.001</entry>
		<entry>Diffractometer system=XPERT-3</entry>
		<entry>Measurement program=C:\PANalytical\Data Collector\Programs\Yichen\regular_2theta_20-50_0.4s-20min.xrdmp, Identifier={AEA8F2F2-8BFA-4B07-A521-A571AF38E73A}</entry>
	</comment>
	<sample type="To be analyzed">
		<id></id>
		<name></name>
		<preparedBy></preparedBy>
	</sample>
	<xrdMeasurement measurementType="Scan" status="Completed" sampleMode="Reflection">
		<comment>
			<entry>PHD Lower Level = 4.02 (keV), PHD Upper Level = 11.27 (keV)</entry>
		</comment>
		<usedWavelength intended="K-Alpha 1">
			<kAlpha1 unit="Angstrom">1.5405980</kAlpha1>
			<kAlpha2 unit="Angstrom">1.5444260</kAlpha2>
			<kBeta unit="Angstrom">1.3922500</kBeta>
			<ratioKAlpha2KAlpha1>0.5000</ratioKAlpha2KAlpha1>
		</usedWavelength>
		<incidentBeamPath>
			<radius unit="mm">320.00</radius>
			<xRayTube id="1010048" name="Empyrean Cu LFF HR (9430 033 7310x) DK425175">
				<tension unit="kV">45.0</tension>
				<current unit="mA">40.0</current>
				<anodeMaterial>Cu</anodeMaterial>
				<focus type="Line">
					<length unit="mm">12.0</length>
					<width unit="mm">0.4</width>
					<takeOffAngle unit="deg">4.2</takeOffAngle>
				</focus>
			</xRayTube>
			<xRayMirror id="27090001" name="Inc. Beam Cu W/Si (hybrid MRD)" hybrid="true">
				<crystal type="Graded" shape="Parabolic">W/Si</crystal>
				<acceptanceAngle unit="deg">0.800</acceptanceAngle>
				<length unit="mm">60.0</length>
			</xRayMirror>
			<monochromator id="23090002" name="Hybrid monochr. 2xGe(220) Cu asym." hybrid="true">
				<crystal type="Asymmetric" shape="Flat">Ge</crystal>
				<numberOfReflections>2</numberOfReflections>
				<hkl>
					<h>2</h>
					<k>2</k>
					<l>0</l>
				</hkl>
			</monochromator>
			<divergenceSlit id="22010004" name="Fixed slit 1/2°" xsi:type="fixedDivergenceSlitType">
				<distanceToSample unit="mm">220.00</distanceToSample>
				<height unit="mm">0.76</height>
			</divergenceSlit>
			<beamAttenuator id="26010001" name="Progr. beam attenuator Ni 0.125 mm" xsi:type="intensitySwitchedBeamAttenuatorType">
				<factor>172.00</factor>
				<material>Ni</material>
				<activateLevel unit="counts per second">500000</activateLevel>
				<deactivateLevel unit="counts per second">400000</deactivateLevel>
			</beamAttenuator>
		</incidentBeamPath>
		<diffractedBeamPath>
			<radius unit="mm">320.00</radius>
			<antiScatterSlit id="22090009" name="AS slit 7.5 mm (PIXcel)" xsi:type="fixedAntiScatterSlitType">
				<height unit="mm">7.50</height>
			</antiScatterSlit>
			<sollerSlit id="21010002" name="Soller slits 0.04 rad.">
				<opening unit="rad">0.0400</opening>
			</sollerSlit>
			<receivingSlit id="22010004" name="Fixed slit 1/2°">
				<height unit="mm">0.76</height>
			</receivingSlit>
			<detector id="7010020" name="PIXcel3D-Medipix3 1x1 detector" xsi:type="areaDetectorType">
				<phd unit="%">
					<lowerLevel>25.0</lowerLevel>
					<upperLevel>70.0</upperLevel>
				</phd>
				<mode>Receiving slit</mode>
				<activeChannelsEquatorial>5</activeChannelsEquatorial>
				<activeChannelsAxial>255</activeChannelsAxial>
				<pitchEquatorial unit="mm">0.05500</pitchEquatorial>
				<pitchAxial unit="mm">0.05500</pitchAxial>
				<readOutPeriod unit="seconds">0.050</readOutPeriod>
			</detector>
		</diffractedBeamPath>
		<scan appendNumber="0" mode="Continuous" scanAxis="2Theta-Omega" status="Completed">
			<header>
				<startTimeStamp>2022-07-17T16:17:19-07:00</startTimeStamp>
				<endTimeStamp>2022-07-17T16:37:45-07:00</endTimeStamp>
				<author>
					<name>XRD</name>
				</author>
				<source>
					<applicationSoftware version="6.1b">Data Collector</applicationSoftware>
					<instrumentControlSoftware version="7.4b 20181204">XPERT-3</instrumentControlSoftware>
					<instrumentID>0000000011163216</instrumentID>
				</source>
			</header>
			<dataPoints>
				<positions axis="2Theta" unit="deg">
					<startPosition>20.0050</startPosition>
					<endPosition>49.9950</endPosition>
				</positions>
				<positions axis="Omega" unit="deg">
					<startPosition>9.9263</startPosition>
					<endPosition>24.9213</endPosition>
				</positions>
				<positions axis="Phi" unit="deg">
					<commonPosition>0.00</commonPosition>
				</positions>
				<positions axis="Chi" unit="deg">
					<commonPosition>-0.18</commonPosition>
				</positions>
				<positions axis="X" unit="mm">
					<commonPosition>0.32</commonPosition>
				</positions>
				<positions axis="Y" unit="mm">
					<commonPosition>0.00</commonPosition>
				</positions>
				<positions axis="Z" unit="mm">
					<commonPosition>8.363</commonPosition>
				</positions>
				<beamAttenuationFactors>1.00 1.00 1.00 1.00 1.00 1.00 1.00 1.00 1.00 1.00 1.00 1.00 1.00 1.00 1.00 1.00 1.00 1.00 1.00 1.00 1.00 1.00 1.00 1.00 1.00 1.00 1.00 1.00 1.00 1.00 1.00 1.00 1.00 1.00 1.00 1.00 1.00 1.00 1.00 1.00 1.00 1.00 1.00 1.00 1.00 1.00 1.00 1.00 1.00 1.00 1.00 1.00 1.00 1.00 1.00 1.00 1.00 1.00 1.00 1.00 1.00 1.00 1.00 1.00 1.00 1.00 1.00 1.00 1.00 1.00 1.00 1.00 1.00 1.00 1.00 1.00 1.00 1.00 1.00 1.00 1.00 1.00 1.00 1.00 1.00 1.00 1.00 1.00 1.00 1.00 1.00 1.00 1.00 1.00 1.00 1.00 1.00 1.00 1.00 1.00 1.00 1.00 1.00 1.00 1.00 1.00 1.00 1.00 1.00 1.00 1.00 1.00 1.00 1.00 1.00 1.00 1.00 1.00 1.00 1.00 1.00 1.00 1.00 1.00 1.00 1.00 1.00 1.00 1.00 1.00 1.00 1.00 1.00 1.00 1.00 1.00 1.00 1.00 1.00 1.00 1.00 1.00 1.00 1.00 1.00 1.00 1.00 1.00 1.00 1.00 1.00 1.00 1.00 1.00 1.00 1.00 1.00 1.00 1.00 1.00 1.00 1.00 1.00 1.00 1.00 1.00 1.00 1.00 1.00 1.00 1.00 1.00 1.00 1.00 1.00 1.00 1.00 1.00 1.00 1.00 1.00 1.00 1.00 1.00 1.00 1.00 1.00 1.00 1.00 1.00 1.00 1.00 1.00 1.00 1.00 1.00 1.00 1.00 1.00 1.00 1.00 1.00 1.00 1.00 1.00 1.00 1.00 1.00 1.00 1.00 1.00 1.00 1.00 1.00 1.00 1.00 1.00 1.00 1.00 1.00 1.00 1.00 1.00 1.00 1.00 1.00 1.00 1.00 1.00 1.00 1.00 1.00 1.00 1.00 1.00 1.00 1.00 1.00 1.00 1.00 1.00 1.00 1.00 1.00 1.00 1.00 1.00 1.00 1.00 1.00 1.00 1.00 1.00 1.00 1.00 1.00 1.00 1.00 1.00 1.00 1.00 1.00 1.00 1.00 1.00 1.00 1.00 1.00 1.00 1.00 1.00 1.00 1.00 1.00 1.00 1.00 1.00 1.00 1.00 1.00 1.00 1.00 1.00 1.00 1.00 1.00 1.00 1.00 1.00 1.00 1.00 1.00 1.00 1.00 1.00 1.00 1.00 1.00 1.00 1.00 1.00 1.00 1.00 1.00 1.00 1.00 1.00 1.00 1.00 1.00 1.00 1.00 1.00 1.00 1.00 1.00 1.00 1.00 1.00 1.00 1.00 1.00 1.00 1.00 1.00 1.00 1.00 1.00 1.00 1.00 1.00 1.00 1.00 1.00 1.00 1.00 1.00 1.00 1.00 1.00 1.00 1.00 1.00 1.00 1.00 1.00 1.00 1.00 1.00 1.00 1.00 1.00 1.00 1.00 1.00 1.00 1.00 1.00 1.00 1.00 1.00 1.00 1.00 1.00 1.00 1.00 1.00 1.00 1.00 1.00 1.00 1.00 1.00 1.00 1.00 1.00 1.00 1.00 1.00 1.00 1.00 1.00 1.00 1.00 1.00 1.00 1.00 1.00 1.00 1.00 1.00 1.00 1.00 1.00 1.00 1.00 1.00 1.00 1.00 1.00 1.00 1.00 1.00 1.00 1.00 1.00 1.00 1.00 1.00 1.00 1.00 1.00 1.00 1.00 1.00 1.00 1.00 1.00 1.00 1.00 1.00 1.00 1.00 1.00 1.00 1.00 1.00 1.00 1.00 1.00 1.00 1.00 1.00 1.00 1.00 1.00 1.00 1.00 1.00 1.00 1.00 1.00 1.00 1.00 1.00 1.00 1.00 1.00 1.00 1.00 1.00 1.00 1.00 1.00 1.00 1.00 1.00 1.00 1.00 1.00 1.00 1.00 1.00 1.00 1.00 1.00 1.00 1.00 1.00 1.00 1.00 1.00 1.00 1.00 1.00 1.00 1.00 1.00 1.00 1.00 1.00 1.00 1.00 1.00 1.00 1.00 1.00 1.00 1.00 1.00 1.00 1.00 1.00 1.00 1.00 1.00 1.00 1.00 1.00 1.00 1.00 1.00 1.00 1.00 1.00 1.00 1.00 1.00 1.00 1.00 1.00 1.00 1.00 1.00 1.00 1.00 1.00 1.00 1.00 1.00 1.00 1.00 1.00 1.00 1.00 1.00 1.00 1.00 1.00 1.00 1.00 1.00 1.00 1.00 1.00 1.00 1.00 1.00 1.00 1.00 1.00 1.00 1.00 1.00 1.00 1.00 1.00 1.00 1.00 1.00 1.00 1.00 1.00 1.00 1.00 1.00 1.00 1.00 1.00 1.00 1.00 1.00 1.00 1.00 1.00 1.00 1.00 1.00 1.00 1.00 1.00 1.00 1.00 1.00 1.00 1.00 1.00 1.00 1.00 1.00 1.00 1.00 1.00 1.00 1.00 1.00 1.00 1.00 1.00 1.00 1.00 1.00 1.00 1.00 1.00 1.00 1.00 1.00 1.00 1.00 1.00 1.00 1.00 1.00 1.00 1.00 1.00 1.00 1.00 1.00 1.00 1.00 1.00 1.00 1.00 1.00 1.00 1.00 1.00 1.00 1.00 1.00 1.00 1.00 1.00 1.00 1.00 1.00 1.00 1.00 1.00 1.00 1.00 1.00 1.00 1.00 1.00 1.00 1.00 1.00 1.00 1.00 1.00 1.00 1.00 1.00 1.00 1.00 1.00 1.00 1.00 1.00 1.00 1.00 1.00 1.00 1.00 1.00 1.00 1.00 1.00 1.00 1.00 1.00 1.00 1.00 1.00 1.00 1.00 1.00 1.00 1.00 1.00 1.00 1.00 1.00 1.00 1.00 1.00 1.00 1.00 1.00 1.00 1.00 1.00 1.00 1.00 1.00 1.00 1.00 1.00 1.00 1.00 1.00 1.00 1.00 1.00 1.00 1.00 1.00 1.00 1.00 1.00 1.00 1.00 1.00 1.00 1.00 1.00 1.00 1.00 1.00 1.00 1.00 1.00 1.00 1.00 1.00 1.00 1.00 1.00 1.00 1.00 1.00 1.00 1.00 1.00 1.00 1.00 1.00 1.00 1.00 1.00 1.00 1.00 1.00 1.00 1.00 1.00 1.00 1.00 1.00 1.00 1.00 1.00 1.00 1.00 1.00 1.00 1.00 1.00 1.00 1.00 1.00 1.00 1.00 1.00 1.00 1.00 1.00 1.00 1.00 1.00 1.00 1.00 1.00 1.00 1.00 1.00 1.00 1.00 1.00 1.00 1.00 1.00 1.00 1.00 1.00 1.00 1.00 1.00 1.00 1.00 1.00 1.00 1.00 1.00 1.00 1.00 1.00 1.00 1.00 1.00 1.00 1.00 1.00 1.00 1.00 1.00 1.00 1.00 1.00 1.00 1.00 1.00 1.00 1.00 1.00 1.00 1.00 1.00 1.00 1.00 1.00 1.00 1.00 1.00 1.00 1.00 1.00 1.00 1.00 1.00 1.00 1.00 1.00 1.00 1.00 1.00 1.00 1.00 1.00 1.00 1.00 1.00 1.00 1.00 1.00 1.00 1.00 1.00 1.00 1.00 1.00 1.00 1.00 1.00 1.00 1.00 1.00 1.00 1.00 1.00 1.00 1.00 1.00 1.00 1.00 1.00 1.00 1.00 1.00 1.00 1.00 1.00 1.00 1.00 1.00 1.00 1.00 1.00 1.00 1.00 1.00 1.00 1.00 1.00 1.00 1.00 1.00 1.00 1.00 1.00 1.00 1.00 1.00 1.00 1.00 1.00 1.00 1.00 1.00 1.00 1.00 1.00 1.00 1.00 1.00 1.00 1.00 1.00 1.00 1.00 1.00 1.00 1.00 1.00 1.00 1.00 1.00 1.00 1.00 1.00 1.00 1.00 1.00 1.00 1.00 1.00 1.00 1.00 1.00 1.00 1.00 1.00 1.00 1.00 1.00 1.00 1.00 1.00 1.00 1.00 1.00 1.00 1.00 1.00 1.00 1.00 1.00 1.00 1.00 1.00 1.00 1.00 1.00 1.00 1.00 1.00 1.00 1.00 1.00 1.00 1.00 1.00 1.00 1.00 1.00 1.00 1.00 1.00 1.00 1.00 1.00 1.00 1.00 1.00 1.00 1.00 1.00 1.00 1.00 1.00 1.00 1.00 1.00 1.00 1.00 1.00 1.00 1.00 1.00 1.00 1.00 1.00 1.00 1.00 1.00 1.00 1.00 1.00 1.00 1.00 1.00 1.00 1.00 1.00 1.00 1.00 1.00 1.00 1.00 1.00 1.00 1.00 1.00 1.00 1.00 1.00 1.00 1.00 1.00 1.00 1.00 1.00 1.00 1.00 1.00 1.00 1.00 1.00 1.00 1.00 1.00 1.00 1.00 1.00 1.00 1.00 1.00 1.00 1.00 1.00 1.00 1.00 1.00 1.00 1.00 1.00 1.00 1.00 1.00 1.00 1.00 1.00 1.00 1.00 1.00 1.00 1.00 1.00 1.00 1.00 1.00 1.00 1.00 1.00 1.00 1.00 1.00 1.00 1.00 1.00 1.00 1.00 1.00 1.00 1.00 1.00 1.00 1.00 1.00 1.00 1.00 1.00 1.00 1.00 1.00 1.00 1.00 1.00 1.00 1.00 1.00 1.00 1.00 1.00 1.00 1.00 1.00 1.00 1.00 1.00 1.00 1.00 1.00 1.00 1.00 1.00 1.00 1.00 1.00 1.00 1.00 1.00 1.00 1.00 1.00 1.00 1.00 1.00 1.00 1.00 1.00 1.00 1.00 1.00 1.00 1.00 1.00 1.00 1.00 1.00 1.00 1.00 1.00 1.00 1.00 1.00 1.00 1.00 1.00 1.00 1.00 1.00 1.00 1.00 1.00 1.00 1.00 1.00 1.00 1.00 1.00 1.00 1.00 1.00 1.00 1.00 1.00 1.00 1.00 1.00 1.00 1.00 1.00 1.00 1.00 1.00 1.00 1.00 1.00 1.00 1.00 1.00 1.00 1.00 1.00 1.00 1.00 1.00 1.00 1.00 1.00 1.00 1.00 1.00 1.00 1.00 1.00 1.00 1.00 1.00 1.00 1.00 1.00 1.00 1.00 1.00 1.00 1.00 1.00 1.00 1.00 1.00 1.00 1.00 1.00 1.00 1.00 1.00 1.00 1.00 1.00 1.00 1.00 1.00 1.00 1.00 1.00 1.00 1.00 1.00 1.00 1.00 1.00 1.00 1.00 1.00 1.00 1.00 1.00 1.00 1.00 1.00 1.00 1.00 1.00 1.00 1.00 1.00 1.00 1.00 1.00 1.00 1.00 1.00 1.00 1.00 1.00 1.00 1.00 1.00 1.00 1.00 1.00 1.00 1.00 1.00 1.00 1.00 1.00 1.00 1.00 1.00 1.00 1.00 1.00 1.00 1.00 1.00 1.00 1.00 1.00 1.00 1.00 1.00 1.00 1.00 1.00 1.00 1.00 1.00 1.00 1.00 1.00 1.00 1.00 1.00 1.00 1.00 1.00 1.00 1.00 1.00 1.00 1.00 1.00 1.00 1.00 1.00 1.00 1.00 1.00 1.00 1.00 1.00 1.00 1.00 1.00 1.00 1.00 1.00 1.00 1.00 1.00 1.00 1.00 1.00 1.00 1.00 1.00 1.00 1.00 1.00 1.00 1.00 1.00 1.00 1.00 1.00 1.00 1.00 1.00 1.00 1.00 1.00 1.00 1.00 1.00 1.00 1.00 1.00 1.00 1.00 1.00 1.00 1.00 1.00 1.00 1.00 1.00 1.00 1.00 1.00 1.00 1.00 1.00 1.00 1.00 1.00 1.00 1.00 1.00 1.00 1.00 1.00 1.00 1.00 1.00 1.00 1.00 1.00 1.00 1.00 1.00 1.00 1.00 1.00 1.00 1.00 1.00 1.00 1.00 1.00 1.00 1.00 1.00 1.00 1.00 1.00 1.00 1.00 1.00 1.00 1.00 1.00 1.00 1.00 1.00 1.00 1.00 1.00 1.00 1.00 1.00 1.00 1.00 1.00 1.00 1.00 1.00 1.00 1.00 1.00 1.00 1.00 1.00 1.00 1.00 1.00 1.00 1.00 1.00 1.00 1.00 1.00 1.00 1.00 1.00 1.00 1.00 1.00 1.00 1.00 1.00 1.00 1.00 1.00 1.00 1.00 1.00 1.00 1.00 1.00 1.00 1.00 1.00 1.00 1.00 1.00 1.00 1.00 1.00 1.00 1.00 1.00 1.00 1.00 1.00 1.00 1.00 1.00 1.00 1.00 1.00 1.00 1.00 1.00 1.00 1.00 1.00 1.00 1.00 1.00 1.00 1.00 1.00 1.00 1.00 1.00 1.00 1.00 1.00 1.00 1.00 1.00 1.00 1.00 1.00 1.00 1.00 1.00 1.00 1.00 1.00 1.00 1.00 1.00 1.00 1.00 1.00 1.00 1.00 1.00 1.00 1.00 1.00 1.00 1.00 1.00 1.00 1.00 1.00 1.00 1.00 1.00 1.00 1.00 1.00 1.00 1.00 1.00 1.00 1.00 1.00 1.00 1.00 1.00 1.00 1.00 1.00 1.00 1.00 1.00 1.00 1.00 1.00 1.00 1.00 1.00 1.00 1.00 1.00 1.00 1.00 1.00 1.00 1.00 1.00 1.00 1.00 1.00 1.00 1.00 1.00 1.00 1.00 1.00 1.00 1.00 1.00 1.00 1.00 1.00 1.00 1.00 1.00 1.00 1.00 1.00 1.00 1.00 1.00 1.00 1.00 1.00 1.00 1.00 1.00 1.00 1.00 1.00 1.00 1.00 1.00 1.00 1.00 1.00 1.00 1.00 1.00 1.00 1.00 1.00 1.00 1.00 1.00 1.00 1.00 1.00 1.00 1.00 1.00 1.00 1.00 1.00 1.00 1.00 1.00 1.00 1.00 1.00 1.00 1.00 1.00 1.00 1.00 1.00 1.00 1.00 1.00 1.00 1.00 1.00 1.00 1.00 1.00 1.00 1.00 1.00 1.00 1.00 1.00 1.00 1.00 1.00 1.00 1.00 1.00 1.00 1.00 1.00 1.00 1.00 1.00 1.00 1.00 1.00 1.00 1.00 1.00 1.00 1.00 1.00 1.00 1.00 1.00 1.00 1.00 1.00 1.00 1.00 1.00 1.00 1.00 1.00 1.00 1.00 1.00 1.00 1.00 1.00 1.00 1.00 1.00 1.00 1.00 1.00 1.00 1.00 1.00 1.00 1.00 1.00 1.00 1.00 1.00 1.00 1.00 1.00 1.00 1.00 1.00 1.00 1.00 1.00 1.00 1.00 1.00 1.00 1.00 1.00 1.00 1.00 1.00 1.00 1.00 1.00 1.00 1.00 1.00 1.00 1.00 1.00 1.00 1.00 1.00 1.00 1.00 1.00 1.00 1.00 1.00 1.00 1.00 1.00 1.00 1.00 1.00 1.00 1.00 1.00 1.00 1.00 1.00 1.00 1.00 1.00 1.00 1.00 1.00 1.00 1.00 1.00 1.00 1.00 1.00 1.00 1.00 1.00 1.00 1.00 1.00 1.00 1.00 1.00 1.00 1.00 1.00 1.00 1.00 1.00 1.00 1.00 1.00 1.00 1.00 1.00 1.00 1.00 1.00 1.00 1.00 1.00 1.00 1.00 1.00 1.00 1.00 1.00 1.00 1.00 1.00 1.00 1.00 1.00 1.00 1.00 1.00 1.00 1.00 1.00 1.00 1.00 1.00 1.00 1.00 1.00 1.00 1.00 1.00 1.00 1.00 1.00 1.00 1.00 1.00 1.00 1.00 1.00 1.00 1.00 1.00 1.00 1.00 1.00 1.00 1.00 1.00 1.00 1.00 1.00 1.00 1.00 1.00 1.00 1.00 1.00 1.00 1.00 1.00 1.00 1.00 1.00 1.00 1.00 1.00 1.00 1.00 1.00 1.00 1.00 1.00 1.00 1.00 1.00 1.00 1.00 1.00 1.00 1.00 1.00 1.00 1.00 1.00 1.00 1.00 1.00 1.00 1.00 1.00 1.00 1.00 1.00 1.00 1.00 1.00 1.00 1.00 1.00 1.00 1.00 1.00 1.00 1.00 1.00 1.00 1.00 1.00 1.00 1.00 1.00 1.00 1.00 1.00 1.00 1.00 1.00 1.00 1.00 1.00 1.00 1.00 1.00 1.00 1.00 1.00 1.00 1.00 1.00 1.00 1.00 1.00 1.00 1.00 1.00 1.00 1.00 1.00 1.00 1.00 1.00 1.00 1.00 1.00 1.00 1.00 1.00 1.00 1.00 1.00 1.00 1.00 1.00 1.00 1.00 1.00 1.00 1.00 1.00 1.00 1.00 1.00 1.00 1.00 1.00 1.00 1.00 1.00 1.00 1.00 1.00 1.00 1.00 1.00 1.00 1.00 1.00 1.00 1.00 1.00 1.00 1.00 1.00 1.00 1.00 1.00 1.00 1.00 1.00 1.00 1.00 1.00 1.00 1.00 1.00 1.00 1.00 1.00 1.00 1.00 1.00 1.00 1.00 1.00 1.00 1.00 1.00 1.00 1.00 1.00 1.00 1.00 1.00 1.00 1.00 1.00 1.00 1.00 1.00 1.00 1.00 1.00 1.00 1.00 1.00 1.00 1.00 1.00 1.00 1.00 1.00 1.00 1.00 1.00 1.00 1.00 1.00 1.00 1.00 1.00 1.00 1.00 1.00 1.00 1.00 1.00 1.00 1.00 1.00 1.00 1.00 1.00 1.00 1.00 1.00 1.00 1.00 1.00 1.00 1.00 1.00 1.00 1.00 1.00 1.00 1.00 1.00 1.00 1.00 1.00 1.00 1.00 1.00 1.00 1.00 1.00 1.00 1.00 1.00 1.00 1.00 1.00 1.00 1.00 1.00 1.00 1.00 1.00 1.00 1.00 1.00 1.00 1.00 1.00 1.00 1.00 1.00 1.00 1.00 1.00 1.00 1.00 1.00 1.00 1.00 1.00 1.00 1.00 1.00 1.00 1.00 1.00 1.00 1.00 1.00 1.00 1.00 1.00 1.00 1.00 1.00 1.00 1.00 1.00 1.00 1.00 1.00 1.00 1.00 1.00 1.00 1.00 1.00 1.00 1.00 1.00 1.00 1.00 1.00 1.00 1.00 1.00 1.00 1.00 1.00 1.00 1.00 1.00 1.00 1.00 1.00 1.00 1.00 1.00 1.00 1.00 1.00 1.00 1.00 1.00 1.00 1.00 1.00 1.00 1.00 1.00 1.00 1.00 1.00 1.00 1.00 1.00 1.00 1.00 1.00 1.00 1.00 1.00 1.00 1.00 1.00 1.00 1.00 1.00 1.00 1.00 1.00 1.00 1.00 1.00 1.00 1.00 1.00 1.00 1.00 1.00 1.00 1.00 1.00 1.00 1.00 1.00 1.00 1.00 1.00 1.00 1.00 1.00 1.00 1.00 1.00 1.00 1.00 1.00 1.00 1.00 1.00 1.00 1.00 1.00 1.00 1.00 1.00 1.00 1.00 1.00 1.00 1.00 1.00 1.00 1.00 1.00 1.00 1.00 1.00 1.00 1.00 1.00 1.00 1.00 1.00 1.00 1.00 1.00 1.00 1.00 1.00 1.00 1.00 1.00 1.00 1.00 1.00 1.00 1.00 1.00 1.00 1.00 1.00 1.00 1.00 1.00 1.00 1.00 1.00 1.00 1.00 1.00 1.00 1.00 1.00 1.00 1.00 1.00 1.00 1.00 1.00 1.00 1.00 1.00 1.00 1.00 1.00 1.00 1.00 1.00 1.00 1.00 1.00 1.00 1.00 1.00 1.00 1.00 1.00 1.00 1.00 1.00 1.00 1.00 1.00 1.00 1.00 1.00 1.00 1.00 1.00 1.00 1.00 1.00 1.00 1.00 1.00 1.00 1.00 1.00 1.00 1.00 1.00 1.00 1.00 1.00 1.00 1.00 1.00 1.00 1.00 1.00 1.00 1.00 1.00 1.00 1.00 1.00 1.00 1.00 1.00 1.00 1.00 1.00 1.00 1.00 1.00 1.00 1.00 1.00 1.00 1.00 1.00 1.00 1.00 1.00 1.00 1.00 1.00 1.00 1.00 1.00 1.00 1.00 1.00 1.00 1.00 1.00 1.00 1.00 1.00 1.00 1.00 1.00 1.00 1.00 1.00 1.00 1.00 1.00 1.00 1.00 1.00 1.00 1.00 1.00 1.00 1.00 1.00 1.00 1.00 1.00 1.00 1.00 1.00 1.00 1.00 1.00 1.00 1.00 1.00 1.00 1.00 1.00 1.00 1.00 1.00 1.00 1.00 1.00 1.00 1.00 1.00 1.00 1.00 1.00 1.00 1.00 1.00 1.00 1.00 1.00 1.00 1.00 1.00 1.00 1.00 1.00 1.00 1.00 1.00 1.00 1.00 1.00 1.00 1.00 1.00 1.00 1.00 1.00 1.00 1.00 1.00 1.00 1.00 1.00 1.00 1.00 1.00 1.00 1.00 1.00 1.00 1.00 1.00 1.00 1.00 1.00 1.00 1.00 1.00 1.00 1.00 1.00 1.00 1.00 1.00 1.00 1.00 1.00 1.00 1.00 1.00 1.00 1.00 1.00 1.00 1.00 1.00 1.00 1.00 1.00 1.00 1.00 1.00 1.00 1.00 1.00 1.00 1.00 1.00 1.00 1.00 1.00 1.00 1.00 1.00 1.00 1.00 1.00 1.00 1.00 1.00 1.00 1.00 1.00 1.00 1.00 1.00 1.00 1.00 1.00 1.00 1.00 1.00 1.00 1.00 1.00 1.00 1.00 1.00 1.00 1.00 1.00 1.00 1.00 1.00 1.00 1.00 1.00 1.00 1.00 1.00 1.00 1.00 1.00 1.00 1.00 1.00 1.00 1.00 1.00 1.00 1.00 1.00 1.00 1.00 1.00 1.00 1.00 1.00 1.00 1.00 1.00 1.00 1.00 1.00 1.00 1.00 1.00 1.00 1.00 1.00 1.00 1.00 1.00 1.00 1.00 1.00 1.00 1.00 1.00 1.00 1.00 1.00 1.00 1.00 1.00 1.00 1.00 1.00 1.00 1.00 1.00 1.00 1.00 1.00 1.00 1.00 1.00 1.00 1.00 1.00 1.00 1.00 1.00 1.00 1.00 1.00 1.00 1.00 1.00 1.00 1.00 1.00 1.00 1.00 1.00 1.00 1.00 1.00 1.00 1.00 1.00 1.00 1.00 1.00 1.00 1.00 1.00 1.00 1.00 1.00 1.00 1.00 1.00 1.00 1.00 1.00 1.00 1.00 1.00 1.00 1.00 1.00 1.00 1.00 1.00 1.00 1.00 1.00 1.00 1.00 1.00 1.00 1.00 1.00 1.00 1.00 1.00 1.00 1.00 1.00 1.00 1.00 1.00 1.00 1.00 1.00 1.00 1.00 1.00 1.00 1.00 1.00 1.00 1.00 1.00 1.00 1.00 1.00 1.00 1.00 1.00 1.00 1.00 1.00 1.00 1.00 1.00 1.00 172.00 172.00 172.00 172.00 172.00 172.00 172.00 172.00 172.00 172.00 172.00 172.00 172.00 1.00 1.00 1.00 1.00 1.00 1.00 1.00 1.00 1.00 1.00 1.00 1.00 1.00 1.00 1.00 1.00 1.00 1.00 1.00 1.00 1.00 1.00 1.00 1.00 1.00 1.00 1.00 1.00 1.00 1.00 1.00 1.00 1.00 1.00 1.00 1.00 1.00 1.00 1.00 1.00 1.00 1.00 1.00 1.00 1.00 1.00 1.00 1.00 1.00 1.00 1.00 1.00 1.00 1.00 1.00 1.00 1.00 1.00 1.00 1.00 1.00 1.00 1.00 1.00 1.00 1.00 1.00 1.00 1.00 1.00 1.00 1.00 1.00 1.00 1.00 1.00 1.00 1.00 1.00 1.00 1.00 1.00 1.00 1.00 1.00 1.00 1.00 1.00 1.00 1.00 1.00 1.00 1.00 1.00 1.00 1.00 1.00 1.00 1.00 1.00 1.00 1.00 1.00 1.00 1.00 1.00 1.00 1.00 1.00 1.00 1.00 1.00 1.00 1.00 1.00 1.00 1.00 1.00 1.00 1.00 1.00 1.00 1.00 1.00 1.00 1.00 1.00 1.00 1.00 1.00 1.00 1.00 1.00 1.00 1.00 1.00 1.00 1.00 1.00 1.00 1.00 1.00 1.00 1.00 1.00 1.00 1.00 1.00 1.00 1.00 1.00 1.00 1.00 1.00 1.00 1.00 1.00 1.00 1.00 1.00 1.00 1.00 1.00 1.00 1.00 1.00 1.00 1.00 1.00 1.00 1.00 1.00 1.00 1.00 1.00 1.00 1.00 1.00 1.00 1.00 1.00 1.00 1.00 1.00 1.00 1.00 1.00 1.00 1.00 1.00 1.00 1.00 1.00 1.00 1.00 1.00 1.00 1.00 1.00 1.00 1.00 1.00 1.00 1.00 1.00 1.00 1.00 1.00 1.00 1.00 1.00 1.00 1.00 1.00 1.00 1.00 1.00 1.00 1.00 1.00 1.00 1.00 1.00 1.00 1.00 1.00 1.00 1.00 1.00 1.00 1.00 1.00 1.00 1.00 1.00 1.00 1.00 1.00 1.00 1.00 1.00 1.00 1.00 1.00 1.00 1.00 1.00 1.00 1.00 1.00 1.00 1.00 1.00 1.00 1.00 1.00 1.00 1.00 1.00 1.00 1.00 1.00 1.00 1.00 1.00 1.00 1.00 1.00 1.00 1.00 1.00 1.00 1.00 1.00 1.00 1.00 1.00 1.00 1.00 1.00 1.00 1.00 1.00 1.00 1.00 1.00 1.00 1.00 1.00 1.00 1.00 1.00 1.00 1.00 1.00 1.00 1.00 1.00 1.00 1.00 1.00 1.00 1.00 1.00 1.00 1.00 1.00 1.00 1.00 1.00 1.00 1.00 1.00 1.00 1.00 1.00 1.00 1.00 1.00 1.00 1.00 1.00 1.00 1.00 1.00 1.00 1.00 1.00 1.00 1.00 1.00 1.00 1.00 1.00 1.00 1.00 1.00 1.00 1.00 1.00 1.00 1.00 1.00 1.00 1.00 1.00 1.00 1.00</beamAttenuationFactors>
				<commonCountingTime unit="seconds">0.352</commonCountingTime>
				<counts unit="counts">37 32 33 34 26 41 39 43 42 45 40 32 27 36 35 28 29 24 29 35 38 29 33 47 42 32 42 28 28 32 27 25 34 29 41 30 37 35 27 31 32 33 31 32 25 35 43 35 31 40 30 36 24 35 43 33 35 45 38 36 27 32 40 36 25 22 33 34 30 31 31 38 27 29 27 32 34 36 40 32 27 24 24 25 42 37 37 28 36 40 36 34 34 32 22 31 29 30 27 28 31 34 27 39 37 36 32 42 45 29 43 39 29 38 28 18 25 30 38 28 37 23 32 30 35 40 34 35 29 34 25 35 47 30 38 38 30 33 34 26 27 29 34 30 38 32 27 37 39 27 41 41 43 47 45 34 23 28 33 37 28 21 28 40 31 39 31 39 38 54 37 41 42 52 43 43 45 31 39 32 37 40 36 26 38 44 25 37 50 49 53 46 52 59 58 63 36 55 58 55 37 40 44 42 34 46 44 53 51 55 59 75 76 102 84 103 87 113 80 85 88 85 58 58 62 64 63 72 100 110 154 235 279 368 440 579 725 791 880 1012 1077 1128 1243 1329 1418 1467 1429 1402 1373 1365 1329 1225 1138 1029 914 860 689 600 473 390 331 229 218 166 152 134 195 267 2452 11915 18490 20445 22602 30956 60734 117535 129063 66282 25613 12116 5661 1546 562 363 271 212 168 129 112 82 74 72 52 62 51 67 68 72 71 90 83 94 77 78 101 80 62 65 50 50 44 54 43 40 35 41 40 31 49 50 44 57 45 40 42 53 44 56 41 38 39 30 30 36 21 35 37 34 27 26 26 39 32 46 33 45 29 36 39 23 35 29 27 28 38 28 24 36 42 28 38 32 36 28 42 39 27 41 31 43 39 31 19 37 36 40 21 23 25 24 24 20 27 24 26 20 29 28 32 34 34 31 25 34 26 25 23 31 27 28 15 26 22 26 27 25 24 36 33 23 35 40 30 41 30 43 26 30 31 34 23 15 23 31 35 22 20 31 32 25 25 37 29 23 19 24 27 38 22 28 26 34 30 18 22 29 24 24 27 26 21 26 20 25 28 38 37 41 19 18 26 23 27 21 25 21 21 24 32 24 17 29 36 34 25 22 24 21 22 21 32 25 25 30 26 20 19 29 23 19 29 22 25 13 26 18 29 28 24 24 26 23 24 23 19 22 28 26 28 20 37 30 13 32 24 24 22 25 35 15 18 25 33 13 26 24 32 22 22 16 25 23 26 26 21 22 24 25 19 21 26 24 19 25 20 20 20 23 27 23 23 32 36 19 21 22 14 20 29 19 18 23 12 11 17 23 22 29 28 25 17 17 32 25 22 18 22 26 25 24 13 25 14 22 24 21 22 26 16 23 20 18 23 30 20 21 21 28 21 19 19 20 20 23 20 16 20 21 26 20 15 18 22 18 18 18 20 19 25 29 25 16 20 17 22 13 25 21 23 25 15 33 18 25 19 16 13 22 23 18 27 23 23 16 22 20 19 16 17 19 25 18 22 28 28 16 16 18 12 17 22 17 29 15 21 20 26 15 21 26 14 19 22 24 20 22 24 22 25 18 20 22 13 17 29 26 21 20 15 17 18 21 23 15 16 23 21 19 18 23 12 24 27 15 23 22 13 28 16 21 14 18 23 20 30 19 19 20 21 21 21 15 17 19 19 22 20 19 23 15 17 31 28 26 31 13 21 16 22 15 26 21 11 21 19 17 16 19 14 18 15 21 23 24 20 18 19 16 20 17 15 14 23 16 22 18 17 29 19 14 21 26 21 14 11 22 17 17 8 19 20 20 13 20 9 14 18 16 17 17 17 16 11 16 19 14 20 24 23 20 25 18 17 21 12 20 26 13 19 16 21 18 19 28 27 13 11 19 13 14 23 19 16 24 15 17 17 24 23 19 21 28 29 21 22 23 17 17 17 20 28 26 23 17 24 20 15 26 18 12 18 22 15 14 25 16 16 21 19 15 17 23 15 21 35 10 14 17 16 17 18 17 11 15 12 17 22 7 20 17 23 12 20 14 14 17 11 18 14 14 19 14 17 25 17 15 12 10 17 9 24 14 15 10 18 16 10 20 20 23 21 16 13 19 12 17 15 16 21 12 20 27 18 10 10 12 10 19 21 21 14 12 16 10 17 14 21 20 24 15 20 9 15 13 11 9 25 17 14 11 13 16 14 14 13 17 20 16 17 22 22 23 23 22 13 13 19 19 11 14 12 14 14 12 19 14 20 15 10 11 21 17 16 13 10 15 16 13 16 14 28 11 19 11 12 14 14 8 12 15 24 8 12 16 10 10 15 14 18 13 13 13 13 18 19 18 17 12 24 13 17 10 19 8 18 18 13 10 20 21 11 17 18 16 15 17 19 18 14 18 16 17 16 10 18 10 18 11 13 13 18 10 9 14 13 19 15 11 16 13 11 16 12 11 16 23 17 16 17 15 19 12 8 18 13 18 14 14 10 16 16 15 10 10 14 13 21 15 13 14 10 16 15 15 15 15 6 15 10 13 12 10 9 14 17 16 19 22 18 12 17 16 10 16 14 20 25 4 15 18 11 12 7 18 16 10 12 12 13 16 18 11 11 15 14 15 11 11 14 11 19 12 16 11 16 9 18 11 18 14 16 14 11 17 12 19 18 16 13 10 13 11 16 16 8 7 9 14 24 10 13 14 12 16 16 11 16 13 15 14 13 11 13 22 10 12 10 14 12 14 13 24 11 22 9 22 18 14 16 11 6 16 12 13 15 12 8 10 14 18 9 11 12 14 12 14 11 16 16 17 12 5 15 11 18 12 15 14 16 13 21 5 13 12 8 11 4 8 14 21 15 5 11 13 8 11 11 11 20 10 12 19 13 9 14 13 17 13 13 13 11 9 6 11 14 11 14 13 14 9 11 7 13 17 8 9 11 13 8 15 15 14 9 13 12 9 7 10 11 13 10 11 14 11 15 10 7 13 12 11 9 17 9 19 11 13 22 15 10 13 13 10 8 7 12 14 6 14 14 13 11 6 11 12 8 11 8 11 12 15 12 11 9 13 6 9 14 14 10 14 10 15 12 15 9 11 6 19 14 17 9 17 11 8 12 9 10 11 6 9 19 15 14 12 9 11 7 19 6 10 16 9 10 11 7 13 14 14 13 9 5 10 7 12 3 7 14 7 15 12 10 10 10 11 9 9 17 12 9 10 9 13 7 14 9 16 13 16 15 7 6 14 16 11 9 9 13 10 10 10 10 13 9 14 10 11 9 4 17 6 7 10 9 15 8 12 12 16 8 5 12 13 11 14 17 6 15 9 14 11 8 10 12 15 17 13 11 10 8 11 11 16 8 3 15 10 11 9 8 8 9 11 11 9 10 4 15 11 10 8 9 11 11 8 10 13 8 10 14 16 8 8 6 11 7 13 13 12 14 7 14 11 11 5 16 12 8 15 15 10 9 18 11 13 8 12 9 14 9 9 13 9 7 16 11 4 7 11 13 12 12 10 13 10 19 11 4 9 14 9 8 14 12 10 20 8 13 9 9 7 7 11 12 9 11 3 12 18 11 9 12 9 7 13 8 11 12 8 18 11 12 9 10 9 5 11 14 8 7 11 10 7 16 12 8 11 10 21 5 11 4 7 11 16 13 12 11 8 15 14 9 12 9 14 4 9 4 9 12 7 10 11 9 11 9 12 9 11 12 11 14 12 8 9 9 9 14 16 9 10 7 16 12 13 10 8 14 8 11 7 8 6 8 13 13 9 8 9 10 9 14 8 10 17 9 5 11 10 12 19 10 9 13 9 13 8 5 6 11 10 10 12 15 10 12 7 13 8 9 12 10 7 10 10 8 9 12 13 10 15 11 7 12 3 7 11 7 16 9 16 12 13 7 12 10 11 10 7 14 16 6 9 10 5 7 6 12 12 9 8 17 6 11 15 8 13 12 10 11 10 18 10 10 9 11 10 9 9 10 8 7 10 6 11 8 15 13 7 6 8 10 6 9 7 10 8 9 12 9 12 7 9 15 10 8 12 15 5 15 6 8 12 14 10 5 12 9 6 7 14 11 5 9 5 14 11 6 13 7 17 10 13 7 8 9 12 10 7 12 9 7 14 7 11 11 5 9 13 10 3 10 16 16 11 10 11 11 9 11 11 8 3 6 8 11 13 4 8 7 17 6 6 9 6 11 10 7 10 12 11 9 12 8 10 9 6 6 6 10 8 12 15 9 7 9 8 12 13 14 10 17 7 15 13 15 10 7 9 16 2 8 8 12 9 13 9 13 8 11 8 10 7 11 13 5 6 15 12 9 11 8 11 10 10 10 8 8 10 6 19 6 10 10 7 8 9 9 16 5 12 16 9 10 17 10 9 7 7 10 18 13 15 9 10 16 7 13 8 9 14 5 13 9 10 9 7 9 10 8 9 11 4 13 15 15 8 7 13 8 6 12 7 9 14 10 15 11 8 10 5 13 6 8 9 16 11 11 6 13 14 6 6 12 8 8 5 13 9 13 8 6 14 14 10 9 6 13 9 14 11 10 15 10 10 13 9 11 7 7 12 7 13 8 7 5 14 7 16 18 6 15 9 11 9 8 10 8 11 8 7 7 5 14 9 19 12 7 16 5 12 7 6 9 6 6 14 15 10 8 9 14 9 8 5 9 9 8 7 7 10 14 11 15 9 9 7 7 9 13 8 16 12 10 5 11 9 13 8 10 12 9 10 7 3 15 5 14 5 7 6 5 12 9 4 13 12 10 11 14 13 6 10 10 8 7 13 7 12 10 16 9 12 16 7 18 13 18 8 12 9 14 14 9 12 6 9 6 9 14 13 11 9 8 10 12 12 16 9 13 11 5 5 8 5 16 11 8 7 9 10 9 10 11 12 8 10 13 15 13 5 13 8 7 14 9 7 13 9 14 10 5 20 10 11 11 11 10 6 10 13 12 19 11 15 5 7 14 10 7 8 11 14 10 7 13 11 8 8 9 8 8 7 2 8 6 9 9 11 10 9 7 14 15 12 16 8 8 6 11 10 7 12 15 11 10 8 10 14 7 15 12 11 16 5 13 15 4 9 13 10 15 13 10 9 6 10 10 8 10 10 9 7 14 13 13 11 11 13 12 10 12 10 10 11 8 13 8 11 8 13 7 8 12 9 18 11 10 20 6 13 11 2 15 15 6 12 14 12 7 10 13 8 11 10 6 12 10 6 13 12 8 13 13 11 9 10 8 12 16 7 10 11 7 8 15 9 5 2 18 10 5 9 8 15 16 14 15 11 21 8 16 14 8 12 10 15 6 7 12 12 4 10 9 13 15 18 6 11 10 9 14 7 16 10 9 11 19 6 13 17 15 11 18 9 6 11 12 17 18 10 11 25 18 13 8 23 11 20 14 19 11 16 12 10 13 12 7 15 19 18 12 13 11 15 17 17 21 24 13 16 16 19 15 18 12 10 13 14 11 9 12 16 11 12 8 18 14 16 12 19 32 25 23 18 15 18 20 17 13 18 16 11 19 15 7 9 10 21 10 20 17 17 21 22 22 17 19 19 19 18 14 17 22 18 10 23 15 15 22 10 20 13 25 21 30 32 28 31 24 20 25 21 33 27 26 23 26 21 11 17 21 16 23 21 21 30 26 25 27 32 46 46 35 46 42 33 41 23 28 29 25 29 28 14 29 30 27 33 40 36 55 34 66 52 62 64 60 59 60 56 52 50 36 42 47 35 23 29 29 44 45 41 53 67 78 79 92 109 113 84 128 118 119 95 106 85 77 99 62 85 73 86 67 125 132 149 174 192 206 252 302 317 324 324 336 346 312 292 315 310 245 328 324 358 412 487 643 809 1032 1369 1718 2111 2660 2978 3668 4277 4939 5604 6222 6666 7451 8092 8675 9142 9629 9985 10626 10590 10549 10457 10418 10112 9775 9358 8735 8376 7591 6946 6357 5609 4884 4204 3576 3029 2414 1914 1614 1206 993 787 679 605 602 615 664 779 808 970 1009 1144 1247 1235 1337 1358 1377 1348 1384 1314 1368 1452 1569 1845 2580 5014 14332 39198 84675 133955 159371 1301 1467 1369 1232 1055 1188 1596 3030 6644 8153 5408 2580 1112 92075 34572 17220 7098 3525 2005 1357 1100 821 662 511 376 322 251 222 147 136 114 87 93 85 84 77 83 80 101 98 89 74 99 94 81 79 63 50 56 51 53 29 21 25 17 22 22 14 28 36 26 35 31 32 39 38 35 25 25 29 24 15 15 20 14 19 10 13 10 10 18 16 19 16 23 25 17 20 18 17 11 13 19 19 13 15 15 18 15 15 16 20 6 9 18 10 14 16 13 12 11 16 15 19 14 17 14 11 10 9 18 15 12 12 15 13 12 11 11 11 10 14 8 7 10 9 14 8 8 18 10 7 11 9 10 9 6 15 12 7 14 7 11 13 9 6 18 15 10 9 12 14 5 9 12 12 11 13 7 4 9 9 7 12 12 14 15 11 10 8 6 8 8 11 9 13 15 11 12 8 7 6 15 9 11 6 9 6 12 8 7 5 1 3 10 10 10 10 8 8 12 6 3 5 9 14 8 10 9 8 6 9 5 8 5 5 5 8 8 7 11 7 9 12 8 4 14 4 9 12 7 5 8 7 10 4 6 9 3 4 6 5 5 7 10 8 12 6 8 11 9 6 5 9 6 4 10 3 5 8 8 9 7 8 8 9 6 9 9 5 7 4 7 8 7 8 3 6 6 6 7 10 4 7 10 10 2 5 8 12 6 4 5 6 10 8 12 10 11 6 7 5 6 8 2 6 5 8 9 6 8 7 10 8 11 9 10 7 9 8 5 7 3 9 5 9 6 7 11 8 5 7 6 9 4 8 8 3 9 7 11 8 4 5 5 5 1 5 10 6 6</counts>
			</dataPoints>
		</scan>
	</xrdMeasurement>
</xrdMeasurements>