File: data/previous_data/set_3-YG035-038/xrd/YG038-SRO001-STO001-06192022.xrdml
<xrdMeasurements xmlns="http://www.xrdml.com/XRDMeasurement/2.1" xmlns:xsi="http://www.w3.org/2001/XMLSchema-instance" xsi:schemaLocation="http://www.xrdml.com/XRDMeasurement/2.1 http://www.xrdml.com/XRDMeasurement/2.1/XRDMeasurement.xsd" status="Completed">
	<comment>
		<entry>Configuration=Main Configuration, Owner=User-1, Creation date=6/17/2015 3:36:16 PM</entry>
		<entry>Goniometer=HR HD (Theta/2Theta); Minimum step size 2Theta:0.0001; Minimum step size Omega:0.0001</entry>
		<entry>Sample stage=MRD Cradle; Minimum step size Phi:0.01; Minimum step size Chi:0.01; Minimum step size X:0.01; Minimum step size Y:0.01; Minimum step size Z:0.001</entry>
		<entry>Diffractometer system=XPERT-3</entry>
		<entry>Measurement program=C:\PANalytical\Data Collector\Programs\Yichen\regular_2theta_20-50_0.4s-20min.xrdmp, Identifier={AEA8F2F2-8BFA-4B07-A521-A571AF38E73A}</entry>
	</comment>
	<sample type="To be analyzed">
		<id></id>
		<name></name>
		<preparedBy></preparedBy>
	</sample>
	<xrdMeasurement measurementType="Scan" status="Completed" sampleMode="Reflection">
		<comment>
			<entry>PHD Lower Level = 4.02 (keV), PHD Upper Level = 11.27 (keV)</entry>
		</comment>
		<usedWavelength intended="K-Alpha 1">
			<kAlpha1 unit="Angstrom">1.5405980</kAlpha1>
			<kAlpha2 unit="Angstrom">1.5444260</kAlpha2>
			<kBeta unit="Angstrom">1.3922500</kBeta>
			<ratioKAlpha2KAlpha1>0.5000</ratioKAlpha2KAlpha1>
		</usedWavelength>
		<incidentBeamPath>
			<radius unit="mm">320.00</radius>
			<xRayTube id="1010048" name="Empyrean Cu LFF HR (9430 033 7310x) DK425175">
				<tension unit="kV">45.0</tension>
				<current unit="mA">40.0</current>
				<anodeMaterial>Cu</anodeMaterial>
				<focus type="Line">
					<length unit="mm">12.0</length>
					<width unit="mm">0.4</width>
					<takeOffAngle unit="deg">4.2</takeOffAngle>
				</focus>
			</xRayTube>
			<xRayMirror id="27090001" name="Inc. Beam Cu W/Si (hybrid MRD)" hybrid="true">
				<crystal type="Graded" shape="Parabolic">W/Si</crystal>
				<acceptanceAngle unit="deg">0.800</acceptanceAngle>
				<length unit="mm">60.0</length>
			</xRayMirror>
			<monochromator id="23090002" name="Hybrid monochr. 2xGe(220) Cu asym." hybrid="true">
				<crystal type="Asymmetric" shape="Flat">Ge</crystal>
				<numberOfReflections>2</numberOfReflections>
				<hkl>
					<h>2</h>
					<k>2</k>
					<l>0</l>
				</hkl>
			</monochromator>
			<divergenceSlit id="22010004" name="Fixed slit 1/2°" xsi:type="fixedDivergenceSlitType">
				<distanceToSample unit="mm">220.00</distanceToSample>
				<height unit="mm">0.76</height>
			</divergenceSlit>
			<beamAttenuator id="26010001" name="Progr. beam attenuator Ni 0.125 mm" xsi:type="intensitySwitchedBeamAttenuatorType">
				<factor>172.00</factor>
				<material>Ni</material>
				<activateLevel unit="counts per second">500000</activateLevel>
				<deactivateLevel unit="counts per second">400000</deactivateLevel>
			</beamAttenuator>
		</incidentBeamPath>
		<diffractedBeamPath>
			<radius unit="mm">320.00</radius>
			<antiScatterSlit id="22090009" name="AS slit 7.5 mm (PIXcel)" xsi:type="fixedAntiScatterSlitType">
				<height unit="mm">7.50</height>
			</antiScatterSlit>
			<sollerSlit id="21010002" name="Soller slits 0.04 rad.">
				<opening unit="rad">0.0400</opening>
			</sollerSlit>
			<receivingSlit id="22010004" name="Fixed slit 1/2°">
				<height unit="mm">0.76</height>
			</receivingSlit>
			<detector id="7010020" name="PIXcel3D-Medipix3 1x1 detector" xsi:type="areaDetectorType">
				<phd unit="%">
					<lowerLevel>25.0</lowerLevel>
					<upperLevel>70.0</upperLevel>
				</phd>
				<mode>Receiving slit</mode>
				<activeChannelsEquatorial>5</activeChannelsEquatorial>
				<activeChannelsAxial>255</activeChannelsAxial>
				<pitchEquatorial unit="mm">0.05500</pitchEquatorial>
				<pitchAxial unit="mm">0.05500</pitchAxial>
				<readOutPeriod unit="seconds">0.050</readOutPeriod>
			</detector>
		</diffractedBeamPath>
		<scan appendNumber="0" mode="Continuous" scanAxis="2Theta-Omega" status="Completed">
			<header>
				<startTimeStamp>2022-06-19T14:13:09-07:00</startTimeStamp>
				<endTimeStamp>2022-06-19T14:33:35-07:00</endTimeStamp>
				<author>
					<name>XRD</name>
				</author>
				<source>
					<applicationSoftware version="6.1b">Data Collector</applicationSoftware>
					<instrumentControlSoftware version="7.4b 20181204">XPERT-3</instrumentControlSoftware>
					<instrumentID>0000000011163216</instrumentID>
				</source>
			</header>
			<dataPoints>
				<positions axis="2Theta" unit="deg">
					<startPosition>20.0050</startPosition>
					<endPosition>49.9950</endPosition>
				</positions>
				<positions axis="Omega" unit="deg">
					<startPosition>10.3948</startPosition>
					<endPosition>25.3898</endPosition>
				</positions>
				<positions axis="Phi" unit="deg">
					<commonPosition>0.00</commonPosition>
				</positions>
				<positions axis="Chi" unit="deg">
					<commonPosition>-0.25</commonPosition>
				</positions>
				<positions axis="X" unit="mm">
					<commonPosition>-0.02</commonPosition>
				</positions>
				<positions axis="Y" unit="mm">
					<commonPosition>0.00</commonPosition>
				</positions>
				<positions axis="Z" unit="mm">
					<commonPosition>8.779</commonPosition>
				</positions>
				<beamAttenuationFactors>1.00 1.00 1.00 1.00 1.00 1.00 1.00 1.00 1.00 1.00 1.00 1.00 1.00 1.00 1.00 1.00 1.00 1.00 1.00 1.00 1.00 1.00 1.00 1.00 1.00 1.00 1.00 1.00 1.00 1.00 1.00 1.00 1.00 1.00 1.00 1.00 1.00 1.00 1.00 1.00 1.00 1.00 1.00 1.00 1.00 1.00 1.00 1.00 1.00 1.00 1.00 1.00 1.00 1.00 1.00 1.00 1.00 1.00 1.00 1.00 1.00 1.00 1.00 1.00 1.00 1.00 1.00 1.00 1.00 1.00 1.00 1.00 1.00 1.00 1.00 1.00 1.00 1.00 1.00 1.00 1.00 1.00 1.00 1.00 1.00 1.00 1.00 1.00 1.00 1.00 1.00 1.00 1.00 1.00 1.00 1.00 1.00 1.00 1.00 1.00 1.00 1.00 1.00 1.00 1.00 1.00 1.00 1.00 1.00 1.00 1.00 1.00 1.00 1.00 1.00 1.00 1.00 1.00 1.00 1.00 1.00 1.00 1.00 1.00 1.00 1.00 1.00 1.00 1.00 1.00 1.00 1.00 1.00 1.00 1.00 1.00 1.00 1.00 1.00 1.00 1.00 1.00 1.00 1.00 1.00 1.00 1.00 1.00 1.00 1.00 1.00 1.00 1.00 1.00 1.00 1.00 1.00 1.00 1.00 1.00 1.00 1.00 1.00 1.00 1.00 1.00 1.00 1.00 1.00 1.00 1.00 1.00 1.00 1.00 1.00 1.00 1.00 1.00 1.00 1.00 1.00 1.00 1.00 1.00 1.00 1.00 1.00 1.00 1.00 1.00 1.00 1.00 1.00 1.00 1.00 1.00 1.00 1.00 1.00 1.00 1.00 1.00 1.00 1.00 1.00 1.00 1.00 1.00 1.00 1.00 1.00 1.00 1.00 1.00 1.00 1.00 1.00 1.00 1.00 1.00 1.00 1.00 1.00 1.00 1.00 1.00 1.00 1.00 1.00 1.00 1.00 1.00 1.00 1.00 1.00 1.00 1.00 1.00 1.00 1.00 1.00 1.00 1.00 1.00 1.00 1.00 1.00 1.00 1.00 1.00 1.00 1.00 1.00 1.00 1.00 1.00 1.00 1.00 1.00 1.00 1.00 1.00 1.00 1.00 1.00 1.00 1.00 1.00 1.00 1.00 1.00 1.00 1.00 1.00 1.00 1.00 1.00 1.00 1.00 1.00 1.00 1.00 1.00 1.00 1.00 1.00 1.00 1.00 1.00 1.00 1.00 1.00 1.00 1.00 1.00 1.00 1.00 1.00 1.00 1.00 1.00 1.00 1.00 1.00 1.00 1.00 1.00 1.00 1.00 1.00 1.00 1.00 1.00 1.00 1.00 1.00 1.00 1.00 1.00 1.00 1.00 1.00 1.00 1.00 1.00 1.00 1.00 1.00 1.00 1.00 1.00 1.00 1.00 1.00 1.00 1.00 1.00 1.00 1.00 1.00 1.00 1.00 1.00 1.00 1.00 1.00 1.00 1.00 1.00 1.00 1.00 1.00 1.00 1.00 1.00 1.00 1.00 1.00 1.00 1.00 1.00 1.00 1.00 1.00 1.00 1.00 1.00 1.00 1.00 1.00 1.00 1.00 1.00 1.00 1.00 1.00 1.00 1.00 1.00 1.00 1.00 1.00 1.00 1.00 1.00 1.00 1.00 1.00 1.00 1.00 1.00 1.00 1.00 1.00 1.00 1.00 1.00 1.00 1.00 1.00 1.00 1.00 1.00 1.00 1.00 1.00 1.00 1.00 1.00 1.00 1.00 1.00 1.00 1.00 1.00 1.00 1.00 1.00 1.00 1.00 1.00 1.00 1.00 1.00 1.00 1.00 1.00 1.00 1.00 1.00 1.00 1.00 1.00 1.00 1.00 1.00 1.00 1.00 1.00 1.00 1.00 1.00 1.00 1.00 1.00 1.00 1.00 1.00 1.00 1.00 1.00 1.00 1.00 1.00 1.00 1.00 1.00 1.00 1.00 1.00 1.00 1.00 1.00 1.00 1.00 1.00 1.00 1.00 1.00 1.00 1.00 1.00 1.00 1.00 1.00 1.00 1.00 1.00 1.00 1.00 1.00 1.00 1.00 1.00 1.00 1.00 1.00 1.00 1.00 1.00 1.00 1.00 1.00 1.00 1.00 1.00 1.00 1.00 1.00 1.00 1.00 1.00 1.00 1.00 1.00 1.00 1.00 1.00 1.00 1.00 1.00 1.00 1.00 1.00 1.00 1.00 1.00 1.00 1.00 1.00 1.00 1.00 1.00 1.00 1.00 1.00 1.00 1.00 1.00 1.00 1.00 1.00 1.00 1.00 1.00 1.00 1.00 1.00 1.00 1.00 1.00 1.00 1.00 1.00 1.00 1.00 1.00 1.00 1.00 1.00 1.00 1.00 1.00 1.00 1.00 1.00 1.00 1.00 1.00 1.00 1.00 1.00 1.00 1.00 1.00 1.00 1.00 1.00 1.00 1.00 1.00 1.00 1.00 1.00 1.00 1.00 1.00 1.00 1.00 1.00 1.00 1.00 1.00 1.00 1.00 1.00 1.00 1.00 1.00 1.00 1.00 1.00 1.00 1.00 1.00 1.00 1.00 1.00 1.00 1.00 1.00 1.00 1.00 1.00 1.00 1.00 1.00 1.00 1.00 1.00 1.00 1.00 1.00 1.00 1.00 1.00 1.00 1.00 1.00 1.00 1.00 1.00 1.00 1.00 1.00 1.00 1.00 1.00 1.00 1.00 1.00 1.00 1.00 1.00 1.00 1.00 1.00 1.00 1.00 1.00 1.00 1.00 1.00 1.00 1.00 1.00 1.00 1.00 1.00 1.00 1.00 1.00 1.00 1.00 1.00 1.00 1.00 1.00 1.00 1.00 1.00 1.00 1.00 1.00 1.00 1.00 1.00 1.00 1.00 1.00 1.00 1.00 1.00 1.00 1.00 1.00 1.00 1.00 1.00 1.00 1.00 1.00 1.00 1.00 1.00 1.00 1.00 1.00 1.00 1.00 1.00 1.00 1.00 1.00 1.00 1.00 1.00 1.00 1.00 1.00 1.00 1.00 1.00 1.00 1.00 1.00 1.00 1.00 1.00 1.00 1.00 1.00 1.00 1.00 1.00 1.00 1.00 1.00 1.00 1.00 1.00 1.00 1.00 1.00 1.00 1.00 1.00 1.00 1.00 1.00 1.00 1.00 1.00 1.00 1.00 1.00 1.00 1.00 1.00 1.00 1.00 1.00 1.00 1.00 1.00 1.00 1.00 1.00 1.00 1.00 1.00 1.00 1.00 1.00 1.00 1.00 1.00 1.00 1.00 1.00 1.00 1.00 1.00 1.00 1.00 1.00 1.00 1.00 1.00 1.00 1.00 1.00 1.00 1.00 1.00 1.00 1.00 1.00 1.00 1.00 1.00 1.00 1.00 1.00 1.00 1.00 1.00 1.00 1.00 1.00 1.00 1.00 1.00 1.00 1.00 1.00 1.00 1.00 1.00 1.00 1.00 1.00 1.00 1.00 1.00 1.00 1.00 1.00 1.00 1.00 1.00 1.00 1.00 1.00 1.00 1.00 1.00 1.00 1.00 1.00 1.00 1.00 1.00 1.00 1.00 1.00 1.00 1.00 1.00 1.00 1.00 1.00 1.00 1.00 1.00 1.00 1.00 1.00 1.00 1.00 1.00 1.00 1.00 1.00 1.00 1.00 1.00 1.00 1.00 1.00 1.00 1.00 1.00 1.00 1.00 1.00 1.00 1.00 1.00 1.00 1.00 1.00 1.00 1.00 1.00 1.00 1.00 1.00 1.00 1.00 1.00 1.00 1.00 1.00 1.00 1.00 1.00 1.00 1.00 1.00 1.00 1.00 1.00 1.00 1.00 1.00 1.00 1.00 1.00 1.00 1.00 1.00 1.00 1.00 1.00 1.00 1.00 1.00 1.00 1.00 1.00 1.00 1.00 1.00 1.00 1.00 1.00 1.00 1.00 1.00 1.00 1.00 1.00 1.00 1.00 1.00 1.00 1.00 1.00 1.00 1.00 1.00 1.00 1.00 1.00 1.00 1.00 1.00 1.00 1.00 1.00 1.00 1.00 1.00 1.00 1.00 1.00 1.00 1.00 1.00 1.00 1.00 1.00 1.00 1.00 1.00 1.00 1.00 1.00 1.00 1.00 1.00 1.00 1.00 1.00 1.00 1.00 1.00 1.00 1.00 1.00 1.00 1.00 1.00 1.00 1.00 1.00 1.00 1.00 1.00 1.00 1.00 1.00 1.00 1.00 1.00 1.00 1.00 1.00 1.00 1.00 1.00 1.00 1.00 1.00 1.00 1.00 1.00 1.00 1.00 1.00 1.00 1.00 1.00 1.00 1.00 1.00 1.00 1.00 1.00 1.00 1.00 1.00 1.00 1.00 1.00 1.00 1.00 1.00 1.00 1.00 1.00 1.00 1.00 1.00 1.00 1.00 1.00 1.00 1.00 1.00 1.00 1.00 1.00 1.00 1.00 1.00 1.00 1.00 1.00 1.00 1.00 1.00 1.00 1.00 1.00 1.00 1.00 1.00 1.00 1.00 1.00 1.00 1.00 1.00 1.00 1.00 1.00 1.00 1.00 1.00 1.00 1.00 1.00 1.00 1.00 1.00 1.00 1.00 1.00 1.00 1.00 1.00 1.00 1.00 1.00 1.00 1.00 1.00 1.00 1.00 1.00 1.00 1.00 1.00 1.00 1.00 1.00 1.00 1.00 1.00 1.00 1.00 1.00 1.00 1.00 1.00 1.00 1.00 1.00 1.00 1.00 1.00 1.00 1.00 1.00 1.00 1.00 1.00 1.00 1.00 1.00 1.00 1.00 1.00 1.00 1.00 1.00 1.00 1.00 1.00 1.00 1.00 1.00 1.00 1.00 1.00 1.00 1.00 1.00 1.00 1.00 1.00 1.00 1.00 1.00 1.00 1.00 1.00 1.00 1.00 1.00 1.00 1.00 1.00 1.00 1.00 1.00 1.00 1.00 1.00 1.00 1.00 1.00 1.00 1.00 1.00 1.00 1.00 1.00 1.00 1.00 1.00 1.00 1.00 1.00 1.00 1.00 1.00 1.00 1.00 1.00 1.00 1.00 1.00 1.00 1.00 1.00 1.00 1.00 1.00 1.00 1.00 1.00 1.00 1.00 1.00 1.00 1.00 1.00 1.00 1.00 1.00 1.00 1.00 1.00 1.00 1.00 1.00 1.00 1.00 1.00 1.00 1.00 1.00 1.00 1.00 1.00 1.00 1.00 1.00 1.00 1.00 1.00 1.00 1.00 1.00 1.00 1.00 1.00 1.00 1.00 1.00 1.00 1.00 1.00 1.00 1.00 1.00 1.00 1.00 1.00 1.00 1.00 1.00 1.00 1.00 1.00 1.00 1.00 1.00 1.00 1.00 1.00 1.00 1.00 1.00 1.00 1.00 1.00 1.00 1.00 1.00 1.00 1.00 1.00 1.00 1.00 1.00 1.00 1.00 1.00 1.00 1.00 1.00 1.00 1.00 1.00 1.00 1.00 1.00 1.00 1.00 1.00 1.00 1.00 1.00 1.00 1.00 1.00 1.00 1.00 1.00 1.00 1.00 1.00 1.00 1.00 1.00 1.00 1.00 1.00 1.00 1.00 1.00 1.00 1.00 1.00 1.00 1.00 1.00 1.00 1.00 1.00 1.00 1.00 1.00 1.00 1.00 1.00 1.00 1.00 1.00 1.00 1.00 1.00 1.00 1.00 1.00 1.00 1.00 1.00 1.00 1.00 1.00 1.00 1.00 1.00 1.00 1.00 1.00 1.00 1.00 1.00 1.00 1.00 1.00 1.00 1.00 1.00 1.00 1.00 1.00 1.00 1.00 1.00 1.00 1.00 1.00 1.00 1.00 1.00 1.00 1.00 1.00 1.00 1.00 1.00 1.00 1.00 1.00 1.00 1.00 1.00 1.00 1.00 1.00 1.00 1.00 1.00 1.00 1.00 1.00 1.00 1.00 1.00 1.00 1.00 1.00 1.00 1.00 1.00 1.00 1.00 1.00 1.00 1.00 1.00 1.00 1.00 1.00 1.00 1.00 1.00 1.00 1.00 1.00 1.00 1.00 1.00 1.00 1.00 1.00 1.00 1.00 1.00 1.00 1.00 1.00 1.00 1.00 1.00 1.00 1.00 1.00 1.00 1.00 1.00 1.00 1.00 1.00 1.00 1.00 1.00 1.00 1.00 1.00 1.00 1.00 1.00 1.00 1.00 1.00 1.00 1.00 1.00 1.00 1.00 1.00 1.00 1.00 1.00 1.00 1.00 1.00 1.00 1.00 1.00 1.00 1.00 1.00 1.00 1.00 1.00 1.00 1.00 1.00 1.00 1.00 1.00 1.00 1.00 1.00 1.00 1.00 1.00 1.00 1.00 1.00 1.00 1.00 1.00 1.00 1.00 1.00 1.00 1.00 1.00 1.00 1.00 1.00 1.00 1.00 1.00 1.00 1.00 1.00 1.00 1.00 1.00 1.00 1.00 1.00 1.00 1.00 1.00 1.00 1.00 1.00 1.00 1.00 1.00 1.00 1.00 1.00 1.00 1.00 1.00 1.00 1.00 1.00 1.00 1.00 1.00 1.00 1.00 1.00 1.00 1.00 1.00 1.00 1.00 1.00 1.00 1.00 1.00 1.00 1.00 1.00 1.00 1.00 1.00 1.00 1.00 1.00 1.00 1.00 1.00 1.00 1.00 1.00 1.00 1.00 1.00 1.00 1.00 1.00 1.00 1.00 1.00 1.00 1.00 1.00 1.00 1.00 1.00 1.00 1.00 1.00 1.00 1.00 1.00 1.00 1.00 1.00 1.00 1.00 1.00 1.00 1.00 1.00 1.00 1.00 1.00 1.00 1.00 1.00 1.00 1.00 1.00 1.00 1.00 1.00 1.00 1.00 1.00 1.00 1.00 1.00 1.00 1.00 1.00 1.00 1.00 1.00 1.00 1.00 1.00 1.00 1.00 1.00 1.00 1.00 1.00 1.00 1.00 1.00 1.00 1.00 1.00 1.00 1.00 1.00 1.00 1.00 1.00 1.00 1.00 1.00 1.00 1.00 1.00 1.00 1.00 1.00 1.00 1.00 1.00 1.00 1.00 1.00 1.00 1.00 1.00 1.00 1.00 1.00 1.00 1.00 1.00 1.00 1.00 1.00 1.00 1.00 1.00 1.00 1.00 1.00 1.00 1.00 1.00 1.00 1.00 1.00 1.00 1.00 1.00 1.00 1.00 1.00 1.00 1.00 1.00 1.00 1.00 1.00 1.00 1.00 1.00 1.00 1.00 1.00 1.00 1.00 1.00 1.00 1.00 1.00 1.00 1.00 1.00 1.00 1.00 1.00 1.00 1.00 1.00 1.00 1.00 1.00 1.00 1.00 1.00 1.00 1.00 1.00 1.00 1.00 1.00 1.00 1.00 1.00 1.00 1.00 1.00 1.00 1.00 1.00 1.00 1.00 1.00 1.00 1.00 1.00 1.00 1.00 1.00 1.00 1.00 1.00 1.00 1.00 1.00 1.00 1.00 1.00 1.00 1.00 1.00 1.00 1.00 1.00 1.00 1.00 1.00 1.00 1.00 1.00 1.00 1.00 1.00 1.00 1.00 1.00 1.00 1.00 1.00 1.00 1.00 1.00 1.00 1.00 1.00 1.00 1.00 1.00 1.00 1.00 1.00 1.00 1.00 1.00 1.00 1.00 1.00 1.00 1.00 1.00 1.00 1.00 1.00 1.00 1.00 1.00 1.00 1.00 1.00 1.00 1.00 1.00 1.00 1.00 1.00 1.00 1.00 1.00 1.00 1.00 1.00 1.00 1.00 1.00 1.00 1.00 1.00 1.00 1.00 1.00 1.00 1.00 1.00 1.00 1.00 1.00 1.00 1.00 1.00 1.00 1.00 1.00 1.00 1.00 1.00 1.00 1.00 1.00 1.00 1.00 1.00 1.00 1.00 1.00 1.00 1.00 1.00 1.00 1.00 1.00 1.00 1.00 1.00 1.00 1.00 1.00 1.00 1.00 1.00 1.00 1.00 1.00 1.00 1.00 1.00 1.00 1.00 1.00 1.00 1.00 1.00 1.00 1.00 1.00 1.00 1.00 1.00 1.00 1.00 1.00 1.00 1.00 1.00 1.00 1.00 1.00 1.00 1.00 1.00 1.00 1.00 1.00 1.00 1.00 1.00 1.00 1.00 1.00 1.00 1.00 1.00 1.00 1.00 1.00 1.00 1.00 1.00 1.00 1.00 1.00 1.00 1.00 1.00 1.00 1.00 1.00 1.00 1.00 1.00 1.00 1.00 1.00 1.00 1.00 1.00 1.00 1.00 1.00 1.00 1.00 1.00 1.00 1.00 1.00 1.00 1.00 1.00 1.00 1.00 1.00 1.00 1.00 1.00 1.00 1.00 1.00 1.00 1.00 1.00 1.00 1.00 1.00 1.00 1.00 1.00 1.00 1.00 1.00 1.00 1.00 1.00 1.00 1.00 1.00 1.00 1.00 1.00 1.00 1.00 1.00 1.00 1.00 1.00 1.00 1.00 1.00 1.00 1.00 1.00 1.00 1.00 1.00 1.00 1.00 1.00 1.00 1.00 1.00 1.00 1.00 1.00 1.00 1.00 1.00 1.00 1.00 1.00 1.00 1.00 1.00 1.00 1.00 1.00 1.00 1.00 1.00 1.00 1.00 1.00 1.00 1.00 1.00 1.00 1.00 1.00 1.00 1.00 1.00 1.00 1.00 1.00 1.00 1.00 1.00 1.00 1.00 1.00 1.00 1.00 1.00 1.00 1.00 1.00 1.00 1.00 1.00 1.00 1.00 1.00 1.00 1.00 1.00 1.00 1.00 1.00 1.00 1.00 1.00 1.00 1.00 1.00 1.00 1.00 1.00 1.00 1.00 1.00 1.00 1.00 1.00 1.00 1.00 1.00 1.00 1.00 1.00 1.00 1.00 1.00 1.00 1.00 1.00 1.00 1.00 1.00 1.00 1.00 1.00 1.00 1.00 1.00 1.00 1.00 1.00 1.00 1.00 1.00 1.00 1.00 1.00 1.00 1.00 1.00 1.00 1.00 1.00 1.00 1.00 1.00 1.00 1.00 1.00 1.00 1.00 1.00 1.00 1.00 1.00 1.00 1.00 1.00 1.00 1.00 1.00 1.00 1.00 1.00 1.00 1.00 1.00 1.00 1.00 1.00 1.00 1.00 1.00 1.00 1.00 1.00 1.00 1.00 1.00 1.00 1.00 1.00 1.00 1.00 1.00 1.00 1.00 1.00 1.00 1.00 1.00 1.00 1.00 1.00 1.00 1.00 1.00 1.00 1.00 1.00 1.00 1.00 1.00 1.00 1.00 1.00 1.00 1.00 1.00 1.00 1.00 1.00 1.00 1.00 1.00 1.00 1.00 1.00 1.00 1.00 1.00 1.00 1.00 1.00 1.00 1.00 1.00 1.00 1.00 1.00 1.00 1.00 1.00 1.00 1.00 1.00 1.00 1.00 1.00 1.00 1.00 1.00 1.00 1.00 1.00 1.00 1.00 1.00 1.00 1.00 1.00 1.00 1.00 1.00 1.00 1.00 1.00 1.00 1.00 1.00 1.00 1.00 1.00 1.00 1.00 1.00 1.00 1.00 1.00 1.00 1.00 1.00 1.00 1.00 1.00 1.00 1.00 1.00 1.00 1.00 1.00 1.00 1.00 1.00 1.00 1.00 1.00 1.00 1.00 1.00 1.00 1.00 1.00 1.00 1.00 1.00 1.00 1.00 1.00 1.00 1.00 1.00 1.00 1.00 1.00 1.00 1.00 1.00 1.00 1.00 1.00 1.00 1.00 1.00 1.00 1.00 1.00 1.00 1.00 1.00 1.00 1.00 1.00 1.00 1.00 1.00 1.00 1.00 1.00 1.00 1.00 1.00 1.00 1.00 1.00 1.00 1.00 1.00 1.00 1.00 1.00 1.00 1.00 1.00 1.00 1.00 1.00 1.00 1.00 1.00 1.00 1.00 1.00 1.00 1.00 1.00 1.00 1.00 1.00 1.00 1.00 1.00 1.00 1.00 1.00 1.00 1.00 1.00 1.00 1.00 1.00 1.00 1.00 1.00 1.00 1.00 1.00 1.00 1.00 1.00 1.00 1.00 1.00 1.00 1.00 1.00 1.00 1.00 1.00 1.00 1.00 1.00 1.00 1.00 1.00 1.00 1.00 1.00 1.00 1.00 1.00 1.00 1.00 1.00 1.00 1.00 1.00 1.00 1.00 1.00 1.00 1.00 1.00 1.00 1.00 1.00 1.00 1.00 1.00 1.00 1.00 1.00 1.00 1.00 1.00 1.00 1.00 1.00 1.00 1.00 1.00 1.00 1.00 1.00 1.00 1.00 1.00 1.00 1.00 1.00 1.00 1.00 1.00 1.00 1.00 1.00 1.00 1.00 1.00 1.00 1.00 1.00 1.00 1.00 1.00 1.00 1.00 1.00 1.00 1.00 1.00 1.00 1.00 1.00 1.00 1.00 1.00 1.00 1.00 1.00 1.00 1.00 1.00 1.00 1.00 1.00 1.00 1.00 1.00 1.00 1.00 1.00 1.00 1.00 1.00 1.00 1.00 1.00 1.00 1.00 1.00 1.00 1.00 1.00 1.00 1.00 1.00 1.00 1.00 1.00 1.00 1.00 1.00 1.00 1.00 1.00 1.00 1.00 1.00 1.00 1.00 1.00 1.00 1.00 1.00 1.00 1.00 1.00 1.00 1.00 1.00 1.00 1.00 1.00 1.00 1.00 1.00 1.00 1.00 1.00 1.00 1.00 1.00 1.00 1.00 1.00 1.00 1.00 1.00 1.00 1.00 1.00 1.00 1.00 1.00 1.00 1.00 1.00 1.00 1.00 1.00 1.00 1.00 1.00 1.00 1.00 1.00 1.00 1.00 1.00 1.00 1.00 1.00 1.00 1.00 1.00 1.00 1.00 1.00 1.00 1.00 1.00 1.00 1.00 1.00 1.00 1.00 1.00 1.00 1.00 1.00 1.00 1.00 1.00 1.00 1.00 1.00 1.00 1.00 1.00 1.00 1.00 1.00 1.00 1.00 1.00 1.00 1.00 1.00 1.00 1.00 1.00 1.00 1.00 1.00 1.00 1.00 1.00 1.00 1.00 1.00 1.00 1.00 1.00 1.00 1.00 1.00 1.00 1.00 1.00 1.00 1.00 1.00 1.00 1.00 1.00 1.00 1.00 1.00 1.00 1.00 1.00 1.00 1.00 1.00 1.00 1.00 1.00 1.00 1.00 1.00 1.00 1.00 1.00 1.00 1.00 1.00 1.00 1.00 1.00 1.00 1.00 1.00 1.00 1.00 1.00 1.00 1.00 1.00 1.00 1.00 1.00 1.00 1.00 1.00 1.00 1.00 1.00 1.00 1.00 1.00 1.00 1.00 1.00 1.00 1.00 1.00 1.00 1.00 1.00 1.00 1.00 1.00 1.00 1.00 1.00 1.00 1.00 1.00 1.00 1.00 1.00 1.00 1.00 1.00 1.00 1.00 1.00 1.00 1.00 1.00 1.00 1.00 1.00 1.00 1.00 1.00 1.00 1.00 1.00 1.00 1.00 1.00 1.00 1.00 1.00 1.00 1.00 1.00 1.00 1.00 1.00 172.00 172.00 172.00 172.00 172.00 172.00 172.00 1.00 1.00 1.00 1.00 1.00 1.00 1.00 1.00 1.00 1.00 1.00 1.00 1.00 1.00 1.00 1.00 1.00 1.00 1.00 1.00 1.00 1.00 1.00 1.00 1.00 1.00 1.00 1.00 1.00 1.00 1.00 1.00 1.00 1.00 1.00 1.00 1.00 1.00 1.00 1.00 1.00 1.00 1.00 1.00 1.00 1.00 1.00 1.00 1.00 1.00 1.00 1.00 1.00 1.00 1.00 1.00 1.00 1.00 1.00 1.00 1.00 1.00 1.00 1.00 1.00 1.00 1.00 1.00 1.00 1.00 1.00 1.00 1.00 1.00 1.00 1.00 1.00 1.00 1.00 1.00 1.00 1.00 1.00 1.00 1.00 1.00 1.00 1.00 1.00 1.00 1.00 1.00 1.00 1.00 1.00 1.00 1.00 1.00 1.00 1.00 1.00 1.00 1.00 1.00 1.00 1.00 1.00 1.00 1.00 1.00 1.00 1.00 1.00 1.00 1.00 1.00 1.00 1.00 1.00 1.00 1.00 1.00 1.00 1.00 1.00 1.00 1.00 1.00 1.00 1.00 1.00 1.00 1.00 1.00 1.00 1.00 1.00 1.00 1.00 1.00 1.00 1.00 1.00 1.00 1.00 1.00 1.00 1.00 1.00 1.00 1.00 1.00 1.00 1.00 1.00 1.00 1.00 1.00 1.00 1.00 1.00 1.00 1.00 1.00 1.00 1.00 1.00 1.00 1.00 1.00 1.00 1.00 1.00 1.00 1.00 1.00 1.00 1.00 1.00 1.00 1.00 1.00 1.00 1.00 1.00 1.00 1.00 1.00 1.00 1.00 1.00 1.00 1.00 1.00 1.00 1.00 1.00 1.00 1.00 1.00 1.00 1.00 1.00 1.00 1.00 1.00 1.00 1.00 1.00 1.00 1.00 1.00 1.00 1.00 1.00 1.00 1.00 1.00 1.00 1.00 1.00 1.00 1.00 1.00 1.00 1.00 1.00 1.00 1.00 1.00 1.00 1.00 1.00 1.00 1.00 1.00 1.00 1.00 1.00 1.00 1.00 1.00 1.00 1.00 1.00 1.00 1.00 1.00 1.00 1.00 1.00 1.00 1.00 1.00 1.00 1.00 1.00 1.00 1.00 1.00 1.00 1.00 1.00 1.00 1.00 1.00 1.00 1.00 1.00 1.00 1.00 1.00 1.00 1.00 1.00 1.00 1.00 1.00 1.00 1.00 1.00 1.00 1.00 1.00 1.00 1.00 1.00 1.00 1.00 1.00 1.00 1.00 1.00 1.00 1.00 1.00 1.00 1.00 1.00 1.00 1.00 1.00 1.00 1.00 1.00 1.00 1.00 1.00 1.00 1.00 1.00 1.00 1.00 1.00 1.00 1.00 1.00 1.00 1.00 1.00 1.00 1.00 1.00 1.00 1.00 1.00 1.00 1.00 1.00 1.00 1.00 1.00 1.00 1.00 1.00 1.00 1.00 1.00 1.00 1.00 1.00 1.00 1.00 1.00 1.00 1.00 1.00 1.00 1.00</beamAttenuationFactors>
				<commonCountingTime unit="seconds">0.352</commonCountingTime>
				<counts unit="counts">39 38 33 39 37 33 29 44 43 32 42 28 27 32 30 27 36 38 28 33 35 34 39 32 34 25 30 35 31 40 32 46 27 32 32 42 26 38 53 28 32 27 37 33 35 49 32 38 30 35 43 40 25 42 31 38 36 34 35 34 34 26 28 43 35 41 45 20 33 33 30 22 31 38 34 30 28 33 23 35 43 33 28 34 45 40 36 26 36 45 34 30 29 26 29 34 40 35 39 26 27 37 39 42 37 34 48 43 39 40 42 40 34 24 36 38 32 31 35 26 25 46 44 16 23 40 40 31 35 32 46 30 26 46 38 33 38 40 44 47 32 39 34 43 44 44 33 25 30 35 35 20 38 39 25 39 31 28 37 37 25 47 38 37 40 35 37 42 60 55 56 45 45 48 50 38 52 54 36 41 29 22 42 39 40 40 32 24 37 49 50 46 52 62 75 61 66 76 75 84 62 83 79 68 83 76 83 48 71 65 52 46 45 41 32 41 47 55 68 76 88 120 132 204 201 231 312 290 416 444 458 618 614 610 746 612 809 869 830 984 908 946 931 892 1043 814 941 1010 763 927 677 779 778 525 603 531 379 406 374 285 268 247 200 167 225 538 4324 9458 12450 13272 18027 33960 58100 116307 98310 66384 64559 29659 16902 919 354 372 305 240 274 252 228 239 240 159 180 178 165 153 131 114 121 72 82 91 57 52 52 36 51 40 48 45 32 50 37 46 49 48 41 65 71 56 68 70 86 62 81 61 64 48 65 48 43 44 31 33 44 28 40 27 32 27 36 36 38 39 50 50 40 39 49 46 68 61 51 45 47 36 41 41 46 45 35 27 37 40 39 28 21 14 30 31 32 23 30 42 37 31 27 36 37 27 41 42 38 35 39 47 34 41 37 33 33 39 39 33 35 31 17 27 12 27 24 28 25 33 24 30 29 37 17 32 31 31 32 32 33 41 37 43 26 47 25 30 31 18 25 25 36 24 23 22 34 22 41 19 28 34 27 28 30 31 26 28 31 32 35 35 38 24 23 27 31 31 38 29 31 27 30 30 34 22 26 27 29 23 29 17 30 21 23 25 32 22 26 27 26 18 32 32 27 25 24 25 27 15 33 31 26 25 19 28 20 24 21 21 27 24 27 26 25 22 18 22 27 26 19 28 17 37 26 29 32 36 25 21 18 28 22 20 34 24 28 15 10 16 23 25 25 25 25 19 15 23 20 17 25 25 35 24 26 28 27 28 19 35 18 22 26 22 24 25 23 23 16 30 16 23 22 22 26 24 18 13 32 35 19 19 28 27 32 26 24 23 29 24 24 25 17 18 14 24 16 20 12 16 23 18 22 22 22 20 25 21 21 34 22 25 19 24 18 25 18 30 18 21 16 19 22 30 17 16 26 18 30 15 17 23 26 25 20 15 22 35 17 21 28 28 31 19 16 29 31 26 25 24 21 20 25 18 24 17 15 16 20 21 22 18 20 31 24 21 18 15 15 24 19 18 18 14 24 18 20 20 16 20 18 28 21 22 23 18 27 26 18 14 22 13 18 18 14 24 12 19 21 18 25 19 24 18 26 33 21 19 20 13 20 32 14 17 16 21 15 24 24 12 25 20 19 19 25 14 24 17 12 21 24 20 22 27 27 16 25 27 21 27 12 19 14 20 17 24 19 27 16 22 17 19 20 13 26 25 22 20 10 25 19 15 17 28 25 19 18 17 19 18 22 21 26 21 26 13 19 22 15 29 14 19 15 18 13 22 21 22 13 21 16 18 20 23 24 23 17 27 15 20 19 15 20 19 22 22 13 18 14 20 15 20 19 16 24 14 15 14 15 18 20 20 24 27 14 19 19 16 18 16 18 20 15 19 19 22 24 14 29 18 26 20 26 19 31 30 21 24 18 20 20 23 18 19 19 22 22 25 26 16 19 21 20 28 19 19 12 17 20 21 22 18 20 18 20 21 12 19 16 21 17 19 12 13 10 23 16 20 13 21 17 15 17 18 16 17 17 19 22 23 14 18 18 17 15 18 13 19 17 19 15 17 13 15 15 11 14 18 19 10 18 15 10 13 18 11 17 15 27 20 11 9 10 21 21 15 19 16 21 17 21 13 12 22 14 14 12 22 14 12 20 19 18 20 16 20 13 20 15 19 22 17 15 11 17 13 17 12 12 24 20 10 19 16 13 15 12 15 19 22 14 15 21 21 23 13 12 18 14 13 17 12 14 15 20 13 18 17 14 19 18 19 22 13 17 21 13 15 15 20 11 21 14 15 14 14 11 15 10 12 13 9 15 13 18 13 13 19 12 11 14 11 13 15 15 15 10 16 13 15 12 10 16 10 15 22 19 14 13 18 20 19 20 16 22 16 22 14 15 20 20 20 17 14 13 7 19 13 17 15 14 20 19 15 20 25 21 11 11 16 12 26 21 14 20 15 16 15 18 8 24 20 9 12 12 15 11 12 13 10 17 21 14 17 13 12 22 14 17 11 17 15 17 16 19 16 10 11 12 12 15 16 10 6 15 17 14 18 17 13 15 13 15 18 11 13 14 9 12 13 13 11 14 12 10 17 17 9 11 13 13 16 17 21 13 13 12 12 11 9 12 12 8 19 12 14 17 10 17 11 15 14 20 10 13 16 14 9 18 19 8 12 9 13 13 9 16 7 9 11 16 10 19 14 14 14 12 16 9 11 10 13 22 19 12 14 19 17 13 19 6 10 10 17 19 7 14 10 12 19 15 13 12 12 14 19 17 10 19 14 10 11 11 13 8 12 15 16 12 6 16 13 16 18 12 12 6 15 5 17 12 20 12 11 17 13 8 10 12 17 16 15 10 17 10 9 13 12 19 12 11 10 25 9 9 16 7 19 15 12 14 23 9 5 9 16 9 16 18 18 17 7 16 13 13 10 15 23 9 11 18 18 5 11 4 11 7 12 9 12 11 11 14 12 14 14 17 12 13 15 16 11 11 6 12 7 11 11 15 17 11 12 16 14 15 13 8 10 12 14 14 8 14 15 17 8 6 8 16 20 6 11 12 16 13 14 12 11 14 3 11 8 14 7 12 9 14 16 17 16 16 11 17 11 12 9 12 15 15 13 14 16 6 7 12 12 10 16 16 11 7 11 18 11 12 19 15 9 12 9 9 10 7 9 14 16 18 9 12 12 13 19 11 17 13 9 14 10 13 9 13 9 7 15 14 11 15 6 14 9 15 8 11 10 12 7 9 14 14 13 15 9 12 15 11 11 19 12 17 17 16 9 13 6 14 11 13 15 13 15 10 8 10 11 16 12 16 7 8 11 7 10 12 13 11 8 12 5 8 8 9 14 14 12 19 10 12 11 13 8 13 9 8 11 11 17 14 8 12 12 13 17 8 3 7 11 10 14 16 9 6 9 13 12 7 9 12 14 16 13 8 8 9 11 9 7 8 10 16 12 13 17 7 10 20 7 12 10 10 11 8 8 16 5 13 12 9 10 8 12 10 16 16 8 8 13 11 12 17 9 9 13 12 11 13 13 13 13 11 10 6 18 10 11 11 8 13 17 11 7 6 18 6 16 5 9 7 5 13 8 13 8 10 10 7 19 13 9 15 11 9 12 10 9 11 7 9 10 16 16 13 4 9 6 10 15 9 5 14 8 13 8 16 16 12 13 10 17 10 12 10 8 17 19 10 16 15 11 13 14 11 10 12 12 13 10 15 13 7 11 11 11 17 7 8 8 8 13 10 13 6 6 15 9 6 8 11 7 9 11 10 9 7 10 18 6 6 7 9 11 11 11 9 12 0 11 8 13 13 9 8 11 3 8 14 8 8 17 13 7 13 17 10 16 7 9 10 15 11 14 13 11 11 11 4 11 8 10 11 10 7 7 6 12 8 11 10 18 9 16 8 9 14 9 7 12 7 9 8 9 9 7 9 9 12 9 11 13 19 18 8 13 8 9 10 15 6 20 9 12 5 7 10 16 9 9 11 11 10 7 11 13 16 12 16 11 10 8 15 11 19 11 12 12 16 8 10 8 10 8 14 13 11 10 12 8 18 11 7 9 9 9 10 9 8 14 12 8 9 13 10 6 10 13 9 13 6 14 6 12 10 4 11 4 9 11 6 7 7 10 10 9 7 11 18 13 5 8 6 7 14 5 8 12 12 13 7 16 14 15 17 10 9 10 7 9 3 7 9 5 14 9 6 10 8 9 10 9 10 12 11 10 11 11 13 11 13 18 9 7 8 9 10 11 4 13 13 13 3 7 16 12 9 10 12 8 5 11 11 14 15 8 11 14 17 8 10 15 9 10 12 5 11 8 14 9 9 11 12 10 21 9 12 12 7 15 11 9 12 16 9 8 13 10 5 9 4 7 10 6 9 8 12 10 17 12 11 12 5 16 10 11 10 8 6 11 11 3 7 8 10 9 12 4 13 14 11 11 9 11 6 14 10 10 12 10 11 8 7 9 15 10 12 9 12 13 13 10 7 13 13 8 7 9 13 10 12 13 8 11 15 7 9 7 11 13 13 11 12 8 10 10 12 6 9 7 11 7 13 12 9 9 12 11 10 7 15 9 9 16 11 14 10 12 9 13 12 12 10 22 6 8 14 6 6 8 9 10 14 5 8 6 8 12 6 12 8 13 13 9 12 16 12 7 5 6 9 10 10 12 14 11 12 10 8 10 9 11 12 10 6 11 12 10 6 10 6 9 3 14 5 11 5 9 15 7 8 12 14 16 9 10 11 8 13 13 12 9 13 12 3 9 6 7 5 10 13 10 10 12 11 13 9 18 15 11 10 7 13 15 11 11 8 8 14 10 15 9 12 11 13 13 10 8 15 12 13 7 4 4 11 9 7 13 8 5 10 17 10 9 11 11 13 14 4 20 16 5 7 11 7 10 12 8 13 11 10 6 12 13 15 11 11 7 9 9 16 7 7 14 10 6 12 17 10 9 13 12 16 8 8 7 6 13 7 7 10 11 12 13 14 10 9 8 6 11 8 11 4 10 12 7 17 8 6 9 9 4 11 11 8 10 13 13 9 10 9 12 7 14 8 16 7 15 13 16 8 12 9 11 12 12 14 12 9 11 10 12 12 18 13 15 11 19 6 10 17 13 11 17 16 11 9 18 5 12 9 17 7 7 11 11 11 12 11 11 14 11 6 12 15 10 13 12 15 12 12 8 12 12 5 10 15 15 7 8 11 9 16 11 12 7 22 15 9 10 8 16 12 12 7 14 15 14 6 13 11 18 18 15 16 20 10 13 13 13 15 7 9 10 10 15 12 9 17 12 14 15 9 14 18 15 14 17 12 18 15 18 14 15 18 12 26 19 14 24 16 11 11 17 21 14 12 19 9 10 14 18 10 21 18 9 11 20 19 19 15 16 23 18 16 19 23 18 23 27 25 20 18 24 20 15 15 18 17 15 13 13 13 7 8 15 14 16 17 19 13 21 25 24 18 28 21 23 30 30 15 24 16 26 23 26 27 26 28 17 19 19 14 19 15 10 15 12 21 16 10 15 21 21 30 28 28 25 31 36 42 30 27 32 43 46 22 35 29 24 33 34 24 23 20 20 17 12 20 10 15 18 16 15 18 32 35 46 37 40 30 50 60 59 53 59 65 69 48 50 54 33 39 49 26 45 23 35 16 18 12 25 22 24 20 24 52 44 59 66 67 82 98 88 93 98 116 114 102 123 99 124 105 88 99 91 60 70 46 46 33 38 37 41 38 33 46 66 63 110 110 123 161 195 227 231 238 282 296 320 317 339 307 342 327 317 284 255 256 181 166 148 122 94 105 115 125 146 202 260 393 507 674 892 1067 1306 1524 1983 2363 2715 2969 3457 3941 4361 4998 5256 5705 6366 6837 7290 7688 7811 8573 8726 9331 9434 9955 9858 9693 10003 9970 9985 9771 9649 9376 9095 8849 8151 7881 7643 7129 6619 6249 5573 4949 4460 4011 3528 2994 2565 2136 1896 1540 1243 957 810 569 487 435 393 425 489 565 693 783 930 1079 1229 1535 1788 2048 2454 3223 4482 8984 19867 34622 50022 68415 91625 102468 85400 62384 53599 62480 98784 2488 6354 7755 6732 6105 3909 1055 47414 15526 7603 4354 2925 2166 1535 1101 862 637 530 368 275 226 204 131 124 120 110 103 107 107 116 114 129 130 132 150 151 123 153 136 127 121 98 82 85 92 69 77 49 39 36 28 21 15 25 9 15 22 21 10 30 23 25 37 23 36 37 37 40 51 45 46 40 28 40 39 36 26 26 35 19 18 19 16 15 11 12 12 10 8 11 12 9 17 11 19 10 20 9 27 16 16 10 23 19 16 27 19 18 20 13 21 21 18 9 14 8 9 10 24 10 9 9 7 14 15 9 16 15 15 12 17 10 13 10 21 15 17 16 14 12 17 14 16 9 12 14 11 13 7 8 10 9 8 11 8 8 6 5 6 9 11 10 12 9 12 13 13 13 12 13 14 14 8 10 10 6 8 5 8 6 7 10 9 6 3 7 7 13 13 11 8 4 7 8 13 9 5 9 11 13 8 9 7 15 7 4 10 9 9 10 7 6 11 4 10 10 7 9 13 14 5 9 4 17 7 12 15 7 7 11 7 7 5 15 13 11 8 7 5 8 13 5 19 10 7 14 9 7 12 13 9 5 4 8 5 8 7 7 11 8 7 10 10 7 5 5 4 9 6 11 10 7 8 3 9 7 10 9 8 4 9 11 3 11 9 3 9 9 9 14 6 6 4 8 8 12 6 9 5 6 13 4 14 6 6 10 10 10 12 11 11 8 5 6 8 11 4 11 7 6 8 10 3 14 8 9 6 5 7 8 11 14 6 6 5 4 6 10 4 7 4 8 4 9 1 6 8 7 6 11 8 11 5 6 6 7</counts>
			</dataPoints>
		</scan>
	</xrdMeasurement>
</xrdMeasurements>