File: data/previous_data/set_3-YG035-038/xrd/YG036-SRO001-STO001-06162022.xrdml
<xrdMeasurements xmlns="http://www.xrdml.com/XRDMeasurement/2.1" xmlns:xsi="http://www.w3.org/2001/XMLSchema-instance" xsi:schemaLocation="http://www.xrdml.com/XRDMeasurement/2.1 http://www.xrdml.com/XRDMeasurement/2.1/XRDMeasurement.xsd" status="Completed">
	<comment>
		<entry>Configuration=Main Configuration, Owner=User-1, Creation date=6/17/2015 3:36:16 PM</entry>
		<entry>Goniometer=HR HD (Theta/2Theta); Minimum step size 2Theta:0.0001; Minimum step size Omega:0.0001</entry>
		<entry>Sample stage=MRD Cradle; Minimum step size Phi:0.01; Minimum step size Chi:0.01; Minimum step size X:0.01; Minimum step size Y:0.01; Minimum step size Z:0.001</entry>
		<entry>Diffractometer system=XPERT-3</entry>
		<entry>Measurement program=C:\PANalytical\Data Collector\Programs\Yichen\regular_2theta_20-50_0.4s-20min.xrdmp, Identifier={AEA8F2F2-8BFA-4B07-A521-A571AF38E73A}</entry>
	</comment>
	<sample type="To be analyzed">
		<id></id>
		<name></name>
		<preparedBy></preparedBy>
	</sample>
	<xrdMeasurement measurementType="Scan" status="Completed" sampleMode="Reflection">
		<comment>
			<entry>PHD Lower Level = 4.02 (keV), PHD Upper Level = 11.27 (keV)</entry>
		</comment>
		<usedWavelength intended="K-Alpha 1">
			<kAlpha1 unit="Angstrom">1.5405980</kAlpha1>
			<kAlpha2 unit="Angstrom">1.5444260</kAlpha2>
			<kBeta unit="Angstrom">1.3922500</kBeta>
			<ratioKAlpha2KAlpha1>0.5000</ratioKAlpha2KAlpha1>
		</usedWavelength>
		<incidentBeamPath>
			<radius unit="mm">320.00</radius>
			<xRayTube id="1010048" name="Empyrean Cu LFF HR (9430 033 7310x) DK425175">
				<tension unit="kV">45.0</tension>
				<current unit="mA">40.0</current>
				<anodeMaterial>Cu</anodeMaterial>
				<focus type="Line">
					<length unit="mm">12.0</length>
					<width unit="mm">0.4</width>
					<takeOffAngle unit="deg">4.2</takeOffAngle>
				</focus>
			</xRayTube>
			<xRayMirror id="27090001" name="Inc. Beam Cu W/Si (hybrid MRD)" hybrid="true">
				<crystal type="Graded" shape="Parabolic">W/Si</crystal>
				<acceptanceAngle unit="deg">0.800</acceptanceAngle>
				<length unit="mm">60.0</length>
			</xRayMirror>
			<monochromator id="23090002" name="Hybrid monochr. 2xGe(220) Cu asym." hybrid="true">
				<crystal type="Asymmetric" shape="Flat">Ge</crystal>
				<numberOfReflections>2</numberOfReflections>
				<hkl>
					<h>2</h>
					<k>2</k>
					<l>0</l>
				</hkl>
			</monochromator>
			<divergenceSlit id="22010004" name="Fixed slit 1/2°" xsi:type="fixedDivergenceSlitType">
				<distanceToSample unit="mm">220.00</distanceToSample>
				<height unit="mm">0.76</height>
			</divergenceSlit>
			<beamAttenuator id="26010001" name="Progr. beam attenuator Ni 0.125 mm" xsi:type="intensitySwitchedBeamAttenuatorType">
				<factor>172.00</factor>
				<material>Ni</material>
				<activateLevel unit="counts per second">500000</activateLevel>
				<deactivateLevel unit="counts per second">400000</deactivateLevel>
			</beamAttenuator>
		</incidentBeamPath>
		<diffractedBeamPath>
			<radius unit="mm">320.00</radius>
			<antiScatterSlit id="22090009" name="AS slit 7.5 mm (PIXcel)" xsi:type="fixedAntiScatterSlitType">
				<height unit="mm">7.50</height>
			</antiScatterSlit>
			<sollerSlit id="21010002" name="Soller slits 0.04 rad.">
				<opening unit="rad">0.0400</opening>
			</sollerSlit>
			<receivingSlit id="22010004" name="Fixed slit 1/2°">
				<height unit="mm">0.76</height>
			</receivingSlit>
			<detector id="7010020" name="PIXcel3D-Medipix3 1x1 detector" xsi:type="areaDetectorType">
				<phd unit="%">
					<lowerLevel>25.0</lowerLevel>
					<upperLevel>70.0</upperLevel>
				</phd>
				<mode>Receiving slit</mode>
				<activeChannelsEquatorial>5</activeChannelsEquatorial>
				<activeChannelsAxial>255</activeChannelsAxial>
				<pitchEquatorial unit="mm">0.05500</pitchEquatorial>
				<pitchAxial unit="mm">0.05500</pitchAxial>
				<readOutPeriod unit="seconds">0.050</readOutPeriod>
			</detector>
		</diffractedBeamPath>
		<scan appendNumber="0" mode="Continuous" scanAxis="2Theta-Omega" status="Completed">
			<header>
				<startTimeStamp>2022-06-16T15:15:30-07:00</startTimeStamp>
				<endTimeStamp>2022-06-16T15:35:56-07:00</endTimeStamp>
				<author>
					<name>XRD</name>
				</author>
				<source>
					<applicationSoftware version="6.1b">Data Collector</applicationSoftware>
					<instrumentControlSoftware version="7.4b 20181204">XPERT-3</instrumentControlSoftware>
					<instrumentID>0000000011163216</instrumentID>
				</source>
			</header>
			<dataPoints>
				<positions axis="2Theta" unit="deg">
					<startPosition>20.0050</startPosition>
					<endPosition>49.9950</endPosition>
				</positions>
				<positions axis="Omega" unit="deg">
					<startPosition>10.3418</startPosition>
					<endPosition>25.3368</endPosition>
				</positions>
				<positions axis="Phi" unit="deg">
					<commonPosition>0.00</commonPosition>
				</positions>
				<positions axis="Chi" unit="deg">
					<commonPosition>-0.11</commonPosition>
				</positions>
				<positions axis="X" unit="mm">
					<commonPosition>-0.32</commonPosition>
				</positions>
				<positions axis="Y" unit="mm">
					<commonPosition>0.00</commonPosition>
				</positions>
				<positions axis="Z" unit="mm">
					<commonPosition>8.821</commonPosition>
				</positions>
				<beamAttenuationFactors>1.00 1.00 1.00 1.00 1.00 1.00 1.00 1.00 1.00 1.00 1.00 1.00 1.00 1.00 1.00 1.00 1.00 1.00 1.00 1.00 1.00 1.00 1.00 1.00 1.00 1.00 1.00 1.00 1.00 1.00 1.00 1.00 1.00 1.00 1.00 1.00 1.00 1.00 1.00 1.00 1.00 1.00 1.00 1.00 1.00 1.00 1.00 1.00 1.00 1.00 1.00 1.00 1.00 1.00 1.00 1.00 1.00 1.00 1.00 1.00 1.00 1.00 1.00 1.00 1.00 1.00 1.00 1.00 1.00 1.00 1.00 1.00 1.00 1.00 1.00 1.00 1.00 1.00 1.00 1.00 1.00 1.00 1.00 1.00 1.00 1.00 1.00 1.00 1.00 1.00 1.00 1.00 1.00 1.00 1.00 1.00 1.00 1.00 1.00 1.00 1.00 1.00 1.00 1.00 1.00 1.00 1.00 1.00 1.00 1.00 1.00 1.00 1.00 1.00 1.00 1.00 1.00 1.00 1.00 1.00 1.00 1.00 1.00 1.00 1.00 1.00 1.00 1.00 1.00 1.00 1.00 1.00 1.00 1.00 1.00 1.00 1.00 1.00 1.00 1.00 1.00 1.00 1.00 1.00 1.00 1.00 1.00 1.00 1.00 1.00 1.00 1.00 1.00 1.00 1.00 1.00 1.00 1.00 1.00 1.00 1.00 1.00 1.00 1.00 1.00 1.00 1.00 1.00 1.00 1.00 1.00 1.00 1.00 1.00 1.00 1.00 1.00 1.00 1.00 1.00 1.00 1.00 1.00 1.00 1.00 1.00 1.00 1.00 1.00 1.00 1.00 1.00 1.00 1.00 1.00 1.00 1.00 1.00 1.00 1.00 1.00 1.00 1.00 1.00 1.00 1.00 1.00 1.00 1.00 1.00 1.00 1.00 1.00 1.00 1.00 1.00 1.00 1.00 1.00 1.00 1.00 1.00 1.00 1.00 1.00 1.00 1.00 1.00 1.00 1.00 1.00 1.00 1.00 1.00 1.00 1.00 1.00 1.00 1.00 1.00 1.00 1.00 1.00 1.00 1.00 1.00 1.00 1.00 1.00 1.00 1.00 1.00 1.00 1.00 1.00 1.00 1.00 1.00 1.00 1.00 1.00 1.00 1.00 1.00 1.00 1.00 1.00 1.00 1.00 1.00 1.00 1.00 1.00 1.00 1.00 1.00 1.00 1.00 1.00 1.00 1.00 1.00 1.00 1.00 1.00 1.00 1.00 1.00 1.00 1.00 1.00 1.00 1.00 1.00 1.00 1.00 1.00 1.00 1.00 1.00 1.00 1.00 1.00 1.00 1.00 1.00 1.00 1.00 1.00 1.00 1.00 1.00 1.00 1.00 1.00 1.00 1.00 1.00 1.00 1.00 1.00 1.00 1.00 1.00 1.00 1.00 1.00 1.00 1.00 1.00 1.00 1.00 1.00 1.00 1.00 1.00 1.00 1.00 1.00 1.00 1.00 1.00 1.00 1.00 1.00 1.00 1.00 1.00 1.00 1.00 1.00 1.00 1.00 1.00 1.00 1.00 1.00 1.00 1.00 1.00 1.00 1.00 1.00 1.00 1.00 1.00 1.00 1.00 1.00 1.00 1.00 1.00 1.00 1.00 1.00 1.00 1.00 1.00 1.00 1.00 1.00 1.00 1.00 1.00 1.00 1.00 1.00 1.00 1.00 1.00 1.00 1.00 1.00 1.00 1.00 1.00 1.00 1.00 1.00 1.00 1.00 1.00 1.00 1.00 1.00 1.00 1.00 1.00 1.00 1.00 1.00 1.00 1.00 1.00 1.00 1.00 1.00 1.00 1.00 1.00 1.00 1.00 1.00 1.00 1.00 1.00 1.00 1.00 1.00 1.00 1.00 1.00 1.00 1.00 1.00 1.00 1.00 1.00 1.00 1.00 1.00 1.00 1.00 1.00 1.00 1.00 1.00 1.00 1.00 1.00 1.00 1.00 1.00 1.00 1.00 1.00 1.00 1.00 1.00 1.00 1.00 1.00 1.00 1.00 1.00 1.00 1.00 1.00 1.00 1.00 1.00 1.00 1.00 1.00 1.00 1.00 1.00 1.00 1.00 1.00 1.00 1.00 1.00 1.00 1.00 1.00 1.00 1.00 1.00 1.00 1.00 1.00 1.00 1.00 1.00 1.00 1.00 1.00 1.00 1.00 1.00 1.00 1.00 1.00 1.00 1.00 1.00 1.00 1.00 1.00 1.00 1.00 1.00 1.00 1.00 1.00 1.00 1.00 1.00 1.00 1.00 1.00 1.00 1.00 1.00 1.00 1.00 1.00 1.00 1.00 1.00 1.00 1.00 1.00 1.00 1.00 1.00 1.00 1.00 1.00 1.00 1.00 1.00 1.00 1.00 1.00 1.00 1.00 1.00 1.00 1.00 1.00 1.00 1.00 1.00 1.00 1.00 1.00 1.00 1.00 1.00 1.00 1.00 1.00 1.00 1.00 1.00 1.00 1.00 1.00 1.00 1.00 1.00 1.00 1.00 1.00 1.00 1.00 1.00 1.00 1.00 1.00 1.00 1.00 1.00 1.00 1.00 1.00 1.00 1.00 1.00 1.00 1.00 1.00 1.00 1.00 1.00 1.00 1.00 1.00 1.00 1.00 1.00 1.00 1.00 1.00 1.00 1.00 1.00 1.00 1.00 1.00 1.00 1.00 1.00 1.00 1.00 1.00 1.00 1.00 1.00 1.00 1.00 1.00 1.00 1.00 1.00 1.00 1.00 1.00 1.00 1.00 1.00 1.00 1.00 1.00 1.00 1.00 1.00 1.00 1.00 1.00 1.00 1.00 1.00 1.00 1.00 1.00 1.00 1.00 1.00 1.00 1.00 1.00 1.00 1.00 1.00 1.00 1.00 1.00 1.00 1.00 1.00 1.00 1.00 1.00 1.00 1.00 1.00 1.00 1.00 1.00 1.00 1.00 1.00 1.00 1.00 1.00 1.00 1.00 1.00 1.00 1.00 1.00 1.00 1.00 1.00 1.00 1.00 1.00 1.00 1.00 1.00 1.00 1.00 1.00 1.00 1.00 1.00 1.00 1.00 1.00 1.00 1.00 1.00 1.00 1.00 1.00 1.00 1.00 1.00 1.00 1.00 1.00 1.00 1.00 1.00 1.00 1.00 1.00 1.00 1.00 1.00 1.00 1.00 1.00 1.00 1.00 1.00 1.00 1.00 1.00 1.00 1.00 1.00 1.00 1.00 1.00 1.00 1.00 1.00 1.00 1.00 1.00 1.00 1.00 1.00 1.00 1.00 1.00 1.00 1.00 1.00 1.00 1.00 1.00 1.00 1.00 1.00 1.00 1.00 1.00 1.00 1.00 1.00 1.00 1.00 1.00 1.00 1.00 1.00 1.00 1.00 1.00 1.00 1.00 1.00 1.00 1.00 1.00 1.00 1.00 1.00 1.00 1.00 1.00 1.00 1.00 1.00 1.00 1.00 1.00 1.00 1.00 1.00 1.00 1.00 1.00 1.00 1.00 1.00 1.00 1.00 1.00 1.00 1.00 1.00 1.00 1.00 1.00 1.00 1.00 1.00 1.00 1.00 1.00 1.00 1.00 1.00 1.00 1.00 1.00 1.00 1.00 1.00 1.00 1.00 1.00 1.00 1.00 1.00 1.00 1.00 1.00 1.00 1.00 1.00 1.00 1.00 1.00 1.00 1.00 1.00 1.00 1.00 1.00 1.00 1.00 1.00 1.00 1.00 1.00 1.00 1.00 1.00 1.00 1.00 1.00 1.00 1.00 1.00 1.00 1.00 1.00 1.00 1.00 1.00 1.00 1.00 1.00 1.00 1.00 1.00 1.00 1.00 1.00 1.00 1.00 1.00 1.00 1.00 1.00 1.00 1.00 1.00 1.00 1.00 1.00 1.00 1.00 1.00 1.00 1.00 1.00 1.00 1.00 1.00 1.00 1.00 1.00 1.00 1.00 1.00 1.00 1.00 1.00 1.00 1.00 1.00 1.00 1.00 1.00 1.00 1.00 1.00 1.00 1.00 1.00 1.00 1.00 1.00 1.00 1.00 1.00 1.00 1.00 1.00 1.00 1.00 1.00 1.00 1.00 1.00 1.00 1.00 1.00 1.00 1.00 1.00 1.00 1.00 1.00 1.00 1.00 1.00 1.00 1.00 1.00 1.00 1.00 1.00 1.00 1.00 1.00 1.00 1.00 1.00 1.00 1.00 1.00 1.00 1.00 1.00 1.00 1.00 1.00 1.00 1.00 1.00 1.00 1.00 1.00 1.00 1.00 1.00 1.00 1.00 1.00 1.00 1.00 1.00 1.00 1.00 1.00 1.00 1.00 1.00 1.00 1.00 1.00 1.00 1.00 1.00 1.00 1.00 1.00 1.00 1.00 1.00 1.00 1.00 1.00 1.00 1.00 1.00 1.00 1.00 1.00 1.00 1.00 1.00 1.00 1.00 1.00 1.00 1.00 1.00 1.00 1.00 1.00 1.00 1.00 1.00 1.00 1.00 1.00 1.00 1.00 1.00 1.00 1.00 1.00 1.00 1.00 1.00 1.00 1.00 1.00 1.00 1.00 1.00 1.00 1.00 1.00 1.00 1.00 1.00 1.00 1.00 1.00 1.00 1.00 1.00 1.00 1.00 1.00 1.00 1.00 1.00 1.00 1.00 1.00 1.00 1.00 1.00 1.00 1.00 1.00 1.00 1.00 1.00 1.00 1.00 1.00 1.00 1.00 1.00 1.00 1.00 1.00 1.00 1.00 1.00 1.00 1.00 1.00 1.00 1.00 1.00 1.00 1.00 1.00 1.00 1.00 1.00 1.00 1.00 1.00 1.00 1.00 1.00 1.00 1.00 1.00 1.00 1.00 1.00 1.00 1.00 1.00 1.00 1.00 1.00 1.00 1.00 1.00 1.00 1.00 1.00 1.00 1.00 1.00 1.00 1.00 1.00 1.00 1.00 1.00 1.00 1.00 1.00 1.00 1.00 1.00 1.00 1.00 1.00 1.00 1.00 1.00 1.00 1.00 1.00 1.00 1.00 1.00 1.00 1.00 1.00 1.00 1.00 1.00 1.00 1.00 1.00 1.00 1.00 1.00 1.00 1.00 1.00 1.00 1.00 1.00 1.00 1.00 1.00 1.00 1.00 1.00 1.00 1.00 1.00 1.00 1.00 1.00 1.00 1.00 1.00 1.00 1.00 1.00 1.00 1.00 1.00 1.00 1.00 1.00 1.00 1.00 1.00 1.00 1.00 1.00 1.00 1.00 1.00 1.00 1.00 1.00 1.00 1.00 1.00 1.00 1.00 1.00 1.00 1.00 1.00 1.00 1.00 1.00 1.00 1.00 1.00 1.00 1.00 1.00 1.00 1.00 1.00 1.00 1.00 1.00 1.00 1.00 1.00 1.00 1.00 1.00 1.00 1.00 1.00 1.00 1.00 1.00 1.00 1.00 1.00 1.00 1.00 1.00 1.00 1.00 1.00 1.00 1.00 1.00 1.00 1.00 1.00 1.00 1.00 1.00 1.00 1.00 1.00 1.00 1.00 1.00 1.00 1.00 1.00 1.00 1.00 1.00 1.00 1.00 1.00 1.00 1.00 1.00 1.00 1.00 1.00 1.00 1.00 1.00 1.00 1.00 1.00 1.00 1.00 1.00 1.00 1.00 1.00 1.00 1.00 1.00 1.00 1.00 1.00 1.00 1.00 1.00 1.00 1.00 1.00 1.00 1.00 1.00 1.00 1.00 1.00 1.00 1.00 1.00 1.00 1.00 1.00 1.00 1.00 1.00 1.00 1.00 1.00 1.00 1.00 1.00 1.00 1.00 1.00 1.00 1.00 1.00 1.00 1.00 1.00 1.00 1.00 1.00 1.00 1.00 1.00 1.00 1.00 1.00 1.00 1.00 1.00 1.00 1.00 1.00 1.00 1.00 1.00 1.00 1.00 1.00 1.00 1.00 1.00 1.00 1.00 1.00 1.00 1.00 1.00 1.00 1.00 1.00 1.00 1.00 1.00 1.00 1.00 1.00 1.00 1.00 1.00 1.00 1.00 1.00 1.00 1.00 1.00 1.00 1.00 1.00 1.00 1.00 1.00 1.00 1.00 1.00 1.00 1.00 1.00 1.00 1.00 1.00 1.00 1.00 1.00 1.00 1.00 1.00 1.00 1.00 1.00 1.00 1.00 1.00 1.00 1.00 1.00 1.00 1.00 1.00 1.00 1.00 1.00 1.00 1.00 1.00 1.00 1.00 1.00 1.00 1.00 1.00 1.00 1.00 1.00 1.00 1.00 1.00 1.00 1.00 1.00 1.00 1.00 1.00 1.00 1.00 1.00 1.00 1.00 1.00 1.00 1.00 1.00 1.00 1.00 1.00 1.00 1.00 1.00 1.00 1.00 1.00 1.00 1.00 1.00 1.00 1.00 1.00 1.00 1.00 1.00 1.00 1.00 1.00 1.00 1.00 1.00 1.00 1.00 1.00 1.00 1.00 1.00 1.00 1.00 1.00 1.00 1.00 1.00 1.00 1.00 1.00 1.00 1.00 1.00 1.00 1.00 1.00 1.00 1.00 1.00 1.00 1.00 1.00 1.00 1.00 1.00 1.00 1.00 1.00 1.00 1.00 1.00 1.00 1.00 1.00 1.00 1.00 1.00 1.00 1.00 1.00 1.00 1.00 1.00 1.00 1.00 1.00 1.00 1.00 1.00 1.00 1.00 1.00 1.00 1.00 1.00 1.00 1.00 1.00 1.00 1.00 1.00 1.00 1.00 1.00 1.00 1.00 1.00 1.00 1.00 1.00 1.00 1.00 1.00 1.00 1.00 1.00 1.00 1.00 1.00 1.00 1.00 1.00 1.00 1.00 1.00 1.00 1.00 1.00 1.00 1.00 1.00 1.00 1.00 1.00 1.00 1.00 1.00 1.00 1.00 1.00 1.00 1.00 1.00 1.00 1.00 1.00 1.00 1.00 1.00 1.00 1.00 1.00 1.00 1.00 1.00 1.00 1.00 1.00 1.00 1.00 1.00 1.00 1.00 1.00 1.00 1.00 1.00 1.00 1.00 1.00 1.00 1.00 1.00 1.00 1.00 1.00 1.00 1.00 1.00 1.00 1.00 1.00 1.00 1.00 1.00 1.00 1.00 1.00 1.00 1.00 1.00 1.00 1.00 1.00 1.00 1.00 1.00 1.00 1.00 1.00 1.00 1.00 1.00 1.00 1.00 1.00 1.00 1.00 1.00 1.00 1.00 1.00 1.00 1.00 1.00 1.00 1.00 1.00 1.00 1.00 1.00 1.00 1.00 1.00 1.00 1.00 1.00 1.00 1.00 1.00 1.00 1.00 1.00 1.00 1.00 1.00 1.00 1.00 1.00 1.00 1.00 1.00 1.00 1.00 1.00 1.00 1.00 1.00 1.00 1.00 1.00 1.00 1.00 1.00 1.00 1.00 1.00 1.00 1.00 1.00 1.00 1.00 1.00 1.00 1.00 1.00 1.00 1.00 1.00 1.00 1.00 1.00 1.00 1.00 1.00 1.00 1.00 1.00 1.00 1.00 1.00 1.00 1.00 1.00 1.00 1.00 1.00 1.00 1.00 1.00 1.00 1.00 1.00 1.00 1.00 1.00 1.00 1.00 1.00 1.00 1.00 1.00 1.00 1.00 1.00 1.00 1.00 1.00 1.00 1.00 1.00 1.00 1.00 1.00 1.00 1.00 1.00 1.00 1.00 1.00 1.00 1.00 1.00 1.00 1.00 1.00 1.00 1.00 1.00 1.00 1.00 1.00 1.00 1.00 1.00 1.00 1.00 1.00 1.00 1.00 1.00 1.00 1.00 1.00 1.00 1.00 1.00 1.00 1.00 1.00 1.00 1.00 1.00 1.00 1.00 1.00 1.00 1.00 1.00 1.00 1.00 1.00 1.00 1.00 1.00 1.00 1.00 1.00 1.00 1.00 1.00 1.00 1.00 1.00 1.00 1.00 1.00 1.00 1.00 1.00 1.00 1.00 1.00 1.00 1.00 1.00 1.00 1.00 1.00 1.00 1.00 1.00 1.00 1.00 1.00 1.00 1.00 1.00 1.00 1.00 1.00 1.00 1.00 1.00 1.00 1.00 1.00 1.00 1.00 1.00 1.00 1.00 1.00 1.00 1.00 1.00 1.00 1.00 1.00 1.00 1.00 1.00 1.00 1.00 1.00 1.00 1.00 1.00 1.00 1.00 1.00 1.00 1.00 1.00 1.00 1.00 1.00 1.00 1.00 1.00 1.00 1.00 1.00 1.00 1.00 1.00 1.00 1.00 1.00 1.00 1.00 1.00 1.00 1.00 1.00 1.00 1.00 1.00 1.00 1.00 1.00 1.00 1.00 1.00 1.00 1.00 1.00 1.00 1.00 1.00 1.00 1.00 1.00 1.00 1.00 1.00 1.00 1.00 1.00 1.00 1.00 1.00 1.00 1.00 1.00 1.00 1.00 1.00 1.00 1.00 1.00 1.00 1.00 1.00 1.00 1.00 1.00 1.00 1.00 1.00 1.00 1.00 1.00 1.00 1.00 1.00 1.00 1.00 1.00 1.00 1.00 1.00 1.00 1.00 1.00 1.00 1.00 1.00 1.00 1.00 1.00 1.00 1.00 1.00 1.00 1.00 1.00 1.00 1.00 1.00 1.00 1.00 1.00 1.00 1.00 1.00 1.00 1.00 1.00 1.00 1.00 1.00 1.00 1.00 1.00 1.00 1.00 1.00 1.00 1.00 1.00 1.00 1.00 1.00 1.00 1.00 1.00 1.00 1.00 1.00 1.00 1.00 1.00 1.00 1.00 1.00 1.00 1.00 1.00 1.00 1.00 1.00 1.00 1.00 1.00 1.00 1.00 1.00 1.00 1.00 1.00 1.00 1.00 1.00 1.00 1.00 1.00 1.00 1.00 1.00 1.00 1.00 1.00 1.00 1.00 1.00 1.00 1.00 1.00 1.00 1.00 1.00 1.00 1.00 1.00 1.00 1.00 1.00 1.00 1.00 1.00 1.00 1.00 1.00 1.00 1.00 1.00 1.00 1.00 1.00 1.00 1.00 1.00 1.00 1.00 1.00 1.00 1.00 1.00 1.00 1.00 1.00 1.00 1.00 1.00 1.00 1.00 1.00 1.00 1.00 1.00 1.00 1.00 1.00 1.00 1.00 1.00 1.00 1.00 1.00 1.00 1.00 1.00 1.00 1.00 1.00 1.00 1.00 1.00 1.00 1.00 1.00 1.00 1.00 1.00 1.00 1.00 1.00 1.00 1.00 1.00 1.00 1.00 1.00 1.00 1.00 1.00 1.00 1.00 1.00 1.00 1.00 1.00 1.00 1.00 1.00 1.00 1.00 1.00 1.00 1.00 1.00 1.00 1.00 1.00 1.00 1.00 1.00 1.00 1.00 1.00 1.00 1.00 1.00 1.00 1.00 1.00 1.00 1.00 1.00 1.00 1.00 1.00 1.00 1.00 1.00 1.00 1.00 1.00 1.00 1.00 1.00 1.00 1.00 1.00 1.00 1.00 1.00 1.00 1.00 1.00 1.00 1.00 1.00 1.00 1.00 1.00 1.00 1.00 1.00 1.00 1.00 1.00 1.00 1.00 1.00 1.00 1.00 1.00 1.00 1.00 1.00 1.00 1.00 1.00 1.00 1.00 1.00 1.00 1.00 1.00 1.00 1.00 1.00 1.00 1.00 1.00 1.00 1.00 1.00 1.00 1.00 1.00 1.00 1.00 1.00 1.00 1.00 1.00 1.00 1.00 1.00 1.00 1.00 1.00 1.00 1.00 1.00 1.00 1.00 1.00 1.00 1.00 1.00 1.00 1.00 1.00 1.00 1.00 1.00 1.00 1.00 1.00 1.00 1.00 1.00 1.00 1.00 1.00 1.00 1.00 1.00 1.00 1.00 1.00 1.00 1.00 1.00 1.00 1.00 1.00 1.00 1.00 1.00 1.00 1.00 1.00 1.00 1.00 1.00 1.00 1.00 1.00 1.00 1.00 1.00 1.00 1.00 1.00 1.00 1.00 1.00 1.00 1.00 1.00 1.00 1.00 1.00 1.00 1.00 1.00 1.00 1.00 1.00 1.00 1.00 1.00 1.00 1.00 1.00 1.00 1.00 1.00 1.00 1.00 1.00 1.00 1.00 1.00 1.00 1.00 1.00 1.00 1.00 1.00 1.00 1.00 1.00 1.00 1.00 1.00 1.00 1.00 1.00 1.00 1.00 1.00 1.00 1.00 1.00 1.00 1.00 1.00 1.00 1.00 1.00 1.00 1.00 1.00 1.00 1.00 1.00 1.00 1.00 1.00 1.00 1.00 1.00 1.00 1.00 1.00 1.00 1.00 1.00 1.00 1.00 1.00 1.00 1.00 1.00 1.00 1.00 1.00 1.00 1.00 1.00 1.00 1.00 1.00 1.00 1.00 1.00 1.00 1.00 1.00 1.00 1.00 1.00 1.00 1.00 1.00 1.00 1.00 1.00 1.00 1.00 1.00 1.00 1.00 1.00 1.00 1.00 1.00 1.00 1.00 1.00 1.00 1.00 1.00 1.00 1.00 1.00 1.00 1.00 1.00 1.00 1.00 1.00 1.00 1.00 1.00 1.00 1.00 1.00 1.00 1.00 1.00 1.00 1.00 1.00 1.00 1.00 1.00 1.00 1.00 1.00 1.00 1.00 1.00 1.00 1.00 1.00 1.00 1.00 1.00 1.00 1.00 1.00 1.00 1.00 1.00 1.00 1.00 1.00 1.00 1.00 1.00 1.00 1.00 1.00 1.00 1.00 1.00 1.00 1.00 1.00 1.00 1.00 1.00 1.00 1.00 1.00 1.00 1.00 1.00 1.00 1.00 1.00 1.00 1.00 1.00 1.00 1.00 1.00 1.00 1.00 1.00 1.00 1.00 1.00 1.00 1.00 1.00 1.00 1.00 1.00 1.00 1.00 1.00 1.00 1.00 1.00 1.00 1.00 1.00 1.00 1.00 1.00 1.00 1.00 1.00 1.00 1.00 1.00 1.00 1.00 1.00 1.00 1.00 1.00 1.00 1.00 1.00 1.00 1.00 1.00 1.00 1.00 1.00 1.00 1.00 1.00 1.00 1.00 1.00 1.00 1.00 1.00 1.00 1.00 1.00 1.00 1.00 1.00 1.00 1.00 1.00 1.00 1.00 1.00 1.00 1.00 1.00 1.00 1.00 1.00 1.00 1.00 1.00 1.00 1.00 1.00 1.00 1.00 1.00 1.00 1.00 1.00 1.00 1.00 1.00 1.00 1.00 1.00 1.00 1.00 1.00 1.00 1.00 1.00 1.00 1.00 1.00 1.00 1.00 1.00 1.00 1.00 1.00 1.00 1.00 1.00 1.00 1.00 1.00 1.00 1.00 1.00 1.00 1.00 1.00 1.00 1.00 1.00 1.00 1.00 1.00 1.00 1.00 1.00 1.00 1.00 1.00 1.00 1.00 1.00 1.00 1.00 1.00 1.00 1.00 1.00 1.00 1.00 1.00 1.00 1.00 1.00 1.00 1.00 1.00 1.00 1.00 1.00 1.00 1.00 1.00 1.00 1.00 1.00 1.00 1.00 1.00 1.00 1.00 1.00 1.00 1.00 1.00 1.00 1.00 1.00 1.00 1.00 1.00 1.00 1.00 172.00 172.00 172.00 172.00 172.00 172.00 172.00 172.00 172.00 172.00 172.00 172.00 172.00 172.00 1.00 1.00 1.00 1.00 1.00 1.00 1.00 1.00 1.00 1.00 1.00 1.00 1.00 1.00 1.00 1.00 1.00 1.00 1.00 1.00 1.00 1.00 1.00 1.00 1.00 1.00 1.00 1.00 1.00 1.00 1.00 1.00 1.00 1.00 1.00 1.00 1.00 1.00 1.00 1.00 1.00 1.00 1.00 1.00 1.00 1.00 1.00 1.00 1.00 1.00 1.00 1.00 1.00 1.00 1.00 1.00 1.00 1.00 1.00 1.00 1.00 1.00 1.00 1.00 1.00 1.00 1.00 1.00 1.00 1.00 1.00 1.00 1.00 1.00 1.00 1.00 1.00 1.00 1.00 1.00 1.00 1.00 1.00 1.00 1.00 1.00 1.00 1.00 1.00 1.00 1.00 1.00 1.00 1.00 1.00 1.00 1.00 1.00 1.00 1.00 1.00 1.00 1.00 1.00 1.00 1.00 1.00 1.00 1.00 1.00 1.00 1.00 1.00 1.00 1.00 1.00 1.00 1.00 1.00 1.00 1.00 1.00 1.00 1.00 1.00 1.00 1.00 1.00 1.00 1.00 1.00 1.00 1.00 1.00 1.00 1.00 1.00 1.00 1.00 1.00 1.00 1.00 1.00 1.00 1.00 1.00 1.00 1.00 1.00 1.00 1.00 1.00 1.00 1.00 1.00 1.00 1.00 1.00 1.00 1.00 1.00 1.00 1.00 1.00 1.00 1.00 1.00 1.00 1.00 1.00 1.00 1.00 1.00 1.00 1.00 1.00 1.00 1.00 1.00 1.00 1.00 1.00 1.00 1.00 1.00 1.00 1.00 1.00 1.00 1.00 1.00 1.00 1.00 1.00 1.00 1.00 1.00 1.00 1.00 1.00 1.00 1.00 1.00 1.00 1.00 1.00 1.00 1.00 1.00 1.00 1.00 1.00 1.00 1.00 1.00 1.00 1.00 1.00 1.00 1.00 1.00 1.00 1.00 1.00 1.00 1.00 1.00 1.00 1.00 1.00 1.00 1.00 1.00 1.00 1.00 1.00 1.00 1.00 1.00 1.00 1.00 1.00 1.00 1.00 1.00 1.00 1.00 1.00 1.00 1.00 1.00 1.00 1.00 1.00 1.00 1.00 1.00 1.00 1.00 1.00 1.00 1.00 1.00 1.00 1.00 1.00 1.00 1.00 1.00 1.00 1.00 1.00 1.00 1.00 1.00 1.00 1.00 1.00 1.00 1.00 1.00 1.00 1.00 1.00 1.00 1.00 1.00 1.00 1.00 1.00 1.00 1.00 1.00 1.00 1.00 1.00 1.00 1.00 1.00 1.00 1.00 1.00 1.00 1.00 1.00 1.00 1.00 1.00 1.00 1.00 1.00 1.00 1.00 1.00 1.00 1.00 1.00 1.00 1.00 1.00 1.00 1.00 1.00 1.00 1.00 1.00 1.00 1.00 1.00 1.00 1.00 1.00 1.00 1.00 1.00 1.00 1.00 1.00 1.00 1.00 1.00 1.00 1.00 1.00 1.00 1.00 1.00</beamAttenuationFactors>
				<commonCountingTime unit="seconds">0.352</commonCountingTime>
				<counts unit="counts">49 32 32 53 31 31 26 33 28 23 46 34 32 60 35 28 32 32 40 33 51 52 43 37 37 32 48 33 44 36 40 34 29 38 49 37 34 42 37 30 33 27 27 40 31 33 24 28 35 42 35 24 35 37 40 30 37 35 36 26 43 40 34 36 44 28 25 44 47 34 31 33 34 45 30 33 31 29 27 37 35 39 52 24 31 35 37 29 37 33 38 36 36 25 27 24 36 38 33 30 45 35 34 39 41 34 35 40 28 40 36 38 31 39 35 42 28 36 34 28 31 28 32 35 32 39 34 36 46 42 34 42 40 40 38 35 37 37 41 49 44 38 38 41 30 37 34 29 27 32 33 41 45 39 37 39 39 48 39 47 48 39 52 54 56 35 45 36 33 39 35 35 31 41 23 50 34 41 42 42 54 47 50 52 68 53 58 57 63 64 59 60 56 39 39 36 35 31 49 47 46 59 56 70 86 94 85 98 97 119 135 96 123 122 112 104 64 91 74 67 51 50 55 66 84 93 117 190 239 284 365 483 573 684 755 826 934 1087 1104 1348 1348 1399 1554 1476 1637 1477 1578 1430 1390 1500 1223 1384 1120 987 938 764 668 666 502 440 369 296 239 202 211 228 295 611 7181 12734 17739 24168 34694 61369 92741 99705 65866 49153 39325 20234 11141 1336 898 500 321 341 253 184 196 138 99 133 87 77 65 54 51 38 40 58 68 56 67 73 67 85 72 80 66 65 92 63 70 65 40 50 51 36 47 43 37 42 30 30 44 40 37 46 40 50 48 47 47 49 53 41 34 38 38 33 23 38 40 29 32 19 32 26 31 33 24 38 36 31 41 25 39 40 45 32 27 35 27 49 29 28 27 30 24 26 26 34 39 19 29 26 22 42 35 35 36 30 34 29 26 27 25 18 32 22 36 36 30 26 22 17 38 26 32 26 22 28 24 30 28 32 25 20 29 34 26 29 33 22 33 36 24 32 30 24 27 23 27 27 26 26 32 29 29 28 20 33 26 23 23 29 29 21 36 25 19 32 34 26 22 24 27 16 26 31 25 23 21 20 26 27 23 27 31 22 26 34 35 32 25 19 20 18 27 24 27 23 21 24 24 18 27 19 20 26 23 31 23 26 21 29 25 29 22 19 22 29 27 23 15 22 16 21 29 21 24 25 29 28 25 27 22 29 23 26 30 27 36 21 26 16 22 14 28 21 15 26 22 15 17 20 24 27 22 23 23 23 20 19 28 25 24 22 23 28 9 26 32 22 23 21 17 17 13 31 19 17 27 31 20 22 21 19 20 24 32 30 25 20 16 28 28 13 22 22 20 17 27 26 22 21 22 22 21 21 19 17 20 22 19 33 27 19 17 29 25 27 22 29 28 19 14 23 23 21 21 22 25 19 29 24 22 21 19 25 21 20 16 24 20 19 25 14 27 23 20 17 19 31 21 18 10 24 24 22 23 34 20 22 18 30 32 33 31 20 21 18 22 25 15 18 22 19 16 10 22 18 18 22 14 24 20 20 25 22 27 23 30 23 20 24 20 26 17 17 24 25 14 25 28 22 19 20 23 18 25 11 20 18 17 20 13 13 21 24 20 25 16 9 20 11 19 16 19 14 18 18 12 20 25 16 27 17 17 16 20 19 18 25 9 23 18 22 27 14 17 19 22 15 17 17 17 26 16 24 15 18 19 19 21 12 22 14 22 13 23 20 18 27 17 16 20 18 24 20 20 8 16 19 12 14 19 16 21 13 18 9 29 10 14 22 21 19 15 16 19 28 23 11 17 23 28 17 28 19 26 17 14 11 16 13 20 15 15 21 18 15 23 15 19 16 15 17 14 23 15 14 29 20 21 18 26 21 27 14 17 15 28 23 22 20 14 13 21 18 15 15 26 25 22 22 20 19 18 18 19 24 17 23 23 16 21 26 13 17 23 16 20 17 17 23 12 10 18 19 19 24 14 17 22 14 24 17 13 21 18 19 16 20 23 16 21 14 25 13 15 17 14 22 19 10 11 21 22 15 23 25 17 19 15 15 15 19 16 18 14 22 16 18 21 20 14 18 20 16 13 12 22 18 23 22 15 8 18 22 14 19 18 14 14 15 17 13 24 15 15 19 22 24 7 20 18 21 14 16 11 14 13 19 15 23 17 17 16 13 11 28 16 16 17 18 14 15 12 16 17 21 21 19 16 19 16 22 20 15 13 18 16 13 15 14 22 12 15 16 19 10 19 19 20 17 16 13 9 10 14 11 11 21 19 11 15 17 13 10 13 22 13 15 14 13 11 11 9 15 10 19 11 14 13 12 18 11 17 18 15 16 16 12 14 14 13 12 16 11 11 15 13 13 16 12 19 12 22 14 19 12 15 12 16 16 12 12 16 14 17 19 22 13 20 21 10 15 16 20 16 9 17 18 19 13 14 14 17 22 13 12 14 13 9 13 24 19 25 10 13 12 12 14 15 8 19 17 19 8 19 11 18 8 19 8 12 18 11 15 13 14 13 25 18 11 18 16 19 19 17 7 17 13 15 23 14 20 13 16 10 18 12 11 8 14 14 13 10 17 10 18 15 7 17 17 11 22 10 14 15 14 15 14 9 8 11 16 11 9 15 12 19 19 16 10 10 12 16 12 13 12 17 10 15 8 14 15 13 10 14 13 14 17 18 21 11 12 18 12 9 18 15 13 7 14 15 12 15 11 12 8 12 9 23 22 13 18 15 12 13 13 13 19 12 20 11 8 11 12 20 19 12 18 13 12 7 17 12 7 9 10 13 12 13 24 13 13 9 11 13 14 16 22 17 12 11 10 12 13 14 13 18 15 11 8 9 17 9 13 12 11 20 11 14 18 10 10 14 14 13 13 18 12 14 11 13 8 12 17 14 13 16 12 20 15 22 7 12 16 14 8 14 6 4 17 15 10 14 14 10 12 15 11 12 14 16 13 18 15 6 8 15 7 12 13 4 13 12 15 14 12 14 16 11 16 12 13 14 9 16 14 11 12 16 10 10 9 11 6 11 11 10 13 9 9 13 14 14 12 12 10 10 11 7 11 15 20 21 14 15 3 15 16 9 16 13 9 17 11 21 17 12 11 16 10 12 8 13 15 14 10 12 11 10 11 15 11 12 7 12 12 6 10 7 15 17 12 15 7 16 11 12 11 7 9 13 6 18 13 14 7 20 5 11 16 15 9 11 16 18 7 16 17 6 12 14 11 12 11 10 15 13 11 11 6 12 10 7 16 7 15 12 9 15 9 14 17 13 7 11 9 13 19 16 7 13 10 11 11 8 10 11 11 15 13 11 8 9 16 10 10 6 8 13 18 18 14 7 8 13 14 13 14 9 9 12 15 10 7 8 12 8 10 15 11 11 8 14 10 14 12 12 12 9 12 7 10 14 12 11 9 15 13 12 14 11 14 6 8 21 14 6 5 12 10 6 15 9 10 9 8 16 15 9 11 14 8 12 12 18 12 10 10 12 22 12 11 7 9 16 12 10 13 10 6 11 10 12 11 10 11 6 14 10 6 8 10 16 10 12 13 10 12 12 7 8 19 13 8 16 5 11 14 15 13 12 8 11 4 16 10 12 11 9 8 10 12 12 9 10 15 13 15 9 8 16 12 12 9 19 5 11 15 10 8 13 14 15 13 10 10 12 14 6 12 11 9 10 3 8 11 15 10 10 11 12 10 7 6 12 7 8 10 5 14 5 12 15 12 5 14 7 11 9 11 8 10 16 9 7 13 8 4 10 7 11 6 8 4 14 6 13 9 13 8 18 22 11 9 10 9 10 7 15 12 7 8 14 7 10 7 9 9 12 11 14 12 7 12 9 16 12 12 10 7 4 15 8 13 14 3 11 11 10 16 15 19 12 12 16 12 19 12 18 9 11 16 10 10 11 13 16 13 19 8 13 11 13 7 9 14 11 5 9 7 8 14 13 6 10 12 15 9 7 8 7 15 14 5 13 17 7 4 11 8 3 5 9 10 12 12 14 9 14 16 9 10 14 9 12 7 3 8 8 8 13 10 14 14 11 9 9 8 5 15 9 14 14 11 17 12 7 13 7 9 12 12 7 9 13 17 5 6 13 12 13 13 8 15 18 9 7 9 11 9 16 8 12 12 10 8 8 5 16 9 7 4 12 11 17 10 8 15 16 14 10 14 8 10 9 7 11 8 7 14 9 8 10 17 9 17 10 11 13 7 14 9 11 18 8 13 11 6 16 13 12 5 9 15 11 8 10 11 7 11 9 6 9 9 13 11 8 6 11 10 13 6 14 8 11 3 13 5 12 9 12 9 16 13 6 7 8 15 10 6 13 9 8 12 14 8 11 18 10 8 8 12 14 10 6 14 13 10 8 2 15 10 5 7 12 12 10 14 9 11 10 14 12 10 8 12 6 12 14 13 7 8 9 4 15 9 14 9 6 12 12 13 8 12 12 14 3 7 11 9 4 15 12 16 6 8 15 18 16 3 9 8 9 14 12 14 8 8 7 9 13 8 11 10 9 13 9 10 9 13 15 7 13 17 9 12 13 11 9 8 11 6 13 9 14 12 9 13 11 9 8 10 13 9 11 6 8 8 12 6 13 6 9 10 11 12 11 19 9 11 6 7 10 6 10 9 8 6 8 9 14 9 13 10 11 9 11 14 3 8 11 11 14 9 12 10 17 11 17 6 12 10 9 8 10 10 11 8 13 17 12 5 9 4 16 9 11 12 17 7 11 8 10 11 7 11 7 13 8 10 10 8 10 10 11 12 14 15 9 10 8 9 10 14 11 10 9 11 10 12 6 12 14 14 12 8 10 14 9 11 19 8 11 11 11 22 11 14 9 9 11 17 17 9 11 18 14 10 10 9 8 9 10 11 12 9 11 17 18 12 16 15 14 10 17 17 11 18 15 19 13 9 8 10 17 16 7 10 13 8 9 15 18 9 11 17 17 21 14 18 18 23 18 13 12 14 27 17 16 19 9 11 8 11 13 11 11 7 11 14 7 10 15 16 9 19 20 16 7 11 13 11 18 18 9 10 13 12 11 8 13 11 14 11 18 12 16 10 8 8 16 15 17 21 17 19 24 18 22 21 12 11 17 11 11 13 15 12 9 9 12 12 15 15 15 12 21 13 20 27 11 20 15 15 14 12 12 12 14 11 9 13 6 13 10 11 8 18 13 16 15 18 15 12 17 19 15 13 13 23 12 22 16 25 9 15 22 9 15 13 12 7 18 14 7 9 13 21 17 19 20 23 27 14 21 17 24 12 21 13 18 16 12 19 6 19 9 19 16 18 15 17 24 16 17 18 17 21 17 19 23 28 20 22 22 26 25 16 22 15 16 11 15 13 13 14 14 13 14 16 29 21 28 28 21 27 26 28 41 28 23 25 21 27 19 17 15 15 18 9 15 16 22 14 20 18 19 26 37 29 25 26 35 30 25 27 29 24 24 24 18 17 25 17 15 13 12 14 16 20 19 25 26 19 31 23 44 44 42 41 46 43 39 29 43 21 31 17 17 18 19 14 13 14 21 19 31 25 30 34 51 41 48 47 41 43 55 45 48 46 34 37 34 28 31 27 37 26 29 24 21 20 44 35 30 47 51 62 60 68 69 78 60 76 88 55 78 66 53 48 40 31 32 28 32 25 24 23 31 40 49 53 67 89 97 93 128 99 112 108 105 104 100 69 105 85 66 60 56 56 41 36 40 38 42 99 69 92 143 155 158 174 198 201 226 217 234 208 185 195 162 158 127 120 119 93 78 61 66 84 106 121 148 195 250 287 392 429 403 536 570 599 656 607 618 614 559 501 441 410 345 308 259 277 312 334 444 582 883 1189 1571 1987 2573 3205 3927 4765 5736 6385 7351 8980 9804 10747 11782 12735 13914 14671 15460 16327 17235 17751 17752 17854 17945 17764 17997 17444 16978 16320 15428 14639 13823 12816 11430 10091 9181 8293 7324 6181 5209 4282 3676 2831 2171 1679 1258 907 750 674 650 682 748 906 1014 1220 1442 1628 1882 2048 2184 2251 2495 2535 2478 2638 2693 2887 3264 4120 6040 12613 36428 90461 158504 1231 1471 1647 1610 1780 2103 3752 7175 8374 6922 5846 5073 4365 2626 136045 24785 9112 4362 2500 1634 1385 1171 1055 829 764 639 659 554 499 434 421 357 276 231 215 175 116 103 77 52 49 39 44 51 48 40 62 53 74 79 86 72 80 87 60 82 88 65 62 74 51 54 35 26 27 20 23 16 15 19 20 25 30 18 39 28 32 29 36 33 47 40 38 33 37 32 28 32 23 24 14 16 14 20 14 8 12 13 10 10 14 17 21 23 23 22 15 19 22 17 23 24 23 22 14 15 16 16 12 9 17 10 11 12 12 13 19 20 11 13 14 14 10 12 18 24 13 9 17 13 9 12 9 13 9 12 11 9 12 9 6 8 11 6 15 10 10 11 16 10 14 13 13 18 15 15 15 11 17 8 16 13 14 9 11 9 8 13 6 8 6 13 11 11 6 12 10 11 17 11 10 15 8 4 9 9 9 11 8 7 15 9 8 15 10 12 5 8 16 8 17 10 15 11 4 13 13 7 8 10 6 5 12 12 9 5 8 8 3 7 9 9 8 11 4 14 13 9 8 7 5 5 8 6 9 12 4 9 8 6 7 9 9 9 10 9 5 11 8 9 8 9 10 8 9 9 10 5 6 9 11 10 8 13 8 6 8 16 7 12 5 9 8 6 9 10 11 9 7 6 7 10 9 8 5 4 10 9 6 11 8 2 8 3 10 5 9 7 14 10 9 9 15 2 5 6 7 8 5 8 7 4 10 10 7 10 4 6 6 6 4 7 5 5 8 8 9 9 7 7 5 9 7 8 7 8 5 8 6 8 8 9 6 4 10 5 3 5 5 9 5</counts>
			</dataPoints>
		</scan>
	</xrdMeasurement>
</xrdMeasurements>