File: data/previous_data/set_3-YG035-038/xrd/YG037-SRO001-STO001-RSM-06192022.xrdml
<?xml version="1.0" encoding="utf-8"?>
<xrdMeasurements xmlns="http://www.xrdml.com/XRDMeasurement/2.1" xmlns:xsi="http://www.w3.org/2001/XMLSchema-instance" xsi:schemaLocation="http://www.xrdml.com/XRDMeasurement/2.1 http://www.xrdml.com/XRDMeasurement/2.1/XRDMeasurement.xsd" status="Completed">
	<sample type="To be analyzed">
		<id/>
		<name/>
		<preparedBy/>
	</sample>
	<xrdMeasurement status="Completed" measurementType="Area measurement" measurementStepAxis="Omega" sampleMode="Reflection">
		<comment>
			<entry>PHD Lower Level = 4.02 (keV), PHD Upper Level = 11.27 (keV)</entry>
		</comment>
		<usedWavelength intended="K-Alpha 1">
			<kAlpha1 unit="Angstrom">1.5405980</kAlpha1>
			<kAlpha2 unit="Angstrom">1.5444260</kAlpha2>
			<kBeta unit="Angstrom">1.3922500</kBeta>
			<ratioKAlpha2KAlpha1>0.5</ratioKAlpha2KAlpha1>
		</usedWavelength>
		<incidentBeamPath>
			<radius unit="mm">320.00</radius>
			<xRayTube id="1010048" name="Empyrean Cu LFF HR (9430 033 7310x) DK425175">
				<tension unit="kV">45.0</tension>
				<current unit="mA">40.0</current>
				<anodeMaterial>Cu</anodeMaterial>
				<focus type="Line">
					<length unit="mm">12.0</length>
					<width unit="mm">0.4</width>
					<takeOffAngle unit="deg">4.2</takeOffAngle>
				</focus>
			</xRayTube>
			<xRayMirror xsi:type="xRayMirrorType" id="27090001" name="Inc. Beam Cu W/Si (hybrid MRD)" hybrid="true">
				<crystal type="Graded" shape="Parabolic">W/Si</crystal>
				<acceptanceAngle unit="deg">0.800</acceptanceAngle>
				<length unit="mm">60.0</length>
			</xRayMirror>
			<monochromator xsi:type="monochromatorType" id="23090002" name="Hybrid monochr. 2xGe(220) Cu asym." hybrid="true">
				<crystal type="Asymmetric" shape="Flat">Ge</crystal>
				<numberOfReflections>2</numberOfReflections>
				<hkl>
					<h>2</h>
					<k>2</k>
					<l>0</l>
				</hkl>
			</monochromator>
			<divergenceSlit xsi:type="fixedDivergenceSlitType" id="22010004" name="Fixed slit 1/2°">
				<distanceToSample unit="mm">220.00</distanceToSample>
				<height unit="mm">0.76</height>
			</divergenceSlit>
		</incidentBeamPath>
		<sampleOffset>
			<position axis="Omega" unit="deg">-0.4701</position>
			<position axis="Chi" unit="deg">0.23</position>
		</sampleOffset>
		<diffractedBeamPath>
			<radius unit="mm">320.00</radius>
			<antiScatterSlit xsi:type="fixedAntiScatterSlitType" id="22090009" name="AS slit 7.5 mm (PIXcel)">
				<height unit="mm">7.50</height>
			</antiScatterSlit>
			<sollerSlit xsi:type="sollerSlitType" id="21010002" name="Soller slits 0.04 rad.">
				<opening unit="rad">0.0400</opening>
			</sollerSlit>
			<receivingSlit xsi:type="receivingSlitType" id="22010004" name="Fixed slit 1/2°">
				<height unit="mm">0.76</height>
			</receivingSlit>
			<detector xsi:type="areaDetectorType" id="7010020" name="PIXcel3D-Medipix3 1x1 detector">
				<phd unit="%">
					<lowerLevel>25</lowerLevel>
					<upperLevel>70</upperLevel>
				</phd>
				<mode>Scanning snapshot equatorial</mode>
				<activeChannelsEquatorial>255</activeChannelsEquatorial>
				<activeChannelsAxial>255</activeChannelsAxial>
				<pitchEquatorial unit="mm">0.05500</pitchEquatorial>
				<pitchAxial unit="mm">0.05500</pitchAxial>
				<readOutPeriod unit="seconds">0.195</readOutPeriod>
			</detector>
		</diffractedBeamPath>
		<scan status="Completed" appendNumber="0" scanAxis="2Theta" mode="Continuous">
			<header>
				<startTimeStamp>2022-06-19T13:59:46-07:00</startTimeStamp>
				<endTimeStamp>2022-06-19T14:02:39-07:00</endTimeStamp>
				<author>
					<name>XRD</name>
				</author>
				<source>
					<applicationSoftware version="6.1b">Data Collector</applicationSoftware>
					<instrumentControlSoftware version="7.4b 20181204">XPERT-3</instrumentControlSoftware>
					<instrumentID>0000000011163216</instrumentID>
				</source>
			</header>
			<dataPoints>
				<positions axis="2Theta" unit="deg">
					<startPosition>75.431417636843</startPosition>
					<endPosition>77.9421823631571</endPosition>
				</positions>
				<positions axis="Omega" unit="deg">
					<commonPosition>18.16606193</commonPosition>
				</positions>
				<positions axis="Phi" unit="deg">
					<commonPosition>-8.19</commonPosition>
				</positions>
				<positions axis="Chi" unit="deg">
					<commonPosition>0</commonPosition>
				</positions>
				<positions axis="X" unit="mm">
					<commonPosition>-0.01</commonPosition>
				</positions>
				<positions axis="Y" unit="mm">
					<commonPosition>0</commonPosition>
				</positions>
				<positions axis="Z" unit="mm">
					<commonPosition>8.786</commonPosition>
				</positions>
				<commonCountingTime unit="seconds">0.189</commonCountingTime>
				<counts unit="counts">0 0 1 0 0 0 0 1 0 0 0 0 0 0 0 0 0 0 0 0 0 0 0 0 0 1 1 0 0 0 0 0 0 0 0 0 0 0 0 0 0 0 0 0 0 0 0 0 0 0 0 0 1 0 0 0 0 0 0 0 0 0 0 0 0 1 0 0 1 0 0 0 0 0 1 0 1 0 0 0 0 0 0 0 0 0 0 0 0 0 0 0 0 0 0 0 0 0 0 0 0 0 0 0 0 0 0 3 0 0 1 0 0 0 0 0 0 0 0 0 0 0 1 0 0 1 0 1 0 0 0 0 1 0 0 0 0 0 0 0 0 0 0 0 0 0 0 1 0 1 0 0 0 0 0 0 0 1 0 1 0 0 0 0 0 1 0 0 1 1 0 0 0 0 0 0 0 0 0 0 0 0 0 0 0 0 0 0 0 0 0 0 0 0 0 0 0 0 0 0 0 0 0 0 0 0 0 0 0 0 0 0 1 0 0 0 0 0 0 0 0 0 0 0 0 0 0 0 0 1 0 0 0 0 0 0 0 1 0 0 0 0 0 0 0 0 0 0 0 0 0 0 0 0 0</counts>
			</dataPoints>
		</scan>
		<scan status="Completed" appendNumber="0" scanAxis="2Theta" mode="Continuous">
			<header>
				<startTimeStamp>2022-06-19T13:59:46-07:00</startTimeStamp>
				<endTimeStamp>2022-06-19T14:02:39-07:00</endTimeStamp>
				<author>
					<name>XRD</name>
				</author>
				<source>
					<applicationSoftware version="6.1b">Data Collector</applicationSoftware>
					<instrumentControlSoftware version="7.4b 20181204">XPERT-3</instrumentControlSoftware>
					<instrumentID>0000000011163216</instrumentID>
				</source>
			</header>
			<dataPoints>
				<positions axis="2Theta" unit="deg">
					<startPosition>75.431417636843</startPosition>
					<endPosition>77.9421823631571</endPosition>
				</positions>
				<positions axis="Omega" unit="deg">
					<commonPosition>18.1709857860123</commonPosition>
				</positions>
				<positions axis="Phi" unit="deg">
					<commonPosition>-8.19</commonPosition>
				</positions>
				<positions axis="Chi" unit="deg">
					<commonPosition>0</commonPosition>
				</positions>
				<positions axis="X" unit="mm">
					<commonPosition>-0.01</commonPosition>
				</positions>
				<positions axis="Y" unit="mm">
					<commonPosition>0</commonPosition>
				</positions>
				<positions axis="Z" unit="mm">
					<commonPosition>8.786</commonPosition>
				</positions>
				<commonCountingTime unit="seconds">0.189</commonCountingTime>
				<counts unit="counts">0 0 0 0 0 0 0 0 0 0 0 0 0 0 0 0 0 0 0 0 1 0 0 0 1 0 0 0 1 0 0 0 0 1 0 0 0 0 0 0 0 0 1 0 0 0 0 0 0 2 0 0 0 0 0 0 0 1 0 0 0 1 0 0 0 0 0 0 0 0 0 0 0 0 0 0 0 0 0 0 0 1 0 0 1 0 0 0 0 1 0 0 1 0 0 1 0 0 1 0 0 1 0 0 0 0 0 0 0 0 0 1 0 0 0 0 0 0 0 0 0 0 0 1 0 0 0 0 0 0 0 0 0 0 0 0 0 0 0 0 0 0 0 0 0 0 0 0 0 0 0 0 0 0 0 0 0 0 0 0 0 0 0 1 1 0 0 0 0 0 0 0 0 0 0 0 0 0 0 0 0 0 1 0 1 0 1 0 0 0 0 1 0 1 1 0 0 0 0 0 0 0 1 0 0 0 1 0 0 1 0 0 0 0 0 0 0 0 0 0 0 0 0 0 0 0 1 0 1 0 0 0 0 0 0 0 1 0 1 0 0 0 0 0 0 0 0 0 0 1 0 0 0 0 0</counts>
			</dataPoints>
		</scan>
		<scan status="Completed" appendNumber="0" scanAxis="2Theta" mode="Continuous">
			<header>
				<startTimeStamp>2022-06-19T13:59:46-07:00</startTimeStamp>
				<endTimeStamp>2022-06-19T14:02:39-07:00</endTimeStamp>
				<author>
					<name>XRD</name>
				</author>
				<source>
					<applicationSoftware version="6.1b">Data Collector</applicationSoftware>
					<instrumentControlSoftware version="7.4b 20181204">XPERT-3</instrumentControlSoftware>
					<instrumentID>0000000011163216</instrumentID>
				</source>
			</header>
			<dataPoints>
				<positions axis="2Theta" unit="deg">
					<startPosition>75.431417636843</startPosition>
					<endPosition>77.9421823631571</endPosition>
				</positions>
				<positions axis="Omega" unit="deg">
					<commonPosition>18.1759096420247</commonPosition>
				</positions>
				<positions axis="Phi" unit="deg">
					<commonPosition>-8.19</commonPosition>
				</positions>
				<positions axis="Chi" unit="deg">
					<commonPosition>0</commonPosition>
				</positions>
				<positions axis="X" unit="mm">
					<commonPosition>-0.01</commonPosition>
				</positions>
				<positions axis="Y" unit="mm">
					<commonPosition>0</commonPosition>
				</positions>
				<positions axis="Z" unit="mm">
					<commonPosition>8.786</commonPosition>
				</positions>
				<commonCountingTime unit="seconds">0.189</commonCountingTime>
				<counts unit="counts">1 0 0 0 0 0 0 0 0 0 0 0 0 0 0 0 0 0 0 0 0 0 0 0 0 1 0 0 0 0 0 0 0 0 0 0 0 0 0 0 0 1 0 0 0 0 0 0 0 0 0 0 0 0 0 0 0 0 0 0 0 0 1 0 0 0 0 0 0 0 0 0 0 0 0 0 0 0 0 0 0 0 0 0 0 0 0 0 2 0 0 0 0 0 0 0 0 0 0 0 0 0 3 1 0 0 0 0 0 0 0 0 0 0 0 0 0 0 0 0 0 0 1 0 0 0 1 0 0 0 0 0 0 0 0 0 0 0 0 0 0 0 1 0 0 0 0 0 0 0 0 1 0 0 0 0 0 0 0 0 0 0 0 0 0 0 0 0 0 0 0 0 0 0 1 0 0 0 0 0 0 1 0 0 1 0 0 0 0 0 0 0 0 0 0 0 0 0 0 0 0 0 0 0 0 0 0 0 0 0 1 0 0 0 0 0 0 0 1 0 0 0 0 0 0 0 0 0 0 0 0 0 0 0 1 0 1 1 0 0 0 0 0 1 0 0 0 0 0 0 0 0 0 0 0</counts>
			</dataPoints>
		</scan>
		<scan status="Completed" appendNumber="0" scanAxis="2Theta" mode="Continuous">
			<header>
				<startTimeStamp>2022-06-19T13:59:46-07:00</startTimeStamp>
				<endTimeStamp>2022-06-19T14:02:39-07:00</endTimeStamp>
				<author>
					<name>XRD</name>
				</author>
				<source>
					<applicationSoftware version="6.1b">Data Collector</applicationSoftware>
					<instrumentControlSoftware version="7.4b 20181204">XPERT-3</instrumentControlSoftware>
					<instrumentID>0000000011163216</instrumentID>
				</source>
			</header>
			<dataPoints>
				<positions axis="2Theta" unit="deg">
					<startPosition>75.431417636843</startPosition>
					<endPosition>77.9421823631571</endPosition>
				</positions>
				<positions axis="Omega" unit="deg">
					<commonPosition>18.180833498037</commonPosition>
				</positions>
				<positions axis="Phi" unit="deg">
					<commonPosition>-8.19</commonPosition>
				</positions>
				<positions axis="Chi" unit="deg">
					<commonPosition>0</commonPosition>
				</positions>
				<positions axis="X" unit="mm">
					<commonPosition>-0.01</commonPosition>
				</positions>
				<positions axis="Y" unit="mm">
					<commonPosition>0</commonPosition>
				</positions>
				<positions axis="Z" unit="mm">
					<commonPosition>8.786</commonPosition>
				</positions>
				<commonCountingTime unit="seconds">0.189</commonCountingTime>
				<counts unit="counts">0 0 0 1 0 1 0 0 1 0 0 0 0 0 0 0 0 0 0 0 0 0 0 0 0 0 0 0 0 1 0 0 0 0 0 0 0 0 0 0 0 0 0 0 0 0 1 0 0 0 0 0 0 1 1 1 1 0 0 0 0 0 0 0 0 0 0 0 0 0 0 0 0 0 0 0 0 0 0 0 0 0 0 0 0 0 0 0 0 1 0 0 0 0 0 0 0 0 0 0 0 0 0 0 1 0 2 0 0 0 0 1 0 0 0 0 1 0 0 0 0 1 0 1 0 0 0 0 0 0 0 0 0 0 0 0 0 0 0 1 0 0 0 0 0 1 0 0 0 0 0 0 0 0 0 0 0 0 0 0 0 0 0 0 0 0 0 0 0 0 0 1 0 0 0 0 0 0 0 0 0 0 0 0 0 0 0 0 1 0 0 0 0 0 0 0 0 0 0 0 0 1 1 0 0 0 0 0 0 0 2 0 0 1 0 0 0 0 0 0 0 0 0 0 0 0 1 0 0 0 0 0 0 0 1 0 0 1 0 0 0 0 0 0 0 0 0 1 1 0 0 0 0 0 1</counts>
			</dataPoints>
		</scan>
		<scan status="Completed" appendNumber="0" scanAxis="2Theta" mode="Continuous">
			<header>
				<startTimeStamp>2022-06-19T13:59:46-07:00</startTimeStamp>
				<endTimeStamp>2022-06-19T14:02:39-07:00</endTimeStamp>
				<author>
					<name>XRD</name>
				</author>
				<source>
					<applicationSoftware version="6.1b">Data Collector</applicationSoftware>
					<instrumentControlSoftware version="7.4b 20181204">XPERT-3</instrumentControlSoftware>
					<instrumentID>0000000011163216</instrumentID>
				</source>
			</header>
			<dataPoints>
				<positions axis="2Theta" unit="deg">
					<startPosition>75.431417636843</startPosition>
					<endPosition>77.9421823631571</endPosition>
				</positions>
				<positions axis="Omega" unit="deg">
					<commonPosition>18.1857573540494</commonPosition>
				</positions>
				<positions axis="Phi" unit="deg">
					<commonPosition>-8.19</commonPosition>
				</positions>
				<positions axis="Chi" unit="deg">
					<commonPosition>0</commonPosition>
				</positions>
				<positions axis="X" unit="mm">
					<commonPosition>-0.01</commonPosition>
				</positions>
				<positions axis="Y" unit="mm">
					<commonPosition>0</commonPosition>
				</positions>
				<positions axis="Z" unit="mm">
					<commonPosition>8.786</commonPosition>
				</positions>
				<commonCountingTime unit="seconds">0.189</commonCountingTime>
				<counts unit="counts">0 0 0 0 0 0 0 0 0 0 0 0 0 0 0 0 0 0 0 0 0 0 0 0 0 0 0 0 0 0 0 0 1 0 0 0 0 0 0 0 0 0 0 0 0 0 0 0 0 0 0 0 0 1 0 0 0 0 0 0 0 0 0 0 0 0 1 0 0 0 0 0 1 0 1 0 0 0 0 0 0 1 0 0 0 0 0 0 0 0 0 0 0 0 0 0 0 0 0 0 0 0 0 0 0 0 0 0 0 0 0 0 0 0 0 0 0 1 0 0 0 0 0 0 0 0 0 0 0 0 0 0 0 0 0 0 0 0 0 0 0 0 0 0 0 0 0 0 0 0 0 0 0 0 0 1 0 0 0 0 0 0 0 0 0 0 0 0 0 0 0 0 0 0 0 0 1 0 0 0 0 0 0 0 0 0 1 0 0 0 0 0 0 0 0 0 0 0 0 0 0 0 0 0 0 0 0 0 0 0 0 0 0 0 0 0 0 0 0 0 0 0 0 0 0 0 0 0 0 0 0 0 0 0 0 0 0 0 0 1 0 0 0 0 0 0 0 0 0 0 0 0 0 0 0</counts>
			</dataPoints>
		</scan>
		<scan status="Completed" appendNumber="0" scanAxis="2Theta" mode="Continuous">
			<header>
				<startTimeStamp>2022-06-19T13:59:46-07:00</startTimeStamp>
				<endTimeStamp>2022-06-19T14:02:39-07:00</endTimeStamp>
				<author>
					<name>XRD</name>
				</author>
				<source>
					<applicationSoftware version="6.1b">Data Collector</applicationSoftware>
					<instrumentControlSoftware version="7.4b 20181204">XPERT-3</instrumentControlSoftware>
					<instrumentID>0000000011163216</instrumentID>
				</source>
			</header>
			<dataPoints>
				<positions axis="2Theta" unit="deg">
					<startPosition>75.431417636843</startPosition>
					<endPosition>77.9421823631571</endPosition>
				</positions>
				<positions axis="Omega" unit="deg">
					<commonPosition>18.1906812100617</commonPosition>
				</positions>
				<positions axis="Phi" unit="deg">
					<commonPosition>-8.19</commonPosition>
				</positions>
				<positions axis="Chi" unit="deg">
					<commonPosition>0</commonPosition>
				</positions>
				<positions axis="X" unit="mm">
					<commonPosition>-0.01</commonPosition>
				</positions>
				<positions axis="Y" unit="mm">
					<commonPosition>0</commonPosition>
				</positions>
				<positions axis="Z" unit="mm">
					<commonPosition>8.786</commonPosition>
				</positions>
				<commonCountingTime unit="seconds">0.189</commonCountingTime>
				<counts unit="counts">0 0 0 0 0 0 0 1 0 0 1 0 0 0 0 0 0 0 0 1 0 0 0 0 0 0 1 0 0 0 0 0 0 0 0 0 1 0 0 0 0 0 0 0 0 0 0 0 0 0 0 0 0 0 0 0 0 0 0 1 0 0 0 0 0 0 0 0 0 0 2 0 0 0 0 0 0 0 0 0 0 0 0 0 0 0 0 0 1 0 0 1 0 1 1 0 0 0 0 0 0 1 0 1 0 0 0 0 0 0 0 0 1 0 0 0 1 0 0 0 0 0 0 0 0 0 0 0 2 0 1 1 1 0 0 0 0 0 0 0 0 0 0 0 0 0 0 0 0 0 0 0 0 1 0 0 0 0 0 0 0 1 0 0 0 0 0 0 0 0 0 1 1 0 0 0 0 0 0 0 0 0 0 0 0 0 0 0 0 0 0 1 0 0 0 0 0 0 0 0 0 0 0 0 0 0 0 0 1 0 0 0 0 0 0 0 0 0 0 0 0 0 0 0 0 0 0 0 0 0 0 0 0 0 1 0 1 0 0 0 0 0 0 0 0 0 0 0 0 0 0 0 0 0 0</counts>
			</dataPoints>
		</scan>
		<scan status="Completed" appendNumber="0" scanAxis="2Theta" mode="Continuous">
			<header>
				<startTimeStamp>2022-06-19T13:59:46-07:00</startTimeStamp>
				<endTimeStamp>2022-06-19T14:02:39-07:00</endTimeStamp>
				<author>
					<name>XRD</name>
				</author>
				<source>
					<applicationSoftware version="6.1b">Data Collector</applicationSoftware>
					<instrumentControlSoftware version="7.4b 20181204">XPERT-3</instrumentControlSoftware>
					<instrumentID>0000000011163216</instrumentID>
				</source>
			</header>
			<dataPoints>
				<positions axis="2Theta" unit="deg">
					<startPosition>75.431417636843</startPosition>
					<endPosition>77.9421823631571</endPosition>
				</positions>
				<positions axis="Omega" unit="deg">
					<commonPosition>18.1956050660741</commonPosition>
				</positions>
				<positions axis="Phi" unit="deg">
					<commonPosition>-8.19</commonPosition>
				</positions>
				<positions axis="Chi" unit="deg">
					<commonPosition>0</commonPosition>
				</positions>
				<positions axis="X" unit="mm">
					<commonPosition>-0.01</commonPosition>
				</positions>
				<positions axis="Y" unit="mm">
					<commonPosition>0</commonPosition>
				</positions>
				<positions axis="Z" unit="mm">
					<commonPosition>8.786</commonPosition>
				</positions>
				<commonCountingTime unit="seconds">0.189</commonCountingTime>
				<counts unit="counts">0 0 0 0 0 0 0 0 0 0 0 0 0 0 0 0 0 0 0 0 0 0 0 0 1 0 0 0 0 0 0 0 0 0 0 0 0 0 0 0 0 0 0 0 0 0 0 0 0 0 0 0 0 0 0 0 0 0 0 0 0 0 0 0 0 0 0 0 0 0 0 0 0 0 0 0 1 0 0 0 0 0 0 2 0 0 0 0 0 0 0 1 0 0 0 0 0 1 0 0 0 0 0 1 0 0 0 0 0 0 0 0 0 0 0 0 0 0 0 0 0 0 0 0 1 0 0 0 0 0 1 0 0 0 0 1 0 0 0 0 0 0 0 0 1 1 0 0 0 0 1 0 1 0 0 0 0 0 0 0 0 0 0 0 0 0 0 0 0 0 1 0 0 0 0 0 0 0 0 0 0 0 0 0 0 0 0 1 0 0 0 0 0 0 0 0 0 0 0 0 0 0 0 0 0 0 0 0 0 0 0 0 0 0 0 0 0 0 0 0 0 0 0 0 1 0 0 0 0 0 0 0 0 1 0 0 0 0 0 0 0 0 0 0 0 0 0 0 0 0 0 0 0 0 0</counts>
			</dataPoints>
		</scan>
		<scan status="Completed" appendNumber="0" scanAxis="2Theta" mode="Continuous">
			<header>
				<startTimeStamp>2022-06-19T13:59:46-07:00</startTimeStamp>
				<endTimeStamp>2022-06-19T14:02:39-07:00</endTimeStamp>
				<author>
					<name>XRD</name>
				</author>
				<source>
					<applicationSoftware version="6.1b">Data Collector</applicationSoftware>
					<instrumentControlSoftware version="7.4b 20181204">XPERT-3</instrumentControlSoftware>
					<instrumentID>0000000011163216</instrumentID>
				</source>
			</header>
			<dataPoints>
				<positions axis="2Theta" unit="deg">
					<startPosition>75.431417636843</startPosition>
					<endPosition>77.9421823631571</endPosition>
				</positions>
				<positions axis="Omega" unit="deg">
					<commonPosition>18.2005289220864</commonPosition>
				</positions>
				<positions axis="Phi" unit="deg">
					<commonPosition>-8.19</commonPosition>
				</positions>
				<positions axis="Chi" unit="deg">
					<commonPosition>0</commonPosition>
				</positions>
				<positions axis="X" unit="mm">
					<commonPosition>-0.01</commonPosition>
				</positions>
				<positions axis="Y" unit="mm">
					<commonPosition>0</commonPosition>
				</positions>
				<positions axis="Z" unit="mm">
					<commonPosition>8.786</commonPosition>
				</positions>
				<commonCountingTime unit="seconds">0.189</commonCountingTime>
				<counts unit="counts">0 0 0 0 0 0 0 0 0 0 1 0 0 1 0 0 0 0 0 0 1 0 0 0 0 0 0 0 0 0 0 0 1 0 0 0 0 0 0 0 0 0 0 0 0 0 0 0 0 1 0 0 0 0 0 0 0 0 0 0 0 0 0 0 0 0 0 0 0 0 0 0 1 0 0 0 0 0 1 0 0 0 0 0 0 0 1 0 0 0 0 0 0 1 0 0 0 1 0 1 0 0 0 0 0 0 0 0 0 0 0 0 0 0 0 0 0 0 0 0 0 0 1 1 0 0 0 0 0 1 0 1 0 0 1 0 0 0 0 0 0 0 0 0 0 0 0 0 0 0 0 0 0 0 0 0 0 0 0 0 0 0 0 0 0 0 0 0 0 0 0 1 0 0 0 0 0 0 0 0 0 0 0 0 0 0 0 0 1 0 0 0 0 0 0 0 0 0 1 0 0 0 0 0 0 0 0 0 0 0 1 0 0 0 0 0 0 0 0 0 1 0 0 0 0 0 0 0 0 0 0 0 0 0 0 0 0 0 0 0 0 0 0 0 0 0 0 0 0 0 0 0 0 0 1</counts>
			</dataPoints>
		</scan>
		<scan status="Completed" appendNumber="0" scanAxis="2Theta" mode="Continuous">
			<header>
				<startTimeStamp>2022-06-19T13:59:46-07:00</startTimeStamp>
				<endTimeStamp>2022-06-19T14:02:39-07:00</endTimeStamp>
				<author>
					<name>XRD</name>
				</author>
				<source>
					<applicationSoftware version="6.1b">Data Collector</applicationSoftware>
					<instrumentControlSoftware version="7.4b 20181204">XPERT-3</instrumentControlSoftware>
					<instrumentID>0000000011163216</instrumentID>
				</source>
			</header>
			<dataPoints>
				<positions axis="2Theta" unit="deg">
					<startPosition>75.431417636843</startPosition>
					<endPosition>77.9421823631571</endPosition>
				</positions>
				<positions axis="Omega" unit="deg">
					<commonPosition>18.2054527780988</commonPosition>
				</positions>
				<positions axis="Phi" unit="deg">
					<commonPosition>-8.19</commonPosition>
				</positions>
				<positions axis="Chi" unit="deg">
					<commonPosition>0</commonPosition>
				</positions>
				<positions axis="X" unit="mm">
					<commonPosition>-0.01</commonPosition>
				</positions>
				<positions axis="Y" unit="mm">
					<commonPosition>0</commonPosition>
				</positions>
				<positions axis="Z" unit="mm">
					<commonPosition>8.786</commonPosition>
				</positions>
				<commonCountingTime unit="seconds">0.189</commonCountingTime>
				<counts unit="counts">0 0 0 0 0 0 0 1 1 1 0 0 0 0 0 0 0 0 1 0 0 0 0 0 0 0 1 0 0 0 1 0 1 1 0 0 0 0 0 0 0 0 0 0 0 0 0 0 0 0 0 0 0 0 0 0 0 0 0 0 0 0 0 0 0 0 0 0 0 1 0 0 0 0 1 0 0 0 0 0 0 0 0 0 0 0 0 0 1 0 0 0 1 0 0 0 0 1 0 0 1 0 0 0 2 0 0 0 0 0 0 0 1 0 0 1 0 0 0 0 0 0 0 0 0 0 0 0 0 0 0 0 0 1 0 1 0 0 0 0 0 0 0 0 0 0 0 0 0 0 0 1 0 0 0 0 0 0 0 0 0 0 0 0 0 0 0 0 0 0 0 0 0 0 0 0 1 0 1 0 1 0 1 0 0 1 0 0 0 0 0 0 0 1 0 0 0 0 0 0 0 0 0 0 0 0 0 0 0 0 0 0 0 0 1 0 0 0 0 0 0 0 0 0 1 0 0 0 0 0 0 0 0 0 0 0 0 0 0 0 0 0 0 0 0 0 0 0 0 0 0 0 0 0 0</counts>
			</dataPoints>
		</scan>
		<scan status="Completed" appendNumber="0" scanAxis="2Theta" mode="Continuous">
			<header>
				<startTimeStamp>2022-06-19T13:59:46-07:00</startTimeStamp>
				<endTimeStamp>2022-06-19T14:02:39-07:00</endTimeStamp>
				<author>
					<name>XRD</name>
				</author>
				<source>
					<applicationSoftware version="6.1b">Data Collector</applicationSoftware>
					<instrumentControlSoftware version="7.4b 20181204">XPERT-3</instrumentControlSoftware>
					<instrumentID>0000000011163216</instrumentID>
				</source>
			</header>
			<dataPoints>
				<positions axis="2Theta" unit="deg">
					<startPosition>75.431417636843</startPosition>
					<endPosition>77.9421823631571</endPosition>
				</positions>
				<positions axis="Omega" unit="deg">
					<commonPosition>18.2103766341111</commonPosition>
				</positions>
				<positions axis="Phi" unit="deg">
					<commonPosition>-8.19</commonPosition>
				</positions>
				<positions axis="Chi" unit="deg">
					<commonPosition>0</commonPosition>
				</positions>
				<positions axis="X" unit="mm">
					<commonPosition>-0.01</commonPosition>
				</positions>
				<positions axis="Y" unit="mm">
					<commonPosition>0</commonPosition>
				</positions>
				<positions axis="Z" unit="mm">
					<commonPosition>8.786</commonPosition>
				</positions>
				<commonCountingTime unit="seconds">0.189</commonCountingTime>
				<counts unit="counts">0 0 1 0 0 0 0 0 0 1 0 0 0 0 0 0 0 0 0 0 0 0 1 0 0 1 0 0 1 0 0 0 0 0 1 0 0 0 0 0 0 0 0 0 1 0 1 0 0 1 0 0 0 0 0 0 0 0 1 0 0 0 0 0 1 0 0 0 0 0 0 0 0 0 0 0 1 0 0 0 0 0 0 0 0 0 0 0 0 0 0 0 0 0 0 0 0 0 0 0 0 1 0 0 0 0 0 0 1 0 0 0 0 0 0 0 0 0 0 0 0 0 0 0 0 0 0 0 0 0 0 0 0 0 0 0 0 0 0 0 0 0 0 0 0 0 0 0 0 1 0 0 0 0 0 0 0 0 0 0 0 0 0 0 0 0 0 0 0 0 0 0 0 0 0 0 0 0 0 0 0 0 0 0 0 0 0 0 0 0 0 0 0 0 0 0 0 0 0 0 0 0 0 0 0 0 0 0 0 0 0 0 1 0 0 0 0 0 0 0 0 0 0 0 0 0 0 0 1 0 0 0 0 0 0 0 0 0 0 0 0 0 0 0 0 0 0 0 0 0 0 0 0 0 0</counts>
			</dataPoints>
		</scan>
		<scan status="Completed" appendNumber="0" scanAxis="2Theta" mode="Continuous">
			<header>
				<startTimeStamp>2022-06-19T13:59:46-07:00</startTimeStamp>
				<endTimeStamp>2022-06-19T14:02:39-07:00</endTimeStamp>
				<author>
					<name>XRD</name>
				</author>
				<source>
					<applicationSoftware version="6.1b">Data Collector</applicationSoftware>
					<instrumentControlSoftware version="7.4b 20181204">XPERT-3</instrumentControlSoftware>
					<instrumentID>0000000011163216</instrumentID>
				</source>
			</header>
			<dataPoints>
				<positions axis="2Theta" unit="deg">
					<startPosition>75.431417636843</startPosition>
					<endPosition>77.9421823631571</endPosition>
				</positions>
				<positions axis="Omega" unit="deg">
					<commonPosition>18.2153004901235</commonPosition>
				</positions>
				<positions axis="Phi" unit="deg">
					<commonPosition>-8.19</commonPosition>
				</positions>
				<positions axis="Chi" unit="deg">
					<commonPosition>0</commonPosition>
				</positions>
				<positions axis="X" unit="mm">
					<commonPosition>-0.01</commonPosition>
				</positions>
				<positions axis="Y" unit="mm">
					<commonPosition>0</commonPosition>
				</positions>
				<positions axis="Z" unit="mm">
					<commonPosition>8.786</commonPosition>
				</positions>
				<commonCountingTime unit="seconds">0.189</commonCountingTime>
				<counts unit="counts">0 1 0 0 2 1 0 0 0 0 0 0 0 0 0 0 0 0 0 0 0 0 0 0 0 0 0 0 0 0 0 0 0 0 0 0 0 0 0 1 1 0 0 0 0 0 0 1 0 0 0 0 0 0 0 1 1 0 0 1 0 0 0 0 0 0 0 0 0 0 0 1 0 0 0 0 0 0 0 0 0 1 0 0 0 0 0 0 0 0 0 0 0 0 1 0 0 0 0 0 0 0 1 0 0 0 0 0 0 0 0 0 0 0 0 0 0 0 0 0 0 0 0 0 0 0 1 0 0 1 0 0 0 0 0 0 0 0 0 0 0 0 0 0 0 1 0 0 0 0 0 0 0 0 0 1 0 0 0 1 0 0 0 0 1 0 0 0 0 0 0 0 2 0 2 0 0 0 0 0 0 0 0 0 0 0 0 0 0 0 0 0 0 1 0 0 0 0 0 1 0 0 0 0 0 0 0 0 0 0 0 1 0 0 0 0 0 0 0 0 0 0 0 0 0 0 1 0 0 0 0 0 0 0 0 0 0 0 0 0 0 0 0 0 0 0 0 0 0 0 0 0 0 0 0</counts>
			</dataPoints>
		</scan>
		<scan status="Completed" appendNumber="0" scanAxis="2Theta" mode="Continuous">
			<header>
				<startTimeStamp>2022-06-19T13:59:46-07:00</startTimeStamp>
				<endTimeStamp>2022-06-19T14:02:39-07:00</endTimeStamp>
				<author>
					<name>XRD</name>
				</author>
				<source>
					<applicationSoftware version="6.1b">Data Collector</applicationSoftware>
					<instrumentControlSoftware version="7.4b 20181204">XPERT-3</instrumentControlSoftware>
					<instrumentID>0000000011163216</instrumentID>
				</source>
			</header>
			<dataPoints>
				<positions axis="2Theta" unit="deg">
					<startPosition>75.431417636843</startPosition>
					<endPosition>77.9421823631571</endPosition>
				</positions>
				<positions axis="Omega" unit="deg">
					<commonPosition>18.2202243461358</commonPosition>
				</positions>
				<positions axis="Phi" unit="deg">
					<commonPosition>-8.19</commonPosition>
				</positions>
				<positions axis="Chi" unit="deg">
					<commonPosition>0</commonPosition>
				</positions>
				<positions axis="X" unit="mm">
					<commonPosition>-0.01</commonPosition>
				</positions>
				<positions axis="Y" unit="mm">
					<commonPosition>0</commonPosition>
				</positions>
				<positions axis="Z" unit="mm">
					<commonPosition>8.786</commonPosition>
				</positions>
				<commonCountingTime unit="seconds">0.189</commonCountingTime>
				<counts unit="counts">1 1 1 0 0 0 0 0 0 0 0 0 0 0 0 0 0 0 0 0 0 0 0 0 0 0 0 1 0 1 0 0 0 0 0 0 0 1 0 0 0 0 0 0 0 0 0 1 0 0 0 0 0 0 0 0 0 0 0 0 0 0 0 0 0 0 0 0 0 0 0 0 0 0 2 0 0 0 1 0 0 0 0 0 1 0 0 0 0 0 0 0 0 0 0 0 0 1 0 0 0 0 0 0 0 0 0 0 0 1 0 0 0 0 0 0 0 0 0 0 0 0 0 0 0 0 0 0 0 0 0 0 0 0 0 0 0 0 0 1 0 0 0 0 0 0 0 0 0 0 0 0 0 0 0 0 1 0 0 0 0 0 0 0 0 0 0 0 0 0 1 0 0 0 0 0 0 0 0 0 0 0 0 0 0 1 0 0 0 0 0 0 0 0 0 1 0 0 0 0 0 0 0 0 0 0 0 0 0 0 0 0 0 0 0 0 0 1 0 1 0 0 0 1 0 0 0 0 0 0 0 0 0 0 0 0 0 0 0 0 0 0 0 0 0 0 0 0 0 0 0 0 0 0 0</counts>
			</dataPoints>
		</scan>
		<scan status="Completed" appendNumber="0" scanAxis="2Theta" mode="Continuous">
			<header>
				<startTimeStamp>2022-06-19T13:59:46-07:00</startTimeStamp>
				<endTimeStamp>2022-06-19T14:02:39-07:00</endTimeStamp>
				<author>
					<name>XRD</name>
				</author>
				<source>
					<applicationSoftware version="6.1b">Data Collector</applicationSoftware>
					<instrumentControlSoftware version="7.4b 20181204">XPERT-3</instrumentControlSoftware>
					<instrumentID>0000000011163216</instrumentID>
				</source>
			</header>
			<dataPoints>
				<positions axis="2Theta" unit="deg">
					<startPosition>75.431417636843</startPosition>
					<endPosition>77.9421823631571</endPosition>
				</positions>
				<positions axis="Omega" unit="deg">
					<commonPosition>18.2251482021481</commonPosition>
				</positions>
				<positions axis="Phi" unit="deg">
					<commonPosition>-8.19</commonPosition>
				</positions>
				<positions axis="Chi" unit="deg">
					<commonPosition>0</commonPosition>
				</positions>
				<positions axis="X" unit="mm">
					<commonPosition>-0.01</commonPosition>
				</positions>
				<positions axis="Y" unit="mm">
					<commonPosition>0</commonPosition>
				</positions>
				<positions axis="Z" unit="mm">
					<commonPosition>8.786</commonPosition>
				</positions>
				<commonCountingTime unit="seconds">0.189</commonCountingTime>
				<counts unit="counts">0 0 0 0 0 0 0 0 0 0 0 0 0 0 0 0 0 0 0 0 0 0 0 0 0 0 0 1 0 0 1 0 0 0 0 0 0 0 1 0 1 0 0 0 0 0 0 0 0 0 0 0 0 1 0 0 0 0 0 0 1 0 1 0 0 0 0 0 0 1 0 1 0 0 0 0 0 1 0 0 1 0 0 0 0 0 0 0 0 0 0 0 0 0 0 0 0 1 0 0 0 0 0 0 0 0 0 0 0 0 0 0 0 0 0 0 0 0 0 0 0 0 0 0 0 0 0 0 0 0 0 0 0 0 0 0 0 0 1 0 1 1 0 0 0 0 0 1 0 0 0 1 0 0 0 0 0 0 0 0 0 0 0 0 0 1 0 0 0 0 0 1 0 0 0 1 1 0 0 0 0 0 0 0 0 0 0 0 0 0 0 0 0 0 0 0 0 0 0 0 0 0 0 0 0 0 2 0 0 0 0 0 0 0 0 0 0 0 0 0 0 0 0 0 0 0 1 0 0 0 0 0 0 0 0 0 0 0 1 0 0 0 0 0 1 0 0 0 0 0 0 0 0 1 1</counts>
			</dataPoints>
		</scan>
		<scan status="Completed" appendNumber="0" scanAxis="2Theta" mode="Continuous">
			<header>
				<startTimeStamp>2022-06-19T13:59:46-07:00</startTimeStamp>
				<endTimeStamp>2022-06-19T14:02:39-07:00</endTimeStamp>
				<author>
					<name>XRD</name>
				</author>
				<source>
					<applicationSoftware version="6.1b">Data Collector</applicationSoftware>
					<instrumentControlSoftware version="7.4b 20181204">XPERT-3</instrumentControlSoftware>
					<instrumentID>0000000011163216</instrumentID>
				</source>
			</header>
			<dataPoints>
				<positions axis="2Theta" unit="deg">
					<startPosition>75.431417636843</startPosition>
					<endPosition>77.9421823631571</endPosition>
				</positions>
				<positions axis="Omega" unit="deg">
					<commonPosition>18.2300720581605</commonPosition>
				</positions>
				<positions axis="Phi" unit="deg">
					<commonPosition>-8.19</commonPosition>
				</positions>
				<positions axis="Chi" unit="deg">
					<commonPosition>0</commonPosition>
				</positions>
				<positions axis="X" unit="mm">
					<commonPosition>-0.01</commonPosition>
				</positions>
				<positions axis="Y" unit="mm">
					<commonPosition>0</commonPosition>
				</positions>
				<positions axis="Z" unit="mm">
					<commonPosition>8.786</commonPosition>
				</positions>
				<commonCountingTime unit="seconds">0.189</commonCountingTime>
				<counts unit="counts">0 0 0 1 0 0 1 0 0 0 0 0 0 0 1 0 0 0 0 1 0 0 0 0 0 0 0 0 0 0 0 0 0 0 0 0 0 0 0 0 0 0 0 0 0 0 0 0 0 0 0 0 0 0 1 0 0 0 0 0 0 0 0 0 0 0 0 0 0 1 0 0 0 0 0 0 0 0 0 0 0 0 0 0 0 0 1 0 0 0 0 1 0 0 0 0 0 0 0 0 0 0 0 0 0 0 0 0 0 0 0 0 0 0 0 0 0 0 0 0 0 0 0 0 1 0 0 0 0 0 0 0 0 0 0 0 1 1 0 0 0 0 0 0 0 0 0 0 0 0 0 0 0 0 2 0 1 0 0 0 1 0 0 0 0 0 0 0 0 0 0 0 0 0 0 0 0 0 1 0 0 0 0 0 0 0 0 0 1 0 0 0 0 0 0 0 1 0 0 0 0 0 0 1 0 0 0 0 0 0 0 0 0 0 0 0 0 0 0 0 0 0 0 0 1 0 0 0 0 0 0 0 0 0 0 0 1 0 1 0 0 0 0 0 1 0 0 0 0 0 0 0 0 1 0</counts>
			</dataPoints>
		</scan>
		<scan status="Completed" appendNumber="0" scanAxis="2Theta" mode="Continuous">
			<header>
				<startTimeStamp>2022-06-19T13:59:46-07:00</startTimeStamp>
				<endTimeStamp>2022-06-19T14:02:39-07:00</endTimeStamp>
				<author>
					<name>XRD</name>
				</author>
				<source>
					<applicationSoftware version="6.1b">Data Collector</applicationSoftware>
					<instrumentControlSoftware version="7.4b 20181204">XPERT-3</instrumentControlSoftware>
					<instrumentID>0000000011163216</instrumentID>
				</source>
			</header>
			<dataPoints>
				<positions axis="2Theta" unit="deg">
					<startPosition>75.431417636843</startPosition>
					<endPosition>77.9421823631571</endPosition>
				</positions>
				<positions axis="Omega" unit="deg">
					<commonPosition>18.2349959141728</commonPosition>
				</positions>
				<positions axis="Phi" unit="deg">
					<commonPosition>-8.19</commonPosition>
				</positions>
				<positions axis="Chi" unit="deg">
					<commonPosition>0</commonPosition>
				</positions>
				<positions axis="X" unit="mm">
					<commonPosition>-0.01</commonPosition>
				</positions>
				<positions axis="Y" unit="mm">
					<commonPosition>0</commonPosition>
				</positions>
				<positions axis="Z" unit="mm">
					<commonPosition>8.786</commonPosition>
				</positions>
				<commonCountingTime unit="seconds">0.189</commonCountingTime>
				<counts unit="counts">0 0 1 1 0 0 0 0 0 0 0 0 0 0 0 0 0 0 0 0 0 0 0 0 0 0 0 1 0 0 0 0 0 0 0 0 1 0 0 0 0 1 0 0 0 0 0 0 0 0 0 0 0 0 0 0 0 0 0 0 1 0 0 1 0 0 0 0 0 0 0 0 0 0 0 0 0 0 0 0 0 0 0 0 0 0 0 0 0 0 0 0 0 0 0 0 0 0 0 0 0 0 0 0 1 0 0 1 0 0 0 0 0 0 0 0 0 0 0 0 0 0 1 0 0 0 0 0 1 0 0 0 0 0 0 0 0 0 0 0 0 0 0 0 0 0 0 0 0 0 0 0 0 0 0 0 0 1 0 0 0 0 0 0 0 0 0 0 0 0 0 1 0 0 0 0 0 0 0 0 0 1 0 0 0 0 0 0 0 0 0 0 1 0 2 0 0 0 0 0 0 0 0 0 0 0 0 0 0 0 0 0 0 0 0 0 0 0 1 0 0 0 0 0 0 0 0 0 0 0 0 0 1 0 0 0 0 0 0 0 0 0 0 0 0 0 1 0 0 0 1 0 0 0 0</counts>
			</dataPoints>
		</scan>
		<scan status="Completed" appendNumber="0" scanAxis="2Theta" mode="Continuous">
			<header>
				<startTimeStamp>2022-06-19T13:59:46-07:00</startTimeStamp>
				<endTimeStamp>2022-06-19T14:02:39-07:00</endTimeStamp>
				<author>
					<name>XRD</name>
				</author>
				<source>
					<applicationSoftware version="6.1b">Data Collector</applicationSoftware>
					<instrumentControlSoftware version="7.4b 20181204">XPERT-3</instrumentControlSoftware>
					<instrumentID>0000000011163216</instrumentID>
				</source>
			</header>
			<dataPoints>
				<positions axis="2Theta" unit="deg">
					<startPosition>75.431417636843</startPosition>
					<endPosition>77.9421823631571</endPosition>
				</positions>
				<positions axis="Omega" unit="deg">
					<commonPosition>18.2399197701852</commonPosition>
				</positions>
				<positions axis="Phi" unit="deg">
					<commonPosition>-8.19</commonPosition>
				</positions>
				<positions axis="Chi" unit="deg">
					<commonPosition>0</commonPosition>
				</positions>
				<positions axis="X" unit="mm">
					<commonPosition>-0.01</commonPosition>
				</positions>
				<positions axis="Y" unit="mm">
					<commonPosition>0</commonPosition>
				</positions>
				<positions axis="Z" unit="mm">
					<commonPosition>8.786</commonPosition>
				</positions>
				<commonCountingTime unit="seconds">0.189</commonCountingTime>
				<counts unit="counts">0 0 0 0 0 0 0 0 0 0 0 0 0 0 0 0 0 0 0 0 0 0 0 0 0 0 0 0 0 0 1 0 1 0 2 0 0 0 0 0 0 1 1 1 0 0 0 0 0 1 0 0 0 0 0 0 0 0 0 1 0 0 1 0 0 0 0 0 0 0 0 0 0 0 0 0 0 0 0 0 0 0 0 0 0 0 0 0 0 0 0 0 0 0 0 0 0 0 0 0 0 0 0 0 0 2 0 0 0 0 0 0 0 0 0 0 0 0 0 1 0 0 0 0 0 0 0 0 0 1 1 0 0 0 0 0 0 0 0 0 0 1 0 0 0 0 0 0 0 0 0 0 0 0 0 0 0 0 1 0 0 1 0 0 0 0 0 0 0 0 0 0 0 0 0 0 0 0 0 0 0 0 0 0 0 0 0 0 1 0 0 0 0 0 0 0 0 0 1 0 0 0 0 0 0 0 0 0 1 0 0 0 0 0 0 0 0 0 0 0 0 0 0 0 0 0 0 0 0 0 0 1 0 0 0 0 0 0 0 0 0 0 0 0 0 0 0 0 0 0 0 2 0 0 0</counts>
			</dataPoints>
		</scan>
		<scan status="Completed" appendNumber="0" scanAxis="2Theta" mode="Continuous">
			<header>
				<startTimeStamp>2022-06-19T13:59:46-07:00</startTimeStamp>
				<endTimeStamp>2022-06-19T14:02:39-07:00</endTimeStamp>
				<author>
					<name>XRD</name>
				</author>
				<source>
					<applicationSoftware version="6.1b">Data Collector</applicationSoftware>
					<instrumentControlSoftware version="7.4b 20181204">XPERT-3</instrumentControlSoftware>
					<instrumentID>0000000011163216</instrumentID>
				</source>
			</header>
			<dataPoints>
				<positions axis="2Theta" unit="deg">
					<startPosition>75.431417636843</startPosition>
					<endPosition>77.9421823631571</endPosition>
				</positions>
				<positions axis="Omega" unit="deg">
					<commonPosition>18.2448436261975</commonPosition>
				</positions>
				<positions axis="Phi" unit="deg">
					<commonPosition>-8.19</commonPosition>
				</positions>
				<positions axis="Chi" unit="deg">
					<commonPosition>0</commonPosition>
				</positions>
				<positions axis="X" unit="mm">
					<commonPosition>-0.01</commonPosition>
				</positions>
				<positions axis="Y" unit="mm">
					<commonPosition>0</commonPosition>
				</positions>
				<positions axis="Z" unit="mm">
					<commonPosition>8.786</commonPosition>
				</positions>
				<commonCountingTime unit="seconds">0.189</commonCountingTime>
				<counts unit="counts">0 0 1 0 0 0 0 0 0 0 0 0 0 0 1 0 0 0 0 0 0 0 0 0 0 0 0 0 0 0 0 0 0 0 0 1 0 0 0 0 1 1 0 0 0 0 0 0 0 0 0 0 1 0 0 0 0 0 0 0 0 0 0 0 0 0 0 0 0 0 0 0 1 0 0 0 0 0 0 0 0 0 0 0 0 0 0 0 0 0 0 0 0 0 1 0 0 1 0 0 0 0 0 0 0 0 1 0 0 0 0 1 0 0 0 0 0 0 0 0 0 0 0 0 0 0 0 0 0 0 0 0 0 0 0 0 0 1 0 0 0 0 0 0 1 0 0 0 0 0 0 0 0 0 0 0 0 0 0 0 0 0 0 1 0 0 0 0 0 1 1 0 1 0 1 0 0 0 1 0 0 0 1 0 0 0 0 0 0 0 0 0 0 0 0 0 0 0 0 1 0 0 0 0 0 0 0 0 0 0 0 0 1 0 1 1 0 0 0 0 1 0 0 0 0 0 0 0 0 1 0 0 0 0 0 0 0 0 0 0 0 0 0 1 0 0 0 0 1 0 0 0 0 0 0</counts>
			</dataPoints>
		</scan>
		<scan status="Completed" appendNumber="0" scanAxis="2Theta" mode="Continuous">
			<header>
				<startTimeStamp>2022-06-19T13:59:46-07:00</startTimeStamp>
				<endTimeStamp>2022-06-19T14:02:39-07:00</endTimeStamp>
				<author>
					<name>XRD</name>
				</author>
				<source>
					<applicationSoftware version="6.1b">Data Collector</applicationSoftware>
					<instrumentControlSoftware version="7.4b 20181204">XPERT-3</instrumentControlSoftware>
					<instrumentID>0000000011163216</instrumentID>
				</source>
			</header>
			<dataPoints>
				<positions axis="2Theta" unit="deg">
					<startPosition>75.431417636843</startPosition>
					<endPosition>77.9421823631571</endPosition>
				</positions>
				<positions axis="Omega" unit="deg">
					<commonPosition>18.2497674822099</commonPosition>
				</positions>
				<positions axis="Phi" unit="deg">
					<commonPosition>-8.19</commonPosition>
				</positions>
				<positions axis="Chi" unit="deg">
					<commonPosition>0</commonPosition>
				</positions>
				<positions axis="X" unit="mm">
					<commonPosition>-0.01</commonPosition>
				</positions>
				<positions axis="Y" unit="mm">
					<commonPosition>0</commonPosition>
				</positions>
				<positions axis="Z" unit="mm">
					<commonPosition>8.786</commonPosition>
				</positions>
				<commonCountingTime unit="seconds">0.189</commonCountingTime>
				<counts unit="counts">0 0 0 0 0 1 0 0 0 0 0 0 0 0 0 0 0 0 0 1 0 0 0 0 0 0 0 0 0 0 1 0 0 1 0 0 0 0 0 0 0 0 0 0 0 0 0 0 0 0 0 0 0 0 1 0 0 0 0 0 0 0 0 0 0 0 0 0 0 0 0 0 0 0 0 0 0 1 0 0 1 0 0 0 0 0 0 0 0 0 0 1 0 0 1 2 0 1 0 0 0 0 0 1 0 0 0 0 1 0 0 0 0 0 0 0 0 0 0 0 1 0 0 0 0 0 0 0 0 0 0 1 0 0 0 0 0 0 0 0 0 0 0 0 0 0 1 0 0 0 0 0 0 0 0 1 0 0 0 0 0 0 0 0 0 0 0 0 0 0 0 0 0 1 0 1 0 0 0 1 0 0 0 0 0 0 0 0 0 0 0 0 1 0 0 0 0 0 0 0 0 0 0 0 0 0 0 0 0 0 0 0 0 0 0 0 0 1 0 0 0 0 0 0 0 0 0 0 0 0 0 1 0 0 0 1 1 1 0 0 0 0 0 0 0 0 0 0 0 0 0 0 1 0 0</counts>
			</dataPoints>
		</scan>
		<scan status="Completed" appendNumber="0" scanAxis="2Theta" mode="Continuous">
			<header>
				<startTimeStamp>2022-06-19T13:59:46-07:00</startTimeStamp>
				<endTimeStamp>2022-06-19T14:02:39-07:00</endTimeStamp>
				<author>
					<name>XRD</name>
				</author>
				<source>
					<applicationSoftware version="6.1b">Data Collector</applicationSoftware>
					<instrumentControlSoftware version="7.4b 20181204">XPERT-3</instrumentControlSoftware>
					<instrumentID>0000000011163216</instrumentID>
				</source>
			</header>
			<dataPoints>
				<positions axis="2Theta" unit="deg">
					<startPosition>75.431417636843</startPosition>
					<endPosition>77.9421823631571</endPosition>
				</positions>
				<positions axis="Omega" unit="deg">
					<commonPosition>18.2546913382222</commonPosition>
				</positions>
				<positions axis="Phi" unit="deg">
					<commonPosition>-8.19</commonPosition>
				</positions>
				<positions axis="Chi" unit="deg">
					<commonPosition>0</commonPosition>
				</positions>
				<positions axis="X" unit="mm">
					<commonPosition>-0.01</commonPosition>
				</positions>
				<positions axis="Y" unit="mm">
					<commonPosition>0</commonPosition>
				</positions>
				<positions axis="Z" unit="mm">
					<commonPosition>8.786</commonPosition>
				</positions>
				<commonCountingTime unit="seconds">0.189</commonCountingTime>
				<counts unit="counts">0 0 0 0 0 0 0 0 0 0 0 1 0 0 0 0 0 0 0 1 1 0 0 0 1 1 0 1 1 0 0 0 1 0 0 0 0 0 0 0 0 0 0 0 0 0 0 0 0 0 0 0 0 0 0 0 0 0 0 0 0 0 0 0 0 0 0 0 0 0 0 0 0 0 0 0 0 0 0 0 0 0 1 0 0 0 0 0 0 0 0 0 0 0 0 0 0 0 0 1 0 0 0 0 1 0 0 0 0 0 0 0 0 0 1 0 0 0 1 1 0 0 0 0 0 0 1 0 0 0 0 0 0 0 0 0 0 0 0 0 0 0 1 0 1 0 0 0 0 0 0 0 0 0 0 0 0 0 0 0 0 0 0 0 0 0 0 0 0 0 0 0 0 0 0 0 0 0 0 0 0 1 0 0 0 0 0 1 0 0 0 0 0 0 0 0 0 0 0 0 0 0 2 1 0 0 0 0 0 0 0 0 1 0 0 0 0 0 0 0 0 0 0 1 0 0 0 0 0 1 1 0 0 0 1 0 0 0 0 0 0 0 0 0 0 0 0 0 0 0 0 0 0 0 0</counts>
			</dataPoints>
		</scan>
		<scan status="Completed" appendNumber="0" scanAxis="2Theta" mode="Continuous">
			<header>
[...]
				</positions>
				<commonCountingTime unit="seconds">0.189</commonCountingTime>
				<counts unit="counts">0 0 0 0 0 0 0 0 0 0 0 0 0 0 0 0 0 0 0 0 0 0 0 0 0 0 0 0 0 0 0 0 0 0 0 0 0 0 0 0 1 0 0 0 0 0 0 0 1 0 0 0 0 0 0 0 0 0 0 0 0 0 0 0 0 0 0 0 0 0 0 0 0 0 0 0 0 0 0 2 0 1 0 0 0 0 0 0 1 0 0 0 0 0 0 0 0 0 0 1 0 0 0 0 0 0 0 0 0 0 0 0 0 0 0 0 0 1 0 1 0 1 0 0 1 0 0 1 0 0 0 0 0 0 0 0 0 0 0 0 0 1 1 0 1 0 0 0 0 0 0 0 0 0 0 0 0 0 0 0 0 0 0 0 0 0 0 0 0 0 0 0 0 0 0 0 0 0 0 0 0 0 0 0 0 0 0 0 0 0 0 0 0 0 2 0 0 1 0 0 0 0 0 0 0 0 0 0 0 0 0 0 1 0 1 0 0 0 0 0 1 0 0 0 0 0 0 0 0 0 0 0 0 0 0 0 0 0 0 0 0 0 0 0 0 0 0 0 0 0 0 0 1 0 0</counts>
			</dataPoints>
		</scan>
		<scan status="Completed" appendNumber="0" scanAxis="2Theta" mode="Continuous">
			<header>
				<startTimeStamp>2022-06-19T13:59:46-07:00</startTimeStamp>
				<endTimeStamp>2022-06-19T14:02:39-07:00</endTimeStamp>
				<author>
					<name>XRD</name>
				</author>
				<source>
					<applicationSoftware version="6.1b">Data Collector</applicationSoftware>
					<instrumentControlSoftware version="7.4b 20181204">XPERT-3</instrumentControlSoftware>
					<instrumentID>0000000011163216</instrumentID>
				</source>
			</header>
			<dataPoints>
				<positions axis="2Theta" unit="deg">
					<startPosition>75.431417636843</startPosition>
					<endPosition>77.9421823631571</endPosition>
				</positions>
				<positions axis="Omega" unit="deg">
					<commonPosition>22.1100705958889</commonPosition>
				</positions>
				<positions axis="Phi" unit="deg">
					<commonPosition>-8.19</commonPosition>
				</positions>
				<positions axis="Chi" unit="deg">
					<commonPosition>0</commonPosition>
				</positions>
				<positions axis="X" unit="mm">
					<commonPosition>-0.01</commonPosition>
				</positions>
				<positions axis="Y" unit="mm">
					<commonPosition>0</commonPosition>
				</positions>
				<positions axis="Z" unit="mm">
					<commonPosition>8.786</commonPosition>
				</positions>
				<commonCountingTime unit="seconds">0.189</commonCountingTime>
				<counts unit="counts">0 0 0 0 0 0 0 1 0 0 0 0 0 0 0 0 0 0 0 0 0 0 0 0 0 0 0 0 0 0 0 0 0 0 0 0 0 0 1 0 0 0 0 0 0 0 0 1 0 0 0 0 0 0 0 1 0 0 0 0 0 0 0 0 0 0 0 0 0 1 0 0 0 0 0 0 0 1 0 0 0 0 0 0 0 0 0 0 0 0 0 0 0 1 0 0 1 0 0 1 0 0 0 0 0 0 0 1 0 0 0 0 0 0 0 0 0 0 0 0 0 0 0 0 0 0 0 0 0 1 0 1 0 0 0 0 0 0 0 0 0 0 0 0 0 0 0 0 0 0 0 0 0 0 0 0 0 0 0 0 0 1 1 0 0 0 0 1 0 0 0 0 0 0 0 0 0 0 0 0 0 0 0 0 0 0 0 0 0 0 0 0 0 0 1 1 0 0 0 0 0 0 0 0 0 0 0 0 0 0 0 0 0 0 0 0 0 0 0 1 0 0 0 0 1 0 0 0 0 0 0 0 0 0 1 0 0 0 0 0 0 0 0 0 0 0 0 0 0 0 0 0 0 1 0</counts>
			</dataPoints>
		</scan>
		<scan status="Completed" appendNumber="0" scanAxis="2Theta" mode="Continuous">
			<header>
				<startTimeStamp>2022-06-19T13:59:46-07:00</startTimeStamp>
				<endTimeStamp>2022-06-19T14:02:39-07:00</endTimeStamp>
				<author>
					<name>XRD</name>
				</author>
				<source>
					<applicationSoftware version="6.1b">Data Collector</applicationSoftware>
					<instrumentControlSoftware version="7.4b 20181204">XPERT-3</instrumentControlSoftware>
					<instrumentID>0000000011163216</instrumentID>
				</source>
			</header>
			<dataPoints>
				<positions axis="2Theta" unit="deg">
					<startPosition>75.431417636843</startPosition>
					<endPosition>77.9421823631571</endPosition>
				</positions>
				<positions axis="Omega" unit="deg">
					<commonPosition>22.1149944519012</commonPosition>
				</positions>
				<positions axis="Phi" unit="deg">
					<commonPosition>-8.19</commonPosition>
				</positions>
				<positions axis="Chi" unit="deg">
					<commonPosition>0</commonPosition>
				</positions>
				<positions axis="X" unit="mm">
					<commonPosition>-0.01</commonPosition>
				</positions>
				<positions axis="Y" unit="mm">
					<commonPosition>0</commonPosition>
				</positions>
				<positions axis="Z" unit="mm">
					<commonPosition>8.786</commonPosition>
				</positions>
				<commonCountingTime unit="seconds">0.189</commonCountingTime>
				<counts unit="counts">0 1 0 0 0 0 0 0 0 0 0 0 0 0 0 1 0 0 0 0 0 0 0 0 1 0 0 0 0 0 0 1 0 0 0 0 1 0 0 0 1 0 0 0 0 0 0 0 0 0 0 0 0 1 0 0 0 0 1 0 0 0 1 0 0 1 0 1 0 0 0 0 0 0 1 0 0 0 0 0 0 0 0 0 0 0 0 0 0 0 0 0 0 0 0 0 0 0 0 0 0 1 0 0 0 0 1 0 0 0 0 0 0 0 0 1 0 0 0 0 0 0 0 1 1 0 0 0 0 1 0 0 0 0 0 1 0 0 0 1 0 0 0 0 1 0 0 0 0 0 0 0 0 1 0 0 0 0 0 0 0 0 0 0 0 0 0 0 0 0 0 0 0 0 0 0 0 0 0 0 1 0 0 0 0 0 0 0 0 0 1 0 0 0 0 0 0 0 0 0 0 0 0 0 0 0 0 0 0 0 1 0 0 0 0 0 1 0 0 0 2 0 0 0 0 0 0 0 0 0 0 0 0 0 0 0 0 0 0 0 0 0 1 0 0 0 0 1 0 0 0 0 0 0 0</counts>
			</dataPoints>
		</scan>
		<scan status="Completed" appendNumber="0" scanAxis="2Theta" mode="Continuous">
			<header>
				<startTimeStamp>2022-06-19T13:59:46-07:00</startTimeStamp>
				<endTimeStamp>2022-06-19T14:02:39-07:00</endTimeStamp>
				<author>
					<name>XRD</name>
				</author>
				<source>
					<applicationSoftware version="6.1b">Data Collector</applicationSoftware>
					<instrumentControlSoftware version="7.4b 20181204">XPERT-3</instrumentControlSoftware>
					<instrumentID>0000000011163216</instrumentID>
				</source>
			</header>
			<dataPoints>
				<positions axis="2Theta" unit="deg">
					<startPosition>75.431417636843</startPosition>
					<endPosition>77.9421823631571</endPosition>
				</positions>
				<positions axis="Omega" unit="deg">
					<commonPosition>22.1199183079136</commonPosition>
				</positions>
				<positions axis="Phi" unit="deg">
					<commonPosition>-8.19</commonPosition>
				</positions>
				<positions axis="Chi" unit="deg">
					<commonPosition>0</commonPosition>
				</positions>
				<positions axis="X" unit="mm">
					<commonPosition>-0.01</commonPosition>
				</positions>
				<positions axis="Y" unit="mm">
					<commonPosition>0</commonPosition>
				</positions>
				<positions axis="Z" unit="mm">
					<commonPosition>8.786</commonPosition>
				</positions>
				<commonCountingTime unit="seconds">0.189</commonCountingTime>
				<counts unit="counts">1 0 0 0 0 0 2 0 0 0 0 0 0 0 0 0 0 0 0 0 0 0 0 0 0 0 0 0 0 1 0 0 0 0 0 0 0 0 0 1 0 0 0 0 0 0 0 0 0 0 0 0 0 0 0 0 0 0 0 0 0 0 0 0 0 0 1 0 0 0 1 0 0 0 0 1 0 0 0 0 0 1 0 1 0 0 0 0 1 0 0 0 1 0 0 0 1 0 0 0 0 0 0 0 0 0 0 0 0 0 0 0 0 0 0 0 0 0 0 0 0 0 0 0 0 0 0 0 0 0 0 0 0 0 0 0 0 0 1 0 0 0 0 0 0 0 0 0 0 0 0 0 0 0 0 0 0 0 0 0 0 0 0 0 0 0 0 0 0 0 0 0 0 0 0 0 0 0 0 0 0 0 0 0 0 0 0 0 0 1 0 0 1 0 0 0 0 0 0 0 0 0 1 0 0 0 0 1 0 0 0 0 0 0 0 0 0 0 0 0 0 0 0 0 0 0 0 0 0 0 0 0 0 0 1 0 0 0 0 0 0 0 0 0 0 1 0 0 0 0 0 0 0 0 0</counts>
			</dataPoints>
		</scan>
		<scan status="Completed" appendNumber="0" scanAxis="2Theta" mode="Continuous">
			<header>
				<startTimeStamp>2022-06-19T13:59:46-07:00</startTimeStamp>
				<endTimeStamp>2022-06-19T14:02:39-07:00</endTimeStamp>
				<author>
					<name>XRD</name>
				</author>
				<source>
					<applicationSoftware version="6.1b">Data Collector</applicationSoftware>
					<instrumentControlSoftware version="7.4b 20181204">XPERT-3</instrumentControlSoftware>
					<instrumentID>0000000011163216</instrumentID>
				</source>
			</header>
			<dataPoints>
				<positions axis="2Theta" unit="deg">
					<startPosition>75.431417636843</startPosition>
					<endPosition>77.9421823631571</endPosition>
				</positions>
				<positions axis="Omega" unit="deg">
					<commonPosition>22.1248421639259</commonPosition>
				</positions>
				<positions axis="Phi" unit="deg">
					<commonPosition>-8.19</commonPosition>
				</positions>
				<positions axis="Chi" unit="deg">
					<commonPosition>0</commonPosition>
				</positions>
				<positions axis="X" unit="mm">
					<commonPosition>-0.01</commonPosition>
				</positions>
				<positions axis="Y" unit="mm">
					<commonPosition>0</commonPosition>
				</positions>
				<positions axis="Z" unit="mm">
					<commonPosition>8.786</commonPosition>
				</positions>
				<commonCountingTime unit="seconds">0.189</commonCountingTime>
				<counts unit="counts">1 1 0 0 0 0 0 0 0 0 0 0 1 0 1 0 0 0 0 0 0 0 0 0 0 0 1 0 0 0 0 0 0 0 0 1 0 0 0 0 0 0 0 0 0 0 0 0 1 1 0 0 0 0 0 0 0 1 0 0 0 0 0 0 0 0 0 0 0 0 0 0 0 0 0 0 0 0 0 0 0 0 0 0 0 0 0 0 0 0 0 0 0 0 0 0 0 0 0 0 0 0 0 0 0 0 0 0 1 0 0 0 0 0 0 0 0 0 0 0 0 0 0 0 0 0 0 0 0 0 0 0 0 0 0 0 0 0 0 0 0 0 0 0 0 0 1 0 0 0 0 0 0 0 0 0 1 0 0 1 0 0 0 0 0 0 0 0 0 1 0 0 0 1 1 0 0 0 0 0 0 0 1 0 0 0 0 0 0 1 0 0 0 0 0 0 0 0 0 1 0 0 1 2 0 0 0 0 0 0 0 0 0 1 0 0 0 0 0 0 0 0 0 0 0 0 0 0 0 0 0 0 0 0 0 0 0 0 0 0 0 0 0 0 0 0 0 0 1 1 0 0 0 0 0</counts>
			</dataPoints>
		</scan>
		<scan status="Completed" appendNumber="0" scanAxis="2Theta" mode="Continuous">
			<header>
				<startTimeStamp>2022-06-19T13:59:46-07:00</startTimeStamp>
				<endTimeStamp>2022-06-19T14:02:39-07:00</endTimeStamp>
				<author>
					<name>XRD</name>
				</author>
				<source>
					<applicationSoftware version="6.1b">Data Collector</applicationSoftware>
					<instrumentControlSoftware version="7.4b 20181204">XPERT-3</instrumentControlSoftware>
					<instrumentID>0000000011163216</instrumentID>
				</source>
			</header>
			<dataPoints>
				<positions axis="2Theta" unit="deg">
					<startPosition>75.431417636843</startPosition>
					<endPosition>77.9421823631571</endPosition>
				</positions>
				<positions axis="Omega" unit="deg">
					<commonPosition>22.1297660199383</commonPosition>
				</positions>
				<positions axis="Phi" unit="deg">
					<commonPosition>-8.19</commonPosition>
				</positions>
				<positions axis="Chi" unit="deg">
					<commonPosition>0</commonPosition>
				</positions>
				<positions axis="X" unit="mm">
					<commonPosition>-0.01</commonPosition>
				</positions>
				<positions axis="Y" unit="mm">
					<commonPosition>0</commonPosition>
				</positions>
				<positions axis="Z" unit="mm">
					<commonPosition>8.786</commonPosition>
				</positions>
				<commonCountingTime unit="seconds">0.189</commonCountingTime>
				<counts unit="counts">0 0 0 0 0 0 0 0 0 0 0 0 0 0 0 0 0 0 0 0 0 0 0 0 0 0 1 0 0 0 0 0 0 0 0 0 0 0 0 0 0 0 0 0 0 0 0 0 0 0 0 0 0 0 0 0 0 0 0 0 0 0 0 0 0 0 0 0 0 0 1 0 0 0 0 0 0 1 0 1 1 0 0 0 0 0 0 0 0 0 0 0 0 0 0 0 0 0 0 0 0 0 0 0 0 0 0 0 0 0 0 0 0 0 0 0 0 0 0 0 0 0 0 0 0 0 0 0 0 0 0 0 0 0 1 0 0 0 0 0 0 1 0 0 0 0 0 0 0 0 0 0 0 0 1 0 1 0 0 0 0 0 0 0 0 0 0 0 0 0 0 0 0 0 0 1 0 1 0 0 0 0 0 0 0 1 0 0 1 0 0 0 0 0 0 1 0 0 0 0 0 0 0 0 1 0 0 0 0 0 0 0 0 1 0 0 0 1 0 0 0 0 0 0 0 0 0 0 0 0 0 0 1 0 0 0 0 0 0 0 0 0 0 0 0 0 0 0 0 1 0 0 0 0 0</counts>
			</dataPoints>
		</scan>
		<scan status="Completed" appendNumber="0" scanAxis="2Theta" mode="Continuous">
			<header>
				<startTimeStamp>2022-06-19T13:59:46-07:00</startTimeStamp>
				<endTimeStamp>2022-06-19T14:02:39-07:00</endTimeStamp>
				<author>
					<name>XRD</name>
				</author>
				<source>
					<applicationSoftware version="6.1b">Data Collector</applicationSoftware>
					<instrumentControlSoftware version="7.4b 20181204">XPERT-3</instrumentControlSoftware>
					<instrumentID>0000000011163216</instrumentID>
				</source>
			</header>
			<dataPoints>
				<positions axis="2Theta" unit="deg">
					<startPosition>75.431417636843</startPosition>
					<endPosition>77.9421823631571</endPosition>
				</positions>
				<positions axis="Omega" unit="deg">
					<commonPosition>22.1346898759506</commonPosition>
				</positions>
				<positions axis="Phi" unit="deg">
					<commonPosition>-8.19</commonPosition>
				</positions>
				<positions axis="Chi" unit="deg">
					<commonPosition>0</commonPosition>
				</positions>
				<positions axis="X" unit="mm">
					<commonPosition>-0.01</commonPosition>
				</positions>
				<positions axis="Y" unit="mm">
					<commonPosition>0</commonPosition>
				</positions>
				<positions axis="Z" unit="mm">
					<commonPosition>8.786</commonPosition>
				</positions>
				<commonCountingTime unit="seconds">0.189</commonCountingTime>
				<counts unit="counts">0 0 0 0 0 0 0 0 0 0 0 0 0 0 0 0 0 0 0 0 0 0 0 0 0 0 1 0 0 0 0 0 1 0 0 0 0 0 0 0 0 1 0 0 0 0 0 0 0 0 0 0 1 0 0 0 1 0 0 0 0 0 0 0 0 0 0 0 0 0 0 0 0 0 0 0 0 0 1 1 1 1 0 0 0 0 0 0 0 0 0 0 1 0 0 0 1 0 1 0 0 0 2 0 0 0 0 0 0 0 0 0 0 0 0 1 0 0 0 0 0 0 1 0 1 0 0 0 0 0 0 0 0 0 0 0 0 0 1 0 0 0 0 0 0 0 0 0 0 0 0 0 0 0 0 0 0 0 0 0 0 0 0 0 0 0 0 1 0 0 0 0 0 0 0 0 1 0 0 1 0 0 0 0 0 0 0 0 0 0 0 0 0 0 0 0 0 0 0 0 0 1 0 0 0 0 0 0 0 0 0 0 0 0 0 0 0 0 0 0 0 0 0 0 0 0 0 0 0 0 1 0 0 0 1 0 0 0 0 0 0 0 0 0 0 0 0 0 0 0 1 0 0 0 0</counts>
			</dataPoints>
		</scan>
		<scan status="Completed" appendNumber="0" scanAxis="2Theta" mode="Continuous">
			<header>
				<startTimeStamp>2022-06-19T13:59:46-07:00</startTimeStamp>
				<endTimeStamp>2022-06-19T14:02:39-07:00</endTimeStamp>
				<author>
					<name>XRD</name>
				</author>
				<source>
					<applicationSoftware version="6.1b">Data Collector</applicationSoftware>
					<instrumentControlSoftware version="7.4b 20181204">XPERT-3</instrumentControlSoftware>
					<instrumentID>0000000011163216</instrumentID>
				</source>
			</header>
			<dataPoints>
				<positions axis="2Theta" unit="deg">
					<startPosition>75.431417636843</startPosition>
					<endPosition>77.9421823631571</endPosition>
				</positions>
				<positions axis="Omega" unit="deg">
					<commonPosition>22.139613731963</commonPosition>
				</positions>
				<positions axis="Phi" unit="deg">
					<commonPosition>-8.19</commonPosition>
				</positions>
				<positions axis="Chi" unit="deg">
					<commonPosition>0</commonPosition>
				</positions>
				<positions axis="X" unit="mm">
					<commonPosition>-0.01</commonPosition>
				</positions>
				<positions axis="Y" unit="mm">
					<commonPosition>0</commonPosition>
				</positions>
				<positions axis="Z" unit="mm">
					<commonPosition>8.786</commonPosition>
				</positions>
				<commonCountingTime unit="seconds">0.189</commonCountingTime>
				<counts unit="counts">0 0 0 0 0 0 0 0 0 0 0 0 1 0 0 0 0 0 0 0 0 0 0 0 1 0 0 0 0 1 0 0 0 0 0 1 1 0 1 0 0 0 0 0 0 0 0 0 0 0 0 0 0 0 0 0 0 0 0 0 0 0 0 0 0 0 1 0 0 0 0 1 0 0 0 0 0 1 0 0 1 0 0 0 0 0 0 0 0 0 0 0 0 0 0 0 0 0 0 0 0 0 0 0 0 0 0 0 0 0 0 0 0 0 1 0 0 1 0 0 0 0 1 0 0 0 0 0 0 1 0 0 0 0 0 0 0 1 0 0 1 0 0 0 0 1 0 0 0 0 0 0 0 0 0 0 0 0 0 0 0 0 0 0 0 0 0 0 0 0 0 0 1 0 0 0 0 0 1 0 0 0 0 0 0 0 0 0 0 0 0 0 0 0 0 0 0 0 0 0 0 1 0 1 0 1 0 0 0 1 0 0 0 0 0 0 0 0 0 0 0 0 0 0 0 1 0 0 0 0 0 0 0 0 0 0 0 0 0 0 0 0 0 0 0 1 0 0 0 0 0 0 1 1 0</counts>
			</dataPoints>
		</scan>
		<scan status="Completed" appendNumber="0" scanAxis="2Theta" mode="Continuous">
			<header>
				<startTimeStamp>2022-06-19T13:59:46-07:00</startTimeStamp>
				<endTimeStamp>2022-06-19T14:02:39-07:00</endTimeStamp>
				<author>
					<name>XRD</name>
				</author>
				<source>
					<applicationSoftware version="6.1b">Data Collector</applicationSoftware>
					<instrumentControlSoftware version="7.4b 20181204">XPERT-3</instrumentControlSoftware>
					<instrumentID>0000000011163216</instrumentID>
				</source>
			</header>
			<dataPoints>
				<positions axis="2Theta" unit="deg">
					<startPosition>75.431417636843</startPosition>
					<endPosition>77.9421823631571</endPosition>
				</positions>
				<positions axis="Omega" unit="deg">
					<commonPosition>22.1445375879753</commonPosition>
				</positions>
				<positions axis="Phi" unit="deg">
					<commonPosition>-8.19</commonPosition>
				</positions>
				<positions axis="Chi" unit="deg">
					<commonPosition>0</commonPosition>
				</positions>
				<positions axis="X" unit="mm">
					<commonPosition>-0.01</commonPosition>
				</positions>
				<positions axis="Y" unit="mm">
					<commonPosition>0</commonPosition>
				</positions>
				<positions axis="Z" unit="mm">
					<commonPosition>8.786</commonPosition>
				</positions>
				<commonCountingTime unit="seconds">0.189</commonCountingTime>
				<counts unit="counts">0 0 1 1 0 0 0 0 0 0 1 0 0 0 0 0 0 0 0 0 0 0 0 0 1 0 0 0 0 0 0 0 0 0 0 0 0 0 0 0 0 0 0 0 0 0 0 0 0 0 0 0 0 0 0 0 0 1 1 0 0 0 0 0 0 0 0 0 0 0 0 0 0 0 0 0 0 0 1 1 0 0 0 0 0 0 0 0 0 0 0 0 0 0 0 0 0 0 0 0 0 0 0 0 0 0 0 0 0 0 0 0 0 0 0 0 0 0 0 0 0 0 0 0 0 0 0 0 0 0 0 1 0 0 0 0 1 0 1 0 0 1 0 1 0 0 1 0 0 0 0 0 0 0 0 0 0 0 0 0 0 0 0 0 0 0 0 0 0 0 0 0 0 0 0 0 0 0 0 1 0 0 0 0 0 0 0 0 0 0 0 0 0 0 0 0 0 0 0 0 0 0 0 0 0 0 0 0 1 0 0 1 0 0 0 0 0 0 0 0 0 0 0 0 0 1 0 0 0 1 0 0 0 0 0 0 0 0 0 0 0 0 0 0 0 0 0 0 0 0 0 0 1 0 0</counts>
			</dataPoints>
		</scan>
		<scan status="Completed" appendNumber="0" scanAxis="2Theta" mode="Continuous">
			<header>
				<startTimeStamp>2022-06-19T13:59:46-07:00</startTimeStamp>
				<endTimeStamp>2022-06-19T14:02:39-07:00</endTimeStamp>
				<author>
					<name>XRD</name>
				</author>
				<source>
					<applicationSoftware version="6.1b">Data Collector</applicationSoftware>
					<instrumentControlSoftware version="7.4b 20181204">XPERT-3</instrumentControlSoftware>
					<instrumentID>0000000011163216</instrumentID>
				</source>
			</header>
			<dataPoints>
				<positions axis="2Theta" unit="deg">
					<startPosition>75.431417636843</startPosition>
					<endPosition>77.9421823631571</endPosition>
				</positions>
				<positions axis="Omega" unit="deg">
					<commonPosition>22.1494614439877</commonPosition>
				</positions>
				<positions axis="Phi" unit="deg">
					<commonPosition>-8.19</commonPosition>
				</positions>
				<positions axis="Chi" unit="deg">
					<commonPosition>0</commonPosition>
				</positions>
				<positions axis="X" unit="mm">
					<commonPosition>-0.01</commonPosition>
				</positions>
				<positions axis="Y" unit="mm">
					<commonPosition>0</commonPosition>
				</positions>
				<positions axis="Z" unit="mm">
					<commonPosition>8.786</commonPosition>
				</positions>
				<commonCountingTime unit="seconds">0.189</commonCountingTime>
				<counts unit="counts">0 0 0 0 0 0 0 0 0 0 0 0 0 0 0 1 0 0 0 0 0 0 0 0 0 0 0 0 0 0 0 0 0 0 0 1 0 0 0 0 1 0 0 0 0 0 0 0 0 0 0 0 0 1 0 0 0 0 0 0 0 0 0 0 0 1 0 0 0 0 0 1 0 0 0 1 0 0 0 1 0 0 0 0 0 0 0 0 0 0 1 0 0 0 0 0 0 0 0 0 0 0 0 0 0 0 0 0 0 0 0 0 0 0 1 0 0 0 0 0 1 0 0 0 0 0 0 0 0 0 0 0 0 0 0 0 0 0 0 0 0 0 1 0 0 0 0 0 0 0 0 0 0 0 0 0 0 0 0 0 0 0 0 0 0 0 0 0 0 0 1 0 0 0 1 0 0 0 0 0 0 0 0 0 0 0 0 0 0 0 0 0 0 0 1 1 0 0 0 0 0 0 0 0 0 0 0 0 0 0 0 0 0 0 0 0 0 1 0 0 0 0 0 0 0 0 0 0 1 0 0 0 0 0 0 0 0 0 1 0 0 0 0 0 0 0 0 0 0 0 0 0 0 0 0</counts>
			</dataPoints>
		</scan>
		<scan status="Completed" appendNumber="0" scanAxis="2Theta" mode="Continuous">
			<header>
				<startTimeStamp>2022-06-19T13:59:46-07:00</startTimeStamp>
				<endTimeStamp>2022-06-19T14:02:39-07:00</endTimeStamp>
				<author>
					<name>XRD</name>
				</author>
				<source>
					<applicationSoftware version="6.1b">Data Collector</applicationSoftware>
					<instrumentControlSoftware version="7.4b 20181204">XPERT-3</instrumentControlSoftware>
					<instrumentID>0000000011163216</instrumentID>
				</source>
			</header>
			<dataPoints>
				<positions axis="2Theta" unit="deg">
					<startPosition>75.431417636843</startPosition>
					<endPosition>77.9421823631571</endPosition>
				</positions>
				<positions axis="Omega" unit="deg">
					<commonPosition>22.1543853</commonPosition>
				</positions>
				<positions axis="Phi" unit="deg">
					<commonPosition>-8.19</commonPosition>
				</positions>
				<positions axis="Chi" unit="deg">
					<commonPosition>0</commonPosition>
				</positions>
				<positions axis="X" unit="mm">
					<commonPosition>-0.01</commonPosition>
				</positions>
				<positions axis="Y" unit="mm">
					<commonPosition>0</commonPosition>
				</positions>
				<positions axis="Z" unit="mm">
					<commonPosition>8.786</commonPosition>
				</positions>
				<commonCountingTime unit="seconds">0.189</commonCountingTime>
				<counts unit="counts">0 0 0 0 0 0 0 0 0 0 0 0 0 0 0 0 0 0 0 0 0 0 0 0 0 0 0 0 0 0 0 0 0 0 0 0 0 0 1 0 0 0 0 0 0 0 0 1 0 1 0 0 0 0 0 0 1 0 0 0 0 1 0 0 0 0 0 0 0 0 0 0 1 0 0 1 0 0 0 0 0 0 0 2 0 0 0 0 0 0 1 0 0 0 0 0 0 0 0 0 0 0 0 0 0 0 0 0 0 0 1 0 0 0 0 0 0 0 0 0 0 0 0 0 0 0 0 0 1 0 0 0 1 0 0 0 0 0 0 0 1 0 0 0 0 0 0 0 0 0 0 0 1 0 2 0 0 0 0 0 0 0 0 0 0 0 0 0 0 0 0 0 0 0 0 0 0 0 0 0 0 0 0 0 0 0 1 0 0 0 0 0 0 0 0 0 1 0 0 0 0 0 0 0 0 0 0 0 0 0 0 0 0 0 0 0 0 0 0 0 0 0 0 0 0 0 0 0 0 0 0 1 0 0 0 0 0 0 0 0 0 0 0 0 0 0 0 0 0 0 0 0 0 0 0</counts>
			</dataPoints>
		</scan>
	</xrdMeasurement>
</xrdMeasurements>