File: data/previous_data/set_3-YG035-038/xrd/YG036-SRO001-STO001-RSM-06162022.xrdml
<?xml version="1.0" encoding="utf-8"?>
<xrdMeasurements xmlns="http://www.xrdml.com/XRDMeasurement/2.1" xmlns:xsi="http://www.w3.org/2001/XMLSchema-instance" xsi:schemaLocation="http://www.xrdml.com/XRDMeasurement/2.1 http://www.xrdml.com/XRDMeasurement/2.1/XRDMeasurement.xsd" status="Completed">
	<sample type="To be analyzed">
		<id/>
		<name/>
		<preparedBy/>
	</sample>
	<xrdMeasurement status="Completed" measurementType="Area measurement" measurementStepAxis="Omega" sampleMode="Reflection">
		<comment>
			<entry>PHD Lower Level = 4.02 (keV), PHD Upper Level = 11.27 (keV)</entry>
		</comment>
		<usedWavelength intended="K-Alpha 1">
			<kAlpha1 unit="Angstrom">1.5405980</kAlpha1>
			<kAlpha2 unit="Angstrom">1.5444260</kAlpha2>
			<kBeta unit="Angstrom">1.3922500</kBeta>
			<ratioKAlpha2KAlpha1>0.5</ratioKAlpha2KAlpha1>
		</usedWavelength>
		<incidentBeamPath>
			<radius unit="mm">320.00</radius>
			<xRayTube id="1010048" name="Empyrean Cu LFF HR (9430 033 7310x) DK425175">
				<tension unit="kV">45.0</tension>
				<current unit="mA">40.0</current>
				<anodeMaterial>Cu</anodeMaterial>
				<focus type="Line">
					<length unit="mm">12.0</length>
					<width unit="mm">0.4</width>
					<takeOffAngle unit="deg">4.2</takeOffAngle>
				</focus>
			</xRayTube>
			<xRayMirror xsi:type="xRayMirrorType" id="27090001" name="Inc. Beam Cu W/Si (hybrid MRD)" hybrid="true">
				<crystal type="Graded" shape="Parabolic">W/Si</crystal>
				<acceptanceAngle unit="deg">0.800</acceptanceAngle>
				<length unit="mm">60.0</length>
			</xRayMirror>
			<monochromator xsi:type="monochromatorType" id="23090002" name="Hybrid monochr. 2xGe(220) Cu asym." hybrid="true">
				<crystal type="Asymmetric" shape="Flat">Ge</crystal>
				<numberOfReflections>2</numberOfReflections>
				<hkl>
					<h>2</h>
					<k>2</k>
					<l>0</l>
				</hkl>
			</monochromator>
			<divergenceSlit xsi:type="fixedDivergenceSlitType" id="22010004" name="Fixed slit 1/2°">
				<distanceToSample unit="mm">220.00</distanceToSample>
				<height unit="mm">0.76</height>
			</divergenceSlit>
		</incidentBeamPath>
		<sampleOffset>
			<position axis="Omega" unit="deg">-0.3393</position>
			<position axis="Chi" unit="deg">0.11</position>
		</sampleOffset>
		<diffractedBeamPath>
			<radius unit="mm">320.00</radius>
			<antiScatterSlit xsi:type="fixedAntiScatterSlitType" id="22090009" name="AS slit 7.5 mm (PIXcel)">
				<height unit="mm">7.50</height>
			</antiScatterSlit>
			<sollerSlit xsi:type="sollerSlitType" id="21010002" name="Soller slits 0.04 rad.">
				<opening unit="rad">0.0400</opening>
			</sollerSlit>
			<receivingSlit xsi:type="receivingSlitType" id="22010004" name="Fixed slit 1/2°">
				<height unit="mm">0.76</height>
			</receivingSlit>
			<detector xsi:type="areaDetectorType" id="7010020" name="PIXcel3D-Medipix3 1x1 detector">
				<phd unit="%">
					<lowerLevel>25</lowerLevel>
					<upperLevel>70</upperLevel>
				</phd>
				<mode>Scanning snapshot equatorial</mode>
				<activeChannelsEquatorial>255</activeChannelsEquatorial>
				<activeChannelsAxial>255</activeChannelsAxial>
				<pitchEquatorial unit="mm">0.05500</pitchEquatorial>
				<pitchAxial unit="mm">0.05500</pitchAxial>
				<readOutPeriod unit="seconds">0.195</readOutPeriod>
			</detector>
		</diffractedBeamPath>
		<scan status="Completed" appendNumber="0" scanAxis="2Theta" mode="Continuous">
			<header>
				<startTimeStamp>2022-06-16T15:51:56-07:00</startTimeStamp>
				<endTimeStamp>2022-06-16T15:54:49-07:00</endTimeStamp>
				<author>
					<name>XRD</name>
				</author>
				<source>
					<applicationSoftware version="6.1b">Data Collector</applicationSoftware>
					<instrumentControlSoftware version="7.4b 20181204">XPERT-3</instrumentControlSoftware>
					<instrumentID>0000000011163216</instrumentID>
				</source>
			</header>
			<dataPoints>
				<positions axis="2Theta" unit="deg">
					<startPosition>75.431417636843</startPosition>
					<endPosition>77.9421823631571</endPosition>
				</positions>
				<positions axis="Omega" unit="deg">
					<commonPosition>18.16076193</commonPosition>
				</positions>
				<positions axis="Phi" unit="deg">
					<commonPosition>8.92</commonPosition>
				</positions>
				<positions axis="Chi" unit="deg">
					<commonPosition>-0.09</commonPosition>
				</positions>
				<positions axis="X" unit="mm">
					<commonPosition>-0.32</commonPosition>
				</positions>
				<positions axis="Y" unit="mm">
					<commonPosition>0</commonPosition>
				</positions>
				<positions axis="Z" unit="mm">
					<commonPosition>8.821</commonPosition>
				</positions>
				<commonCountingTime unit="seconds">0.189</commonCountingTime>
				<counts unit="counts">1 0 0 0 0 0 0 0 0 0 0 1 0 0 0 0 0 0 1 0 1 0 0 0 0 0 0 1 0 0 0 0 0 0 1 0 0 0 0 0 0 0 0 0 0 0 0 0 0 0 1 0 0 0 0 0 0 0 0 0 0 0 0 0 1 0 0 0 0 0 0 1 0 0 0 0 0 0 0 0 0 0 0 0 0 0 0 1 0 0 0 0 0 0 0 0 0 0 0 0 0 0 0 0 0 0 0 0 0 0 0 0 0 0 0 0 0 0 0 0 0 0 0 0 1 0 0 0 0 0 0 0 0 0 1 0 0 0 0 0 0 0 1 0 0 0 0 0 0 0 1 0 0 0 0 0 0 0 1 0 0 0 0 0 0 0 0 0 0 0 0 0 0 0 0 0 0 0 0 0 0 0 0 0 1 0 0 0 0 0 0 0 0 0 0 0 0 0 0 1 0 0 1 0 0 0 0 0 0 2 0 0 0 0 0 0 0 0 0 0 0 0 0 0 0 1 0 0 0 0 0 0 1 0 0 0 1 0 0 1 1 0 0 0 0 0 0 1 0 1 0 0 0 0 0</counts>
			</dataPoints>
		</scan>
		<scan status="Completed" appendNumber="0" scanAxis="2Theta" mode="Continuous">
			<header>
				<startTimeStamp>2022-06-16T15:51:56-07:00</startTimeStamp>
				<endTimeStamp>2022-06-16T15:54:49-07:00</endTimeStamp>
				<author>
					<name>XRD</name>
				</author>
				<source>
					<applicationSoftware version="6.1b">Data Collector</applicationSoftware>
					<instrumentControlSoftware version="7.4b 20181204">XPERT-3</instrumentControlSoftware>
					<instrumentID>0000000011163216</instrumentID>
				</source>
			</header>
			<dataPoints>
				<positions axis="2Theta" unit="deg">
					<startPosition>75.431417636843</startPosition>
					<endPosition>77.9421823631571</endPosition>
				</positions>
				<positions axis="Omega" unit="deg">
					<commonPosition>18.1656857860074</commonPosition>
				</positions>
				<positions axis="Phi" unit="deg">
					<commonPosition>8.92</commonPosition>
				</positions>
				<positions axis="Chi" unit="deg">
					<commonPosition>-0.09</commonPosition>
				</positions>
				<positions axis="X" unit="mm">
					<commonPosition>-0.32</commonPosition>
				</positions>
				<positions axis="Y" unit="mm">
					<commonPosition>0</commonPosition>
				</positions>
				<positions axis="Z" unit="mm">
					<commonPosition>8.821</commonPosition>
				</positions>
				<commonCountingTime unit="seconds">0.189</commonCountingTime>
				<counts unit="counts">0 0 1 0 0 1 0 0 0 0 0 0 0 0 0 0 0 0 1 0 1 0 0 0 0 0 0 0 0 0 0 0 0 0 0 0 1 0 0 0 0 0 0 1 0 0 0 0 1 0 0 0 0 0 0 0 0 0 0 0 0 0 0 0 0 0 0 0 0 0 0 0 0 1 0 0 1 0 0 0 0 0 1 0 0 0 0 0 0 0 0 0 0 0 0 0 0 0 0 0 0 0 0 1 0 0 1 0 0 0 0 0 0 0 2 0 0 1 0 0 1 0 0 0 0 0 0 0 0 0 0 0 0 0 0 0 1 0 0 0 0 0 0 0 0 1 0 0 0 0 0 0 0 0 0 0 0 1 0 0 0 0 0 1 0 0 0 0 0 0 0 0 0 0 0 0 0 0 0 0 0 0 0 0 1 0 0 0 0 0 0 0 0 0 0 0 1 0 0 0 0 0 0 0 0 1 0 1 0 0 0 0 0 0 0 0 0 0 0 0 0 0 0 0 0 1 0 0 0 0 0 0 0 0 0 0 1 0 0 0 0 0 0 1 0 0 0 0 1 0 0 0 0 0 1</counts>
			</dataPoints>
		</scan>
		<scan status="Completed" appendNumber="0" scanAxis="2Theta" mode="Continuous">
			<header>
				<startTimeStamp>2022-06-16T15:51:56-07:00</startTimeStamp>
				<endTimeStamp>2022-06-16T15:54:49-07:00</endTimeStamp>
				<author>
					<name>XRD</name>
				</author>
				<source>
					<applicationSoftware version="6.1b">Data Collector</applicationSoftware>
					<instrumentControlSoftware version="7.4b 20181204">XPERT-3</instrumentControlSoftware>
					<instrumentID>0000000011163216</instrumentID>
				</source>
			</header>
			<dataPoints>
				<positions axis="2Theta" unit="deg">
					<startPosition>75.431417636843</startPosition>
					<endPosition>77.9421823631571</endPosition>
				</positions>
				<positions axis="Omega" unit="deg">
					<commonPosition>18.1706096420147</commonPosition>
				</positions>
				<positions axis="Phi" unit="deg">
					<commonPosition>8.92</commonPosition>
				</positions>
				<positions axis="Chi" unit="deg">
					<commonPosition>-0.09</commonPosition>
				</positions>
				<positions axis="X" unit="mm">
					<commonPosition>-0.32</commonPosition>
				</positions>
				<positions axis="Y" unit="mm">
					<commonPosition>0</commonPosition>
				</positions>
				<positions axis="Z" unit="mm">
					<commonPosition>8.821</commonPosition>
				</positions>
				<commonCountingTime unit="seconds">0.189</commonCountingTime>
				<counts unit="counts">0 0 0 0 1 0 0 1 0 0 0 0 0 0 0 0 0 0 0 0 0 0 1 0 0 0 0 0 0 0 0 0 0 0 0 0 0 0 0 0 0 0 0 0 0 0 0 0 0 0 0 0 0 0 0 0 0 0 0 0 0 0 0 0 0 0 0 0 0 0 0 0 0 0 0 1 0 0 0 0 0 0 0 0 0 0 0 0 0 0 0 0 0 0 0 0 0 0 0 0 0 0 0 0 0 0 0 0 0 0 0 0 0 1 0 1 0 0 0 0 0 1 0 1 1 0 0 0 0 0 0 0 0 0 0 0 0 0 0 0 0 0 0 0 0 0 0 0 0 0 0 0 0 0 0 0 0 0 0 0 1 0 0 0 0 0 0 0 0 0 0 1 0 0 0 2 0 0 0 2 0 0 0 0 0 0 0 0 0 0 1 0 0 0 0 1 0 0 0 0 0 1 0 0 0 0 0 0 0 0 1 0 0 0 2 0 0 1 1 0 0 0 0 0 1 0 0 0 0 0 0 0 0 0 0 0 0 0 0 0 0 0 0 0 0 0 0 0 0 0 0 0 0 0 0</counts>
			</dataPoints>
		</scan>
		<scan status="Completed" appendNumber="0" scanAxis="2Theta" mode="Continuous">
			<header>
				<startTimeStamp>2022-06-16T15:51:56-07:00</startTimeStamp>
				<endTimeStamp>2022-06-16T15:54:49-07:00</endTimeStamp>
				<author>
					<name>XRD</name>
				</author>
				<source>
					<applicationSoftware version="6.1b">Data Collector</applicationSoftware>
					<instrumentControlSoftware version="7.4b 20181204">XPERT-3</instrumentControlSoftware>
					<instrumentID>0000000011163216</instrumentID>
				</source>
			</header>
			<dataPoints>
				<positions axis="2Theta" unit="deg">
					<startPosition>75.431417636843</startPosition>
					<endPosition>77.9421823631571</endPosition>
				</positions>
				<positions axis="Omega" unit="deg">
					<commonPosition>18.1755334980221</commonPosition>
				</positions>
				<positions axis="Phi" unit="deg">
					<commonPosition>8.92</commonPosition>
				</positions>
				<positions axis="Chi" unit="deg">
					<commonPosition>-0.09</commonPosition>
				</positions>
				<positions axis="X" unit="mm">
					<commonPosition>-0.32</commonPosition>
				</positions>
				<positions axis="Y" unit="mm">
					<commonPosition>0</commonPosition>
				</positions>
				<positions axis="Z" unit="mm">
					<commonPosition>8.821</commonPosition>
				</positions>
				<commonCountingTime unit="seconds">0.189</commonCountingTime>
				<counts unit="counts">0 0 0 0 0 1 1 0 0 0 0 0 0 0 0 0 2 0 0 0 0 0 0 0 0 0 0 0 0 0 0 0 0 0 0 0 0 0 0 0 0 0 1 0 0 0 0 0 0 0 0 0 0 0 0 0 0 1 0 0 0 0 0 0 0 0 0 0 0 0 0 0 0 1 0 1 0 0 0 0 1 0 1 0 0 0 0 0 0 0 0 0 0 0 0 0 0 0 0 0 0 0 0 0 0 0 0 0 0 0 0 0 0 0 0 0 0 0 0 0 0 1 1 0 0 0 0 0 0 0 0 0 0 0 0 0 0 0 0 0 0 0 0 0 0 0 0 0 0 0 0 0 1 0 0 0 0 0 0 0 0 0 0 0 1 0 0 0 0 0 0 0 0 1 0 0 0 0 0 0 0 0 0 0 0 0 0 0 0 2 0 0 0 0 0 1 0 0 0 0 0 0 0 0 0 0 0 0 0 0 0 1 0 2 0 1 0 0 0 0 0 1 0 0 0 0 0 1 0 0 0 1 0 1 0 0 0 1 0 0 0 0 0 0 0 0 0 0 0 0 0 0 0 0 0</counts>
			</dataPoints>
		</scan>
		<scan status="Completed" appendNumber="0" scanAxis="2Theta" mode="Continuous">
			<header>
				<startTimeStamp>2022-06-16T15:51:56-07:00</startTimeStamp>
				<endTimeStamp>2022-06-16T15:54:49-07:00</endTimeStamp>
				<author>
					<name>XRD</name>
				</author>
				<source>
					<applicationSoftware version="6.1b">Data Collector</applicationSoftware>
					<instrumentControlSoftware version="7.4b 20181204">XPERT-3</instrumentControlSoftware>
					<instrumentID>0000000011163216</instrumentID>
				</source>
			</header>
			<dataPoints>
				<positions axis="2Theta" unit="deg">
					<startPosition>75.431417636843</startPosition>
					<endPosition>77.9421823631571</endPosition>
				</positions>
				<positions axis="Omega" unit="deg">
					<commonPosition>18.1804573540295</commonPosition>
				</positions>
				<positions axis="Phi" unit="deg">
					<commonPosition>8.92</commonPosition>
				</positions>
				<positions axis="Chi" unit="deg">
					<commonPosition>-0.09</commonPosition>
				</positions>
				<positions axis="X" unit="mm">
					<commonPosition>-0.32</commonPosition>
				</positions>
				<positions axis="Y" unit="mm">
					<commonPosition>0</commonPosition>
				</positions>
				<positions axis="Z" unit="mm">
					<commonPosition>8.821</commonPosition>
				</positions>
				<commonCountingTime unit="seconds">0.189</commonCountingTime>
				<counts unit="counts">0 0 0 0 0 0 0 0 0 0 0 0 0 0 1 0 0 0 0 0 0 1 0 0 1 0 0 0 0 0 0 0 1 0 1 0 0 0 0 0 0 0 0 0 2 0 0 0 0 0 0 0 0 0 0 0 0 0 0 0 0 0 0 0 0 0 0 0 0 0 0 0 0 0 0 0 0 0 0 0 0 0 0 0 0 0 0 0 0 0 0 0 0 0 0 0 0 1 0 0 0 0 0 0 0 0 0 0 0 0 0 0 0 0 0 0 0 0 0 0 0 0 0 0 0 0 0 0 0 1 0 1 0 0 1 0 0 0 0 0 0 0 0 0 0 0 0 0 0 0 0 0 0 0 0 1 0 0 0 0 0 0 0 0 0 0 0 0 0 1 0 0 0 0 0 0 0 0 0 0 0 0 0 0 0 0 0 0 0 0 0 0 0 0 0 0 1 0 0 0 0 0 1 0 0 0 0 0 0 1 0 0 0 0 0 0 0 0 0 0 0 0 0 0 0 0 0 0 0 0 0 0 0 0 0 0 0 0 0 0 0 0 0 0 1 0 1 0 1 0 0 0 0 0 0</counts>
			</dataPoints>
		</scan>
		<scan status="Completed" appendNumber="0" scanAxis="2Theta" mode="Continuous">
			<header>
				<startTimeStamp>2022-06-16T15:51:56-07:00</startTimeStamp>
				<endTimeStamp>2022-06-16T15:54:49-07:00</endTimeStamp>
				<author>
					<name>XRD</name>
				</author>
				<source>
					<applicationSoftware version="6.1b">Data Collector</applicationSoftware>
					<instrumentControlSoftware version="7.4b 20181204">XPERT-3</instrumentControlSoftware>
					<instrumentID>0000000011163216</instrumentID>
				</source>
			</header>
			<dataPoints>
				<positions axis="2Theta" unit="deg">
					<startPosition>75.431417636843</startPosition>
					<endPosition>77.9421823631571</endPosition>
				</positions>
				<positions axis="Omega" unit="deg">
					<commonPosition>18.1853812100369</commonPosition>
				</positions>
				<positions axis="Phi" unit="deg">
					<commonPosition>8.92</commonPosition>
				</positions>
				<positions axis="Chi" unit="deg">
					<commonPosition>-0.09</commonPosition>
				</positions>
				<positions axis="X" unit="mm">
					<commonPosition>-0.32</commonPosition>
				</positions>
				<positions axis="Y" unit="mm">
					<commonPosition>0</commonPosition>
				</positions>
				<positions axis="Z" unit="mm">
					<commonPosition>8.821</commonPosition>
				</positions>
				<commonCountingTime unit="seconds">0.189</commonCountingTime>
				<counts unit="counts">0 0 0 0 0 0 0 0 1 1 0 0 0 0 0 0 0 0 1 0 0 2 1 0 0 0 0 0 0 0 1 0 0 0 0 0 0 0 0 0 1 0 0 0 0 0 0 0 0 0 0 0 0 0 0 0 0 0 0 0 0 1 0 0 0 0 0 0 0 0 0 1 0 0 1 0 0 1 0 0 0 0 0 0 0 0 0 0 0 1 1 0 0 1 0 1 1 0 0 0 0 0 0 0 0 0 0 0 0 0 0 0 0 0 0 0 0 0 1 0 0 0 0 0 0 1 0 0 0 0 0 0 0 2 0 0 0 1 1 0 0 0 0 0 0 0 0 0 0 0 1 0 0 0 0 0 1 0 0 0 0 0 0 0 0 0 0 0 0 0 0 0 0 0 0 0 1 0 0 0 0 0 1 0 0 0 0 0 0 0 0 1 0 0 1 0 0 0 1 0 1 0 0 0 0 0 0 1 1 0 0 1 0 0 0 0 0 0 2 0 0 0 0 0 0 0 0 0 0 0 1 0 0 0 0 0 0 0 1 0 0 1 0 1 0 0 0 0 0 0 0 1 0 0 0</counts>
			</dataPoints>
		</scan>
		<scan status="Completed" appendNumber="0" scanAxis="2Theta" mode="Continuous">
			<header>
				<startTimeStamp>2022-06-16T15:51:56-07:00</startTimeStamp>
				<endTimeStamp>2022-06-16T15:54:49-07:00</endTimeStamp>
				<author>
					<name>XRD</name>
				</author>
				<source>
					<applicationSoftware version="6.1b">Data Collector</applicationSoftware>
					<instrumentControlSoftware version="7.4b 20181204">XPERT-3</instrumentControlSoftware>
					<instrumentID>0000000011163216</instrumentID>
				</source>
			</header>
			<dataPoints>
				<positions axis="2Theta" unit="deg">
					<startPosition>75.431417636843</startPosition>
					<endPosition>77.9421823631571</endPosition>
				</positions>
				<positions axis="Omega" unit="deg">
					<commonPosition>18.1903050660442</commonPosition>
				</positions>
				<positions axis="Phi" unit="deg">
					<commonPosition>8.92</commonPosition>
				</positions>
				<positions axis="Chi" unit="deg">
					<commonPosition>-0.09</commonPosition>
				</positions>
				<positions axis="X" unit="mm">
					<commonPosition>-0.32</commonPosition>
				</positions>
				<positions axis="Y" unit="mm">
					<commonPosition>0</commonPosition>
				</positions>
				<positions axis="Z" unit="mm">
					<commonPosition>8.821</commonPosition>
				</positions>
				<commonCountingTime unit="seconds">0.189</commonCountingTime>
				<counts unit="counts">0 0 0 0 2 0 0 0 0 0 0 0 0 1 0 1 0 0 0 0 0 0 0 0 0 0 0 0 0 0 0 0 0 0 0 0 0 0 0 0 0 0 0 0 0 0 0 0 0 0 0 0 0 0 0 0 0 0 0 0 0 0 0 0 0 0 0 0 0 1 0 0 1 0 0 0 0 0 0 0 0 0 0 0 0 1 0 0 0 0 0 0 0 0 0 0 0 1 0 0 0 0 0 1 0 0 0 0 0 0 0 0 0 1 0 0 0 0 0 0 1 0 0 0 0 0 0 0 0 0 0 0 0 0 1 0 0 0 0 0 0 0 0 0 0 0 0 0 1 2 0 0 0 0 0 0 0 0 0 0 0 0 0 0 0 0 0 0 0 0 0 0 0 0 0 0 0 0 0 0 0 0 0 0 0 0 0 0 0 0 0 0 1 0 0 0 0 0 0 0 0 0 0 0 0 0 0 1 0 0 0 0 0 0 0 0 0 0 0 1 0 0 0 0 0 0 0 0 1 0 0 0 0 0 0 0 0 0 0 0 0 0 0 0 0 1 0 0 0 1 0 0 0 0 0</counts>
			</dataPoints>
		</scan>
		<scan status="Completed" appendNumber="0" scanAxis="2Theta" mode="Continuous">
			<header>
				<startTimeStamp>2022-06-16T15:51:56-07:00</startTimeStamp>
				<endTimeStamp>2022-06-16T15:54:49-07:00</endTimeStamp>
				<author>
					<name>XRD</name>
				</author>
				<source>
					<applicationSoftware version="6.1b">Data Collector</applicationSoftware>
					<instrumentControlSoftware version="7.4b 20181204">XPERT-3</instrumentControlSoftware>
					<instrumentID>0000000011163216</instrumentID>
				</source>
			</header>
			<dataPoints>
				<positions axis="2Theta" unit="deg">
					<startPosition>75.431417636843</startPosition>
					<endPosition>77.9421823631571</endPosition>
				</positions>
				<positions axis="Omega" unit="deg">
					<commonPosition>18.1952289220516</commonPosition>
				</positions>
				<positions axis="Phi" unit="deg">
					<commonPosition>8.92</commonPosition>
				</positions>
				<positions axis="Chi" unit="deg">
					<commonPosition>-0.09</commonPosition>
				</positions>
				<positions axis="X" unit="mm">
					<commonPosition>-0.32</commonPosition>
				</positions>
				<positions axis="Y" unit="mm">
					<commonPosition>0</commonPosition>
				</positions>
				<positions axis="Z" unit="mm">
					<commonPosition>8.821</commonPosition>
				</positions>
				<commonCountingTime unit="seconds">0.189</commonCountingTime>
				<counts unit="counts">0 0 0 0 0 0 0 0 0 0 0 0 0 0 1 0 0 0 0 0 0 0 0 0 0 1 0 0 1 0 0 1 0 0 0 0 0 1 0 0 0 1 0 0 0 0 0 0 0 0 0 0 0 0 0 1 0 0 0 0 0 0 0 0 0 0 1 0 0 0 0 0 0 0 0 0 0 0 0 0 0 0 0 0 0 0 0 0 0 0 1 0 0 0 0 0 0 0 0 0 0 0 0 0 0 0 0 0 0 0 0 0 0 0 0 0 0 0 0 0 0 1 0 1 0 0 0 0 0 0 0 1 0 0 0 0 0 1 0 0 0 0 0 1 0 0 0 1 0 0 0 0 0 0 0 0 0 0 0 0 0 1 0 1 0 0 0 0 0 0 0 0 0 0 0 0 0 0 0 0 0 1 0 0 0 0 0 0 0 0 0 0 0 0 0 0 0 0 0 0 0 0 0 0 0 0 0 0 0 0 0 0 1 0 1 0 0 0 0 0 0 0 0 0 0 0 1 0 0 0 0 0 0 0 0 0 1 0 0 0 0 0 0 0 0 0 1 0 0 0 0 0 1 0 0</counts>
			</dataPoints>
		</scan>
		<scan status="Completed" appendNumber="0" scanAxis="2Theta" mode="Continuous">
			<header>
				<startTimeStamp>2022-06-16T15:51:56-07:00</startTimeStamp>
				<endTimeStamp>2022-06-16T15:54:49-07:00</endTimeStamp>
				<author>
					<name>XRD</name>
				</author>
				<source>
					<applicationSoftware version="6.1b">Data Collector</applicationSoftware>
					<instrumentControlSoftware version="7.4b 20181204">XPERT-3</instrumentControlSoftware>
					<instrumentID>0000000011163216</instrumentID>
				</source>
			</header>
			<dataPoints>
				<positions axis="2Theta" unit="deg">
					<startPosition>75.431417636843</startPosition>
					<endPosition>77.9421823631571</endPosition>
				</positions>
				<positions axis="Omega" unit="deg">
					<commonPosition>18.200152778059</commonPosition>
				</positions>
				<positions axis="Phi" unit="deg">
					<commonPosition>8.92</commonPosition>
				</positions>
				<positions axis="Chi" unit="deg">
					<commonPosition>-0.09</commonPosition>
				</positions>
				<positions axis="X" unit="mm">
					<commonPosition>-0.32</commonPosition>
				</positions>
				<positions axis="Y" unit="mm">
					<commonPosition>0</commonPosition>
				</positions>
				<positions axis="Z" unit="mm">
					<commonPosition>8.821</commonPosition>
				</positions>
				<commonCountingTime unit="seconds">0.189</commonCountingTime>
				<counts unit="counts">0 0 0 0 0 0 0 0 0 0 0 0 0 0 0 0 0 0 0 0 1 0 0 0 0 0 0 1 0 0 1 0 0 0 0 0 0 0 0 0 0 1 1 0 0 0 0 1 0 0 1 0 0 0 0 0 0 0 0 0 0 0 0 0 0 0 0 0 0 0 0 0 1 0 0 0 0 0 0 0 0 0 0 0 0 1 0 0 0 1 0 0 0 0 0 0 0 0 0 0 0 0 0 0 0 1 0 0 0 0 0 0 0 0 0 0 0 0 0 0 0 0 0 0 0 0 0 0 1 0 0 0 0 0 0 0 0 0 0 0 0 0 0 0 0 0 0 0 0 0 0 0 0 0 0 0 0 0 0 0 0 2 0 0 0 0 0 0 0 0 0 0 0 0 0 0 0 0 0 0 0 0 0 0 2 0 0 0 0 0 0 0 0 0 0 0 0 0 0 0 0 0 0 0 0 0 0 0 0 0 0 0 0 0 0 0 0 0 0 1 0 0 0 0 0 0 0 0 0 0 0 0 0 0 0 0 0 0 0 0 0 0 0 0 0 0 0 0 0 0 1 0 0 0 0</counts>
			</dataPoints>
		</scan>
		<scan status="Completed" appendNumber="0" scanAxis="2Theta" mode="Continuous">
			<header>
				<startTimeStamp>2022-06-16T15:51:56-07:00</startTimeStamp>
				<endTimeStamp>2022-06-16T15:54:49-07:00</endTimeStamp>
				<author>
					<name>XRD</name>
				</author>
				<source>
					<applicationSoftware version="6.1b">Data Collector</applicationSoftware>
					<instrumentControlSoftware version="7.4b 20181204">XPERT-3</instrumentControlSoftware>
					<instrumentID>0000000011163216</instrumentID>
				</source>
			</header>
			<dataPoints>
				<positions axis="2Theta" unit="deg">
					<startPosition>75.431417636843</startPosition>
					<endPosition>77.9421823631571</endPosition>
				</positions>
				<positions axis="Omega" unit="deg">
					<commonPosition>18.2050766340663</commonPosition>
				</positions>
				<positions axis="Phi" unit="deg">
					<commonPosition>8.92</commonPosition>
				</positions>
				<positions axis="Chi" unit="deg">
					<commonPosition>-0.09</commonPosition>
				</positions>
				<positions axis="X" unit="mm">
					<commonPosition>-0.32</commonPosition>
				</positions>
				<positions axis="Y" unit="mm">
					<commonPosition>0</commonPosition>
				</positions>
				<positions axis="Z" unit="mm">
					<commonPosition>8.821</commonPosition>
				</positions>
				<commonCountingTime unit="seconds">0.189</commonCountingTime>
				<counts unit="counts">1 0 0 0 0 0 0 1 0 0 0 2 0 0 0 0 0 0 0 0 0 0 0 0 0 0 1 0 0 0 0 1 0 0 0 0 0 1 1 0 0 0 0 0 0 0 0 0 0 0 0 0 0 0 0 0 0 0 0 1 0 0 2 0 0 0 0 0 0 0 0 0 0 0 0 0 0 0 0 0 0 0 2 0 0 0 0 0 0 0 0 0 0 0 0 0 0 1 0 0 0 0 0 0 0 0 0 1 0 0 0 0 0 0 0 0 1 0 0 1 0 0 0 0 0 0 0 0 0 0 0 0 0 0 0 0 0 0 0 0 0 0 0 0 0 0 0 0 0 0 0 0 0 0 0 0 0 0 0 0 1 0 0 0 0 0 0 0 0 0 0 0 0 1 0 0 0 1 0 0 0 0 0 0 0 0 0 1 0 0 0 0 0 0 1 0 0 0 0 0 0 1 0 0 0 0 0 0 0 0 1 0 0 0 0 0 0 0 0 0 0 0 0 0 0 0 0 0 0 0 0 0 0 0 0 0 0 0 0 0 0 0 0 0 1 0 0 0 0 0 0 0 0 0 0</counts>
			</dataPoints>
		</scan>
		<scan status="Completed" appendNumber="0" scanAxis="2Theta" mode="Continuous">
			<header>
				<startTimeStamp>2022-06-16T15:51:56-07:00</startTimeStamp>
				<endTimeStamp>2022-06-16T15:54:49-07:00</endTimeStamp>
				<author>
					<name>XRD</name>
				</author>
				<source>
					<applicationSoftware version="6.1b">Data Collector</applicationSoftware>
					<instrumentControlSoftware version="7.4b 20181204">XPERT-3</instrumentControlSoftware>
					<instrumentID>0000000011163216</instrumentID>
				</source>
			</header>
			<dataPoints>
				<positions axis="2Theta" unit="deg">
					<startPosition>75.431417636843</startPosition>
					<endPosition>77.9421823631571</endPosition>
				</positions>
				<positions axis="Omega" unit="deg">
					<commonPosition>18.2100004900737</commonPosition>
				</positions>
				<positions axis="Phi" unit="deg">
					<commonPosition>8.92</commonPosition>
				</positions>
				<positions axis="Chi" unit="deg">
					<commonPosition>-0.09</commonPosition>
				</positions>
				<positions axis="X" unit="mm">
					<commonPosition>-0.32</commonPosition>
				</positions>
				<positions axis="Y" unit="mm">
					<commonPosition>0</commonPosition>
				</positions>
				<positions axis="Z" unit="mm">
					<commonPosition>8.821</commonPosition>
				</positions>
				<commonCountingTime unit="seconds">0.189</commonCountingTime>
				<counts unit="counts">0 0 1 0 0 0 0 1 0 0 0 1 0 0 0 1 0 0 0 0 0 0 0 0 0 0 0 0 0 0 1 0 0 0 0 0 0 0 0 1 0 0 0 0 0 0 0 1 0 0 0 0 0 0 0 0 0 0 0 0 0 0 0 0 0 0 0 0 0 0 0 1 0 1 0 0 0 0 0 0 0 0 1 0 0 0 0 0 0 0 0 1 1 1 0 0 0 0 0 1 0 0 0 0 0 0 0 0 0 0 0 0 0 0 1 0 0 0 0 1 0 0 1 0 0 0 1 0 0 0 0 0 0 0 1 0 0 2 0 0 0 0 0 0 0 0 0 1 0 0 0 0 0 0 0 0 0 0 0 0 0 0 0 0 0 0 0 0 0 0 0 0 0 0 0 1 0 0 0 0 0 0 0 0 0 0 0 0 0 0 0 0 0 0 0 0 0 0 0 1 0 0 0 1 0 0 0 0 0 0 0 0 0 0 0 0 1 0 0 0 0 0 0 0 0 0 0 0 0 0 0 0 0 0 0 0 0 0 0 0 1 0 0 0 0 0 0 0 1 0 0 0 0 1 0</counts>
			</dataPoints>
		</scan>
		<scan status="Completed" appendNumber="0" scanAxis="2Theta" mode="Continuous">
			<header>
				<startTimeStamp>2022-06-16T15:51:56-07:00</startTimeStamp>
				<endTimeStamp>2022-06-16T15:54:49-07:00</endTimeStamp>
				<author>
					<name>XRD</name>
				</author>
				<source>
					<applicationSoftware version="6.1b">Data Collector</applicationSoftware>
					<instrumentControlSoftware version="7.4b 20181204">XPERT-3</instrumentControlSoftware>
					<instrumentID>0000000011163216</instrumentID>
				</source>
			</header>
			<dataPoints>
				<positions axis="2Theta" unit="deg">
					<startPosition>75.431417636843</startPosition>
					<endPosition>77.9421823631571</endPosition>
				</positions>
				<positions axis="Omega" unit="deg">
					<commonPosition>18.2149243460811</commonPosition>
				</positions>
				<positions axis="Phi" unit="deg">
					<commonPosition>8.92</commonPosition>
				</positions>
				<positions axis="Chi" unit="deg">
					<commonPosition>-0.09</commonPosition>
				</positions>
				<positions axis="X" unit="mm">
					<commonPosition>-0.32</commonPosition>
				</positions>
				<positions axis="Y" unit="mm">
					<commonPosition>0</commonPosition>
				</positions>
				<positions axis="Z" unit="mm">
					<commonPosition>8.821</commonPosition>
				</positions>
				<commonCountingTime unit="seconds">0.189</commonCountingTime>
				<counts unit="counts">0 1 0 0 0 1 0 0 0 1 0 0 0 0 0 0 0 0 0 0 0 0 0 0 0 0 0 0 0 0 0 0 0 0 1 0 0 0 0 0 0 0 0 0 0 0 0 0 0 0 0 0 0 0 0 1 0 0 0 0 0 0 1 0 0 0 0 0 0 0 0 0 0 0 0 1 0 1 0 0 0 0 0 0 0 0 0 2 1 0 1 0 0 0 0 0 0 0 0 0 1 0 0 0 0 0 0 0 0 0 0 0 0 0 0 0 0 1 0 0 0 0 0 0 0 0 0 0 0 0 0 0 0 0 0 0 0 0 0 0 0 0 0 0 0 0 0 0 0 1 1 0 1 0 0 0 0 0 0 0 0 0 0 0 0 0 0 0 0 1 0 0 0 1 0 0 0 0 0 0 0 0 0 0 0 0 0 0 0 0 0 1 0 0 0 0 0 0 0 0 0 0 0 0 0 0 0 0 0 0 1 0 0 0 0 0 0 0 1 0 0 0 0 0 0 0 0 0 0 0 0 0 0 0 1 0 0 0 0 0 0 0 0 0 0 0 0 0 1 0 0 0 0 0 0</counts>
			</dataPoints>
		</scan>
		<scan status="Completed" appendNumber="0" scanAxis="2Theta" mode="Continuous">
			<header>
				<startTimeStamp>2022-06-16T15:51:56-07:00</startTimeStamp>
				<endTimeStamp>2022-06-16T15:54:49-07:00</endTimeStamp>
				<author>
					<name>XRD</name>
				</author>
				<source>
					<applicationSoftware version="6.1b">Data Collector</applicationSoftware>
					<instrumentControlSoftware version="7.4b 20181204">XPERT-3</instrumentControlSoftware>
					<instrumentID>0000000011163216</instrumentID>
				</source>
			</header>
			<dataPoints>
				<positions axis="2Theta" unit="deg">
					<startPosition>75.431417636843</startPosition>
					<endPosition>77.9421823631571</endPosition>
				</positions>
				<positions axis="Omega" unit="deg">
					<commonPosition>18.2198482020885</commonPosition>
				</positions>
				<positions axis="Phi" unit="deg">
					<commonPosition>8.92</commonPosition>
				</positions>
				<positions axis="Chi" unit="deg">
					<commonPosition>-0.09</commonPosition>
				</positions>
				<positions axis="X" unit="mm">
					<commonPosition>-0.32</commonPosition>
				</positions>
				<positions axis="Y" unit="mm">
					<commonPosition>0</commonPosition>
				</positions>
				<positions axis="Z" unit="mm">
					<commonPosition>8.821</commonPosition>
				</positions>
				<commonCountingTime unit="seconds">0.189</commonCountingTime>
				<counts unit="counts">0 1 0 0 0 0 0 0 0 0 1 0 0 0 1 0 0 0 0 0 1 0 0 0 0 0 0 0 0 0 0 0 0 1 0 0 0 0 0 0 0 0 1 0 0 0 0 0 1 0 0 0 0 0 0 0 0 0 0 0 0 0 0 0 0 0 0 0 0 0 0 0 0 0 0 0 0 0 0 0 0 0 0 0 0 0 0 0 0 0 0 1 0 0 0 0 0 0 0 0 0 0 1 0 0 0 0 0 0 0 0 0 0 0 0 0 0 0 0 0 0 0 0 1 0 0 0 1 0 1 0 0 1 0 0 0 1 0 1 0 0 0 0 0 0 0 0 0 0 0 0 0 0 0 0 0 0 0 0 0 0 0 0 0 0 0 1 0 0 0 0 0 0 0 0 0 0 0 0 0 0 0 0 0 1 0 1 0 1 0 1 0 0 0 0 1 0 0 0 0 0 0 0 0 0 0 0 0 0 0 0 0 0 0 0 0 0 0 0 0 0 0 0 0 0 0 0 0 0 0 0 0 0 1 0 0 1 1 0 0 0 0 1 0 0 1 1 0 0 0 0 1 0 0 0</counts>
			</dataPoints>
		</scan>
		<scan status="Completed" appendNumber="0" scanAxis="2Theta" mode="Continuous">
			<header>
				<startTimeStamp>2022-06-16T15:51:56-07:00</startTimeStamp>
				<endTimeStamp>2022-06-16T15:54:49-07:00</endTimeStamp>
				<author>
					<name>XRD</name>
				</author>
				<source>
					<applicationSoftware version="6.1b">Data Collector</applicationSoftware>
					<instrumentControlSoftware version="7.4b 20181204">XPERT-3</instrumentControlSoftware>
					<instrumentID>0000000011163216</instrumentID>
				</source>
			</header>
			<dataPoints>
				<positions axis="2Theta" unit="deg">
					<startPosition>75.431417636843</startPosition>
					<endPosition>77.9421823631571</endPosition>
				</positions>
				<positions axis="Omega" unit="deg">
					<commonPosition>18.2247720580958</commonPosition>
				</positions>
				<positions axis="Phi" unit="deg">
					<commonPosition>8.92</commonPosition>
				</positions>
				<positions axis="Chi" unit="deg">
					<commonPosition>-0.09</commonPosition>
				</positions>
				<positions axis="X" unit="mm">
					<commonPosition>-0.32</commonPosition>
				</positions>
				<positions axis="Y" unit="mm">
					<commonPosition>0</commonPosition>
				</positions>
				<positions axis="Z" unit="mm">
					<commonPosition>8.821</commonPosition>
				</positions>
				<commonCountingTime unit="seconds">0.189</commonCountingTime>
				<counts unit="counts">0 0 0 1 0 0 0 0 0 0 0 0 1 1 0 1 0 0 0 0 0 0 0 0 0 1 0 0 0 0 0 0 1 1 0 0 0 0 0 0 0 0 0 0 0 0 0 0 0 0 0 0 0 0 0 0 0 0 0 0 1 0 0 0 0 0 1 0 0 0 0 0 0 0 0 0 0 0 0 0 0 0 0 0 0 0 0 0 0 0 0 0 1 0 0 0 0 0 0 0 0 0 0 0 0 0 0 0 0 0 0 0 0 0 0 0 0 1 0 1 0 0 0 0 0 0 0 0 0 0 0 0 0 0 0 0 0 0 0 0 0 0 0 0 0 0 0 0 0 0 1 0 0 0 0 0 0 0 0 0 0 0 0 0 0 0 0 0 0 0 1 1 0 0 0 0 0 0 0 0 0 0 0 0 0 0 0 0 0 0 1 0 0 0 0 0 1 0 0 0 0 0 0 0 0 0 0 0 0 0 0 0 0 0 0 0 0 0 0 1 0 0 0 1 0 0 0 1 0 0 0 0 0 0 0 0 0 0 1 0 0 0 0 0 0 0 0 0 1 0 0 0 0 0 0</counts>
			</dataPoints>
		</scan>
		<scan status="Completed" appendNumber="0" scanAxis="2Theta" mode="Continuous">
			<header>
				<startTimeStamp>2022-06-16T15:51:56-07:00</startTimeStamp>
				<endTimeStamp>2022-06-16T15:54:49-07:00</endTimeStamp>
				<author>
					<name>XRD</name>
				</author>
				<source>
					<applicationSoftware version="6.1b">Data Collector</applicationSoftware>
					<instrumentControlSoftware version="7.4b 20181204">XPERT-3</instrumentControlSoftware>
					<instrumentID>0000000011163216</instrumentID>
				</source>
			</header>
			<dataPoints>
				<positions axis="2Theta" unit="deg">
					<startPosition>75.431417636843</startPosition>
					<endPosition>77.9421823631571</endPosition>
				</positions>
				<positions axis="Omega" unit="deg">
					<commonPosition>18.2296959141032</commonPosition>
				</positions>
				<positions axis="Phi" unit="deg">
					<commonPosition>8.92</commonPosition>
				</positions>
				<positions axis="Chi" unit="deg">
					<commonPosition>-0.09</commonPosition>
				</positions>
				<positions axis="X" unit="mm">
					<commonPosition>-0.32</commonPosition>
				</positions>
				<positions axis="Y" unit="mm">
					<commonPosition>0</commonPosition>
				</positions>
				<positions axis="Z" unit="mm">
					<commonPosition>8.821</commonPosition>
				</positions>
				<commonCountingTime unit="seconds">0.189</commonCountingTime>
				<counts unit="counts">1 0 0 0 0 0 0 1 0 0 0 0 0 0 0 0 0 0 0 1 0 0 0 0 0 0 0 0 0 0 0 0 0 0 1 0 0 0 0 0 0 0 0 0 0 0 0 0 0 0 0 0 0 0 0 0 0 0 0 0 0 1 0 0 0 0 0 0 0 0 0 0 1 0 0 0 0 0 0 0 0 0 1 0 0 0 0 0 0 0 0 2 0 0 0 0 1 0 0 0 1 0 0 0 0 0 0 0 0 0 0 0 0 0 0 0 0 0 0 0 0 0 0 0 0 0 0 0 0 0 1 1 0 0 0 0 0 0 0 0 0 0 0 0 0 0 0 0 1 0 0 0 0 1 1 0 0 0 0 0 0 0 0 0 0 0 0 0 0 0 1 0 0 0 0 0 0 0 0 0 0 0 0 0 0 0 0 1 0 0 0 0 0 0 0 0 0 0 0 0 0 0 0 0 0 0 0 0 0 0 0 0 1 0 0 0 0 0 1 0 0 0 0 0 0 0 0 1 0 0 0 1 0 1 0 0 0 0 0 0 0 0 0 0 0 0 1 0 0 0 0 0 0 0 0</counts>
			</dataPoints>
		</scan>
		<scan status="Completed" appendNumber="0" scanAxis="2Theta" mode="Continuous">
			<header>
				<startTimeStamp>2022-06-16T15:51:56-07:00</startTimeStamp>
				<endTimeStamp>2022-06-16T15:54:49-07:00</endTimeStamp>
				<author>
					<name>XRD</name>
				</author>
				<source>
					<applicationSoftware version="6.1b">Data Collector</applicationSoftware>
					<instrumentControlSoftware version="7.4b 20181204">XPERT-3</instrumentControlSoftware>
					<instrumentID>0000000011163216</instrumentID>
				</source>
			</header>
			<dataPoints>
				<positions axis="2Theta" unit="deg">
					<startPosition>75.431417636843</startPosition>
					<endPosition>77.9421823631571</endPosition>
				</positions>
				<positions axis="Omega" unit="deg">
					<commonPosition>18.2346197701106</commonPosition>
				</positions>
				<positions axis="Phi" unit="deg">
					<commonPosition>8.92</commonPosition>
				</positions>
				<positions axis="Chi" unit="deg">
					<commonPosition>-0.09</commonPosition>
				</positions>
				<positions axis="X" unit="mm">
					<commonPosition>-0.32</commonPosition>
				</positions>
				<positions axis="Y" unit="mm">
					<commonPosition>0</commonPosition>
				</positions>
				<positions axis="Z" unit="mm">
					<commonPosition>8.821</commonPosition>
				</positions>
				<commonCountingTime unit="seconds">0.189</commonCountingTime>
				<counts unit="counts">1 0 0 1 0 0 0 0 0 0 0 0 0 0 0 0 0 0 0 0 0 0 0 0 0 0 0 0 0 0 0 0 1 0 0 0 0 0 0 0 0 1 0 0 0 0 0 0 0 0 0 1 1 0 0 0 0 0 1 1 0 0 0 0 1 0 1 1 0 0 0 0 0 0 0 0 0 0 0 0 0 0 0 0 0 0 1 0 0 0 0 0 1 0 1 0 0 0 1 0 0 0 0 0 0 0 0 0 0 0 0 0 0 0 1 0 0 0 0 0 0 0 0 0 0 0 0 0 0 1 0 0 1 0 0 1 1 0 0 1 0 0 1 0 0 0 0 0 0 1 0 0 0 0 0 0 0 0 1 0 0 0 0 1 0 0 0 0 0 0 0 0 0 0 0 1 0 0 0 0 0 0 0 1 0 0 0 0 0 0 0 0 0 0 0 0 0 0 0 0 0 0 0 0 0 0 0 0 0 0 0 1 0 0 0 0 0 0 0 0 0 0 0 0 0 0 0 0 0 0 0 0 0 0 0 0 0 0 0 0 0 0 0 0 0 0 0 0 1 0 0 0 0 1 1</counts>
			</dataPoints>
		</scan>
		<scan status="Completed" appendNumber="0" scanAxis="2Theta" mode="Continuous">
			<header>
				<startTimeStamp>2022-06-16T15:51:56-07:00</startTimeStamp>
				<endTimeStamp>2022-06-16T15:54:49-07:00</endTimeStamp>
				<author>
					<name>XRD</name>
				</author>
				<source>
					<applicationSoftware version="6.1b">Data Collector</applicationSoftware>
					<instrumentControlSoftware version="7.4b 20181204">XPERT-3</instrumentControlSoftware>
					<instrumentID>0000000011163216</instrumentID>
				</source>
			</header>
			<dataPoints>
				<positions axis="2Theta" unit="deg">
					<startPosition>75.431417636843</startPosition>
					<endPosition>77.9421823631571</endPosition>
				</positions>
				<positions axis="Omega" unit="deg">
					<commonPosition>18.2395436261179</commonPosition>
				</positions>
				<positions axis="Phi" unit="deg">
					<commonPosition>8.92</commonPosition>
				</positions>
				<positions axis="Chi" unit="deg">
					<commonPosition>-0.09</commonPosition>
				</positions>
				<positions axis="X" unit="mm">
					<commonPosition>-0.32</commonPosition>
				</positions>
				<positions axis="Y" unit="mm">
					<commonPosition>0</commonPosition>
				</positions>
				<positions axis="Z" unit="mm">
					<commonPosition>8.821</commonPosition>
				</positions>
				<commonCountingTime unit="seconds">0.189</commonCountingTime>
				<counts unit="counts">0 0 1 0 1 0 0 1 0 0 0 0 0 0 0 1 0 0 0 0 0 0 0 0 0 0 0 0 0 0 0 0 0 0 0 1 0 0 0 0 0 0 0 1 0 0 0 0 0 1 1 0 0 1 0 0 0 1 0 0 0 0 0 0 1 0 0 0 0 0 0 1 0 0 0 0 1 0 0 0 0 0 0 0 0 0 0 1 0 0 1 0 1 0 0 0 0 0 0 0 0 0 0 0 0 0 0 0 0 0 0 0 1 1 1 0 0 0 0 0 0 2 0 0 0 0 0 0 0 0 0 0 0 0 0 0 0 0 0 0 0 0 0 0 0 0 0 0 0 0 0 0 0 1 0 0 0 0 0 0 0 0 0 0 0 0 0 0 0 0 0 1 0 0 0 0 0 0 0 0 0 0 1 0 0 1 0 0 0 0 0 0 1 0 0 0 0 0 0 0 0 0 0 0 0 0 0 0 0 0 0 0 0 0 1 0 0 1 0 0 0 0 1 0 0 0 0 2 0 0 0 0 0 0 0 0 0 0 0 0 0 0 0 0 0 0 0 0 0 0 2 0 0 0 0</counts>
			</dataPoints>
		</scan>
		<scan status="Completed" appendNumber="0" scanAxis="2Theta" mode="Continuous">
			<header>
				<startTimeStamp>2022-06-16T15:51:56-07:00</startTimeStamp>
				<endTimeStamp>2022-06-16T15:54:49-07:00</endTimeStamp>
				<author>
					<name>XRD</name>
				</author>
				<source>
					<applicationSoftware version="6.1b">Data Collector</applicationSoftware>
					<instrumentControlSoftware version="7.4b 20181204">XPERT-3</instrumentControlSoftware>
					<instrumentID>0000000011163216</instrumentID>
				</source>
			</header>
			<dataPoints>
				<positions axis="2Theta" unit="deg">
					<startPosition>75.431417636843</startPosition>
					<endPosition>77.9421823631571</endPosition>
				</positions>
				<positions axis="Omega" unit="deg">
					<commonPosition>18.2444674821253</commonPosition>
				</positions>
				<positions axis="Phi" unit="deg">
					<commonPosition>8.92</commonPosition>
				</positions>
				<positions axis="Chi" unit="deg">
					<commonPosition>-0.09</commonPosition>
				</positions>
				<positions axis="X" unit="mm">
					<commonPosition>-0.32</commonPosition>
				</positions>
				<positions axis="Y" unit="mm">
					<commonPosition>0</commonPosition>
				</positions>
				<positions axis="Z" unit="mm">
					<commonPosition>8.821</commonPosition>
				</positions>
				<commonCountingTime unit="seconds">0.189</commonCountingTime>
				<counts unit="counts">0 0 0 0 0 0 0 0 1 0 0 0 0 0 0 0 0 0 0 0 0 1 0 0 0 0 0 0 0 0 1 0 0 1 0 0 0 1 0 0 0 1 0 0 0 0 0 0 0 0 0 0 0 0 1 0 1 0 0 0 0 0 0 1 0 0 0 0 0 0 0 0 0 0 0 0 0 1 0 0 0 0 1 0 0 0 1 0 0 0 0 0 0 0 0 0 0 0 1 1 0 0 0 0 0 0 0 1 1 0 0 1 0 0 0 0 0 0 1 0 0 0 0 0 0 0 0 0 0 0 0 1 0 0 0 0 0 0 0 0 0 1 0 0 0 0 0 0 0 0 0 0 0 0 0 0 0 0 0 0 0 0 0 0 0 0 0 0 0 0 0 0 0 1 0 0 0 0 0 0 0 0 0 2 0 0 0 0 0 0 0 0 0 0 0 0 0 0 0 0 0 0 0 0 0 0 0 0 0 0 0 0 0 0 0 0 0 0 0 0 0 0 0 0 0 0 0 0 0 0 0 0 0 0 0 0 0 0 0 0 0 0 0 0 1 0 0 0 0 1 1 0 0 0 0</counts>
			</dataPoints>
		</scan>
		<scan status="Completed" appendNumber="0" scanAxis="2Theta" mode="Continuous">
			<header>
				<startTimeStamp>2022-06-16T15:51:56-07:00</startTimeStamp>
				<endTimeStamp>2022-06-16T15:54:49-07:00</endTimeStamp>
				<author>
					<name>XRD</name>
				</author>
				<source>
					<applicationSoftware version="6.1b">Data Collector</applicationSoftware>
					<instrumentControlSoftware version="7.4b 20181204">XPERT-3</instrumentControlSoftware>
					<instrumentID>0000000011163216</instrumentID>
				</source>
			</header>
			<dataPoints>
				<positions axis="2Theta" unit="deg">
					<startPosition>75.431417636843</startPosition>
					<endPosition>77.9421823631571</endPosition>
				</positions>
				<positions axis="Omega" unit="deg">
					<commonPosition>18.2493913381327</commonPosition>
				</positions>
				<positions axis="Phi" unit="deg">
					<commonPosition>8.92</commonPosition>
				</positions>
				<positions axis="Chi" unit="deg">
					<commonPosition>-0.09</commonPosition>
				</positions>
				<positions axis="X" unit="mm">
					<commonPosition>-0.32</commonPosition>
				</positions>
				<positions axis="Y" unit="mm">
					<commonPosition>0</commonPosition>
				</positions>
				<positions axis="Z" unit="mm">
					<commonPosition>8.821</commonPosition>
				</positions>
				<commonCountingTime unit="seconds">0.189</commonCountingTime>
				<counts unit="counts">1 0 0 0 0 0 0 0 0 0 0 1 1 1 0 0 0 0 0 0 0 0 0 0 0 0 1 0 0 0 1 0 0 0 0 0 1 1 0 0 0 0 0 0 0 0 0 0 0 0 0 0 0 0 0 0 0 0 0 0 0 0 0 0 0 0 0 0 0 0 0 0 0 0 0 0 0 0 0 0 0 0 0 0 0 0 0 0 0 1 0 0 0 0 0 0 0 0 0 0 0 0 2 0 0 0 0 1 0 0 0 0 1 1 0 0 0 0 0 0 1 0 0 0 0 0 0 0 0 0 1 0 0 2 0 1 0 0 0 0 0 0 0 1 0 0 0 0 0 0 0 0 0 0 0 0 2 0 0 0 0 0 0 0 0 0 0 0 0 0 0 0 0 0 0 0 0 0 0 0 1 0 1 0 0 0 2 0 0 0 0 0 0 0 0 1 0 1 0 0 0 0 0 0 0 0 0 0 0 0 0 0 0 0 0 1 1 0 0 0 0 0 0 0 0 0 0 1 0 0 0 0 0 0 0 0 0 0 0 0 0 0 0 1 0 0 0 1 0 0 0 0 0 0 0</counts>
			</dataPoints>
		</scan>
[...]
				</positions>
				<commonCountingTime unit="seconds">0.189</commonCountingTime>
				<counts unit="counts">0 0 1 0 1 0 0 0 0 0 0 0 0 0 0 0 0 0 0 0 0 0 1 0 0 0 0 0 0 0 0 0 0 2 0 0 0 0 0 0 0 0 0 0 0 0 0 0 0 0 0 0 0 0 0 0 0 0 0 0 0 0 0 0 0 0 0 0 0 0 0 0 0 0 0 0 0 0 0 0 1 1 0 0 0 0 0 0 0 0 0 0 0 0 0 0 0 0 0 1 0 0 0 1 0 0 1 0 0 0 0 0 0 0 0 0 0 0 0 0 0 1 0 0 0 0 0 0 0 0 0 0 0 0 0 0 0 0 0 0 0 0 0 0 0 1 0 0 0 0 0 0 0 0 0 0 0 0 1 0 0 0 0 0 0 0 1 0 0 0 0 1 0 0 0 0 0 0 0 1 0 1 0 0 0 0 0 0 0 1 0 0 0 0 0 0 0 0 0 1 0 0 0 0 0 1 0 1 1 0 0 0 0 0 0 0 0 0 0 0 0 1 0 0 0 0 0 0 0 0 0 0 1 0 0 0 0 0 0 0 0 0 0 0 0 0 0 0 0 0 0 1 1 0 0</counts>
			</dataPoints>
		</scan>
		<scan status="Completed" appendNumber="0" scanAxis="2Theta" mode="Continuous">
			<header>
				<startTimeStamp>2022-06-16T15:51:56-07:00</startTimeStamp>
				<endTimeStamp>2022-06-16T15:54:49-07:00</endTimeStamp>
				<author>
					<name>XRD</name>
				</author>
				<source>
					<applicationSoftware version="6.1b">Data Collector</applicationSoftware>
					<instrumentControlSoftware version="7.4b 20181204">XPERT-3</instrumentControlSoftware>
					<instrumentID>0000000011163216</instrumentID>
				</source>
			</header>
			<dataPoints>
				<positions axis="2Theta" unit="deg">
					<startPosition>75.431417636843</startPosition>
					<endPosition>77.9421823631571</endPosition>
				</positions>
				<positions axis="Omega" unit="deg">
					<commonPosition>22.1244660159337</commonPosition>
				</positions>
				<positions axis="Phi" unit="deg">
					<commonPosition>8.92</commonPosition>
				</positions>
				<positions axis="Chi" unit="deg">
					<commonPosition>-0.09</commonPosition>
				</positions>
				<positions axis="X" unit="mm">
					<commonPosition>-0.32</commonPosition>
				</positions>
				<positions axis="Y" unit="mm">
					<commonPosition>0</commonPosition>
				</positions>
				<positions axis="Z" unit="mm">
					<commonPosition>8.821</commonPosition>
				</positions>
				<commonCountingTime unit="seconds">0.189</commonCountingTime>
				<counts unit="counts">0 1 0 0 0 0 0 0 0 0 0 0 0 0 0 0 0 0 0 0 0 0 0 0 0 0 0 0 0 0 0 0 0 0 0 0 0 0 1 0 0 0 0 0 0 0 1 0 0 0 0 0 1 0 0 0 0 0 0 0 0 0 0 0 0 0 0 0 0 0 0 0 0 0 0 2 0 0 0 0 2 0 0 0 0 0 0 1 0 0 0 0 0 0 0 0 0 0 0 0 0 0 0 0 0 0 0 0 0 0 0 0 0 0 0 0 0 0 0 1 0 0 0 1 0 0 0 0 0 0 0 0 0 0 0 0 0 0 0 0 0 0 0 0 0 0 0 0 0 0 0 0 0 0 0 0 0 0 0 0 0 0 0 0 0 0 0 0 0 0 0 0 0 0 0 1 0 0 0 0 0 0 0 0 1 0 0 0 0 0 0 0 0 0 0 0 0 0 0 0 0 0 0 0 0 1 0 0 0 0 0 1 0 0 0 0 0 0 0 0 1 0 0 2 0 0 0 0 0 1 0 0 0 0 0 1 1 1 0 0 0 0 0 1 0 0 0 0 0 0 0 0 0 0 0</counts>
			</dataPoints>
		</scan>
		<scan status="Completed" appendNumber="0" scanAxis="2Theta" mode="Continuous">
			<header>
				<startTimeStamp>2022-06-16T15:51:56-07:00</startTimeStamp>
				<endTimeStamp>2022-06-16T15:54:49-07:00</endTimeStamp>
				<author>
					<name>XRD</name>
				</author>
				<source>
					<applicationSoftware version="6.1b">Data Collector</applicationSoftware>
					<instrumentControlSoftware version="7.4b 20181204">XPERT-3</instrumentControlSoftware>
					<instrumentID>0000000011163216</instrumentID>
				</source>
			</header>
			<dataPoints>
				<positions axis="2Theta" unit="deg">
					<startPosition>75.431417636843</startPosition>
					<endPosition>77.9421823631571</endPosition>
				</positions>
				<positions axis="Omega" unit="deg">
					<commonPosition>22.129389871941</commonPosition>
				</positions>
				<positions axis="Phi" unit="deg">
					<commonPosition>8.92</commonPosition>
				</positions>
				<positions axis="Chi" unit="deg">
					<commonPosition>-0.09</commonPosition>
				</positions>
				<positions axis="X" unit="mm">
					<commonPosition>-0.32</commonPosition>
				</positions>
				<positions axis="Y" unit="mm">
					<commonPosition>0</commonPosition>
				</positions>
				<positions axis="Z" unit="mm">
					<commonPosition>8.821</commonPosition>
				</positions>
				<commonCountingTime unit="seconds">0.189</commonCountingTime>
				<counts unit="counts">0 0 0 0 0 0 0 0 1 0 0 0 0 0 0 0 0 0 0 0 0 0 1 0 0 0 0 0 1 0 0 0 0 0 0 0 0 0 0 0 0 0 0 0 0 0 0 0 0 0 0 0 0 0 0 0 0 0 0 0 0 0 0 0 0 0 0 1 0 0 0 0 1 0 0 0 0 0 0 0 0 0 1 0 0 0 0 0 2 0 0 0 0 0 0 0 0 0 0 0 0 0 0 0 0 0 1 0 0 0 1 0 1 0 0 1 0 0 2 0 0 0 0 0 0 0 0 0 0 0 0 0 0 0 0 0 0 0 0 0 0 0 2 0 0 0 0 0 0 0 0 0 0 0 0 0 0 0 0 1 0 0 0 0 0 0 0 1 1 0 0 0 0 0 0 1 0 0 0 0 0 0 0 0 0 0 0 0 0 0 0 0 0 0 0 0 0 0 0 0 0 0 1 0 0 0 0 0 0 0 0 0 1 0 0 0 0 0 0 0 0 0 0 0 0 0 0 0 0 0 0 0 0 0 0 0 0 0 0 0 0 0 0 0 0 0 0 0 0 0 1 0 0 1 1</counts>
			</dataPoints>
		</scan>
		<scan status="Completed" appendNumber="0" scanAxis="2Theta" mode="Continuous">
			<header>
				<startTimeStamp>2022-06-16T15:51:56-07:00</startTimeStamp>
				<endTimeStamp>2022-06-16T15:54:49-07:00</endTimeStamp>
				<author>
					<name>XRD</name>
				</author>
				<source>
					<applicationSoftware version="6.1b">Data Collector</applicationSoftware>
					<instrumentControlSoftware version="7.4b 20181204">XPERT-3</instrumentControlSoftware>
					<instrumentID>0000000011163216</instrumentID>
				</source>
			</header>
			<dataPoints>
				<positions axis="2Theta" unit="deg">
					<startPosition>75.431417636843</startPosition>
					<endPosition>77.9421823631571</endPosition>
				</positions>
				<positions axis="Omega" unit="deg">
					<commonPosition>22.1343137279484</commonPosition>
				</positions>
				<positions axis="Phi" unit="deg">
					<commonPosition>8.92</commonPosition>
				</positions>
				<positions axis="Chi" unit="deg">
					<commonPosition>-0.09</commonPosition>
				</positions>
				<positions axis="X" unit="mm">
					<commonPosition>-0.32</commonPosition>
				</positions>
				<positions axis="Y" unit="mm">
					<commonPosition>0</commonPosition>
				</positions>
				<positions axis="Z" unit="mm">
					<commonPosition>8.821</commonPosition>
				</positions>
				<commonCountingTime unit="seconds">0.189</commonCountingTime>
				<counts unit="counts">0 0 0 0 0 0 0 0 0 0 0 0 0 1 1 0 1 0 0 0 0 0 0 0 0 0 0 0 0 0 0 0 0 0 0 0 0 0 0 0 0 0 0 0 0 0 0 0 0 0 0 0 0 0 0 0 0 0 0 0 1 0 0 0 0 0 0 0 0 0 0 0 0 0 0 0 1 0 0 0 0 0 0 1 0 0 0 0 0 0 0 0 0 0 0 0 0 0 0 0 0 0 0 1 0 0 0 1 1 0 1 0 0 0 0 0 1 0 0 1 0 0 0 1 0 0 0 0 0 0 0 1 0 1 0 0 0 0 1 0 0 0 0 0 0 1 0 0 0 0 0 0 0 0 0 1 0 0 0 0 0 0 0 0 0 0 0 1 0 0 0 0 0 0 0 0 0 0 1 0 0 0 0 0 0 1 0 0 0 0 0 0 0 0 0 1 0 0 0 0 0 0 0 0 0 0 0 1 0 0 0 0 0 0 0 0 0 1 0 1 0 1 0 0 0 0 0 0 0 0 0 1 0 2 0 0 0 0 0 0 2 0 1 0 0 0 0 0 0 0 0 0 0 0 0</counts>
			</dataPoints>
		</scan>
		<scan status="Completed" appendNumber="0" scanAxis="2Theta" mode="Continuous">
			<header>
				<startTimeStamp>2022-06-16T15:51:56-07:00</startTimeStamp>
				<endTimeStamp>2022-06-16T15:54:49-07:00</endTimeStamp>
				<author>
					<name>XRD</name>
				</author>
				<source>
					<applicationSoftware version="6.1b">Data Collector</applicationSoftware>
					<instrumentControlSoftware version="7.4b 20181204">XPERT-3</instrumentControlSoftware>
					<instrumentID>0000000011163216</instrumentID>
				</source>
			</header>
			<dataPoints>
				<positions axis="2Theta" unit="deg">
					<startPosition>75.431417636843</startPosition>
					<endPosition>77.9421823631571</endPosition>
				</positions>
				<positions axis="Omega" unit="deg">
					<commonPosition>22.1392375839558</commonPosition>
				</positions>
				<positions axis="Phi" unit="deg">
					<commonPosition>8.92</commonPosition>
				</positions>
				<positions axis="Chi" unit="deg">
					<commonPosition>-0.09</commonPosition>
				</positions>
				<positions axis="X" unit="mm">
					<commonPosition>-0.32</commonPosition>
				</positions>
				<positions axis="Y" unit="mm">
					<commonPosition>0</commonPosition>
				</positions>
				<positions axis="Z" unit="mm">
					<commonPosition>8.821</commonPosition>
				</positions>
				<commonCountingTime unit="seconds">0.189</commonCountingTime>
				<counts unit="counts">0 0 0 0 1 0 0 0 0 0 0 0 0 0 1 0 0 0 0 0 0 0 0 0 0 0 0 0 0 0 0 1 0 2 1 0 0 0 0 1 0 0 0 0 0 0 0 0 0 0 0 0 0 0 0 0 0 0 0 0 0 0 0 0 0 0 0 0 0 0 0 0 0 3 0 0 0 0 0 0 0 0 0 0 0 0 0 0 0 0 1 0 0 1 1 0 0 0 0 0 0 0 0 0 0 0 0 0 0 0 0 0 0 0 0 0 0 0 0 0 0 0 0 0 0 0 0 0 0 1 0 0 0 0 0 0 0 0 0 0 0 0 0 1 0 0 0 0 0 0 0 0 0 0 0 0 0 0 0 0 0 0 0 0 2 0 0 1 0 0 0 0 0 0 0 0 0 0 0 0 0 1 0 0 0 0 0 0 0 0 0 0 0 0 0 0 0 0 0 0 0 0 0 0 0 0 1 0 0 0 0 0 0 0 0 1 0 1 0 1 0 0 0 0 0 0 0 0 0 0 0 0 1 0 0 0 0 1 0 0 0 0 1 0 0 0 0 0 0 0 0 0 0 0 0</counts>
			</dataPoints>
		</scan>
		<scan status="Completed" appendNumber="0" scanAxis="2Theta" mode="Continuous">
			<header>
				<startTimeStamp>2022-06-16T15:51:56-07:00</startTimeStamp>
				<endTimeStamp>2022-06-16T15:54:49-07:00</endTimeStamp>
				<author>
					<name>XRD</name>
				</author>
				<source>
					<applicationSoftware version="6.1b">Data Collector</applicationSoftware>
					<instrumentControlSoftware version="7.4b 20181204">XPERT-3</instrumentControlSoftware>
					<instrumentID>0000000011163216</instrumentID>
				</source>
			</header>
			<dataPoints>
				<positions axis="2Theta" unit="deg">
					<startPosition>75.431417636843</startPosition>
					<endPosition>77.9421823631571</endPosition>
				</positions>
				<positions axis="Omega" unit="deg">
					<commonPosition>22.1441614399631</commonPosition>
				</positions>
				<positions axis="Phi" unit="deg">
					<commonPosition>8.92</commonPosition>
				</positions>
				<positions axis="Chi" unit="deg">
					<commonPosition>-0.09</commonPosition>
				</positions>
				<positions axis="X" unit="mm">
					<commonPosition>-0.32</commonPosition>
				</positions>
				<positions axis="Y" unit="mm">
					<commonPosition>0</commonPosition>
				</positions>
				<positions axis="Z" unit="mm">
					<commonPosition>8.821</commonPosition>
				</positions>
				<commonCountingTime unit="seconds">0.189</commonCountingTime>
				<counts unit="counts">0 0 0 0 0 1 0 0 0 0 0 0 0 0 1 0 1 0 0 0 0 0 0 0 1 0 0 0 0 0 0 0 0 0 0 0 0 0 0 0 0 0 0 0 0 0 0 0 0 0 0 0 0 1 0 0 1 0 0 0 0 0 0 0 0 0 0 0 0 0 0 0 0 0 0 0 0 0 0 1 0 0 0 0 2 0 0 0 0 0 0 0 0 0 0 0 0 0 0 0 0 0 0 0 0 0 0 0 1 0 0 0 0 0 0 1 0 0 0 0 1 0 0 0 0 0 0 0 0 0 0 0 0 0 0 0 0 0 0 0 0 0 0 0 0 0 0 0 0 0 0 0 0 0 0 0 0 0 0 0 0 0 1 0 0 0 0 0 0 0 0 0 0 0 0 1 0 0 0 0 0 0 0 0 0 0 0 0 0 0 0 0 0 0 0 0 0 1 0 0 0 0 1 0 0 0 0 0 1 0 0 0 0 0 0 0 1 0 0 0 0 0 0 0 0 0 1 0 0 1 0 0 0 0 0 0 0 0 0 0 0 0 1 1 0 0 0 0 0 0 0 0 0 0 0</counts>
			</dataPoints>
		</scan>
		<scan status="Completed" appendNumber="0" scanAxis="2Theta" mode="Continuous">
			<header>
				<startTimeStamp>2022-06-16T15:51:56-07:00</startTimeStamp>
				<endTimeStamp>2022-06-16T15:54:49-07:00</endTimeStamp>
				<author>
					<name>XRD</name>
				</author>
				<source>
					<applicationSoftware version="6.1b">Data Collector</applicationSoftware>
					<instrumentControlSoftware version="7.4b 20181204">XPERT-3</instrumentControlSoftware>
					<instrumentID>0000000011163216</instrumentID>
				</source>
			</header>
			<dataPoints>
				<positions axis="2Theta" unit="deg">
					<startPosition>75.431417636843</startPosition>
					<endPosition>77.9421823631571</endPosition>
				</positions>
				<positions axis="Omega" unit="deg">
					<commonPosition>22.1490852959705</commonPosition>
				</positions>
				<positions axis="Phi" unit="deg">
					<commonPosition>8.92</commonPosition>
				</positions>
				<positions axis="Chi" unit="deg">
					<commonPosition>-0.09</commonPosition>
				</positions>
				<positions axis="X" unit="mm">
					<commonPosition>-0.32</commonPosition>
				</positions>
				<positions axis="Y" unit="mm">
					<commonPosition>0</commonPosition>
				</positions>
				<positions axis="Z" unit="mm">
					<commonPosition>8.821</commonPosition>
				</positions>
				<commonCountingTime unit="seconds">0.189</commonCountingTime>
				<counts unit="counts">0 0 0 0 0 0 1 0 0 0 0 0 0 0 0 0 0 0 0 0 0 0 1 0 0 0 0 0 0 0 0 1 0 1 0 1 0 0 0 0 0 0 0 0 0 0 0 0 0 0 0 0 0 1 0 0 0 0 1 0 0 1 0 0 0 0 0 0 0 0 0 0 0 0 0 0 0 1 1 1 0 0 0 0 0 0 0 0 0 0 0 0 0 0 0 0 0 0 0 0 0 0 0 0 0 0 0 2 0 0 0 0 0 0 1 0 0 2 0 0 0 0 0 0 0 0 0 0 0 0 1 0 0 0 0 0 0 0 0 0 0 0 0 0 0 1 0 0 1 0 0 0 0 0 0 0 0 0 1 0 0 0 0 0 0 0 0 0 0 0 0 0 0 0 0 0 0 0 0 0 0 0 0 0 0 0 1 0 0 0 0 0 0 0 0 0 1 0 0 0 1 0 0 0 0 0 0 0 0 0 0 1 0 0 0 0 2 0 0 0 0 0 0 0 0 0 0 0 0 0 0 0 0 0 0 0 0 0 0 0 0 0 0 0 0 0 0 0 0 0 0 0 0 0 0</counts>
			</dataPoints>
		</scan>
		<scan status="Completed" appendNumber="0" scanAxis="2Theta" mode="Continuous">
			<header>
				<startTimeStamp>2022-06-16T15:51:56-07:00</startTimeStamp>
				<endTimeStamp>2022-06-16T15:54:49-07:00</endTimeStamp>
				<author>
					<name>XRD</name>
				</author>
				<source>
					<applicationSoftware version="6.1b">Data Collector</applicationSoftware>
					<instrumentControlSoftware version="7.4b 20181204">XPERT-3</instrumentControlSoftware>
					<instrumentID>0000000011163216</instrumentID>
				</source>
			</header>
			<dataPoints>
				<positions axis="2Theta" unit="deg">
					<startPosition>75.431417636843</startPosition>
					<endPosition>77.9421823631571</endPosition>
				</positions>
				<positions axis="Omega" unit="deg">
					<commonPosition>22.1540091519779</commonPosition>
				</positions>
				<positions axis="Phi" unit="deg">
					<commonPosition>8.92</commonPosition>
				</positions>
				<positions axis="Chi" unit="deg">
					<commonPosition>-0.09</commonPosition>
				</positions>
				<positions axis="X" unit="mm">
					<commonPosition>-0.32</commonPosition>
				</positions>
				<positions axis="Y" unit="mm">
					<commonPosition>0</commonPosition>
				</positions>
				<positions axis="Z" unit="mm">
					<commonPosition>8.821</commonPosition>
				</positions>
				<commonCountingTime unit="seconds">0.189</commonCountingTime>
				<counts unit="counts">0 1 0 0 0 0 0 0 0 0 0 0 0 0 1 0 0 0 0 0 1 0 0 0 0 0 1 0 0 0 0 1 0 0 0 0 0 0 0 0 0 0 0 0 0 0 0 0 0 0 0 0 0 0 0 0 0 0 0 1 0 0 0 0 0 0 0 0 0 0 0 0 0 0 0 0 0 0 0 0 0 1 0 0 0 0 0 0 0 0 0 0 0 0 0 0 0 0 0 0 0 0 0 0 0 0 0 0 1 0 0 0 0 0 0 0 0 0 0 0 1 0 0 0 0 0 0 0 0 0 0 0 0 0 0 0 0 0 0 0 0 0 0 0 1 0 0 0 0 0 1 1 0 0 0 1 0 0 0 0 0 0 0 0 0 0 0 0 0 0 0 0 0 0 0 0 0 0 0 0 0 1 0 0 0 0 0 0 0 0 0 0 0 0 0 0 0 1 0 0 0 0 0 0 0 0 0 0 0 2 1 0 0 0 0 0 0 0 0 0 0 0 0 0 0 0 0 0 0 0 1 0 0 0 0 0 0 0 0 0 0 0 1 0 0 0 0 0 0 0 0 1 0 0 0</counts>
			</dataPoints>
		</scan>
		<scan status="Completed" appendNumber="0" scanAxis="2Theta" mode="Continuous">
			<header>
				<startTimeStamp>2022-06-16T15:51:56-07:00</startTimeStamp>
				<endTimeStamp>2022-06-16T15:54:49-07:00</endTimeStamp>
				<author>
					<name>XRD</name>
				</author>
				<source>
					<applicationSoftware version="6.1b">Data Collector</applicationSoftware>
					<instrumentControlSoftware version="7.4b 20181204">XPERT-3</instrumentControlSoftware>
					<instrumentID>0000000011163216</instrumentID>
				</source>
			</header>
			<dataPoints>
				<positions axis="2Theta" unit="deg">
					<startPosition>75.431417636843</startPosition>
					<endPosition>77.9421823631571</endPosition>
				</positions>
				<positions axis="Omega" unit="deg">
					<commonPosition>22.1589330079853</commonPosition>
				</positions>
				<positions axis="Phi" unit="deg">
					<commonPosition>8.92</commonPosition>
				</positions>
				<positions axis="Chi" unit="deg">
					<commonPosition>-0.09</commonPosition>
				</positions>
				<positions axis="X" unit="mm">
					<commonPosition>-0.32</commonPosition>
				</positions>
				<positions axis="Y" unit="mm">
					<commonPosition>0</commonPosition>
				</positions>
				<positions axis="Z" unit="mm">
					<commonPosition>8.821</commonPosition>
				</positions>
				<commonCountingTime unit="seconds">0.189</commonCountingTime>
				<counts unit="counts">1 0 0 0 0 0 0 0 0 0 0 0 0 0 0 0 0 0 0 0 0 0 0 0 0 0 0 0 0 0 0 0 0 0 0 1 0 1 0 0 0 0 0 0 0 0 0 0 0 0 0 0 0 0 0 0 0 0 2 0 0 0 0 0 0 0 0 0 0 0 0 0 1 0 0 0 0 0 0 0 0 0 1 0 0 0 0 0 0 0 0 0 0 0 0 0 0 0 0 0 0 1 0 0 0 0 0 0 0 0 0 0 0 0 1 0 0 0 1 0 0 0 1 0 0 0 0 0 0 0 0 0 0 0 0 0 0 0 0 0 0 0 0 0 0 0 0 0 0 0 0 0 0 0 0 0 0 0 0 0 0 0 0 0 0 0 1 0 0 0 0 0 0 0 0 0 0 0 0 0 0 0 1 0 1 1 0 0 0 1 0 0 0 0 0 0 0 0 0 0 1 0 0 0 2 0 0 0 0 0 1 0 0 0 0 0 0 0 0 0 0 0 0 0 0 0 0 0 0 0 0 0 0 0 0 0 0 0 0 1 0 0 0 0 0 0 0 1 0 0 0 0 0 1 0</counts>
			</dataPoints>
		</scan>
		<scan status="Completed" appendNumber="0" scanAxis="2Theta" mode="Continuous">
			<header>
				<startTimeStamp>2022-06-16T15:51:56-07:00</startTimeStamp>
				<endTimeStamp>2022-06-16T15:54:49-07:00</endTimeStamp>
				<author>
					<name>XRD</name>
				</author>
				<source>
					<applicationSoftware version="6.1b">Data Collector</applicationSoftware>
					<instrumentControlSoftware version="7.4b 20181204">XPERT-3</instrumentControlSoftware>
					<instrumentID>0000000011163216</instrumentID>
				</source>
			</header>
			<dataPoints>
				<positions axis="2Theta" unit="deg">
					<startPosition>75.431417636843</startPosition>
					<endPosition>77.9421823631571</endPosition>
				</positions>
				<positions axis="Omega" unit="deg">
					<commonPosition>22.1638568639926</commonPosition>
				</positions>
				<positions axis="Phi" unit="deg">
					<commonPosition>8.92</commonPosition>
				</positions>
				<positions axis="Chi" unit="deg">
					<commonPosition>-0.09</commonPosition>
				</positions>
				<positions axis="X" unit="mm">
					<commonPosition>-0.32</commonPosition>
				</positions>
				<positions axis="Y" unit="mm">
					<commonPosition>0</commonPosition>
				</positions>
				<positions axis="Z" unit="mm">
					<commonPosition>8.821</commonPosition>
				</positions>
				<commonCountingTime unit="seconds">0.189</commonCountingTime>
				<counts unit="counts">0 0 0 0 0 0 0 0 1 0 0 0 0 0 0 0 0 0 0 0 0 0 0 0 0 0 0 0 1 0 1 0 0 0 0 0 0 0 2 0 0 0 0 0 0 0 0 0 1 0 0 0 0 0 0 0 1 0 1 0 0 0 0 1 0 0 0 0 0 0 0 0 0 0 0 0 0 0 0 0 0 0 0 0 0 0 0 1 0 0 0 0 1 0 0 0 0 0 0 0 0 1 1 0 0 0 0 0 0 0 0 0 0 0 1 0 0 0 0 0 0 0 0 0 0 0 0 0 0 0 0 0 0 0 0 0 0 0 0 0 0 0 0 0 1 0 1 0 0 0 0 0 0 0 1 0 0 0 0 0 0 0 0 0 0 0 0 0 0 0 0 0 0 1 0 0 0 1 0 1 0 0 0 0 0 1 0 1 0 0 0 0 2 0 0 0 0 0 0 0 0 0 0 0 0 0 0 0 0 0 0 0 0 0 0 0 0 0 0 0 0 0 0 1 0 0 0 0 0 0 0 0 0 1 0 0 0 0 0 0 0 0 0 0 0 0 0 0 0 0 0 1 0 0 0</counts>
			</dataPoints>
		</scan>
		<scan status="Completed" appendNumber="0" scanAxis="2Theta" mode="Continuous">
			<header>
				<startTimeStamp>2022-06-16T15:51:56-07:00</startTimeStamp>
				<endTimeStamp>2022-06-16T15:54:49-07:00</endTimeStamp>
				<author>
					<name>XRD</name>
				</author>
				<source>
					<applicationSoftware version="6.1b">Data Collector</applicationSoftware>
					<instrumentControlSoftware version="7.4b 20181204">XPERT-3</instrumentControlSoftware>
					<instrumentID>0000000011163216</instrumentID>
				</source>
			</header>
			<dataPoints>
				<positions axis="2Theta" unit="deg">
					<startPosition>75.431417636843</startPosition>
					<endPosition>77.9421823631571</endPosition>
				</positions>
				<positions axis="Omega" unit="deg">
					<commonPosition>22.16878072</commonPosition>
				</positions>
				<positions axis="Phi" unit="deg">
					<commonPosition>8.92</commonPosition>
				</positions>
				<positions axis="Chi" unit="deg">
					<commonPosition>-0.09</commonPosition>
				</positions>
				<positions axis="X" unit="mm">
					<commonPosition>-0.32</commonPosition>
				</positions>
				<positions axis="Y" unit="mm">
					<commonPosition>0</commonPosition>
				</positions>
				<positions axis="Z" unit="mm">
					<commonPosition>8.821</commonPosition>
				</positions>
				<commonCountingTime unit="seconds">0.189</commonCountingTime>
				<counts unit="counts">0 0 0 0 1 0 0 0 0 1 0 1 0 0 0 0 0 1 0 0 0 0 0 0 0 0 0 0 0 0 0 0 0 0 0 0 0 0 0 0 0 0 0 0 0 0 0 0 0 0 0 0 0 0 0 0 0 0 0 0 0 0 0 0 0 0 0 0 0 0 0 0 0 0 0 0 0 0 0 0 0 0 1 0 0 0 0 0 0 0 0 0 0 0 0 0 0 0 0 0 0 1 0 0 0 0 0 0 1 1 0 0 0 0 0 0 0 0 0 0 0 0 0 0 0 0 0 0 0 0 0 0 0 0 0 0 0 0 0 0 0 0 0 0 0 0 0 0 0 0 0 0 0 0 0 0 0 0 0 0 0 0 0 0 0 0 0 0 0 0 1 0 0 0 0 0 1 0 0 0 0 0 0 0 0 0 0 0 0 0 0 0 0 0 0 1 0 0 0 0 0 0 0 0 0 0 0 0 0 0 0 0 0 0 0 0 0 0 0 0 0 0 0 0 1 0 0 0 0 0 0 0 0 0 0 0 0 0 0 0 0 0 0 0 0 1 1 1 0 0 0 0 0 0 0</counts>
			</dataPoints>
		</scan>
	</xrdMeasurement>
</xrdMeasurements>