File: data/previous_data/set_3-YG035-038/xrd/YG035-SRO001-STO001-06152022.xrdml
<xrdMeasurements xmlns="http://www.xrdml.com/XRDMeasurement/2.1" xmlns:xsi="http://www.w3.org/2001/XMLSchema-instance" xsi:schemaLocation="http://www.xrdml.com/XRDMeasurement/2.1 http://www.xrdml.com/XRDMeasurement/2.1/XRDMeasurement.xsd" status="Completed">
	<comment>
		<entry>Configuration=Main Configuration, Owner=User-1, Creation date=6/17/2015 3:36:16 PM</entry>
		<entry>Goniometer=HR HD (Theta/2Theta); Minimum step size 2Theta:0.0001; Minimum step size Omega:0.0001</entry>
		<entry>Sample stage=MRD Cradle; Minimum step size Phi:0.01; Minimum step size Chi:0.01; Minimum step size X:0.01; Minimum step size Y:0.01; Minimum step size Z:0.001</entry>
		<entry>Diffractometer system=XPERT-3</entry>
		<entry>Measurement program=C:\PANalytical\Data Collector\Programs\Yichen\regular_2theta_20-50_0.4s-20min.xrdmp, Identifier={AEA8F2F2-8BFA-4B07-A521-A571AF38E73A}</entry>
	</comment>
	<sample type="To be analyzed">
		<id></id>
		<name></name>
		<preparedBy></preparedBy>
	</sample>
	<xrdMeasurement measurementType="Scan" status="Completed" sampleMode="Reflection">
		<comment>
			<entry>PHD Lower Level = 4.02 (keV), PHD Upper Level = 11.27 (keV)</entry>
		</comment>
		<usedWavelength intended="K-Alpha 1">
			<kAlpha1 unit="Angstrom">1.5405980</kAlpha1>
			<kAlpha2 unit="Angstrom">1.5444260</kAlpha2>
			<kBeta unit="Angstrom">1.3922500</kBeta>
			<ratioKAlpha2KAlpha1>0.5000</ratioKAlpha2KAlpha1>
		</usedWavelength>
		<incidentBeamPath>
			<radius unit="mm">320.00</radius>
			<xRayTube id="1010048" name="Empyrean Cu LFF HR (9430 033 7310x) DK425175">
				<tension unit="kV">45.0</tension>
				<current unit="mA">40.0</current>
				<anodeMaterial>Cu</anodeMaterial>
				<focus type="Line">
					<length unit="mm">12.0</length>
					<width unit="mm">0.4</width>
					<takeOffAngle unit="deg">4.2</takeOffAngle>
				</focus>
			</xRayTube>
			<xRayMirror id="27090001" name="Inc. Beam Cu W/Si (hybrid MRD)" hybrid="true">
				<crystal type="Graded" shape="Parabolic">W/Si</crystal>
				<acceptanceAngle unit="deg">0.800</acceptanceAngle>
				<length unit="mm">60.0</length>
			</xRayMirror>
			<monochromator id="23090002" name="Hybrid monochr. 2xGe(220) Cu asym." hybrid="true">
				<crystal type="Asymmetric" shape="Flat">Ge</crystal>
				<numberOfReflections>2</numberOfReflections>
				<hkl>
					<h>2</h>
					<k>2</k>
					<l>0</l>
				</hkl>
			</monochromator>
			<divergenceSlit id="22010004" name="Fixed slit 1/2°" xsi:type="fixedDivergenceSlitType">
				<distanceToSample unit="mm">220.00</distanceToSample>
				<height unit="mm">0.76</height>
			</divergenceSlit>
			<beamAttenuator id="26010001" name="Progr. beam attenuator Ni 0.125 mm" xsi:type="intensitySwitchedBeamAttenuatorType">
				<factor>172.00</factor>
				<material>Ni</material>
				<activateLevel unit="counts per second">500000</activateLevel>
				<deactivateLevel unit="counts per second">400000</deactivateLevel>
			</beamAttenuator>
		</incidentBeamPath>
		<diffractedBeamPath>
			<radius unit="mm">320.00</radius>
			<antiScatterSlit id="22090009" name="AS slit 7.5 mm (PIXcel)" xsi:type="fixedAntiScatterSlitType">
				<height unit="mm">7.50</height>
			</antiScatterSlit>
			<sollerSlit id="21010002" name="Soller slits 0.04 rad.">
				<opening unit="rad">0.0400</opening>
			</sollerSlit>
			<receivingSlit id="22010004" name="Fixed slit 1/2°">
				<height unit="mm">0.76</height>
			</receivingSlit>
			<detector id="7010020" name="PIXcel3D-Medipix3 1x1 detector" xsi:type="areaDetectorType">
				<phd unit="%">
					<lowerLevel>25.0</lowerLevel>
					<upperLevel>70.0</upperLevel>
				</phd>
				<mode>Receiving slit</mode>
				<activeChannelsEquatorial>5</activeChannelsEquatorial>
				<activeChannelsAxial>255</activeChannelsAxial>
				<pitchEquatorial unit="mm">0.05500</pitchEquatorial>
				<pitchAxial unit="mm">0.05500</pitchAxial>
				<readOutPeriod unit="seconds">0.050</readOutPeriod>
			</detector>
		</diffractedBeamPath>
		<scan appendNumber="0" mode="Continuous" scanAxis="2Theta-Omega" status="Completed">
			<header>
				<startTimeStamp>2022-06-15T16:52:32-07:00</startTimeStamp>
				<endTimeStamp>2022-06-15T17:12:57-07:00</endTimeStamp>
				<author>
					<name>XRD</name>
				</author>
				<source>
					<applicationSoftware version="6.1b">Data Collector</applicationSoftware>
					<instrumentControlSoftware version="7.4b 20181204">XPERT-3</instrumentControlSoftware>
					<instrumentID>0000000011163216</instrumentID>
				</source>
			</header>
			<dataPoints>
				<positions axis="2Theta" unit="deg">
					<startPosition>20.0050</startPosition>
					<endPosition>49.9950</endPosition>
				</positions>
				<positions axis="Omega" unit="deg">
					<startPosition>10.4492</startPosition>
					<endPosition>25.4442</endPosition>
				</positions>
				<positions axis="Phi" unit="deg">
					<commonPosition>0.00</commonPosition>
				</positions>
				<positions axis="Chi" unit="deg">
					<commonPosition>-0.21</commonPosition>
				</positions>
				<positions axis="X" unit="mm">
					<commonPosition>0.09</commonPosition>
				</positions>
				<positions axis="Y" unit="mm">
					<commonPosition>0.00</commonPosition>
				</positions>
				<positions axis="Z" unit="mm">
					<commonPosition>8.794</commonPosition>
				</positions>
				<beamAttenuationFactors>1.00 1.00 1.00 1.00 1.00 1.00 1.00 1.00 1.00 1.00 1.00 1.00 1.00 1.00 1.00 1.00 1.00 1.00 1.00 1.00 1.00 1.00 1.00 1.00 1.00 1.00 1.00 1.00 1.00 1.00 1.00 1.00 1.00 1.00 1.00 1.00 1.00 1.00 1.00 1.00 1.00 1.00 1.00 1.00 1.00 1.00 1.00 1.00 1.00 1.00 1.00 1.00 1.00 1.00 1.00 1.00 1.00 1.00 1.00 1.00 1.00 1.00 1.00 1.00 1.00 1.00 1.00 1.00 1.00 1.00 1.00 1.00 1.00 1.00 1.00 1.00 1.00 1.00 1.00 1.00 1.00 1.00 1.00 1.00 1.00 1.00 1.00 1.00 1.00 1.00 1.00 1.00 1.00 1.00 1.00 1.00 1.00 1.00 1.00 1.00 1.00 1.00 1.00 1.00 1.00 1.00 1.00 1.00 1.00 1.00 1.00 1.00 1.00 1.00 1.00 1.00 1.00 1.00 1.00 1.00 1.00 1.00 1.00 1.00 1.00 1.00 1.00 1.00 1.00 1.00 1.00 1.00 1.00 1.00 1.00 1.00 1.00 1.00 1.00 1.00 1.00 1.00 1.00 1.00 1.00 1.00 1.00 1.00 1.00 1.00 1.00 1.00 1.00 1.00 1.00 1.00 1.00 1.00 1.00 1.00 1.00 1.00 1.00 1.00 1.00 1.00 1.00 1.00 1.00 1.00 1.00 1.00 1.00 1.00 1.00 1.00 1.00 1.00 1.00 1.00 1.00 1.00 1.00 1.00 1.00 1.00 1.00 1.00 1.00 1.00 1.00 1.00 1.00 1.00 1.00 1.00 1.00 1.00 1.00 1.00 1.00 1.00 1.00 1.00 1.00 1.00 1.00 1.00 1.00 1.00 1.00 1.00 1.00 1.00 1.00 1.00 1.00 1.00 1.00 1.00 1.00 1.00 1.00 1.00 1.00 1.00 1.00 1.00 1.00 1.00 1.00 1.00 1.00 1.00 1.00 1.00 1.00 1.00 1.00 1.00 1.00 1.00 1.00 1.00 1.00 1.00 1.00 1.00 1.00 1.00 1.00 1.00 1.00 1.00 1.00 1.00 1.00 1.00 1.00 1.00 1.00 1.00 1.00 1.00 1.00 1.00 1.00 1.00 1.00 1.00 1.00 1.00 1.00 1.00 1.00 1.00 1.00 1.00 1.00 1.00 1.00 1.00 1.00 1.00 1.00 1.00 1.00 1.00 1.00 1.00 1.00 1.00 1.00 1.00 1.00 1.00 1.00 1.00 1.00 1.00 1.00 1.00 1.00 1.00 1.00 1.00 1.00 1.00 1.00 1.00 1.00 1.00 1.00 1.00 1.00 1.00 1.00 1.00 1.00 1.00 1.00 1.00 1.00 1.00 1.00 1.00 1.00 1.00 1.00 1.00 1.00 1.00 1.00 1.00 1.00 1.00 1.00 1.00 1.00 1.00 1.00 1.00 1.00 1.00 1.00 1.00 1.00 1.00 1.00 1.00 1.00 1.00 1.00 1.00 1.00 1.00 1.00 1.00 1.00 1.00 1.00 1.00 1.00 1.00 1.00 1.00 1.00 1.00 1.00 1.00 1.00 1.00 1.00 1.00 1.00 1.00 1.00 1.00 1.00 1.00 1.00 1.00 1.00 1.00 1.00 1.00 1.00 1.00 1.00 1.00 1.00 1.00 1.00 1.00 1.00 1.00 1.00 1.00 1.00 1.00 1.00 1.00 1.00 1.00 1.00 1.00 1.00 1.00 1.00 1.00 1.00 1.00 1.00 1.00 1.00 1.00 1.00 1.00 1.00 1.00 1.00 1.00 1.00 1.00 1.00 1.00 1.00 1.00 1.00 1.00 1.00 1.00 1.00 1.00 1.00 1.00 1.00 1.00 1.00 1.00 1.00 1.00 1.00 1.00 1.00 1.00 1.00 1.00 1.00 1.00 1.00 1.00 1.00 1.00 1.00 1.00 1.00 1.00 1.00 1.00 1.00 1.00 1.00 1.00 1.00 1.00 1.00 1.00 1.00 1.00 1.00 1.00 1.00 1.00 1.00 1.00 1.00 1.00 1.00 1.00 1.00 1.00 1.00 1.00 1.00 1.00 1.00 1.00 1.00 1.00 1.00 1.00 1.00 1.00 1.00 1.00 1.00 1.00 1.00 1.00 1.00 1.00 1.00 1.00 1.00 1.00 1.00 1.00 1.00 1.00 1.00 1.00 1.00 1.00 1.00 1.00 1.00 1.00 1.00 1.00 1.00 1.00 1.00 1.00 1.00 1.00 1.00 1.00 1.00 1.00 1.00 1.00 1.00 1.00 1.00 1.00 1.00 1.00 1.00 1.00 1.00 1.00 1.00 1.00 1.00 1.00 1.00 1.00 1.00 1.00 1.00 1.00 1.00 1.00 1.00 1.00 1.00 1.00 1.00 1.00 1.00 1.00 1.00 1.00 1.00 1.00 1.00 1.00 1.00 1.00 1.00 1.00 1.00 1.00 1.00 1.00 1.00 1.00 1.00 1.00 1.00 1.00 1.00 1.00 1.00 1.00 1.00 1.00 1.00 1.00 1.00 1.00 1.00 1.00 1.00 1.00 1.00 1.00 1.00 1.00 1.00 1.00 1.00 1.00 1.00 1.00 1.00 1.00 1.00 1.00 1.00 1.00 1.00 1.00 1.00 1.00 1.00 1.00 1.00 1.00 1.00 1.00 1.00 1.00 1.00 1.00 1.00 1.00 1.00 1.00 1.00 1.00 1.00 1.00 1.00 1.00 1.00 1.00 1.00 1.00 1.00 1.00 1.00 1.00 1.00 1.00 1.00 1.00 1.00 1.00 1.00 1.00 1.00 1.00 1.00 1.00 1.00 1.00 1.00 1.00 1.00 1.00 1.00 1.00 1.00 1.00 1.00 1.00 1.00 1.00 1.00 1.00 1.00 1.00 1.00 1.00 1.00 1.00 1.00 1.00 1.00 1.00 1.00 1.00 1.00 1.00 1.00 1.00 1.00 1.00 1.00 1.00 1.00 1.00 1.00 1.00 1.00 1.00 1.00 1.00 1.00 1.00 1.00 1.00 1.00 1.00 1.00 1.00 1.00 1.00 1.00 1.00 1.00 1.00 1.00 1.00 1.00 1.00 1.00 1.00 1.00 1.00 1.00 1.00 1.00 1.00 1.00 1.00 1.00 1.00 1.00 1.00 1.00 1.00 1.00 1.00 1.00 1.00 1.00 1.00 1.00 1.00 1.00 1.00 1.00 1.00 1.00 1.00 1.00 1.00 1.00 1.00 1.00 1.00 1.00 1.00 1.00 1.00 1.00 1.00 1.00 1.00 1.00 1.00 1.00 1.00 1.00 1.00 1.00 1.00 1.00 1.00 1.00 1.00 1.00 1.00 1.00 1.00 1.00 1.00 1.00 1.00 1.00 1.00 1.00 1.00 1.00 1.00 1.00 1.00 1.00 1.00 1.00 1.00 1.00 1.00 1.00 1.00 1.00 1.00 1.00 1.00 1.00 1.00 1.00 1.00 1.00 1.00 1.00 1.00 1.00 1.00 1.00 1.00 1.00 1.00 1.00 1.00 1.00 1.00 1.00 1.00 1.00 1.00 1.00 1.00 1.00 1.00 1.00 1.00 1.00 1.00 1.00 1.00 1.00 1.00 1.00 1.00 1.00 1.00 1.00 1.00 1.00 1.00 1.00 1.00 1.00 1.00 1.00 1.00 1.00 1.00 1.00 1.00 1.00 1.00 1.00 1.00 1.00 1.00 1.00 1.00 1.00 1.00 1.00 1.00 1.00 1.00 1.00 1.00 1.00 1.00 1.00 1.00 1.00 1.00 1.00 1.00 1.00 1.00 1.00 1.00 1.00 1.00 1.00 1.00 1.00 1.00 1.00 1.00 1.00 1.00 1.00 1.00 1.00 1.00 1.00 1.00 1.00 1.00 1.00 1.00 1.00 1.00 1.00 1.00 1.00 1.00 1.00 1.00 1.00 1.00 1.00 1.00 1.00 1.00 1.00 1.00 1.00 1.00 1.00 1.00 1.00 1.00 1.00 1.00 1.00 1.00 1.00 1.00 1.00 1.00 1.00 1.00 1.00 1.00 1.00 1.00 1.00 1.00 1.00 1.00 1.00 1.00 1.00 1.00 1.00 1.00 1.00 1.00 1.00 1.00 1.00 1.00 1.00 1.00 1.00 1.00 1.00 1.00 1.00 1.00 1.00 1.00 1.00 1.00 1.00 1.00 1.00 1.00 1.00 1.00 1.00 1.00 1.00 1.00 1.00 1.00 1.00 1.00 1.00 1.00 1.00 1.00 1.00 1.00 1.00 1.00 1.00 1.00 1.00 1.00 1.00 1.00 1.00 1.00 1.00 1.00 1.00 1.00 1.00 1.00 1.00 1.00 1.00 1.00 1.00 1.00 1.00 1.00 1.00 1.00 1.00 1.00 1.00 1.00 1.00 1.00 1.00 1.00 1.00 1.00 1.00 1.00 1.00 1.00 1.00 1.00 1.00 1.00 1.00 1.00 1.00 1.00 1.00 1.00 1.00 1.00 1.00 1.00 1.00 1.00 1.00 1.00 1.00 1.00 1.00 1.00 1.00 1.00 1.00 1.00 1.00 1.00 1.00 1.00 1.00 1.00 1.00 1.00 1.00 1.00 1.00 1.00 1.00 1.00 1.00 1.00 1.00 1.00 1.00 1.00 1.00 1.00 1.00 1.00 1.00 1.00 1.00 1.00 1.00 1.00 1.00 1.00 1.00 1.00 1.00 1.00 1.00 1.00 1.00 1.00 1.00 1.00 1.00 1.00 1.00 1.00 1.00 1.00 1.00 1.00 1.00 1.00 1.00 1.00 1.00 1.00 1.00 1.00 1.00 1.00 1.00 1.00 1.00 1.00 1.00 1.00 1.00 1.00 1.00 1.00 1.00 1.00 1.00 1.00 1.00 1.00 1.00 1.00 1.00 1.00 1.00 1.00 1.00 1.00 1.00 1.00 1.00 1.00 1.00 1.00 1.00 1.00 1.00 1.00 1.00 1.00 1.00 1.00 1.00 1.00 1.00 1.00 1.00 1.00 1.00 1.00 1.00 1.00 1.00 1.00 1.00 1.00 1.00 1.00 1.00 1.00 1.00 1.00 1.00 1.00 1.00 1.00 1.00 1.00 1.00 1.00 1.00 1.00 1.00 1.00 1.00 1.00 1.00 1.00 1.00 1.00 1.00 1.00 1.00 1.00 1.00 1.00 1.00 1.00 1.00 1.00 1.00 1.00 1.00 1.00 1.00 1.00 1.00 1.00 1.00 1.00 1.00 1.00 1.00 1.00 1.00 1.00 1.00 1.00 1.00 1.00 1.00 1.00 1.00 1.00 1.00 1.00 1.00 1.00 1.00 1.00 1.00 1.00 1.00 1.00 1.00 1.00 1.00 1.00 1.00 1.00 1.00 1.00 1.00 1.00 1.00 1.00 1.00 1.00 1.00 1.00 1.00 1.00 1.00 1.00 1.00 1.00 1.00 1.00 1.00 1.00 1.00 1.00 1.00 1.00 1.00 1.00 1.00 1.00 1.00 1.00 1.00 1.00 1.00 1.00 1.00 1.00 1.00 1.00 1.00 1.00 1.00 1.00 1.00 1.00 1.00 1.00 1.00 1.00 1.00 1.00 1.00 1.00 1.00 1.00 1.00 1.00 1.00 1.00 1.00 1.00 1.00 1.00 1.00 1.00 1.00 1.00 1.00 1.00 1.00 1.00 1.00 1.00 1.00 1.00 1.00 1.00 1.00 1.00 1.00 1.00 1.00 1.00 1.00 1.00 1.00 1.00 1.00 1.00 1.00 1.00 1.00 1.00 1.00 1.00 1.00 1.00 1.00 1.00 1.00 1.00 1.00 1.00 1.00 1.00 1.00 1.00 1.00 1.00 1.00 1.00 1.00 1.00 1.00 1.00 1.00 1.00 1.00 1.00 1.00 1.00 1.00 1.00 1.00 1.00 1.00 1.00 1.00 1.00 1.00 1.00 1.00 1.00 1.00 1.00 1.00 1.00 1.00 1.00 1.00 1.00 1.00 1.00 1.00 1.00 1.00 1.00 1.00 1.00 1.00 1.00 1.00 1.00 1.00 1.00 1.00 1.00 1.00 1.00 1.00 1.00 1.00 1.00 1.00 1.00 1.00 1.00 1.00 1.00 1.00 1.00 1.00 1.00 1.00 1.00 1.00 1.00 1.00 1.00 1.00 1.00 1.00 1.00 1.00 1.00 1.00 1.00 1.00 1.00 1.00 1.00 1.00 1.00 1.00 1.00 1.00 1.00 1.00 1.00 1.00 1.00 1.00 1.00 1.00 1.00 1.00 1.00 1.00 1.00 1.00 1.00 1.00 1.00 1.00 1.00 1.00 1.00 1.00 1.00 1.00 1.00 1.00 1.00 1.00 1.00 1.00 1.00 1.00 1.00 1.00 1.00 1.00 1.00 1.00 1.00 1.00 1.00 1.00 1.00 1.00 1.00 1.00 1.00 1.00 1.00 1.00 1.00 1.00 1.00 1.00 1.00 1.00 1.00 1.00 1.00 1.00 1.00 1.00 1.00 1.00 1.00 1.00 1.00 1.00 1.00 1.00 1.00 1.00 1.00 1.00 1.00 1.00 1.00 1.00 1.00 1.00 1.00 1.00 1.00 1.00 1.00 1.00 1.00 1.00 1.00 1.00 1.00 1.00 1.00 1.00 1.00 1.00 1.00 1.00 1.00 1.00 1.00 1.00 1.00 1.00 1.00 1.00 1.00 1.00 1.00 1.00 1.00 1.00 1.00 1.00 1.00 1.00 1.00 1.00 1.00 1.00 1.00 1.00 1.00 1.00 1.00 1.00 1.00 1.00 1.00 1.00 1.00 1.00 1.00 1.00 1.00 1.00 1.00 1.00 1.00 1.00 1.00 1.00 1.00 1.00 1.00 1.00 1.00 1.00 1.00 1.00 1.00 1.00 1.00 1.00 1.00 1.00 1.00 1.00 1.00 1.00 1.00 1.00 1.00 1.00 1.00 1.00 1.00 1.00 1.00 1.00 1.00 1.00 1.00 1.00 1.00 1.00 1.00 1.00 1.00 1.00 1.00 1.00 1.00 1.00 1.00 1.00 1.00 1.00 1.00 1.00 1.00 1.00 1.00 1.00 1.00 1.00 1.00 1.00 1.00 1.00 1.00 1.00 1.00 1.00 1.00 1.00 1.00 1.00 1.00 1.00 1.00 1.00 1.00 1.00 1.00 1.00 1.00 1.00 1.00 1.00 1.00 1.00 1.00 1.00 1.00 1.00 1.00 1.00 1.00 1.00 1.00 1.00 1.00 1.00 1.00 1.00 1.00 1.00 1.00 1.00 1.00 1.00 1.00 1.00 1.00 1.00 1.00 1.00 1.00 1.00 1.00 1.00 1.00 1.00 1.00 1.00 1.00 1.00 1.00 1.00 1.00 1.00 1.00 1.00 1.00 1.00 1.00 1.00 1.00 1.00 1.00 1.00 1.00 1.00 1.00 1.00 1.00 1.00 1.00 1.00 1.00 1.00 1.00 1.00 1.00 1.00 1.00 1.00 1.00 1.00 1.00 1.00 1.00 1.00 1.00 1.00 1.00 1.00 1.00 1.00 1.00 1.00 1.00 1.00 1.00 1.00 1.00 1.00 1.00 1.00 1.00 1.00 1.00 1.00 1.00 1.00 1.00 1.00 1.00 1.00 1.00 1.00 1.00 1.00 1.00 1.00 1.00 1.00 1.00 1.00 1.00 1.00 1.00 1.00 1.00 1.00 1.00 1.00 1.00 1.00 1.00 1.00 1.00 1.00 1.00 1.00 1.00 1.00 1.00 1.00 1.00 1.00 1.00 1.00 1.00 1.00 1.00 1.00 1.00 1.00 1.00 1.00 1.00 1.00 1.00 1.00 1.00 1.00 1.00 1.00 1.00 1.00 1.00 1.00 1.00 1.00 1.00 1.00 1.00 1.00 1.00 1.00 1.00 1.00 1.00 1.00 1.00 1.00 1.00 1.00 1.00 1.00 1.00 1.00 1.00 1.00 1.00 1.00 1.00 1.00 1.00 1.00 1.00 1.00 1.00 1.00 1.00 1.00 1.00 1.00 1.00 1.00 1.00 1.00 1.00 1.00 1.00 1.00 1.00 1.00 1.00 1.00 1.00 1.00 1.00 1.00 1.00 1.00 1.00 1.00 1.00 1.00 1.00 1.00 1.00 1.00 1.00 1.00 1.00 1.00 1.00 1.00 1.00 1.00 1.00 1.00 1.00 1.00 1.00 1.00 1.00 1.00 1.00 1.00 1.00 1.00 1.00 1.00 1.00 1.00 1.00 1.00 1.00 1.00 1.00 1.00 1.00 1.00 1.00 1.00 1.00 1.00 1.00 1.00 1.00 1.00 1.00 1.00 1.00 1.00 1.00 1.00 1.00 1.00 1.00 1.00 1.00 1.00 1.00 1.00 1.00 1.00 1.00 1.00 1.00 1.00 1.00 1.00 1.00 1.00 1.00 1.00 1.00 1.00 1.00 1.00 1.00 1.00 1.00 1.00 1.00 1.00 1.00 1.00 1.00 1.00 1.00 1.00 1.00 1.00 1.00 1.00 1.00 1.00 1.00 1.00 1.00 1.00 1.00 1.00 1.00 1.00 1.00 1.00 1.00 1.00 1.00 1.00 1.00 1.00 1.00 1.00 1.00 1.00 1.00 1.00 1.00 1.00 1.00 1.00 1.00 1.00 1.00 1.00 1.00 1.00 1.00 1.00 1.00 1.00 1.00 1.00 1.00 1.00 1.00 1.00 1.00 1.00 1.00 1.00 1.00 1.00 1.00 1.00 1.00 1.00 1.00 1.00 1.00 1.00 1.00 1.00 1.00 1.00 1.00 1.00 1.00 1.00 1.00 1.00 1.00 1.00 1.00 1.00 1.00 1.00 1.00 1.00 1.00 1.00 1.00 1.00 1.00 1.00 1.00 1.00 1.00 1.00 1.00 1.00 1.00 1.00 1.00 1.00 1.00 1.00 1.00 1.00 1.00 1.00 1.00 1.00 1.00 1.00 1.00 1.00 1.00 1.00 1.00 1.00 1.00 1.00 1.00 1.00 1.00 1.00 1.00 1.00 1.00 1.00 1.00 1.00 1.00 1.00 1.00 1.00 1.00 1.00 1.00 1.00 1.00 1.00 1.00 1.00 1.00 1.00 1.00 1.00 1.00 1.00 1.00 1.00 1.00 1.00 1.00 1.00 1.00 1.00 1.00 1.00 1.00 1.00 1.00 1.00 1.00 1.00 1.00 1.00 1.00 1.00 1.00 1.00 1.00 1.00 1.00 1.00 1.00 1.00 1.00 1.00 1.00 1.00 1.00 1.00 1.00 1.00 1.00 1.00 1.00 1.00 1.00 1.00 1.00 1.00 1.00 1.00 1.00 1.00 1.00 1.00 1.00 1.00 1.00 1.00 1.00 1.00 1.00 1.00 1.00 1.00 1.00 1.00 1.00 1.00 1.00 1.00 1.00 1.00 1.00 1.00 1.00 1.00 1.00 1.00 1.00 1.00 1.00 1.00 1.00 1.00 1.00 1.00 1.00 1.00 1.00 1.00 1.00 1.00 1.00 1.00 1.00 1.00 1.00 1.00 1.00 1.00 1.00 1.00 1.00 1.00 1.00 1.00 1.00 1.00 1.00 1.00 1.00 1.00 1.00 1.00 1.00 1.00 1.00 1.00 1.00 1.00 1.00 1.00 1.00 1.00 1.00 1.00 1.00 1.00 1.00 1.00 1.00 1.00 1.00 1.00 1.00 1.00 1.00 1.00 1.00 1.00 1.00 1.00 1.00 1.00 1.00 1.00 1.00 1.00 1.00 1.00 1.00 1.00 1.00 1.00 1.00 1.00 1.00 1.00 1.00 1.00 1.00 1.00 1.00 1.00 1.00 1.00 1.00 1.00 1.00 1.00 1.00 1.00 1.00 1.00 1.00 1.00 1.00 1.00 1.00 1.00 1.00 1.00 1.00 1.00 1.00 1.00 1.00 1.00 1.00 1.00 1.00 1.00 1.00 1.00 1.00 1.00 1.00 1.00 1.00 1.00 1.00 1.00 1.00 1.00 1.00 1.00 1.00 1.00 1.00 1.00 1.00 1.00 1.00 1.00 1.00 1.00 1.00 1.00 1.00 1.00 1.00 1.00 1.00 1.00 1.00 1.00 1.00 1.00 1.00 1.00 1.00 1.00 1.00 1.00 1.00 1.00 1.00 1.00 1.00 1.00 1.00 1.00 1.00 1.00 1.00 1.00 1.00 1.00 1.00 1.00 1.00 1.00 1.00 1.00 1.00 1.00 1.00 1.00 1.00 1.00 1.00 1.00 1.00 1.00 1.00 1.00 1.00 1.00 1.00 1.00 1.00 1.00 1.00 1.00 1.00 1.00 1.00 1.00 1.00 1.00 1.00 1.00 1.00 1.00 1.00 1.00 1.00 1.00 1.00 1.00 1.00 1.00 1.00 1.00 1.00 1.00 1.00 1.00 1.00 1.00 1.00 1.00 1.00 1.00 1.00 1.00 1.00 1.00 1.00 1.00 1.00 1.00 1.00 1.00 1.00 1.00 1.00 1.00 1.00 1.00 1.00 1.00 1.00 1.00 1.00 1.00 1.00 1.00 1.00 1.00 1.00 1.00 1.00 1.00 1.00 1.00 1.00 1.00 1.00 1.00 1.00 1.00 1.00 1.00 1.00 1.00 1.00 1.00 1.00 1.00 1.00 1.00 1.00 1.00 1.00 1.00 1.00 1.00 1.00 1.00 1.00 1.00 1.00 1.00 1.00 1.00 1.00 1.00 1.00 1.00 1.00 1.00 1.00 1.00 1.00 1.00 1.00 1.00 1.00 1.00 1.00 1.00 1.00 1.00 1.00 1.00 1.00 1.00 1.00 1.00 1.00 1.00 1.00 1.00 1.00 1.00 1.00 1.00 1.00 1.00 1.00 1.00 1.00 1.00 1.00 1.00 1.00 1.00 1.00 1.00 1.00 1.00 1.00 1.00 1.00 1.00 1.00 1.00 1.00 1.00 1.00 1.00 1.00 1.00 1.00 1.00 1.00 1.00 1.00 1.00 1.00 1.00 1.00 1.00 1.00 1.00 1.00 1.00 1.00 1.00 1.00 1.00 1.00 1.00 1.00 1.00 1.00 1.00 1.00 1.00 1.00 1.00 1.00 1.00 1.00 1.00 1.00 1.00 1.00 1.00 1.00 1.00 1.00 1.00 1.00 1.00 1.00 1.00 1.00 1.00 1.00 1.00 1.00 1.00 1.00 1.00 1.00 1.00 1.00 1.00 1.00 1.00 1.00 1.00 1.00 1.00 1.00 1.00 1.00 1.00 1.00 1.00 1.00 1.00 1.00 1.00 1.00 1.00 1.00 1.00 1.00 1.00 1.00 1.00 1.00 1.00 1.00 1.00 1.00 1.00 1.00 1.00 1.00 1.00 1.00 1.00 1.00 1.00 1.00 1.00 1.00 1.00 1.00 1.00 1.00 1.00 1.00 1.00 1.00 1.00 1.00 1.00 1.00 1.00 1.00 1.00 1.00 1.00 1.00 1.00 1.00 1.00 1.00 1.00 1.00 1.00 1.00 1.00 1.00 1.00 1.00 1.00 1.00 1.00 1.00 1.00 172.00 172.00 172.00 172.00 172.00 1.00 1.00 1.00 1.00 1.00 1.00 1.00 1.00 1.00 1.00 1.00 1.00 1.00 1.00 1.00 1.00 1.00 1.00 1.00 1.00 1.00 1.00 1.00 1.00 1.00 1.00 1.00 1.00 1.00 1.00 1.00 1.00 1.00 1.00 1.00 1.00 1.00 1.00 1.00 1.00 1.00 1.00 1.00 1.00 1.00 1.00 1.00 1.00 1.00 1.00 1.00 1.00 1.00 1.00 1.00 1.00 1.00 1.00 1.00 1.00 1.00 1.00 1.00 1.00 1.00 1.00 1.00 1.00 1.00 1.00 1.00 1.00 1.00 1.00 1.00 1.00 1.00 1.00 1.00 1.00 1.00 1.00 1.00 1.00 1.00 1.00 1.00 1.00 1.00 1.00 1.00 1.00 1.00 1.00 1.00 1.00 1.00 1.00 1.00 1.00 1.00 1.00 1.00 1.00 1.00 1.00 1.00 1.00 1.00 1.00 1.00 1.00 1.00 1.00 1.00 1.00 1.00 1.00 1.00 1.00 1.00 1.00 1.00 1.00 1.00 1.00 1.00 1.00 1.00 1.00 1.00 1.00 1.00 1.00 1.00 1.00 1.00 1.00 1.00 1.00 1.00 1.00 1.00 1.00 1.00 1.00 1.00 1.00 1.00 1.00 1.00 1.00 1.00 1.00 1.00 1.00 1.00 1.00 1.00 1.00 1.00 1.00 1.00 1.00 1.00 1.00 1.00 1.00 1.00 1.00 1.00 1.00 1.00 1.00 1.00 1.00 1.00 1.00 1.00 1.00 1.00 1.00 1.00 1.00 1.00 1.00 1.00 1.00 1.00 1.00 1.00 1.00 1.00 1.00 1.00 1.00 1.00 1.00 1.00 1.00 1.00 1.00 1.00 1.00 1.00 1.00 1.00 1.00 1.00 1.00 1.00 1.00 1.00 1.00 1.00 1.00 1.00 1.00 1.00 1.00 1.00 1.00 1.00 1.00 1.00 1.00 1.00 1.00 1.00 1.00 1.00 1.00 1.00 1.00 1.00 1.00 1.00 1.00 1.00 1.00 1.00 1.00 1.00 1.00 1.00 1.00 1.00 1.00 1.00 1.00 1.00 1.00 1.00 1.00 1.00 1.00 1.00 1.00 1.00 1.00 1.00 1.00 1.00 1.00 1.00 1.00 1.00 1.00 1.00 1.00 1.00 1.00 1.00 1.00 1.00 1.00 1.00 1.00 1.00 1.00 1.00 1.00 1.00 1.00 1.00 1.00 1.00 1.00 1.00 1.00 1.00 1.00 1.00 1.00 1.00 1.00 1.00 1.00 1.00 1.00 1.00 1.00 1.00 1.00 1.00 1.00 1.00 1.00 1.00 1.00 1.00 1.00 1.00 1.00 1.00 1.00 1.00 1.00 1.00 1.00 1.00 1.00 1.00 1.00 1.00 1.00 1.00 1.00 1.00 1.00 1.00 1.00 1.00 1.00 1.00 1.00 1.00 1.00 1.00 1.00 1.00 1.00 1.00 1.00 1.00 1.00 1.00 1.00 1.00 1.00</beamAttenuationFactors>
				<commonCountingTime unit="seconds">0.352</commonCountingTime>
				<counts unit="counts">26 32 41 40 46 47 31 37 27 30 32 33 27 33 35 54 36 41 35 34 28 35 33 33 36 37 37 34 36 45 23 31 29 34 38 39 35 31 35 28 48 27 37 35 44 35 36 32 34 33 22 35 41 44 39 56 35 39 30 43 37 42 36 25 39 30 38 23 33 41 39 35 36 25 38 36 42 33 26 36 45 34 34 32 40 35 33 34 35 30 40 38 29 36 41 33 36 32 46 34 33 35 31 26 28 31 28 44 30 38 21 37 26 46 28 29 22 25 31 40 41 29 32 32 18 24 39 30 31 32 30 31 34 29 30 29 34 45 36 28 28 43 38 40 30 27 31 34 36 30 25 21 17 28 23 34 30 33 33 25 32 37 47 31 32 34 35 31 29 35 40 38 43 27 34 39 35 31 32 39 34 34 32 25 44 34 42 41 31 33 35 42 37 34 34 40 36 33 29 29 30 28 32 44 46 47 59 58 60 49 75 38 70 55 69 53 52 71 44 50 41 37 43 46 47 73 79 131 157 206 295 243 390 476 440 713 616 731 1018 611 1198 945 1032 1362 728 1319 1084 929 1286 721 1009 907 615 752 609 436 431 358 205 250 245 123 149 224 411 999 1753 3334 5896 13147 34596 36080 63095 68084 78307 103675 42631 10158 1504 623 557 483 303 262 198 160 143 101 73 87 73 54 71 74 88 90 102 102 120 98 118 97 117 96 79 75 76 62 59 51 43 49 34 41 45 33 35 47 38 68 68 77 67 64 70 58 60 59 55 34 38 32 34 29 34 27 33 30 38 33 49 57 47 56 43 54 50 48 57 46 33 43 37 39 25 37 21 25 38 41 36 30 35 41 31 43 31 45 46 50 51 42 40 41 29 42 29 31 32 25 31 21 25 40 39 33 30 39 33 39 38 33 29 36 34 33 35 39 28 30 27 33 24 37 25 34 18 23 33 23 34 32 30 28 36 23 40 29 36 23 24 33 26 25 25 32 31 23 25 27 35 28 33 36 26 34 37 37 32 36 34 28 19 23 26 22 23 19 25 24 24 32 24 27 20 23 24 33 35 21 30 30 33 26 26 20 30 19 38 22 22 22 25 27 14 24 25 20 27 29 23 45 26 41 28 23 27 22 32 28 22 22 27 19 23 16 28 24 32 16 26 32 33 23 39 35 38 24 24 24 13 30 15 32 17 20 30 19 25 31 23 29 30 31 24 27 31 33 23 23 25 25 24 32 26 25 22 23 22 21 20 24 24 17 23 24 24 21 27 20 23 26 28 22 26 16 18 22 31 21 21 19 15 25 20 21 21 25 22 29 17 15 29 24 27 15 22 27 29 19 26 23 15 23 27 24 15 24 24 18 19 23 14 21 35 27 18 23 19 22 20 11 18 24 28 27 19 21 33 15 25 22 17 24 14 29 14 24 28 20 19 20 20 23 14 17 24 13 27 22 20 27 32 19 17 28 18 20 27 28 14 28 13 24 26 27 32 17 30 15 25 12 21 22 28 23 17 18 27 19 22 18 29 26 19 21 19 22 21 18 26 18 32 21 14 19 27 27 19 15 27 11 16 22 23 24 21 27 32 15 22 17 15 23 21 26 22 15 17 19 21 20 22 22 26 9 17 16 19 20 11 10 17 18 25 20 21 19 21 18 23 11 20 24 13 21 14 23 18 20 19 17 22 19 15 21 24 28 13 22 22 24 19 23 16 28 12 14 19 18 22 12 24 18 25 17 24 21 16 22 19 24 21 24 24 16 24 19 33 21 15 16 19 25 11 16 17 16 24 21 17 17 20 10 15 25 22 17 16 20 24 14 28 17 19 22 24 23 22 23 19 27 17 24 18 30 23 15 18 18 15 13 17 21 16 27 18 17 22 18 20 22 21 18 24 9 29 12 22 22 16 14 21 22 20 17 18 15 21 26 21 21 22 19 28 21 21 22 26 16 19 11 21 17 21 15 22 20 22 15 12 19 16 13 15 22 17 17 18 12 17 16 21 19 34 24 19 21 22 16 12 14 19 19 18 16 18 19 16 16 18 19 26 19 16 27 18 19 20 12 21 17 16 12 22 18 17 26 17 27 15 20 14 21 16 10 18 23 22 18 14 22 22 18 17 19 25 15 13 17 20 19 20 11 14 14 27 13 12 24 18 20 11 14 23 12 18 14 19 17 17 15 10 18 24 12 22 18 16 16 17 17 19 10 15 13 20 9 14 13 13 17 17 18 8 18 12 14 12 22 14 12 26 17 15 16 16 15 20 15 18 22 8 19 17 12 15 13 17 18 9 13 8 9 14 16 12 6 21 15 17 17 19 18 20 17 14 20 9 13 18 14 21 9 19 15 17 21 12 13 15 11 23 12 13 13 18 17 15 13 18 13 17 17 22 13 16 13 18 16 12 22 20 11 13 16 14 13 15 17 14 16 15 18 19 6 21 12 16 10 21 16 12 15 16 11 23 13 15 13 17 18 12 10 17 12 13 16 16 20 11 11 16 16 24 9 16 16 18 21 19 12 15 16 13 10 14 15 11 17 15 18 18 7 11 15 11 11 14 12 15 27 19 21 17 14 10 16 11 16 15 7 14 13 9 20 16 13 10 13 17 8 15 16 15 11 10 12 10 16 10 11 14 11 16 15 10 11 19 15 14 8 14 10 11 10 11 13 19 8 7 14 11 16 17 15 10 19 13 9 10 13 11 10 15 13 12 19 11 14 14 19 15 12 21 11 12 10 11 15 25 7 13 13 12 14 15 12 24 12 21 15 22 14 8 10 11 17 15 14 9 18 10 18 15 7 9 13 9 8 15 16 18 6 19 11 12 12 10 10 15 9 11 14 14 16 11 9 9 20 13 9 20 16 10 14 11 11 17 10 9 10 11 13 10 10 12 14 9 4 10 16 11 14 15 11 19 11 16 10 17 11 13 10 13 16 16 10 11 17 8 9 9 14 13 13 18 11 7 16 14 12 20 3 13 14 24 21 13 16 8 9 12 12 13 13 9 17 8 11 8 11 19 11 10 12 14 9 10 7 12 3 10 11 16 18 19 15 14 11 8 13 6 16 14 10 5 11 11 16 19 14 6 9 7 16 8 23 12 17 5 11 16 7 16 10 16 7 5 16 13 13 11 10 18 11 11 13 12 11 8 9 11 11 13 16 12 14 12 9 14 14 10 16 6 9 17 13 12 7 9 10 13 6 13 6 16 9 6 13 16 10 11 7 4 10 14 15 11 12 14 12 13 12 10 14 19 11 11 18 14 7 16 12 19 8 6 7 10 10 5 19 13 10 13 11 9 8 10 15 11 13 9 16 13 13 14 10 10 12 8 9 10 18 11 11 13 9 10 9 9 7 18 15 16 18 10 8 13 11 15 14 8 10 12 9 10 8 12 6 14 11 14 13 14 16 14 10 12 8 8 11 13 15 12 10 12 10 12 13 8 10 10 16 12 17 11 9 8 7 9 14 19 8 11 17 9 17 11 11 18 8 12 18 10 8 11 18 12 10 12 10 13 9 12 10 8 12 17 8 9 10 11 11 12 20 7 9 15 11 10 9 10 9 7 8 13 10 9 13 10 11 10 10 9 12 11 8 9 16 9 7 9 8 12 12 11 10 13 13 6 12 4 13 12 15 13 8 12 14 8 11 12 5 9 9 10 11 9 4 10 8 6 7 14 9 12 8 7 12 6 13 13 14 13 12 11 10 11 7 8 16 14 10 10 10 11 15 9 9 9 15 13 9 10 9 11 11 8 8 12 13 10 16 7 10 13 17 13 9 14 8 14 14 11 11 11 8 10 9 13 10 12 13 7 12 9 14 8 8 5 7 9 11 16 13 15 13 11 11 11 13 8 6 14 6 9 8 7 7 10 9 10 3 9 15 11 13 7 6 13 6 16 12 7 10 7 8 5 5 6 15 9 12 7 8 10 10 6 7 11 13 5 10 11 5 5 18 13 19 7 14 6 7 13 5 12 13 6 7 14 13 17 16 8 9 8 5 12 9 16 12 12 10 11 6 18 9 17 12 14 7 12 14 12 10 5 13 10 10 10 6 17 12 6 13 10 7 7 11 13 12 17 12 11 14 11 10 11 4 9 9 11 8 11 9 13 4 14 14 7 8 5 14 4 10 4 8 12 9 11 11 6 7 11 2 10 8 8 14 5 13 7 15 5 14 16 12 8 5 11 6 11 9 15 11 10 11 5 10 10 13 8 14 9 9 14 20 8 9 9 9 8 11 10 11 8 11 4 11 11 5 8 10 10 17 10 12 11 10 14 13 15 12 11 15 12 7 12 12 13 11 13 11 9 10 5 5 16 7 6 9 9 11 11 7 7 10 8 8 3 8 15 9 12 7 10 9 9 8 7 8 16 11 14 11 24 6 8 14 9 10 12 16 8 11 7 13 4 13 13 15 4 8 13 11 7 13 9 7 8 11 5 10 9 11 13 14 10 11 15 6 10 8 9 9 8 13 6 10 7 8 6 11 12 8 8 11 9 6 5 8 8 8 13 10 10 11 14 7 12 8 7 5 11 6 12 8 9 7 8 8 11 5 13 8 10 8 16 11 7 12 10 20 10 4 11 9 7 6 8 10 11 10 13 11 10 9 6 10 20 15 14 6 11 4 16 8 10 7 9 7 6 5 7 12 6 11 2 13 9 13 10 7 6 8 6 13 11 4 10 16 6 10 6 14 13 13 8 12 8 6 12 5 5 8 13 12 16 12 4 7 11 17 11 10 9 7 13 7 9 12 10 7 8 8 13 8 11 5 7 16 8 4 16 3 7 11 11 13 7 14 7 7 7 11 11 8 14 9 9 13 13 7 6 4 10 12 5 5 13 8 9 12 9 8 14 10 7 5 10 12 11 12 7 6 10 9 9 8 8 7 7 14 11 9 6 8 5 11 10 6 9 10 7 11 12 5 10 14 2 14 9 12 11 10 8 8 8 12 5 4 4 6 10 6 8 6 5 5 15 9 7 7 11 10 5 7 11 9 12 9 10 13 16 6 9 13 11 7 10 6 9 14 6 8 4 8 6 8 4 10 11 7 9 11 9 14 8 6 9 6 9 10 8 8 9 12 8 11 6 12 6 7 4 13 7 10 7 7 6 8 3 3 9 16 14 11 5 7 10 8 8 7 12 9 7 14 10 9 10 9 10 5 6 13 13 12 11 11 6 11 5 8 9 11 13 5 7 7 6 10 8 7 8 15 6 8 6 8 7 6 12 9 10 9 13 9 5 8 6 6 13 10 9 6 7 10 9 8 6 10 8 7 11 6 6 5 9 7 9 12 6 13 4 12 13 12 5 6 10 15 7 5 11 7 13 13 8 8 6 8 9 7 11 13 11 7 9 10 10 7 17 9 11 7 9 7 14 5 10 6 16 9 18 11 4 8 10 9 13 13 9 11 8 8 8 10 11 12 11 12 3 8 10 9 10 10 8 7 13 9 10 8 8 14 10 8 7 11 10 9 11 16 14 9 10 9 8 14 14 16 8 18 6 12 13 6 8 14 8 16 7 7 13 11 12 8 12 7 10 10 6 15 13 9 14 14 15 15 12 19 16 12 20 7 16 18 14 12 10 7 14 14 10 11 19 21 15 10 18 10 20 20 18 14 15 19 21 15 18 23 18 16 13 14 19 16 25 15 13 18 19 22 16 12 22 25 31 23 35 36 38 44 33 26 27 33 34 12 19 14 15 13 12 16 28 25 26 30 35 45 52 58 68 63 54 73 63 63 56 50 56 46 40 26 25 24 34 37 40 52 60 88 97 99 134 148 168 206 210 216 192 195 210 152 140 143 128 117 104 128 140 150 206 361 446 573 777 1045 1329 1542 1918 2455 2841 3237 3476 3804 4439 5072 5519 5697 5809 6276 6534 6896 6963 6504 6554 6667 6343 6150 5877 5438 5014 4590 4166 3737 3311 2792 2208 1842 1568 1229 965 657 414 345 213 207 202 198 242 335 419 545 619 612 752 871 889 871 955 991 937 1054 1171 1462 2285 4590 7087 9535 12132 15245 16854 18938 22163 25921 29505 33206 38883 48843 65893 94496 138951 1717 4386 7199 3225 1197 88868 13597 6160 2994 2114 1448 1137 881 728 630 481 355 313 286 209 161 124 63 70 57 55 48 49 56 56 67 80 62 68 83 72 67 68 66 67 66 49 37 41 37 17 19 18 13 16 12 21 16 19 21 28 28 35 40 32 40 38 21 27 21 26 31 16 16 21 18 13 12 11 10 16 11 16 23 13 24 23 22 31 18 33 13 21 23 17 16 18 9 9 6 6 12 8 13 5 12 14 18 11 14 15 18 12 17 16 13 11 11 15 17 9 15 12 12 9 8 8 13 14 18 9 13 9 9 5 16 14 12 9 6 12 12 7 14 12 11 4 11 12 5 9 14 9 9 9 6 13 10 10 15 9 12 15 6 12 12 12 8 12 6 9 9 9 5 8 8 15 9 8 11 12 10 13 11 13 13 6 17 14 5 10 12 12 7 8 7 12 6 5 9 12 10 11 5 14 9 7 10 6 11 10 9 18 11 7 11 12 10 8 9 4 12 9 11 5 3 10 7 11 13 9 7 7 9 14 7 9 11 9 12 8 11 10 8 5 7 9 10 6 5 4 8 7 9 4 3 10 6 8 7 6 6 9 6 4 11 9 9 6 7 13 4 7 7 8 12 12 11 9 4 5 8 10 6 15 6 12 6 9 5 5 8 3 5 13 12 11 10 10 7 6 8 6 10 5 7 12 7 4 10 9 10 5 13 8 12 6 8 7 8 12 11 13 8 8 2 12 6 8 3 10 2 6 8 6 5 4 8 10 9 9 6 8 7 5 7 6 5 11 9 6 10 15 9 1 9 7 10 5 8</counts>
			</dataPoints>
		</scan>
	</xrdMeasurement>
</xrdMeasurements>