File: data/XRD_RSM/YG064/YG064 phi 90  RSM slow 3 degree_1.xrdml
<?xml version="1.0" encoding="utf-8"?>
<xrdMeasurements xmlns="http://www.xrdml.com/XRDMeasurement/2.2" xmlns:xsi="http://www.w3.org/2001/XMLSchema-instance" xsi:schemaLocation="http://www.xrdml.com/XRDMeasurement/2.2 http://www.xrdml.com/XRDMeasurement/2.2/XRDMeasurement.xsd" status="Completed">
	<comment>
		<entry>Configuration=3-axes Cradle_Reflection, Owner=lw627, Creation date=9/2/2021 3:55:24 PM</entry>
		<entry>Goniometer=Theta/Theta; Minimum step size 2Theta:0.0001; Minimum step size Omega:0.0001</entry>
		<entry>Sample stage=Chi-Phi-z stage 240 mm (reflection); Minimum step size Phi:0.01; Minimum step size Chi:0.01; Minimum step size Z:0.001</entry>
		<entry>Diffractometer system=EMPYREAN</entry>
		<entry>Measurement program=C:\PANalytical\Data Collector\Programs\Liyan Wu\Film programs\RSM slow 3 degree.xrdmp, Identifier={0351664C-55A7-43E7-B72A-7307F4B26703}</entry>
	</comment>
	<sample type="To be analyzed">
		<id/>
		<name/>
		<preparedBy/>
	</sample>
	<xrdMeasurement status="Completed" measurementType="Area measurement" measurementStepAxis="Omega-2Theta" sampleMode="Reflection">
		<comment>
			<entry>PHD Lower Level = 4.02 (keV), PHD Upper Level = 11.27 (keV)</entry>
		</comment>
		<usedWavelength intended="K-Alpha 1">
			<kAlpha1 unit="Angstrom">1.5405980</kAlpha1>
			<kAlpha2 unit="Angstrom">1.5444260</kAlpha2>
			<kBeta unit="Angstrom">1.3922500</kBeta>
			<ratioKAlpha2KAlpha1>0</ratioKAlpha2KAlpha1>
		</usedWavelength>
		<incidentBeamPath>
			<radius unit="mm">240.00</radius>
			<xRayTube id="1010048" name="Empyrean Cu LFF HR (9430 033 7310x) DK432574">
				<tension unit="kV">45.0</tension>
				<current unit="mA">40.0</current>
				<anodeMaterial>Cu</anodeMaterial>
				<focus type="Line">
					<length unit="mm">12.0</length>
					<width unit="mm">0.4</width>
					<takeOffAngle unit="deg">4.4</takeOffAngle>
				</focus>
			</xRayTube>
			<xRayMirror xsi:type="xRayMirrorType" id="27080001" name="Inc. Beam Cu W/Si (hybrid MPD)" hybrid="true">
				<crystal type="Graded" shape="Parabolic">W/Si</crystal>
				<acceptanceAngle unit="deg">0.800</acceptanceAngle>
				<length unit="mm">55.3</length>
			</xRayMirror>
			<monochromator xsi:type="monochromatorType" id="23090002" name="Hybrid monochr. 2xGe220 Cu asym." hybrid="true">
				<crystal type="Asymmetric" shape="Flat">Ge</crystal>
				<numberOfReflections>2</numberOfReflections>
				<hkl>
					<h>2</h>
					<k>2</k>
					<l>0</l>
				</hkl>
			</monochromator>
			<divergenceSlit xsi:type="fixedDivergenceSlitType" id="22010005" name="Fixed slit 1/4°">
				<distanceToSample unit="mm">179.30</distanceToSample>
				<height unit="mm">0.38</height>
			</divergenceSlit>
		</incidentBeamPath>
		<diffractedBeamPath>
			<radius unit="mm">240.00</radius>
			<antiScatterSlit xsi:type="fixedAntiScatterSlitType" id="22060009" name="Programmable anti-scatter slit">
				<angle unit="deg">4</angle>
			</antiScatterSlit>
			<detector xsi:type="areaDetectorType" id="7010020" name="PIXcel3D-Medipix3 1x1 detector">
				<phd unit="%">
					<lowerLevel>25</lowerLevel>
					<upperLevel>70</upperLevel>
				</phd>
				<mode>Scanning snapshot equatorial</mode>
				<activeChannelsEquatorial>255</activeChannelsEquatorial>
				<activeChannelsAxial>255</activeChannelsAxial>
				<pitchEquatorial unit="mm">0.05500</pitchEquatorial>
				<pitchAxial unit="mm">0.05500</pitchAxial>
				<readOutPeriod unit="seconds">0.980</readOutPeriod>
			</detector>
		</diffractedBeamPath>
		<scan status="Completed" appendNumber="0" scanAxis="2Theta" mode="Continuous">
			<header>
				<startTimeStamp>2024-09-11T13:00:55-04:00</startTimeStamp>
				<endTimeStamp>2024-09-11T13:30:54-04:00</endTimeStamp>
				<author>
					<name>lw627</name>
				</author>
				<source>
					<applicationSoftware version="7.1">Data Collector</applicationSoftware>
					<instrumentControlSoftware version="8.2  20201204">EMPYREAN</instrumentControlSoftware>
					<instrumentID>0000000011260721</instrumentID>
				</source>
			</header>
			<dataPoints>
				<positions axis="2Theta" unit="deg">
					<startPosition>71.5454063943918</startPosition>
					<endPosition>74.8926761656082</endPosition>
				</positions>
				<positions axis="Omega" unit="deg">
					<commonPosition>17.96652064</commonPosition>
				</positions>
				<positions axis="Phi" unit="deg">
					<commonPosition>91.37</commonPosition>
				</positions>
				<positions axis="Chi" unit="deg">
					<commonPosition>0</commonPosition>
				</positions>
				<positions axis="Z" unit="mm">
					<commonPosition>8.335</commonPosition>
				</positions>
				<commonCountingTime unit="seconds">0.974</commonCountingTime>
				<counts unit="counts">0 0 1 0 0 0 0 0 0 0 1 0 0 1 0 0 0 0 0 0 0 0 1 0 0 0 0 2 0 0 1 0 0 0 0 0 0 1 0 0 1 1 0 0 1 0 0 0 2 1 0 0 0 0 0 1 0 0 0 0 0 0 0 1 0 0 1 0 1 1 0 0 1 0 2 0 0 0 0 0 0 1 1 0 0 0 1 0 1 0 0 0 0 1 0 0 0 1 1 0 0 1 0 0 0 1 0 0 0 0 0 0 1 0 1 0 0 1 0 0 0 0 1 1 0 0 1 0 0 0 0 1 1 0 1 2 0 0 0 1 0 0 0 0 1 0 0 0 1 0 0 1 0 0 0 0 1 0 0 1 0 0 0 0 0 1 0 0 0 1 1 0 2 0 0 0 0 0 1 0 2 0 1 1 0 0 0 0 1 0 0 2 1 0 0 0 0 0 1 0 0 0 0 0 0 0 0 0 0 0 1 1 2 1 0 0 0 0 0 0 0 0 0 0 1 0 1 0 0 0 1 1 0 0 0 0 0 1 1 0 0 1 0 0 0 0 0 1 1 0 0 0 0 1 0</counts>
			</dataPoints>
		</scan>
		<scan status="Completed" appendNumber="0" scanAxis="2Theta" mode="Continuous">
			<header>
				<startTimeStamp>2024-09-11T13:00:55-04:00</startTimeStamp>
				<endTimeStamp>2024-09-11T13:30:54-04:00</endTimeStamp>
				<author>
					<name>lw627</name>
				</author>
				<source>
					<applicationSoftware version="7.1">Data Collector</applicationSoftware>
					<instrumentControlSoftware version="8.2  20201204">EMPYREAN</instrumentControlSoftware>
					<instrumentID>0000000011260721</instrumentID>
				</source>
			</header>
			<dataPoints>
				<positions axis="2Theta" unit="deg">
					<startPosition>71.5486889650599</startPosition>
					<endPosition>74.8959587362764</endPosition>
				</positions>
				<positions axis="Omega" unit="deg">
					<commonPosition>17.9681619253341</commonPosition>
				</positions>
				<positions axis="Phi" unit="deg">
					<commonPosition>91.37</commonPosition>
				</positions>
				<positions axis="Chi" unit="deg">
					<commonPosition>0</commonPosition>
				</positions>
				<positions axis="Z" unit="mm">
					<commonPosition>8.335</commonPosition>
				</positions>
				<commonCountingTime unit="seconds">0.974</commonCountingTime>
				<counts unit="counts">0 0 0 0 1 0 0 0 0 0 0 1 0 0 0 0 0 1 0 1 0 0 0 0 0 0 0 0 0 0 0 1 1 0 0 0 0 0 0 0 0 0 0 0 0 0 0 0 1 2 1 0 1 0 1 1 0 0 0 0 0 0 0 0 0 1 1 0 0 0 1 0 1 0 1 1 0 0 0 0 0 0 1 0 0 0 1 1 0 0 0 0 0 0 0 0 0 2 0 0 1 0 0 0 0 1 0 0 0 0 1 0 0 0 0 0 0 0 0 0 0 0 0 0 2 0 1 0 1 2 0 0 0 0 0 0 0 1 0 1 0 0 0 0 0 0 0 1 1 1 1 0 0 0 0 2 0 0 1 0 0 0 0 0 0 2 1 0 0 0 0 0 0 1 1 0 0 0 0 0 1 0 0 0 0 0 2 0 0 2 2 0 0 2 0 1 0 1 0 0 0 1 0 0 0 1 0 0 0 0 1 0 1 0 0 0 0 0 0 0 0 0 0 0 0 1 0 0 1 0 1 0 1 0 0 0 0 2 1 0 0 0 0 0 0 1 1 0 1 0 0 2 0 0 0</counts>
			</dataPoints>
		</scan>
		<scan status="Completed" appendNumber="0" scanAxis="2Theta" mode="Continuous">
			<header>
				<startTimeStamp>2024-09-11T13:00:55-04:00</startTimeStamp>
				<endTimeStamp>2024-09-11T13:30:54-04:00</endTimeStamp>
				<author>
					<name>lw627</name>
				</author>
				<source>
					<applicationSoftware version="7.1">Data Collector</applicationSoftware>
					<instrumentControlSoftware version="8.2  20201204">EMPYREAN</instrumentControlSoftware>
					<instrumentID>0000000011260721</instrumentID>
				</source>
			</header>
			<dataPoints>
				<positions axis="2Theta" unit="deg">
					<startPosition>71.551971535728</startPosition>
					<endPosition>74.8992413069445</endPosition>
				</positions>
				<positions axis="Omega" unit="deg">
					<commonPosition>17.9698032106681</commonPosition>
				</positions>
				<positions axis="Phi" unit="deg">
					<commonPosition>91.37</commonPosition>
				</positions>
				<positions axis="Chi" unit="deg">
					<commonPosition>0</commonPosition>
				</positions>
				<positions axis="Z" unit="mm">
					<commonPosition>8.335</commonPosition>
				</positions>
				<commonCountingTime unit="seconds">0.974</commonCountingTime>
				<counts unit="counts">0 0 0 0 0 0 0 1 0 1 0 0 1 0 1 0 0 0 1 0 0 0 1 0 1 0 1 1 0 0 3 0 0 0 0 0 0 0 0 0 0 1 0 0 0 0 0 1 0 0 0 0 1 1 0 0 0 0 1 0 1 0 0 1 1 0 0 1 1 0 0 0 2 2 1 1 1 0 0 0 0 0 0 0 0 1 0 0 1 0 1 2 0 0 1 0 1 0 0 0 0 0 1 0 0 1 0 0 0 1 0 0 0 0 1 0 0 0 1 0 1 1 0 0 0 1 0 0 0 0 2 0 0 1 0 1 0 1 0 0 0 0 1 0 0 0 1 0 0 0 0 1 1 1 1 0 0 1 0 1 1 1 0 1 0 0 1 0 2 0 0 0 0 0 0 0 0 0 0 0 1 0 1 1 1 1 0 2 1 0 1 1 1 2 1 0 0 0 0 0 0 0 0 0 0 0 0 1 0 0 1 0 0 0 0 0 0 0 0 1 1 0 0 0 0 0 1 0 0 0 0 0 0 0 0 0 0 0 0 0 0 0 0 1 0 0 0 1 0 1 0 0 0 0 0</counts>
			</dataPoints>
		</scan>
		<scan status="Completed" appendNumber="0" scanAxis="2Theta" mode="Continuous">
			<header>
				<startTimeStamp>2024-09-11T13:00:55-04:00</startTimeStamp>
				<endTimeStamp>2024-09-11T13:30:54-04:00</endTimeStamp>
				<author>
					<name>lw627</name>
				</author>
				<source>
					<applicationSoftware version="7.1">Data Collector</applicationSoftware>
					<instrumentControlSoftware version="8.2  20201204">EMPYREAN</instrumentControlSoftware>
					<instrumentID>0000000011260721</instrumentID>
				</source>
			</header>
			<dataPoints>
				<positions axis="2Theta" unit="deg">
					<startPosition>71.5552541063961</startPosition>
					<endPosition>74.9025238776126</endPosition>
				</positions>
				<positions axis="Omega" unit="deg">
					<commonPosition>17.9714444960022</commonPosition>
				</positions>
				<positions axis="Phi" unit="deg">
					<commonPosition>91.37</commonPosition>
				</positions>
				<positions axis="Chi" unit="deg">
					<commonPosition>0</commonPosition>
				</positions>
				<positions axis="Z" unit="mm">
					<commonPosition>8.335</commonPosition>
				</positions>
				<commonCountingTime unit="seconds">0.974</commonCountingTime>
				<counts unit="counts">0 0 0 0 0 0 1 0 0 0 0 1 0 0 0 0 0 0 0 0 0 2 0 0 0 0 1 1 0 0 0 1 0 0 0 0 0 1 0 0 0 0 0 0 1 0 0 0 0 0 0 0 0 0 1 0 0 0 0 0 0 0 1 0 1 1 0 0 3 0 0 2 0 1 0 0 0 0 0 0 0 0 0 0 1 0 0 0 1 1 2 0 1 0 0 0 1 1 0 1 0 2 0 1 1 0 0 2 1 0 0 0 0 0 0 1 0 0 0 0 2 0 0 0 1 1 1 0 0 0 0 1 0 1 0 1 0 1 0 0 0 0 1 0 0 0 0 2 0 0 0 0 0 0 0 0 1 0 0 1 2 1 0 0 0 0 0 0 0 0 0 1 0 0 1 0 0 0 1 1 0 1 0 0 2 0 1 0 0 0 0 0 0 0 1 0 0 1 0 1 0 0 0 0 0 1 0 0 0 0 1 0 1 0 0 0 2 0 0 1 1 0 1 0 0 1 0 0 1 0 0 0 1 0 1 0 0 1 0 0 1 0 1 0 0 0 0 1 0 0 0 0 0 0 0</counts>
			</dataPoints>
		</scan>
		<scan status="Completed" appendNumber="0" scanAxis="2Theta" mode="Continuous">
			<header>
				<startTimeStamp>2024-09-11T13:00:55-04:00</startTimeStamp>
				<endTimeStamp>2024-09-11T13:30:54-04:00</endTimeStamp>
				<author>
					<name>lw627</name>
				</author>
				<source>
					<applicationSoftware version="7.1">Data Collector</applicationSoftware>
					<instrumentControlSoftware version="8.2  20201204">EMPYREAN</instrumentControlSoftware>
					<instrumentID>0000000011260721</instrumentID>
				</source>
			</header>
			<dataPoints>
				<positions axis="2Theta" unit="deg">
					<startPosition>71.5585366770643</startPosition>
					<endPosition>74.9058064482807</endPosition>
				</positions>
				<positions axis="Omega" unit="deg">
					<commonPosition>17.9730857813363</commonPosition>
				</positions>
				<positions axis="Phi" unit="deg">
					<commonPosition>91.37</commonPosition>
				</positions>
				<positions axis="Chi" unit="deg">
					<commonPosition>0</commonPosition>
				</positions>
				<positions axis="Z" unit="mm">
					<commonPosition>8.335</commonPosition>
				</positions>
				<commonCountingTime unit="seconds">0.974</commonCountingTime>
				<counts unit="counts">0 0 0 0 0 0 0 2 0 1 1 0 0 0 0 0 0 1 0 0 0 0 0 0 0 0 0 1 0 1 0 0 0 0 0 1 0 0 0 0 0 0 0 1 0 0 0 0 0 0 1 1 1 0 0 0 0 1 0 0 0 0 0 0 0 0 0 0 0 0 0 0 0 0 2 0 1 2 0 2 0 0 0 0 1 0 1 0 0 0 1 1 0 0 0 1 0 0 0 0 0 0 0 0 0 0 0 0 1 0 2 0 0 0 0 2 0 0 0 0 0 0 0 0 0 0 0 0 1 1 0 0 1 1 0 0 0 0 0 0 0 1 0 0 0 0 0 1 1 0 0 0 0 0 0 0 0 0 1 0 1 1 1 0 1 0 1 0 0 0 0 0 0 1 0 0 0 0 0 0 0 0 1 0 0 0 3 0 0 0 0 0 1 1 0 0 0 0 0 0 0 0 0 0 0 0 0 0 0 0 0 0 1 2 0 1 0 0 0 0 0 0 0 0 0 0 1 0 0 1 0 1 0 0 1 1 0 0 1 0 0 0 0 0 0 0 0 0 2 3 1 0 0 0 1</counts>
			</dataPoints>
		</scan>
		<scan status="Completed" appendNumber="0" scanAxis="2Theta" mode="Continuous">
			<header>
				<startTimeStamp>2024-09-11T13:00:55-04:00</startTimeStamp>
				<endTimeStamp>2024-09-11T13:30:54-04:00</endTimeStamp>
				<author>
					<name>lw627</name>
				</author>
				<source>
					<applicationSoftware version="7.1">Data Collector</applicationSoftware>
					<instrumentControlSoftware version="8.2  20201204">EMPYREAN</instrumentControlSoftware>
					<instrumentID>0000000011260721</instrumentID>
				</source>
			</header>
			<dataPoints>
				<positions axis="2Theta" unit="deg">
					<startPosition>71.5618192477324</startPosition>
					<endPosition>74.9090890189489</endPosition>
				</positions>
				<positions axis="Omega" unit="deg">
					<commonPosition>17.9747270666703</commonPosition>
				</positions>
				<positions axis="Phi" unit="deg">
					<commonPosition>91.37</commonPosition>
				</positions>
				<positions axis="Chi" unit="deg">
					<commonPosition>0</commonPosition>
				</positions>
				<positions axis="Z" unit="mm">
					<commonPosition>8.335</commonPosition>
				</positions>
				<commonCountingTime unit="seconds">0.974</commonCountingTime>
				<counts unit="counts">0 1 0 0 0 0 1 2 0 1 2 0 1 1 0 0 0 0 1 1 1 0 1 1 0 1 0 0 0 0 0 0 0 0 0 0 1 1 0 0 0 0 0 0 1 0 0 0 0 1 0 0 0 0 0 0 0 0 1 1 0 0 0 1 1 1 1 0 0 0 1 0 0 0 1 0 0 0 1 0 0 0 0 0 1 0 0 1 1 2 0 0 1 0 0 0 0 0 0 0 0 0 0 0 0 0 0 0 0 0 0 0 0 0 1 0 1 0 0 0 0 0 2 0 1 0 1 0 0 1 1 0 0 1 0 0 0 1 0 0 0 0 0 0 0 0 0 0 0 0 0 0 0 0 0 1 0 1 0 1 0 1 0 0 0 1 1 0 1 0 0 0 0 0 0 0 1 0 1 0 1 1 0 1 1 0 0 0 1 0 0 0 0 0 1 0 0 0 0 1 0 0 0 0 0 0 0 0 0 0 2 0 0 0 1 0 0 0 0 0 0 0 1 1 0 0 0 0 0 0 0 0 0 1 0 1 0 1 0 0 0 0 0 1 1 0 0 0 0 0 1 1 1 1 0</counts>
			</dataPoints>
		</scan>
		<scan status="Completed" appendNumber="0" scanAxis="2Theta" mode="Continuous">
			<header>
				<startTimeStamp>2024-09-11T13:00:55-04:00</startTimeStamp>
				<endTimeStamp>2024-09-11T13:30:54-04:00</endTimeStamp>
				<author>
					<name>lw627</name>
				</author>
				<source>
					<applicationSoftware version="7.1">Data Collector</applicationSoftware>
					<instrumentControlSoftware version="8.2  20201204">EMPYREAN</instrumentControlSoftware>
					<instrumentID>0000000011260721</instrumentID>
				</source>
			</header>
			<dataPoints>
				<positions axis="2Theta" unit="deg">
					<startPosition>71.5651018184005</startPosition>
					<endPosition>74.912371589617</endPosition>
				</positions>
				<positions axis="Omega" unit="deg">
					<commonPosition>17.9763683520044</commonPosition>
				</positions>
				<positions axis="Phi" unit="deg">
					<commonPosition>91.37</commonPosition>
				</positions>
				<positions axis="Chi" unit="deg">
					<commonPosition>0</commonPosition>
				</positions>
				<positions axis="Z" unit="mm">
					<commonPosition>8.335</commonPosition>
				</positions>
				<commonCountingTime unit="seconds">0.974</commonCountingTime>
				<counts unit="counts">0 0 0 0 1 1 0 0 1 0 0 0 0 0 1 0 1 1 0 0 0 0 1 0 0 0 1 0 0 0 0 1 0 0 0 0 0 0 0 0 0 0 1 0 0 1 0 0 1 1 0 0 0 0 0 0 2 0 0 0 0 2 0 1 0 0 0 0 0 0 0 0 0 0 0 0 0 0 0 0 2 1 0 1 0 1 0 0 0 0 0 0 1 0 0 1 0 1 0 0 0 0 0 0 0 0 1 1 1 0 0 0 0 0 0 0 0 0 1 0 0 1 0 1 0 0 1 0 1 1 0 0 0 0 0 0 0 0 0 1 0 0 0 0 0 0 0 0 0 0 1 3 1 0 0 0 0 0 0 0 0 0 1 0 0 1 0 1 0 0 0 0 0 0 0 0 0 0 0 0 0 0 0 0 0 2 0 1 1 0 0 0 0 0 0 0 0 0 0 0 0 2 0 1 0 1 0 0 1 1 0 0 0 0 0 0 0 0 0 0 0 0 0 0 0 1 1 0 0 0 0 0 1 0 1 0 0 1 0 0 0 0 1 0 0 0 0 0 0 0 0 0 0 0 0</counts>
			</dataPoints>
		</scan>
		<scan status="Completed" appendNumber="0" scanAxis="2Theta" mode="Continuous">
			<header>
				<startTimeStamp>2024-09-11T13:00:55-04:00</startTimeStamp>
				<endTimeStamp>2024-09-11T13:30:54-04:00</endTimeStamp>
				<author>
					<name>lw627</name>
				</author>
				<source>
					<applicationSoftware version="7.1">Data Collector</applicationSoftware>
					<instrumentControlSoftware version="8.2  20201204">EMPYREAN</instrumentControlSoftware>
					<instrumentID>0000000011260721</instrumentID>
				</source>
			</header>
			<dataPoints>
				<positions axis="2Theta" unit="deg">
					<startPosition>71.5683843890687</startPosition>
					<endPosition>74.9156541602851</endPosition>
				</positions>
				<positions axis="Omega" unit="deg">
					<commonPosition>17.9780096373384</commonPosition>
				</positions>
				<positions axis="Phi" unit="deg">
					<commonPosition>91.37</commonPosition>
				</positions>
				<positions axis="Chi" unit="deg">
					<commonPosition>0</commonPosition>
				</positions>
				<positions axis="Z" unit="mm">
					<commonPosition>8.335</commonPosition>
				</positions>
				<commonCountingTime unit="seconds">0.974</commonCountingTime>
				<counts unit="counts">0 2 0 0 0 0 0 0 1 0 0 0 0 0 0 2 0 0 0 0 0 0 0 0 0 0 0 0 0 0 1 0 0 0 0 0 0 0 0 1 0 0 0 0 0 1 1 1 0 0 0 1 0 0 0 0 0 0 0 2 0 0 0 1 0 0 1 1 1 0 0 1 0 0 0 0 0 0 0 1 0 0 1 0 0 1 0 1 0 0 0 0 0 0 1 0 1 0 0 0 0 1 0 0 0 0 0 0 0 0 0 0 0 1 0 0 0 0 0 2 2 1 0 0 0 0 0 0 0 0 0 0 0 0 0 0 0 2 0 0 2 0 1 0 1 0 0 0 0 0 0 0 1 0 0 0 2 2 1 1 0 0 1 0 0 0 0 0 0 0 0 0 0 1 0 0 0 0 1 0 0 1 3 0 0 0 0 0 0 0 1 0 1 0 0 2 1 0 1 0 1 0 0 3 0 0 0 0 0 0 0 0 0 0 0 0 0 0 0 0 0 0 0 0 0 0 0 0 0 0 0 0 0 0 0 0 1 0 0 0 0 1 0 0 0 0 0 0 0 1 0 2 0 0 1</counts>
			</dataPoints>
		</scan>
		<scan status="Completed" appendNumber="0" scanAxis="2Theta" mode="Continuous">
			<header>
				<startTimeStamp>2024-09-11T13:00:55-04:00</startTimeStamp>
				<endTimeStamp>2024-09-11T13:30:54-04:00</endTimeStamp>
				<author>
					<name>lw627</name>
				</author>
				<source>
					<applicationSoftware version="7.1">Data Collector</applicationSoftware>
					<instrumentControlSoftware version="8.2  20201204">EMPYREAN</instrumentControlSoftware>
					<instrumentID>0000000011260721</instrumentID>
				</source>
			</header>
			<dataPoints>
				<positions axis="2Theta" unit="deg">
					<startPosition>71.5716669597368</startPosition>
					<endPosition>74.9189367309532</endPosition>
				</positions>
				<positions axis="Omega" unit="deg">
					<commonPosition>17.9796509226725</commonPosition>
				</positions>
				<positions axis="Phi" unit="deg">
					<commonPosition>91.37</commonPosition>
				</positions>
				<positions axis="Chi" unit="deg">
					<commonPosition>0</commonPosition>
				</positions>
				<positions axis="Z" unit="mm">
					<commonPosition>8.335</commonPosition>
				</positions>
				<commonCountingTime unit="seconds">0.974</commonCountingTime>
				<counts unit="counts">0 1 0 0 0 0 0 0 0 0 0 0 1 0 0 0 1 0 0 0 1 0 2 2 0 1 0 0 0 0 0 0 0 1 0 0 0 0 2 0 0 0 2 0 1 0 0 0 3 0 0 0 0 0 0 2 0 0 0 1 0 0 0 0 0 0 0 1 0 0 0 0 1 2 0 0 0 0 1 0 0 0 1 0 0 0 2 0 0 0 0 0 0 1 0 0 0 1 0 0 0 1 0 1 0 0 1 0 0 0 0 0 0 1 0 1 0 0 0 0 0 0 0 1 3 3 0 0 0 0 0 2 0 0 0 0 1 0 0 0 0 0 0 0 1 1 0 0 0 0 0 0 0 0 2 1 1 1 0 0 0 0 1 1 0 0 0 0 0 1 0 0 1 1 0 0 1 0 0 0 0 0 0 1 0 0 0 0 0 0 2 0 2 1 0 0 1 0 0 0 1 2 0 1 0 0 0 0 0 0 0 0 0 0 1 0 1 1 0 1 0 0 0 1 0 1 1 0 0 0 0 0 0 0 1 1 0 1 0 0 0 0 0 0 0 0 0 0 0 0 0 1 1 0 0</counts>
			</dataPoints>
		</scan>
		<scan status="Completed" appendNumber="0" scanAxis="2Theta" mode="Continuous">
			<header>
				<startTimeStamp>2024-09-11T13:00:55-04:00</startTimeStamp>
				<endTimeStamp>2024-09-11T13:30:54-04:00</endTimeStamp>
				<author>
					<name>lw627</name>
				</author>
				<source>
					<applicationSoftware version="7.1">Data Collector</applicationSoftware>
					<instrumentControlSoftware version="8.2  20201204">EMPYREAN</instrumentControlSoftware>
					<instrumentID>0000000011260721</instrumentID>
				</source>
			</header>
			<dataPoints>
				<positions axis="2Theta" unit="deg">
					<startPosition>71.5749495304049</startPosition>
					<endPosition>74.9222193016214</endPosition>
				</positions>
				<positions axis="Omega" unit="deg">
					<commonPosition>17.9812922080066</commonPosition>
				</positions>
				<positions axis="Phi" unit="deg">
					<commonPosition>91.37</commonPosition>
				</positions>
				<positions axis="Chi" unit="deg">
					<commonPosition>0</commonPosition>
				</positions>
				<positions axis="Z" unit="mm">
					<commonPosition>8.335</commonPosition>
				</positions>
				<commonCountingTime unit="seconds">0.974</commonCountingTime>
				<counts unit="counts">0 0 0 0 0 0 1 0 0 0 0 0 0 0 0 1 0 0 0 0 0 0 0 0 0 0 1 0 1 0 0 0 1 0 0 1 0 0 1 0 0 0 0 1 0 0 0 0 0 0 0 0 0 0 0 2 0 0 0 0 0 1 0 0 0 0 0 0 0 1 0 0 0 2 2 0 1 0 0 0 0 0 0 3 1 0 0 0 0 0 0 1 0 0 0 1 0 1 1 0 1 0 1 0 1 1 0 0 0 0 1 0 0 0 0 0 0 0 0 3 0 1 0 0 0 2 0 0 0 0 1 0 2 1 0 0 0 0 0 0 0 0 0 0 0 0 0 2 0 0 0 0 1 0 0 1 0 0 0 2 0 0 2 1 0 0 0 0 0 0 0 0 0 0 0 0 0 1 0 0 2 0 0 0 1 0 0 0 0 1 1 0 0 1 0 0 0 0 0 0 1 0 1 1 0 0 0 0 1 0 1 0 0 0 0 1 0 0 1 0 0 0 0 0 1 1 0 0 0 1 0 0 2 2 0 0 1 1 0 0 0 1 1 0 0 0 0 0 1 1 1 1 0 0 0</counts>
			</dataPoints>
		</scan>
		<scan status="Completed" appendNumber="0" scanAxis="2Theta" mode="Continuous">
			<header>
				<startTimeStamp>2024-09-11T13:00:55-04:00</startTimeStamp>
				<endTimeStamp>2024-09-11T13:30:54-04:00</endTimeStamp>
				<author>
					<name>lw627</name>
				</author>
				<source>
					<applicationSoftware version="7.1">Data Collector</applicationSoftware>
					<instrumentControlSoftware version="8.2  20201204">EMPYREAN</instrumentControlSoftware>
					<instrumentID>0000000011260721</instrumentID>
				</source>
			</header>
			<dataPoints>
				<positions axis="2Theta" unit="deg">
					<startPosition>71.578232101073</startPosition>
					<endPosition>74.9255018722895</endPosition>
				</positions>
				<positions axis="Omega" unit="deg">
					<commonPosition>17.9829334933406</commonPosition>
				</positions>
				<positions axis="Phi" unit="deg">
					<commonPosition>91.37</commonPosition>
				</positions>
				<positions axis="Chi" unit="deg">
					<commonPosition>0</commonPosition>
				</positions>
				<positions axis="Z" unit="mm">
					<commonPosition>8.335</commonPosition>
				</positions>
				<commonCountingTime unit="seconds">0.974</commonCountingTime>
				<counts unit="counts">0 0 0 0 1 0 0 0 0 0 1 1 0 0 0 0 0 0 1 1 0 0 0 0 1 1 0 1 0 1 0 1 0 0 0 0 0 0 0 0 0 1 0 0 0 1 0 0 0 3 1 0 1 0 0 0 0 0 0 2 0 0 0 0 0 0 0 0 1 0 0 0 0 0 0 0 0 0 0 0 1 0 0 0 1 0 1 0 1 0 0 0 1 1 0 0 0 0 0 1 0 0 0 1 0 0 0 1 1 1 0 0 0 0 0 0 0 1 0 0 0 2 0 1 1 0 0 3 0 0 0 0 1 0 0 0 1 0 0 0 0 0 0 0 0 2 1 0 0 0 1 0 0 0 2 0 0 1 0 1 0 0 0 0 0 0 0 0 0 1 2 0 0 0 0 0 0 2 0 0 0 0 0 0 0 0 1 0 1 0 0 2 1 0 1 0 0 0 0 1 0 1 0 1 1 0 1 2 0 2 0 0 0 0 0 0 0 1 0 0 1 0 0 0 1 1 1 1 0 1 1 0 0 0 0 0 0 0 0 1 0 0 0 0 0 0 0 0 1 1 0 0 1 0 1</counts>
			</dataPoints>
		</scan>
		<scan status="Completed" appendNumber="0" scanAxis="2Theta" mode="Continuous">
			<header>
				<startTimeStamp>2024-09-11T13:00:55-04:00</startTimeStamp>
				<endTimeStamp>2024-09-11T13:30:54-04:00</endTimeStamp>
				<author>
					<name>lw627</name>
				</author>
				<source>
					<applicationSoftware version="7.1">Data Collector</applicationSoftware>
					<instrumentControlSoftware version="8.2  20201204">EMPYREAN</instrumentControlSoftware>
					<instrumentID>0000000011260721</instrumentID>
				</source>
			</header>
			<dataPoints>
				<positions axis="2Theta" unit="deg">
					<startPosition>71.5815146717412</startPosition>
					<endPosition>74.9287844429576</endPosition>
				</positions>
				<positions axis="Omega" unit="deg">
					<commonPosition>17.9845747786747</commonPosition>
				</positions>
				<positions axis="Phi" unit="deg">
					<commonPosition>91.37</commonPosition>
				</positions>
				<positions axis="Chi" unit="deg">
					<commonPosition>0</commonPosition>
				</positions>
				<positions axis="Z" unit="mm">
					<commonPosition>8.335</commonPosition>
				</positions>
				<commonCountingTime unit="seconds">0.974</commonCountingTime>
				<counts unit="counts">1 0 1 0 0 0 0 0 0 0 1 0 1 0 0 0 0 1 0 1 0 0 0 0 0 2 0 0 0 1 0 1 0 0 0 0 1 2 1 2 0 0 0 0 0 0 0 0 0 0 1 0 0 0 1 0 1 0 1 1 0 0 0 0 0 1 1 0 0 0 0 1 1 0 1 0 0 0 0 1 0 0 1 0 0 0 1 0 0 0 0 1 1 0 0 1 0 0 1 1 0 1 0 0 0 1 0 0 0 0 1 0 1 0 0 0 0 0 0 0 1 0 1 0 0 0 0 0 0 0 1 0 0 1 0 1 2 0 0 1 0 1 0 0 1 0 0 1 0 0 0 0 0 1 0 0 0 1 2 0 0 0 0 0 0 0 1 1 2 1 1 0 0 0 0 0 0 0 0 1 0 0 0 0 0 1 0 0 1 1 0 2 0 0 0 0 1 0 1 1 1 0 0 0 0 0 0 2 0 0 0 0 0 1 0 0 0 0 0 0 0 0 0 0 1 0 0 0 1 0 0 0 0 1 1 0 0 1 0 0 0 1 0 1 0 0 1 1 2 0 1 0 0 0 0</counts>
			</dataPoints>
		</scan>
		<scan status="Completed" appendNumber="0" scanAxis="2Theta" mode="Continuous">
			<header>
				<startTimeStamp>2024-09-11T13:00:55-04:00</startTimeStamp>
				<endTimeStamp>2024-09-11T13:30:54-04:00</endTimeStamp>
				<author>
					<name>lw627</name>
				</author>
				<source>
					<applicationSoftware version="7.1">Data Collector</applicationSoftware>
					<instrumentControlSoftware version="8.2  20201204">EMPYREAN</instrumentControlSoftware>
					<instrumentID>0000000011260721</instrumentID>
				</source>
			</header>
			<dataPoints>
				<positions axis="2Theta" unit="deg">
					<startPosition>71.5847972424093</startPosition>
					<endPosition>74.9320670136258</endPosition>
				</positions>
				<positions axis="Omega" unit="deg">
					<commonPosition>17.9862160640088</commonPosition>
				</positions>
				<positions axis="Phi" unit="deg">
					<commonPosition>91.37</commonPosition>
				</positions>
				<positions axis="Chi" unit="deg">
					<commonPosition>0</commonPosition>
				</positions>
				<positions axis="Z" unit="mm">
					<commonPosition>8.335</commonPosition>
				</positions>
				<commonCountingTime unit="seconds">0.974</commonCountingTime>
				<counts unit="counts">1 0 0 0 0 0 2 0 0 0 0 0 0 2 0 0 0 0 0 0 0 1 0 1 0 1 0 1 0 0 1 0 0 0 1 0 0 0 0 1 1 0 0 1 1 0 0 0 1 0 0 0 0 0 1 1 0 1 1 0 0 0 0 0 1 0 0 1 0 1 0 0 2 0 0 0 0 0 0 0 1 1 0 0 0 0 0 1 1 1 0 0 1 1 1 0 0 1 2 1 0 1 0 0 0 0 0 0 1 1 0 1 0 1 0 1 0 0 0 0 0 0 0 0 1 0 0 0 0 0 0 0 0 0 0 1 1 0 2 1 0 0 0 0 0 1 0 0 0 0 0 0 0 0 1 0 0 0 1 0 0 0 0 2 1 2 0 0 0 0 0 0 0 1 1 0 1 0 1 0 0 0 2 0 0 2 0 0 0 0 0 0 0 1 0 0 0 0 0 0 0 1 1 0 0 0 0 1 0 0 0 0 0 0 0 0 0 0 0 2 0 0 0 0 0 1 0 0 0 0 0 0 0 0 0 0 1 0 0 0 0 0 1 0 0 0 0 0 0 0 0 0 0 0 0</counts>
			</dataPoints>
		</scan>
		<scan status="Completed" appendNumber="0" scanAxis="2Theta" mode="Continuous">
			<header>
				<startTimeStamp>2024-09-11T13:00:55-04:00</startTimeStamp>
				<endTimeStamp>2024-09-11T13:30:54-04:00</endTimeStamp>
				<author>
					<name>lw627</name>
				</author>
				<source>
					<applicationSoftware version="7.1">Data Collector</applicationSoftware>
					<instrumentControlSoftware version="8.2  20201204">EMPYREAN</instrumentControlSoftware>
					<instrumentID>0000000011260721</instrumentID>
				</source>
			</header>
			<dataPoints>
				<positions axis="2Theta" unit="deg">
					<startPosition>71.5880798130774</startPosition>
					<endPosition>74.9353495842939</endPosition>
				</positions>
				<positions axis="Omega" unit="deg">
					<commonPosition>17.9878573493428</commonPosition>
				</positions>
				<positions axis="Phi" unit="deg">
					<commonPosition>91.37</commonPosition>
				</positions>
				<positions axis="Chi" unit="deg">
					<commonPosition>0</commonPosition>
				</positions>
				<positions axis="Z" unit="mm">
					<commonPosition>8.335</commonPosition>
				</positions>
				<commonCountingTime unit="seconds">0.974</commonCountingTime>
				<counts unit="counts">0 0 0 0 1 0 1 0 0 0 1 1 1 0 0 0 0 0 1 0 1 0 0 0 1 0 0 0 0 1 0 0 2 1 0 0 1 0 0 0 1 1 0 1 0 0 0 0 0 0 0 0 0 1 0 0 0 0 0 0 1 0 1 0 0 0 0 0 0 1 1 0 1 1 3 2 1 0 0 0 0 0 0 0 0 0 0 0 0 0 0 0 0 1 1 0 0 1 1 0 0 0 0 1 0 0 1 1 0 0 2 0 0 0 1 0 0 0 1 1 2 2 0 0 0 1 0 0 0 0 0 1 0 0 0 0 1 0 0 0 2 1 0 0 1 1 0 2 0 0 0 0 1 2 0 0 1 1 0 0 0 1 0 0 1 2 0 0 2 1 0 0 0 1 0 0 0 0 0 1 1 0 0 0 0 0 0 1 1 2 0 0 0 0 0 0 0 0 1 0 0 0 2 1 0 0 1 0 0 0 0 1 0 1 0 1 0 1 0 0 0 0 1 1 0 0 0 0 2 0 0 2 0 1 0 0 0 0 0 0 0 0 1 0 2 0 0 0 1 0 0 0 0 1 0</counts>
			</dataPoints>
		</scan>
		<scan status="Completed" appendNumber="0" scanAxis="2Theta" mode="Continuous">
			<header>
				<startTimeStamp>2024-09-11T13:00:55-04:00</startTimeStamp>
				<endTimeStamp>2024-09-11T13:30:54-04:00</endTimeStamp>
				<author>
					<name>lw627</name>
				</author>
				<source>
					<applicationSoftware version="7.1">Data Collector</applicationSoftware>
					<instrumentControlSoftware version="8.2  20201204">EMPYREAN</instrumentControlSoftware>
					<instrumentID>0000000011260721</instrumentID>
				</source>
			</header>
			<dataPoints>
				<positions axis="2Theta" unit="deg">
					<startPosition>71.5913623837455</startPosition>
					<endPosition>74.938632154962</endPosition>
				</positions>
				<positions axis="Omega" unit="deg">
					<commonPosition>17.9894986346769</commonPosition>
				</positions>
				<positions axis="Phi" unit="deg">
					<commonPosition>91.37</commonPosition>
				</positions>
				<positions axis="Chi" unit="deg">
					<commonPosition>0</commonPosition>
				</positions>
				<positions axis="Z" unit="mm">
					<commonPosition>8.335</commonPosition>
				</positions>
				<commonCountingTime unit="seconds">0.974</commonCountingTime>
				<counts unit="counts">0 0 2 0 0 2 0 0 0 2 2 1 0 0 0 1 1 0 0 0 0 0 0 0 0 0 0 0 0 0 0 0 0 1 0 0 1 1 0 0 1 0 0 1 0 0 0 0 0 0 0 0 0 0 0 0 0 0 0 1 0 0 0 0 0 1 1 1 0 0 0 0 0 0 1 3 0 1 0 1 0 0 2 0 0 0 0 0 0 0 0 0 0 0 0 1 0 1 0 0 0 0 2 0 0 2 0 0 0 0 0 0 0 1 1 0 1 1 0 1 0 0 0 0 1 1 0 0 0 1 0 0 0 0 2 0 0 0 0 0 1 0 1 0 1 1 0 1 0 1 0 0 0 0 0 1 0 1 1 1 0 1 0 0 0 0 1 2 1 0 0 0 1 0 1 0 1 2 0 0 1 0 0 0 0 1 0 0 0 0 1 2 1 0 0 0 1 1 0 1 0 0 0 0 0 0 0 1 0 0 0 0 0 0 1 0 0 1 0 0 0 0 0 0 1 0 0 0 1 0 2 0 0 0 0 0 0 0 0 0 0 0 0 0 0 2 0 1 2 1 0 0 0 0 0</counts>
			</dataPoints>
		</scan>
		<scan status="Completed" appendNumber="0" scanAxis="2Theta" mode="Continuous">
			<header>
				<startTimeStamp>2024-09-11T13:00:55-04:00</startTimeStamp>
				<endTimeStamp>2024-09-11T13:30:54-04:00</endTimeStamp>
				<author>
					<name>lw627</name>
				</author>
				<source>
					<applicationSoftware version="7.1">Data Collector</applicationSoftware>
					<instrumentControlSoftware version="8.2  20201204">EMPYREAN</instrumentControlSoftware>
					<instrumentID>0000000011260721</instrumentID>
				</source>
			</header>
			<dataPoints>
				<positions axis="2Theta" unit="deg">
					<startPosition>71.5946449544137</startPosition>
					<endPosition>74.9419147256301</endPosition>
				</positions>
				<positions axis="Omega" unit="deg">
					<commonPosition>17.991139920011</commonPosition>
				</positions>
				<positions axis="Phi" unit="deg">
					<commonPosition>91.37</commonPosition>
				</positions>
				<positions axis="Chi" unit="deg">
					<commonPosition>0</commonPosition>
				</positions>
				<positions axis="Z" unit="mm">
					<commonPosition>8.335</commonPosition>
				</positions>
				<commonCountingTime unit="seconds">0.974</commonCountingTime>
				<counts unit="counts">2 0 0 0 0 1 1 1 1 0 0 0 0 0 2 0 0 0 0 0 1 0 0 0 1 0 0 0 0 1 0 0 0 0 0 0 2 1 1 0 0 0 0 1 1 0 0 0 0 0 0 0 0 0 0 0 0 0 0 0 1 0 0 0 0 0 0 0 0 0 0 1 0 0 0 1 0 0 0 0 1 0 0 0 0 2 0 0 1 0 0 0 0 1 0 0 0 2 0 0 0 1 1 0 0 0 0 0 1 0 0 0 1 0 0 0 2 0 0 1 0 0 0 0 0 0 1 0 1 0 0 0 0 0 0 2 0 0 0 0 1 0 0 2 0 0 0 0 1 1 0 0 0 0 0 0 0 2 0 0 0 0 0 0 0 0 0 0 0 0 0 2 0 0 0 0 0 0 0 0 0 0 0 0 1 0 0 1 0 1 1 0 1 0 0 0 0 1 0 2 1 1 0 0 0 0 0 0 0 0 0 0 0 0 0 0 0 1 2 0 0 0 0 0 0 0 0 0 0 0 0 0 1 1 0 0 1 1 0 0 0 0 0 1 1 2 1 0 0 0 1 0 0 1 2</counts>
			</dataPoints>
		</scan>
		<scan status="Completed" appendNumber="0" scanAxis="2Theta" mode="Continuous">
			<header>
				<startTimeStamp>2024-09-11T13:00:55-04:00</startTimeStamp>
				<endTimeStamp>2024-09-11T13:30:54-04:00</endTimeStamp>
				<author>
					<name>lw627</name>
				</author>
				<source>
					<applicationSoftware version="7.1">Data Collector</applicationSoftware>
					<instrumentControlSoftware version="8.2  20201204">EMPYREAN</instrumentControlSoftware>
					<instrumentID>0000000011260721</instrumentID>
				</source>
			</header>
			<dataPoints>
				<positions axis="2Theta" unit="deg">
					<startPosition>71.5979275250818</startPosition>
					<endPosition>74.9451972962983</endPosition>
				</positions>
				<positions axis="Omega" unit="deg">
					<commonPosition>17.992781205345</commonPosition>
				</positions>
				<positions axis="Phi" unit="deg">
					<commonPosition>91.37</commonPosition>
				</positions>
				<positions axis="Chi" unit="deg">
					<commonPosition>0</commonPosition>
				</positions>
				<positions axis="Z" unit="mm">
					<commonPosition>8.335</commonPosition>
				</positions>
				<commonCountingTime unit="seconds">0.974</commonCountingTime>
				<counts unit="counts">0 1 0 0 0 0 0 0 0 0 1 0 0 2 1 2 0 0 0 0 1 0 0 1 0 0 1 0 0 0 1 0 0 0 0 0 0 0 0 0 0 0 1 1 0 2 2 0 0 0 2 0 0 1 0 1 0 0 0 1 0 0 1 0 0 1 0 0 0 0 0 0 0 0 0 0 0 0 1 1 1 0 0 0 1 0 0 0 0 0 1 0 0 1 0 0 1 0 1 1 1 1 0 0 0 0 0 0 0 0 0 0 0 3 1 0 2 0 0 0 0 0 0 0 0 0 0 0 0 1 0 0 0 1 0 1 0 0 2 1 0 0 0 0 1 0 0 0 0 0 0 1 0 2 0 1 1 1 0 1 0 0 0 0 1 0 0 0 0 1 0 0 1 2 0 0 1 0 0 2 0 1 0 0 0 0 0 1 1 0 0 0 0 0 0 0 0 0 0 0 2 0 1 0 0 0 0 1 0 1 0 0 0 0 0 0 1 0 0 0 1 0 0 1 0 1 0 0 0 0 0 0 1 0 2 0 1 0 0 2 0 0 0 0 0 0 0 1 0 0 0 0 0 0 1</counts>
			</dataPoints>
		</scan>
		<scan status="Completed" appendNumber="0" scanAxis="2Theta" mode="Continuous">
			<header>
				<startTimeStamp>2024-09-11T13:00:55-04:00</startTimeStamp>
				<endTimeStamp>2024-09-11T13:30:54-04:00</endTimeStamp>
				<author>
					<name>lw627</name>
				</author>
				<source>
					<applicationSoftware version="7.1">Data Collector</applicationSoftware>
					<instrumentControlSoftware version="8.2  20201204">EMPYREAN</instrumentControlSoftware>
					<instrumentID>0000000011260721</instrumentID>
				</source>
			</header>
			<dataPoints>
				<positions axis="2Theta" unit="deg">
					<startPosition>71.6012100957499</startPosition>
					<endPosition>74.9484798669664</endPosition>
				</positions>
				<positions axis="Omega" unit="deg">
					<commonPosition>17.9944224906791</commonPosition>
				</positions>
				<positions axis="Phi" unit="deg">
					<commonPosition>91.37</commonPosition>
				</positions>
				<positions axis="Chi" unit="deg">
					<commonPosition>0</commonPosition>
				</positions>
				<positions axis="Z" unit="mm">
					<commonPosition>8.335</commonPosition>
				</positions>
				<commonCountingTime unit="seconds">0.974</commonCountingTime>
				<counts unit="counts">0 0 1 2 0 1 1 1 1 0 1 0 1 1 0 0 1 0 0 0 0 1 1 1 0 1 0 0 0 0 0 1 0 0 0 0 0 0 0 0 0 0 0 0 1 0 1 0 0 1 0 0 0 0 0 1 0 0 0 1 0 0 1 0 0 0 0 1 0 1 0 0 2 0 0 0 0 0 0 1 0 0 0 0 0 0 0 0 1 0 1 1 2 0 0 0 0 0 1 0 1 0 1 1 0 0 1 0 0 0 1 0 0 0 1 1 0 0 0 0 0 0 0 1 1 0 0 0 1 0 0 0 2 0 0 1 2 1 0 2 0 0 0 0 0 1 0 0 0 0 0 0 0 1 1 1 0 0 0 1 0 1 1 0 0 0 1 0 1 1 0 0 0 1 0 0 0 0 0 1 0 0 0 0 0 1 0 0 0 0 0 0 0 0 0 0 2 0 0 1 0 1 0 0 0 0 0 1 2 0 2 1 0 0 0 0 0 0 1 0 0 1 2 0 0 0 0 1 0 1 0 0 0 1 0 0 0 0 2 0 0 0 1 0 0 1 0 0 0 1 0 0 0 0 0</counts>
			</dataPoints>
		</scan>
		<scan status="Completed" appendNumber="0" scanAxis="2Theta" mode="Continuous">
			<header>
				<startTimeStamp>2024-09-11T13:00:55-04:00</startTimeStamp>
				<endTimeStamp>2024-09-11T13:30:54-04:00</endTimeStamp>
				<author>
					<name>lw627</name>
				</author>
				<source>
					<applicationSoftware version="7.1">Data Collector</applicationSoftware>
					<instrumentControlSoftware version="8.2  20201204">EMPYREAN</instrumentControlSoftware>
					<instrumentID>0000000011260721</instrumentID>
				</source>
			</header>
			<dataPoints>
				<positions axis="2Theta" unit="deg">
					<startPosition>71.6044926664181</startPosition>
					<endPosition>74.9517624376345</endPosition>
				</positions>
				<positions axis="Omega" unit="deg">
					<commonPosition>17.9960637760131</commonPosition>
				</positions>
				<positions axis="Phi" unit="deg">
					<commonPosition>91.37</commonPosition>
				</positions>
				<positions axis="Chi" unit="deg">
					<commonPosition>0</commonPosition>
				</positions>
				<positions axis="Z" unit="mm">
					<commonPosition>8.335</commonPosition>
				</positions>
				<commonCountingTime unit="seconds">0.974</commonCountingTime>
				<counts unit="counts">0 0 0 0 1 0 1 1 1 0 1 0 0 0 1 1 2 0 0 0 0 0 0 0 0 0 0 1 0 1 1 1 0 0 0 0 0 1 0 1 1 0 0 0 0 0 1 0 0 0 0 0 1 0 1 0 0 1 0 0 2 0 0 0 0 1 2 0 0 1 1 1 2 0 1 0 1 0 0 0 0 1 0 0 0 0 0 0 0 0 0 0 0 1 0 0 0 1 1 0 0 0 0 0 0 0 1 1 0 2 0 0 1 0 0 0 0 0 1 0 0 0 0 2 0 0 2 1 0 0 2 0 0 0 0 1 1 0 1 1 1 0 0 0 0 0 0 0 0 0 1 1 1 0 0 0 0 0 0 0 0 1 0 0 0 1 1 0 0 0 1 0 1 2 0 0 2 0 0 1 0 0 1 1 1 0 0 0 0 0 0 0 0 0 0 0 0 0 0 1 1 1 0 0 0 0 0 0 0 0 0 1 0 0 0 0 0 0 0 0 0 0 0 0 0 1 1 0 0 1 1 0 0 0 0 0 0 0 0 0 0 1 0 0 1 0 0 0 0 0 0 0 0 0 0</counts>
			</dataPoints>
		</scan>
		<scan status="Completed" appendNumber="0" scanAxis="2Theta" mode="Continuous">
			<header>
				<startTimeStamp>2024-09-11T13:00:55-04:00</startTimeStamp>
				<endTimeStamp>2024-09-11T13:30:54-04:00</endTimeStamp>
				<author>
					<name>lw627</name>
				</author>
				<source>
					<applicationSoftware version="7.1">Data Collector</applicationSoftware>
					<instrumentControlSoftware version="8.2  20201204">EMPYREAN</instrumentControlSoftware>
					<instrumentID>0000000011260721</instrumentID>
				</source>
			</header>
			<dataPoints>
				<positions axis="2Theta" unit="deg">
					<startPosition>71.6077752370862</startPosition>
					<endPosition>74.9550450083026</endPosition>
				</positions>
				<positions axis="Omega" unit="deg">
					<commonPosition>17.9977050613472</commonPosition>
				</positions>
				<positions axis="Phi" unit="deg">
					<commonPosition>91.37</commonPosition>
				</positions>
				<positions axis="Chi" unit="deg">
					<commonPosition>0</commonPosition>
				</positions>
				<positions axis="Z" unit="mm">
					<commonPosition>8.335</commonPosition>
				</positions>
				<commonCountingTime unit="seconds">0.974</commonCountingTime>
				<counts unit="counts">0 0 0 0 1 0 0 1 0 0 0 0 0 1 1 0 0 0 0 0 1 0 0 1 0 0 1 0 1 0 0 1 0 1 0 1 0 0 0 1 0 0 0 0 1 0 0 0 0 0 0 0 2 1 0 0 0 0 0 1 1 2 1 1 0 0 0 0 1 0 0 0 0 0 0 1 0 0 0 0 0 0 0 1 0 0 1 0 0 0 0 1 1 0 0 0 1 1 1 0 0 1 0 0 0 1 0 1 1 1 0 0 0 1 1 1 1 0 0 0 0 0 0 1 1 2 0 1 1 0 0 0 0 2 0 1 0 0 0 0 0 2 0 0 1 0 0 0 0 1 0 0 1 0 0 0 0 0 0 0 2 1 0 0 0 0 0 0 0 0 0 0 1 1 0 1 0 0 0 0 0 0 0 0 0 0 0 1 1 1 0 0 2 0 0 0 0 0 0 2 0 2 0 0 0 0 0 0 0 0 2 0 1 0 0 0 0 0 2 0 0 0 0 2 0 0 0 0 1 0 1 0 0 2 0 0 1 0 0 0 0 0 0 0 0 0 0 1 0 0 0 0 0 0 0</counts>
			</dataPoints>
		</scan>
		<scan status="Completed" appendNumber="0" scanAxis="2Theta" mode="Continuous">
			<header>
				<startTimeStamp>2024-09-11T13:00:55-04:00</startTimeStamp>
				<endTimeStamp>2024-09-11T13:30:54-04:00</endTimeStamp>
				<author>
					<name>lw627</name>
				</author>
				<source>
					<applicationSoftware version="7.1">Data Collector</applicationSoftware>
					<instrumentControlSoftware version="8.2  20201204">EMPYREAN</instrumentControlSoftware>
					<instrumentID>0000000011260721</instrumentID>
				</source>
			</header>
			<dataPoints>
				<positions axis="2Theta" unit="deg">
					<startPosition>71.6110578077543</startPosition>
					<endPosition>74.9583275789708</endPosition>
				</positions>
				<positions axis="Omega" unit="deg">
					<commonPosition>17.9993463466813</commonPosition>
				</positions>
				<positions axis="Phi" unit="deg">
					<commonPosition>91.37</commonPosition>
				</positions>
				<positions axis="Chi" unit="deg">
					<commonPosition>0</commonPosition>
				</positions>
				<positions axis="Z" unit="mm">
					<commonPosition>8.335</commonPosition>
				</positions>
				<commonCountingTime unit="seconds">0.974</commonCountingTime>
[...]
					<commonPosition>0</commonPosition>
				</positions>
				<positions axis="Z" unit="mm">
					<commonPosition>8.335</commonPosition>
				</positions>
				<commonCountingTime unit="seconds">0.974</commonCountingTime>
				<counts unit="counts">0 0 1 0 0 0 0 2 0 0 0 0 0 1 0 0 0 0 0 0 0 0 0 0 0 0 0 1 0 0 0 0 1 0 0 0 0 0 1 0 1 0 2 0 0 1 1 1 0 0 0 2 1 0 0 0 1 1 1 0 0 1 1 0 0 0 0 2 1 1 1 0 0 1 0 0 1 0 0 0 1 0 0 1 0 2 0 0 0 0 0 0 0 0 0 0 0 0 0 1 0 1 0 0 1 2 0 0 0 0 0 0 0 0 1 0 0 0 0 0 0 1 0 1 0 0 0 0 0 0 0 0 0 0 0 0 0 1 0 1 0 0 0 0 2 0 0 0 3 0 0 0 0 1 0 1 0 0 1 1 0 0 0 0 1 0 0 0 0 0 0 0 0 3 1 1 0 0 0 0 0 1 0 2 0 3 0 0 0 0 0 0 0 0 0 0 0 0 0 0 0 0 0 0 1 0 0 0 1 0 0 0 0 0 0 1 0 0 1 0 0 0 0 0 0 0 1 0 0 0 0 0 0 0 0 0 0 1 0 0 0 0 1 0 1 1 0 0 0 0 0 0 1 0 1</counts>
			</dataPoints>
		</scan>
		<scan status="Completed" appendNumber="0" scanAxis="2Theta" mode="Continuous">
			<header>
				<startTimeStamp>2024-09-11T13:00:55-04:00</startTimeStamp>
				<endTimeStamp>2024-09-11T13:30:54-04:00</endTimeStamp>
				<author>
					<name>lw627</name>
				</author>
				<source>
					<applicationSoftware version="7.1">Data Collector</applicationSoftware>
					<instrumentControlSoftware version="8.2  20201204">EMPYREAN</instrumentControlSoftware>
					<instrumentID>0000000011260721</instrumentID>
				</source>
			</header>
			<dataPoints>
				<positions axis="2Theta" unit="deg">
					<startPosition>77.5065547277105</startPosition>
					<endPosition>80.853824498927</endPosition>
				</positions>
				<positions axis="Omega" unit="deg">
					<commonPosition>20.9470948066594</commonPosition>
				</positions>
				<positions axis="Phi" unit="deg">
					<commonPosition>91.37</commonPosition>
				</positions>
				<positions axis="Chi" unit="deg">
					<commonPosition>0</commonPosition>
				</positions>
				<positions axis="Z" unit="mm">
					<commonPosition>8.335</commonPosition>
				</positions>
				<commonCountingTime unit="seconds">0.974</commonCountingTime>
				<counts unit="counts">0 0 1 1 0 0 1 1 0 0 0 0 0 1 0 0 0 0 1 1 0 0 0 0 0 0 0 2 0 2 0 0 0 0 0 1 1 0 0 1 1 1 0 0 0 0 0 2 0 0 0 0 1 0 0 0 0 0 0 0 0 0 0 0 0 1 1 1 0 1 1 0 0 0 0 0 0 0 0 0 0 0 0 0 0 0 0 0 0 0 1 0 1 0 0 0 0 0 0 1 0 0 0 1 0 0 0 0 0 0 1 0 0 1 0 0 0 0 1 0 0 0 0 0 0 0 1 0 0 1 1 0 0 0 0 1 0 0 0 0 0 0 0 1 0 0 0 0 2 0 1 1 0 0 0 0 0 0 0 0 0 0 0 0 0 1 0 0 0 0 1 0 1 0 0 0 1 0 0 0 0 0 0 1 0 0 0 0 0 0 1 0 0 1 0 0 0 0 0 0 0 0 2 1 0 0 0 0 1 0 0 1 1 0 0 0 1 0 0 0 1 0 1 0 0 1 0 0 0 0 0 0 0 0 1 1 0 0 2 1 0 0 1 1 0 0 0 0 1 0 0 0 1 0 1</counts>
			</dataPoints>
		</scan>
		<scan status="Completed" appendNumber="0" scanAxis="2Theta" mode="Continuous">
			<header>
				<startTimeStamp>2024-09-11T13:00:55-04:00</startTimeStamp>
				<endTimeStamp>2024-09-11T13:30:54-04:00</endTimeStamp>
				<author>
					<name>lw627</name>
				</author>
				<source>
					<applicationSoftware version="7.1">Data Collector</applicationSoftware>
					<instrumentControlSoftware version="8.2  20201204">EMPYREAN</instrumentControlSoftware>
					<instrumentID>0000000011260721</instrumentID>
				</source>
			</header>
			<dataPoints>
				<positions axis="2Theta" unit="deg">
					<startPosition>77.5098372983786</startPosition>
					<endPosition>80.8571070695951</endPosition>
				</positions>
				<positions axis="Omega" unit="deg">
					<commonPosition>20.9487360919934</commonPosition>
				</positions>
				<positions axis="Phi" unit="deg">
					<commonPosition>91.37</commonPosition>
				</positions>
				<positions axis="Chi" unit="deg">
					<commonPosition>0</commonPosition>
				</positions>
				<positions axis="Z" unit="mm">
					<commonPosition>8.335</commonPosition>
				</positions>
				<commonCountingTime unit="seconds">0.974</commonCountingTime>
				<counts unit="counts">0 0 0 0 1 1 1 0 0 0 0 1 0 0 0 1 1 0 0 1 0 1 1 0 0 1 0 0 0 1 0 2 0 1 0 0 0 0 1 0 0 0 1 0 0 1 0 0 1 1 0 0 0 0 0 0 0 0 0 1 2 0 0 0 0 0 0 0 0 0 1 2 1 0 0 1 1 1 0 0 0 0 0 0 1 0 0 0 0 0 0 0 1 2 0 0 0 0 2 1 1 0 0 0 0 0 0 1 0 0 0 0 0 0 0 1 0 0 0 0 0 2 1 0 0 0 0 0 0 0 2 0 0 0 0 0 1 0 0 0 1 0 1 0 1 1 1 0 1 0 0 0 1 0 1 0 0 0 0 0 0 1 0 0 1 0 0 1 1 1 0 0 0 1 0 0 1 0 0 1 0 0 1 0 1 0 1 1 0 0 0 2 0 0 0 0 0 1 0 1 1 0 0 0 1 0 1 1 1 0 0 0 0 0 0 0 1 1 0 0 0 0 0 1 1 0 0 0 0 0 0 0 1 0 3 0 0 0 0 1 0 0 0 0 1 0 0 1 2 0 0 1 1 0 0</counts>
			</dataPoints>
		</scan>
		<scan status="Completed" appendNumber="0" scanAxis="2Theta" mode="Continuous">
			<header>
				<startTimeStamp>2024-09-11T13:00:55-04:00</startTimeStamp>
				<endTimeStamp>2024-09-11T13:30:54-04:00</endTimeStamp>
				<author>
					<name>lw627</name>
				</author>
				<source>
					<applicationSoftware version="7.1">Data Collector</applicationSoftware>
					<instrumentControlSoftware version="8.2  20201204">EMPYREAN</instrumentControlSoftware>
					<instrumentID>0000000011260721</instrumentID>
				</source>
			</header>
			<dataPoints>
				<positions axis="2Theta" unit="deg">
					<startPosition>77.5131198690467</startPosition>
					<endPosition>80.8603896402632</endPosition>
				</positions>
				<positions axis="Omega" unit="deg">
					<commonPosition>20.9503773773275</commonPosition>
				</positions>
				<positions axis="Phi" unit="deg">
					<commonPosition>91.37</commonPosition>
				</positions>
				<positions axis="Chi" unit="deg">
					<commonPosition>0</commonPosition>
				</positions>
				<positions axis="Z" unit="mm">
					<commonPosition>8.335</commonPosition>
				</positions>
				<commonCountingTime unit="seconds">0.974</commonCountingTime>
				<counts unit="counts">1 1 0 0 1 1 0 1 1 1 0 0 1 0 0 0 0 0 0 1 0 0 0 0 0 0 1 0 0 0 0 1 0 1 0 0 2 0 3 0 1 1 0 2 1 0 2 0 0 1 0 0 0 0 0 0 0 0 0 0 1 0 0 0 0 0 0 0 1 0 0 0 1 2 0 0 0 0 1 1 0 1 1 1 2 1 0 0 0 0 0 0 1 0 0 0 0 2 0 0 0 0 1 0 1 0 0 0 1 1 1 0 0 0 1 0 0 1 0 0 0 0 0 0 1 0 0 0 0 0 1 0 0 1 0 0 1 1 0 1 0 0 1 0 0 1 0 0 0 2 1 1 0 1 1 0 0 0 0 0 0 2 0 0 0 0 0 0 1 1 2 1 0 0 0 0 1 1 1 0 0 0 0 1 0 0 0 0 0 0 0 0 3 0 0 0 0 0 0 0 0 0 0 0 0 0 1 0 0 1 0 0 2 0 0 0 0 0 0 1 0 0 0 0 0 1 0 0 0 0 0 0 0 0 1 2 0 0 0 0 1 0 0 0 2 0 0 1 0 0 0 0 0 0 1</counts>
			</dataPoints>
		</scan>
		<scan status="Completed" appendNumber="0" scanAxis="2Theta" mode="Continuous">
			<header>
				<startTimeStamp>2024-09-11T13:00:55-04:00</startTimeStamp>
				<endTimeStamp>2024-09-11T13:30:54-04:00</endTimeStamp>
				<author>
					<name>lw627</name>
				</author>
				<source>
					<applicationSoftware version="7.1">Data Collector</applicationSoftware>
					<instrumentControlSoftware version="8.2  20201204">EMPYREAN</instrumentControlSoftware>
					<instrumentID>0000000011260721</instrumentID>
				</source>
			</header>
			<dataPoints>
				<positions axis="2Theta" unit="deg">
					<startPosition>77.5164024397149</startPosition>
					<endPosition>80.8636722109314</endPosition>
				</positions>
				<positions axis="Omega" unit="deg">
					<commonPosition>20.9520186626616</commonPosition>
				</positions>
				<positions axis="Phi" unit="deg">
					<commonPosition>91.37</commonPosition>
				</positions>
				<positions axis="Chi" unit="deg">
					<commonPosition>0</commonPosition>
				</positions>
				<positions axis="Z" unit="mm">
					<commonPosition>8.335</commonPosition>
				</positions>
				<commonCountingTime unit="seconds">0.974</commonCountingTime>
				<counts unit="counts">0 2 0 0 0 1 1 1 0 0 0 0 1 2 0 0 2 0 1 0 1 0 0 0 0 1 0 0 0 0 0 1 0 0 0 2 0 0 1 0 0 1 0 2 0 1 0 0 0 0 0 0 1 0 0 1 2 1 0 0 0 1 0 0 0 0 1 0 0 0 0 0 1 0 0 0 0 0 0 0 0 0 0 0 2 1 0 0 0 0 0 0 1 0 1 1 0 0 0 0 0 0 0 0 0 0 0 0 0 0 0 0 0 0 0 0 0 0 0 0 0 1 0 0 0 1 0 0 0 0 0 0 0 0 0 1 1 2 0 1 0 0 0 0 0 0 0 0 0 0 0 0 0 0 0 0 0 1 0 0 0 0 1 0 0 0 1 1 1 0 1 0 0 0 1 0 0 0 0 1 0 0 0 0 1 0 0 1 0 0 1 1 0 0 1 0 0 0 0 0 1 0 0 0 0 0 0 0 1 0 0 0 0 0 1 0 0 0 0 0 0 0 0 1 0 0 0 0 0 0 0 1 0 0 0 2 0 1 0 0 0 1 0 0 0 0 0 0 1 1 0 2 0 0 1</counts>
			</dataPoints>
		</scan>
		<scan status="Completed" appendNumber="0" scanAxis="2Theta" mode="Continuous">
			<header>
				<startTimeStamp>2024-09-11T13:00:55-04:00</startTimeStamp>
				<endTimeStamp>2024-09-11T13:30:54-04:00</endTimeStamp>
				<author>
					<name>lw627</name>
				</author>
				<source>
					<applicationSoftware version="7.1">Data Collector</applicationSoftware>
					<instrumentControlSoftware version="8.2  20201204">EMPYREAN</instrumentControlSoftware>
					<instrumentID>0000000011260721</instrumentID>
				</source>
			</header>
			<dataPoints>
				<positions axis="2Theta" unit="deg">
					<startPosition>77.519685010383</startPosition>
					<endPosition>80.8669547815995</endPosition>
				</positions>
				<positions axis="Omega" unit="deg">
					<commonPosition>20.9536599479956</commonPosition>
				</positions>
				<positions axis="Phi" unit="deg">
					<commonPosition>91.37</commonPosition>
				</positions>
				<positions axis="Chi" unit="deg">
					<commonPosition>0</commonPosition>
				</positions>
				<positions axis="Z" unit="mm">
					<commonPosition>8.335</commonPosition>
				</positions>
				<commonCountingTime unit="seconds">0.974</commonCountingTime>
				<counts unit="counts">2 2 1 0 1 2 1 2 0 0 0 0 0 1 1 1 1 0 1 1 0 0 0 0 0 0 0 1 0 0 0 0 0 1 1 0 0 0 0 0 0 0 0 0 1 0 1 1 0 0 1 1 1 0 2 0 1 0 0 0 0 0 1 0 1 1 0 1 0 0 0 0 0 0 0 0 0 0 1 0 0 0 0 0 0 0 1 0 0 0 0 1 0 1 1 1 0 0 1 0 0 0 0 0 1 0 0 0 0 0 0 0 0 0 0 0 0 1 1 0 1 0 0 0 0 0 0 0 0 1 0 0 1 1 1 0 0 1 0 0 1 0 0 0 1 0 0 0 1 1 0 0 0 0 0 0 1 1 1 1 0 0 0 1 0 0 0 0 0 0 0 0 1 0 1 0 0 0 0 2 0 0 0 0 0 0 0 0 0 0 0 0 1 0 0 1 3 0 0 0 0 0 3 0 0 0 0 0 0 0 0 0 1 1 0 0 0 1 0 0 0 0 1 0 0 0 0 0 1 1 0 0 0 0 0 0 0 0 1 0 0 0 0 0 0 2 0 0 0 0 0 0 0 0 0</counts>
			</dataPoints>
		</scan>
		<scan status="Completed" appendNumber="0" scanAxis="2Theta" mode="Continuous">
			<header>
				<startTimeStamp>2024-09-11T13:00:55-04:00</startTimeStamp>
				<endTimeStamp>2024-09-11T13:30:54-04:00</endTimeStamp>
				<author>
					<name>lw627</name>
				</author>
				<source>
					<applicationSoftware version="7.1">Data Collector</applicationSoftware>
					<instrumentControlSoftware version="8.2  20201204">EMPYREAN</instrumentControlSoftware>
					<instrumentID>0000000011260721</instrumentID>
				</source>
			</header>
			<dataPoints>
				<positions axis="2Theta" unit="deg">
					<startPosition>77.5229675810511</startPosition>
					<endPosition>80.8702373522676</endPosition>
				</positions>
				<positions axis="Omega" unit="deg">
					<commonPosition>20.9553012333297</commonPosition>
				</positions>
				<positions axis="Phi" unit="deg">
					<commonPosition>91.37</commonPosition>
				</positions>
				<positions axis="Chi" unit="deg">
					<commonPosition>0</commonPosition>
				</positions>
				<positions axis="Z" unit="mm">
					<commonPosition>8.335</commonPosition>
				</positions>
				<commonCountingTime unit="seconds">0.974</commonCountingTime>
				<counts unit="counts">0 0 0 0 2 1 1 0 0 0 0 0 0 0 0 1 1 0 0 0 2 0 1 0 0 1 0 1 0 0 0 0 1 0 1 0 0 0 0 1 0 0 0 0 0 0 0 0 1 2 1 1 1 2 2 0 0 1 1 2 0 1 0 2 1 0 0 1 1 1 0 0 0 1 0 0 0 1 0 0 1 0 0 0 0 0 0 0 0 0 0 1 0 0 0 0 0 0 0 0 0 0 2 0 0 1 0 0 0 1 0 1 0 0 0 0 0 0 0 0 0 0 0 0 0 0 1 0 0 0 0 0 0 1 0 0 0 1 0 1 0 0 0 0 1 0 0 0 0 0 1 0 0 0 0 0 0 0 0 1 0 0 1 0 0 0 0 0 0 0 0 0 0 0 0 0 0 0 0 0 0 0 0 0 0 1 0 0 0 0 1 0 0 0 1 0 0 2 0 1 1 0 0 0 0 0 0 0 0 0 0 0 1 0 0 0 2 0 0 0 1 1 1 0 0 0 0 0 0 1 1 0 0 0 0 1 0 0 0 1 1 0 1 0 0 0 0 0 0 0 1 0 0 0 1</counts>
			</dataPoints>
		</scan>
		<scan status="Completed" appendNumber="0" scanAxis="2Theta" mode="Continuous">
			<header>
				<startTimeStamp>2024-09-11T13:00:55-04:00</startTimeStamp>
				<endTimeStamp>2024-09-11T13:30:54-04:00</endTimeStamp>
				<author>
					<name>lw627</name>
				</author>
				<source>
					<applicationSoftware version="7.1">Data Collector</applicationSoftware>
					<instrumentControlSoftware version="8.2  20201204">EMPYREAN</instrumentControlSoftware>
					<instrumentID>0000000011260721</instrumentID>
				</source>
			</header>
			<dataPoints>
				<positions axis="2Theta" unit="deg">
					<startPosition>77.5262501517193</startPosition>
					<endPosition>80.8735199229357</endPosition>
				</positions>
				<positions axis="Omega" unit="deg">
					<commonPosition>20.9569425186637</commonPosition>
				</positions>
				<positions axis="Phi" unit="deg">
					<commonPosition>91.37</commonPosition>
				</positions>
				<positions axis="Chi" unit="deg">
					<commonPosition>0</commonPosition>
				</positions>
				<positions axis="Z" unit="mm">
					<commonPosition>8.335</commonPosition>
				</positions>
				<commonCountingTime unit="seconds">0.974</commonCountingTime>
				<counts unit="counts">2 1 1 0 0 0 0 0 0 0 0 0 1 1 0 2 0 0 0 0 1 0 0 1 1 0 0 0 0 0 0 0 0 0 1 1 0 1 0 0 0 0 2 0 0 1 0 0 0 1 1 0 1 0 1 2 2 1 1 1 0 1 0 0 1 0 0 1 0 0 1 0 0 0 1 1 0 2 0 0 0 0 0 0 1 2 0 1 0 0 0 0 1 0 0 1 0 0 0 0 0 0 0 0 0 0 2 0 0 0 0 0 1 1 0 0 0 0 0 0 0 0 0 1 0 1 0 0 0 1 1 2 0 0 0 1 1 0 0 1 0 1 0 0 0 0 0 0 0 0 0 1 0 0 0 0 1 1 0 0 0 0 0 0 0 0 0 1 0 1 0 0 0 1 0 0 0 0 0 1 0 1 0 0 0 0 1 0 1 0 0 1 0 0 0 0 0 0 0 1 1 0 0 0 0 1 1 0 0 0 0 0 0 2 1 0 0 0 0 1 0 1 0 0 2 0 0 0 0 1 1 1 0 0 0 0 0 1 0 0 0 0 0 0 0 0 0 0 0 0 1 0 1 1 0</counts>
			</dataPoints>
		</scan>
		<scan status="Completed" appendNumber="0" scanAxis="2Theta" mode="Continuous">
			<header>
				<startTimeStamp>2024-09-11T13:00:55-04:00</startTimeStamp>
				<endTimeStamp>2024-09-11T13:30:54-04:00</endTimeStamp>
				<author>
					<name>lw627</name>
				</author>
				<source>
					<applicationSoftware version="7.1">Data Collector</applicationSoftware>
					<instrumentControlSoftware version="8.2  20201204">EMPYREAN</instrumentControlSoftware>
					<instrumentID>0000000011260721</instrumentID>
				</source>
			</header>
			<dataPoints>
				<positions axis="2Theta" unit="deg">
					<startPosition>77.5295327223874</startPosition>
					<endPosition>80.8768024936039</endPosition>
				</positions>
				<positions axis="Omega" unit="deg">
					<commonPosition>20.9585838039978</commonPosition>
				</positions>
				<positions axis="Phi" unit="deg">
					<commonPosition>91.37</commonPosition>
				</positions>
				<positions axis="Chi" unit="deg">
					<commonPosition>0</commonPosition>
				</positions>
				<positions axis="Z" unit="mm">
					<commonPosition>8.335</commonPosition>
				</positions>
				<commonCountingTime unit="seconds">0.974</commonCountingTime>
				<counts unit="counts">0 0 0 1 1 0 0 0 0 0 0 0 1 1 1 0 0 0 0 0 0 0 0 0 1 0 0 0 1 1 0 1 0 0 0 1 0 0 0 0 0 0 0 0 0 0 1 1 0 0 0 0 0 0 0 1 1 1 0 0 0 0 0 1 1 0 0 1 0 0 2 0 0 0 0 0 0 0 0 0 0 0 0 0 0 0 0 1 0 0 0 1 0 1 0 1 0 0 0 1 1 1 0 1 0 1 0 0 0 0 0 0 0 0 0 0 0 0 0 0 0 0 0 0 1 0 0 0 0 0 0 0 0 2 0 1 0 1 0 0 0 0 0 0 0 0 0 0 1 0 0 0 0 1 0 1 0 0 0 0 0 0 0 0 0 1 0 1 0 1 1 1 0 0 0 0 0 0 0 0 0 0 1 1 0 0 0 0 0 0 0 1 0 0 0 0 0 1 1 0 1 0 1 0 0 0 0 0 0 1 1 0 0 0 0 0 0 0 0 0 0 0 0 0 1 0 1 0 0 0 0 1 0 1 0 0 1 1 0 0 0 0 0 1 0 0 0 0 0 1 0 0 1 0 0</counts>
			</dataPoints>
		</scan>
		<scan status="Completed" appendNumber="0" scanAxis="2Theta" mode="Continuous">
			<header>
				<startTimeStamp>2024-09-11T13:00:55-04:00</startTimeStamp>
				<endTimeStamp>2024-09-11T13:30:54-04:00</endTimeStamp>
				<author>
					<name>lw627</name>
				</author>
				<source>
					<applicationSoftware version="7.1">Data Collector</applicationSoftware>
					<instrumentControlSoftware version="8.2  20201204">EMPYREAN</instrumentControlSoftware>
					<instrumentID>0000000011260721</instrumentID>
				</source>
			</header>
			<dataPoints>
				<positions axis="2Theta" unit="deg">
					<startPosition>77.5328152930555</startPosition>
					<endPosition>80.880085064272</endPosition>
				</positions>
				<positions axis="Omega" unit="deg">
					<commonPosition>20.9602250893319</commonPosition>
				</positions>
				<positions axis="Phi" unit="deg">
					<commonPosition>91.37</commonPosition>
				</positions>
				<positions axis="Chi" unit="deg">
					<commonPosition>0</commonPosition>
				</positions>
				<positions axis="Z" unit="mm">
					<commonPosition>8.335</commonPosition>
				</positions>
				<commonCountingTime unit="seconds">0.974</commonCountingTime>
				<counts unit="counts">1 0 0 1 1 0 0 1 0 1 0 1 0 0 0 0 1 0 0 1 1 0 0 1 0 1 0 0 0 0 0 1 0 1 0 1 1 0 1 0 0 0 0 0 0 0 0 1 0 0 0 0 0 1 0 0 0 2 0 0 1 0 0 0 0 0 0 0 0 0 1 0 0 0 0 1 0 0 0 0 0 0 1 0 1 1 0 0 0 0 1 0 0 1 1 0 0 0 0 0 1 0 0 1 0 0 0 0 1 0 1 0 0 1 0 0 0 0 0 0 0 0 1 0 0 3 0 0 0 2 0 0 0 0 0 0 0 0 0 0 1 0 1 0 0 0 0 0 1 1 0 0 0 0 0 0 0 1 0 0 0 0 1 0 0 0 0 0 0 0 1 0 0 0 0 0 1 0 0 1 1 0 1 0 0 1 2 0 0 0 0 0 1 0 1 0 0 1 1 1 1 0 0 0 0 0 1 0 0 3 0 0 0 1 1 0 0 0 0 1 0 0 0 1 0 0 0 0 0 0 0 0 1 0 0 0 0 1 0 1 0 0 0 0 0 0 0 0 2 0 0 0 1 0 0</counts>
			</dataPoints>
		</scan>
		<scan status="Completed" appendNumber="0" scanAxis="2Theta" mode="Continuous">
			<header>
				<startTimeStamp>2024-09-11T13:00:55-04:00</startTimeStamp>
				<endTimeStamp>2024-09-11T13:30:54-04:00</endTimeStamp>
				<author>
					<name>lw627</name>
				</author>
				<source>
					<applicationSoftware version="7.1">Data Collector</applicationSoftware>
					<instrumentControlSoftware version="8.2  20201204">EMPYREAN</instrumentControlSoftware>
					<instrumentID>0000000011260721</instrumentID>
				</source>
			</header>
			<dataPoints>
				<positions axis="2Theta" unit="deg">
					<startPosition>77.5360978637236</startPosition>
					<endPosition>80.8833676349401</endPosition>
				</positions>
				<positions axis="Omega" unit="deg">
					<commonPosition>20.9618663746659</commonPosition>
				</positions>
				<positions axis="Phi" unit="deg">
					<commonPosition>91.37</commonPosition>
				</positions>
				<positions axis="Chi" unit="deg">
					<commonPosition>0</commonPosition>
				</positions>
				<positions axis="Z" unit="mm">
					<commonPosition>8.335</commonPosition>
				</positions>
				<commonCountingTime unit="seconds">0.974</commonCountingTime>
				<counts unit="counts">0 0 0 0 0 0 0 0 0 1 1 0 0 0 0 0 0 0 1 0 0 2 0 0 0 0 1 1 0 0 0 0 1 0 1 1 0 0 0 0 0 0 0 0 1 1 0 0 0 0 0 0 0 0 1 2 0 0 1 0 0 0 0 0 0 0 0 0 0 0 0 0 0 1 2 0 1 1 0 0 0 0 1 0 0 0 0 0 0 1 0 1 0 0 1 1 0 0 0 0 0 1 0 0 1 0 0 0 0 1 0 0 0 0 0 0 1 1 1 0 0 0 0 1 0 0 0 1 0 0 0 0 0 0 0 0 1 0 0 0 0 0 0 1 0 0 0 0 0 0 0 0 1 1 1 1 1 0 0 1 1 0 0 0 1 0 0 0 0 0 0 1 0 0 0 0 1 0 2 0 0 0 0 1 0 0 0 0 0 0 0 2 0 1 0 0 0 0 1 0 1 0 0 1 0 0 0 0 0 0 0 1 0 0 0 0 0 0 0 0 0 0 0 0 1 0 0 0 0 2 1 2 0 0 0 0 1 1 0 0 0 0 0 0 0 0 0 0 0 0 0 0 0 0 1</counts>
			</dataPoints>
		</scan>
		<scan status="Completed" appendNumber="0" scanAxis="2Theta" mode="Continuous">
			<header>
				<startTimeStamp>2024-09-11T13:00:55-04:00</startTimeStamp>
				<endTimeStamp>2024-09-11T13:30:54-04:00</endTimeStamp>
				<author>
					<name>lw627</name>
				</author>
				<source>
					<applicationSoftware version="7.1">Data Collector</applicationSoftware>
					<instrumentControlSoftware version="8.2  20201204">EMPYREAN</instrumentControlSoftware>
					<instrumentID>0000000011260721</instrumentID>
				</source>
			</header>
			<dataPoints>
				<positions axis="2Theta" unit="deg">
					<startPosition>77.5393804343918</startPosition>
					<endPosition>80.8866502056082</endPosition>
				</positions>
				<positions axis="Omega" unit="deg">
					<commonPosition>20.96350766</commonPosition>
				</positions>
				<positions axis="Phi" unit="deg">
					<commonPosition>91.37</commonPosition>
				</positions>
				<positions axis="Chi" unit="deg">
					<commonPosition>0</commonPosition>
				</positions>
				<positions axis="Z" unit="mm">
					<commonPosition>8.335</commonPosition>
				</positions>
				<commonCountingTime unit="seconds">0.974</commonCountingTime>
				<counts unit="counts">1 1 1 0 3 2 0 0 0 1 0 0 1 1 0 0 0 1 0 0 1 0 0 0 0 0 2 0 0 0 0 0 1 1 1 1 0 0 1 1 0 0 1 0 2 0 0 1 0 0 0 0 0 1 0 0 1 0 0 0 0 0 1 0 0 0 1 0 0 0 0 0 0 0 0 0 0 0 0 0 0 1 1 1 0 1 0 0 0 0 1 1 0 2 0 1 1 0 1 0 0 0 1 1 1 0 1 0 0 0 1 0 1 1 0 0 0 0 0 0 2 0 1 0 0 0 0 0 0 0 0 1 0 0 1 1 0 0 0 0 0 0 0 0 2 0 0 0 1 0 1 0 0 0 0 0 0 0 3 0 1 0 0 0 0 0 0 0 1 0 0 0 0 0 0 0 0 0 0 0 0 0 0 0 0 0 0 1 1 0 0 0 0 1 0 0 0 0 0 0 0 0 0 0 0 0 0 0 0 1 0 0 0 0 0 0 0 0 2 0 0 0 1 0 0 0 1 0 0 1 0 0 0 0 0 0 0 0 0 0 0 0 0 0 0 0 1 1 0 0 0 0 1 1 0</counts>
			</dataPoints>
		</scan>
	</xrdMeasurement>
</xrdMeasurements>