File: data/previous_data/set_1-YG028-030/xrd/YG028-SRO001-STO001-06022022.xrdml
<xrdMeasurements xmlns="http://www.xrdml.com/XRDMeasurement/2.1" xmlns:xsi="http://www.w3.org/2001/XMLSchema-instance" xsi:schemaLocation="http://www.xrdml.com/XRDMeasurement/2.1 http://www.xrdml.com/XRDMeasurement/2.1/XRDMeasurement.xsd" status="Completed">
	<comment>
		<entry>Configuration=Main Configuration, Owner=User-1, Creation date=6/17/2015 3:36:16 PM</entry>
		<entry>Goniometer=HR HD (Theta/2Theta); Minimum step size 2Theta:0.0001; Minimum step size Omega:0.0001</entry>
		<entry>Sample stage=MRD Cradle; Minimum step size Phi:0.01; Minimum step size Chi:0.01; Minimum step size X:0.01; Minimum step size Y:0.01; Minimum step size Z:0.001</entry>
		<entry>Diffractometer system=XPERT-3</entry>
		<entry>Measurement program=C:\PANalytical\Data Collector\Programs\Yichen\regular_2theta_20-50_0.4s-20min.xrdmp, Identifier={AEA8F2F2-8BFA-4B07-A521-A571AF38E73A}</entry>
	</comment>
	<sample type="To be analyzed">
		<id></id>
		<name></name>
		<preparedBy></preparedBy>
	</sample>
	<xrdMeasurement measurementType="Scan" status="Completed" sampleMode="Reflection">
		<comment>
			<entry>PHD Lower Level = 4.02 (keV), PHD Upper Level = 11.27 (keV)</entry>
		</comment>
		<usedWavelength intended="K-Alpha 1">
			<kAlpha1 unit="Angstrom">1.5405980</kAlpha1>
			<kAlpha2 unit="Angstrom">1.5444260</kAlpha2>
			<kBeta unit="Angstrom">1.3922500</kBeta>
			<ratioKAlpha2KAlpha1>0.5000</ratioKAlpha2KAlpha1>
		</usedWavelength>
		<incidentBeamPath>
			<radius unit="mm">320.00</radius>
			<xRayTube id="1010048" name="Empyrean Cu LFF HR (9430 033 7310x) DK425175">
				<tension unit="kV">45.0</tension>
				<current unit="mA">40.0</current>
				<anodeMaterial>Cu</anodeMaterial>
				<focus type="Line">
					<length unit="mm">12.0</length>
					<width unit="mm">0.4</width>
					<takeOffAngle unit="deg">4.2</takeOffAngle>
				</focus>
			</xRayTube>
			<xRayMirror id="27090001" name="Inc. Beam Cu W/Si (hybrid MRD)" hybrid="true">
				<crystal type="Graded" shape="Parabolic">W/Si</crystal>
				<acceptanceAngle unit="deg">0.800</acceptanceAngle>
				<length unit="mm">60.0</length>
			</xRayMirror>
			<monochromator id="23090002" name="Hybrid monochr. 2xGe(220) Cu asym." hybrid="true">
				<crystal type="Asymmetric" shape="Flat">Ge</crystal>
				<numberOfReflections>2</numberOfReflections>
				<hkl>
					<h>2</h>
					<k>2</k>
					<l>0</l>
				</hkl>
			</monochromator>
			<divergenceSlit id="22010004" name="Fixed slit 1/2°" xsi:type="fixedDivergenceSlitType">
				<distanceToSample unit="mm">220.00</distanceToSample>
				<height unit="mm">0.76</height>
			</divergenceSlit>
			<beamAttenuator id="26010001" name="Progr. beam attenuator Ni 0.125 mm" xsi:type="intensitySwitchedBeamAttenuatorType">
				<factor>172.00</factor>
				<material>Ni</material>
				<activateLevel unit="counts per second">500000</activateLevel>
				<deactivateLevel unit="counts per second">400000</deactivateLevel>
			</beamAttenuator>
		</incidentBeamPath>
		<diffractedBeamPath>
			<radius unit="mm">320.00</radius>
			<antiScatterSlit id="22090009" name="AS slit 7.5 mm (PIXcel)" xsi:type="fixedAntiScatterSlitType">
				<height unit="mm">7.50</height>
			</antiScatterSlit>
			<sollerSlit id="21010002" name="Soller slits 0.04 rad.">
				<opening unit="rad">0.0400</opening>
			</sollerSlit>
			<receivingSlit id="22010004" name="Fixed slit 1/2°">
				<height unit="mm">0.76</height>
			</receivingSlit>
			<detector id="7010020" name="PIXcel3D-Medipix3 1x1 detector" xsi:type="areaDetectorType">
				<phd unit="%">
					<lowerLevel>25.0</lowerLevel>
					<upperLevel>70.0</upperLevel>
				</phd>
				<mode>Receiving slit</mode>
				<activeChannelsEquatorial>5</activeChannelsEquatorial>
				<activeChannelsAxial>255</activeChannelsAxial>
				<pitchEquatorial unit="mm">0.05500</pitchEquatorial>
				<pitchAxial unit="mm">0.05500</pitchAxial>
				<readOutPeriod unit="seconds">0.050</readOutPeriod>
			</detector>
		</diffractedBeamPath>
		<scan appendNumber="0" mode="Continuous" scanAxis="2Theta-Omega" status="Completed">
			<header>
				<startTimeStamp>2022-06-02T10:14:39-07:00</startTimeStamp>
				<endTimeStamp>2022-06-02T10:35:05-07:00</endTimeStamp>
				<author>
					<name>XRD</name>
				</author>
				<source>
					<applicationSoftware version="6.1b">Data Collector</applicationSoftware>
					<instrumentControlSoftware version="7.4b 20181204">XPERT-3</instrumentControlSoftware>
					<instrumentID>0000000011163216</instrumentID>
				</source>
			</header>
			<dataPoints>
				<positions axis="2Theta" unit="deg">
					<startPosition>20.0050</startPosition>
					<endPosition>49.9950</endPosition>
				</positions>
				<positions axis="Omega" unit="deg">
					<startPosition>10.6082</startPosition>
					<endPosition>25.6032</endPosition>
				</positions>
				<positions axis="Phi" unit="deg">
					<commonPosition>0.00</commonPosition>
				</positions>
				<positions axis="Chi" unit="deg">
					<commonPosition>-0.03</commonPosition>
				</positions>
				<positions axis="X" unit="mm">
					<commonPosition>-0.76</commonPosition>
				</positions>
				<positions axis="Y" unit="mm">
					<commonPosition>0.00</commonPosition>
				</positions>
				<positions axis="Z" unit="mm">
					<commonPosition>8.721</commonPosition>
				</positions>
				<beamAttenuationFactors>1.00 1.00 1.00 1.00 1.00 1.00 1.00 1.00 1.00 1.00 1.00 1.00 1.00 1.00 1.00 1.00 1.00 1.00 1.00 1.00 1.00 1.00 1.00 1.00 1.00 1.00 1.00 1.00 1.00 1.00 1.00 1.00 1.00 1.00 1.00 1.00 1.00 1.00 1.00 1.00 1.00 1.00 1.00 1.00 1.00 1.00 1.00 1.00 1.00 1.00 1.00 1.00 1.00 1.00 1.00 1.00 1.00 1.00 1.00 1.00 1.00 1.00 1.00 1.00 1.00 1.00 1.00 1.00 1.00 1.00 1.00 1.00 1.00 1.00 1.00 1.00 1.00 1.00 1.00 1.00 1.00 1.00 1.00 1.00 1.00 1.00 1.00 1.00 1.00 1.00 1.00 1.00 1.00 1.00 1.00 1.00 1.00 1.00 1.00 1.00 1.00 1.00 1.00 1.00 1.00 1.00 1.00 1.00 1.00 1.00 1.00 1.00 1.00 1.00 1.00 1.00 1.00 1.00 1.00 1.00 1.00 1.00 1.00 1.00 1.00 1.00 1.00 1.00 1.00 1.00 1.00 1.00 1.00 1.00 1.00 1.00 1.00 1.00 1.00 1.00 1.00 1.00 1.00 1.00 1.00 1.00 1.00 1.00 1.00 1.00 1.00 1.00 1.00 1.00 1.00 1.00 1.00 1.00 1.00 1.00 1.00 1.00 1.00 1.00 1.00 1.00 1.00 1.00 1.00 1.00 1.00 1.00 1.00 1.00 1.00 1.00 1.00 1.00 1.00 1.00 1.00 1.00 1.00 1.00 1.00 1.00 1.00 1.00 1.00 1.00 1.00 1.00 1.00 1.00 1.00 1.00 1.00 1.00 1.00 1.00 1.00 1.00 1.00 1.00 1.00 1.00 1.00 1.00 1.00 1.00 1.00 1.00 1.00 1.00 1.00 1.00 1.00 1.00 1.00 1.00 1.00 1.00 1.00 1.00 1.00 1.00 1.00 1.00 1.00 1.00 1.00 1.00 1.00 1.00 1.00 1.00 1.00 1.00 1.00 1.00 1.00 1.00 1.00 1.00 1.00 1.00 1.00 1.00 1.00 1.00 1.00 1.00 1.00 1.00 1.00 1.00 1.00 1.00 1.00 1.00 1.00 1.00 1.00 1.00 1.00 1.00 1.00 1.00 1.00 1.00 1.00 1.00 1.00 1.00 1.00 1.00 1.00 1.00 1.00 1.00 1.00 1.00 1.00 1.00 1.00 1.00 1.00 1.00 1.00 1.00 1.00 1.00 1.00 1.00 1.00 1.00 1.00 1.00 1.00 1.00 1.00 1.00 1.00 1.00 1.00 1.00 1.00 1.00 1.00 1.00 1.00 1.00 1.00 1.00 1.00 1.00 1.00 1.00 1.00 1.00 1.00 1.00 1.00 1.00 1.00 1.00 1.00 1.00 1.00 1.00 1.00 1.00 1.00 1.00 1.00 1.00 1.00 1.00 1.00 1.00 1.00 1.00 1.00 1.00 1.00 1.00 1.00 1.00 1.00 1.00 1.00 1.00 1.00 1.00 1.00 1.00 1.00 1.00 1.00 1.00 1.00 1.00 1.00 1.00 1.00 1.00 1.00 1.00 1.00 1.00 1.00 1.00 1.00 1.00 1.00 1.00 1.00 1.00 1.00 1.00 1.00 1.00 1.00 1.00 1.00 1.00 1.00 1.00 1.00 1.00 1.00 1.00 1.00 1.00 1.00 1.00 1.00 1.00 1.00 1.00 1.00 1.00 1.00 1.00 1.00 1.00 1.00 1.00 1.00 1.00 1.00 1.00 1.00 1.00 1.00 1.00 1.00 1.00 1.00 1.00 1.00 1.00 1.00 1.00 1.00 1.00 1.00 1.00 1.00 1.00 1.00 1.00 1.00 1.00 1.00 1.00 1.00 1.00 1.00 1.00 1.00 1.00 1.00 1.00 1.00 1.00 1.00 1.00 1.00 1.00 1.00 1.00 1.00 1.00 1.00 1.00 1.00 1.00 1.00 1.00 1.00 1.00 1.00 1.00 1.00 1.00 1.00 1.00 1.00 1.00 1.00 1.00 1.00 1.00 1.00 1.00 1.00 1.00 1.00 1.00 1.00 1.00 1.00 1.00 1.00 1.00 1.00 1.00 1.00 1.00 1.00 1.00 1.00 1.00 1.00 1.00 1.00 1.00 1.00 1.00 1.00 1.00 1.00 1.00 1.00 1.00 1.00 1.00 1.00 1.00 1.00 1.00 1.00 1.00 1.00 1.00 1.00 1.00 1.00 1.00 1.00 1.00 1.00 1.00 1.00 1.00 1.00 1.00 1.00 1.00 1.00 1.00 1.00 1.00 1.00 1.00 1.00 1.00 1.00 1.00 1.00 1.00 1.00 1.00 1.00 1.00 1.00 1.00 1.00 1.00 1.00 1.00 1.00 1.00 1.00 1.00 1.00 1.00 1.00 1.00 1.00 1.00 1.00 1.00 1.00 1.00 1.00 1.00 1.00 1.00 1.00 1.00 1.00 1.00 1.00 1.00 1.00 1.00 1.00 1.00 1.00 1.00 1.00 1.00 1.00 1.00 1.00 1.00 1.00 1.00 1.00 1.00 1.00 1.00 1.00 1.00 1.00 1.00 1.00 1.00 1.00 1.00 1.00 1.00 1.00 1.00 1.00 1.00 1.00 1.00 1.00 1.00 1.00 1.00 1.00 1.00 1.00 1.00 1.00 1.00 1.00 1.00 1.00 1.00 1.00 1.00 1.00 1.00 1.00 1.00 1.00 1.00 1.00 1.00 1.00 1.00 1.00 1.00 1.00 1.00 1.00 1.00 1.00 1.00 1.00 1.00 1.00 1.00 1.00 1.00 1.00 1.00 1.00 1.00 1.00 1.00 1.00 1.00 1.00 1.00 1.00 1.00 1.00 1.00 1.00 1.00 1.00 1.00 1.00 1.00 1.00 1.00 1.00 1.00 1.00 1.00 1.00 1.00 1.00 1.00 1.00 1.00 1.00 1.00 1.00 1.00 1.00 1.00 1.00 1.00 1.00 1.00 1.00 1.00 1.00 1.00 1.00 1.00 1.00 1.00 1.00 1.00 1.00 1.00 1.00 1.00 1.00 1.00 1.00 1.00 1.00 1.00 1.00 1.00 1.00 1.00 1.00 1.00 1.00 1.00 1.00 1.00 1.00 1.00 1.00 1.00 1.00 1.00 1.00 1.00 1.00 1.00 1.00 1.00 1.00 1.00 1.00 1.00 1.00 1.00 1.00 1.00 1.00 1.00 1.00 1.00 1.00 1.00 1.00 1.00 1.00 1.00 1.00 1.00 1.00 1.00 1.00 1.00 1.00 1.00 1.00 1.00 1.00 1.00 1.00 1.00 1.00 1.00 1.00 1.00 1.00 1.00 1.00 1.00 1.00 1.00 1.00 1.00 1.00 1.00 1.00 1.00 1.00 1.00 1.00 1.00 1.00 1.00 1.00 1.00 1.00 1.00 1.00 1.00 1.00 1.00 1.00 1.00 1.00 1.00 1.00 1.00 1.00 1.00 1.00 1.00 1.00 1.00 1.00 1.00 1.00 1.00 1.00 1.00 1.00 1.00 1.00 1.00 1.00 1.00 1.00 1.00 1.00 1.00 1.00 1.00 1.00 1.00 1.00 1.00 1.00 1.00 1.00 1.00 1.00 1.00 1.00 1.00 1.00 1.00 1.00 1.00 1.00 1.00 1.00 1.00 1.00 1.00 1.00 1.00 1.00 1.00 1.00 1.00 1.00 1.00 1.00 1.00 1.00 1.00 1.00 1.00 1.00 1.00 1.00 1.00 1.00 1.00 1.00 1.00 1.00 1.00 1.00 1.00 1.00 1.00 1.00 1.00 1.00 1.00 1.00 1.00 1.00 1.00 1.00 1.00 1.00 1.00 1.00 1.00 1.00 1.00 1.00 1.00 1.00 1.00 1.00 1.00 1.00 1.00 1.00 1.00 1.00 1.00 1.00 1.00 1.00 1.00 1.00 1.00 1.00 1.00 1.00 1.00 1.00 1.00 1.00 1.00 1.00 1.00 1.00 1.00 1.00 1.00 1.00 1.00 1.00 1.00 1.00 1.00 1.00 1.00 1.00 1.00 1.00 1.00 1.00 1.00 1.00 1.00 1.00 1.00 1.00 1.00 1.00 1.00 1.00 1.00 1.00 1.00 1.00 1.00 1.00 1.00 1.00 1.00 1.00 1.00 1.00 1.00 1.00 1.00 1.00 1.00 1.00 1.00 1.00 1.00 1.00 1.00 1.00 1.00 1.00 1.00 1.00 1.00 1.00 1.00 1.00 1.00 1.00 1.00 1.00 1.00 1.00 1.00 1.00 1.00 1.00 1.00 1.00 1.00 1.00 1.00 1.00 1.00 1.00 1.00 1.00 1.00 1.00 1.00 1.00 1.00 1.00 1.00 1.00 1.00 1.00 1.00 1.00 1.00 1.00 1.00 1.00 1.00 1.00 1.00 1.00 1.00 1.00 1.00 1.00 1.00 1.00 1.00 1.00 1.00 1.00 1.00 1.00 1.00 1.00 1.00 1.00 1.00 1.00 1.00 1.00 1.00 1.00 1.00 1.00 1.00 1.00 1.00 1.00 1.00 1.00 1.00 1.00 1.00 1.00 1.00 1.00 1.00 1.00 1.00 1.00 1.00 1.00 1.00 1.00 1.00 1.00 1.00 1.00 1.00 1.00 1.00 1.00 1.00 1.00 1.00 1.00 1.00 1.00 1.00 1.00 1.00 1.00 1.00 1.00 1.00 1.00 1.00 1.00 1.00 1.00 1.00 1.00 1.00 1.00 1.00 1.00 1.00 1.00 1.00 1.00 1.00 1.00 1.00 1.00 1.00 1.00 1.00 1.00 1.00 1.00 1.00 1.00 1.00 1.00 1.00 1.00 1.00 1.00 1.00 1.00 1.00 1.00 1.00 1.00 1.00 1.00 1.00 1.00 1.00 1.00 1.00 1.00 1.00 1.00 1.00 1.00 1.00 1.00 1.00 1.00 1.00 1.00 1.00 1.00 1.00 1.00 1.00 1.00 1.00 1.00 1.00 1.00 1.00 1.00 1.00 1.00 1.00 1.00 1.00 1.00 1.00 1.00 1.00 1.00 1.00 1.00 1.00 1.00 1.00 1.00 1.00 1.00 1.00 1.00 1.00 1.00 1.00 1.00 1.00 1.00 1.00 1.00 1.00 1.00 1.00 1.00 1.00 1.00 1.00 1.00 1.00 1.00 1.00 1.00 1.00 1.00 1.00 1.00 1.00 1.00 1.00 1.00 1.00 1.00 1.00 1.00 1.00 1.00 1.00 1.00 1.00 1.00 1.00 1.00 1.00 1.00 1.00 1.00 1.00 1.00 1.00 1.00 1.00 1.00 1.00 1.00 1.00 1.00 1.00 1.00 1.00 1.00 1.00 1.00 1.00 1.00 1.00 1.00 1.00 1.00 1.00 1.00 1.00 1.00 1.00 1.00 1.00 1.00 1.00 1.00 1.00 1.00 1.00 1.00 1.00 1.00 1.00 1.00 1.00 1.00 1.00 1.00 1.00 1.00 1.00 1.00 1.00 1.00 1.00 1.00 1.00 1.00 1.00 1.00 1.00 1.00 1.00 1.00 1.00 1.00 1.00 1.00 1.00 1.00 1.00 1.00 1.00 1.00 1.00 1.00 1.00 1.00 1.00 1.00 1.00 1.00 1.00 1.00 1.00 1.00 1.00 1.00 1.00 1.00 1.00 1.00 1.00 1.00 1.00 1.00 1.00 1.00 1.00 1.00 1.00 1.00 1.00 1.00 1.00 1.00 1.00 1.00 1.00 1.00 1.00 1.00 1.00 1.00 1.00 1.00 1.00 1.00 1.00 1.00 1.00 1.00 1.00 1.00 1.00 1.00 1.00 1.00 1.00 1.00 1.00 1.00 1.00 1.00 1.00 1.00 1.00 1.00 1.00 1.00 1.00 1.00 1.00 1.00 1.00 1.00 1.00 1.00 1.00 1.00 1.00 1.00 1.00 1.00 1.00 1.00 1.00 1.00 1.00 1.00 1.00 1.00 1.00 1.00 1.00 1.00 1.00 1.00 1.00 1.00 1.00 1.00 1.00 1.00 1.00 1.00 1.00 1.00 1.00 1.00 1.00 1.00 1.00 1.00 1.00 1.00 1.00 1.00 1.00 1.00 1.00 1.00 1.00 1.00 1.00 1.00 1.00 1.00 1.00 1.00 1.00 1.00 1.00 1.00 1.00 1.00 1.00 1.00 1.00 1.00 1.00 1.00 1.00 1.00 1.00 1.00 1.00 1.00 1.00 1.00 1.00 1.00 1.00 1.00 1.00 1.00 1.00 1.00 1.00 1.00 1.00 1.00 1.00 1.00 1.00 1.00 1.00 1.00 1.00 1.00 1.00 1.00 1.00 1.00 1.00 1.00 1.00 1.00 1.00 1.00 1.00 1.00 1.00 1.00 1.00 1.00 1.00 1.00 1.00 1.00 1.00 1.00 1.00 1.00 1.00 1.00 1.00 1.00 1.00 1.00 1.00 1.00 1.00 1.00 1.00 1.00 1.00 1.00 1.00 1.00 1.00 1.00 1.00 1.00 1.00 1.00 1.00 1.00 1.00 1.00 1.00 1.00 1.00 1.00 1.00 1.00 1.00 1.00 1.00 1.00 1.00 1.00 1.00 1.00 1.00 1.00 1.00 1.00 1.00 1.00 1.00 1.00 1.00 1.00 1.00 1.00 1.00 1.00 1.00 1.00 1.00 1.00 1.00 1.00 1.00 1.00 1.00 1.00 1.00 1.00 1.00 1.00 1.00 1.00 1.00 1.00 1.00 1.00 1.00 1.00 1.00 1.00 1.00 1.00 1.00 1.00 1.00 1.00 1.00 1.00 1.00 1.00 1.00 1.00 1.00 1.00 1.00 1.00 1.00 1.00 1.00 1.00 1.00 1.00 1.00 1.00 1.00 1.00 1.00 1.00 1.00 1.00 1.00 1.00 1.00 1.00 1.00 1.00 1.00 1.00 1.00 1.00 1.00 1.00 1.00 1.00 1.00 1.00 1.00 1.00 1.00 1.00 1.00 1.00 1.00 1.00 1.00 1.00 1.00 1.00 1.00 1.00 1.00 1.00 1.00 1.00 1.00 1.00 1.00 1.00 1.00 1.00 1.00 1.00 1.00 1.00 1.00 1.00 1.00 1.00 1.00 1.00 1.00 1.00 1.00 1.00 1.00 1.00 1.00 1.00 1.00 1.00 1.00 1.00 1.00 1.00 1.00 1.00 1.00 1.00 1.00 1.00 1.00 1.00 1.00 1.00 1.00 1.00 1.00 1.00 1.00 1.00 1.00 1.00 1.00 1.00 1.00 1.00 1.00 1.00 1.00 1.00 1.00 1.00 1.00 1.00 1.00 1.00 1.00 1.00 1.00 1.00 1.00 1.00 1.00 1.00 1.00 1.00 1.00 1.00 1.00 1.00 1.00 1.00 1.00 1.00 1.00 1.00 1.00 1.00 1.00 1.00 1.00 1.00 1.00 1.00 1.00 1.00 1.00 1.00 1.00 1.00 1.00 1.00 1.00 1.00 1.00 1.00 1.00 1.00 1.00 1.00 1.00 1.00 1.00 1.00 1.00 1.00 1.00 1.00 1.00 1.00 1.00 1.00 1.00 1.00 1.00 1.00 1.00 1.00 1.00 1.00 1.00 1.00 1.00 1.00 1.00 1.00 1.00 1.00 1.00 1.00 1.00 1.00 1.00 1.00 1.00 1.00 1.00 1.00 1.00 1.00 1.00 1.00 1.00 1.00 1.00 1.00 1.00 1.00 1.00 1.00 1.00 1.00 1.00 1.00 1.00 1.00 1.00 1.00 1.00 1.00 1.00 1.00 1.00 1.00 1.00 1.00 1.00 1.00 1.00 1.00 1.00 1.00 1.00 1.00 1.00 1.00 1.00 1.00 1.00 1.00 1.00 1.00 1.00 1.00 1.00 1.00 1.00 1.00 1.00 1.00 1.00 1.00 1.00 1.00 1.00 1.00 1.00 1.00 1.00 1.00 1.00 1.00 1.00 1.00 1.00 1.00 1.00 1.00 1.00 1.00 1.00 1.00 1.00 1.00 1.00 1.00 1.00 1.00 1.00 1.00 1.00 1.00 1.00 1.00 1.00 1.00 1.00 1.00 1.00 1.00 1.00 1.00 1.00 1.00 1.00 1.00 1.00 1.00 1.00 1.00 1.00 1.00 1.00 1.00 1.00 1.00 1.00 1.00 1.00 1.00 1.00 1.00 1.00 1.00 1.00 1.00 1.00 1.00 1.00 1.00 1.00 1.00 1.00 1.00 1.00 1.00 1.00 1.00 1.00 1.00 1.00 1.00 1.00 1.00 1.00 1.00 1.00 1.00 1.00 1.00 1.00 1.00 1.00 1.00 1.00 1.00 1.00 1.00 1.00 1.00 1.00 1.00 1.00 1.00 1.00 1.00 1.00 1.00 1.00 1.00 1.00 1.00 1.00 1.00 1.00 1.00 1.00 1.00 1.00 1.00 1.00 1.00 1.00 1.00 1.00 1.00 1.00 1.00 1.00 1.00 1.00 1.00 1.00 1.00 1.00 1.00 1.00 1.00 1.00 1.00 1.00 1.00 1.00 1.00 1.00 1.00 1.00 1.00 1.00 1.00 1.00 1.00 1.00 1.00 1.00 1.00 1.00 1.00 1.00 1.00 1.00 1.00 1.00 1.00 1.00 1.00 1.00 1.00 1.00 1.00 1.00 1.00 1.00 1.00 1.00 1.00 1.00 1.00 1.00 1.00 1.00 1.00 1.00 1.00 1.00 1.00 1.00 1.00 1.00 1.00 1.00 1.00 1.00 1.00 1.00 1.00 1.00 1.00 1.00 1.00 1.00 1.00 1.00 1.00 1.00 1.00 1.00 1.00 1.00 1.00 1.00 1.00 1.00 1.00 1.00 1.00 1.00 1.00 1.00 1.00 1.00 1.00 1.00 1.00 1.00 1.00 1.00 1.00 1.00 1.00 1.00 1.00 1.00 1.00 1.00 1.00 1.00 1.00 1.00 1.00 1.00 1.00 1.00 1.00 1.00 1.00 1.00 1.00 1.00 1.00 1.00 1.00 1.00 1.00 1.00 1.00 1.00 1.00 1.00 1.00 1.00 1.00 1.00 1.00 1.00 1.00 1.00 1.00 1.00 1.00 1.00 1.00 1.00 1.00 1.00 1.00 1.00 1.00 1.00 1.00 1.00 1.00 1.00 1.00 1.00 1.00 1.00 1.00 1.00 1.00 1.00 1.00 1.00 1.00 1.00 1.00 1.00 1.00 1.00 1.00 1.00 1.00 1.00 1.00 1.00 1.00 1.00 1.00 1.00 1.00 1.00 1.00 1.00 1.00 1.00 1.00 1.00 1.00 1.00 1.00 1.00 1.00 1.00 1.00 1.00 1.00 1.00 1.00 1.00 1.00 1.00 1.00 1.00 1.00 1.00 1.00 1.00 1.00 1.00 1.00 1.00 1.00 1.00 1.00 1.00 1.00 1.00 1.00 1.00 1.00 1.00 1.00 1.00 1.00 1.00 1.00 1.00 1.00 1.00 1.00 1.00 1.00 1.00 1.00 1.00 1.00 1.00 1.00 1.00 1.00 1.00 1.00 1.00 1.00 1.00 1.00 1.00 1.00 1.00 1.00 1.00 1.00 1.00 1.00 1.00 1.00 1.00 1.00 1.00 1.00 1.00 1.00 1.00 1.00 1.00 1.00 1.00 1.00 1.00 1.00 1.00 1.00 1.00 1.00 1.00 1.00 1.00 1.00 1.00 1.00 1.00 1.00 1.00 1.00 1.00 1.00 1.00 1.00 1.00 1.00 1.00 1.00 1.00 1.00 1.00 1.00 1.00 1.00 1.00 1.00 1.00 1.00 1.00 1.00 1.00 1.00 1.00 1.00 1.00 1.00 1.00 1.00 1.00 1.00 1.00 1.00 1.00 1.00 1.00 1.00 1.00 1.00 1.00 1.00 1.00 1.00 1.00 1.00 1.00 1.00 1.00 1.00 1.00 1.00 1.00 1.00 1.00 1.00 1.00 1.00 1.00 1.00 1.00 1.00 1.00 1.00 1.00 1.00 1.00 1.00 1.00 1.00 1.00 1.00 1.00 1.00 1.00 1.00 1.00 1.00 1.00 1.00 1.00 1.00 1.00 1.00 1.00 1.00 1.00 1.00 1.00 1.00 1.00 1.00 1.00 1.00 1.00 1.00 1.00 1.00 1.00 1.00 1.00 1.00 1.00 1.00 1.00 1.00 1.00 1.00 1.00 1.00 1.00 1.00 1.00 1.00 1.00 1.00 1.00 1.00 1.00 1.00 1.00 1.00 1.00 1.00 1.00 1.00 1.00 1.00 1.00 1.00 1.00 1.00 1.00 1.00 1.00 1.00 1.00 1.00 1.00 1.00 1.00 1.00 1.00 1.00 1.00 1.00 1.00 1.00 1.00 1.00 1.00 1.00 1.00 1.00 1.00 1.00 1.00 1.00 1.00 1.00 1.00 1.00 1.00 1.00 1.00 1.00 1.00 1.00 1.00 1.00 1.00 1.00 1.00 1.00 1.00 1.00 1.00 1.00 1.00 1.00 1.00 1.00 1.00 1.00 1.00 1.00 1.00 1.00 1.00 1.00 1.00 1.00 1.00 1.00 1.00 1.00 1.00 1.00 1.00 1.00 1.00 1.00 1.00 1.00 1.00 1.00 1.00 1.00 1.00 1.00 1.00 1.00 1.00 1.00 1.00 1.00 1.00 1.00 1.00 1.00 1.00 1.00 1.00 1.00 1.00 1.00 1.00 1.00 1.00 1.00 1.00 1.00 1.00 1.00 1.00 1.00 1.00 1.00 1.00 1.00 1.00 1.00 1.00 1.00 1.00 1.00 1.00 1.00 1.00 1.00 1.00 1.00 1.00 1.00 1.00 1.00 1.00 1.00 1.00 1.00 1.00 1.00 1.00 1.00 1.00 1.00 1.00 1.00 1.00 1.00 1.00 1.00 1.00 1.00 1.00 1.00 1.00 1.00 1.00 1.00 1.00 1.00 1.00 1.00 1.00 1.00 1.00 1.00 1.00 1.00 1.00 1.00 1.00 1.00 1.00 1.00 1.00 1.00 1.00 1.00 1.00 1.00 1.00 1.00 1.00 1.00 1.00 1.00 1.00 1.00 1.00 1.00 1.00 1.00 1.00 1.00 1.00 1.00 1.00 1.00 1.00 1.00 1.00 1.00 1.00 1.00 1.00 1.00 1.00 1.00 1.00 1.00 1.00 1.00 1.00 1.00 1.00 1.00 1.00 1.00 1.00 1.00 1.00 1.00 1.00 1.00 1.00 1.00 1.00 1.00 1.00 1.00 1.00 1.00 1.00 1.00 1.00 1.00 1.00 1.00 1.00 1.00 1.00 1.00 1.00 1.00 1.00 1.00 1.00 1.00 1.00 1.00 1.00 1.00 1.00 1.00 1.00 1.00 1.00 1.00 1.00 1.00 1.00 1.00 1.00 1.00 1.00 1.00 1.00 1.00 1.00 1.00 1.00 1.00 1.00 1.00 1.00 1.00 1.00 1.00 1.00 1.00 1.00 1.00 1.00 1.00 1.00 1.00 1.00 1.00 1.00 1.00 1.00 1.00 1.00 1.00 1.00 1.00 1.00 172.00 172.00 172.00 1.00 1.00 1.00 1.00 1.00 1.00 1.00 1.00 1.00 1.00 1.00 1.00 1.00 1.00 1.00 1.00 1.00 1.00 1.00 1.00 1.00 1.00 1.00 1.00 1.00 1.00 1.00 1.00 1.00 1.00 1.00 1.00 1.00 1.00 1.00 1.00 1.00 1.00 1.00 1.00 1.00 1.00 1.00 1.00 1.00 1.00 1.00 1.00 1.00 1.00 1.00 1.00 1.00 1.00 1.00 1.00 1.00 1.00 1.00 1.00 1.00 1.00 1.00 1.00 1.00 1.00 1.00 1.00 1.00 1.00 1.00 1.00 1.00 1.00 1.00 1.00 1.00 1.00 1.00 1.00 1.00 1.00 1.00 1.00 1.00 1.00 1.00 1.00 1.00 1.00 1.00 1.00 1.00 1.00 1.00 1.00 1.00 1.00 1.00 1.00 1.00 1.00 1.00 1.00 1.00 1.00 1.00 1.00 1.00 1.00 1.00 1.00 1.00 1.00 1.00 1.00 1.00 1.00 1.00 1.00 1.00 1.00 1.00 1.00 1.00 1.00 1.00 1.00 1.00 1.00 1.00 1.00 1.00 1.00 1.00 1.00 1.00 1.00 1.00 1.00 1.00 1.00 1.00 1.00 1.00 1.00 1.00 1.00 1.00 1.00 1.00 1.00 1.00 1.00 1.00 1.00 1.00 1.00 1.00 1.00 1.00 1.00 1.00 1.00 1.00 1.00 1.00 1.00 1.00 1.00 1.00 1.00 1.00 1.00 1.00 1.00 1.00 1.00 1.00 1.00 1.00 1.00 1.00 1.00 1.00 1.00 1.00 1.00 1.00 1.00 1.00 1.00 1.00 1.00 1.00 1.00 1.00 1.00 1.00 1.00 1.00 1.00 1.00 1.00 1.00 1.00 1.00 1.00 1.00 1.00 1.00 1.00 1.00 1.00 1.00 1.00 1.00 1.00 1.00 1.00 1.00 1.00 1.00 1.00 1.00 1.00 1.00 1.00 1.00 1.00 1.00 1.00 1.00 1.00 1.00 1.00 1.00 1.00 1.00 1.00 1.00 1.00 1.00 1.00 1.00 1.00 1.00 1.00 1.00 1.00 1.00 1.00 1.00 1.00 1.00 1.00 1.00 1.00 1.00 1.00 1.00 1.00 1.00 1.00 1.00 1.00 1.00 1.00 1.00 1.00 1.00 1.00 1.00 1.00 1.00 1.00 1.00 1.00 1.00 1.00 1.00 1.00 1.00 1.00 1.00 1.00 1.00 1.00 1.00 1.00 1.00 1.00 1.00 1.00 1.00 1.00 1.00 1.00 1.00 1.00 1.00 1.00 1.00 1.00 1.00 1.00 1.00 1.00 1.00 1.00 1.00 1.00 1.00 1.00 1.00 1.00 1.00 1.00 1.00 1.00 1.00 1.00 1.00 1.00 1.00 1.00 1.00 1.00 1.00 1.00 1.00 1.00 1.00 1.00 1.00 1.00 1.00 1.00 1.00 1.00 1.00 1.00 1.00 1.00 1.00 1.00 1.00 1.00 1.00 1.00 1.00</beamAttenuationFactors>
				<commonCountingTime unit="seconds">0.352</commonCountingTime>
				<counts unit="counts">38 43 37 34 36 50 27 53 29 38 29 44 36 38 35 28 44 42 37 38 45 38 45 27 47 33 40 41 38 46 39 34 41 42 30 40 50 34 41 43 32 34 27 27 30 31 34 35 31 38 44 38 30 39 37 41 34 45 30 29 27 18 29 42 31 41 30 26 39 40 33 38 34 24 36 26 35 47 31 44 31 26 26 26 36 21 34 32 37 29 52 37 41 34 39 27 35 31 34 40 31 41 39 32 39 27 27 38 37 30 38 26 39 36 37 31 42 32 35 30 36 38 32 28 37 39 36 41 37 45 33 41 43 29 37 32 42 44 30 36 32 35 36 31 31 29 40 43 43 34 36 40 44 43 44 39 35 41 24 28 31 37 27 30 39 34 39 39 38 32 43 30 42 45 41 43 46 37 36 36 44 36 40 39 47 31 45 26 44 39 46 40 52 62 57 45 53 52 54 46 61 43 44 36 35 35 41 42 56 54 51 78 54 108 130 103 121 108 126 119 101 93 87 87 67 48 50 59 58 92 159 156 228 336 428 542 619 710 982 910 1131 1228 1269 1431 1324 1590 1562 1510 1590 1443 1370 1286 1232 1109 973 810 780 620 483 411 326 247 216 170 174 228 414 1832 2821 4684 8777 10711 14725 17203 98524 196848 94862 22370 6520 4114 2392 491 421 316 248 177 127 84 93 70 85 65 79 53 85 107 107 89 93 95 106 103 96 88 92 73 59 46 39 45 36 37 36 38 39 52 44 52 56 56 64 56 54 55 53 45 48 52 47 47 40 34 38 36 31 24 31 42 36 54 43 47 43 50 45 43 56 46 37 26 34 29 29 33 24 33 35 32 29 41 42 52 54 46 32 41 30 36 34 30 30 31 29 28 37 27 27 31 36 35 32 42 39 34 37 32 34 39 30 36 30 31 27 22 24 33 26 27 31 32 41 41 30 30 30 31 29 32 27 29 33 31 38 30 31 32 30 25 30 36 23 31 30 33 35 15 31 33 29 30 31 24 29 32 32 27 30 22 24 35 34 21 32 21 27 30 36 33 30 30 26 24 31 26 31 24 18 30 30 32 25 32 19 27 28 23 25 35 35 24 22 31 16 27 28 31 24 16 19 25 20 21 27 18 22 23 26 22 17 40 29 24 26 31 35 25 28 33 21 35 28 21 28 19 24 29 21 27 17 19 29 38 23 29 17 23 24 35 31 28 30 25 17 23 34 23 20 21 27 19 29 27 26 29 31 24 22 23 28 32 22 24 28 23 27 25 30 23 19 31 24 19 21 29 32 19 28 18 36 25 36 21 26 19 28 28 23 25 25 23 20 30 28 19 24 22 18 26 24 22 24 21 19 23 22 13 21 21 20 22 18 20 27 24 24 22 25 19 27 25 32 17 25 13 21 34 26 26 22 22 22 23 20 26 16 20 22 13 28 23 23 17 20 25 26 17 19 17 22 29 15 19 21 20 19 22 27 22 22 20 27 19 24 25 20 18 13 19 22 24 21 23 23 18 16 11 17 8 23 20 28 28 20 21 28 25 22 25 25 27 21 23 23 16 29 20 18 16 19 24 25 21 25 23 21 22 22 16 28 23 17 17 22 17 29 26 16 23 18 18 17 16 18 14 28 21 13 14 22 17 17 23 20 18 26 21 22 14 20 20 19 20 19 22 21 16 7 20 24 21 17 25 24 22 21 17 23 28 18 15 24 16 13 16 28 9 17 19 21 21 30 19 15 27 29 21 19 31 15 21 22 13 18 8 19 25 13 24 17 21 15 14 24 14 23 25 21 13 10 22 21 15 21 25 18 25 21 17 14 19 21 27 27 23 19 23 25 24 19 21 14 18 18 14 20 15 18 20 21 16 13 18 26 16 27 19 13 21 12 22 24 15 19 19 22 23 24 18 23 16 20 12 13 23 18 25 15 22 22 27 14 12 12 15 16 22 24 18 16 14 11 11 15 23 18 20 18 12 20 19 17 13 17 13 15 19 14 18 14 14 9 22 13 17 25 21 22 16 18 17 15 13 24 11 12 14 17 25 25 21 12 23 19 10 29 17 15 20 14 9 16 18 19 16 18 15 18 13 6 21 18 16 15 11 17 13 18 24 17 15 13 16 15 11 23 19 18 18 9 21 14 20 16 14 13 21 21 17 25 17 13 13 13 17 22 22 10 11 22 13 16 13 15 15 15 12 18 9 14 13 18 18 15 16 14 17 19 17 26 19 18 16 13 20 12 13 17 20 17 19 17 13 16 17 16 12 21 13 25 15 13 24 24 25 19 24 16 18 11 21 19 21 25 15 21 17 15 23 21 13 21 18 17 12 16 15 14 17 22 15 25 12 14 12 11 17 25 14 15 21 23 21 20 14 14 13 13 18 14 10 8 13 17 18 14 20 14 16 20 16 23 14 14 19 19 19 20 16 10 11 15 20 20 17 8 16 22 13 15 14 17 18 11 5 12 7 9 14 19 13 14 14 16 17 13 19 16 13 12 8 19 10 11 13 19 12 20 13 13 13 16 11 18 12 11 13 10 16 13 16 18 19 13 12 17 16 10 23 14 14 15 16 6 7 19 12 13 14 17 17 13 9 16 15 10 13 8 9 14 10 12 11 11 18 11 12 11 20 13 15 15 17 9 15 10 12 10 14 15 16 16 16 8 14 15 13 13 14 14 13 19 10 21 11 17 13 15 16 10 14 18 21 16 16 16 23 16 10 12 16 17 13 18 15 14 8 8 13 15 14 12 11 18 22 15 13 19 14 18 14 17 13 17 22 21 14 22 7 14 15 15 17 11 19 16 13 16 11 17 16 11 16 13 22 18 10 16 14 8 8 19 12 14 8 14 12 14 10 12 19 16 13 11 13 11 9 16 13 12 13 12 16 15 6 16 11 10 13 14 21 10 17 7 10 11 13 13 15 15 18 23 12 8 20 10 15 5 12 6 10 17 9 15 11 19 15 16 13 17 11 18 12 17 18 9 11 13 10 10 15 19 8 15 14 7 13 16 10 18 17 13 9 15 13 18 12 10 14 13 16 14 7 12 7 22 7 15 19 20 16 14 14 8 11 12 10 11 13 18 9 11 7 9 16 8 7 14 14 4 19 11 10 11 11 11 12 15 15 15 9 10 11 11 18 14 14 17 13 16 3 11 9 15 9 12 14 12 14 16 14 10 11 13 8 10 11 15 14 9 7 13 17 12 14 10 9 12 16 14 24 9 20 11 12 16 10 5 4 13 13 13 6 14 13 10 13 18 15 16 13 9 5 10 15 17 14 14 12 15 10 14 15 14 16 10 14 8 4 12 8 16 18 10 7 8 11 11 10 11 14 6 11 14 10 12 14 9 16 14 11 11 21 14 12 8 23 13 11 11 14 13 13 13 9 12 11 16 13 7 11 18 11 15 14 6 15 6 6 5 12 12 9 13 8 13 10 11 11 17 13 15 14 14 11 10 14 15 10 12 7 15 13 12 12 8 17 17 10 19 11 16 10 16 15 9 13 16 13 8 10 9 18 18 11 10 11 10 12 15 11 12 11 5 10 12 14 14 17 4 14 10 9 9 15 8 11 8 19 10 4 15 11 11 9 12 13 9 7 11 17 13 9 11 15 6 11 17 10 7 11 11 21 7 9 9 16 9 13 7 14 7 10 10 11 14 11 13 11 10 7 13 11 18 11 10 10 11 9 12 9 11 11 14 13 13 8 14 9 9 9 11 11 8 10 8 12 10 9 11 12 12 16 8 8 15 18 13 6 12 8 15 11 9 6 11 8 7 7 12 12 13 10 5 14 12 10 9 7 2 11 19 9 7 10 9 10 6 13 6 10 8 8 11 9 4 7 9 7 11 12 13 10 8 11 12 10 13 11 13 10 12 6 10 9 9 17 17 7 11 8 11 12 8 11 9 9 5 9 12 6 17 10 8 10 13 16 10 12 7 7 21 7 10 15 12 10 16 8 9 11 10 10 9 10 9 9 8 10 9 11 7 7 3 12 9 11 8 9 21 9 10 11 15 12 11 12 11 16 12 13 14 4 13 6 9 7 6 12 17 10 11 11 14 9 13 11 12 10 7 10 12 16 11 8 12 10 7 11 12 8 9 11 9 13 22 20 8 13 6 7 10 10 17 3 6 12 8 9 10 12 8 11 12 12 10 10 9 13 14 5 16 11 12 20 11 10 11 12 9 7 14 11 9 7 8 12 11 10 15 9 7 10 7 13 9 6 5 11 10 14 20 7 11 6 14 13 10 12 9 10 13 13 12 11 10 12 7 19 9 10 14 6 12 6 2 10 15 10 7 10 13 10 10 8 7 10 5 18 7 12 11 12 10 15 9 11 7 12 10 16 11 13 8 13 12 14 8 9 12 8 6 14 7 13 10 7 9 10 9 6 11 6 12 11 10 6 16 5 6 14 7 15 4 7 14 15 9 7 8 6 11 6 5 11 3 8 12 12 9 11 5 11 12 10 4 13 8 9 7 11 4 11 24 9 13 15 11 9 12 12 10 7 11 14 11 11 7 11 7 6 10 14 6 10 7 9 9 4 12 8 7 15 6 18 5 3 9 10 15 14 7 9 6 7 14 17 8 12 8 13 10 10 11 12 13 9 12 14 12 8 12 15 7 8 11 7 13 8 9 8 15 9 7 9 8 14 10 8 11 7 8 15 11 7 14 14 10 9 10 15 15 9 10 12 11 13 7 17 8 9 10 8 11 10 19 7 10 13 8 13 4 12 10 9 10 10 12 11 10 8 12 8 15 11 11 13 10 6 9 9 12 8 10 15 15 18 10 4 7 9 10 6 10 6 11 9 6 8 12 8 9 5 10 6 9 14 11 8 7 15 7 6 8 13 11 8 10 13 8 9 4 12 7 4 9 17 12 12 15 10 9 14 8 9 8 12 13 9 10 13 4 10 17 10 16 8 5 11 9 11 6 17 10 8 7 8 11 12 13 8 11 9 13 15 18 15 9 11 8 16 12 14 13 7 16 11 14 10 11 10 7 11 13 13 15 9 8 11 7 11 5 8 11 9 12 9 10 14 7 12 11 5 12 9 10 10 12 13 16 6 12 14 12 7 12 19 8 10 9 13 11 12 13 11 11 9 11 14 9 9 13 8 8 10 14 11 6 7 10 14 14 10 13 16 16 11 15 13 14 12 9 15 12 5 9 9 16 14 9 12 14 17 12 11 11 8 12 13 7 7 9 13 12 11 8 10 5 8 7 14 8 20 11 12 8 9 9 10 11 18 10 7 4 14 9 15 10 13 7 14 11 9 6 14 13 13 9 13 13 12 9 11 16 7 11 15 12 14 11 5 9 13 8 9 13 12 12 9 13 10 20 19 14 13 10 10 15 8 8 8 10 9 14 11 8 17 13 13 16 15 21 14 22 8 20 11 9 13 9 5 16 10 7 15 12 10 15 13 14 14 15 16 15 10 16 19 11 13 12 14 8 18 15 14 6 9 11 15 12 15 18 13 21 14 22 11 22 18 19 18 16 28 8 14 11 11 12 16 10 14 10 11 15 19 17 20 21 21 28 18 20 26 27 20 20 16 17 9 10 10 9 11 9 15 13 27 22 17 18 20 21 29 23 26 22 29 29 19 21 18 20 13 15 15 14 24 27 21 21 25 33 31 30 30 35 30 35 30 44 38 29 21 24 23 13 18 20 14 18 25 23 37 41 40 47 49 51 60 42 67 60 56 48 49 38 39 27 33 22 21 23 35 28 50 58 54 69 113 93 105 122 105 124 109 104 134 87 63 68 58 48 46 50 52 82 106 107 137 190 219 260 271 308 309 347 348 353 329 293 269 227 206 171 162 178 226 312 401 570 812 1057 1371 1845 2196 2770 3294 4048 4633 5333 5942 6554 7201 7648 8238 8733 9096 9352 9485 9365 9260 9226 8979 8707 8171 7438 6990 6336 5578 5023 4328 3842 3234 2489 2033 1615 1299 1026 750 601 533 548 524 552 569 739 771 909 944 1066 1064 1100 1079 1069 1069 971 954 967 884 845 935 1037 1286 1946 4282 12957 27652 39615 49122 56434 55644 40321 27056 24322 29795 49258 191892 6290 8685 3403 84793 22447 10840 5820 3324 2261 1480 1144 844 707 519 441 316 230 208 134 123 93 89 62 74 80 91 89 100 96 91 103 97 91 86 77 64 79 37 43 31 33 19 15 22 13 14 23 21 31 22 29 41 36 32 38 37 32 24 30 41 20 19 15 13 17 14 14 16 10 20 10 23 16 17 21 19 17 17 18 19 20 24 15 11 12 21 12 14 14 10 17 10 15 11 16 19 15 15 7 26 17 18 15 11 11 18 8 10 12 9 10 10 13 9 9 9 11 16 9 5 11 15 12 9 13 15 11 13 12 10 7 8 14 11 13 10 9 9 5 14 8 8 10 6 11 13 11 14 12 15 8 10 9 6 7 7 10 12 6 7 7 8 12 9 10 11 10 6 7 9 10 11 5 10 12 7 8 11 11 11 7 5 2 6 6 4 7 10 6 9 9 3 5 9 6 10 13 10 7 10 5 6 6 7 8 5 12 5 4 3 7 5 4 6 12 9 9 11 10 11 8 4 9 7 13 9 9 4 7 6 8 7 10 11 7 7 9 11 9 12 10 12 8 2 5 10 10 8 9 4 5 5 11 5 8 13 6 6 9 12 6 11 6 14 10 11 12 6 9 8 12 5 5 6 3 7 2 9 10 8 4 8 5 8 6 5 6 7 9 6 7 3 8 2 8 5 9 8 6 8 7 8 7 6 6 4 2 6 7 10 7 8 3 10 7 9 6 6 9 7 6 7 6 7 9 9 8 8 7 5 10 4 11 2 7 6 2 7 8 7 7 4 4 9 7 9 10 7 6 8 6 4 7 8</counts>
			</dataPoints>
		</scan>
	</xrdMeasurement>
</xrdMeasurements>